[{"market":"0x375409bc5eeeff961e82b479caeccc20f33d15738e5bce1186d628aa3d9dfb1f","asset_id":"77121637225348873006259930776623502125079210522997384841464684944292365296940","timestamp":"1780150300255","hash":"9fa2509fed64ca0f1a4c9010db8976d977517b5c","bids":[{"price":"0.001","size":"21319088.56"},{"price":"0.002","size":"5005.12"},{"price":"0.003","size":"14.23"},{"price":"0.005","size":"2222222"},{"price":"0.006","size":"2000000"},{"price":"0.007","size":"800"},{"price":"0.008","size":"5.22"},{"price":"0.013","size":"1728"},{"price":"0.014","size":"52"},{"price":"0.1","size":"2991.34"},{"price":"0.151","size":"5000"},{"price":"0.155","size":"200"},{"price":"0.16","size":"300"},{"price":"0.161","size":"300"},{"price":"0.163","size":"300"},{"price":"0.18","size":"300"},{"price":"0.2","size":"1000"},{"price":"0.22","size":"345.04"},{"price":"0.221","size":"200"},{"price":"0.222","size":"135.13"},{"price":"0.223","size":"5.22"},{"price":"0.23","size":"230.97"},{"price":"0.25","size":"300"},{"price":"0.26","size":"300"},{"price":"0.27","size":"300"},{"price":"0.3","size":"2974.99"},{"price":"0.301","size":"200"},{"price":"0.35","size":"293.98"},{"price":"0.38","size":"133.26"},{"price":"0.39","size":"105"},{"price":"0.4","size":"36025"},{"price":"0.408","size":"4900"},{"price":"0.409","size":"6100"},{"price":"0.44","size":"105"},{"price":"0.45","size":"100"},{"price":"0.451","size":"1009.54"},{"price":"0.493","size":"494.73"},{"price":"0.5","size":"27051.85"},{"price":"0.501","size":"4100"},{"price":"0.502","size":"144.67"},{"price":"0.51","size":"275.39"},{"price":"0.55","size":"302.74"},{"price":"0.56","size":"100"},{"price":"0.6","size":"22248.33"},{"price":"0.613","size":"100"},{"price":"0.62","size":"100"},{"price":"0.623","size":"105"},{"price":"0.643","size":"100"},{"price":"0.65","size":"16362.62"},{"price":"0.661","size":"5100"},{"price":"0.662","size":"2095.26"},{"price":"0.67","size":"11.2"},{"price":"0.671","size":"100"},{"price":"0.673","size":"100"},{"price":"0.68","size":"99.99"},{"price":"0.69","size":"242.85"},{"price":"0.7","size":"1709.85"},{"price":"0.703","size":"100"},{"price":"0.712","size":"1000"},{"price":"0.72","size":"252.85"},{"price":"0.721","size":"100"},{"price":"0.733","size":"100"},{"price":"0.74","size":"180.76"},{"price":"0.742","size":"1000"},{"price":"0.75","size":"4558.91"},{"price":"0.761","size":"99.99"},{"price":"0.762","size":"400"},{"price":"0.763","size":"100"},{"price":"0.767","size":"8608.24"},{"price":"0.77","size":"200"},{"price":"0.771","size":"200"},{"price":"0.772","size":"1000"},{"price":"0.774","size":"16354.68"},{"price":"0.776","size":"9000"},{"price":"0.79","size":"3113.4"},{"price":"0.792","size":"1100"},{"price":"0.8","size":"18652.43"},{"price":"0.802","size":"1006.22"},{"price":"0.804","size":"1486.78"},{"price":"0.805","size":"30"},{"price":"0.81","size":"888.99"},{"price":"0.812","size":"1100"},{"price":"0.813","size":"100"},{"price":"0.82","size":"3820"},{"price":"0.822","size":"1000"},{"price":"0.828","size":"5.43"},{"price":"0.83","size":"110"},{"price":"0.834","size":"436.03"},{"price":"0.84","size":"390.66"},{"price":"0.841","size":"50"},{"price":"0.847","size":"263.15"},{"price":"0.85","size":"279.81"},{"price":"0.852","size":"1180.09"},{"price":"0.854","size":"847.46"},{"price":"0.855","size":"219.97"},{"price":"0.856","size":"118.44"},{"price":"0.857","size":"269"},{"price":"0.858","size":"167.16"},{"price":"0.86","size":"190.28"},{"price":"0.861","size":"232.7"},{"price":"0.862","size":"2611.44"},{"price":"0.863","size":"173.7"},{"price":"0.864","size":"145.37"},{"price":"0.865","size":"94.28"},{"price":"0.866","size":"111.44"},{"price":"0.867","size":"15000"},{"price":"0.868","size":"25121.44"},{"price":"0.869","size":"21"},{"price":"0.87","size":"60785.22"},{"price":"0.871","size":"4854.15"},{"price":"0.872","size":"55395.74"},{"price":"0.873","size":"1122.06"},{"price":"0.874","size":"312.33"},{"price":"0.875","size":"1879.28"},{"price":"0.876","size":"349.34"},{"price":"0.877","size":"20"},{"price":"0.878","size":"256.72"},{"price":"0.879","size":"99"},{"price":"0.88","size":"20859.13"},{"price":"0.881","size":"148797.59"},{"price":"0.882","size":"3293.19"},{"price":"0.883","size":"516048.24"},{"price":"0.884","size":"21720.12"},{"price":"0.885","size":"12999.15"},{"price":"0.886","size":"13106.41"},{"price":"0.887","size":"205630.56"},{"price":"0.888","size":"49868.31"}],"asks":[{"price":"0.999","size":"4816069"},{"price":"0.998","size":"1001693"},{"price":"0.996","size":"556755"},{"price":"0.995","size":"55655"},{"price":"0.994","size":"20000"},{"price":"0.993","size":"10800"},{"price":"0.992","size":"10000"},{"price":"0.991","size":"10000"},{"price":"0.99","size":"10000"},{"price":"0.989","size":"5000"},{"price":"0.988","size":"5000"},{"price":"0.987","size":"5000"},{"price":"0.986","size":"5000"},{"price":"0.985","size":"6000"},{"price":"0.984","size":"5000"},{"price":"0.983","size":"5000"},{"price":"0.982","size":"5060"},{"price":"0.981","size":"5000"},{"price":"0.98","size":"5375"},{"price":"0.979","size":"5020"},{"price":"0.978","size":"5000"},{"price":"0.977","size":"5000"},{"price":"0.976","size":"5000"},{"price":"0.96","size":"100"},{"price":"0.951","size":"100"},{"price":"0.95","size":"3975"},{"price":"0.948","size":"87.37"},{"price":"0.947","size":"1093.81"},{"price":"0.94","size":"50316.67"},{"price":"0.936","size":"169.92"},{"price":"0.935","size":"5000"},{"price":"0.93","size":"100"},{"price":"0.924","size":"267.15"},{"price":"0.92","size":"600"},{"price":"0.918","size":"105"},{"price":"0.912","size":"335.31"},{"price":"0.91","size":"500"},{"price":"0.907","size":"300"},{"price":"0.906","size":"16319"},{"price":"0.904","size":"11000"},{"price":"0.903","size":"500"},{"price":"0.9","size":"16088.38"},{"price":"0.899","size":"10000"},{"price":"0.898","size":"1010"},{"price":"0.897","size":"20"},{"price":"0.896","size":"2540"},{"price":"0.895","size":"600"},{"price":"0.894","size":"860"},{"price":"0.893","size":"5000"},{"price":"0.892","size":"9287.02"},{"price":"0.891","size":"11086.74"},{"price":"0.89","size":"150754.77"},{"price":"0.889","size":"242461.2"}],"tick_size":"0.001","event_type":"book","last_trade_price":"0.111"},{"market":"0x7976b8dbacf9077eb1453a62bcefd6ab2df199acd28aad276ff0d920d6992892","asset_id":"112680630004798425069810935278212000865453267506345451433803052322987302357330","timestamp":"1780150303041","hash":"c5610f02dc037c13f9c5f4c742132912179d03ed","bids":[{"price":"0.001","size":"13320371.6"},{"price":"0.002","size":"9.57"},{"price":"0.003","size":"156.25"},{"price":"0.004","size":"13.49"},{"price":"0.009","size":"8400"},{"price":"0.01","size":"7.03"},{"price":"0.012","size":"666666"},{"price":"0.013","size":"600000"},{"price":"0.014","size":"2534.99"},{"price":"0.016","size":"125.09"},{"price":"0.02","size":"5012"},{"price":"0.021","size":"3999.99"},{"price":"0.022","size":"5.22"},{"price":"0.05","size":"3109.99"},{"price":"0.051","size":"10.45"},{"price":"0.08","size":"3005"},{"price":"0.11","size":"1000"},{"price":"0.12","size":"1000"},{"price":"0.13","size":"1000"},{"price":"0.14","size":"999.99"},{"price":"0.15","size":"1000"},{"price":"0.16","size":"1000"},{"price":"0.168","size":"20"},{"price":"0.196","size":"301"},{"price":"0.2","size":"749.67"},{"price":"0.207","size":"400"},{"price":"0.208","size":"544.23"},{"price":"0.209","size":"300"},{"price":"0.21","size":"5.72"},{"price":"0.23","size":"408.6"},{"price":"0.25","size":"544.97"},{"price":"0.31","size":"305.55"},{"price":"0.32","size":"205"},{"price":"0.36","size":"231.25"},{"price":"0.384","size":"7223.76"},{"price":"0.39","size":"5"},{"price":"0.4","size":"34671.65"},{"price":"0.403","size":"1311"},{"price":"0.42","size":"211.4"},{"price":"0.421","size":"567.32"},{"price":"0.45","size":"510.51"},{"price":"0.451","size":"510.51"},{"price":"0.49","size":"220"},{"price":"0.5","size":"29664.87"},{"price":"0.501","size":"4216.7"},{"price":"0.502","size":"130"},{"price":"0.504","size":"457.83"},{"price":"0.505","size":"263.77"},{"price":"0.51","size":"264.58"},{"price":"0.52","size":"100"},{"price":"0.53","size":"100"},{"price":"0.54","size":"100"},{"price":"0.55","size":"726.73"},{"price":"0.56","size":"147"},{"price":"0.57","size":"100"},{"price":"0.58","size":"188.58"},{"price":"0.59","size":"110"},{"price":"0.598","size":"13.07"},{"price":"0.6","size":"26789.54"},{"price":"0.601","size":"274.25"},{"price":"0.602","size":"406.1"},{"price":"0.623","size":"5"},{"price":"0.628","size":"1000"},{"price":"0.63","size":"3300"},{"price":"0.65","size":"15514.62"},{"price":"0.654","size":"124.73"},{"price":"0.656","size":"122.73"},{"price":"0.658","size":"6141.34"},{"price":"0.66","size":"1046.85"},{"price":"0.664","size":"10100"},{"price":"0.666","size":"474.07"},{"price":"0.671","size":"100"},{"price":"0.68","size":"3006"},{"price":"0.681","size":"2095.26"},{"price":"0.688","size":"1000"},{"price":"0.691","size":"2359.94"},{"price":"0.696","size":"100"},{"price":"0.7","size":"282.21"},{"price":"0.701","size":"400"},{"price":"0.717","size":"100"},{"price":"0.718","size":"1000"},{"price":"0.72","size":"11.42"},{"price":"0.726","size":"16.03"},{"price":"0.738","size":"1100"},{"price":"0.748","size":"1000"},{"price":"0.75","size":"3963.47"},{"price":"0.751","size":"30"},{"price":"0.758","size":"1100"},{"price":"0.759","size":"100"},{"price":"0.76","size":"195"},{"price":"0.764","size":"7"},{"price":"0.765","size":"150"},{"price":"0.767","size":"5"},{"price":"0.768","size":"1000"},{"price":"0.77","size":"3823.69"},{"price":"0.774","size":"362.18"},{"price":"0.78","size":"225"},{"price":"0.782","size":"13.78"},{"price":"0.783","size":"16.02"},{"price":"0.784","size":"50"},{"price":"0.79","size":"50"},{"price":"0.794","size":"25.37"},{"price":"0.795","size":"10"},{"price":"0.796","size":"25"},{"price":"0.798","size":"50"},{"price":"0.799","size":"382.17"},{"price":"0.8","size":"8356.84"},{"price":"0.802","size":"1019"},{"price":"0.803","size":"125"},{"price":"0.806","size":"181.36"},{"price":"0.807","size":"232.7"},{"price":"0.808","size":"30"},{"price":"0.809","size":"16007.3"},{"price":"0.812","size":"15279.71"},{"price":"0.814","size":"10"},{"price":"0.815","size":"405.96"},{"price":"0.816","size":"49.77"},{"price":"0.817","size":"50"},{"price":"0.818","size":"50.31"},{"price":"0.819","size":"1000"},{"price":"0.82","size":"12835.92"},{"price":"0.821","size":"41454.56"},{"price":"0.822","size":"930.5"},{"price":"0.823","size":"1627.85"},{"price":"0.824","size":"15407.48"},{"price":"0.825","size":"96558.27"},{"price":"0.826","size":"58022.86"},{"price":"0.827","size":"26925.87"},{"price":"0.828","size":"25913.26"},{"price":"0.829","size":"2301.97"},{"price":"0.83","size":"102064.74"},{"price":"0.831","size":"2054.06"},{"price":"0.832","size":"152433.89"}],"asks":[{"price":"0.999","size":"4816394"},{"price":"0.998","size":"2359"},{"price":"0.997","size":"100"},{"price":"0.996","size":"1111111"},{"price":"0.995","size":"255655"},{"price":"0.994","size":"100000"},{"price":"0.993","size":"10800"},{"price":"0.992","size":"10000"},{"price":"0.991","size":"10000"},{"price":"0.99","size":"10335"},{"price":"0.989","size":"10000"},{"price":"0.988","size":"10000"},{"price":"0.987","size":"5000"},{"price":"0.986","size":"5000"},{"price":"0.985","size":"5000"},{"price":"0.984","size":"5000"},{"price":"0.982","size":"5008.33"},{"price":"0.981","size":"5000"},{"price":"0.98","size":"7380"},{"price":"0.979","size":"3000"},{"price":"0.978","size":"3000"},{"price":"0.977","size":"3000"},{"price":"0.976","size":"3000"},{"price":"0.975","size":"3000"},{"price":"0.974","size":"3000"},{"price":"0.973","size":"3000"},{"price":"0.972","size":"3000"},{"price":"0.959","size":"731.7"},{"price":"0.951","size":"100"},{"price":"0.95","size":"56135"},{"price":"0.931","size":"20"},{"price":"0.93","size":"30"},{"price":"0.927","size":"30"},{"price":"0.926","size":"30"},{"price":"0.9","size":"10035"},{"price":"0.89","size":"91.09"},{"price":"0.889","size":"1077.83"},{"price":"0.88","size":"11038.99"},{"price":"0.879","size":"5"},{"price":"0.878","size":"93.8"},{"price":"0.877","size":"5"},{"price":"0.876","size":"5"},{"price":"0.875","size":"5"},{"price":"0.874","size":"5"},{"price":"0.873","size":"5"},{"price":"0.872","size":"5"},{"price":"0.871","size":"5"},{"price":"0.87","size":"165"},{"price":"0.869","size":"5"},{"price":"0.868","size":"105"},{"price":"0.867","size":"5"},{"price":"0.866","size":"156.01"},{"price":"0.865","size":"5"},{"price":"0.864","size":"5"},{"price":"0.863","size":"5"},{"price":"0.862","size":"5"},{"price":"0.861","size":"5"},{"price":"0.86","size":"2179.99"},{"price":"0.859","size":"6015"},{"price":"0.858","size":"5005"},{"price":"0.857","size":"2505"},{"price":"0.856","size":"15"},{"price":"0.855","size":"5"},{"price":"0.854","size":"6206.58"},{"price":"0.853","size":"3015"},{"price":"0.852","size":"7875"},{"price":"0.851","size":"3105"},{"price":"0.85","size":"47190"},{"price":"0.849","size":"26520"},{"price":"0.848","size":"4713.32"},{"price":"0.847","size":"18384.44"},{"price":"0.846","size":"7101.99"},{"price":"0.845","size":"2090"},{"price":"0.844","size":"3989.08"},{"price":"0.843","size":"30663.44"},{"price":"0.842","size":"7106.04"},{"price":"0.841","size":"538.42"},{"price":"0.84","size":"12647.71"},{"price":"0.839","size":"759"},{"price":"0.838","size":"2708.81"},{"price":"0.837","size":"3792.11"},{"price":"0.836","size":"29110.34"},{"price":"0.835","size":"26149.08"},{"price":"0.834","size":"4697.83"},{"price":"0.833","size":"64310.14"}],"tick_size":"0.001","event_type":"book","last_trade_price":"0.168"},{"market":"0x0c4cd2055d6ea89354ffddc55d6dbcef9355748112ea952fc925f3db6a5c457f","asset_id":"115428153746996892211798999366308897078723117634059783423375188043903703749062","timestamp":"1780150303041","hash":"11153c88ac9cc4f9d2b7b1e437b29815932d0746","bids":[{"price":"0.001","size":"19311591.2"},{"price":"0.002","size":"55.07"},{"price":"0.013","size":"1716.7"},{"price":"0.015","size":"1904.95"},{"price":"0.016","size":"11.03"},{"price":"0.036","size":"36000"},{"price":"0.04","size":"333350"},{"price":"0.041","size":"300000"},{"price":"0.042","size":"800"},{"price":"0.05","size":"14660"},{"price":"0.051","size":"10.53"},{"price":"0.09","size":"19"},{"price":"0.15","size":"127.23"},{"price":"0.22","size":"128.36"},{"price":"0.221","size":"5.26"},{"price":"0.228","size":"131.57"},{"price":"0.27","size":"1904.95"},{"price":"0.39","size":"5"},{"price":"0.4","size":"34375"},{"price":"0.401","size":"10000"},{"price":"0.402","size":"1492"},{"price":"0.45","size":"22.5"},{"price":"0.5","size":"26767.96"},{"price":"0.501","size":"3000"},{"price":"0.502","size":"1077.83"},{"price":"0.6","size":"21522.45"},{"price":"0.601","size":"2000"},{"price":"0.603","size":"1164"},{"price":"0.623","size":"5"},{"price":"0.64","size":"1211"},{"price":"0.65","size":"27012.52"},{"price":"0.66","size":"46.4"},{"price":"0.696","size":"5000"},{"price":"0.7","size":"557.74"},{"price":"0.701","size":"30"},{"price":"0.73","size":"6500"},{"price":"0.738","size":"1000"},{"price":"0.74","size":"100"},{"price":"0.75","size":"3383.18"},{"price":"0.752","size":"2906.99"},{"price":"0.767","size":"5"},{"price":"0.768","size":"1000"},{"price":"0.778","size":"100"},{"price":"0.779","size":"400"},{"price":"0.798","size":"1000"},{"price":"0.799","size":"100"},{"price":"0.8","size":"12081.05"},{"price":"0.801","size":"2095.26"},{"price":"0.81","size":"100"},{"price":"0.818","size":"1000"},{"price":"0.82","size":"183.62"},{"price":"0.828","size":"1000"},{"price":"0.83","size":"2373"},{"price":"0.838","size":"1268.53"},{"price":"0.84","size":"12150"},{"price":"0.841","size":"100"},{"price":"0.843","size":"100"},{"price":"0.845","size":"144"},{"price":"0.848","size":"1000"},{"price":"0.85","size":"4045.57"},{"price":"0.855","size":"11634.31"},{"price":"0.856","size":"7"},{"price":"0.86","size":"716"},{"price":"0.861","size":"144283.19"},{"price":"0.862","size":"100"},{"price":"0.867","size":"438"},{"price":"0.868","size":"50"},{"price":"0.87","size":"996"},{"price":"0.871","size":"209826.98"},{"price":"0.875","size":"1020.47"},{"price":"0.877","size":"25"},{"price":"0.878","size":"45"},{"price":"0.879","size":"94"},{"price":"0.88","size":"15096.64"},{"price":"0.882","size":"648.12"},{"price":"0.883","size":"125"},{"price":"0.884","size":"10789.73"},{"price":"0.886","size":"230.12"},{"price":"0.887","size":"1395.49"},{"price":"0.888","size":"236.32"},{"price":"0.889","size":"1186.28"},{"price":"0.89","size":"6421.54"},{"price":"0.891","size":"5069.15"},{"price":"0.892","size":"52728.52"},{"price":"0.894","size":"355.22"},{"price":"0.895","size":"5319.74"},{"price":"0.896","size":"52728.51"},{"price":"0.897","size":"114.3"},{"price":"0.898","size":"229.06"},{"price":"0.899","size":"27080.06"},{"price":"0.9","size":"35120.43"},{"price":"0.901","size":"34710.7"},{"price":"0.902","size":"84437.86"},{"price":"0.903","size":"1730.09"},{"price":"0.904","size":"1129.06"},{"price":"0.905","size":"2510"},{"price":"0.906","size":"229.06"},{"price":"0.907","size":"33247.87"},{"price":"0.908","size":"15415.06"},{"price":"0.909","size":"8064.56"},{"price":"0.91","size":"36872.79"},{"price":"0.911","size":"25024.11"},{"price":"0.912","size":"15129.46"},{"price":"0.913","size":"59775.19"},{"price":"0.914","size":"171104.43"}],"asks":[{"price":"0.999","size":"4912713.42"},{"price":"0.998","size":"1003359"},{"price":"0.997","size":"1111111"},{"price":"0.996","size":"55555"},{"price":"0.995","size":"500"},{"price":"0.994","size":"6000"},{"price":"0.99","size":"11200"},{"price":"0.985","size":"5.65"},{"price":"0.984","size":"5000000"},{"price":"0.983","size":"800"},{"price":"0.98","size":"5050"},{"price":"0.979","size":"2300"},{"price":"0.97","size":"4330"},{"price":"0.969","size":"367.48"},{"price":"0.959","size":"720"},{"price":"0.958","size":"725.45"},{"price":"0.952","size":"70"},{"price":"0.951","size":"71"},{"price":"0.95","size":"5879.09"},{"price":"0.93","size":"513068.11"},{"price":"0.929","size":"6800"},{"price":"0.928","size":"437"},{"price":"0.927","size":"333"},{"price":"0.925","size":"1245"},{"price":"0.924","size":"5000"},{"price":"0.922","size":"11231.85"},{"price":"0.921","size":"127"},{"price":"0.92","size":"44813"},{"price":"0.919","size":"39326.98"},{"price":"0.918","size":"47132.51"},{"price":"0.917","size":"184952.96"},{"price":"0.916","size":"13437.85"},{"price":"0.915","size":"109152.01"}],"tick_size":"0.001","event_type":"book","last_trade_price":"0.086"},{"market":"0x7876851632c295043c66536150a304cb785abdf712ba8489d298c6e6926be106","asset_id":"19291692040378529618917910599727571242305935029274321291612270922648172794670","timestamp":"1780150296518","hash":"d91ff1db3c4eb5235fc0df8ba6d7d57ce141e84e","bids":[{"price":"0.001","size":"21002524.32"},{"price":"0.002","size":"90011.18"},{"price":"0.003","size":"800"},{"price":"0.004","size":"70.1"},{"price":"0.031","size":"500"},{"price":"0.05","size":"40"},{"price":"0.051","size":"9.59"},{"price":"0.1","size":"2500"},{"price":"0.2","size":"1000"},{"price":"0.201","size":"5.94"},{"price":"0.247","size":"121.45"},{"price":"0.3","size":"600"},{"price":"0.4","size":"34625"},{"price":"0.401","size":"18000"},{"price":"0.45","size":"100"},{"price":"0.451","size":"1330"},{"price":"0.5","size":"25000"},{"price":"0.501","size":"12000"},{"price":"0.51","size":"7.97"},{"price":"0.6","size":"20833.33"},{"price":"0.65","size":"15384.62"},{"price":"0.652","size":"2095.26"},{"price":"0.653","size":"1103"},{"price":"0.75","size":"100"},{"price":"0.778","size":"227.27"},{"price":"0.808","size":"8"},{"price":"0.841","size":"1000"},{"price":"0.85","size":"445.83"},{"price":"0.851","size":"400"},{"price":"0.871","size":"1000"},{"price":"0.891","size":"1000"},{"price":"0.9","size":"90.9"},{"price":"0.901","size":"1000"},{"price":"0.902","size":"30"},{"price":"0.904","size":"8"},{"price":"0.911","size":"1100"},{"price":"0.92","size":"1000"},{"price":"0.921","size":"1000"},{"price":"0.93","size":"3800"},{"price":"0.935","size":"3500"},{"price":"0.938","size":"3500"},{"price":"0.94","size":"2000"},{"price":"0.941","size":"50"},{"price":"0.943","size":"3000"},{"price":"0.944","size":"2000"},{"price":"0.95","size":"3309.92"},{"price":"0.951","size":"2045"},{"price":"0.952","size":"3833.33"},{"price":"0.953","size":"75"},{"price":"0.954","size":"19"},{"price":"0.955","size":"3067"},{"price":"0.956","size":"250"},{"price":"0.957","size":"3000"},{"price":"0.958","size":"3000"},{"price":"0.96","size":"232.7"},{"price":"0.961","size":"3007.2"},{"price":"0.964","size":"5000"},{"price":"0.965","size":"15430.62"},{"price":"0.967","size":"10424"},{"price":"0.968","size":"4287.08"},{"price":"0.97","size":"18916.9"},{"price":"0.971","size":"3000"},{"price":"0.972","size":"14648"},{"price":"0.974","size":"5000"},{"price":"0.975","size":"10372.72"},{"price":"0.976","size":"5500"},{"price":"0.978","size":"17239.4"},{"price":"0.979","size":"6000"},{"price":"0.98","size":"14721.53"},{"price":"0.981","size":"2790.7"},{"price":"0.982","size":"62681.81"},{"price":"0.983","size":"110028.15"},{"price":"0.984","size":"118582.98"},{"price":"0.985","size":"107389"},{"price":"0.986","size":"10"},{"price":"0.987","size":"8338.33"},{"price":"0.988","size":"4839211.94"},{"price":"0.989","size":"1799038.22"}],"asks":[{"price":"0.999","size":"3862270"},{"price":"0.998","size":"1322096"},{"price":"0.997","size":"451830"},{"price":"0.996","size":"72622"},{"price":"0.995","size":"30650"},{"price":"0.994","size":"11473.99"},{"price":"0.993","size":"31428.57"},{"price":"0.992","size":"328294"},{"price":"0.991","size":"247324.61"},{"price":"0.99","size":"1180706.14"}],"tick_size":"0.001","event_type":"book","last_trade_price":"0.011"},{"market":"0x4f3421fb2daf5cca7430ed8d8132463963081572d75434393a1808fdb8829fe8","asset_id":"31940783580344558651011323787577288681658737625185216525249046282994042503801","timestamp":"1780150299201","hash":"95af88b615244d3f96738f61e61116e7163ef350","bids":[{"price":"0.001","size":"21074238.91"},{"price":"0.002","size":"37.76"},{"price":"0.01","size":"25779.6"},{"price":"0.011","size":"6.21"},{"price":"0.014","size":"1111111"},{"price":"0.015","size":"1000000"},{"price":"0.02","size":"36500"},{"price":"0.021","size":"800"},{"price":"0.022","size":"11.19"},{"price":"0.05","size":"40"},{"price":"0.077","size":"2000"},{"price":"0.078","size":"5.64"},{"price":"0.1","size":"2229.88"},{"price":"0.11","size":"1016"},{"price":"0.12","size":"1021"},{"price":"0.13","size":"1000"},{"price":"0.14","size":"999.99"},{"price":"0.15","size":"1153.71"},{"price":"0.2","size":"409.2"},{"price":"0.224","size":"433.92"},{"price":"0.225","size":"5.14"},{"price":"0.25","size":"453.7"},{"price":"0.253","size":"200"},{"price":"0.254","size":"200"},{"price":"0.27","size":"200"},{"price":"0.28","size":"200"},{"price":"0.31","size":"200"},{"price":"0.33","size":"215.15"},{"price":"0.34","size":"199.99"},{"price":"0.35","size":"102.46"},{"price":"0.36","size":"228"},{"price":"0.361","size":"100"},{"price":"0.4","size":"34637.29"},{"price":"0.401","size":"5000"},{"price":"0.41","size":"200"},{"price":"0.42","size":"200"},{"price":"0.43","size":"200"},{"price":"0.44","size":"200"},{"price":"0.45","size":"354.02"},{"price":"0.46","size":"200"},{"price":"0.461","size":"1077.83"},{"price":"0.5","size":"25496.62"},{"price":"0.501","size":"5100"},{"price":"0.51","size":"205.76"},{"price":"0.511","size":"100"},{"price":"0.52","size":"100"},{"price":"0.53","size":"100"},{"price":"0.54","size":"100"},{"price":"0.55","size":"100"},{"price":"0.56","size":"100"},{"price":"0.57","size":"100"},{"price":"0.58","size":"100"},{"price":"0.6","size":"21059.73"},{"price":"0.61","size":"100"},{"price":"0.62","size":"111.9"},{"price":"0.632","size":"5322.31"},{"price":"0.64","size":"28.8"},{"price":"0.643","size":"100"},{"price":"0.65","size":"16970.62"},{"price":"0.66","size":"100"},{"price":"0.67","size":"100"},{"price":"0.673","size":"100"},{"price":"0.674","size":"100"},{"price":"0.678","size":"100"},{"price":"0.68","size":"410.68"},{"price":"0.69","size":"100"},{"price":"0.7","size":"422.3"},{"price":"0.703","size":"100"},{"price":"0.704","size":"100"},{"price":"0.708","size":"100"},{"price":"0.71","size":"61.7"},{"price":"0.725","size":"1000"},{"price":"0.733","size":"100"},{"price":"0.75","size":"3192.15"},{"price":"0.755","size":"1000"},{"price":"0.76","size":"341.8"},{"price":"0.763","size":"100"},{"price":"0.764","size":"100"},{"price":"0.767","size":"100"},{"price":"0.768","size":"400"},{"price":"0.777","size":"100"},{"price":"0.78","size":"258.06"},{"price":"0.781","size":"100"},{"price":"0.785","size":"1000"},{"price":"0.79","size":"47.6"},{"price":"0.798","size":"1781.45"},{"price":"0.8","size":"246868.85"},{"price":"0.801","size":"100"},{"price":"0.803","size":"100"},{"price":"0.805","size":"1000"},{"price":"0.815","size":"1000"},{"price":"0.816","size":"100"},{"price":"0.818","size":"30"},{"price":"0.824","size":"100"},{"price":"0.825","size":"1000"},{"price":"0.83","size":"39.23"},{"price":"0.835","size":"1000"},{"price":"0.84","size":"356.45"},{"price":"0.845","size":"100"},{"price":"0.849","size":"2441.52"},{"price":"0.85","size":"19727.35"},{"price":"0.851","size":"800"},{"price":"0.853","size":"118.33"},{"price":"0.855","size":"13.33"},{"price":"0.858","size":"35.21"},{"price":"0.86","size":"34.6"},{"price":"0.861","size":"170"},{"price":"0.866","size":"75"},{"price":"0.867","size":"17.97"},{"price":"0.868","size":"144"},{"price":"0.87","size":"4000"},{"price":"0.872","size":"232.7"},{"price":"0.873","size":"7.26"},{"price":"0.875","size":"170"},{"price":"0.88","size":"197"},{"price":"0.882","size":"1000"},{"price":"0.885","size":"925.73"},{"price":"0.886","size":"100"},{"price":"0.887","size":"100"},{"price":"0.888","size":"100"},{"price":"0.889","size":"100"},{"price":"0.89","size":"16564.23"},{"price":"0.891","size":"1343.33"},{"price":"0.892","size":"7071.71"},{"price":"0.893","size":"15257.35"},{"price":"0.894","size":"120752.78"},{"price":"0.896","size":"28940.81"},{"price":"0.897","size":"18183.31"},{"price":"0.898","size":"126782.5"},{"price":"0.899","size":"98264.59"}],"asks":[{"price":"0.999","size":"4715397.01"},{"price":"0.998","size":"14"},{"price":"0.997","size":"1112792"},{"price":"0.996","size":"55564"},{"price":"0.995","size":"10009"},{"price":"0.994","size":"11109"},{"price":"0.993","size":"10009"},{"price":"0.992","size":"10009"},{"price":"0.991","size":"5009"},{"price":"0.99","size":"6209"},{"price":"0.989","size":"5009"},{"price":"0.988","size":"5009"},{"price":"0.987","size":"4309"},{"price":"0.986","size":"3009"},{"price":"0.985","size":"5009"},{"price":"0.984","size":"3009"},{"price":"0.983","size":"3009"},{"price":"0.982","size":"9"},{"price":"0.981","size":"5009"},{"price":"0.98","size":"6234"},{"price":"0.979","size":"4008.99"},{"price":"0.978","size":"4009"},{"price":"0.977","size":"4009"},{"price":"0.976","size":"3009"},{"price":"0.975","size":"3009"},{"price":"0.974","size":"4009"},{"price":"0.973","size":"3009"},{"price":"0.972","size":"4009"},{"price":"0.971","size":"2009"},{"price":"0.97","size":"4209"},{"price":"0.969","size":"2509"},{"price":"0.968","size":"2652.85"},{"price":"0.967","size":"2509"},{"price":"0.966","size":"2509"},{"price":"0.965","size":"9"},{"price":"0.964","size":"9"},{"price":"0.963","size":"9"},{"price":"0.962","size":"609"},{"price":"0.961","size":"9"},{"price":"0.96","size":"259"},{"price":"0.959","size":"9"},{"price":"0.958","size":"9"},{"price":"0.957","size":"9"},{"price":"0.956","size":"9"},{"price":"0.955","size":"9"},{"price":"0.954","size":"9"},{"price":"0.953","size":"9"},{"price":"0.952","size":"9"},{"price":"0.951","size":"9"},{"price":"0.95","size":"279"},{"price":"0.949","size":"10009"},{"price":"0.948","size":"9"},{"price":"0.947","size":"9"},{"price":"0.946","size":"9"},{"price":"0.945","size":"309"},{"price":"0.944","size":"9"},{"price":"0.943","size":"9"},{"price":"0.942","size":"9"},{"price":"0.941","size":"9"},{"price":"0.94","size":"19"},{"price":"0.939","size":"202"},{"price":"0.938","size":"10009"},{"price":"0.937","size":"5009"},{"price":"0.936","size":"7509"},{"price":"0.935","size":"5151"},{"price":"0.934","size":"6209"},{"price":"0.933","size":"4529"},{"price":"0.932","size":"2856.05"},{"price":"0.931","size":"2772.73"},{"price":"0.93","size":"13367.54"},{"price":"0.929","size":"1564"},{"price":"0.928","size":"5464.3"},{"price":"0.927","size":"1109"},{"price":"0.926","size":"357402.07"},{"price":"0.925","size":"36562.67"},{"price":"0.924","size":"5803.29"},{"price":"0.923","size":"434.15"},{"price":"0.922","size":"512.12"},{"price":"0.921","size":"25029"},{"price":"0.92","size":"15376.09"},{"price":"0.919","size":"1633.99"},{"price":"0.918","size":"14672.52"},{"price":"0.917","size":"3381.41"},{"price":"0.916","size":"9"},{"price":"0.915","size":"826.33"},{"price":"0.914","size":"22609"},{"price":"0.913","size":"4605.61"},{"price":"0.912","size":"1782.17"},{"price":"0.911","size":"570.79"},{"price":"0.91","size":"5344.55"},{"price":"0.909","size":"958.45"},{"price":"0.908","size":"909"},{"price":"0.907","size":"1609"},{"price":"0.906","size":"2240.91"},{"price":"0.905","size":"3928.99"},{"price":"0.904","size":"2009"},{"price":"0.903","size":"7534.46"},{"price":"0.902","size":"1468"},{"price":"0.901","size":"922.07"},{"price":"0.9","size":"139031.33"}],"tick_size":"0.001","event_type":"book","last_trade_price":"0.101"},{"market":"0x9b6fef249040fd17e9c107955b37ac2c3e923509b6b0ff01cc463a331ddeb894","asset_id":"32270411694523539495262303868629477861017829722282576458031815333486368239544","timestamp":"1780150300268","hash":"2565600f075c7b713a20880bc9098e3fdcbbf884","bids":[{"price":"0.001","size":"12219098.99"},{"price":"0.002","size":"178.57"},{"price":"0.003","size":"21.08"},{"price":"0.009","size":"18000"},{"price":"0.01","size":"100"},{"price":"0.011","size":"5.62"},{"price":"0.012","size":"1111111"},{"price":"0.013","size":"900000"},{"price":"0.014","size":"1300"},{"price":"0.015","size":"500"},{"price":"0.02","size":"99"},{"price":"0.021","size":"6.95"},{"price":"0.05","size":"246.52"},{"price":"0.051","size":"10.84"},{"price":"0.09","size":"5.98"},{"price":"0.1","size":"15"},{"price":"0.12","size":"5005"},{"price":"0.121","size":"12000"},{"price":"0.15","size":"67.49"},{"price":"0.178","size":"289.7"},{"price":"0.2","size":"796.33"},{"price":"0.209","size":"143.54"},{"price":"0.22","size":"100.48"},{"price":"0.221","size":"5.22"},{"price":"0.25","size":"3597"},{"price":"0.251","size":"6000"},{"price":"0.29","size":"9.75"},{"price":"0.3","size":"55.88"},{"price":"0.315","size":"1459.85"},{"price":"0.33","size":"1363.34"},{"price":"0.331","size":"3000"},{"price":"0.34","size":"5"},{"price":"0.35","size":"2159.92"},{"price":"0.4","size":"34587.44"},{"price":"0.401","size":"3000"},{"price":"0.47","size":"5688.73"},{"price":"0.5","size":"36499.86"},{"price":"0.502","size":"1529.99"},{"price":"0.503","size":"14000"},{"price":"0.51","size":"90.9"},{"price":"0.511","size":"1202.04"},{"price":"0.55","size":"513.44"},{"price":"0.56","size":"111.11"},{"price":"0.562","size":"655.13"},{"price":"0.563","size":"65.06"},{"price":"0.57","size":"3964.15"},{"price":"0.6","size":"22272.15"},{"price":"0.624","size":"27.04"},{"price":"0.631","size":"1000"},{"price":"0.636","size":"105.03"},{"price":"0.638","size":"23.57"},{"price":"0.64","size":"4479.3"},{"price":"0.648","size":"7.39"},{"price":"0.65","size":"15415.61"},{"price":"0.651","size":"2155.26"},{"price":"0.661","size":"1000"},{"price":"0.67","size":"18.11"},{"price":"0.672","size":"482.66"},{"price":"0.68","size":"38"},{"price":"0.691","size":"1000"},{"price":"0.699","size":"100"},{"price":"0.7","size":"456.89"},{"price":"0.701","size":"400"},{"price":"0.72","size":"267.14"},{"price":"0.721","size":"1000"},{"price":"0.741","size":"1100"},{"price":"0.75","size":"1422.54"},{"price":"0.751","size":"1201"},{"price":"0.752","size":"1367"},{"price":"0.754","size":"334.02"},{"price":"0.756","size":"30"},{"price":"0.76","size":"302"},{"price":"0.761","size":"1000"},{"price":"0.762","size":"200"},{"price":"0.77","size":"3800"},{"price":"0.771","size":"1000"},{"price":"0.777","size":"11.23"},{"price":"0.779","size":"334.02"},{"price":"0.78","size":"237"},{"price":"0.783","size":"100"},{"price":"0.786","size":"15"},{"price":"0.788","size":"10"},{"price":"0.789","size":"5555.55"},{"price":"0.79","size":"122"},{"price":"0.791","size":"50"},{"price":"0.793","size":"10"},{"price":"0.794","size":"1000"},{"price":"0.795","size":"10"},{"price":"0.8","size":"17681.66"},{"price":"0.801","size":"100"},{"price":"0.802","size":"64"},{"price":"0.803","size":"35"},{"price":"0.804","size":"75"},{"price":"0.805","size":"500"},{"price":"0.806","size":"294"},{"price":"0.807","size":"135"},{"price":"0.808","size":"675.7"},{"price":"0.809","size":"2027"},{"price":"0.81","size":"7109.61"},{"price":"0.811","size":"38219.61"},{"price":"0.812","size":"1708.3"},{"price":"0.813","size":"782.67"},{"price":"0.814","size":"1703.37"},{"price":"0.815","size":"5571.35"},{"price":"0.816","size":"10909.83"},{"price":"0.817","size":"7549.45"},{"price":"0.818","size":"3441.57"},{"price":"0.819","size":"340"},{"price":"0.82","size":"5287.95"},{"price":"0.821","size":"1694.21"},{"price":"0.822","size":"22719.93"},{"price":"0.823","size":"44358.4"},{"price":"0.824","size":"47073"},{"price":"0.825","size":"47040.85"},{"price":"0.826","size":"200"},{"price":"0.827","size":"654.36"},{"price":"0.829","size":"20206.62"},{"price":"0.83","size":"26050"},{"price":"0.831","size":"3000"},{"price":"0.833","size":"3864.75"},{"price":"0.834","size":"32172"},{"price":"0.835","size":"246275.86"},{"price":"0.836","size":"35591.88"}],"asks":[{"price":"0.999","size":"2260279"},{"price":"0.998","size":"1557248"},{"price":"0.997","size":"1001200"},{"price":"0.996","size":"55555"},{"price":"0.995","size":"90100"},{"price":"0.99","size":"720"},{"price":"0.985","size":"5.01"},{"price":"0.984","size":"555555"},{"price":"0.983","size":"60000"},{"price":"0.982","size":"105435.9"},{"price":"0.981","size":"800"},{"price":"0.98","size":"5430"},{"price":"0.978","size":"3000"},{"price":"0.976","size":"3000"},{"price":"0.974","size":"3000"},{"price":"0.972","size":"3000"},{"price":"0.97","size":"3000"},{"price":"0.968","size":"3000"},{"price":"0.966","size":"3000"},{"price":"0.96","size":"750"},{"price":"0.951","size":"100"},{"price":"0.95","size":"150"},{"price":"0.94","size":"10"},{"price":"0.937","size":"30"},{"price":"0.936","size":"30"},{"price":"0.935","size":"10"},{"price":"0.934","size":"50"},{"price":"0.931","size":"10"},{"price":"0.93","size":"50"},{"price":"0.926","size":"50"},{"price":"0.925","size":"35"},{"price":"0.924","size":"30"},{"price":"0.923","size":"20"},{"price":"0.922","size":"20"},{"price":"0.921","size":"20"},{"price":"0.92","size":"140"},{"price":"0.91","size":"10100"},{"price":"0.905","size":"105.2"},{"price":"0.9","size":"10096.92"},{"price":"0.899","size":"1076.68"},{"price":"0.893","size":"37.72"},{"price":"0.892","size":"40"},{"price":"0.89","size":"145.45"},{"price":"0.889","size":"5000"},{"price":"0.885","size":"9"},{"price":"0.884","size":"90"},{"price":"0.88","size":"203.33"},{"price":"0.879","size":"7500"},{"price":"0.878","size":"5000"},{"price":"0.877","size":"100"},{"price":"0.875","size":"956.59"},{"price":"0.874","size":"2500"},{"price":"0.87","size":"328"},{"price":"0.869","size":"2537"},{"price":"0.868","size":"17"},{"price":"0.867","size":"1903.93"},{"price":"0.866","size":"27"},{"price":"0.865","size":"37"},{"price":"0.864","size":"5017"},{"price":"0.863","size":"3218"},{"price":"0.862","size":"7"},{"price":"0.861","size":"7"},{"price":"0.86","size":"717"},{"price":"0.859","size":"7"},{"price":"0.858","size":"507"},{"price":"0.857","size":"97"},{"price":"0.856","size":"7"},{"price":"0.855","size":"707"},{"price":"0.854","size":"7"},{"price":"0.853","size":"16722"},{"price":"0.852","size":"7"},{"price":"0.851","size":"707"},{"price":"0.85","size":"10136.66"},{"price":"0.849","size":"877"},{"price":"0.848","size":"107"},{"price":"0.847","size":"27"},{"price":"0.846","size":"257"},{"price":"0.845","size":"3060.64"},{"price":"0.844","size":"20417"},{"price":"0.843","size":"8647.14"},{"price":"0.842","size":"77"},{"price":"0.841","size":"1056.6"},{"price":"0.84","size":"18638"},{"price":"0.839","size":"39045"},{"price":"0.838","size":"7722.83"},{"price":"0.837","size":"28495.52"}],"tick_size":"0.001","event_type":"book","last_trade_price":"0.164"},{"market":"0x1595b4818eeb1ea1e0bec5de6f057218e557feee9b405a0e930d290384fa1d16","asset_id":"45484070731786948288366703334552551439356529561722304542938873238430842810537","timestamp":"1780150303041","hash":"c4516d71b0d68b696367519b6f93a50365e74d5c","bids":[{"price":"0.001","size":"21202713.62"},{"price":"0.002","size":"105"},{"price":"0.003","size":"32.43"},{"price":"0.01","size":"181.81"},{"price":"0.013","size":"1698.4"},{"price":"0.014","size":"17.32"},{"price":"0.05","size":"2236"},{"price":"0.054","size":"155555"},{"price":"0.055","size":"150000"},{"price":"0.056","size":"800"},{"price":"0.057","size":"5.16"},{"price":"0.1","size":"2500"},{"price":"0.14","size":"27"},{"price":"0.2","size":"1000"},{"price":"0.201","size":"6.67"},{"price":"0.237","size":"126.58"},{"price":"0.3","size":"600"},{"price":"0.348","size":"211.53"},{"price":"0.39","size":"5"},{"price":"0.4","size":"34625"},{"price":"0.401","size":"10000"},{"price":"0.402","size":"1492"},{"price":"0.5","size":"25100"},{"price":"0.501","size":"5000"},{"price":"0.51","size":"87.55"},{"price":"0.511","size":"1103"},{"price":"0.58","size":"17.54"},{"price":"0.584","size":"300"},{"price":"0.6","size":"20859.33"},{"price":"0.61","size":"76.92"},{"price":"0.623","size":"5"},{"price":"0.65","size":"15443.05"},{"price":"0.651","size":"2095.26"},{"price":"0.7","size":"780"},{"price":"0.701","size":"437"},{"price":"0.712","size":"50"},{"price":"0.72","size":"18"},{"price":"0.74","size":"476.92"},{"price":"0.75","size":"2198.07"},{"price":"0.751","size":"400"},{"price":"0.767","size":"5"},{"price":"0.77","size":"43.3"},{"price":"0.78","size":"192.53"},{"price":"0.792","size":"1100"},{"price":"0.8","size":"1307.15"},{"price":"0.801","size":"1500"},{"price":"0.82","size":"12201.05"},{"price":"0.821","size":"400"},{"price":"0.83","size":"1079.99"},{"price":"0.831","size":"1000"},{"price":"0.832","size":"50"},{"price":"0.838","size":"1913.7"},{"price":"0.84","size":"288"},{"price":"0.848","size":"33"},{"price":"0.85","size":"13781.98"},{"price":"0.851","size":"1000"},{"price":"0.855","size":"327.86"},{"price":"0.856","size":"7"},{"price":"0.86","size":"334.14"},{"price":"0.861","size":"1000"},{"price":"0.862","size":"30"},{"price":"0.869","size":"20"},{"price":"0.87","size":"1713.81"},{"price":"0.871","size":"1100"},{"price":"0.878","size":"163.93"},{"price":"0.88","size":"613.23"},{"price":"0.881","size":"1000"},{"price":"0.885","size":"240"},{"price":"0.887","size":"370.37"},{"price":"0.89","size":"5031.81"},{"price":"0.896","size":"1592.3"},{"price":"0.899","size":"100"},{"price":"0.9","size":"23802.24"},{"price":"0.901","size":"100"},{"price":"0.902","size":"7772.33"},{"price":"0.904","size":"500"},{"price":"0.905","size":"5307.69"},{"price":"0.91","size":"11147.07"},{"price":"0.911","size":"956.3"},{"price":"0.912","size":"75"},{"price":"0.913","size":"500"},{"price":"0.915","size":"173.07"},{"price":"0.916","size":"19"},{"price":"0.917","size":"125"},{"price":"0.918","size":"500"},{"price":"0.919","size":"532.55"},{"price":"0.92","size":"1979.21"},{"price":"0.924","size":"5917.15"},{"price":"0.925","size":"6585.96"},{"price":"0.926","size":"3944.76"},{"price":"0.927","size":"5259.68"},{"price":"0.928","size":"7012.91"},{"price":"0.929","size":"42450.48"},{"price":"0.93","size":"32653.14"},{"price":"0.931","size":"10000"},{"price":"0.932","size":"5905.04"},{"price":"0.933","size":"382.3"},{"price":"0.934","size":"6055.04"},{"price":"0.935","size":"22294.08"},{"price":"0.939","size":"950"},{"price":"0.94","size":"2357.57"},{"price":"0.941","size":"250009.76"},{"price":"0.942","size":"11012.52"},{"price":"0.943","size":"1999.94"},{"price":"0.944","size":"16846.47"},{"price":"0.945","size":"3838.22"},{"price":"0.946","size":"9385.11"},{"price":"0.947","size":"4752.36"},{"price":"0.948","size":"407731.61"}],"asks":[{"price":"0.999","size":"2259057"},{"price":"0.998","size":"1000005"},{"price":"0.997","size":"2224894"},{"price":"0.996","size":"56355"},{"price":"0.994","size":"300"},{"price":"0.993","size":"100"},{"price":"0.99","size":"2517.95"},{"price":"0.988","size":"100000"},{"price":"0.981","size":"200"},{"price":"0.98","size":"905"},{"price":"0.972","size":"100000"},{"price":"0.97","size":"1030"},{"price":"0.967","size":"30"},{"price":"0.966","size":"5000"},{"price":"0.965","size":"999.99"},{"price":"0.964","size":"2500"},{"price":"0.961","size":"1500"},{"price":"0.96","size":"8909.44"},{"price":"0.959","size":"1510"},{"price":"0.958","size":"4305"},{"price":"0.957","size":"4718"},{"price":"0.956","size":"1500"},{"price":"0.955","size":"2500"},{"price":"0.954","size":"2720"},{"price":"0.953","size":"2220"},{"price":"0.952","size":"29238.33"},{"price":"0.951","size":"39881.55"},{"price":"0.95","size":"91974.74"},{"price":"0.949","size":"588599.29"}],"tick_size":"0.001","event_type":"book","last_trade_price":"0.052"},{"market":"0x30d55d8124ee1e12dabe89201badc45669b81dff69e4ce44d961f32878ec178a","asset_id":"52986718774908357330412653486471347449818893503063830313445318937088822580057","timestamp":"1780150299198","hash":"b3b75ec748b296db5b4abe55cff4fc4eaa9b7375","bids":[{"price":"0.001","size":"21109405.6"},{"price":"0.002","size":"23.15"},{"price":"0.004","size":"2222222"},{"price":"0.005","size":"2000000"},{"price":"0.006","size":"800"},{"price":"0.007","size":"9.04"},{"price":"0.01","size":"102.2"},{"price":"0.013","size":"1716.8"},{"price":"0.015","size":"750"},{"price":"0.016","size":"11.01"},{"price":"0.05","size":"40"},{"price":"0.051","size":"10.88"},{"price":"0.09","size":"5"},{"price":"0.1","size":"2500"},{"price":"0.13","size":"22.93"},{"price":"0.2","size":"1000"},{"price":"0.227","size":"132.15"},{"price":"0.228","size":"5.03"},{"price":"0.27","size":"750"},{"price":"0.3","size":"605"},{"price":"0.39","size":"5"},{"price":"0.4","size":"34625"},{"price":"0.401","size":"10000"},{"price":"0.402","size":"1492"},{"price":"0.442","size":"6.78"},{"price":"0.45","size":"21"},{"price":"0.451","size":"21"},{"price":"0.5","size":"25662.35"},{"price":"0.502","size":"2000"},{"price":"0.503","size":"3100"},{"price":"0.51","size":"100"},{"price":"0.52","size":"100"},{"price":"0.53","size":"100"},{"price":"0.54","size":"100"},{"price":"0.55","size":"200"},{"price":"0.56","size":"100"},{"price":"0.6","size":"20920.53"},{"price":"0.601","size":"3100"},{"price":"0.623","size":"105"},{"price":"0.637","size":"100"},{"price":"0.64","size":"1263"},{"price":"0.65","size":"15539.21"},{"price":"0.667","size":"100"},{"price":"0.67","size":"50"},{"price":"0.7","size":"503.29"},{"price":"0.733","size":"1000"},{"price":"0.75","size":"1265.57"},{"price":"0.751","size":"280"},{"price":"0.752","size":"2095.26"},{"price":"0.76","size":"117.48"},{"price":"0.763","size":"1000"},{"price":"0.767","size":"5"},{"price":"0.771","size":"100"},{"price":"0.78","size":"355"},{"price":"0.781","size":"400"},{"price":"0.79","size":"31.9"},{"price":"0.792","size":"100"},{"price":"0.793","size":"1000"},{"price":"0.8","size":"1500.76"},{"price":"0.81","size":"330.25"},{"price":"0.813","size":"1100"},{"price":"0.818","size":"862.62"},{"price":"0.82","size":"217.47"},{"price":"0.823","size":"1000"},{"price":"0.825","size":"600"},{"price":"0.827","size":"30"},{"price":"0.83","size":"471.36"},{"price":"0.833","size":"1100"},{"price":"0.834","size":"100"},{"price":"0.84","size":"68"},{"price":"0.843","size":"1000"},{"price":"0.846","size":"5.31"},{"price":"0.85","size":"4497.11"},{"price":"0.855","size":"263.04"},{"price":"0.856","size":"18.23"},{"price":"0.858","size":"12.56"},{"price":"0.86","size":"2499.34"},{"price":"0.861","size":"50"},{"price":"0.862","size":"125"},{"price":"0.868","size":"2500"},{"price":"0.87","size":"186.7"},{"price":"0.871","size":"437.5"},{"price":"0.872","size":"2500"},{"price":"0.873","size":"45"},{"price":"0.874","size":"75"},{"price":"0.875","size":"619"},{"price":"0.876","size":"6425"},{"price":"0.877","size":"5000"},{"price":"0.88","size":"88.12"},{"price":"0.882","size":"15265.93"},{"price":"0.883","size":"200"},{"price":"0.887","size":"437.5"},{"price":"0.888","size":"106.38"},{"price":"0.89","size":"30299.11"},{"price":"0.891","size":"23245"},{"price":"0.893","size":"4000"},{"price":"0.894","size":"4217.77"},{"price":"0.895","size":"10273.48"},{"price":"0.897","size":"62499.24"},{"price":"0.898","size":"56"},{"price":"0.9","size":"9398.5"},{"price":"0.901","size":"44793.63"},{"price":"0.902","size":"62749.23"},{"price":"0.903","size":"25213.57"},{"price":"0.904","size":"764967.01"},{"price":"0.905","size":"37498.61"},{"price":"0.906","size":"46794.57"},{"price":"0.907","size":"87424.83"},{"price":"0.908","size":"77337.54"},{"price":"0.909","size":"83049.2"}],"asks":[{"price":"0.999","size":"4833617.88"},{"price":"0.998","size":"1000671"},{"price":"0.997","size":"672"},{"price":"0.996","size":"501000"},{"price":"0.995","size":"30100"},{"price":"0.994","size":"1182511"},{"price":"0.993","size":"66355"},{"price":"0.992","size":"10000"},{"price":"0.991","size":"10000"},{"price":"0.99","size":"11815"},{"price":"0.989","size":"5000"},{"price":"0.988","size":"5000"},{"price":"0.987","size":"5000"},{"price":"0.986","size":"5000"},{"price":"0.985","size":"5000"},{"price":"0.984","size":"5000"},{"price":"0.983","size":"5000"},{"price":"0.982","size":"5000"},{"price":"0.981","size":"5000"},{"price":"0.98","size":"5375"},{"price":"0.979","size":"3999.99"},{"price":"0.978","size":"3000"},{"price":"0.977","size":"3000"},{"price":"0.976","size":"3000"},{"price":"0.975","size":"3000"},{"price":"0.974","size":"3000"},{"price":"0.973","size":"3000"},{"price":"0.972","size":"3000"},{"price":"0.97","size":"3800"},{"price":"0.966","size":"134.32"},{"price":"0.965","size":"45.64"},{"price":"0.96","size":"300"},{"price":"0.959","size":"300"},{"price":"0.957","size":"50"},{"price":"0.956","size":"134.85"},{"price":"0.955","size":"763.02"},{"price":"0.954","size":"237.14"},{"price":"0.953","size":"237.14"},{"price":"0.951","size":"10"},{"price":"0.95","size":"241"},{"price":"0.949","size":"6"},{"price":"0.948","size":"6"},{"price":"0.947","size":"6"},{"price":"0.946","size":"6"},{"price":"0.945","size":"6"},{"price":"0.944","size":"6"},{"price":"0.943","size":"6"},{"price":"0.942","size":"356.6"},{"price":"0.941","size":"6"},{"price":"0.94","size":"206"},{"price":"0.939","size":"6"},{"price":"0.938","size":"6"},{"price":"0.937","size":"6"},{"price":"0.936","size":"6"},{"price":"0.935","size":"6"},{"price":"0.934","size":"6"},{"price":"0.933","size":"6"},{"price":"0.932","size":"6"},{"price":"0.931","size":"6"},{"price":"0.93","size":"1238.01"},{"price":"0.929","size":"20006"},{"price":"0.928","size":"16"},{"price":"0.927","size":"6"},{"price":"0.926","size":"16006"},{"price":"0.925","size":"516"},{"price":"0.924","size":"38"},{"price":"0.923","size":"6"},{"price":"0.922","size":"6"},{"price":"0.921","size":"1386"},{"price":"0.92","size":"36680"},{"price":"0.919","size":"32011"},{"price":"0.918","size":"10413.85"},{"price":"0.917","size":"11106"},{"price":"0.916","size":"59297.99"},{"price":"0.915","size":"19118.35"},{"price":"0.914","size":"4477.13"},{"price":"0.913","size":"1903.84"},{"price":"0.912","size":"20654"},{"price":"0.911","size":"169555.05"},{"price":"0.91","size":"41517.84"}],"tick_size":"0.001","event_type":"book","last_trade_price":"0.909"}]

PONG
{"market":"0x7876851632c295043c66536150a304cb785abdf712ba8489d298c6e6926be106", "price_changes":[{"asset_id":"19291692040378529618917910599727571242305935029274321291612270922648172794670", "price":"0.956", "size":"125", "side":"BUY", "hash":"94b921abb512b164de41544072bf2e8cf4829292", "best_bid":"0.989", "best_ask":"0.99"}, {"asset_id":"97239126062673310243763617236644392945530356142765650402171508075574679292913", "price":"0.044", "size":"125", "side":"SELL", "hash":"bc533570cbfbe86f6b889606caa0db2e0a639894", "best_bid":"0.01", "best_ask":"0.011"}], "timestamp":"1780150304444", "event_type":"price_change"}
{"market":"0x375409bc5eeeff961e82b479caeccc20f33d15738e5bce1186d628aa3d9dfb1f", "price_changes":[{"asset_id":"115556263888245616435851357148058235707004733438163639091106356867234218207169", "price":"0.12", "size":"20849.13", "side":"SELL", "hash":"3cc77ac363de097e049a14e79db1f8cb3bc97828", "best_bid":"0.111", "best_ask":"0.112"}, {"asset_id":"77121637225348873006259930776623502125079210522997384841464684944292365296940", "price":"0.88", "size":"20849.13", "side":"BUY", "hash":"111123fcf1aa70f538d12e975a05f8984c51405b", "best_bid":"0.888", "best_ask":"0.889"}], "timestamp":"1780150304603", "event_type":"price_change"}
{"market":"0x375409bc5eeeff961e82b479caeccc20f33d15738e5bce1186d628aa3d9dfb1f", "price_changes":[{"asset_id":"115556263888245616435851357148058235707004733438163639091106356867234218207169", "price":"0.112", "size":"49878.31", "side":"SELL", "hash":"6670e7c6397103e6411ea82f5457c5f9212f43bb", "best_bid":"0.111", "best_ask":"0.112"}, {"asset_id":"77121637225348873006259930776623502125079210522997384841464684944292365296940", "price":"0.888", "size":"49878.31", "side":"BUY", "hash":"5cc906d6e985b0fb669befaf20b837251f2f6781", "best_bid":"0.888", "best_ask":"0.889"}], "timestamp":"1780150304809", "event_type":"price_change"}
{"market":"0x4f3421fb2daf5cca7430ed8d8132463963081572d75434393a1808fdb8829fe8", "price_changes":[{"asset_id":"45415751658241142530386585138386640503488308219341470020075667342738719018629", "price":"0.99", "size":"25929.6", "side":"SELL", "hash":"dc91d8c92736f8b7159801bc9e4c6e6f90556410", "best_bid":"0.1", "best_ask":"0.101"}, {"asset_id":"31940783580344558651011323787577288681658737625185216525249046282994042503801", "price":"0.01", "size":"25929.6", "side":"BUY", "hash":"b8976f73e4d18a54f81464084540045c48c83bab", "best_bid":"0.899", "best_ask":"0.9"}], "timestamp":"1780150305565", "event_type":"price_change"}
{"market":"0x4f3421fb2daf5cca7430ed8d8132463963081572d75434393a1808fdb8829fe8", "price_changes":[{"asset_id":"31940783580344558651011323787577288681658737625185216525249046282994042503801", "price":"0.816", "size":"0", "side":"BUY", "hash":"ab501c6352e9ee2a1ceee8dd60f2e185176c4c11", "best_bid":"0.899", "best_ask":"0.9"}, {"asset_id":"45415751658241142530386585138386640503488308219341470020075667342738719018629", "price":"0.184", "size":"0", "side":"SELL", "hash":"cd8d8882fe20a62e7710e4b1745e0a7acccc9b5a", "best_bid":"0.1", "best_ask":"0.101"}], "timestamp":"1780150305567", "event_type":"price_change"}
{"market":"0x4f3421fb2daf5cca7430ed8d8132463963081572d75434393a1808fdb8829fe8", "price_changes":[{"asset_id":"31940783580344558651011323787577288681658737625185216525249046282994042503801", "price":"0.819", "size":"100", "side":"BUY", "hash":"4c12c382c2fee160d5610b246d889b2f3c93d7cd", "best_bid":"0.899", "best_ask":"0.9"}, {"asset_id":"45415751658241142530386585138386640503488308219341470020075667342738719018629", "price":"0.181", "size":"100", "side":"SELL", "hash":"39aa7aabf1baee701e0e27f41f01721af826673d", "best_bid":"0.1", "best_ask":"0.101"}], "timestamp":"1780150305603", "event_type":"price_change"}
{"market":"0x30d55d8124ee1e12dabe89201badc45669b81dff69e4ce44d961f32878ec178a", "price_changes":[{"asset_id":"52986718774908357330412653486471347449818893503063830313445318937088822580057", "price":"0.874", "size":"100", "side":"BUY", "hash":"729d365d942021c2285bb15693d0d35485d93f65", "best_bid":"0.909", "best_ask":"0.91"}, {"asset_id":"27576533317283401577758999384642760405921738493660383550832555714312627457443", "price":"0.126", "size":"100", "side":"SELL", "hash":"9bd533b964f932a73e517da1239866a2712b93a6", "best_bid":"0.09", "best_ask":"0.091"}], "timestamp":"1780150305606", "event_type":"price_change"}
{"market":"0x4f3421fb2daf5cca7430ed8d8132463963081572d75434393a1808fdb8829fe8", "price_changes":[{"asset_id":"31940783580344558651011323787577288681658737625185216525249046282994042503801", "price":"0.867", "size":"42.97", "side":"BUY", "hash":"e483a2081157da2eebb33752b31f716a744501ab", "best_bid":"0.899", "best_ask":"0.9"}, {"asset_id":"45415751658241142530386585138386640503488308219341470020075667342738719018629", "price":"0.133", "size":"42.97", "side":"SELL", "hash":"5d1fdb7e8fa15dea307e671ca047d11e181d772f", "best_bid":"0.1", "best_ask":"0.101"}], "timestamp":"1780150305641", "event_type":"price_change"}
{"market":"0x9b6fef249040fd17e9c107955b37ac2c3e923509b6b0ff01cc463a331ddeb894", "price_changes":[{"asset_id":"32270411694523539495262303868629477861017829722282576458031815333486368239544", "price":"0.802", "size":"89", "side":"BUY", "hash":"0df40a8ac929fad9a30c12d4cf969533a719bd58", "best_bid":"0.836", "best_ask":"0.837"}, {"asset_id":"108233603819467706476318984012158651931658302669301887462181073562758483842092", "price":"0.198", "size":"89", "side":"SELL", "hash":"137d05852097f032e445685b66956793e6c1189d", "best_bid":"0.163", "best_ask":"0.164"}], "timestamp":"1780150306738", "event_type":"price_change"}
{"market":"0x375409bc5eeeff961e82b479caeccc20f33d15738e5bce1186d628aa3d9dfb1f", "price_changes":[{"asset_id":"77121637225348873006259930776623502125079210522997384841464684944292365296940", "price":"0.853", "size":"25", "side":"BUY", "hash":"bdeffc70dedc2fb21c86427b40393f7468b414d6", "best_bid":"0.888", "best_ask":"0.889"}, {"asset_id":"115556263888245616435851357148058235707004733438163639091106356867234218207169", "price":"0.147", "size":"25", "side":"SELL", "hash":"40a07cbea92ad673bc6e438b52f9dc970a9078bd", "best_bid":"0.111", "best_ask":"0.112"}], "timestamp":"1780150306789", "event_type":"price_change"}
{"market":"0x7976b8dbacf9077eb1453a62bcefd6ab2df199acd28aad276ff0d920d6992892", "price_changes":[{"asset_id":"4394372887385518214471608448209527405727552777602031099972143344338178308080", "price":"0.171", "size":"2276.42", "side":"SELL", "hash":"5a74ed8d621319e1768f5080a0f50e64c65663a4", "best_bid":"0.167", "best_ask":"0.168"}, {"asset_id":"112680630004798425069810935278212000865453267506345451433803052322987302357330", "price":"0.829", "size":"2276.42", "side":"BUY", "hash":"c24b267657570ee78fa2e91ac1d7947ab04cda78", "best_bid":"0.832", "best_ask":"0.833"}], "timestamp":"1780150306905", "event_type":"price_change"}
{"market":"0x375409bc5eeeff961e82b479caeccc20f33d15738e5bce1186d628aa3d9dfb1f", "price_changes":[{"asset_id":"115556263888245616435851357148058235707004733438163639091106356867234218207169", "price":"0.115", "size":"12919.15", "side":"SELL", "hash":"22a27b00b6ffad9552498294043543289ef4bfc4", "best_bid":"0.111", "best_ask":"0.112"}, {"asset_id":"77121637225348873006259930776623502125079210522997384841464684944292365296940", "price":"0.885", "size":"12919.15", "side":"BUY", "hash":"fc999bd94f40b5caa2e4fc8e72d885a8c3d5d71a", "best_bid":"0.888", "best_ask":"0.889"}], "timestamp":"1780150306977", "event_type":"price_change"}
{"market":"0x9b6fef249040fd17e9c107955b37ac2c3e923509b6b0ff01cc463a331ddeb894", "price_changes":[{"asset_id":"108233603819467706476318984012158651931658302669301887462181073562758483842092", "price":"0.167", "size":"3784.75", "side":"SELL", "hash":"c9d6e30526df8410ba6a6f7b007f99047645b571", "best_bid":"0.163", "best_ask":"0.164"}, {"asset_id":"32270411694523539495262303868629477861017829722282576458031815333486368239544", "price":"0.833", "size":"3784.75", "side":"BUY", "hash":"d0160d05fa5b9ab69f5597fe191c0955575283d0", "best_bid":"0.836", "best_ask":"0.837"}], "timestamp":"1780150307000", "event_type":"price_change"}
{"market":"0x30d55d8124ee1e12dabe89201badc45669b81dff69e4ce44d961f32878ec178a", "price_changes":[{"asset_id":"27576533317283401577758999384642760405921738493660383550832555714312627457443", "price":"0.093", "size":"87369.17", "side":"SELL", "hash":"5311ddb33bc5f01f11aabcd2637af4913b84da6f", "best_bid":"0.09", "best_ask":"0.091"}, {"asset_id":"52986718774908357330412653486471347449818893503063830313445318937088822580057", "price":"0.907", "size":"87369.17", "side":"BUY", "hash":"40e129bdaa96be92c653e19feb6c1ac616e9c4ec", "best_bid":"0.909", "best_ask":"0.91"}], "timestamp":"1780150307001", "event_type":"price_change"}
{"market":"0x4f3421fb2daf5cca7430ed8d8132463963081572d75434393a1808fdb8829fe8", "price_changes":[{"asset_id":"45415751658241142530386585138386640503488308219341470020075667342738719018629", "price":"0.103", "size":"18122.51", "side":"SELL", "hash":"aa6e2fc766f9ca19662249651f3862e6ca929370", "best_bid":"0.1", "best_ask":"0.101"}, {"asset_id":"31940783580344558651011323787577288681658737625185216525249046282994042503801", "price":"0.897", "size":"18122.51", "side":"BUY", "hash":"a244d003811a239f9bbb76305dde28133ae8382b", "best_bid":"0.899", "best_ask":"0.9"}], "timestamp":"1780150307006", "event_type":"price_change"}
{"market":"0x7976b8dbacf9077eb1453a62bcefd6ab2df199acd28aad276ff0d920d6992892", "price_changes":[{"asset_id":"4394372887385518214471608448209527405727552777602031099972143344338178308080", "price":"0.171", "size":"2301.97", "side":"SELL", "hash":"3283c48616aace17b6e07756da432ec4cb8ce68a", "best_bid":"0.167", "best_ask":"0.168"}, {"asset_id":"112680630004798425069810935278212000865453267506345451433803052322987302357330", "price":"0.829", "size":"2301.97", "side":"BUY", "hash":"71afba8fcd6641b501b2705e0a386ce4a7c65a2a", "best_bid":"0.832", "best_ask":"0.833"}], "timestamp":"1780150307027", "event_type":"price_change"}
{"market":"0x375409bc5eeeff961e82b479caeccc20f33d15738e5bce1186d628aa3d9dfb1f", "price_changes":[{"asset_id":"115556263888245616435851357148058235707004733438163639091106356867234218207169", "price":"0.115", "size":"12999.15", "side":"SELL", "hash":"e1b91bd46b0a9214b725a5fc501e57d7938fbcac", "best_bid":"0.111", "best_ask":"0.112"}, {"asset_id":"77121637225348873006259930776623502125079210522997384841464684944292365296940", "price":"0.885", "size":"12999.15", "side":"BUY", "hash":"7d803ef368e3478b0fd3d4a75d5ee21198fd7f23", "best_bid":"0.888", "best_ask":"0.889"}], "timestamp":"1780150307076", "event_type":"price_change"}
{"market":"0x4f3421fb2daf5cca7430ed8d8132463963081572d75434393a1808fdb8829fe8", "price_changes":[{"asset_id":"45415751658241142530386585138386640503488308219341470020075667342738719018629", "price":"0.103", "size":"18183.31", "side":"SELL", "hash":"068bdbedccd9c928905ac807a76e2b2f6a9f10b1", "best_bid":"0.1", "best_ask":"0.101"}, {"asset_id":"31940783580344558651011323787577288681658737625185216525249046282994042503801", "price":"0.897", "size":"18183.31", "side":"BUY", "hash":"c4e40e099cd2971e14003ff84a3e81bf6c56d1ad", "best_bid":"0.899", "best_ask":"0.9"}], "timestamp":"1780150307136", "event_type":"price_change"}
{"market":"0x9b6fef249040fd17e9c107955b37ac2c3e923509b6b0ff01cc463a331ddeb894", "price_changes":[{"asset_id":"108233603819467706476318984012158651931658302669301887462181073562758483842092", "price":"0.167", "size":"3864.75", "side":"SELL", "hash":"95ea2d77fefd396c02b1c117e7528f189adfea06", "best_bid":"0.163", "best_ask":"0.164"}, {"asset_id":"32270411694523539495262303868629477861017829722282576458031815333486368239544", "price":"0.833", "size":"3864.75", "side":"BUY", "hash":"31de0e142230a7f38d14a30e6d649542de58c784", "best_bid":"0.836", "best_ask":"0.837"}], "timestamp":"1780150307137", "event_type":"price_change"}
{"market":"0x30d55d8124ee1e12dabe89201badc45669b81dff69e4ce44d961f32878ec178a", "price_changes":[{"asset_id":"27576533317283401577758999384642760405921738493660383550832555714312627457443", "price":"0.093", "size":"87424.83", "side":"SELL", "hash":"575bfd406424969b9dc5336d64de4162e55b275a", "best_bid":"0.09", "best_ask":"0.091"}, {"asset_id":"52986718774908357330412653486471347449818893503063830313445318937088822580057", "price":"0.907", "size":"87424.83", "side":"BUY", "hash":"0d00af84f38c1c13285e0c1e68f1f25729c4efee", "best_bid":"0.909", "best_ask":"0.91"}], "timestamp":"1780150307139", "event_type":"price_change"}
{"market":"0x7976b8dbacf9077eb1453a62bcefd6ab2df199acd28aad276ff0d920d6992892", "price_changes":[{"asset_id":"112680630004798425069810935278212000865453267506345451433803052322987302357330", "price":"0.8", "size":"8481.84", "side":"BUY", "hash":"26c902985379d8ef00d26a71a13e1b3535e53b38", "best_bid":"0.832", "best_ask":"0.833"}, {"asset_id":"4394372887385518214471608448209527405727552777602031099972143344338178308080", "price":"0.2", "size":"8481.84", "side":"SELL", "hash":"f1471b55ae5c5aa91dcbb129d157cf534f7b20bb", "best_bid":"0.167", "best_ask":"0.168"}], "timestamp":"1780150307917", "event_type":"price_change"}
{"market":"0x1595b4818eeb1ea1e0bec5de6f057218e557feee9b405a0e930d290384fa1d16", "price_changes":[{"asset_id":"45484070731786948288366703334552551439356529561722304542938873238430842810537", "price":"0.914", "size":"125", "side":"BUY", "hash":"808f53de328bf14a82496fa3b886d6087e8ae310", "best_bid":"0.948", "best_ask":"0.949"}, {"asset_id":"81739002353269632749850710185641576213562066971072676369728657545679630163887", "price":"0.086", "size":"125", "side":"SELL", "hash":"cd961eb99b8c15f80a275e125e97cb6f66e45f81", "best_bid":"0.051", "best_ask":"0.052"}], "timestamp":"1780150308390", "event_type":"price_change"}
{"market":"0x0c4cd2055d6ea89354ffddc55d6dbcef9355748112ea952fc925f3db6a5c457f", "price_changes":[{"asset_id":"115428153746996892211798999366308897078723117634059783423375188043903703749062", "price":"0.88", "size":"15221.64", "side":"BUY", "hash":"fae335310673f81f4e8c332d7cefde4d5e42f453", "best_bid":"0.914", "best_ask":"0.915"}, {"asset_id":"18812649149814341758733697580460697418474693998558159483117100240528657629879", "price":"0.12", "size":"15221.64", "side":"SELL", "hash":"912937ba1d7d4851970290e68f78f4dde6f72352", "best_bid":"0.085", "best_ask":"0.086"}], "timestamp":"1780150308397", "event_type":"price_change"}
{"market":"0x0c4cd2055d6ea89354ffddc55d6dbcef9355748112ea952fc925f3db6a5c457f", "price_changes":[{"asset_id":"18812649149814341758733697580460697418474693998558159483117100240528657629879", "price":"0.088", "size":"15049.46", "side":"SELL", "hash":"0551fe5cb6ec099f7a89f2aad956ade3a81d4bbc", "best_bid":"0.085", "best_ask":"0.086"}, {"asset_id":"115428153746996892211798999366308897078723117634059783423375188043903703749062", "price":"0.912", "size":"15049.46", "side":"BUY", "hash":"d1aa56153db3339d893d4bc6c6a63c25d9e59867", "best_bid":"0.914", "best_ask":"0.915"}], "timestamp":"1780150309000", "event_type":"price_change"}
{"market":"0x0c4cd2055d6ea89354ffddc55d6dbcef9355748112ea952fc925f3db6a5c457f", "price_changes":[{"asset_id":"18812649149814341758733697580460697418474693998558159483117100240528657629879", "price":"0.088", "size":"15129.46", "side":"SELL", "hash":"d071bdb9dffb2e0a24e8c4d8634cea432987e6de", "best_bid":"0.085", "best_ask":"0.086"}, {"asset_id":"115428153746996892211798999366308897078723117634059783423375188043903703749062", "price":"0.912", "size":"15129.46", "side":"BUY", "hash":"3ec15792c5c06cfe607ccdc8353928c8fb60c2ec", "best_bid":"0.914", "best_ask":"0.915"}], "timestamp":"1780150309086", "event_type":"price_change"}
{"market":"0x7876851632c295043c66536150a304cb785abdf712ba8489d298c6e6926be106", "price_changes":[{"asset_id":"19291692040378529618917910599727571242305935029274321291612270922648172794670", "price":"0.956", "size":"250", "side":"BUY", "hash":"ff814762e3a151f1ca7dac45fc65d56088bd50a6", "best_bid":"0.989", "best_ask":"0.99"}, {"asset_id":"97239126062673310243763617236644392945530356142765650402171508075574679292913", "price":"0.044", "size":"250", "side":"SELL", "hash":"962f4ded1e83179056713f95a71ae4c05d5c110c", "best_bid":"0.01", "best_ask":"0.011"}], "timestamp":"1780150309127", "event_type":"price_change"}
{"market":"0x4f3421fb2daf5cca7430ed8d8132463963081572d75434393a1808fdb8829fe8", "price_changes":[{"asset_id":"31940783580344558651011323787577288681658737625185216525249046282994042503801", "price":"0.867", "size":"17.97", "side":"BUY", "hash":"b5e5ae5de536d063af088e3642c0944046d7e210", "best_bid":"0.899", "best_ask":"0.9"}, {"asset_id":"45415751658241142530386585138386640503488308219341470020075667342738719018629", "price":"0.133", "size":"17.97", "side":"SELL", "hash":"c9647a870c2591079bad4b140ba7cb924b943bce", "best_bid":"0.1", "best_ask":"0.101"}], "timestamp":"1780150310861", "event_type":"price_change"}
{"market":"0x30d55d8124ee1e12dabe89201badc45669b81dff69e4ce44d961f32878ec178a", "price_changes":[{"asset_id":"52986718774908357330412653486471347449818893503063830313445318937088822580057", "price":"0.874", "size":"75", "side":"BUY", "hash":"02f13e47acb260a4258a363a8b2cf06a8727fc82", "best_bid":"0.909", "best_ask":"0.91"}, {"asset_id":"27576533317283401577758999384642760405921738493660383550832555714312627457443", "price":"0.126", "size":"75", "side":"SELL", "hash":"cf77059ad5f98d91a469ad5249091eda27c2dd4b", "best_bid":"0.09", "best_ask":"0.091"}], "timestamp":"1780150310861", "event_type":"price_change"}
{"market":"0x375409bc5eeeff961e82b479caeccc20f33d15738e5bce1186d628aa3d9dfb1f", "price_changes":[{"asset_id":"77121637225348873006259930776623502125079210522997384841464684944292365296940", "price":"0.857", "size":"144", "side":"BUY", "hash":"df58594e42c20c672654a4bcff7c9ab9dc006202", "best_bid":"0.888", "best_ask":"0.889"}, {"asset_id":"115556263888245616435851357148058235707004733438163639091106356867234218207169", "price":"0.143", "size":"144", "side":"SELL", "hash":"dde6699f350952143ccf350ba5490e7b161ac1db", "best_bid":"0.111", "best_ask":"0.112"}], "timestamp":"1780150311451", "event_type":"price_change"}
{"market":"0x9b6fef249040fd17e9c107955b37ac2c3e923509b6b0ff01cc463a331ddeb894", "price_changes":[{"asset_id":"32270411694523539495262303868629477861017829722282576458031815333486368239544", "price":"0.806", "size":"169", "side":"BUY", "hash":"b629b96dd4d1c6d82fa9207cf8545e1fcc6c8f30", "best_bid":"0.836", "best_ask":"0.837"}, {"asset_id":"108233603819467706476318984012158651931658302669301887462181073562758483842092", "price":"0.194", "size":"169", "side":"SELL", "hash":"f7bcc70bf4506527a062a64a7d905d8a63279cad", "best_bid":"0.163", "best_ask":"0.164"}], "timestamp":"1780150311451", "event_type":"price_change"}
{"market":"0x9b6fef249040fd17e9c107955b37ac2c3e923509b6b0ff01cc463a331ddeb894", "price_changes":[{"asset_id":"108233603819467706476318984012158651931658302669301887462181073562758483842092", "price":"0.167", "size":"3810.2", "side":"SELL", "hash":"ba402c34f9c5ab5c5fa7c3d621c2913d369a2880", "best_bid":"0.163", "best_ask":"0.164"}, {"asset_id":"32270411694523539495262303868629477861017829722282576458031815333486368239544", "price":"0.833", "size":"3810.2", "side":"BUY", "hash":"b419a42aaf49075378c923c8cdaef216e3f61a39", "best_bid":"0.836", "best_ask":"0.837"}], "timestamp":"1780150311840", "event_type":"price_change"}
{"market":"0x30d55d8124ee1e12dabe89201badc45669b81dff69e4ce44d961f32878ec178a", "price_changes":[{"asset_id":"27576533317283401577758999384642760405921738493660383550832555714312627457443", "price":"0.093", "size":"87364.83", "side":"SELL", "hash":"eb2a3d25fcfaebcca87ee5715238eaa19ec438ff", "best_bid":"0.09", "best_ask":"0.091"}, {"asset_id":"52986718774908357330412653486471347449818893503063830313445318937088822580057", "price":"0.907", "size":"87364.83", "side":"BUY", "hash":"0d4de337a8ecc31c6043f7fc6c6a70c7ea7522dc", "best_bid":"0.909", "best_ask":"0.91"}], "timestamp":"1780150311872", "event_type":"price_change"}
{"market":"0x375409bc5eeeff961e82b479caeccc20f33d15738e5bce1186d628aa3d9dfb1f", "price_changes":[{"asset_id":"115556263888245616435851357148058235707004733438163639091106356867234218207169", "price":"0.115", "size":"12939.15", "side":"SELL", "hash":"1699e17c7b804cb51179dae1b167a4418ad63d8c", "best_bid":"0.111", "best_ask":"0.112"}, {"asset_id":"77121637225348873006259930776623502125079210522997384841464684944292365296940", "price":"0.885", "size":"12939.15", "side":"BUY", "hash":"7e28e806145f31ad57d679e8fa299e89eea9b23f", "best_bid":"0.888", "best_ask":"0.889"}], "timestamp":"1780150311872", "event_type":"price_change"}
{"market":"0x1595b4818eeb1ea1e0bec5de6f057218e557feee9b405a0e930d290384fa1d16", "price_changes":[{"asset_id":"81739002353269632749850710185641576213562066971072676369728657545679630163887", "price":"0.054", "size":"9325.11", "side":"SELL", "hash":"407664566c7e68ab383b6976d89fdcf66ee2e938", "best_bid":"0.051", "best_ask":"0.052"}, {"asset_id":"45484070731786948288366703334552551439356529561722304542938873238430842810537", "price":"0.946", "size":"9325.11", "side":"BUY", "hash":"55e4b9f8fa095a7587777d6e6d3104302932bd93", "best_bid":"0.948", "best_ask":"0.949"}], "timestamp":"1780150311873", "event_type":"price_change"}
{"market":"0x9b6fef249040fd17e9c107955b37ac2c3e923509b6b0ff01cc463a331ddeb894", "price_changes":[{"asset_id":"108233603819467706476318984012158651931658302669301887462181073562758483842092", "price":"0.167", "size":"3864.75", "side":"SELL", "hash":"c704122fd88350c4c705818017a1cec9071e7a99", "best_bid":"0.163", "best_ask":"0.164"}, {"asset_id":"32270411694523539495262303868629477861017829722282576458031815333486368239544", "price":"0.833", "size":"3864.75", "side":"BUY", "hash":"ac89b68d45158772ff7cadfba1e6744db7de2daa", "best_bid":"0.836", "best_ask":"0.837"}], "timestamp":"1780150311972", "event_type":"price_change"}
{"market":"0x375409bc5eeeff961e82b479caeccc20f33d15738e5bce1186d628aa3d9dfb1f", "price_changes":[{"asset_id":"115556263888245616435851357148058235707004733438163639091106356867234218207169", "price":"0.115", "size":"12999.15", "side":"SELL", "hash":"5e8e5c7819cae450b3fcd7ccef4f3a12ddfd35ff", "best_bid":"0.111", "best_ask":"0.112"}, {"asset_id":"77121637225348873006259930776623502125079210522997384841464684944292365296940", "price":"0.885", "size":"12999.15", "side":"BUY", "hash":"cd9223d6d14344f3ab863b1e8e691edebeb0919f", "best_bid":"0.888", "best_ask":"0.889"}], "timestamp":"1780150311974", "event_type":"price_change"}
{"market":"0x1595b4818eeb1ea1e0bec5de6f057218e557feee9b405a0e930d290384fa1d16", "price_changes":[{"asset_id":"81739002353269632749850710185641576213562066971072676369728657545679630163887", "price":"0.054", "size":"9385.11", "side":"SELL", "hash":"fcd8b1e365cfbf4dcd306995ea814d55da6a775a", "best_bid":"0.051", "best_ask":"0.052"}, {"asset_id":"45484070731786948288366703334552551439356529561722304542938873238430842810537", "price":"0.946", "size":"9385.11", "side":"BUY", "hash":"b6feba357ba36d989bef7e2b11d6471e5fe613f8", "best_bid":"0.948", "best_ask":"0.949"}], "timestamp":"1780150311975", "event_type":"price_change"}
{"market":"0x30d55d8124ee1e12dabe89201badc45669b81dff69e4ce44d961f32878ec178a", "price_changes":[{"asset_id":"27576533317283401577758999384642760405921738493660383550832555714312627457443", "price":"0.093", "size":"87424.83", "side":"SELL", "hash":"87bb2124244d104c9a190ccca3b726b84114121a", "best_bid":"0.09", "best_ask":"0.091"}, {"asset_id":"52986718774908357330412653486471347449818893503063830313445318937088822580057", "price":"0.907", "size":"87424.83", "side":"BUY", "hash":"759b9278667972f253f074d002d36f44268683c2", "best_bid":"0.909", "best_ask":"0.91"}], "timestamp":"1780150311978", "event_type":"price_change"}
{"market":"0x7976b8dbacf9077eb1453a62bcefd6ab2df199acd28aad276ff0d920d6992892", "price_changes":[{"asset_id":"4394372887385518214471608448209527405727552777602031099972143344338178308080", "price":"0.171", "size":"2247.95", "side":"SELL", "hash":"59a75a73411efa5b08a3a20b83966bc6cc295909", "best_bid":"0.167", "best_ask":"0.168"}, {"asset_id":"112680630004798425069810935278212000865453267506345451433803052322987302357330", "price":"0.829", "size":"2247.95", "side":"BUY", "hash":"9d6d2e1f7c57206eba3d354fe5773577a4a95e2f", "best_bid":"0.832", "best_ask":"0.833"}], "timestamp":"1780150312003", "event_type":"price_change"}
{"market":"0x0c4cd2055d6ea89354ffddc55d6dbcef9355748112ea952fc925f3db6a5c457f", "price_changes":[{"asset_id":"18812649149814341758733697580460697418474693998558159483117100240528657629879", "price":"0.088", "size":"15069.46", "side":"SELL", "hash":"9f1b7f36db95d5e92f133044af2cf94d1e8c2713", "best_bid":"0.085", "best_ask":"0.086"}, {"asset_id":"115428153746996892211798999366308897078723117634059783423375188043903703749062", "price":"0.912", "size":"15069.46", "side":"BUY", "hash":"15dcd0b28fece53ddcf5654a3d30a850c1b721bf", "best_bid":"0.914", "best_ask":"0.915"}], "timestamp":"1780150312521", "event_type":"price_change"}
{"market":"0x7976b8dbacf9077eb1453a62bcefd6ab2df199acd28aad276ff0d920d6992892", "price_changes":[{"asset_id":"4394372887385518214471608448209527405727552777602031099972143344338178308080", "price":"0.171", "size":"2301.97", "side":"SELL", "hash":"7c69a88171521d060acbdf4ed9b42c8ef877da69", "best_bid":"0.167", "best_ask":"0.168"}, {"asset_id":"112680630004798425069810935278212000865453267506345451433803052322987302357330", "price":"0.829", "size":"2301.97", "side":"BUY", "hash":"90c1293cff9f62fd42d133de21e92e256140c726", "best_bid":"0.832", "best_ask":"0.833"}], "timestamp":"1780150312598", "event_type":"price_change"}
PONG
{"market":"0x0c4cd2055d6ea89354ffddc55d6dbcef9355748112ea952fc925f3db6a5c457f", "price_changes":[{"asset_id":"18812649149814341758733697580460697418474693998558159483117100240528657629879", "price":"0.088", "size":"15129.46", "side":"SELL", "hash":"1df0b9981b7a757c796c110010fa9b8ab1f0412b", "best_bid":"0.085", "best_ask":"0.086"}, {"asset_id":"115428153746996892211798999366308897078723117634059783423375188043903703749062", "price":"0.912", "size":"15129.46", "side":"BUY", "hash":"9412f194d990a6d20d5e971eb210fa55850017c0", "best_bid":"0.914", "best_ask":"0.915"}], "timestamp":"1780150313530", "event_type":"price_change"}
{"market":"0x4f3421fb2daf5cca7430ed8d8132463963081572d75434393a1808fdb8829fe8", "price_changes":[{"asset_id":"45415751658241142530386585138386640503488308219341470020075667342738719018629", "price":"0.103", "size":"18123.31", "side":"SELL", "hash":"0cc761e548500a182a08a0c2d3d8386390717215", "best_bid":"0.1", "best_ask":"0.101"}, {"asset_id":"31940783580344558651011323787577288681658737625185216525249046282994042503801", "price":"0.897", "size":"18123.31", "side":"BUY", "hash":"3ddbb61d94887d0ff4f35dbb6b1e626730bf7c73", "best_bid":"0.899", "best_ask":"0.9"}], "timestamp":"1780150313581", "event_type":"price_change"}
{"market":"0x4f3421fb2daf5cca7430ed8d8132463963081572d75434393a1808fdb8829fe8", "price_changes":[{"asset_id":"45415751658241142530386585138386640503488308219341470020075667342738719018629", "price":"0.103", "size":"18183.31", "side":"SELL", "hash":"f9df95efbea0494429fbc1401aaf89c230c632de", "best_bid":"0.1", "best_ask":"0.101"}, {"asset_id":"31940783580344558651011323787577288681658737625185216525249046282994042503801", "price":"0.897", "size":"18183.31", "side":"BUY", "hash":"3f41bd389c3ab033ab6bbd29e92b8f8d3a1f6bd6", "best_bid":"0.899", "best_ask":"0.9"}], "timestamp":"1780150313691", "event_type":"price_change"}
{"market":"0x7976b8dbacf9077eb1453a62bcefd6ab2df199acd28aad276ff0d920d6992892", "price_changes":[{"asset_id":"112680630004798425069810935278212000865453267506345451433803052322987302357330", "price":"0.799", "size":"407.17", "side":"BUY", "hash":"6d2c83699fd904c2eb62549d5a1b578e1af2fcc5", "best_bid":"0.832", "best_ask":"0.833"}, {"asset_id":"4394372887385518214471608448209527405727552777602031099972143344338178308080", "price":"0.201", "size":"407.17", "side":"SELL", "hash":"258aa143f3008d0b6c6af5242b1bdba9dc7d2e1f", "best_bid":"0.167", "best_ask":"0.168"}], "timestamp":"1780150313753", "event_type":"price_change"}
{"market":"0x0c4cd2055d6ea89354ffddc55d6dbcef9355748112ea952fc925f3db6a5c457f", "price_changes":[{"asset_id":"18812649149814341758733697580460697418474693998558159483117100240528657629879", "price":"0.085", "size":"110727.91", "side":"BUY", "hash":"46d280d9d587ba44d344405c78a63dc5f5e87258", "best_bid":"0.085", "best_ask":"0.086"}, {"asset_id":"115428153746996892211798999366308897078723117634059783423375188043903703749062", "price":"0.915", "size":"110727.91", "side":"SELL", "hash":"63e6b3c502fc7bb32eb5dec8eb54a552aa238363", "best_bid":"0.914", "best_ask":"0.915"}], "timestamp":"1780150314624", "event_type":"price_change"}
{"market":"0x1595b4818eeb1ea1e0bec5de6f057218e557feee9b405a0e930d290384fa1d16", "price_changes":[{"asset_id":"45484070731786948288366703334552551439356529561722304542938873238430842810537", "price":"0.914", "size":"0", "side":"BUY", "hash":"4af4c1bd2e2b2f216325dc48acd928a339075942", "best_bid":"0.948", "best_ask":"0.949"}, {"asset_id":"81739002353269632749850710185641576213562066971072676369728657545679630163887", "price":"0.086", "size":"0", "side":"SELL", "hash":"edb6385b7728eee70f5e00794e09010232726c69", "best_bid":"0.051", "best_ask":"0.052"}], "timestamp":"1780150315406", "event_type":"price_change"}
{"market":"0x0c4cd2055d6ea89354ffddc55d6dbcef9355748112ea952fc925f3db6a5c457f", "price_changes":[{"asset_id":"115428153746996892211798999366308897078723117634059783423375188043903703749062", "price":"0.88", "size":"15096.64", "side":"BUY", "hash":"d85f12ffcf3de5ca62af8cc790522028a80e9bb6", "best_bid":"0.914", "best_ask":"0.915"}, {"asset_id":"18812649149814341758733697580460697418474693998558159483117100240528657629879", "price":"0.12", "size":"15096.64", "side":"SELL", "hash":"c8f511aabe7215c6672aaa46c668273201b9d798", "best_bid":"0.085", "best_ask":"0.086"}], "timestamp":"1780150315407", "event_type":"price_change"}
{"market":"0x7876851632c295043c66536150a304cb785abdf712ba8489d298c6e6926be106", "price_changes":[{"asset_id":"19291692040378529618917910599727571242305935029274321291612270922648172794670", "price":"0.956", "size":"125", "side":"BUY", "hash":"af39048b1e8b2821763317f8fb88dc9b369cc612", "best_bid":"0.989", "best_ask":"0.99"}, {"asset_id":"97239126062673310243763617236644392945530356142765650402171508075574679292913", "price":"0.044", "size":"125", "side":"SELL", "hash":"f4eeb89be26803b1aa7dd1101d63d6c421b96b16", "best_bid":"0.01", "best_ask":"0.011"}], "timestamp":"1780150316282", "event_type":"price_change"}
{"market":"0x4f3421fb2daf5cca7430ed8d8132463963081572d75434393a1808fdb8829fe8", "price_changes":[{"asset_id":"31940783580344558651011323787577288681658737625185216525249046282994042503801", "price":"0.867", "size":"42.97", "side":"BUY", "hash":"d3f2ae2f3c74d5258b0705be68e3b2a4daf8892c", "best_bid":"0.899", "best_ask":"0.9"}, {"asset_id":"45415751658241142530386585138386640503488308219341470020075667342738719018629", "price":"0.133", "size":"42.97", "side":"SELL", "hash":"4d1656e8b19ed6df1f7c706bce360b808efe5390", "best_bid":"0.1", "best_ask":"0.101"}], "timestamp":"1780150317108", "event_type":"price_change"}
{"market":"0x30d55d8124ee1e12dabe89201badc45669b81dff69e4ce44d961f32878ec178a", "price_changes":[{"asset_id":"52986718774908357330412653486471347449818893503063830313445318937088822580057", "price":"0.873", "size":"70", "side":"BUY", "hash":"61cc77c56e411357fd85894ac32955eb202a15ea", "best_bid":"0.909", "best_ask":"0.91"}, {"asset_id":"27576533317283401577758999384642760405921738493660383550832555714312627457443", "price":"0.127", "size":"70", "side":"SELL", "hash":"42c778dd23cc12583a9da4f58463609d47cc2853", "best_bid":"0.09", "best_ask":"0.091"}], "timestamp":"1780150317131", "event_type":"price_change"}
{"market":"0x375409bc5eeeff961e82b479caeccc20f33d15738e5bce1186d628aa3d9dfb1f", "price_changes":[{"asset_id":"77121637225348873006259930776623502125079210522997384841464684944292365296940", "price":"0.857", "size":"269", "side":"BUY", "hash":"83f5d290efe235ec300dd08e8e84a3fbb2ce4cec", "best_bid":"0.888", "best_ask":"0.889"}, {"asset_id":"115556263888245616435851357148058235707004733438163639091106356867234218207169", "price":"0.143", "size":"269", "side":"SELL", "hash":"bfa341dbe2107a53bf0a3cadc791eab126a48c32", "best_bid":"0.111", "best_ask":"0.112"}], "timestamp":"1780150317755", "event_type":"price_change"}
{"market":"0x9b6fef249040fd17e9c107955b37ac2c3e923509b6b0ff01cc463a331ddeb894", "price_changes":[{"asset_id":"32270411694523539495262303868629477861017829722282576458031815333486368239544", "price":"0.806", "size":"294", "side":"BUY", "hash":"f8b14fbc608c58f1a63b9944fc4e25f7d18ded27", "best_bid":"0.836", "best_ask":"0.837"}, {"asset_id":"108233603819467706476318984012158651931658302669301887462181073562758483842092", "price":"0.194", "size":"294", "side":"SELL", "hash":"c457a65730f7aa91d4e2d393b506a41577f4b96f", "best_bid":"0.163", "best_ask":"0.164"}], "timestamp":"1780150317771", "event_type":"price_change"}
{"market":"0x7976b8dbacf9077eb1453a62bcefd6ab2df199acd28aad276ff0d920d6992892", "price_changes":[{"asset_id":"112680630004798425069810935278212000865453267506345451433803052322987302357330", "price":"0.8", "size":"8356.84", "side":"BUY", "hash":"f18ce8e6cbe85c624dbe0de07981e3cbb8c7684f", "best_bid":"0.832", "best_ask":"0.833"}, {"asset_id":"4394372887385518214471608448209527405727552777602031099972143344338178308080", "price":"0.2", "size":"8356.84", "side":"SELL", "hash":"4adb00887c70903422e9a8af53fff5337539fa9f", "best_bid":"0.167", "best_ask":"0.168"}], "timestamp":"1780150318481", "event_type":"price_change"}
{"market":"0x7976b8dbacf9077eb1453a62bcefd6ab2df199acd28aad276ff0d920d6992892", "price_changes":[{"asset_id":"112680630004798425069810935278212000865453267506345451433803052322987302357330", "price":"0.799", "size":"382.17", "side":"BUY", "hash":"ad781bae6f86a8019853cae6ede474004c9217cc", "best_bid":"0.832", "best_ask":"0.833"}, {"asset_id":"4394372887385518214471608448209527405727552777602031099972143344338178308080", "price":"0.201", "size":"382.17", "side":"SELL", "hash":"1525d27e5758773848e05802a825751f23284ae2", "best_bid":"0.167", "best_ask":"0.168"}], "timestamp":"1780150318900", "event_type":"price_change"}
{"market":"0x4f3421fb2daf5cca7430ed8d8132463963081572d75434393a1808fdb8829fe8", "price_changes":[{"asset_id":"31940783580344558651011323787577288681658737625185216525249046282994042503801", "price":"0.861", "size":"45", "side":"BUY", "hash":"190dc58f8ead597c555bdc7371d07c69e0518de5", "best_bid":"0.899", "best_ask":"0.9"}, {"asset_id":"45415751658241142530386585138386640503488308219341470020075667342738719018629", "price":"0.139", "size":"45", "side":"SELL", "hash":"986c2beec77bd1912383a0914962159b6a64c0eb", "best_bid":"0.1", "best_ask":"0.101"}], "timestamp":"1780150319184", "event_type":"price_change"}
{"market":"0x1595b4818eeb1ea1e0bec5de6f057218e557feee9b405a0e930d290384fa1d16", "price_changes":[{"asset_id":"45484070731786948288366703334552551439356529561722304542938873238430842810537", "price":"0.897", "size":"125", "side":"BUY", "hash":"5f7fe97a24a81ea1b370bffd000947699fca486f", "best_bid":"0.948", "best_ask":"0.949"}, {"asset_id":"81739002353269632749850710185641576213562066971072676369728657545679630163887", "price":"0.103", "size":"125", "side":"SELL", "hash":"cc3bb30e66288f3894931e237b9a76879b7f2349", "best_bid":"0.051", "best_ask":"0.052"}], "timestamp":"1780150319699", "event_type":"price_change"}
{"market":"0x0c4cd2055d6ea89354ffddc55d6dbcef9355748112ea952fc925f3db6a5c457f", "price_changes":[{"asset_id":"115428153746996892211798999366308897078723117634059783423375188043903703749062", "price":"0.753", "size":"125", "side":"BUY", "hash":"68511707b1192510472c90a9bebfbca6dc0e888d", "best_bid":"0.914", "best_ask":"0.915"}, {"asset_id":"18812649149814341758733697580460697418474693998558159483117100240528657629879", "price":"0.247", "size":"125", "side":"SELL", "hash":"701d6bd58030368a3bdd69f1fc4e6b9e428d2e31", "best_bid":"0.085", "best_ask":"0.086"}], "timestamp":"1780150319713", "event_type":"price_change"}
{"market":"0x375409bc5eeeff961e82b479caeccc20f33d15738e5bce1186d628aa3d9dfb1f", "price_changes":[{"asset_id":"77121637225348873006259930776623502125079210522997384841464684944292365296940", "price":"0.853", "size":"0", "side":"BUY", "hash":"3539b29f2e647a6869250020c9cf555b3dcea7b5", "best_bid":"0.888", "best_ask":"0.889"}, {"asset_id":"115556263888245616435851357148058235707004733438163639091106356867234218207169", "price":"0.147", "size":"0", "side":"SELL", "hash":"0ab094213867eb23da26a12e1d132228099cafa7", "best_bid":"0.111", "best_ask":"0.112"}], "timestamp":"1780150319833", "event_type":"price_change"}
{"market":"0x9b6fef249040fd17e9c107955b37ac2c3e923509b6b0ff01cc463a331ddeb894", "price_changes":[{"asset_id":"32270411694523539495262303868629477861017829722282576458031815333486368239544", "price":"0.802", "size":"64", "side":"BUY", "hash":"157cc07f9b4c90fb2bcf93962e00e4874990ee48", "best_bid":"0.836", "best_ask":"0.837"}, {"asset_id":"108233603819467706476318984012158651931658302669301887462181073562758483842092", "price":"0.198", "size":"64", "side":"SELL", "hash":"f703ad58ec0bac1aba56d31520e02fd3a0437fa6", "best_bid":"0.163", "best_ask":"0.164"}], "timestamp":"1780150319833", "event_type":"price_change"}
{"market":"0x7876851632c295043c66536150a304cb785abdf712ba8489d298c6e6926be106", "price_changes":[{"asset_id":"97239126062673310243763617236644392945530356142765650402171508075574679292913", "price":"0.011", "size":"1798998.22", "side":"SELL", "hash":"47ac508051acc629a2be5db5a64ad7d1644ea93d", "best_bid":"0.01", "best_ask":"0.011"}, {"asset_id":"19291692040378529618917910599727571242305935029274321291612270922648172794670", "price":"0.989", "size":"1798998.22", "side":"BUY", "hash":"5ae7ed79f9500d4a143ba85f453cc9518c42abac", "best_bid":"0.989", "best_ask":"0.99"}], "timestamp":"1780150320004", "event_type":"price_change"}
{"market":"0x7876851632c295043c66536150a304cb785abdf712ba8489d298c6e6926be106", "price_changes":[{"asset_id":"19291692040378529618917910599727571242305935029274321291612270922648172794670", "price":"0.931", "size":"125", "side":"BUY", "hash":"6e1aaef56f54de71ba9aaa0c4a8e052de4985425", "best_bid":"0.989", "best_ask":"0.99"}, {"asset_id":"97239126062673310243763617236644392945530356142765650402171508075574679292913", "price":"0.069", "size":"125", "side":"SELL", "hash":"8c95a4a51ece0ade3dbb0b18f072274e779efa1b", "best_bid":"0.01", "best_ask":"0.011"}], "timestamp":"1780150320273", "event_type":"price_change"}
{"market":"0x30d55d8124ee1e12dabe89201badc45669b81dff69e4ce44d961f32878ec178a", "price_changes":[{"asset_id":"52986718774908357330412653486471347449818893503063830313445318937088822580057", "price":"0.873", "size":"45", "side":"BUY", "hash":"dcde1a32fb7b0f2453b3a1994d840f3130e550f1", "best_bid":"0.909", "best_ask":"0.91"}, {"asset_id":"27576533317283401577758999384642760405921738493660383550832555714312627457443", "price":"0.127", "size":"45", "side":"SELL", "hash":"b7017288d0afd2b1c62cf69b538abc6e7d583a64", "best_bid":"0.09", "best_ask":"0.091"}], "timestamp":"1780150321057", "event_type":"price_change"}
{"market":"0x4f3421fb2daf5cca7430ed8d8132463963081572d75434393a1808fdb8829fe8", "price_changes":[{"asset_id":"31940783580344558651011323787577288681658737625185216525249046282994042503801", "price":"0.867", "size":"17.97", "side":"BUY", "hash":"887b9942636d0abb6a1e289efd59ed4c6222786a", "best_bid":"0.899", "best_ask":"0.9"}, {"asset_id":"45415751658241142530386585138386640503488308219341470020075667342738719018629", "price":"0.133", "size":"17.97", "side":"SELL", "hash":"6be62be7df24e08790cb69a14d79be5cce006d9a", "best_bid":"0.1", "best_ask":"0.101"}], "timestamp":"1780150321061", "event_type":"price_change"}
{"market":"0x375409bc5eeeff961e82b479caeccc20f33d15738e5bce1186d628aa3d9dfb1f", "price_changes":[{"asset_id":"77121637225348873006259930776623502125079210522997384841464684944292365296940", "price":"0.888", "size":"49852.85", "side":"BUY", "hash":"e0bc53a73fa796a7227dfc4d1ca4e93a74d704ff", "best_bid":"0.888", "best_ask":"0.889"}, {"asset_id":"115556263888245616435851357148058235707004733438163639091106356867234218207169", "price":"0.112", "size":"49852.85", "side":"SELL", "hash":"5988c77b87c1d0ea1fd4c43f98734d3aaac5c3eb", "best_bid":"0.111", "best_ask":"0.112"}], "timestamp":"1780150321500", "event_type":"price_change"}
{"market":"0x9b6fef249040fd17e9c107955b37ac2c3e923509b6b0ff01cc463a331ddeb894", "price_changes":[{"asset_id":"32270411694523539495262303868629477861017829722282576458031815333486368239544", "price":"0.806", "size":"169", "side":"BUY", "hash":"8ce44817becab9971530f83c86e4118b4385298a", "best_bid":"0.836", "best_ask":"0.837"}, {"asset_id":"108233603819467706476318984012158651931658302669301887462181073562758483842092", "price":"0.194", "size":"169", "side":"SELL", "hash":"efc1a89c22ba4fce85a5b24aef562849e6231ce1", "best_bid":"0.163", "best_ask":"0.164"}], "timestamp":"1780150321611", "event_type":"price_change"}
{"market":"0x375409bc5eeeff961e82b479caeccc20f33d15738e5bce1186d628aa3d9dfb1f", "price_changes":[{"asset_id":"77121637225348873006259930776623502125079210522997384841464684944292365296940", "price":"0.857", "size":"144", "side":"BUY", "hash":"b0fcfe8e7222f89d120d1088840f6aee503fe18f", "best_bid":"0.888", "best_ask":"0.889"}, {"asset_id":"115556263888245616435851357148058235707004733438163639091106356867234218207169", "price":"0.143", "size":"144", "side":"SELL", "hash":"8ef54befaaf88b0186bd98eb2562798c6341dfcd", "best_bid":"0.111", "best_ask":"0.112"}], "timestamp":"1780150321612", "event_type":"price_change"}
{"market":"0x7976b8dbacf9077eb1453a62bcefd6ab2df199acd28aad276ff0d920d6992892", "price_changes":[{"asset_id":"112680630004798425069810935278212000865453267506345451433803052322987302357330", "price":"0.765", "size":"275", "side":"BUY", "hash":"bc4969055c43e28193b066bf50054c20cdf4dac9", "best_bid":"0.832", "best_ask":"0.833"}, {"asset_id":"4394372887385518214471608448209527405727552777602031099972143344338178308080", "price":"0.235", "size":"275", "side":"SELL", "hash":"e7b68c7a502953dd9cef4bdd053055db181a7fab", "best_bid":"0.167", "best_ask":"0.168"}], "timestamp":"1780150322741", "event_type":"price_change"}
{"market":"0x1595b4818eeb1ea1e0bec5de6f057218e557feee9b405a0e930d290384fa1d16", "price_changes":[{"asset_id":"45484070731786948288366703334552551439356529561722304542938873238430842810537", "price":"0.905", "size":"5332.69", "side":"BUY", "hash":"e6023ff0aae7b584798f31e35a398f5c3586d3f8", "best_bid":"0.948", "best_ask":"0.949"}, {"asset_id":"81739002353269632749850710185641576213562066971072676369728657545679630163887", "price":"0.095", "size":"5332.69", "side":"SELL", "hash":"bea5e5f70daf2dab391169151c7b3823ad8472a4", "best_bid":"0.051", "best_ask":"0.052"}], "timestamp":"1780150323441", "event_type":"price_change"}
{"market":"0x0c4cd2055d6ea89354ffddc55d6dbcef9355748112ea952fc925f3db6a5c457f", "price_changes":[{"asset_id":"115428153746996892211798999366308897078723117634059783423375188043903703749062", "price":"0.871", "size":"209851.98", "side":"BUY", "hash":"d498457aede2351099c795bc7d4298e3c179cdc6", "best_bid":"0.914", "best_ask":"0.915"}, {"asset_id":"18812649149814341758733697580460697418474693998558159483117100240528657629879", "price":"0.129", "size":"209851.98", "side":"SELL", "hash":"9cc516e3a6a0c0ce486ce180501af87a0abc54ba", "best_bid":"0.085", "best_ask":"0.086"}], "timestamp":"1780150323480", "event_type":"price_change"}
PONG
{"market":"0x7976b8dbacf9077eb1453a62bcefd6ab2df199acd28aad276ff0d920d6992892", "price_changes":[{"asset_id":"4394372887385518214471608448209527405727552777602031099972143344338178308080", "price":"0.184", "size":"0", "side":"SELL", "hash":"cccd141f37c8aaf7b3fc1b59ebd4a0a0dbfa90e9", "best_bid":"0.167", "best_ask":"0.168"}, {"asset_id":"112680630004798425069810935278212000865453267506345451433803052322987302357330", "price":"0.816", "size":"0", "side":"BUY", "hash":"957533351a42aee8a961effe38d0dc5decdefd0c", "best_bid":"0.832", "best_ask":"0.833"}], "timestamp":"1780150324677", "event_type":"price_change"}
{"market":"0x7976b8dbacf9077eb1453a62bcefd6ab2df199acd28aad276ff0d920d6992892", "price_changes":[{"asset_id":"4394372887385518214471608448209527405727552777602031099972143344338178308080", "price":"0.184", "size":"49.77", "side":"SELL", "hash":"00b0d96366b83e2ee42c24a8e35b60df57531fcd", "best_bid":"0.167", "best_ask":"0.168"}, {"asset_id":"112680630004798425069810935278212000865453267506345451433803052322987302357330", "price":"0.816", "size":"49.77", "side":"BUY", "hash":"4aa06d7085215d5ed7ac03b7a915d77c7c396e17", "best_bid":"0.832", "best_ask":"0.833"}], "timestamp":"1780150325031", "event_type":"price_change"}
{"market":"0x7876851632c295043c66536150a304cb785abdf712ba8489d298c6e6926be106", "price_changes":[{"asset_id":"97239126062673310243763617236644392945530356142765650402171508075574679292913", "price":"0.011", "size":"1799038.22", "side":"SELL", "hash":"ba1b8070130cffcfb3454d80c3d05ac1c82e1b59", "best_bid":"0.01", "best_ask":"0.011"}, {"asset_id":"19291692040378529618917910599727571242305935029274321291612270922648172794670", "price":"0.989", "size":"1799038.22", "side":"BUY", "hash":"d8f4a05c0c8fb7393b1c28ac1053ca154277dda0", "best_bid":"0.989", "best_ask":"0.99"}], "timestamp":"1780150325119", "event_type":"price_change"}
{"market":"0x7876851632c295043c66536150a304cb785abdf712ba8489d298c6e6926be106", "price_changes":[{"asset_id":"19291692040378529618917910599727571242305935029274321291612270922648172794670", "price":"0.931", "size":"0", "side":"BUY", "hash":"6233e9f091fe63faf288755d44cc80662752b68b", "best_bid":"0.989", "best_ask":"0.99"}, {"asset_id":"97239126062673310243763617236644392945530356142765650402171508075574679292913", "price":"0.069", "size":"0", "side":"SELL", "hash":"102a672113eb32b5938a57a0ef9b8a7f4a2189a9", "best_bid":"0.01", "best_ask":"0.011"}], "timestamp":"1780150326545", "event_type":"price_change"}
{"market":"0x30d55d8124ee1e12dabe89201badc45669b81dff69e4ce44d961f32878ec178a", "price_changes":[{"asset_id":"52986718774908357330412653486471347449818893503063830313445318937088822580057", "price":"0.862", "size":"0", "side":"BUY", "hash":"f9445886defccf1c02658fe2c41f82262cceb27f", "best_bid":"0.909", "best_ask":"0.91"}, {"asset_id":"27576533317283401577758999384642760405921738493660383550832555714312627457443", "price":"0.138", "size":"0", "side":"SELL", "hash":"4e52f9775f1479fd935be045f818e3acfc03fdfd", "best_bid":"0.09", "best_ask":"0.091"}], "timestamp":"1780150326545", "event_type":"price_change"}
{"market":"0x4f3421fb2daf5cca7430ed8d8132463963081572d75434393a1808fdb8829fe8", "price_changes":[{"asset_id":"31940783580344558651011323787577288681658737625185216525249046282994042503801", "price":"0.836", "size":"125", "side":"BUY", "hash":"055ad4c3cf6d70375a8858089689fe76c7d0cf45", "best_bid":"0.899", "best_ask":"0.9"}, {"asset_id":"45415751658241142530386585138386640503488308219341470020075667342738719018629", "price":"0.164", "size":"125", "side":"SELL", "hash":"463278af4ae1adcd8c37eb4c4128d9ca8e7da682", "best_bid":"0.1", "best_ask":"0.101"}], "timestamp":"1780150327229", "event_type":"price_change"}
{"market":"0x9b6fef249040fd17e9c107955b37ac2c3e923509b6b0ff01cc463a331ddeb894", "price_changes":[{"asset_id":"32270411694523539495262303868629477861017829722282576458031815333486368239544", "price":"0.805", "size":"625", "side":"BUY", "hash":"b0d591be50abd7be05ec19c35186f5099761c726", "best_bid":"0.836", "best_ask":"0.837"}, {"asset_id":"108233603819467706476318984012158651931658302669301887462181073562758483842092", "price":"0.195", "size":"625", "side":"SELL", "hash":"776a50d0ec2bac0e1a760d01b5f12f9cbfa93cc7", "best_bid":"0.163", "best_ask":"0.164"}], "timestamp":"1780150328197", "event_type":"price_change"}
{"market":"0x375409bc5eeeff961e82b479caeccc20f33d15738e5bce1186d628aa3d9dfb1f", "price_changes":[{"asset_id":"77121637225348873006259930776623502125079210522997384841464684944292365296940", "price":"0.856", "size":"243.44", "side":"BUY", "hash":"0cac309c720251415702e3790d56ea016aeb05dd", "best_bid":"0.888", "best_ask":"0.889"}, {"asset_id":"115556263888245616435851357148058235707004733438163639091106356867234218207169", "price":"0.144", "size":"243.44", "side":"SELL", "hash":"4171e03e1d3f4d7e06a9804ef457e5a6287d65e5", "best_bid":"0.111", "best_ask":"0.112"}], "timestamp":"1780150328219", "event_type":"price_change"}
{"market":"0x4f3421fb2daf5cca7430ed8d8132463963081572d75434393a1808fdb8829fe8", "price_changes":[{"asset_id":"45415751658241142530386585138386640503488308219341470020075667342738719018629", "price":"0.1", "size":"139531.33", "side":"BUY", "hash":"901127f3a035a678fff8750a5e78bfbc1cc52a59", "best_bid":"0.1", "best_ask":"0.101"}, {"asset_id":"31940783580344558651011323787577288681658737625185216525249046282994042503801", "price":"0.9", "size":"139531.33", "side":"SELL", "hash":"5949c6f11b25bf65af32767e05017dc0f244b8ba", "best_bid":"0.899", "best_ask":"0.9"}], "timestamp":"1780150328869", "event_type":"price_change"}
{"market":"0x7976b8dbacf9077eb1453a62bcefd6ab2df199acd28aad276ff0d920d6992892", "price_changes":[{"asset_id":"112680630004798425069810935278212000865453267506345451433803052322987302357330", "price":"0.801", "size":"25", "side":"BUY", "hash":"eaa5bcffa36df58f0e40c15486d7ad31d1b9862a", "best_bid":"0.832", "best_ask":"0.833"}, {"asset_id":"4394372887385518214471608448209527405727552777602031099972143344338178308080", "price":"0.199", "size":"25", "side":"SELL", "hash":"c3d18ce0af66bf7ea6b3d6e54ac4b6716c4e5dde", "best_bid":"0.167", "best_ask":"0.168"}], "timestamp":"1780150329421", "event_type":"price_change"}
{"market":"0x0c4cd2055d6ea89354ffddc55d6dbcef9355748112ea952fc925f3db6a5c457f", "price_changes":[{"asset_id":"115428153746996892211798999366308897078723117634059783423375188043903703749062", "price":"0.871", "size":"209826.98", "side":"BUY", "hash":"5b49038b83af9f732996e6367fa9301b187789d4", "best_bid":"0.914", "best_ask":"0.915"}, {"asset_id":"18812649149814341758733697580460697418474693998558159483117100240528657629879", "price":"0.129", "size":"209826.98", "side":"SELL", "hash":"e7fc545434892ec0160da3635d91975088f57fd1", "best_bid":"0.085", "best_ask":"0.086"}], "timestamp":"1780150330113", "event_type":"price_change"}
{"market":"0x1595b4818eeb1ea1e0bec5de6f057218e557feee9b405a0e930d290384fa1d16", "price_changes":[{"asset_id":"45484070731786948288366703334552551439356529561722304542938873238430842810537", "price":"0.905", "size":"5307.69", "side":"BUY", "hash":"bb02cefc6543477f7f97afcb9a5b252dc358b978", "best_bid":"0.948", "best_ask":"0.949"}, {"asset_id":"81739002353269632749850710185641576213562066971072676369728657545679630163887", "price":"0.095", "size":"5307.69", "side":"SELL", "hash":"451dcff74eab39dea7e936fdaaeae6ae319f075e", "best_bid":"0.051", "best_ask":"0.052"}], "timestamp":"1780150330112", "event_type":"price_change"}
{"market":"0x1595b4818eeb1ea1e0bec5de6f057218e557feee9b405a0e930d290384fa1d16", "price_changes":[{"asset_id":"45484070731786948288366703334552551439356529561722304542938873238430842810537", "price":"0.897", "size":"0", "side":"BUY", "hash":"bb02cefc6543477f7f97afcb9a5b252dc358b978", "best_bid":"0.948", "best_ask":"0.949"}, {"asset_id":"81739002353269632749850710185641576213562066971072676369728657545679630163887", "price":"0.103", "size":"0", "side":"SELL", "hash":"451dcff74eab39dea7e936fdaaeae6ae319f075e", "best_bid":"0.051", "best_ask":"0.052"}], "timestamp":"1780150330112", "event_type":"price_change"}
{"market":"0x7876851632c295043c66536150a304cb785abdf712ba8489d298c6e6926be106", "price_changes":[{"asset_id":"19291692040378529618917910599727571242305935029274321291612270922648172794670", "price":"0.942", "size":"125", "side":"BUY", "hash":"beff4148b34e3e2ff61efd3ea497a121c0cf4c06", "best_bid":"0.989", "best_ask":"0.99"}, {"asset_id":"97239126062673310243763617236644392945530356142765650402171508075574679292913", "price":"0.058", "size":"125", "side":"SELL", "hash":"36e8ea802eca52694c2d50aeeca4edba210f86b4", "best_bid":"0.01", "best_ask":"0.011"}], "timestamp":"1780150330787", "event_type":"price_change"}
{"market":"0x30d55d8124ee1e12dabe89201badc45669b81dff69e4ce44d961f32878ec178a", "price_changes":[{"asset_id":"52986718774908357330412653486471347449818893503063830313445318937088822580057", "price":"0.862", "size":"125", "side":"BUY", "hash":"a5b4dfa5efbeadb6bf93f40cf2fcc8f89f5dc82f", "best_bid":"0.909", "best_ask":"0.91"}, {"asset_id":"27576533317283401577758999384642760405921738493660383550832555714312627457443", "price":"0.138", "size":"125", "side":"SELL", "hash":"1b3b224b9acc68dbe44b9a713dd881092432c16b", "best_bid":"0.09", "best_ask":"0.091"}], "timestamp":"1780150331039", "event_type":"price_change"}
{"market":"0x4f3421fb2daf5cca7430ed8d8132463963081572d75434393a1808fdb8829fe8", "price_changes":[{"asset_id":"31940783580344558651011323787577288681658737625185216525249046282994042503801", "price":"0.859", "size":"25", "side":"BUY", "hash":"c792024249118c609505cde6b58c021d9c984264", "best_bid":"0.899", "best_ask":"0.9"}, {"asset_id":"45415751658241142530386585138386640503488308219341470020075667342738719018629", "price":"0.141", "size":"25", "side":"SELL", "hash":"7744ec8ff66167d146228c606c08afc62e57ec30", "best_bid":"0.1", "best_ask":"0.101"}], "timestamp":"1780150331547", "event_type":"price_change"}
{"market":"0x9b6fef249040fd17e9c107955b37ac2c3e923509b6b0ff01cc463a331ddeb894", "price_changes":[{"asset_id":"32270411694523539495262303868629477861017829722282576458031815333486368239544", "price":"0.805", "size":"500", "side":"BUY", "hash":"7754080ab68d7086d03a649d7cb70e44c68b5ca8", "best_bid":"0.836", "best_ask":"0.837"}, {"asset_id":"108233603819467706476318984012158651931658302669301887462181073562758483842092", "price":"0.195", "size":"500", "side":"SELL", "hash":"7fb19454fffb403b386ff9d73d819b4218210fed", "best_bid":"0.163", "best_ask":"0.164"}], "timestamp":"1780150332194", "event_type":"price_change"}
{"market":"0x375409bc5eeeff961e82b479caeccc20f33d15738e5bce1186d628aa3d9dfb1f", "price_changes":[{"asset_id":"77121637225348873006259930776623502125079210522997384841464684944292365296940", "price":"0.856", "size":"118.44", "side":"BUY", "hash":"b02ef7a67f7623689e212d3b772951ed489b4b7b", "best_bid":"0.888", "best_ask":"0.889"}, {"asset_id":"115556263888245616435851357148058235707004733438163639091106356867234218207169", "price":"0.144", "size":"118.44", "side":"SELL", "hash":"b3b26411dca6942d95bf077f1f0dd82d2927ea62", "best_bid":"0.111", "best_ask":"0.112"}], "timestamp":"1780150332194", "event_type":"price_change"}
{"market":"0x1595b4818eeb1ea1e0bec5de6f057218e557feee9b405a0e930d290384fa1d16", "price_changes":[{"asset_id":"81739002353269632749850710185641576213562066971072676369728657545679630163887", "price":"0.054", "size":"9305.11", "side":"SELL", "hash":"fe26948fe400b1069dc0ce4968578c3a54c6d5ec", "best_bid":"0.051", "best_ask":"0.052"}, {"asset_id":"45484070731786948288366703334552551439356529561722304542938873238430842810537", "price":"0.946", "size":"9305.11", "side":"BUY", "hash":"af172cbbe871d1191c02735126716d3104c6a07f", "best_bid":"0.948", "best_ask":"0.949"}], "timestamp":"1780150333000", "event_type":"price_change"}
{"market":"0x1595b4818eeb1ea1e0bec5de6f057218e557feee9b405a0e930d290384fa1d16", "price_changes":[{"asset_id":"81739002353269632749850710185641576213562066971072676369728657545679630163887", "price":"0.054", "size":"9385.11", "side":"SELL", "hash":"e71c4c39e6c0955b50077f8dbfef1523f7a3cd0b", "best_bid":"0.051", "best_ask":"0.052"}, {"asset_id":"45484070731786948288366703334552551439356529561722304542938873238430842810537", "price":"0.946", "size":"9385.11", "side":"BUY", "hash":"ad6f018ff3b6ab3cd089021a35677d0eafbc090b", "best_bid":"0.948", "best_ask":"0.949"}], "timestamp":"1780150333088", "event_type":"price_change"}
{"market":"0x7976b8dbacf9077eb1453a62bcefd6ab2df199acd28aad276ff0d920d6992892", "price_changes":[{"asset_id":"112680630004798425069810935278212000865453267506345451433803052322987302357330", "price":"0.801", "size":"0", "side":"BUY", "hash":"1d5c507ea06e2c8aa53fe5fb2faad638f80031fd", "best_bid":"0.832", "best_ask":"0.833"}, {"asset_id":"4394372887385518214471608448209527405727552777602031099972143344338178308080", "price":"0.199", "size":"0", "side":"SELL", "hash":"91d1de87aca5959ea8c02bfe9a565701e5ea89c1", "best_bid":"0.167", "best_ask":"0.168"}], "timestamp":"1780150333126", "event_type":"price_change"}
