[{"market":"0x7976b8dbacf9077eb1453a62bcefd6ab2df199acd28aad276ff0d920d6992892","asset_id":"112680630004798425069810935278212000865453267506345451433803052322987302357330","timestamp":"1780150397502","hash":"2142bb23fcb8379725f62ad8a8153760c211fd79","bids":[{"price":"0.001","size":"13320371.6"},{"price":"0.002","size":"9.57"},{"price":"0.003","size":"156.25"},{"price":"0.004","size":"13.49"},{"price":"0.009","size":"8400"},{"price":"0.01","size":"7.03"},{"price":"0.012","size":"666666"},{"price":"0.013","size":"600000"},{"price":"0.014","size":"2534.99"},{"price":"0.016","size":"125.09"},{"price":"0.02","size":"5012"},{"price":"0.021","size":"3999.99"},{"price":"0.022","size":"5.22"},{"price":"0.05","size":"3109.99"},{"price":"0.051","size":"10.45"},{"price":"0.08","size":"3005"},{"price":"0.11","size":"1000"},{"price":"0.12","size":"1000"},{"price":"0.13","size":"1000"},{"price":"0.14","size":"999.99"},{"price":"0.15","size":"1000"},{"price":"0.16","size":"1000"},{"price":"0.168","size":"20"},{"price":"0.196","size":"301"},{"price":"0.2","size":"749.67"},{"price":"0.207","size":"400"},{"price":"0.208","size":"544.23"},{"price":"0.209","size":"300"},{"price":"0.21","size":"5.72"},{"price":"0.23","size":"408.6"},{"price":"0.25","size":"544.97"},{"price":"0.31","size":"305.55"},{"price":"0.32","size":"205"},{"price":"0.36","size":"231.25"},{"price":"0.384","size":"7223.76"},{"price":"0.39","size":"5"},{"price":"0.4","size":"34671.65"},{"price":"0.403","size":"1311"},{"price":"0.42","size":"211.4"},{"price":"0.421","size":"567.32"},{"price":"0.45","size":"510.51"},{"price":"0.451","size":"510.51"},{"price":"0.49","size":"220"},{"price":"0.5","size":"29664.87"},{"price":"0.501","size":"4216.7"},{"price":"0.502","size":"130"},{"price":"0.504","size":"457.83"},{"price":"0.505","size":"263.77"},{"price":"0.51","size":"264.58"},{"price":"0.52","size":"100"},{"price":"0.53","size":"100"},{"price":"0.54","size":"100"},{"price":"0.55","size":"726.73"},{"price":"0.56","size":"147"},{"price":"0.57","size":"100"},{"price":"0.58","size":"188.58"},{"price":"0.59","size":"110"},{"price":"0.598","size":"13.07"},{"price":"0.6","size":"26789.54"},{"price":"0.601","size":"274.25"},{"price":"0.602","size":"406.1"},{"price":"0.623","size":"5"},{"price":"0.628","size":"1000"},{"price":"0.63","size":"3300"},{"price":"0.65","size":"15514.62"},{"price":"0.654","size":"124.73"},{"price":"0.656","size":"122.73"},{"price":"0.658","size":"6141.34"},{"price":"0.66","size":"1046.85"},{"price":"0.664","size":"10100"},{"price":"0.666","size":"474.07"},{"price":"0.671","size":"100"},{"price":"0.68","size":"3006"},{"price":"0.681","size":"2095.26"},{"price":"0.688","size":"1000"},{"price":"0.691","size":"2359.94"},{"price":"0.696","size":"100"},{"price":"0.7","size":"282.21"},{"price":"0.701","size":"400"},{"price":"0.717","size":"100"},{"price":"0.718","size":"1000"},{"price":"0.72","size":"11.42"},{"price":"0.726","size":"16.03"},{"price":"0.738","size":"1100"},{"price":"0.748","size":"1000"},{"price":"0.75","size":"3963.47"},{"price":"0.751","size":"30"},{"price":"0.758","size":"1100"},{"price":"0.759","size":"100"},{"price":"0.76","size":"195"},{"price":"0.764","size":"7"},{"price":"0.765","size":"150"},{"price":"0.767","size":"5"},{"price":"0.768","size":"1000"},{"price":"0.77","size":"3823.69"},{"price":"0.774","size":"362.18"},{"price":"0.78","size":"225"},{"price":"0.782","size":"13.78"},{"price":"0.783","size":"16.02"},{"price":"0.784","size":"50"},{"price":"0.79","size":"50"},{"price":"0.794","size":"25.37"},{"price":"0.795","size":"10"},{"price":"0.796","size":"150"},{"price":"0.797","size":"25"},{"price":"0.798","size":"50"},{"price":"0.799","size":"382.17"},{"price":"0.8","size":"8356.84"},{"price":"0.802","size":"1019"},{"price":"0.803","size":"125"},{"price":"0.806","size":"181.36"},{"price":"0.807","size":"232.7"},{"price":"0.808","size":"30"},{"price":"0.809","size":"16007.3"},{"price":"0.812","size":"15279.71"},{"price":"0.814","size":"10"},{"price":"0.815","size":"405.96"},{"price":"0.816","size":"49.77"},{"price":"0.817","size":"50"},{"price":"0.818","size":"50.31"},{"price":"0.819","size":"1000"},{"price":"0.82","size":"12835.92"},{"price":"0.821","size":"41454.56"},{"price":"0.822","size":"930.5"},{"price":"0.823","size":"1627.85"},{"price":"0.824","size":"15407.48"},{"price":"0.825","size":"96558.27"},{"price":"0.826","size":"58022.86"},{"price":"0.827","size":"26925.87"},{"price":"0.828","size":"25913.26"},{"price":"0.829","size":"2301.97"},{"price":"0.83","size":"102074.74"},{"price":"0.831","size":"2054.06"},{"price":"0.832","size":"152269.84"}],"asks":[{"price":"0.999","size":"4816394"},{"price":"0.998","size":"2359"},{"price":"0.997","size":"100"},{"price":"0.996","size":"1111111"},{"price":"0.995","size":"255655"},{"price":"0.994","size":"100000"},{"price":"0.993","size":"10800"},{"price":"0.992","size":"10000"},{"price":"0.991","size":"10000"},{"price":"0.99","size":"10335"},{"price":"0.989","size":"10000"},{"price":"0.988","size":"10000"},{"price":"0.987","size":"5000"},{"price":"0.986","size":"5000"},{"price":"0.985","size":"5000"},{"price":"0.984","size":"5000"},{"price":"0.982","size":"5008.33"},{"price":"0.981","size":"5000"},{"price":"0.98","size":"7380"},{"price":"0.979","size":"3000"},{"price":"0.978","size":"3000"},{"price":"0.977","size":"3000"},{"price":"0.976","size":"3000"},{"price":"0.975","size":"3000"},{"price":"0.974","size":"3000"},{"price":"0.973","size":"3000"},{"price":"0.972","size":"3000"},{"price":"0.959","size":"731.7"},{"price":"0.951","size":"100"},{"price":"0.95","size":"56135"},{"price":"0.931","size":"20"},{"price":"0.93","size":"30"},{"price":"0.927","size":"30"},{"price":"0.926","size":"30"},{"price":"0.9","size":"10035"},{"price":"0.89","size":"91.09"},{"price":"0.889","size":"1077.83"},{"price":"0.88","size":"11038.99"},{"price":"0.879","size":"5"},{"price":"0.878","size":"93.8"},{"price":"0.877","size":"5"},{"price":"0.876","size":"5"},{"price":"0.875","size":"5"},{"price":"0.874","size":"5"},{"price":"0.873","size":"5"},{"price":"0.872","size":"5"},{"price":"0.871","size":"5"},{"price":"0.87","size":"165"},{"price":"0.869","size":"5"},{"price":"0.868","size":"105"},{"price":"0.867","size":"5"},{"price":"0.866","size":"156.01"},{"price":"0.865","size":"5"},{"price":"0.864","size":"5"},{"price":"0.863","size":"5"},{"price":"0.862","size":"5"},{"price":"0.861","size":"5"},{"price":"0.86","size":"2179.99"},{"price":"0.859","size":"6015"},{"price":"0.858","size":"5005"},{"price":"0.857","size":"2505"},{"price":"0.856","size":"15"},{"price":"0.855","size":"5"},{"price":"0.854","size":"6206.58"},{"price":"0.853","size":"3015"},{"price":"0.852","size":"7875"},{"price":"0.851","size":"3105"},{"price":"0.85","size":"47190"},{"price":"0.849","size":"26520"},{"price":"0.848","size":"4713.32"},{"price":"0.847","size":"18384.44"},{"price":"0.846","size":"7101.99"},{"price":"0.845","size":"2090"},{"price":"0.844","size":"3989.08"},{"price":"0.843","size":"30663.44"},{"price":"0.842","size":"7106.04"},{"price":"0.841","size":"538.42"},{"price":"0.84","size":"12647.71"},{"price":"0.839","size":"759"},{"price":"0.838","size":"2708.81"},{"price":"0.837","size":"3792.11"},{"price":"0.836","size":"29110.34"},{"price":"0.835","size":"26149.08"},{"price":"0.834","size":"4697.83"},{"price":"0.833","size":"64310.14"}],"tick_size":"0.001","event_type":"book","last_trade_price":"0.168"},{"market":"0x0c4cd2055d6ea89354ffddc55d6dbcef9355748112ea952fc925f3db6a5c457f","asset_id":"115428153746996892211798999366308897078723117634059783423375188043903703749062","timestamp":"1780150400079","hash":"cb9e6141dd20db67d6f29f7c426e36f7cae33ffe","bids":[{"price":"0.001","size":"19311591.2"},{"price":"0.002","size":"55.07"},{"price":"0.013","size":"1716.7"},{"price":"0.015","size":"1904.95"},{"price":"0.016","size":"11.03"},{"price":"0.036","size":"36000"},{"price":"0.04","size":"333350"},{"price":"0.041","size":"300000"},{"price":"0.042","size":"800"},{"price":"0.05","size":"14660"},{"price":"0.051","size":"10.53"},{"price":"0.09","size":"19"},{"price":"0.15","size":"127.23"},{"price":"0.22","size":"128.36"},{"price":"0.221","size":"5.26"},{"price":"0.228","size":"131.57"},{"price":"0.27","size":"1904.95"},{"price":"0.39","size":"5"},{"price":"0.4","size":"34375"},{"price":"0.401","size":"10000"},{"price":"0.402","size":"1492"},{"price":"0.45","size":"22.5"},{"price":"0.5","size":"26767.96"},{"price":"0.501","size":"3000"},{"price":"0.502","size":"1077.83"},{"price":"0.6","size":"21522.45"},{"price":"0.601","size":"2000"},{"price":"0.603","size":"1164"},{"price":"0.623","size":"5"},{"price":"0.64","size":"1211"},{"price":"0.65","size":"27012.52"},{"price":"0.66","size":"46.4"},{"price":"0.696","size":"5000"},{"price":"0.7","size":"557.74"},{"price":"0.701","size":"30"},{"price":"0.73","size":"6500"},{"price":"0.738","size":"1000"},{"price":"0.74","size":"100"},{"price":"0.75","size":"3383.18"},{"price":"0.752","size":"2906.99"},{"price":"0.755","size":"125"},{"price":"0.767","size":"5"},{"price":"0.768","size":"1000"},{"price":"0.778","size":"100"},{"price":"0.779","size":"400"},{"price":"0.798","size":"1000"},{"price":"0.799","size":"100"},{"price":"0.8","size":"12081.05"},{"price":"0.801","size":"2095.26"},{"price":"0.81","size":"100"},{"price":"0.818","size":"1000"},{"price":"0.82","size":"183.62"},{"price":"0.828","size":"1000"},{"price":"0.83","size":"2373"},{"price":"0.838","size":"1268.53"},{"price":"0.84","size":"12150"},{"price":"0.841","size":"100"},{"price":"0.843","size":"100"},{"price":"0.845","size":"144"},{"price":"0.848","size":"1000"},{"price":"0.85","size":"4045.57"},{"price":"0.855","size":"11634.31"},{"price":"0.856","size":"7"},{"price":"0.86","size":"716"},{"price":"0.861","size":"144283.19"},{"price":"0.862","size":"100"},{"price":"0.867","size":"438"},{"price":"0.868","size":"50"},{"price":"0.87","size":"996"},{"price":"0.871","size":"209851.98"},{"price":"0.875","size":"1020.47"},{"price":"0.877","size":"25"},{"price":"0.878","size":"45"},{"price":"0.879","size":"75"},{"price":"0.88","size":"15096.64"},{"price":"0.881","size":"19"},{"price":"0.882","size":"648.12"},{"price":"0.883","size":"125"},{"price":"0.884","size":"10789.73"},{"price":"0.886","size":"230.12"},{"price":"0.887","size":"1395.49"},{"price":"0.888","size":"236.32"},{"price":"0.889","size":"1186.28"},{"price":"0.89","size":"6421.54"},{"price":"0.891","size":"5069.15"},{"price":"0.892","size":"52728.52"},{"price":"0.894","size":"355.22"},{"price":"0.895","size":"5319.74"},{"price":"0.896","size":"52728.51"},{"price":"0.897","size":"114.3"},{"price":"0.898","size":"229.06"},{"price":"0.899","size":"27080.06"},{"price":"0.9","size":"35120.43"},{"price":"0.901","size":"34710.7"},{"price":"0.902","size":"84437.86"},{"price":"0.903","size":"1730.09"},{"price":"0.904","size":"1129.06"},{"price":"0.905","size":"2510"},{"price":"0.906","size":"229.06"},{"price":"0.907","size":"33247.87"},{"price":"0.908","size":"15415.06"},{"price":"0.909","size":"8064.56"},{"price":"0.91","size":"36872.79"},{"price":"0.911","size":"25024.11"},{"price":"0.912","size":"15129.46"},{"price":"0.913","size":"59775.19"},{"price":"0.914","size":"171104.43"}],"asks":[{"price":"0.999","size":"4912713.42"},{"price":"0.998","size":"1003359"},{"price":"0.997","size":"1111111"},{"price":"0.996","size":"55555"},{"price":"0.995","size":"500"},{"price":"0.994","size":"6000"},{"price":"0.99","size":"11200"},{"price":"0.985","size":"5.65"},{"price":"0.984","size":"5000000"},{"price":"0.983","size":"800"},{"price":"0.98","size":"5050"},{"price":"0.979","size":"2300"},{"price":"0.97","size":"4330"},{"price":"0.969","size":"367.48"},{"price":"0.959","size":"720"},{"price":"0.958","size":"725.45"},{"price":"0.952","size":"70"},{"price":"0.951","size":"71"},{"price":"0.95","size":"5879.09"},{"price":"0.93","size":"513068.11"},{"price":"0.929","size":"6800"},{"price":"0.928","size":"437"},{"price":"0.927","size":"333"},{"price":"0.925","size":"1245"},{"price":"0.924","size":"5000"},{"price":"0.922","size":"11231.85"},{"price":"0.921","size":"127"},{"price":"0.92","size":"44813"},{"price":"0.919","size":"39326.98"},{"price":"0.918","size":"47132.51"},{"price":"0.917","size":"184952.96"},{"price":"0.916","size":"13437.85"},{"price":"0.915","size":"110726.44"}],"tick_size":"0.001","event_type":"book","last_trade_price":"0.086"},{"market":"0x7876851632c295043c66536150a304cb785abdf712ba8489d298c6e6926be106","asset_id":"19291692040378529618917910599727571242305935029274321291612270922648172794670","timestamp":"1780150395140","hash":"03176bbc5d7ea65f0655c13a9de6e030f262f05f","bids":[{"price":"0.001","size":"21002524.32"},{"price":"0.002","size":"90011.18"},{"price":"0.003","size":"800"},{"price":"0.004","size":"70.1"},{"price":"0.031","size":"500"},{"price":"0.05","size":"40"},{"price":"0.051","size":"9.59"},{"price":"0.1","size":"2500"},{"price":"0.2","size":"1000"},{"price":"0.201","size":"5.94"},{"price":"0.247","size":"121.45"},{"price":"0.3","size":"600"},{"price":"0.4","size":"34625"},{"price":"0.401","size":"18000"},{"price":"0.45","size":"100"},{"price":"0.451","size":"1330"},{"price":"0.5","size":"25000"},{"price":"0.501","size":"12000"},{"price":"0.51","size":"7.97"},{"price":"0.6","size":"20833.33"},{"price":"0.65","size":"15384.62"},{"price":"0.652","size":"2095.26"},{"price":"0.653","size":"1103"},{"price":"0.75","size":"100"},{"price":"0.778","size":"227.27"},{"price":"0.808","size":"8"},{"price":"0.841","size":"1000"},{"price":"0.85","size":"445.83"},{"price":"0.851","size":"400"},{"price":"0.871","size":"1000"},{"price":"0.891","size":"1000"},{"price":"0.9","size":"90.9"},{"price":"0.901","size":"1000"},{"price":"0.902","size":"30"},{"price":"0.904","size":"8"},{"price":"0.911","size":"1100"},{"price":"0.92","size":"1000"},{"price":"0.921","size":"1000"},{"price":"0.93","size":"3800"},{"price":"0.931","size":"125"},{"price":"0.935","size":"3500"},{"price":"0.936","size":"25"},{"price":"0.938","size":"3500"},{"price":"0.94","size":"2000"},{"price":"0.941","size":"50"},{"price":"0.943","size":"3000"},{"price":"0.944","size":"2000"},{"price":"0.95","size":"3309.92"},{"price":"0.951","size":"2045"},{"price":"0.952","size":"3833.33"},{"price":"0.953","size":"75"},{"price":"0.954","size":"19"},{"price":"0.955","size":"3067"},{"price":"0.956","size":"125"},{"price":"0.957","size":"3000"},{"price":"0.958","size":"3000"},{"price":"0.96","size":"232.7"},{"price":"0.961","size":"3007.2"},{"price":"0.964","size":"5000"},{"price":"0.965","size":"15430.62"},{"price":"0.967","size":"10424"},{"price":"0.968","size":"4287.08"},{"price":"0.97","size":"18916.9"},{"price":"0.971","size":"3000"},{"price":"0.972","size":"14648"},{"price":"0.974","size":"5000"},{"price":"0.975","size":"10372.72"},{"price":"0.976","size":"5500"},{"price":"0.978","size":"17239.4"},{"price":"0.979","size":"6000"},{"price":"0.98","size":"14721.53"},{"price":"0.981","size":"2790.7"},{"price":"0.982","size":"62681.81"},{"price":"0.983","size":"110028.15"},{"price":"0.984","size":"118582.98"},{"price":"0.985","size":"107389"},{"price":"0.986","size":"10"},{"price":"0.987","size":"8338.33"},{"price":"0.988","size":"4839211.94"},{"price":"0.989","size":"1799038.22"}],"asks":[{"price":"0.999","size":"3862270"},{"price":"0.998","size":"1322096"},{"price":"0.997","size":"451830"},{"price":"0.996","size":"72622"},{"price":"0.995","size":"30650"},{"price":"0.994","size":"11473.99"},{"price":"0.993","size":"31428.57"},{"price":"0.992","size":"328294"},{"price":"0.991","size":"247324.61"},{"price":"0.99","size":"1180706.14"}],"tick_size":"0.001","event_type":"book","last_trade_price":"0.011"},{"market":"0x4f3421fb2daf5cca7430ed8d8132463963081572d75434393a1808fdb8829fe8","asset_id":"31940783580344558651011323787577288681658737625185216525249046282994042503801","timestamp":"1780150402751","hash":"0676d2ffe7314b6e58bc6e31e6a0b5148c97125f","bids":[{"price":"0.001","size":"21074238.91"},{"price":"0.002","size":"37.76"},{"price":"0.01","size":"25929.6"},{"price":"0.011","size":"6.21"},{"price":"0.014","size":"1111111"},{"price":"0.015","size":"1000000"},{"price":"0.02","size":"36500"},{"price":"0.021","size":"800"},{"price":"0.022","size":"11.19"},{"price":"0.05","size":"40"},{"price":"0.077","size":"2000"},{"price":"0.078","size":"5.64"},{"price":"0.1","size":"2254.88"},{"price":"0.11","size":"1016"},{"price":"0.12","size":"1021"},{"price":"0.13","size":"1000"},{"price":"0.14","size":"999.99"},{"price":"0.15","size":"1153.71"},{"price":"0.2","size":"409.2"},{"price":"0.224","size":"433.92"},{"price":"0.225","size":"5.14"},{"price":"0.25","size":"453.7"},{"price":"0.253","size":"200"},{"price":"0.254","size":"200"},{"price":"0.27","size":"200"},{"price":"0.28","size":"200"},{"price":"0.31","size":"200"},{"price":"0.33","size":"215.15"},{"price":"0.34","size":"199.99"},{"price":"0.35","size":"102.46"},{"price":"0.36","size":"228"},{"price":"0.361","size":"100"},{"price":"0.4","size":"34637.29"},{"price":"0.401","size":"5000"},{"price":"0.41","size":"200"},{"price":"0.42","size":"200"},{"price":"0.43","size":"200"},{"price":"0.44","size":"200"},{"price":"0.45","size":"354.02"},{"price":"0.46","size":"200"},{"price":"0.461","size":"1077.83"},{"price":"0.5","size":"25496.62"},{"price":"0.501","size":"5100"},{"price":"0.51","size":"205.76"},{"price":"0.511","size":"100"},{"price":"0.52","size":"100"},{"price":"0.53","size":"100"},{"price":"0.54","size":"100"},{"price":"0.55","size":"100"},{"price":"0.56","size":"100"},{"price":"0.57","size":"100"},{"price":"0.58","size":"100"},{"price":"0.6","size":"21059.73"},{"price":"0.61","size":"100"},{"price":"0.62","size":"111.9"},{"price":"0.632","size":"5322.31"},{"price":"0.64","size":"28.8"},{"price":"0.643","size":"100"},{"price":"0.65","size":"16970.62"},{"price":"0.66","size":"100"},{"price":"0.67","size":"100"},{"price":"0.673","size":"100"},{"price":"0.674","size":"100"},{"price":"0.678","size":"100"},{"price":"0.68","size":"410.68"},{"price":"0.69","size":"100"},{"price":"0.7","size":"422.3"},{"price":"0.703","size":"100"},{"price":"0.704","size":"100"},{"price":"0.708","size":"100"},{"price":"0.71","size":"61.7"},{"price":"0.725","size":"1000"},{"price":"0.733","size":"100"},{"price":"0.75","size":"3192.15"},{"price":"0.755","size":"1000"},{"price":"0.76","size":"341.8"},{"price":"0.763","size":"100"},{"price":"0.764","size":"100"},{"price":"0.767","size":"100"},{"price":"0.768","size":"400"},{"price":"0.777","size":"100"},{"price":"0.78","size":"258.06"},{"price":"0.781","size":"100"},{"price":"0.785","size":"1000"},{"price":"0.79","size":"47.6"},{"price":"0.798","size":"1781.45"},{"price":"0.8","size":"246868.85"},{"price":"0.801","size":"100"},{"price":"0.803","size":"100"},{"price":"0.805","size":"1000"},{"price":"0.815","size":"1000"},{"price":"0.818","size":"30"},{"price":"0.819","size":"100"},{"price":"0.824","size":"100"},{"price":"0.825","size":"1000"},{"price":"0.83","size":"39.23"},{"price":"0.835","size":"1000"},{"price":"0.84","size":"356.45"},{"price":"0.845","size":"100"},{"price":"0.849","size":"2441.52"},{"price":"0.85","size":"19727.35"},{"price":"0.851","size":"800"},{"price":"0.853","size":"118.33"},{"price":"0.855","size":"13.33"},{"price":"0.858","size":"35.21"},{"price":"0.86","size":"34.6"},{"price":"0.861","size":"45"},{"price":"0.866","size":"75"},{"price":"0.867","size":"17.97"},{"price":"0.868","size":"144"},{"price":"0.87","size":"4000"},{"price":"0.872","size":"232.7"},{"price":"0.873","size":"7.26"},{"price":"0.875","size":"170"},{"price":"0.88","size":"197"},{"price":"0.882","size":"1000"},{"price":"0.885","size":"925.73"},{"price":"0.886","size":"100"},{"price":"0.887","size":"100"},{"price":"0.888","size":"100"},{"price":"0.889","size":"100"},{"price":"0.89","size":"16564.23"},{"price":"0.891","size":"1343.33"},{"price":"0.892","size":"7071.71"},{"price":"0.893","size":"15257.35"},{"price":"0.894","size":"120752.78"},{"price":"0.896","size":"28940.81"},{"price":"0.897","size":"18183.31"},{"price":"0.898","size":"126782.5"},{"price":"0.899","size":"98191.81"}],"asks":[{"price":"0.999","size":"4715397.01"},{"price":"0.998","size":"14"},{"price":"0.997","size":"1112792"},{"price":"0.996","size":"55564"},{"price":"0.995","size":"10009"},{"price":"0.994","size":"11109"},{"price":"0.993","size":"10009"},{"price":"0.992","size":"10009"},{"price":"0.991","size":"5009"},{"price":"0.99","size":"6209"},{"price":"0.989","size":"5009"},{"price":"0.988","size":"5009"},{"price":"0.987","size":"4309"},{"price":"0.986","size":"3009"},{"price":"0.985","size":"5009"},{"price":"0.984","size":"3009"},{"price":"0.983","size":"3009"},{"price":"0.982","size":"9"},{"price":"0.981","size":"5009"},{"price":"0.98","size":"6234"},{"price":"0.979","size":"4008.99"},{"price":"0.978","size":"4009"},{"price":"0.977","size":"4009"},{"price":"0.976","size":"3009"},{"price":"0.975","size":"3009"},{"price":"0.974","size":"4009"},{"price":"0.973","size":"3009"},{"price":"0.972","size":"4009"},{"price":"0.971","size":"2009"},{"price":"0.97","size":"4209"},{"price":"0.969","size":"2509"},{"price":"0.968","size":"2652.85"},{"price":"0.967","size":"2509"},{"price":"0.966","size":"2509"},{"price":"0.965","size":"9"},{"price":"0.964","size":"9"},{"price":"0.963","size":"9"},{"price":"0.962","size":"609"},{"price":"0.961","size":"9"},{"price":"0.96","size":"259"},{"price":"0.959","size":"9"},{"price":"0.958","size":"9"},{"price":"0.957","size":"9"},{"price":"0.956","size":"9"},{"price":"0.955","size":"9"},{"price":"0.954","size":"9"},{"price":"0.953","size":"9"},{"price":"0.952","size":"9"},{"price":"0.951","size":"9"},{"price":"0.95","size":"279"},{"price":"0.949","size":"10009"},{"price":"0.948","size":"9"},{"price":"0.947","size":"9"},{"price":"0.946","size":"9"},{"price":"0.945","size":"309"},{"price":"0.944","size":"9"},{"price":"0.943","size":"9"},{"price":"0.942","size":"9"},{"price":"0.941","size":"9"},{"price":"0.94","size":"19"},{"price":"0.939","size":"202"},{"price":"0.938","size":"10009"},{"price":"0.937","size":"5009"},{"price":"0.936","size":"7509"},{"price":"0.935","size":"5151"},{"price":"0.934","size":"6209"},{"price":"0.933","size":"4529"},{"price":"0.932","size":"2856.05"},{"price":"0.931","size":"2772.73"},{"price":"0.93","size":"13367.54"},{"price":"0.929","size":"1564"},{"price":"0.928","size":"5464.3"},{"price":"0.927","size":"1109"},{"price":"0.926","size":"357402.07"},{"price":"0.925","size":"36562.67"},{"price":"0.924","size":"5803.29"},{"price":"0.923","size":"434.15"},{"price":"0.922","size":"512.12"},{"price":"0.921","size":"25029"},{"price":"0.92","size":"15376.09"},{"price":"0.919","size":"1633.99"},{"price":"0.918","size":"14672.52"},{"price":"0.917","size":"3381.41"},{"price":"0.916","size":"9"},{"price":"0.915","size":"826.33"},{"price":"0.914","size":"22609"},{"price":"0.913","size":"4605.61"},{"price":"0.912","size":"1782.17"},{"price":"0.911","size":"570.79"},{"price":"0.91","size":"5344.55"},{"price":"0.909","size":"958.45"},{"price":"0.908","size":"909"},{"price":"0.907","size":"1609"},{"price":"0.906","size":"2240.91"},{"price":"0.905","size":"3928.99"},{"price":"0.904","size":"2009"},{"price":"0.903","size":"7534.46"},{"price":"0.902","size":"1468"},{"price":"0.901","size":"922.07"},{"price":"0.9","size":"139531.33"}],"tick_size":"0.001","event_type":"book","last_trade_price":"0.101"},{"market":"0x9b6fef249040fd17e9c107955b37ac2c3e923509b6b0ff01cc463a331ddeb894","asset_id":"32270411694523539495262303868629477861017829722282576458031815333486368239544","timestamp":"1780150402669","hash":"13384bfd7a0245574081bce03b2a34ca06e15e4f","bids":[{"price":"0.001","size":"12219098.99"},{"price":"0.002","size":"178.57"},{"price":"0.003","size":"21.08"},{"price":"0.009","size":"18000"},{"price":"0.01","size":"100"},{"price":"0.011","size":"5.62"},{"price":"0.012","size":"1111111"},{"price":"0.013","size":"900000"},{"price":"0.014","size":"1300"},{"price":"0.015","size":"500"},{"price":"0.02","size":"99"},{"price":"0.021","size":"6.95"},{"price":"0.05","size":"246.52"},{"price":"0.051","size":"10.84"},{"price":"0.09","size":"5.98"},{"price":"0.1","size":"15"},{"price":"0.12","size":"5005"},{"price":"0.121","size":"12000"},{"price":"0.15","size":"67.49"},{"price":"0.178","size":"289.7"},{"price":"0.2","size":"796.33"},{"price":"0.209","size":"143.54"},{"price":"0.22","size":"100.48"},{"price":"0.221","size":"5.22"},{"price":"0.25","size":"3597"},{"price":"0.251","size":"6000"},{"price":"0.29","size":"9.75"},{"price":"0.3","size":"55.88"},{"price":"0.315","size":"1459.85"},{"price":"0.33","size":"1363.34"},{"price":"0.331","size":"3000"},{"price":"0.34","size":"5"},{"price":"0.35","size":"2159.92"},{"price":"0.4","size":"34587.44"},{"price":"0.401","size":"3000"},{"price":"0.47","size":"5688.73"},{"price":"0.5","size":"36499.86"},{"price":"0.502","size":"1529.99"},{"price":"0.503","size":"14000"},{"price":"0.51","size":"90.9"},{"price":"0.511","size":"1202.04"},{"price":"0.55","size":"513.44"},{"price":"0.56","size":"111.11"},{"price":"0.562","size":"655.13"},{"price":"0.563","size":"65.06"},{"price":"0.57","size":"3964.15"},{"price":"0.6","size":"22272.15"},{"price":"0.624","size":"27.04"},{"price":"0.631","size":"1000"},{"price":"0.636","size":"105.03"},{"price":"0.638","size":"23.57"},{"price":"0.64","size":"4479.3"},{"price":"0.648","size":"7.39"},{"price":"0.65","size":"15415.61"},{"price":"0.651","size":"2155.26"},{"price":"0.661","size":"1000"},{"price":"0.67","size":"18.11"},{"price":"0.672","size":"482.66"},{"price":"0.68","size":"38"},{"price":"0.691","size":"1000"},{"price":"0.699","size":"100"},{"price":"0.7","size":"456.89"},{"price":"0.701","size":"400"},{"price":"0.72","size":"267.14"},{"price":"0.721","size":"1000"},{"price":"0.741","size":"1100"},{"price":"0.75","size":"1422.54"},{"price":"0.751","size":"1201"},{"price":"0.752","size":"1367"},{"price":"0.754","size":"334.02"},{"price":"0.756","size":"30"},{"price":"0.76","size":"302"},{"price":"0.761","size":"1000"},{"price":"0.762","size":"200"},{"price":"0.77","size":"3800"},{"price":"0.771","size":"1000"},{"price":"0.777","size":"11.23"},{"price":"0.779","size":"334.02"},{"price":"0.78","size":"237"},{"price":"0.781","size":"125"},{"price":"0.783","size":"100"},{"price":"0.786","size":"15"},{"price":"0.788","size":"10"},{"price":"0.789","size":"5555.55"},{"price":"0.79","size":"122"},{"price":"0.791","size":"50"},{"price":"0.792","size":"25"},{"price":"0.793","size":"10"},{"price":"0.794","size":"1000"},{"price":"0.795","size":"10"},{"price":"0.8","size":"17681.66"},{"price":"0.801","size":"100"},{"price":"0.802","size":"64"},{"price":"0.803","size":"35"},{"price":"0.804","size":"75"},{"price":"0.805","size":"500"},{"price":"0.806","size":"169"},{"price":"0.807","size":"135"},{"price":"0.808","size":"675.7"},{"price":"0.809","size":"2027"},{"price":"0.81","size":"7109.61"},{"price":"0.811","size":"38219.61"},{"price":"0.812","size":"1708.3"},{"price":"0.813","size":"782.67"},{"price":"0.814","size":"1703.37"},{"price":"0.815","size":"5571.35"},{"price":"0.816","size":"10909.83"},{"price":"0.817","size":"7549.45"},{"price":"0.818","size":"3441.57"},{"price":"0.819","size":"340"},{"price":"0.82","size":"5287.95"},{"price":"0.821","size":"1694.21"},{"price":"0.822","size":"22719.93"},{"price":"0.823","size":"44358.4"},{"price":"0.824","size":"47073"},{"price":"0.825","size":"47040.85"},{"price":"0.826","size":"200"},{"price":"0.827","size":"654.36"},{"price":"0.829","size":"20206.62"},{"price":"0.83","size":"26050"},{"price":"0.831","size":"3000"},{"price":"0.833","size":"3864.75"},{"price":"0.834","size":"32172"},{"price":"0.835","size":"246275.86"},{"price":"0.836","size":"35519.13"}],"asks":[{"price":"0.999","size":"2260279"},{"price":"0.998","size":"1557248"},{"price":"0.997","size":"1001200"},{"price":"0.996","size":"55555"},{"price":"0.995","size":"90100"},{"price":"0.99","size":"720"},{"price":"0.985","size":"5.01"},{"price":"0.984","size":"555555"},{"price":"0.983","size":"60000"},{"price":"0.982","size":"105435.9"},{"price":"0.981","size":"800"},{"price":"0.98","size":"5430"},{"price":"0.978","size":"3000"},{"price":"0.976","size":"3000"},{"price":"0.974","size":"3000"},{"price":"0.972","size":"3000"},{"price":"0.97","size":"3000"},{"price":"0.968","size":"3000"},{"price":"0.966","size":"3000"},{"price":"0.96","size":"750"},{"price":"0.951","size":"100"},{"price":"0.95","size":"150"},{"price":"0.94","size":"10"},{"price":"0.937","size":"30"},{"price":"0.936","size":"30"},{"price":"0.935","size":"10"},{"price":"0.934","size":"50"},{"price":"0.931","size":"10"},{"price":"0.93","size":"50"},{"price":"0.926","size":"50"},{"price":"0.925","size":"35"},{"price":"0.924","size":"30"},{"price":"0.923","size":"20"},{"price":"0.922","size":"20"},{"price":"0.921","size":"20"},{"price":"0.92","size":"140"},{"price":"0.91","size":"10100"},{"price":"0.905","size":"105.2"},{"price":"0.9","size":"10096.92"},{"price":"0.899","size":"1076.68"},{"price":"0.893","size":"37.72"},{"price":"0.892","size":"40"},{"price":"0.89","size":"145.45"},{"price":"0.889","size":"5000"},{"price":"0.885","size":"9"},{"price":"0.884","size":"90"},{"price":"0.88","size":"203.33"},{"price":"0.879","size":"7500"},{"price":"0.878","size":"5000"},{"price":"0.877","size":"100"},{"price":"0.875","size":"956.59"},{"price":"0.874","size":"2500"},{"price":"0.87","size":"328"},{"price":"0.869","size":"2537"},{"price":"0.868","size":"17"},{"price":"0.867","size":"1903.93"},{"price":"0.866","size":"27"},{"price":"0.865","size":"37"},{"price":"0.864","size":"5017"},{"price":"0.863","size":"3218"},{"price":"0.862","size":"7"},{"price":"0.861","size":"7"},{"price":"0.86","size":"717"},{"price":"0.859","size":"7"},{"price":"0.858","size":"507"},{"price":"0.857","size":"97"},{"price":"0.856","size":"7"},{"price":"0.855","size":"707"},{"price":"0.854","size":"7"},{"price":"0.853","size":"16722"},{"price":"0.852","size":"7"},{"price":"0.851","size":"707"},{"price":"0.85","size":"10136.66"},{"price":"0.849","size":"877"},{"price":"0.848","size":"107"},{"price":"0.847","size":"27"},{"price":"0.846","size":"257"},{"price":"0.845","size":"3060.64"},{"price":"0.844","size":"20417"},{"price":"0.843","size":"8647.14"},{"price":"0.842","size":"77"},{"price":"0.841","size":"1056.6"},{"price":"0.84","size":"18638"},{"price":"0.839","size":"39045"},{"price":"0.838","size":"7722.83"},{"price":"0.837","size":"28495.52"}],"tick_size":"0.001","event_type":"book","last_trade_price":"0.164"},{"market":"0x1595b4818eeb1ea1e0bec5de6f057218e557feee9b405a0e930d290384fa1d16","asset_id":"45484070731786948288366703334552551439356529561722304542938873238430842810537","timestamp":"1780150402660","hash":"44aca078f41759cf7993ec825f7b06fa5f4d20d6","bids":[{"price":"0.001","size":"21202713.62"},{"price":"0.002","size":"105"},{"price":"0.003","size":"32.43"},{"price":"0.01","size":"181.81"},{"price":"0.013","size":"1698.4"},{"price":"0.014","size":"17.32"},{"price":"0.05","size":"2236"},{"price":"0.054","size":"155555"},{"price":"0.055","size":"150000"},{"price":"0.056","size":"800"},{"price":"0.057","size":"5.16"},{"price":"0.1","size":"2500"},{"price":"0.14","size":"27"},{"price":"0.2","size":"1000"},{"price":"0.201","size":"6.67"},{"price":"0.237","size":"126.58"},{"price":"0.3","size":"600"},{"price":"0.348","size":"211.53"},{"price":"0.39","size":"5"},{"price":"0.4","size":"34625"},{"price":"0.401","size":"10000"},{"price":"0.402","size":"1492"},{"price":"0.5","size":"25100"},{"price":"0.501","size":"5000"},{"price":"0.51","size":"87.55"},{"price":"0.511","size":"1103"},{"price":"0.58","size":"17.54"},{"price":"0.584","size":"300"},{"price":"0.6","size":"20859.33"},{"price":"0.61","size":"76.92"},{"price":"0.623","size":"5"},{"price":"0.65","size":"15443.05"},{"price":"0.651","size":"2095.26"},{"price":"0.7","size":"780"},{"price":"0.701","size":"437"},{"price":"0.712","size":"50"},{"price":"0.72","size":"18"},{"price":"0.74","size":"476.92"},{"price":"0.75","size":"2198.07"},{"price":"0.751","size":"400"},{"price":"0.767","size":"5"},{"price":"0.77","size":"43.3"},{"price":"0.78","size":"192.53"},{"price":"0.792","size":"1100"},{"price":"0.8","size":"1307.15"},{"price":"0.801","size":"1500"},{"price":"0.82","size":"12201.05"},{"price":"0.821","size":"400"},{"price":"0.83","size":"1079.99"},{"price":"0.831","size":"1000"},{"price":"0.832","size":"50"},{"price":"0.838","size":"1913.7"},{"price":"0.84","size":"288"},{"price":"0.848","size":"33"},{"price":"0.85","size":"13781.98"},{"price":"0.851","size":"1000"},{"price":"0.855","size":"327.86"},{"price":"0.856","size":"7"},{"price":"0.86","size":"334.14"},{"price":"0.861","size":"1000"},{"price":"0.862","size":"30"},{"price":"0.863","size":"125"},{"price":"0.869","size":"20"},{"price":"0.87","size":"1713.81"},{"price":"0.871","size":"1100"},{"price":"0.878","size":"163.93"},{"price":"0.88","size":"613.23"},{"price":"0.881","size":"1000"},{"price":"0.885","size":"240"},{"price":"0.887","size":"370.37"},{"price":"0.89","size":"5031.81"},{"price":"0.896","size":"1592.3"},{"price":"0.899","size":"100"},{"price":"0.9","size":"23802.24"},{"price":"0.901","size":"125"},{"price":"0.902","size":"7772.33"},{"price":"0.904","size":"500"},{"price":"0.905","size":"5307.69"},{"price":"0.91","size":"11147.07"},{"price":"0.911","size":"956.3"},{"price":"0.912","size":"75"},{"price":"0.913","size":"500"},{"price":"0.915","size":"173.07"},{"price":"0.916","size":"19"},{"price":"0.917","size":"125"},{"price":"0.918","size":"500"},{"price":"0.919","size":"532.55"},{"price":"0.92","size":"1979.21"},{"price":"0.924","size":"5917.15"},{"price":"0.925","size":"6585.96"},{"price":"0.926","size":"3944.76"},{"price":"0.927","size":"5259.68"},{"price":"0.928","size":"7012.91"},{"price":"0.929","size":"42450.48"},{"price":"0.93","size":"32653.14"},{"price":"0.931","size":"10000"},{"price":"0.932","size":"5905.04"},{"price":"0.933","size":"382.3"},{"price":"0.934","size":"6055.04"},{"price":"0.935","size":"22294.08"},{"price":"0.939","size":"950"},{"price":"0.94","size":"2357.57"},{"price":"0.941","size":"250009.76"},{"price":"0.942","size":"11012.52"},{"price":"0.943","size":"1999.94"},{"price":"0.944","size":"16846.47"},{"price":"0.945","size":"3838.22"},{"price":"0.946","size":"9385.11"},{"price":"0.947","size":"4752.36"},{"price":"0.948","size":"407731.61"}],"asks":[{"price":"0.999","size":"2259057"},{"price":"0.998","size":"1000005"},{"price":"0.997","size":"2224894"},{"price":"0.996","size":"56355"},{"price":"0.994","size":"300"},{"price":"0.993","size":"100"},{"price":"0.99","size":"2517.95"},{"price":"0.988","size":"100000"},{"price":"0.981","size":"200"},{"price":"0.98","size":"905"},{"price":"0.972","size":"100000"},{"price":"0.97","size":"1030"},{"price":"0.967","size":"30"},{"price":"0.966","size":"5000"},{"price":"0.965","size":"999.99"},{"price":"0.964","size":"2500"},{"price":"0.961","size":"1500"},{"price":"0.96","size":"8909.44"},{"price":"0.959","size":"1510"},{"price":"0.958","size":"4305"},{"price":"0.957","size":"4718"},{"price":"0.956","size":"1500"},{"price":"0.955","size":"2500"},{"price":"0.954","size":"2720"},{"price":"0.953","size":"2220"},{"price":"0.952","size":"29238.33"},{"price":"0.951","size":"39881.55"},{"price":"0.95","size":"91974.74"},{"price":"0.949","size":"588599.29"}],"tick_size":"0.001","event_type":"book","last_trade_price":"0.052"},{"market":"0x30d55d8124ee1e12dabe89201badc45669b81dff69e4ce44d961f32878ec178a","asset_id":"52986718774908357330412653486471347449818893503063830313445318937088822580057","timestamp":"1780150402655","hash":"b2729f584568cdd1cc55785eee9613518fb5ffcc","bids":[{"price":"0.001","size":"21109405.6"},{"price":"0.002","size":"23.15"},{"price":"0.004","size":"2222222"},{"price":"0.005","size":"2000000"},{"price":"0.006","size":"800"},{"price":"0.007","size":"9.04"},{"price":"0.01","size":"102.2"},{"price":"0.013","size":"1716.8"},{"price":"0.015","size":"750"},{"price":"0.016","size":"11.01"},{"price":"0.05","size":"40"},{"price":"0.051","size":"10.88"},{"price":"0.09","size":"5"},{"price":"0.1","size":"2500"},{"price":"0.13","size":"22.93"},{"price":"0.2","size":"1000"},{"price":"0.227","size":"132.15"},{"price":"0.228","size":"5.03"},{"price":"0.27","size":"750"},{"price":"0.3","size":"605"},{"price":"0.39","size":"5"},{"price":"0.4","size":"34625"},{"price":"0.401","size":"10000"},{"price":"0.402","size":"1492"},{"price":"0.442","size":"6.78"},{"price":"0.45","size":"21"},{"price":"0.451","size":"21"},{"price":"0.5","size":"25662.35"},{"price":"0.502","size":"2000"},{"price":"0.503","size":"3100"},{"price":"0.51","size":"100"},{"price":"0.52","size":"100"},{"price":"0.53","size":"100"},{"price":"0.54","size":"100"},{"price":"0.55","size":"200"},{"price":"0.56","size":"100"},{"price":"0.6","size":"20920.53"},{"price":"0.601","size":"3100"},{"price":"0.623","size":"105"},{"price":"0.637","size":"100"},{"price":"0.64","size":"1263"},{"price":"0.65","size":"15539.21"},{"price":"0.667","size":"100"},{"price":"0.67","size":"50"},{"price":"0.7","size":"503.29"},{"price":"0.733","size":"1000"},{"price":"0.75","size":"1265.57"},{"price":"0.751","size":"280"},{"price":"0.752","size":"2095.26"},{"price":"0.76","size":"117.48"},{"price":"0.763","size":"1000"},{"price":"0.767","size":"5"},{"price":"0.771","size":"100"},{"price":"0.78","size":"355"},{"price":"0.781","size":"400"},{"price":"0.79","size":"31.9"},{"price":"0.792","size":"100"},{"price":"0.793","size":"1000"},{"price":"0.8","size":"1500.76"},{"price":"0.81","size":"330.25"},{"price":"0.813","size":"1100"},{"price":"0.818","size":"862.62"},{"price":"0.82","size":"217.47"},{"price":"0.823","size":"1000"},{"price":"0.825","size":"600"},{"price":"0.827","size":"30"},{"price":"0.83","size":"471.36"},{"price":"0.833","size":"1100"},{"price":"0.834","size":"100"},{"price":"0.84","size":"68"},{"price":"0.843","size":"1000"},{"price":"0.846","size":"5.31"},{"price":"0.85","size":"4497.11"},{"price":"0.855","size":"263.04"},{"price":"0.856","size":"18.23"},{"price":"0.858","size":"12.56"},{"price":"0.86","size":"2499.34"},{"price":"0.861","size":"200"},{"price":"0.868","size":"2500"},{"price":"0.87","size":"186.7"},{"price":"0.871","size":"437.5"},{"price":"0.872","size":"2500"},{"price":"0.873","size":"45"},{"price":"0.874","size":"75"},{"price":"0.875","size":"619"},{"price":"0.876","size":"6425"},{"price":"0.877","size":"5000"},{"price":"0.88","size":"88.12"},{"price":"0.882","size":"15265.93"},{"price":"0.883","size":"200"},{"price":"0.887","size":"437.5"},{"price":"0.888","size":"106.38"},{"price":"0.89","size":"30299.11"},{"price":"0.891","size":"23245"},{"price":"0.893","size":"4000"},{"price":"0.894","size":"4217.77"},{"price":"0.895","size":"10273.48"},{"price":"0.897","size":"62499.24"},{"price":"0.898","size":"56"},{"price":"0.9","size":"9398.5"},{"price":"0.901","size":"44793.63"},{"price":"0.902","size":"62749.23"},{"price":"0.903","size":"25213.57"},{"price":"0.904","size":"764967.01"},{"price":"0.905","size":"37498.61"},{"price":"0.906","size":"46794.57"},{"price":"0.907","size":"87424.83"},{"price":"0.908","size":"77337.54"},{"price":"0.909","size":"83049.2"}],"asks":[{"price":"0.999","size":"4833617.88"},{"price":"0.998","size":"1000671"},{"price":"0.997","size":"672"},{"price":"0.996","size":"501000"},{"price":"0.995","size":"30100"},{"price":"0.994","size":"1182511"},{"price":"0.993","size":"66355"},{"price":"0.992","size":"10000"},{"price":"0.991","size":"10000"},{"price":"0.99","size":"11815"},{"price":"0.989","size":"5000"},{"price":"0.988","size":"5000"},{"price":"0.987","size":"5000"},{"price":"0.986","size":"5000"},{"price":"0.985","size":"5000"},{"price":"0.984","size":"5000"},{"price":"0.983","size":"5000"},{"price":"0.982","size":"5000"},{"price":"0.981","size":"5000"},{"price":"0.98","size":"5375"},{"price":"0.979","size":"3999.99"},{"price":"0.978","size":"3000"},{"price":"0.977","size":"3000"},{"price":"0.976","size":"3000"},{"price":"0.975","size":"3000"},{"price":"0.974","size":"3000"},{"price":"0.973","size":"3000"},{"price":"0.972","size":"3000"},{"price":"0.97","size":"3800"},{"price":"0.966","size":"134.32"},{"price":"0.965","size":"45.64"},{"price":"0.96","size":"300"},{"price":"0.959","size":"300"},{"price":"0.957","size":"50"},{"price":"0.956","size":"134.85"},{"price":"0.955","size":"763.02"},{"price":"0.954","size":"237.14"},{"price":"0.953","size":"237.14"},{"price":"0.951","size":"10"},{"price":"0.95","size":"241"},{"price":"0.949","size":"6"},{"price":"0.948","size":"6"},{"price":"0.947","size":"6"},{"price":"0.946","size":"6"},{"price":"0.945","size":"6"},{"price":"0.944","size":"6"},{"price":"0.943","size":"6"},{"price":"0.942","size":"356.6"},{"price":"0.941","size":"6"},{"price":"0.94","size":"206"},{"price":"0.939","size":"6"},{"price":"0.938","size":"6"},{"price":"0.937","size":"6"},{"price":"0.936","size":"6"},{"price":"0.935","size":"6"},{"price":"0.934","size":"6"},{"price":"0.933","size":"6"},{"price":"0.932","size":"6"},{"price":"0.931","size":"6"},{"price":"0.93","size":"1238.01"},{"price":"0.929","size":"20006"},{"price":"0.928","size":"16"},{"price":"0.927","size":"6"},{"price":"0.926","size":"16006"},{"price":"0.925","size":"516"},{"price":"0.924","size":"38"},{"price":"0.923","size":"6"},{"price":"0.922","size":"6"},{"price":"0.921","size":"1386"},{"price":"0.92","size":"36680"},{"price":"0.919","size":"32011"},{"price":"0.918","size":"10413.85"},{"price":"0.917","size":"11106"},{"price":"0.916","size":"59297.99"},{"price":"0.915","size":"19118.35"},{"price":"0.914","size":"4477.13"},{"price":"0.913","size":"1903.84"},{"price":"0.912","size":"20654"},{"price":"0.911","size":"169555.05"},{"price":"0.91","size":"41517.84"}],"tick_size":"0.001","event_type":"book","last_trade_price":"0.909"},{"market":"0x375409bc5eeeff961e82b479caeccc20f33d15738e5bce1186d628aa3d9dfb1f","asset_id":"77121637225348873006259930776623502125079210522997384841464684944292365296940","timestamp":"1780150402655","hash":"257070ec6a9871edb84fc40a79c88471b3b6a681","bids":[{"price":"0.001","size":"21319088.56"},{"price":"0.002","size":"5005.12"},{"price":"0.003","size":"14.23"},{"price":"0.005","size":"2222222"},{"price":"0.006","size":"2000000"},{"price":"0.007","size":"800"},{"price":"0.008","size":"5.22"},{"price":"0.013","size":"1728"},{"price":"0.014","size":"52"},{"price":"0.1","size":"2991.34"},{"price":"0.151","size":"5000"},{"price":"0.155","size":"200"},{"price":"0.16","size":"300"},{"price":"0.161","size":"300"},{"price":"0.163","size":"300"},{"price":"0.18","size":"300"},{"price":"0.2","size":"1000"},{"price":"0.22","size":"345.04"},{"price":"0.221","size":"200"},{"price":"0.222","size":"135.13"},{"price":"0.223","size":"5.22"},{"price":"0.23","size":"230.97"},{"price":"0.25","size":"300"},{"price":"0.26","size":"300"},{"price":"0.27","size":"300"},{"price":"0.3","size":"2974.99"},{"price":"0.301","size":"200"},{"price":"0.35","size":"293.98"},{"price":"0.38","size":"133.26"},{"price":"0.39","size":"105"},{"price":"0.4","size":"36025"},{"price":"0.408","size":"4900"},{"price":"0.409","size":"6100"},{"price":"0.44","size":"105"},{"price":"0.45","size":"100"},{"price":"0.451","size":"1009.54"},{"price":"0.493","size":"494.73"},{"price":"0.5","size":"27051.85"},{"price":"0.501","size":"4100"},{"price":"0.502","size":"144.67"},{"price":"0.51","size":"275.39"},{"price":"0.55","size":"302.74"},{"price":"0.56","size":"100"},{"price":"0.6","size":"22248.33"},{"price":"0.613","size":"100"},{"price":"0.62","size":"100"},{"price":"0.623","size":"105"},{"price":"0.643","size":"100"},{"price":"0.65","size":"16362.62"},{"price":"0.661","size":"5100"},{"price":"0.662","size":"2095.26"},{"price":"0.67","size":"11.2"},{"price":"0.671","size":"100"},{"price":"0.673","size":"100"},{"price":"0.68","size":"99.99"},{"price":"0.69","size":"242.85"},{"price":"0.7","size":"1709.85"},{"price":"0.703","size":"100"},{"price":"0.712","size":"1000"},{"price":"0.72","size":"252.85"},{"price":"0.721","size":"100"},{"price":"0.733","size":"100"},{"price":"0.74","size":"180.76"},{"price":"0.742","size":"1000"},{"price":"0.75","size":"4558.91"},{"price":"0.761","size":"99.99"},{"price":"0.762","size":"400"},{"price":"0.763","size":"100"},{"price":"0.767","size":"8608.24"},{"price":"0.77","size":"200"},{"price":"0.771","size":"200"},{"price":"0.772","size":"1000"},{"price":"0.774","size":"16354.68"},{"price":"0.776","size":"9000"},{"price":"0.79","size":"3113.4"},{"price":"0.792","size":"1100"},{"price":"0.8","size":"18652.43"},{"price":"0.802","size":"1006.22"},{"price":"0.804","size":"1486.78"},{"price":"0.805","size":"30"},{"price":"0.81","size":"888.99"},{"price":"0.812","size":"1100"},{"price":"0.813","size":"100"},{"price":"0.82","size":"3820"},{"price":"0.822","size":"1000"},{"price":"0.828","size":"5.43"},{"price":"0.83","size":"110"},{"price":"0.834","size":"436.03"},{"price":"0.835","size":"125"},{"price":"0.84","size":"390.66"},{"price":"0.841","size":"50"},{"price":"0.842","size":"25"},{"price":"0.847","size":"263.15"},{"price":"0.85","size":"279.81"},{"price":"0.852","size":"1180.09"},{"price":"0.854","size":"847.46"},{"price":"0.855","size":"219.97"},{"price":"0.856","size":"118.44"},{"price":"0.857","size":"144"},{"price":"0.858","size":"167.16"},{"price":"0.86","size":"190.28"},{"price":"0.861","size":"232.7"},{"price":"0.862","size":"2611.44"},{"price":"0.863","size":"173.7"},{"price":"0.864","size":"145.37"},{"price":"0.865","size":"94.28"},{"price":"0.866","size":"111.44"},{"price":"0.867","size":"15000"},{"price":"0.868","size":"25121.44"},{"price":"0.869","size":"21"},{"price":"0.87","size":"60785.22"},{"price":"0.871","size":"4854.15"},{"price":"0.872","size":"55395.74"},{"price":"0.873","size":"1122.06"},{"price":"0.874","size":"312.33"},{"price":"0.875","size":"1879.28"},{"price":"0.876","size":"349.34"},{"price":"0.877","size":"20"},{"price":"0.878","size":"256.72"},{"price":"0.879","size":"99"},{"price":"0.88","size":"20849.13"},{"price":"0.881","size":"148797.59"},{"price":"0.882","size":"3293.19"},{"price":"0.883","size":"516048.24"},{"price":"0.884","size":"21720.12"},{"price":"0.885","size":"12999.15"},{"price":"0.886","size":"13106.41"},{"price":"0.887","size":"205630.56"},{"price":"0.888","size":"49780.08"}],"asks":[{"price":"0.999","size":"4816069"},{"price":"0.998","size":"1001693"},{"price":"0.996","size":"556755"},{"price":"0.995","size":"55655"},{"price":"0.994","size":"20000"},{"price":"0.993","size":"10800"},{"price":"0.992","size":"10000"},{"price":"0.991","size":"10000"},{"price":"0.99","size":"10000"},{"price":"0.989","size":"5000"},{"price":"0.988","size":"5000"},{"price":"0.987","size":"5000"},{"price":"0.986","size":"5000"},{"price":"0.985","size":"6000"},{"price":"0.984","size":"5000"},{"price":"0.983","size":"5000"},{"price":"0.982","size":"5060"},{"price":"0.981","size":"5000"},{"price":"0.98","size":"5375"},{"price":"0.979","size":"5020"},{"price":"0.978","size":"5000"},{"price":"0.977","size":"5000"},{"price":"0.976","size":"5000"},{"price":"0.96","size":"100"},{"price":"0.951","size":"100"},{"price":"0.95","size":"3975"},{"price":"0.948","size":"87.37"},{"price":"0.947","size":"1093.81"},{"price":"0.94","size":"50316.67"},{"price":"0.936","size":"169.92"},{"price":"0.935","size":"5000"},{"price":"0.93","size":"100"},{"price":"0.924","size":"267.15"},{"price":"0.92","size":"600"},{"price":"0.918","size":"105"},{"price":"0.912","size":"335.31"},{"price":"0.91","size":"500"},{"price":"0.907","size":"300"},{"price":"0.906","size":"16319"},{"price":"0.904","size":"11000"},{"price":"0.903","size":"500"},{"price":"0.9","size":"16088.38"},{"price":"0.899","size":"10000"},{"price":"0.898","size":"1010"},{"price":"0.897","size":"20"},{"price":"0.896","size":"2540"},{"price":"0.895","size":"600"},{"price":"0.894","size":"860"},{"price":"0.893","size":"5000"},{"price":"0.892","size":"9287.02"},{"price":"0.891","size":"11086.74"},{"price":"0.89","size":"150754.77"},{"price":"0.889","size":"242461.2"}],"tick_size":"0.001","event_type":"book","last_trade_price":"0.112"}]
{"market":"0x7976b8dbacf9077eb1453a62bcefd6ab2df199acd28aad276ff0d920d6992892", "price_changes":[{"asset_id":"4394372887385518214471608448209527405727552777602031099972143344338178308080", "price":"0.171", "size":"2247.95", "side":"SELL", "hash":"e20652ef9e65d8cfe01a3eb033c2261ce2572bf1", "best_bid":"0.167", "best_ask":"0.168"}, {"asset_id":"112680630004798425069810935278212000865453267506345451433803052322987302357330", "price":"0.829", "size":"2247.95", "side":"BUY", "hash":"109451bd5f8e7d32534a6fe70c48ef48deed5b91", "best_bid":"0.832", "best_ask":"0.833"}], "timestamp":"1780150403810", "event_type":"price_change"}
{"market":"0x0c4cd2055d6ea89354ffddc55d6dbcef9355748112ea952fc925f3db6a5c457f", "price_changes":[{"asset_id":"18812649149814341758733697580460697418474693998558159483117100240528657629879", "price":"0.088", "size":"15069.46", "side":"SELL", "hash":"0295b6b157aeaff93c5783c6d97e181ea83d9471", "best_bid":"0.085", "best_ask":"0.086"}, {"asset_id":"115428153746996892211798999366308897078723117634059783423375188043903703749062", "price":"0.912", "size":"15069.46", "side":"BUY", "hash":"ef30f85fbbb7e43f3931d7c640036f8b401cb574", "best_bid":"0.914", "best_ask":"0.915"}], "timestamp":"1780150403831", "event_type":"price_change"}
{"market":"0x4f3421fb2daf5cca7430ed8d8132463963081572d75434393a1808fdb8829fe8", "price_changes":[{"asset_id":"45415751658241142530386585138386640503488308219341470020075667342738719018629", "price":"0.103", "size":"18123.31", "side":"SELL", "hash":"ffd7df7dc7e9e5fa3bde82c04016f82f8a601125", "best_bid":"0.1", "best_ask":"0.101"}, {"asset_id":"31940783580344558651011323787577288681658737625185216525249046282994042503801", "price":"0.897", "size":"18123.31", "side":"BUY", "hash":"06fd0eeba834a88cb9dd49ceada17bb03a002695", "best_bid":"0.899", "best_ask":"0.9"}], "timestamp":"1780150404475", "event_type":"price_change"}
{"market":"0x0c4cd2055d6ea89354ffddc55d6dbcef9355748112ea952fc925f3db6a5c457f", "price_changes":[{"asset_id":"18812649149814341758733697580460697418474693998558159483117100240528657629879", "price":"0.088", "size":"15129.46", "side":"SELL", "hash":"6603077362f9198e82c146d1c78cfed1f5441344", "best_bid":"0.085", "best_ask":"0.086"}, {"asset_id":"115428153746996892211798999366308897078723117634059783423375188043903703749062", "price":"0.912", "size":"15129.46", "side":"BUY", "hash":"200f38549cf287fb27e5c105f795273b4f45ea63", "best_bid":"0.914", "best_ask":"0.915"}], "timestamp":"1780150404480", "event_type":"price_change"}
{"market":"0x7976b8dbacf9077eb1453a62bcefd6ab2df199acd28aad276ff0d920d6992892", "price_changes":[{"asset_id":"4394372887385518214471608448209527405727552777602031099972143344338178308080", "price":"0.171", "size":"2301.97", "side":"SELL", "hash":"a492bfcbcb3710b9df74d29f977246a58b7c4450", "best_bid":"0.167", "best_ask":"0.168"}, {"asset_id":"112680630004798425069810935278212000865453267506345451433803052322987302357330", "price":"0.829", "size":"2301.97", "side":"BUY", "hash":"de967130ce81401fb83f4d5a242e3b22e46529e2", "best_bid":"0.832", "best_ask":"0.833"}], "timestamp":"1780150404488", "event_type":"price_change"}
{"market":"0x4f3421fb2daf5cca7430ed8d8132463963081572d75434393a1808fdb8829fe8", "price_changes":[{"asset_id":"45415751658241142530386585138386640503488308219341470020075667342738719018629", "price":"0.103", "size":"18183.31", "side":"SELL", "hash":"4493c80545c6415522d3faf04c58e1e3a1d4131e", "best_bid":"0.1", "best_ask":"0.101"}, {"asset_id":"31940783580344558651011323787577288681658737625185216525249046282994042503801", "price":"0.897", "size":"18183.31", "side":"BUY", "hash":"b578ddb9701fe5aa2fab0393babc0e7e9d183719", "best_bid":"0.899", "best_ask":"0.9"}], "timestamp":"1780150404609", "event_type":"price_change"}
{"market":"0x4f3421fb2daf5cca7430ed8d8132463963081572d75434393a1808fdb8829fe8", "price_changes":[{"asset_id":"45415751658241142530386585138386640503488308219341470020075667342738719018629", "price":"0.099", "size":"912.07", "side":"BUY", "hash":"9a8dd58d17ba2119dd1dbc9ca896b0cdba049671", "best_bid":"0.1", "best_ask":"0.101"}, {"asset_id":"31940783580344558651011323787577288681658737625185216525249046282994042503801", "price":"0.901", "size":"912.07", "side":"SELL", "hash":"b6330d95a6e7fbff65449ee75d1504821fa0a40b", "best_bid":"0.899", "best_ask":"0.9"}], "timestamp":"1780150405901", "event_type":"price_change"}
{"market":"0x4f3421fb2daf5cca7430ed8d8132463963081572d75434393a1808fdb8829fe8", "price_changes":[{"asset_id":"45415751658241142530386585138386640503488308219341470020075667342738719018629", "price":"0.09", "size":"5354.55", "side":"BUY", "hash":"37a7e0c10f8dfbf8264c0f0c06ef404b7fcf58f6", "best_bid":"0.1", "best_ask":"0.101"}, {"asset_id":"31940783580344558651011323787577288681658737625185216525249046282994042503801", "price":"0.91", "size":"5354.55", "side":"SELL", "hash":"d4387dbe368d688124ad04768c4778f1d11c4f0c", "best_bid":"0.899", "best_ask":"0.9"}], "timestamp":"1780150406097", "event_type":"price_change"}
{"market":"0x7876851632c295043c66536150a304cb785abdf712ba8489d298c6e6926be106", "price_changes":[{"asset_id":"97239126062673310243763617236644392945530356142765650402171508075574679292913", "price":"0.011", "size":"1798856.4", "side":"SELL", "hash":"7742a2a38d016959bbe821478938fd12acb6fb01", "best_bid":"0.01", "best_ask":"0.011"}, {"asset_id":"19291692040378529618917910599727571242305935029274321291612270922648172794670", "price":"0.989", "size":"1798856.4", "side":"BUY", "hash":"d7be2f635c3d6bafe06d8dcafaea446930b0f090", "best_bid":"0.989", "best_ask":"0.99"}], "timestamp":"1780150406128", "event_type":"price_change"}
{"market":"0x7876851632c295043c66536150a304cb785abdf712ba8489d298c6e6926be106", "asset_id":"19291692040378529618917910599727571242305935029274321291612270922648172794670", "bids":[{"price":"0.001", "size":"21002524.32"}, {"price":"0.002", "size":"90011.18"}, {"price":"0.003", "size":"800"}, {"price":"0.004", "size":"70.1"}, {"price":"0.031", "size":"500"}, {"price":"0.05", "size":"40"}, {"price":"0.051", "size":"9.59"}, {"price":"0.1", "size":"2500"}, {"price":"0.2", "size":"1000"}, {"price":"0.201", "size":"5.94"}, {"price":"0.247", "size":"121.45"}, {"price":"0.3", "size":"600"}, {"price":"0.4", "size":"34625"}, {"price":"0.401", "size":"18000"}, {"price":"0.45", "size":"100"}, {"price":"0.451", "size":"1330"}, {"price":"0.5", "size":"25000"}, {"price":"0.501", "size":"12000"}, {"price":"0.51", "size":"7.97"}, {"price":"0.6", "size":"20833.33"}, {"price":"0.65", "size":"15384.62"}, {"price":"0.652", "size":"2095.26"}, {"price":"0.653", "size":"1103"}, {"price":"0.75", "size":"100"}, {"price":"0.778", "size":"227.27"}, {"price":"0.808", "size":"8"}, {"price":"0.841", "size":"1000"}, {"price":"0.85", "size":"445.83"}, {"price":"0.851", "size":"400"}, {"price":"0.871", "size":"1000"}, {"price":"0.891", "size":"1000"}, {"price":"0.9", "size":"90.9"}, {"price":"0.901", "size":"1000"}, {"price":"0.902", "size":"30"}, {"price":"0.904", "size":"8"}, {"price":"0.911", "size":"1100"}, {"price":"0.92", "size":"1000"}, {"price":"0.921", "size":"1000"}, {"price":"0.93", "size":"3800"}, {"price":"0.931", "size":"125"}, {"price":"0.935", "size":"3500"}, {"price":"0.936", "size":"25"}, {"price":"0.938", "size":"3500"}, {"price":"0.94", "size":"2000"}, {"price":"0.941", "size":"50"}, {"price":"0.943", "size":"3000"}, {"price":"0.944", "size":"2000"}, {"price":"0.95", "size":"3309.92"}, {"price":"0.951", "size":"2045"}, {"price":"0.952", "size":"3833.33"}, {"price":"0.953", "size":"75"}, {"price":"0.954", "size":"19"}, {"price":"0.955", "size":"3067"}, {"price":"0.956", "size":"125"}, {"price":"0.957", "size":"3000"}, {"price":"0.958", "size":"3000"}, {"price":"0.96", "size":"232.7"}, {"price":"0.961", "size":"3007.2"}, {"price":"0.964", "size":"5000"}, {"price":"0.965", "size":"15430.62"}, {"price":"0.967", "size":"10424"}, {"price":"0.968", "size":"4287.08"}, {"price":"0.97", "size":"18916.9"}, {"price":"0.971", "size":"3000"}, {"price":"0.972", "size":"14648"}, {"price":"0.974", "size":"5000"}, {"price":"0.975", "size":"10372.72"}, {"price":"0.976", "size":"5500"}, {"price":"0.978", "size":"17239.4"}, {"price":"0.979", "size":"6000"}, {"price":"0.98", "size":"14721.53"}, {"price":"0.981", "size":"2790.7"}, {"price":"0.982", "size":"62681.81"}, {"price":"0.983", "size":"110028.15"}, {"price":"0.984", "size":"118582.98"}, {"price":"0.985", "size":"107389"}, {"price":"0.986", "size":"10"}, {"price":"0.987", "size":"8338.33"}, {"price":"0.988", "size":"4839211.94"}, {"price":"0.989", "size":"1798856.4"}], "asks":[{"price":"0.999", "size":"3862270"}, {"price":"0.998", "size":"1322096"}, {"price":"0.997", "size":"451830"}, {"price":"0.996", "size":"72622"}, {"price":"0.995", "size":"30650"}, {"price":"0.994", "size":"11473.99"}, {"price":"0.993", "size":"31428.57"}, {"price":"0.992", "size":"328294"}, {"price":"0.991", "size":"247324.61"}, {"price":"0.99", "size":"1180706.14"}], "hash":"d7be2f635c3d6bafe06d8dcafaea446930b0f090", "timestamp":"1780150406128", "event_type":"book"}
{"market":"0x4f3421fb2daf5cca7430ed8d8132463963081572d75434393a1808fdb8829fe8", "price_changes":[{"asset_id":"31940783580344558651011323787577288681658737625185216525249046282994042503801", "price":"0.852", "size":"125", "side":"BUY", "hash":"13a115a935633ec2f6da425a204a52a667beb0cc", "best_bid":"0.899", "best_ask":"0.9"}, {"asset_id":"45415751658241142530386585138386640503488308219341470020075667342738719018629", "price":"0.148", "size":"125", "side":"SELL", "hash":"54284a316a5f325defe39873da020e94447583f8", "best_bid":"0.1", "best_ask":"0.101"}], "timestamp":"1780150406953", "event_type":"price_change"}
{"market":"0x7976b8dbacf9077eb1453a62bcefd6ab2df199acd28aad276ff0d920d6992892", "price_changes":[{"asset_id":"112680630004798425069810935278212000865453267506345451433803052322987302357330", "price":"0.797", "size":"0", "side":"BUY", "hash":"f336afefab64cf4b138a09aa7b19de14135868b2", "best_bid":"0.832", "best_ask":"0.833"}, {"asset_id":"4394372887385518214471608448209527405727552777602031099972143344338178308080", "price":"0.203", "size":"0", "side":"SELL", "hash":"95264f7bc77653ee620906c898005dfd3a3f1083", "best_bid":"0.167", "best_ask":"0.168"}], "timestamp":"1780150409897", "event_type":"price_change"}
{"market":"0x7976b8dbacf9077eb1453a62bcefd6ab2df199acd28aad276ff0d920d6992892", "price_changes":[{"asset_id":"112680630004798425069810935278212000865453267506345451433803052322987302357330", "price":"0.796", "size":"25", "side":"BUY", "hash":"f336afefab64cf4b138a09aa7b19de14135868b2", "best_bid":"0.832", "best_ask":"0.833"}, {"asset_id":"4394372887385518214471608448209527405727552777602031099972143344338178308080", "price":"0.204", "size":"25", "side":"SELL", "hash":"95264f7bc77653ee620906c898005dfd3a3f1083", "best_bid":"0.167", "best_ask":"0.168"}], "timestamp":"1780150409897", "event_type":"price_change"}
{"market":"0x4f3421fb2daf5cca7430ed8d8132463963081572d75434393a1808fdb8829fe8", "price_changes":[{"asset_id":"31940783580344558651011323787577288681658737625185216525249046282994042503801", "price":"0.859", "size":"25", "side":"BUY", "hash":"101975e66dbaa4cc7b855f649653573d9226f5a1", "best_bid":"0.899", "best_ask":"0.9"}, {"asset_id":"45415751658241142530386585138386640503488308219341470020075667342738719018629", "price":"0.141", "size":"25", "side":"SELL", "hash":"74988e9f7840c3d548463e9acf32647a50ecdcc9", "best_bid":"0.1", "best_ask":"0.101"}], "timestamp":"1780150410055", "event_type":"price_change"}
{"market":"0x7976b8dbacf9077eb1453a62bcefd6ab2df199acd28aad276ff0d920d6992892", "price_changes":[{"asset_id":"112680630004798425069810935278212000865453267506345451433803052322987302357330", "price":"0.791", "size":"125", "side":"BUY", "hash":"3ff0f6e3f0b67411d1a4cc2325f583ab84f009f4", "best_bid":"0.832", "best_ask":"0.833"}, {"asset_id":"4394372887385518214471608448209527405727552777602031099972143344338178308080", "price":"0.209", "size":"125", "side":"SELL", "hash":"d24cfba2956823ea2a21c0ae4135e48ec258b25c", "best_bid":"0.167", "best_ask":"0.168"}], "timestamp":"1780150413150", "event_type":"price_change"}
{"market":"0x30d55d8124ee1e12dabe89201badc45669b81dff69e4ce44d961f32878ec178a", "price_changes":[{"asset_id":"52986718774908357330412653486471347449818893503063830313445318937088822580057", "price":"0.909", "size":"82976.45", "side":"BUY", "hash":"1ef1068a8eee4b66e7aa45899102747bf1a8cc23", "best_bid":"0.909", "best_ask":"0.91"}, {"asset_id":"27576533317283401577758999384642760405921738493660383550832555714312627457443", "price":"0.091", "size":"82976.45", "side":"SELL", "hash":"035f4f7aa77fd25cc6408f7ec2d0a829b46160a5", "best_bid":"0.09", "best_ask":"0.091"}], "timestamp":"1780150413869", "event_type":"price_change"}
{"market":"0x30d55d8124ee1e12dabe89201badc45669b81dff69e4ce44d961f32878ec178a", "asset_id":"52986718774908357330412653486471347449818893503063830313445318937088822580057", "bids":[{"price":"0.001", "size":"21109405.6"}, {"price":"0.002", "size":"23.15"}, {"price":"0.004", "size":"2222222"}, {"price":"0.005", "size":"2000000"}, {"price":"0.006", "size":"800"}, {"price":"0.007", "size":"9.04"}, {"price":"0.01", "size":"102.2"}, {"price":"0.013", "size":"1716.8"}, {"price":"0.015", "size":"750"}, {"price":"0.016", "size":"11.01"}, {"price":"0.05", "size":"40"}, {"price":"0.051", "size":"10.88"}, {"price":"0.09", "size":"5"}, {"price":"0.1", "size":"2500"}, {"price":"0.13", "size":"22.93"}, {"price":"0.2", "size":"1000"}, {"price":"0.227", "size":"132.15"}, {"price":"0.228", "size":"5.03"}, {"price":"0.27", "size":"750"}, {"price":"0.3", "size":"605"}, {"price":"0.39", "size":"5"}, {"price":"0.4", "size":"34625"}, {"price":"0.401", "size":"10000"}, {"price":"0.402", "size":"1492"}, {"price":"0.442", "size":"6.78"}, {"price":"0.45", "size":"21"}, {"price":"0.451", "size":"21"}, {"price":"0.5", "size":"25662.35"}, {"price":"0.502", "size":"2000"}, {"price":"0.503", "size":"3100"}, {"price":"0.51", "size":"100"}, {"price":"0.52", "size":"100"}, {"price":"0.53", "size":"100"}, {"price":"0.54", "size":"100"}, {"price":"0.55", "size":"200"}, {"price":"0.56", "size":"100"}, {"price":"0.6", "size":"20920.53"}, {"price":"0.601", "size":"3100"}, {"price":"0.623", "size":"105"}, {"price":"0.637", "size":"100"}, {"price":"0.64", "size":"1263"}, {"price":"0.65", "size":"15539.21"}, {"price":"0.667", "size":"100"}, {"price":"0.67", "size":"50"}, {"price":"0.7", "size":"503.29"}, {"price":"0.733", "size":"1000"}, {"price":"0.75", "size":"1265.57"}, {"price":"0.751", "size":"280"}, {"price":"0.752", "size":"2095.26"}, {"price":"0.76", "size":"117.48"}, {"price":"0.763", "size":"1000"}, {"price":"0.767", "size":"5"}, {"price":"0.771", "size":"100"}, {"price":"0.78", "size":"355"}, {"price":"0.781", "size":"400"}, {"price":"0.79", "size":"31.9"}, {"price":"0.792", "size":"100"}, {"price":"0.793", "size":"1000"}, {"price":"0.8", "size":"1500.76"}, {"price":"0.81", "size":"330.25"}, {"price":"0.813", "size":"1100"}, {"price":"0.818", "size":"862.62"}, {"price":"0.82", "size":"217.47"}, {"price":"0.823", "size":"1000"}, {"price":"0.825", "size":"600"}, {"price":"0.827", "size":"30"}, {"price":"0.83", "size":"471.36"}, {"price":"0.833", "size":"1100"}, {"price":"0.834", "size":"100"}, {"price":"0.84", "size":"68"}, {"price":"0.843", "size":"1000"}, {"price":"0.846", "size":"5.31"}, {"price":"0.85", "size":"4497.11"}, {"price":"0.855", "size":"263.04"}, {"price":"0.856", "size":"18.23"}, {"price":"0.858", "size":"12.56"}, {"price":"0.86", "size":"2499.34"}, {"price":"0.861", "size":"200"}, {"price":"0.868", "size":"2500"}, {"price":"0.87", "size":"186.7"}, {"price":"0.871", "size":"437.5"}, {"price":"0.872", "size":"2500"}, {"price":"0.873", "size":"45"}, {"price":"0.874", "size":"75"}, {"price":"0.875", "size":"619"}, {"price":"0.876", "size":"6425"}, {"price":"0.877", "size":"5000"}, {"price":"0.88", "size":"88.12"}, {"price":"0.882", "size":"15265.93"}, {"price":"0.883", "size":"200"}, {"price":"0.887", "size":"437.5"}, {"price":"0.888", "size":"106.38"}, {"price":"0.89", "size":"30299.11"}, {"price":"0.891", "size":"23245"}, {"price":"0.893", "size":"4000"}, {"price":"0.894", "size":"4217.77"}, {"price":"0.895", "size":"10273.48"}, {"price":"0.897", "size":"62499.24"}, {"price":"0.898", "size":"56"}, {"price":"0.9", "size":"9398.5"}, {"price":"0.901", "size":"44793.63"}, {"price":"0.902", "size":"62749.23"}, {"price":"0.903", "size":"25213.57"}, {"price":"0.904", "size":"764967.01"}, {"price":"0.905", "size":"37498.61"}, {"price":"0.906", "size":"46794.57"}, {"price":"0.907", "size":"87424.83"}, {"price":"0.908", "size":"77337.54"}, {"price":"0.909", "size":"82976.45"}], "asks":[{"price":"0.999", "size":"4833617.88"}, {"price":"0.998", "size":"1000671"}, {"price":"0.997", "size":"672"}, {"price":"0.996", "size":"501000"}, {"price":"0.995", "size":"30100"}, {"price":"0.994", "size":"1182511"}, {"price":"0.993", "size":"66355"}, {"price":"0.992", "size":"10000"}, {"price":"0.991", "size":"10000"}, {"price":"0.99", "size":"11815"}, {"price":"0.989", "size":"5000"}, {"price":"0.988", "size":"5000"}, {"price":"0.987", "size":"5000"}, {"price":"0.986", "size":"5000"}, {"price":"0.985", "size":"5000"}, {"price":"0.984", "size":"5000"}, {"price":"0.983", "size":"5000"}, {"price":"0.982", "size":"5000"}, {"price":"0.981", "size":"5000"}, {"price":"0.98", "size":"5375"}, {"price":"0.979", "size":"3999.99"}, {"price":"0.978", "size":"3000"}, {"price":"0.977", "size":"3000"}, {"price":"0.976", "size":"3000"}, {"price":"0.975", "size":"3000"}, {"price":"0.974", "size":"3000"}, {"price":"0.973", "size":"3000"}, {"price":"0.972", "size":"3000"}, {"price":"0.97", "size":"3800"}, {"price":"0.966", "size":"134.32"}, {"price":"0.965", "size":"45.64"}, {"price":"0.96", "size":"300"}, {"price":"0.959", "size":"300"}, {"price":"0.957", "size":"50"}, {"price":"0.956", "size":"134.85"}, {"price":"0.955", "size":"763.02"}, {"price":"0.954", "size":"237.14"}, {"price":"0.953", "size":"237.14"}, {"price":"0.951", "size":"10"}, {"price":"0.95", "size":"241"}, {"price":"0.949", "size":"6"}, {"price":"0.948", "size":"6"}, {"price":"0.947", "size":"6"}, {"price":"0.946", "size":"6"}, {"price":"0.945", "size":"6"}, {"price":"0.944", "size":"6"}, {"price":"0.943", "size":"6"}, {"price":"0.942", "size":"356.6"}, {"price":"0.941", "size":"6"}, {"price":"0.94", "size":"206"}, {"price":"0.939", "size":"6"}, {"price":"0.938", "size":"6"}, {"price":"0.937", "size":"6"}, {"price":"0.936", "size":"6"}, {"price":"0.935", "size":"6"}, {"price":"0.934", "size":"6"}, {"price":"0.933", "size":"6"}, {"price":"0.932", "size":"6"}, {"price":"0.931", "size":"6"}, {"price":"0.93", "size":"1238.01"}, {"price":"0.929", "size":"20006"}, {"price":"0.928", "size":"16"}, {"price":"0.927", "size":"6"}, {"price":"0.926", "size":"16006"}, {"price":"0.925", "size":"516"}, {"price":"0.924", "size":"38"}, {"price":"0.923", "size":"6"}, {"price":"0.922", "size":"6"}, {"price":"0.921", "size":"1386"}, {"price":"0.92", "size":"36680"}, {"price":"0.919", "size":"32011"}, {"price":"0.918", "size":"10413.85"}, {"price":"0.917", "size":"11106"}, {"price":"0.916", "size":"59297.99"}, {"price":"0.915", "size":"19118.35"}, {"price":"0.914", "size":"4477.13"}, {"price":"0.913", "size":"1903.84"}, {"price":"0.912", "size":"20654"}, {"price":"0.911", "size":"169555.05"}, {"price":"0.91", "size":"41517.84"}], "hash":"1ef1068a8eee4b66e7aa45899102747bf1a8cc23", "timestamp":"1780150413869", "event_type":"book"}
{"market":"0x0c4cd2055d6ea89354ffddc55d6dbcef9355748112ea952fc925f3db6a5c457f", "price_changes":[{"asset_id":"115428153746996892211798999366308897078723117634059783423375188043903703749062", "price":"0.871", "size":"209826.98", "side":"BUY", "hash":"b8eb0726d376fe40754528f4759f0e7bfdf76675", "best_bid":"0.914", "best_ask":"0.915"}, {"asset_id":"18812649149814341758733697580460697418474693998558159483117100240528657629879", "price":"0.129", "size":"209826.98", "side":"SELL", "hash":"a8a847e10c8693f0e3a8ee646c928348d1dfb8ac", "best_bid":"0.085", "best_ask":"0.086"}], "timestamp":"1780150415490", "event_type":"price_change"}
{"market":"0x30d55d8124ee1e12dabe89201badc45669b81dff69e4ce44d961f32878ec178a", "price_changes":[{"asset_id":"52986718774908357330412653486471347449818893503063830313445318937088822580057", "price":"0.876", "size":"6300", "side":"BUY", "hash":"5d89c0a56bfdd740c3b5f38f5adf0f31dfa96da2", "best_bid":"0.909", "best_ask":"0.91"}, {"asset_id":"27576533317283401577758999384642760405921738493660383550832555714312627457443", "price":"0.124", "size":"6300", "side":"SELL", "hash":"df0492e6ff6ad2e4e2f3e587d9160bfc9b2404cb", "best_bid":"0.09", "best_ask":"0.091"}], "timestamp":"1780150416644", "event_type":"price_change"}
{"market":"0x30d55d8124ee1e12dabe89201badc45669b81dff69e4ce44d961f32878ec178a", "price_changes":[{"asset_id":"52986718774908357330412653486471347449818893503063830313445318937088822580057", "price":"0.877", "size":"5125", "side":"BUY", "hash":"645d8f09710448b0f8d3b3c616113be6cb7a17b8", "best_bid":"0.909", "best_ask":"0.91"}, {"asset_id":"27576533317283401577758999384642760405921738493660383550832555714312627457443", "price":"0.123", "size":"5125", "side":"SELL", "hash":"22abf55f4076921149198fe1a5366430d242b7a5", "best_bid":"0.09", "best_ask":"0.091"}], "timestamp":"1780150416834", "event_type":"price_change"}
{"market":"0x7976b8dbacf9077eb1453a62bcefd6ab2df199acd28aad276ff0d920d6992892", "price_changes":[{"asset_id":"112680630004798425069810935278212000865453267506345451433803052322987302357330", "price":"0.792", "size":"25", "side":"BUY", "hash":"9e4a33cf7dd26a2a226dbb07bd0765089aa05fdc", "best_bid":"0.832", "best_ask":"0.833"}, {"asset_id":"4394372887385518214471608448209527405727552777602031099972143344338178308080", "price":"0.208", "size":"25", "side":"SELL", "hash":"4105838f0e2cab9a8365998f1a79b9cd0733f1d4", "best_bid":"0.167", "best_ask":"0.168"}], "timestamp":"1780150418800", "event_type":"price_change"}
{"market":"0x0c4cd2055d6ea89354ffddc55d6dbcef9355748112ea952fc925f3db6a5c457f", "price_changes":[{"asset_id":"115428153746996892211798999366308897078723117634059783423375188043903703749062", "price":"0.753", "size":"25", "side":"BUY", "hash":"4b34a0b8567e70d2a399ed2c7526643499857112", "best_bid":"0.914", "best_ask":"0.915"}, {"asset_id":"18812649149814341758733697580460697418474693998558159483117100240528657629879", "price":"0.247", "size":"25", "side":"SELL", "hash":"4ba5ada538380aba687653dfb6e2ec755e33c819", "best_bid":"0.085", "best_ask":"0.086"}], "timestamp":"1780150420184", "event_type":"price_change"}
{"market":"0x4f3421fb2daf5cca7430ed8d8132463963081572d75434393a1808fdb8829fe8", "price_changes":[{"asset_id":"45415751658241142530386585138386640503488308219341470020075667342738719018629", "price":"0.9", "size":"2229.88", "side":"SELL", "hash":"21b994562efe01006250c9752a8284184a88ff6c", "best_bid":"0.1", "best_ask":"0.101"}, {"asset_id":"31940783580344558651011323787577288681658737625185216525249046282994042503801", "price":"0.1", "size":"2229.88", "side":"BUY", "hash":"e1c8914995dd4892dafb3027e2e1795b198ade0d", "best_bid":"0.899", "best_ask":"0.9"}], "timestamp":"1780150423049", "event_type":"price_change"}
{"market":"0x7976b8dbacf9077eb1453a62bcefd6ab2df199acd28aad276ff0d920d6992892", "price_changes":[{"asset_id":"4394372887385518214471608448209527405727552777602031099972143344338178308080", "price":"0.833", "size":"17.61", "side":"SELL", "hash":"db968a8edfb57a622bb98607c8a63e04a9ae4bfd", "best_bid":"0.167", "best_ask":"0.168"}, {"asset_id":"112680630004798425069810935278212000865453267506345451433803052322987302357330", "price":"0.167", "size":"17.61", "side":"BUY", "hash":"3fc97db0bc3929d05e620a90d01607460fd4ea4c", "best_bid":"0.832", "best_ask":"0.833"}], "timestamp":"1780150423052", "event_type":"price_change"}
{"market":"0x9b6fef249040fd17e9c107955b37ac2c3e923509b6b0ff01cc463a331ddeb894", "price_changes":[{"asset_id":"108233603819467706476318984012158651931658302669301887462181073562758483842092", "price":"0.837", "size":"36", "side":"SELL", "hash":"008563f8b12a4e23daf9969bb58bf34d2a187cac", "best_bid":"0.163", "best_ask":"0.164"}, {"asset_id":"32270411694523539495262303868629477861017829722282576458031815333486368239544", "price":"0.163", "size":"36", "side":"BUY", "hash":"033452c9673195adb22b77de5fba35e48a41aed2", "best_bid":"0.836", "best_ask":"0.837"}], "timestamp":"1780150423069", "event_type":"price_change"}
{"market":"0x4f3421fb2daf5cca7430ed8d8132463963081572d75434393a1808fdb8829fe8", "price_changes":[{"asset_id":"31940783580344558651011323787577288681658737625185216525249046282994042503801", "price":"0.859", "size":"0", "side":"BUY", "hash":"19770ebc6fa7fd93e37d1e9043888e641cc9735d", "best_bid":"0.899", "best_ask":"0.9"}, {"asset_id":"45415751658241142530386585138386640503488308219341470020075667342738719018629", "price":"0.141", "size":"0", "side":"SELL", "hash":"7471f8953878460eabe239d2cafb027fbee1dfb3", "best_bid":"0.1", "best_ask":"0.101"}], "timestamp":"1780150423544", "event_type":"price_change"}
{"market":"0x1595b4818eeb1ea1e0bec5de6f057218e557feee9b405a0e930d290384fa1d16", "price_changes":[{"asset_id":"81739002353269632749850710185641576213562066971072676369728657545679630163887", "price":"0.054", "size":"9305.11", "side":"SELL", "hash":"de999f19e1e245c406fc183a857da05f0153e33f", "best_bid":"0.051", "best_ask":"0.052"}, {"asset_id":"45484070731786948288366703334552551439356529561722304542938873238430842810537", "price":"0.946", "size":"9305.11", "side":"BUY", "hash":"56eb4d6691dd31bca768c8194b446aaee84eaba3", "best_bid":"0.948", "best_ask":"0.949"}], "timestamp":"1780150423599", "event_type":"price_change"}
{"market":"0x1595b4818eeb1ea1e0bec5de6f057218e557feee9b405a0e930d290384fa1d16", "price_changes":[{"asset_id":"81739002353269632749850710185641576213562066971072676369728657545679630163887", "price":"0.054", "size":"9385.11", "side":"SELL", "hash":"a8d029057beea3bbee7df5fbbdda83bc9f8e6079", "best_bid":"0.051", "best_ask":"0.052"}, {"asset_id":"45484070731786948288366703334552551439356529561722304542938873238430842810537", "price":"0.946", "size":"9385.11", "side":"BUY", "hash":"1550c2c59e2e67ec62bb3f48b7496f27d6fbcfe7", "best_bid":"0.948", "best_ask":"0.949"}], "timestamp":"1780150423734", "event_type":"price_change"}
{"market":"0x0c4cd2055d6ea89354ffddc55d6dbcef9355748112ea952fc925f3db6a5c457f", "price_changes":[{"asset_id":"18812649149814341758733697580460697418474693998558159483117100240528657629879", "price":"0.086", "size":"171031.75", "side":"SELL", "hash":"e593f52effacb7275edec9f94e324c864571c918", "best_bid":"0.085", "best_ask":"0.086"}, {"asset_id":"115428153746996892211798999366308897078723117634059783423375188043903703749062", "price":"0.914", "size":"171031.75", "side":"BUY", "hash":"6829775a2aeeae18de48bf4297771bba518c9fd6", "best_bid":"0.914", "best_ask":"0.915"}], "timestamp":"1780150424305", "event_type":"price_change"}
{"market":"0x0c4cd2055d6ea89354ffddc55d6dbcef9355748112ea952fc925f3db6a5c457f", "asset_id":"115428153746996892211798999366308897078723117634059783423375188043903703749062", "bids":[{"price":"0.001", "size":"19311591.2"}, {"price":"0.002", "size":"55.07"}, {"price":"0.013", "size":"1716.7"}, {"price":"0.015", "size":"1904.95"}, {"price":"0.016", "size":"11.03"}, {"price":"0.036", "size":"36000"}, {"price":"0.04", "size":"333350"}, {"price":"0.041", "size":"300000"}, {"price":"0.042", "size":"800"}, {"price":"0.05", "size":"14660"}, {"price":"0.051", "size":"10.53"}, {"price":"0.09", "size":"19"}, {"price":"0.15", "size":"127.23"}, {"price":"0.22", "size":"128.36"}, {"price":"0.221", "size":"5.26"}, {"price":"0.228", "size":"131.57"}, {"price":"0.27", "size":"1904.95"}, {"price":"0.39", "size":"5"}, {"price":"0.4", "size":"34375"}, {"price":"0.401", "size":"10000"}, {"price":"0.402", "size":"1492"}, {"price":"0.45", "size":"22.5"}, {"price":"0.5", "size":"26767.96"}, {"price":"0.501", "size":"3000"}, {"price":"0.502", "size":"1077.83"}, {"price":"0.6", "size":"21522.45"}, {"price":"0.601", "size":"2000"}, {"price":"0.603", "size":"1164"}, {"price":"0.623", "size":"5"}, {"price":"0.64", "size":"1211"}, {"price":"0.65", "size":"27012.52"}, {"price":"0.66", "size":"46.4"}, {"price":"0.696", "size":"5000"}, {"price":"0.7", "size":"557.74"}, {"price":"0.701", "size":"30"}, {"price":"0.73", "size":"6500"}, {"price":"0.738", "size":"1000"}, {"price":"0.74", "size":"100"}, {"price":"0.75", "size":"3383.18"}, {"price":"0.752", "size":"2906.99"}, {"price":"0.753", "size":"25"}, {"price":"0.755", "size":"125"}, {"price":"0.767", "size":"5"}, {"price":"0.768", "size":"1000"}, {"price":"0.778", "size":"100"}, {"price":"0.779", "size":"400"}, {"price":"0.798", "size":"1000"}, {"price":"0.799", "size":"100"}, {"price":"0.8", "size":"12081.05"}, {"price":"0.801", "size":"2095.26"}, {"price":"0.81", "size":"100"}, {"price":"0.818", "size":"1000"}, {"price":"0.82", "size":"183.62"}, {"price":"0.828", "size":"1000"}, {"price":"0.83", "size":"2373"}, {"price":"0.838", "size":"1268.53"}, {"price":"0.84", "size":"12150"}, {"price":"0.841", "size":"100"}, {"price":"0.843", "size":"100"}, {"price":"0.845", "size":"144"}, {"price":"0.848", "size":"1000"}, {"price":"0.85", "size":"4045.57"}, {"price":"0.855", "size":"11634.31"}, {"price":"0.856", "size":"7"}, {"price":"0.86", "size":"716"}, {"price":"0.861", "size":"144283.19"}, {"price":"0.862", "size":"100"}, {"price":"0.867", "size":"438"}, {"price":"0.868", "size":"50"}, {"price":"0.87", "size":"996"}, {"price":"0.871", "size":"209826.98"}, {"price":"0.875", "size":"1020.47"}, {"price":"0.877", "size":"25"}, {"price":"0.878", "size":"45"}, {"price":"0.879", "size":"75"}, {"price":"0.88", "size":"15096.64"}, {"price":"0.881", "size":"19"}, {"price":"0.882", "size":"648.12"}, {"price":"0.883", "size":"125"}, {"price":"0.884", "size":"10789.73"}, {"price":"0.886", "size":"230.12"}, {"price":"0.887", "size":"1395.49"}, {"price":"0.888", "size":"236.32"}, {"price":"0.889", "size":"1186.28"}, {"price":"0.89", "size":"6421.54"}, {"price":"0.891", "size":"5069.15"}, {"price":"0.892", "size":"52728.52"}, {"price":"0.894", "size":"355.22"}, {"price":"0.895", "size":"5319.74"}, {"price":"0.896", "size":"52728.51"}, {"price":"0.897", "size":"114.3"}, {"price":"0.898", "size":"229.06"}, {"price":"0.899", "size":"27080.06"}, {"price":"0.9", "size":"35120.43"}, {"price":"0.901", "size":"34710.7"}, {"price":"0.902", "size":"84437.86"}, {"price":"0.903", "size":"1730.09"}, {"price":"0.904", "size":"1129.06"}, {"price":"0.905", "size":"2510"}, {"price":"0.906", "size":"229.06"}, {"price":"0.907", "size":"33247.87"}, {"price":"0.908", "size":"15415.06"}, {"price":"0.909", "size":"8064.56"}, {"price":"0.91", "size":"36872.79"}, {"price":"0.911", "size":"25024.11"}, {"price":"0.912", "size":"15129.46"}, {"price":"0.913", "size":"59775.19"}, {"price":"0.914", "size":"171031.75"}], "asks":[{"price":"0.999", "size":"4912713.42"}, {"price":"0.998", "size":"1003359"}, {"price":"0.997", "size":"1111111"}, {"price":"0.996", "size":"55555"}, {"price":"0.995", "size":"500"}, {"price":"0.994", "size":"6000"}, {"price":"0.99", "size":"11200"}, {"price":"0.985", "size":"5.65"}, {"price":"0.984", "size":"5000000"}, {"price":"0.983", "size":"800"}, {"price":"0.98", "size":"5050"}, {"price":"0.979", "size":"2300"}, {"price":"0.97", "size":"4330"}, {"price":"0.969", "size":"367.48"}, {"price":"0.959", "size":"720"}, {"price":"0.958", "size":"725.45"}, {"price":"0.952", "size":"70"}, {"price":"0.951", "size":"71"}, {"price":"0.95", "size":"5879.09"}, {"price":"0.93", "size":"513068.11"}, {"price":"0.929", "size":"6800"}, {"price":"0.928", "size":"437"}, {"price":"0.927", "size":"333"}, {"price":"0.925", "size":"1245"}, {"price":"0.924", "size":"5000"}, {"price":"0.922", "size":"11231.85"}, {"price":"0.921", "size":"127"}, {"price":"0.92", "size":"44813"}, {"price":"0.919", "size":"39326.98"}, {"price":"0.918", "size":"47132.51"}, {"price":"0.917", "size":"184952.96"}, {"price":"0.916", "size":"13437.85"}, {"price":"0.915", "size":"110726.44"}], "hash":"6829775a2aeeae18de48bf4297771bba518c9fd6", "timestamp":"1780150424305", "event_type":"book"}
{"market":"0x4f3421fb2daf5cca7430ed8d8132463963081572d75434393a1808fdb8829fe8", "price_changes":[{"asset_id":"45415751658241142530386585138386640503488308219341470020075667342738719018629", "price":"0.05", "size":"79", "side":"BUY", "hash":"67c68fbfb832008770b08af98d9d8f78af2c6512", "best_bid":"0.1", "best_ask":"0.101"}, {"asset_id":"31940783580344558651011323787577288681658737625185216525249046282994042503801", "price":"0.95", "size":"79", "side":"SELL", "hash":"61b3cc58e12cd1eaed54e35036f67ef461299638", "best_bid":"0.899", "best_ask":"0.9"}], "timestamp":"1780150424455", "event_type":"price_change"}
{"market":"0x9b6fef249040fd17e9c107955b37ac2c3e923509b6b0ff01cc463a331ddeb894", "price_changes":[{"asset_id":"32270411694523539495262303868629477861017829722282576458031815333486368239544", "price":"0.792", "size":"0", "side":"BUY", "hash":"9aa8c9647f37cf1535d2d2a128eb9e13ab38c6ce", "best_bid":"0.836", "best_ask":"0.837"}, {"asset_id":"108233603819467706476318984012158651931658302669301887462181073562758483842092", "price":"0.208", "size":"0", "side":"SELL", "hash":"2a1dc611ddeae2ff4f614c6c61b348662fafad78", "best_bid":"0.163", "best_ask":"0.164"}], "timestamp":"1780150424680", "event_type":"price_change"}
{"market":"0x4f3421fb2daf5cca7430ed8d8132463963081572d75434393a1808fdb8829fe8", "price_changes":[{"asset_id":"45415751658241142530386585138386640503488308219341470020075667342738719018629", "price":"0.04", "size":"134", "side":"BUY", "hash":"ab10dae3fd2692582cc4e942443f65c07f6887f5", "best_bid":"0.1", "best_ask":"0.101"}, {"asset_id":"31940783580344558651011323787577288681658737625185216525249046282994042503801", "price":"0.96", "size":"134", "side":"SELL", "hash":"ae8faf72aa1f9f57a765b73405c7a2034a27001f", "best_bid":"0.899", "best_ask":"0.9"}], "timestamp":"1780150424921", "event_type":"price_change"}
{"market":"0x7876851632c295043c66536150a304cb785abdf712ba8489d298c6e6926be106", "price_changes":[{"asset_id":"97239126062673310243763617236644392945530356142765650402171508075574679292913", "price":"0.011", "size":"1798816.4", "side":"SELL", "hash":"502dda4a78c2bddf876009a693acdb9644b98fa7", "best_bid":"0.01", "best_ask":"0.011"}, {"asset_id":"19291692040378529618917910599727571242305935029274321291612270922648172794670", "price":"0.989", "size":"1798816.4", "side":"BUY", "hash":"7e8949c90aafb9929ef250f24d358b845becb22e", "best_bid":"0.989", "best_ask":"0.99"}], "timestamp":"1780150425005", "event_type":"price_change"}
{"market":"0x4f3421fb2daf5cca7430ed8d8132463963081572d75434393a1808fdb8829fe8", "price_changes":[{"asset_id":"45415751658241142530386585138386640503488308219341470020075667342738719018629", "price":"0.05", "size":"279", "side":"BUY", "hash":"737b229511584b70ec3d0c8b89a8db51789bd958", "best_bid":"0.1", "best_ask":"0.101"}, {"asset_id":"31940783580344558651011323787577288681658737625185216525249046282994042503801", "price":"0.95", "size":"279", "side":"SELL", "hash":"abd680e64a564cb704b2c680521fdb3bb2bfcdce", "best_bid":"0.899", "best_ask":"0.9"}], "timestamp":"1780150426315", "event_type":"price_change"}
{"market":"0x7976b8dbacf9077eb1453a62bcefd6ab2df199acd28aad276ff0d920d6992892", "price_changes":[{"asset_id":"4394372887385518214471608448209527405727552777602031099972143344338178308080", "price":"0.184", "size":"0", "side":"SELL", "hash":"78e8b959811ab0c7e1554fa102e952b2c59e70e5", "best_bid":"0.167", "best_ask":"0.168"}, {"asset_id":"112680630004798425069810935278212000865453267506345451433803052322987302357330", "price":"0.816", "size":"0", "side":"BUY", "hash":"73185ae4eb3b84baa1210830c73819f415ce9626", "best_bid":"0.832", "best_ask":"0.833"}], "timestamp":"1780150427340", "event_type":"price_change"}
{"market":"0x7976b8dbacf9077eb1453a62bcefd6ab2df199acd28aad276ff0d920d6992892", "price_changes":[{"asset_id":"4394372887385518214471608448209527405727552777602031099972143344338178308080", "price":"0.184", "size":"49.77", "side":"SELL", "hash":"b6e939474f1eac1b54a98e245649182a397a8be5", "best_bid":"0.167", "best_ask":"0.168"}, {"asset_id":"112680630004798425069810935278212000865453267506345451433803052322987302357330", "price":"0.816", "size":"49.77", "side":"BUY", "hash":"5d33a14bf3f94a69a8316f23e6470d7bd46999bd", "best_bid":"0.832", "best_ask":"0.833"}], "timestamp":"1780150427504", "event_type":"price_change"}
{"market":"0x4f3421fb2daf5cca7430ed8d8132463963081572d75434393a1808fdb8829fe8", "price_changes":[{"asset_id":"45415751658241142530386585138386640503488308219341470020075667342738719018629", "price":"0.04", "size":"259", "side":"BUY", "hash":"1bbaab2a56cfdde91614f96a6fe6720ccf4b3350", "best_bid":"0.1", "best_ask":"0.101"}, {"asset_id":"31940783580344558651011323787577288681658737625185216525249046282994042503801", "price":"0.96", "size":"259", "side":"SELL", "hash":"2a6bb1435e63c08a2250f338cd54b072386fbc68", "best_bid":"0.899", "best_ask":"0.9"}], "timestamp":"1780150427588", "event_type":"price_change"}
{"market":"0x7976b8dbacf9077eb1453a62bcefd6ab2df199acd28aad276ff0d920d6992892", "price_changes":[{"asset_id":"4394372887385518214471608448209527405727552777602031099972143344338178308080", "price":"0.171", "size":"2276.42", "side":"SELL", "hash":"656eab75e3313f7c87a4826630533b43dca5485b", "best_bid":"0.167", "best_ask":"0.168"}, {"asset_id":"112680630004798425069810935278212000865453267506345451433803052322987302357330", "price":"0.829", "size":"2276.42", "side":"BUY", "hash":"d7e3f6699ca3af77ef8ba19f1065ad3c35dac9e2", "best_bid":"0.832", "best_ask":"0.833"}], "timestamp":"1780150427614", "event_type":"price_change"}
{"market":"0x7976b8dbacf9077eb1453a62bcefd6ab2df199acd28aad276ff0d920d6992892", "price_changes":[{"asset_id":"4394372887385518214471608448209527405727552777602031099972143344338178308080", "price":"0.171", "size":"2301.97", "side":"SELL", "hash":"885e3b1bb4f9dc45d076deb345f9cd5763da1fe7", "best_bid":"0.167", "best_ask":"0.168"}, {"asset_id":"112680630004798425069810935278212000865453267506345451433803052322987302357330", "price":"0.829", "size":"2301.97", "side":"BUY", "hash":"4a7a0cff3a7c4c676bb1bf0086744d93d894d4e3", "best_bid":"0.832", "best_ask":"0.833"}], "timestamp":"1780150427748", "event_type":"price_change"}
{"market":"0x30d55d8124ee1e12dabe89201badc45669b81dff69e4ce44d961f32878ec178a", "price_changes":[{"asset_id":"27576533317283401577758999384642760405921738493660383550832555714312627457443", "price":"0.093", "size":"87369.17", "side":"SELL", "hash":"3670dbfd88644a0ee873b617464f2d6b0b152182", "best_bid":"0.09", "best_ask":"0.091"}, {"asset_id":"52986718774908357330412653486471347449818893503063830313445318937088822580057", "price":"0.907", "size":"87369.17", "side":"BUY", "hash":"4589e7dc2a1ed17768f308d87f9102228f3feead", "best_bid":"0.909", "best_ask":"0.91"}], "timestamp":"1780150427830", "event_type":"price_change"}
{"market":"0x4f3421fb2daf5cca7430ed8d8132463963081572d75434393a1808fdb8829fe8", "price_changes":[{"asset_id":"45415751658241142530386585138386640503488308219341470020075667342738719018629", "price":"0.103", "size":"18122.51", "side":"SELL", "hash":"18972466c09a637fdd35d7d2bf417487e20a3586", "best_bid":"0.1", "best_ask":"0.101"}, {"asset_id":"31940783580344558651011323787577288681658737625185216525249046282994042503801", "price":"0.897", "size":"18122.51", "side":"BUY", "hash":"a5e1ff95831ab64f0ed9344fe2932c19f68f686a", "best_bid":"0.899", "best_ask":"0.9"}], "timestamp":"1780150427848", "event_type":"price_change"}
{"market":"0x375409bc5eeeff961e82b479caeccc20f33d15738e5bce1186d628aa3d9dfb1f", "price_changes":[{"asset_id":"115556263888245616435851357148058235707004733438163639091106356867234218207169", "price":"0.115", "size":"12919.15", "side":"SELL", "hash":"3b8820904c4ef083434ba8707350f2de4255ea16", "best_bid":"0.111", "best_ask":"0.112"}, {"asset_id":"77121637225348873006259930776623502125079210522997384841464684944292365296940", "price":"0.885", "size":"12919.15", "side":"BUY", "hash":"fbc49fff686962280c28ed4bd1d13db88be4640c", "best_bid":"0.888", "best_ask":"0.889"}], "timestamp":"1780150427884", "event_type":"price_change"}
{"market":"0x9b6fef249040fd17e9c107955b37ac2c3e923509b6b0ff01cc463a331ddeb894", "price_changes":[{"asset_id":"108233603819467706476318984012158651931658302669301887462181073562758483842092", "price":"0.167", "size":"3784.75", "side":"SELL", "hash":"7c8c6d89e2126c7b25c805e9178ceddf8f41ee8e", "best_bid":"0.163", "best_ask":"0.164"}, {"asset_id":"32270411694523539495262303868629477861017829722282576458031815333486368239544", "price":"0.833", "size":"3784.75", "side":"BUY", "hash":"d3a9529d23f77d0cac0ea0a0e95a1f772e19e5cd", "best_bid":"0.836", "best_ask":"0.837"}], "timestamp":"1780150427915", "event_type":"price_change"}
{"market":"0x4f3421fb2daf5cca7430ed8d8132463963081572d75434393a1808fdb8829fe8", "price_changes":[{"asset_id":"45415751658241142530386585138386640503488308219341470020075667342738719018629", "price":"0.103", "size":"18183.31", "side":"SELL", "hash":"0bb92a3793cf1a62790a7cf41797b0225f8a181f", "best_bid":"0.1", "best_ask":"0.101"}, {"asset_id":"31940783580344558651011323787577288681658737625185216525249046282994042503801", "price":"0.897", "size":"18183.31", "side":"BUY", "hash":"3c372e959d1e624077ed5c5d8c3d35d96b9e1f66", "best_bid":"0.899", "best_ask":"0.9"}], "timestamp":"1780150427947", "event_type":"price_change"}
{"market":"0x30d55d8124ee1e12dabe89201badc45669b81dff69e4ce44d961f32878ec178a", "price_changes":[{"asset_id":"27576533317283401577758999384642760405921738493660383550832555714312627457443", "price":"0.093", "size":"87424.83", "side":"SELL", "hash":"0329f9342cd83135a2beaf3e1644dcc56d2197b3", "best_bid":"0.09", "best_ask":"0.091"}, {"asset_id":"52986718774908357330412653486471347449818893503063830313445318937088822580057", "price":"0.907", "size":"87424.83", "side":"BUY", "hash":"887e5bb488700f60456f67175d2022b6792bed84", "best_bid":"0.909", "best_ask":"0.91"}], "timestamp":"1780150427952", "event_type":"price_change"}
{"market":"0x375409bc5eeeff961e82b479caeccc20f33d15738e5bce1186d628aa3d9dfb1f", "price_changes":[{"asset_id":"115556263888245616435851357148058235707004733438163639091106356867234218207169", "price":"0.115", "size":"12999.15", "side":"SELL", "hash":"882730a5f437d7845a98bf4b2f2c7d4fbaafc6d4", "best_bid":"0.111", "best_ask":"0.112"}, {"asset_id":"77121637225348873006259930776623502125079210522997384841464684944292365296940", "price":"0.885", "size":"12999.15", "side":"BUY", "hash":"c86060fc2a4187ec06487def15e9949f27bd56e5", "best_bid":"0.888", "best_ask":"0.889"}], "timestamp":"1780150427980", "event_type":"price_change"}
{"market":"0x9b6fef249040fd17e9c107955b37ac2c3e923509b6b0ff01cc463a331ddeb894", "price_changes":[{"asset_id":"108233603819467706476318984012158651931658302669301887462181073562758483842092", "price":"0.167", "size":"3864.75", "side":"SELL", "hash":"8763165c2737fe15de5fa971c47f87392d4ea1c2", "best_bid":"0.163", "best_ask":"0.164"}, {"asset_id":"32270411694523539495262303868629477861017829722282576458031815333486368239544", "price":"0.833", "size":"3864.75", "side":"BUY", "hash":"5f95f9e83fc37b689177568e8a039f290a7d939b", "best_bid":"0.836", "best_ask":"0.837"}], "timestamp":"1780150428013", "event_type":"price_change"}
{"market":"0x375409bc5eeeff961e82b479caeccc20f33d15738e5bce1186d628aa3d9dfb1f", "price_changes":[{"asset_id":"115556263888245616435851357148058235707004733438163639091106356867234218207169", "price":"0.06", "size":"50150", "side":"BUY", "hash":"89b6c5bdf315f01dfbb71914dd7caa11bc3accd0", "best_bid":"0.111", "best_ask":"0.112"}, {"asset_id":"77121637225348873006259930776623502125079210522997384841464684944292365296940", "price":"0.94", "size":"50150", "side":"SELL", "hash":"e7fc77a71fed1fc07f03e625ed5345597714dfa3", "best_bid":"0.888", "best_ask":"0.889"}], "timestamp":"1780150429085", "event_type":"price_change"}
{"market":"0x4f3421fb2daf5cca7430ed8d8132463963081572d75434393a1808fdb8829fe8", "price_changes":[{"asset_id":"31940783580344558651011323787577288681658737625185216525249046282994042503801", "price":"0.862", "size":"25", "side":"BUY", "hash":"1d64faa0232d6452ce56d6fb07efb91af499c3e9", "best_bid":"0.899", "best_ask":"0.9"}, {"asset_id":"45415751658241142530386585138386640503488308219341470020075667342738719018629", "price":"0.138", "size":"25", "side":"SELL", "hash":"3c723db056fb93e969842dc345de42178999dbef", "best_bid":"0.1", "best_ask":"0.101"}], "timestamp":"1780150429359", "event_type":"price_change"}
{"market":"0x375409bc5eeeff961e82b479caeccc20f33d15738e5bce1186d628aa3d9dfb1f", "price_changes":[{"asset_id":"115556263888245616435851357148058235707004733438163639091106356867234218207169", "price":"0.05", "size":"3875", "side":"BUY", "hash":"e6fa8721fa760c8ac6022c26369fc9cea5e1aafa", "best_bid":"0.111", "best_ask":"0.112"}, {"asset_id":"77121637225348873006259930776623502125079210522997384841464684944292365296940", "price":"0.95", "size":"3875", "side":"SELL", "hash":"8d98477e2789a9e11a7787d3fd75abef5075fbe1", "best_bid":"0.888", "best_ask":"0.889"}], "timestamp":"1780150429506", "event_type":"price_change"}
{"market":"0x7876851632c295043c66536150a304cb785abdf712ba8489d298c6e6926be106", "price_changes":[{"asset_id":"97239126062673310243763617236644392945530356142765650402171508075574679292913", "price":"0.011", "size":"1798856.4", "side":"SELL", "hash":"4f0ba82e50c46c9479185b8ab5c7bdfbea313ead", "best_bid":"0.01", "best_ask":"0.011"}, {"asset_id":"19291692040378529618917910599727571242305935029274321291612270922648172794670", "price":"0.989", "size":"1798856.4", "side":"BUY", "hash":"4eaf378e90c2dcf030172a9068587ab1b3b1c066", "best_bid":"0.989", "best_ask":"0.99"}], "timestamp":"1780150430098", "event_type":"price_change"}
{"market":"0x0c4cd2055d6ea89354ffddc55d6dbcef9355748112ea952fc925f3db6a5c457f", "price_changes":[{"asset_id":"18812649149814341758733697580460697418474693998558159483117100240528657629879", "price":"0.088", "size":"15049.46", "side":"SELL", "hash":"288a3bd4c8ada73c12e2656169151fac36d28156", "best_bid":"0.085", "best_ask":"0.086"}, {"asset_id":"115428153746996892211798999366308897078723117634059783423375188043903703749062", "price":"0.912", "size":"15049.46", "side":"BUY", "hash":"bec72b5ff9ab77324ac40d50556237861ef63233", "best_bid":"0.914", "best_ask":"0.915"}], "timestamp":"1780150430204", "event_type":"price_change"}
{"market":"0x0c4cd2055d6ea89354ffddc55d6dbcef9355748112ea952fc925f3db6a5c457f", "price_changes":[{"asset_id":"18812649149814341758733697580460697418474693998558159483117100240528657629879", "price":"0.088", "size":"15129.46", "side":"SELL", "hash":"0b748bdb5cf89ae5383abee4ea24c38a78b585b5", "best_bid":"0.085", "best_ask":"0.086"}, {"asset_id":"115428153746996892211798999366308897078723117634059783423375188043903703749062", "price":"0.912", "size":"15129.46", "side":"BUY", "hash":"9533d307ce198e3889146e5143cb3d2d6964d3ad", "best_bid":"0.914", "best_ask":"0.915"}], "timestamp":"1780150430288", "event_type":"price_change"}
{"market":"0x9b6fef249040fd17e9c107955b37ac2c3e923509b6b0ff01cc463a331ddeb894", "price_changes":[{"asset_id":"32270411694523539495262303868629477861017829722282576458031815333486368239544", "price":"0.802", "size":"89", "side":"BUY", "hash":"7db3c0022d858c28cae4c06d1a1c9d4609920ddb", "best_bid":"0.836", "best_ask":"0.837"}, {"asset_id":"108233603819467706476318984012158651931658302669301887462181073562758483842092", "price":"0.198", "size":"89", "side":"SELL", "hash":"053e4c508dcc6268c1647f54938fca5d127e414d", "best_bid":"0.163", "best_ask":"0.164"}], "timestamp":"1780150430809", "event_type":"price_change"}
{"market":"0x375409bc5eeeff961e82b479caeccc20f33d15738e5bce1186d628aa3d9dfb1f", "price_changes":[{"asset_id":"115556263888245616435851357148058235707004733438163639091106356867234218207169", "price":"0.06", "size":"50316.67", "side":"BUY", "hash":"21ed39f03887f183935bba67d3fddc05517ab22f", "best_bid":"0.111", "best_ask":"0.112"}, {"asset_id":"77121637225348873006259930776623502125079210522997384841464684944292365296940", "price":"0.94", "size":"50316.67", "side":"SELL", "hash":"7ba7f922694ef464e73ed21c4eed6c98d42ce9b0", "best_bid":"0.888", "best_ask":"0.889"}], "timestamp":"1780150430899", "event_type":"price_change"}
{"market":"0x7876851632c295043c66536150a304cb785abdf712ba8489d298c6e6926be106", "price_changes":[{"asset_id":"97239126062673310243763617236644392945530356142765650402171508075574679292913", "price":"0.011", "size":"1798765.49", "side":"SELL", "hash":"45e99711bd9346edc5f2f4c2aa05f91e67245cc7", "best_bid":"0.01", "best_ask":"0.011"}, {"asset_id":"19291692040378529618917910599727571242305935029274321291612270922648172794670", "price":"0.989", "size":"1798765.49", "side":"BUY", "hash":"ba7f3adc5f9790b0d07fbb6df2594794ae6d6926", "best_bid":"0.989", "best_ask":"0.99"}], "timestamp":"1780150431031", "event_type":"price_change"}
{"market":"0x7876851632c295043c66536150a304cb785abdf712ba8489d298c6e6926be106", "asset_id":"19291692040378529618917910599727571242305935029274321291612270922648172794670", "bids":[{"price":"0.001", "size":"21002524.32"}, {"price":"0.002", "size":"90011.18"}, {"price":"0.003", "size":"800"}, {"price":"0.004", "size":"70.1"}, {"price":"0.031", "size":"500"}, {"price":"0.05", "size":"40"}, {"price":"0.051", "size":"9.59"}, {"price":"0.1", "size":"2500"}, {"price":"0.2", "size":"1000"}, {"price":"0.201", "size":"5.94"}, {"price":"0.247", "size":"121.45"}, {"price":"0.3", "size":"600"}, {"price":"0.4", "size":"34625"}, {"price":"0.401", "size":"18000"}, {"price":"0.45", "size":"100"}, {"price":"0.451", "size":"1330"}, {"price":"0.5", "size":"25000"}, {"price":"0.501", "size":"12000"}, {"price":"0.51", "size":"7.97"}, {"price":"0.6", "size":"20833.33"}, {"price":"0.65", "size":"15384.62"}, {"price":"0.652", "size":"2095.26"}, {"price":"0.653", "size":"1103"}, {"price":"0.75", "size":"100"}, {"price":"0.778", "size":"227.27"}, {"price":"0.808", "size":"8"}, {"price":"0.841", "size":"1000"}, {"price":"0.85", "size":"445.83"}, {"price":"0.851", "size":"400"}, {"price":"0.871", "size":"1000"}, {"price":"0.891", "size":"1000"}, {"price":"0.9", "size":"90.9"}, {"price":"0.901", "size":"1000"}, {"price":"0.902", "size":"30"}, {"price":"0.904", "size":"8"}, {"price":"0.911", "size":"1100"}, {"price":"0.92", "size":"1000"}, {"price":"0.921", "size":"1000"}, {"price":"0.93", "size":"3800"}, {"price":"0.931", "size":"125"}, {"price":"0.935", "size":"3500"}, {"price":"0.936", "size":"25"}, {"price":"0.938", "size":"3500"}, {"price":"0.94", "size":"2000"}, {"price":"0.941", "size":"50"}, {"price":"0.943", "size":"3000"}, {"price":"0.944", "size":"2000"}, {"price":"0.95", "size":"3309.92"}, {"price":"0.951", "size":"2045"}, {"price":"0.952", "size":"3833.33"}, {"price":"0.953", "size":"75"}, {"price":"0.954", "size":"19"}, {"price":"0.955", "size":"3067"}, {"price":"0.956", "size":"125"}, {"price":"0.957", "size":"3000"}, {"price":"0.958", "size":"3000"}, {"price":"0.96", "size":"232.7"}, {"price":"0.961", "size":"3007.2"}, {"price":"0.964", "size":"5000"}, {"price":"0.965", "size":"15430.62"}, {"price":"0.967", "size":"10424"}, {"price":"0.968", "size":"4287.08"}, {"price":"0.97", "size":"18916.9"}, {"price":"0.971", "size":"3000"}, {"price":"0.972", "size":"14648"}, {"price":"0.974", "size":"5000"}, {"price":"0.975", "size":"10372.72"}, {"price":"0.976", "size":"5500"}, {"price":"0.978", "size":"17239.4"}, {"price":"0.979", "size":"6000"}, {"price":"0.98", "size":"14721.53"}, {"price":"0.981", "size":"2790.7"}, {"price":"0.982", "size":"62681.81"}, {"price":"0.983", "size":"110028.15"}, {"price":"0.984", "size":"118582.98"}, {"price":"0.985", "size":"107389"}, {"price":"0.986", "size":"10"}, {"price":"0.987", "size":"8338.33"}, {"price":"0.988", "size":"4839211.94"}, {"price":"0.989", "size":"1798765.49"}], "asks":[{"price":"0.999", "size":"3862270"}, {"price":"0.998", "size":"1322096"}, {"price":"0.997", "size":"451830"}, {"price":"0.996", "size":"72622"}, {"price":"0.995", "size":"30650"}, {"price":"0.994", "size":"11473.99"}, {"price":"0.993", "size":"31428.57"}, {"price":"0.992", "size":"328294"}, {"price":"0.991", "size":"247324.61"}, {"price":"0.99", "size":"1180706.14"}], "hash":"ba7f3adc5f9790b0d07fbb6df2594794ae6d6926", "timestamp":"1780150431031", "event_type":"book"}
{"market":"0x375409bc5eeeff961e82b479caeccc20f33d15738e5bce1186d628aa3d9dfb1f", "price_changes":[{"asset_id":"115556263888245616435851357148058235707004733438163639091106356867234218207169", "price":"0.05", "size":"3975", "side":"BUY", "hash":"5adc427bc38282d9e877dfd7c3cfb29ca8764a1f", "best_bid":"0.111", "best_ask":"0.112"}, {"asset_id":"77121637225348873006259930776623502125079210522997384841464684944292365296940", "price":"0.95", "size":"3975", "side":"SELL", "hash":"e32dd2ee5b7215421aa450c99f83a5d6d0e604c5", "best_bid":"0.888", "best_ask":"0.889"}], "timestamp":"1780150431625", "event_type":"price_change"}
{"market":"0x30d55d8124ee1e12dabe89201badc45669b81dff69e4ce44d961f32878ec178a", "price_changes":[{"asset_id":"52986718774908357330412653486471347449818893503063830313445318937088822580057", "price":"0.861", "size":"50", "side":"BUY", "hash":"c06cfd35a6e7957d370af83aaad061329f2a60f1", "best_bid":"0.909", "best_ask":"0.91"}, {"asset_id":"27576533317283401577758999384642760405921738493660383550832555714312627457443", "price":"0.139", "size":"50", "side":"SELL", "hash":"5efca6d5caa1bc009fef8f6662dabc5cf4f25dc8", "best_bid":"0.09", "best_ask":"0.091"}], "timestamp":"1780150432298", "event_type":"price_change"}
{"market":"0x1595b4818eeb1ea1e0bec5de6f057218e557feee9b405a0e930d290384fa1d16", "price_changes":[{"asset_id":"45484070731786948288366703334552551439356529561722304542938873238430842810537", "price":"0.901", "size":"100", "side":"BUY", "hash":"5eb8ae078b0ccdf4e220f8c1b210ae9c8a966105", "best_bid":"0.948", "best_ask":"0.949"}, {"asset_id":"81739002353269632749850710185641576213562066971072676369728657545679630163887", "price":"0.099", "size":"100", "side":"SELL", "hash":"c14b1f4299482c22c909a96b863f99120639c541", "best_bid":"0.051", "best_ask":"0.052"}], "timestamp":"1780150432298", "event_type":"price_change"}
{"market":"0x7976b8dbacf9077eb1453a62bcefd6ab2df199acd28aad276ff0d920d6992892", "price_changes":[{"asset_id":"112680630004798425069810935278212000865453267506345451433803052322987302357330", "price":"0.792", "size":"0", "side":"BUY", "hash":"e40fbbefab25141e784e7d38999bdb0bbd2eff57", "best_bid":"0.832", "best_ask":"0.833"}, {"asset_id":"4394372887385518214471608448209527405727552777602031099972143344338178308080", "price":"0.208", "size":"0", "side":"SELL", "hash":"45ebfbed35d7f15832cdd0d7e0d7fb4f0f66488b", "best_bid":"0.167", "best_ask":"0.168"}], "timestamp":"1780150432299", "event_type":"price_change"}
{"market":"0x7976b8dbacf9077eb1453a62bcefd6ab2df199acd28aad276ff0d920d6992892", "price_changes":[{"asset_id":"112680630004798425069810935278212000865453267506345451433803052322987302357330", "price":"0.791", "size":"0", "side":"BUY", "hash":"e40fbbefab25141e784e7d38999bdb0bbd2eff57", "best_bid":"0.832", "best_ask":"0.833"}, {"asset_id":"4394372887385518214471608448209527405727552777602031099972143344338178308080", "price":"0.209", "size":"0", "side":"SELL", "hash":"45ebfbed35d7f15832cdd0d7e0d7fb4f0f66488b", "best_bid":"0.167", "best_ask":"0.168"}], "timestamp":"1780150432299", "event_type":"price_change"}
{"market":"0x375409bc5eeeff961e82b479caeccc20f33d15738e5bce1186d628aa3d9dfb1f", "price_changes":[{"asset_id":"115556263888245616435851357148058235707004733438163639091106356867234218207169", "price":"0.115", "size":"12939.15", "side":"SELL", "hash":"d6c062bf12f833e7c629205fe916f453853a9d88", "best_bid":"0.111", "best_ask":"0.112"}, {"asset_id":"77121637225348873006259930776623502125079210522997384841464684944292365296940", "price":"0.885", "size":"12939.15", "side":"BUY", "hash":"83eaacdc1ed2d363ab5eeafbc8037102bf65d468", "best_bid":"0.888", "best_ask":"0.889"}], "timestamp":"1780150432740", "event_type":"price_change"}
{"market":"0x1595b4818eeb1ea1e0bec5de6f057218e557feee9b405a0e930d290384fa1d16", "price_changes":[{"asset_id":"81739002353269632749850710185641576213562066971072676369728657545679630163887", "price":"0.054", "size":"9325.11", "side":"SELL", "hash":"8eb38a004fbb4968a863426c41680284a9ab7998", "best_bid":"0.051", "best_ask":"0.052"}, {"asset_id":"45484070731786948288366703334552551439356529561722304542938873238430842810537", "price":"0.946", "size":"9325.11", "side":"BUY", "hash":"4ccc9b2117e1e91eeceb18db812dab6dedcfbf8b", "best_bid":"0.948", "best_ask":"0.949"}], "timestamp":"1780150432768", "event_type":"price_change"}
{"market":"0x9b6fef249040fd17e9c107955b37ac2c3e923509b6b0ff01cc463a331ddeb894", "price_changes":[{"asset_id":"108233603819467706476318984012158651931658302669301887462181073562758483842092", "price":"0.167", "size":"3810.2", "side":"SELL", "hash":"5a3fc804f44c8181f02126e536cf0d42fa1bb0e2", "best_bid":"0.163", "best_ask":"0.164"}, {"asset_id":"32270411694523539495262303868629477861017829722282576458031815333486368239544", "price":"0.833", "size":"3810.2", "side":"BUY", "hash":"645fd97b635ec73d901d6a283b24cdc9596cbc13", "best_bid":"0.836", "best_ask":"0.837"}], "timestamp":"1780150432770", "event_type":"price_change"}
{"market":"0x30d55d8124ee1e12dabe89201badc45669b81dff69e4ce44d961f32878ec178a", "price_changes":[{"asset_id":"27576533317283401577758999384642760405921738493660383550832555714312627457443", "price":"0.093", "size":"87364.83", "side":"SELL", "hash":"469557fc898fa3b103c6f875d20eec109fb659f1", "best_bid":"0.09", "best_ask":"0.091"}, {"asset_id":"52986718774908357330412653486471347449818893503063830313445318937088822580057", "price":"0.907", "size":"87364.83", "side":"BUY", "hash":"ac54f139cb48bd0353cdc832cee797066f21503d", "best_bid":"0.909", "best_ask":"0.91"}], "timestamp":"1780150432772", "event_type":"price_change"}
{"market":"0x375409bc5eeeff961e82b479caeccc20f33d15738e5bce1186d628aa3d9dfb1f", "price_changes":[{"asset_id":"115556263888245616435851357148058235707004733438163639091106356867234218207169", "price":"0.115", "size":"12999.15", "side":"SELL", "hash":"da0886acc0cd3dd36a25d513910a0f3879c4e9c7", "best_bid":"0.111", "best_ask":"0.112"}, {"asset_id":"77121637225348873006259930776623502125079210522997384841464684944292365296940", "price":"0.885", "size":"12999.15", "side":"BUY", "hash":"d4e7c70906b51a8098d3827d9f71109ff19e1185", "best_bid":"0.888", "best_ask":"0.889"}], "timestamp":"1780150432824", "event_type":"price_change"}
{"market":"0x1595b4818eeb1ea1e0bec5de6f057218e557feee9b405a0e930d290384fa1d16", "price_changes":[{"asset_id":"81739002353269632749850710185641576213562066971072676369728657545679630163887", "price":"0.054", "size":"9385.11", "side":"SELL", "hash":"a667f2138055c1c3c7856479a0820f2018c95b74", "best_bid":"0.051", "best_ask":"0.052"}, {"asset_id":"45484070731786948288366703334552551439356529561722304542938873238430842810537", "price":"0.946", "size":"9385.11", "side":"BUY", "hash":"70cd69321b9cfc76856c5263831e4279826835f4", "best_bid":"0.948", "best_ask":"0.949"}], "timestamp":"1780150432866", "event_type":"price_change"}
{"market":"0x30d55d8124ee1e12dabe89201badc45669b81dff69e4ce44d961f32878ec178a", "price_changes":[{"asset_id":"27576533317283401577758999384642760405921738493660383550832555714312627457443", "price":"0.093", "size":"87424.83", "side":"SELL", "hash":"8d384ddcfc59cc00f6c9b62048a53412b4622e05", "best_bid":"0.09", "best_ask":"0.091"}, {"asset_id":"52986718774908357330412653486471347449818893503063830313445318937088822580057", "price":"0.907", "size":"87424.83", "side":"BUY", "hash":"37040511d83a11b62b48e7891f2de4418aa6715c", "best_bid":"0.909", "best_ask":"0.91"}], "timestamp":"1780150432868", "event_type":"price_change"}
{"market":"0x9b6fef249040fd17e9c107955b37ac2c3e923509b6b0ff01cc463a331ddeb894", "price_changes":[{"asset_id":"108233603819467706476318984012158651931658302669301887462181073562758483842092", "price":"0.167", "size":"3864.75", "side":"SELL", "hash":"11f731794fa735a337d329c8bb89f3a771ea6ff3", "best_bid":"0.163", "best_ask":"0.164"}, {"asset_id":"32270411694523539495262303868629477861017829722282576458031815333486368239544", "price":"0.833", "size":"3864.75", "side":"BUY", "hash":"409712b04553e8a0c76d40ac8602130fe69de877", "best_bid":"0.836", "best_ask":"0.837"}], "timestamp":"1780150432869", "event_type":"price_change"}
