[{"market":"0x1fad72fae204143ff1c3035e99e7c0f65ea8d5cd9bd1070987bd1a3316f772be","asset_id":"98022490269692409998126496127597032490334070080325855126491859374983463996227","timestamp":"1779862954465","hash":"44f415e4e345a3e9a2b9578a713f78a945d664be","bids":[{"price":"0.01","size":"39183.01"},{"price":"0.02","size":"5257.75"},{"price":"0.03","size":"4700"},{"price":"0.04","size":"29451.82"},{"price":"0.05","size":"20"},{"price":"0.06","size":"3674.77"},{"price":"0.07","size":"3128.57"},{"price":"0.08","size":"352.94"},{"price":"0.09","size":"622.22"},{"price":"0.11","size":"654.54"},{"price":"0.12","size":"3091.41"},{"price":"0.13","size":"855.76"},{"price":"0.14","size":"1030.78"},{"price":"0.15","size":"460.33"},{"price":"0.18","size":"2835.71"},{"price":"0.19","size":"336.84"},{"price":"0.22","size":"6859.04"},{"price":"0.23","size":"2651.86"},{"price":"0.25","size":"603.72"},{"price":"0.26","size":"589.31"},{"price":"0.29","size":"86.2"},{"price":"0.32","size":"1722.15"},{"price":"0.33","size":"454"},{"price":"0.35","size":"2223.97"},{"price":"0.36","size":"413.08"},{"price":"0.37","size":"10"},{"price":"0.38","size":"1725.03"},{"price":"0.4","size":"2085.96"},{"price":"0.41","size":"1701.47"},{"price":"0.42","size":"1795.13"},{"price":"0.43","size":"156.44"},{"price":"0.44","size":"550"},{"price":"0.45","size":"261.35"},{"price":"0.46","size":"31.08"},{"price":"0.47","size":"325.99"},{"price":"0.48","size":"5"},{"price":"0.49","size":"1000"},{"price":"0.5","size":"13639"},{"price":"0.51","size":"4883.21"},{"price":"0.52","size":"65.7"},{"price":"0.53","size":"168.43"},{"price":"0.54","size":"63.96"}],"asks":[{"price":"0.99","size":"32303.66"},{"price":"0.98","size":"6145.88"},{"price":"0.97","size":"1533"},{"price":"0.94","size":"3100"},{"price":"0.93","size":"8350.52"},{"price":"0.92","size":"1193.08"},{"price":"0.91","size":"388"},{"price":"0.9","size":"5"},{"price":"0.89","size":"1645.78"},{"price":"0.86","size":"5166.61"},{"price":"0.85","size":"1276.54"},{"price":"0.84","size":"1250"},{"price":"0.83","size":"70"},{"price":"0.81","size":"800"},{"price":"0.8","size":"2190.18"},{"price":"0.79","size":"1582.91"},{"price":"0.78","size":"1184.61"},{"price":"0.77","size":"863.45"},{"price":"0.76","size":"723"},{"price":"0.75","size":"489.2"},{"price":"0.74","size":"459"},{"price":"0.73","size":"216.8"},{"price":"0.7","size":"13.63"},{"price":"0.68","size":"453.03"},{"price":"0.67","size":"181.21"},{"price":"0.66","size":"255.99"},{"price":"0.65","size":"272.39"},{"price":"0.64","size":"8.81"},{"price":"0.62","size":"46.18"},{"price":"0.61","size":"43.46"},{"price":"0.6","size":"27.5"},{"price":"0.59","size":"13"},{"price":"0.56","size":"36.84"},{"price":"0.55","size":"33"}],"tick_size":"0.01","event_type":"book","last_trade_price":"0.550"}]

PONG
{"market":"0x1fad72fae204143ff1c3035e99e7c0f65ea8d5cd9bd1070987bd1a3316f772be","price_changes":[{"asset_id":"98022490269692409998126496127597032490334070080325855126491859374983463996227","price":"0.14","size":"1130.78","side":"BUY","hash":"227f34f867489060d04c3b93495d0dfd6d5680be","best_bid":"0.54","best_ask":"0.55"},{"asset_id":"53831553061883006530739877284105938919721408776239639687877978808906551086026","price":"0.86","size":"1130.78","side":"SELL","hash":"393e21c41202066d96c6057185e156bf224f65ab","best_bid":"0.45","best_ask":"0.46"}],"timestamp":"1779862957116","event_type":"price_change"}
{"market":"0x1fad72fae204143ff1c3035e99e7c0f65ea8d5cd9bd1070987bd1a3316f772be","price_changes":[{"asset_id":"98022490269692409998126496127597032490334070080325855126491859374983463996227","price":"0.07","size":"3528.57","side":"BUY","hash":"fbeeec13fa38a799d4852b4d0e98f98e47f4f5e5","best_bid":"0.54","best_ask":"0.55"},{"asset_id":"53831553061883006530739877284105938919721408776239639687877978808906551086026","price":"0.93","size":"3528.57","side":"SELL","hash":"4a7dcb6c26d6b54c8644576596b6dfe409804927","best_bid":"0.45","best_ask":"0.46"}],"timestamp":"1779862957120","event_type":"price_change"}
{"market":"0x1fad72fae204143ff1c3035e99e7c0f65ea8d5cd9bd1070987bd1a3316f772be","price_changes":[{"asset_id":"98022490269692409998126496127597032490334070080325855126491859374983463996227","price":"0.04","size":"30051.82","side":"BUY","hash":"0dc0e69a667107ffac967fe10775dc0f1ca5452e","best_bid":"0.54","best_ask":"0.55"},{"asset_id":"53831553061883006530739877284105938919721408776239639687877978808906551086026","price":"0.96","size":"30051.82","side":"SELL","hash":"3df3581fc1f88de355236e40c03a2785e0996136","best_bid":"0.45","best_ask":"0.46"}],"timestamp":"1779862957168","event_type":"price_change"}
{"market":"0x1fad72fae204143ff1c3035e99e7c0f65ea8d5cd9bd1070987bd1a3316f772be","price_changes":[{"asset_id":"98022490269692409998126496127597032490334070080325855126491859374983463996227","price":"0.04","size":"15801.82","side":"BUY","hash":"eda2a9025b2476567e300db83b6748d0e71643fa","best_bid":"0.54","best_ask":"0.55"},{"asset_id":"53831553061883006530739877284105938919721408776239639687877978808906551086026","price":"0.96","size":"15801.82","side":"SELL","hash":"69f8fe7aa835d035f2ca01490cf3e1571f77c50f","best_bid":"0.45","best_ask":"0.46"}],"timestamp":"1779862957998","event_type":"price_change"}
{"market":"0x1fad72fae204143ff1c3035e99e7c0f65ea8d5cd9bd1070987bd1a3316f772be","price_changes":[{"asset_id":"98022490269692409998126496127597032490334070080325855126491859374983463996227","price":"0.05","size":"11420","side":"BUY","hash":"e4416eacf2bdc82f90d95324832c9baa0978600a","best_bid":"0.54","best_ask":"0.55"},{"asset_id":"53831553061883006530739877284105938919721408776239639687877978808906551086026","price":"0.95","size":"11420","side":"SELL","hash":"ac555c2194faaad0e7da582e6edd8dee35854897","best_bid":"0.45","best_ask":"0.46"}],"timestamp":"1779862958010","event_type":"price_change"}
{"market":"0x1fad72fae204143ff1c3035e99e7c0f65ea8d5cd9bd1070987bd1a3316f772be","price_changes":[{"asset_id":"98022490269692409998126496127597032490334070080325855126491859374983463996227","price":"0.05","size":"11400","side":"BUY","hash":"a9e0503f8bd7a201f8d5ada72798048b4c71d486","best_bid":"0.54","best_ask":"0.55"},{"asset_id":"53831553061883006530739877284105938919721408776239639687877978808906551086026","price":"0.95","size":"11400","side":"SELL","hash":"a1ae1ca6f0d181b44be91330d4475a14420d8087","best_bid":"0.45","best_ask":"0.46"}],"timestamp":"1779862958049","event_type":"price_change"}
{"market":"0x1fad72fae204143ff1c3035e99e7c0f65ea8d5cd9bd1070987bd1a3316f772be","price_changes":[{"asset_id":"98022490269692409998126496127597032490334070080325855126491859374983463996227","price":"0.43","size":"411.44","side":"BUY","hash":"8445dc3c28fa65263d80d483bd416be5120bb214","best_bid":"0.54","best_ask":"0.55"},{"asset_id":"53831553061883006530739877284105938919721408776239639687877978808906551086026","price":"0.57","size":"411.44","side":"SELL","hash":"3d2e22f60a281a833d00e612d9423cfcfbf3d1e2","best_bid":"0.45","best_ask":"0.46"}],"timestamp":"1779862958620","event_type":"price_change"}
{"market":"0x1fad72fae204143ff1c3035e99e7c0f65ea8d5cd9bd1070987bd1a3316f772be","price_changes":[{"asset_id":"98022490269692409998126496127597032490334070080325855126491859374983463996227","price":"0.26","size":"339.31","side":"BUY","hash":"174ebe6a2bd9efe2508d5e5ca7ce667243fd32ef","best_bid":"0.54","best_ask":"0.55"},{"asset_id":"53831553061883006530739877284105938919721408776239639687877978808906551086026","price":"0.74","size":"339.31","side":"SELL","hash":"644e07995acaec4aa433c5a3c91985cb5bd99d19","best_bid":"0.45","best_ask":"0.46"}],"timestamp":"1779862961491","event_type":"price_change"}
{"market":"0x1fad72fae204143ff1c3035e99e7c0f65ea8d5cd9bd1070987bd1a3316f772be","price_changes":[{"asset_id":"98022490269692409998126496127597032490334070080325855126491859374983463996227","price":"0.13","size":"230.76","side":"BUY","hash":"174ebe6a2bd9efe2508d5e5ca7ce667243fd32ef","best_bid":"0.54","best_ask":"0.55"},{"asset_id":"53831553061883006530739877284105938919721408776239639687877978808906551086026","price":"0.87","size":"230.76","side":"SELL","hash":"644e07995acaec4aa433c5a3c91985cb5bd99d19","best_bid":"0.45","best_ask":"0.46"}],"timestamp":"1779862961491","event_type":"price_change"}
{"market":"0x1fad72fae204143ff1c3035e99e7c0f65ea8d5cd9bd1070987bd1a3316f772be","price_changes":[{"asset_id":"98022490269692409998126496127597032490334070080325855126491859374983463996227","price":"0.03","size":"2700","side":"BUY","hash":"bff29db437e2e0129ca25d50a81e4e141bccdfb8","best_bid":"0.54","best_ask":"0.55"},{"asset_id":"53831553061883006530739877284105938919721408776239639687877978808906551086026","price":"0.97","size":"2700","side":"SELL","hash":"44cf719c678cd6ecbe438a5275c65bc3301de0d1","best_bid":"0.45","best_ask":"0.46"}],"timestamp":"1779862961494","event_type":"price_change"}
{"market":"0x1fad72fae204143ff1c3035e99e7c0f65ea8d5cd9bd1070987bd1a3316f772be","price_changes":[{"asset_id":"98022490269692409998126496127597032490334070080325855126491859374983463996227","price":"0.06","size":"2674.77","side":"BUY","hash":"bff29db437e2e0129ca25d50a81e4e141bccdfb8","best_bid":"0.54","best_ask":"0.55"},{"asset_id":"53831553061883006530739877284105938919721408776239639687877978808906551086026","price":"0.94","size":"2674.77","side":"SELL","hash":"44cf719c678cd6ecbe438a5275c65bc3301de0d1","best_bid":"0.45","best_ask":"0.46"}],"timestamp":"1779862961494","event_type":"price_change"}
{"market":"0x1fad72fae204143ff1c3035e99e7c0f65ea8d5cd9bd1070987bd1a3316f772be","price_changes":[{"asset_id":"98022490269692409998126496127597032490334070080325855126491859374983463996227","price":"0.04","size":"17801.82","side":"BUY","hash":"66a4f88b13a556ba1b6d88a9ce37c4ebfc35f939","best_bid":"0.54","best_ask":"0.55"},{"asset_id":"53831553061883006530739877284105938919721408776239639687877978808906551086026","price":"0.96","size":"17801.82","side":"SELL","hash":"7cb5e3abf56e00a3d76b6cfb561d31eec2b6d012","best_bid":"0.45","best_ask":"0.46"}],"timestamp":"1779862963413","event_type":"price_change"}
{"market":"0x1fad72fae204143ff1c3035e99e7c0f65ea8d5cd9bd1070987bd1a3316f772be","price_changes":[{"asset_id":"98022490269692409998126496127597032490334070080325855126491859374983463996227","price":"0.14","size":"1755.78","side":"BUY","hash":"9424b0ed849a4cf9b0b41b30ff4951e497a80943","best_bid":"0.54","best_ask":"0.55"},{"asset_id":"53831553061883006530739877284105938919721408776239639687877978808906551086026","price":"0.86","size":"1755.78","side":"SELL","hash":"5745fbbb43e670212999a92506a761682079e30c","best_bid":"0.45","best_ask":"0.46"}],"timestamp":"1779862963427","event_type":"price_change"}
{"market":"0x1fad72fae204143ff1c3035e99e7c0f65ea8d5cd9bd1070987bd1a3316f772be","price_changes":[{"asset_id":"98022490269692409998126496127597032490334070080325855126491859374983463996227","price":"0.08","size":"1352.94","side":"BUY","hash":"d34a1f144a046d110757fd72e2419b948b8db25a","best_bid":"0.54","best_ask":"0.55"},{"asset_id":"53831553061883006530739877284105938919721408776239639687877978808906551086026","price":"0.92","size":"1352.94","side":"SELL","hash":"5d2cf061ad526fbbdb787e62a15d51b279787d3b","best_bid":"0.45","best_ask":"0.46"}],"timestamp":"1779862963438","event_type":"price_change"}
{"market":"0x1fad72fae204143ff1c3035e99e7c0f65ea8d5cd9bd1070987bd1a3316f772be","price_changes":[{"asset_id":"98022490269692409998126496127597032490334070080325855126491859374983463996227","price":"0.25","size":"853.72","side":"BUY","hash":"62bc9ac84aa9b3a75faebbeffae5515e3d630df6","best_bid":"0.54","best_ask":"0.55"},{"asset_id":"53831553061883006530739877284105938919721408776239639687877978808906551086026","price":"0.75","size":"853.72","side":"SELL","hash":"12540ad4ad239adf2adf58049b63427d44d847e4","best_bid":"0.45","best_ask":"0.46"}],"timestamp":"1779862963451","event_type":"price_change"}
PONG
{"market":"0x1fad72fae204143ff1c3035e99e7c0f65ea8d5cd9bd1070987bd1a3316f772be","price_changes":[{"asset_id":"98022490269692409998126496127597032490334070080325855126491859374983463996227","price":"0.06","size":"1874.77","side":"BUY","hash":"832581e0c2df5f89944c9e65fdc25b083e0926c8","best_bid":"0.54","best_ask":"0.55"},{"asset_id":"53831553061883006530739877284105938919721408776239639687877978808906551086026","price":"0.94","size":"1874.77","side":"SELL","hash":"0694212aa7a741d3537e90e87407f7ec0dc1ce2f","best_bid":"0.45","best_ask":"0.46"}],"timestamp":"1779862966670","event_type":"price_change"}
{"market":"0x1fad72fae204143ff1c3035e99e7c0f65ea8d5cd9bd1070987bd1a3316f772be","price_changes":[{"asset_id":"98022490269692409998126496127597032490334070080325855126491859374983463996227","price":"0.12","size":"2791.41","side":"BUY","hash":"832581e0c2df5f89944c9e65fdc25b083e0926c8","best_bid":"0.54","best_ask":"0.55"},{"asset_id":"53831553061883006530739877284105938919721408776239639687877978808906551086026","price":"0.88","size":"2791.41","side":"SELL","hash":"0694212aa7a741d3537e90e87407f7ec0dc1ce2f","best_bid":"0.45","best_ask":"0.46"}],"timestamp":"1779862966670","event_type":"price_change"}
{"market":"0x1fad72fae204143ff1c3035e99e7c0f65ea8d5cd9bd1070987bd1a3316f772be","price_changes":[{"asset_id":"98022490269692409998126496127597032490334070080325855126491859374983463996227","price":"0.07","size":"2928.57","side":"BUY","hash":"832581e0c2df5f89944c9e65fdc25b083e0926c8","best_bid":"0.54","best_ask":"0.55"},{"asset_id":"53831553061883006530739877284105938919721408776239639687877978808906551086026","price":"0.93","size":"2928.57","side":"SELL","hash":"0694212aa7a741d3537e90e87407f7ec0dc1ce2f","best_bid":"0.45","best_ask":"0.46"}],"timestamp":"1779862966670","event_type":"price_change"}
{"market":"0x1fad72fae204143ff1c3035e99e7c0f65ea8d5cd9bd1070987bd1a3316f772be","price_changes":[{"asset_id":"98022490269692409998126496127597032490334070080325855126491859374983463996227","price":"0.14","size":"2055.78","side":"BUY","hash":"6998e8e479af24462f485543720506b4f7f3313f","best_bid":"0.54","best_ask":"0.55"},{"asset_id":"53831553061883006530739877284105938919721408776239639687877978808906551086026","price":"0.86","size":"2055.78","side":"SELL","hash":"98affe4ae0eea7914e6dd681f2f4f57cc358f6e1","best_bid":"0.45","best_ask":"0.46"}],"timestamp":"1779862969197","event_type":"price_change"}
{"market":"0x1fad72fae204143ff1c3035e99e7c0f65ea8d5cd9bd1070987bd1a3316f772be","price_changes":[{"asset_id":"98022490269692409998126496127597032490334070080325855126491859374983463996227","price":"0.08","size":"1852.94","side":"BUY","hash":"5121988f75981f624185eaa5ac93fd2f06e31d62","best_bid":"0.54","best_ask":"0.55"},{"asset_id":"53831553061883006530739877284105938919721408776239639687877978808906551086026","price":"0.92","size":"1852.94","side":"SELL","hash":"4f098ae14f9415d5bfd8de02ce03670af915aa28","best_bid":"0.45","best_ask":"0.46"}],"timestamp":"1779862969208","event_type":"price_change"}
{"market":"0x1fad72fae204143ff1c3035e99e7c0f65ea8d5cd9bd1070987bd1a3316f772be","price_changes":[{"asset_id":"98022490269692409998126496127597032490334070080325855126491859374983463996227","price":"0.04","size":"18801.82","side":"BUY","hash":"01fbf74c6d477238e267e2366f60f1360799c7b1","best_bid":"0.54","best_ask":"0.55"},{"asset_id":"53831553061883006530739877284105938919721408776239639687877978808906551086026","price":"0.96","size":"18801.82","side":"SELL","hash":"5f2ab0ad7e4ef3612c1ad80107d535d22c06bbb1","best_bid":"0.45","best_ask":"0.46"}],"timestamp":"1779862969223","event_type":"price_change"}
{"market":"0x1fad72fae204143ff1c3035e99e7c0f65ea8d5cd9bd1070987bd1a3316f772be","price_changes":[{"asset_id":"98022490269692409998126496127597032490334070080325855126491859374983463996227","price":"0.01","size":"39188.01","side":"BUY","hash":"d82b1322157f8295e2d91c21f345bbea0ddf82cb","best_bid":"0.54","best_ask":"0.55"},{"asset_id":"53831553061883006530739877284105938919721408776239639687877978808906551086026","price":"0.99","size":"39188.01","side":"SELL","hash":"cfa7820a391a1e8474e63945e0730be61eb5c4f0","best_bid":"0.45","best_ask":"0.46"}],"timestamp":"1779862969355","event_type":"price_change"}
{"market":"0x1fad72fae204143ff1c3035e99e7c0f65ea8d5cd9bd1070987bd1a3316f772be","price_changes":[{"asset_id":"98022490269692409998126496127597032490334070080325855126491859374983463996227","price":"0.32","size":"159.15","side":"BUY","hash":"bcfa4c12e332e33c7296379e5907f8943c6420b4","best_bid":"0.54","best_ask":"0.55"},{"asset_id":"53831553061883006530739877284105938919721408776239639687877978808906551086026","price":"0.68","size":"159.15","side":"SELL","hash":"7bf61c0fe0891472eddf8888ad20c55bd221ff7b","best_bid":"0.45","best_ask":"0.46"}],"timestamp":"1779862970706","event_type":"price_change"}
{"market":"0x1fad72fae204143ff1c3035e99e7c0f65ea8d5cd9bd1070987bd1a3316f772be","price_changes":[{"asset_id":"98022490269692409998126496127597032490334070080325855126491859374983463996227","price":"0.26","size":"2263.31","side":"BUY","hash":"9be3ccc225a45e27b717f855745e12f1d3788ebc","best_bid":"0.54","best_ask":"0.55"},{"asset_id":"53831553061883006530739877284105938919721408776239639687877978808906551086026","price":"0.74","size":"2263.31","side":"SELL","hash":"3684582d56646685083e07d0030f29fd500bc3ae","best_bid":"0.45","best_ask":"0.46"}],"timestamp":"1779862970718","event_type":"price_change"}
{"market":"0x1fad72fae204143ff1c3035e99e7c0f65ea8d5cd9bd1070987bd1a3316f772be","price_changes":[{"asset_id":"98022490269692409998126496127597032490334070080325855126491859374983463996227","price":"0.01","size":"39183.01","side":"BUY","hash":"38c5df1ca17039952f92447fa6ce9842c1aacb64","best_bid":"0.54","best_ask":"0.55"},{"asset_id":"53831553061883006530739877284105938919721408776239639687877978808906551086026","price":"0.99","size":"39183.01","side":"SELL","hash":"7011746629cc0c30287419dfa79093ecdc0a5e8e","best_bid":"0.45","best_ask":"0.46"}],"timestamp":"1779862970884","event_type":"price_change"}
{"market":"0x1fad72fae204143ff1c3035e99e7c0f65ea8d5cd9bd1070987bd1a3316f772be","price_changes":[{"asset_id":"98022490269692409998126496127597032490334070080325855126491859374983463996227","price":"0.14","size":"1388.78","side":"BUY","hash":"3c4facb174cd67587ed45f7bd390086eb0472ba9","best_bid":"0.54","best_ask":"0.55"},{"asset_id":"53831553061883006530739877284105938919721408776239639687877978808906551086026","price":"0.86","size":"1388.78","side":"SELL","hash":"b9336a301d728f3d562db90670bc3007732396d1","best_bid":"0.45","best_ask":"0.46"}],"timestamp":"1779862973791","event_type":"price_change"}
{"market":"0x1fad72fae204143ff1c3035e99e7c0f65ea8d5cd9bd1070987bd1a3316f772be","price_changes":[{"asset_id":"98022490269692409998126496127597032490334070080325855126491859374983463996227","price":"0.33","size":"0","side":"BUY","hash":"b018a04103d6e9288b0a95439d5c2f147843850c","best_bid":"0.54","best_ask":"0.55"},{"asset_id":"53831553061883006530739877284105938919721408776239639687877978808906551086026","price":"0.67","size":"0","side":"SELL","hash":"5ee6882b8894a6961b2f25798e3e209d64901144","best_bid":"0.45","best_ask":"0.46"}],"timestamp":"1779862975330","event_type":"price_change"}
{"market":"0x1fad72fae204143ff1c3035e99e7c0f65ea8d5cd9bd1070987bd1a3316f772be","price_changes":[{"asset_id":"98022490269692409998126496127597032490334070080325855126491859374983463996227","price":"0.27","size":"555","side":"BUY","hash":"ecdecc01fd0e94b4f1aade5b63f1fca3b60fcac2","best_bid":"0.54","best_ask":"0.55"},{"asset_id":"53831553061883006530739877284105938919721408776239639687877978808906551086026","price":"0.73","size":"555","side":"SELL","hash":"933ee6500f649c486e61d5a59517600ef7fbc86e","best_bid":"0.45","best_ask":"0.46"}],"timestamp":"1779862975336","event_type":"price_change"}
PONG
{"market":"0x1fad72fae204143ff1c3035e99e7c0f65ea8d5cd9bd1070987bd1a3316f772be","price_changes":[{"asset_id":"98022490269692409998126496127597032490334070080325855126491859374983463996227","price":"0.13","size":"897.76","side":"BUY","hash":"fcbd3ddaef1d91399b38183d9ac11cb48b64450a","best_bid":"0.54","best_ask":"0.55"},{"asset_id":"53831553061883006530739877284105938919721408776239639687877978808906551086026","price":"0.87","size":"897.76","side":"SELL","hash":"c52a6ffd8eb1cd21868fc2235fe606d431750bb1","best_bid":"0.45","best_ask":"0.46"}],"timestamp":"1779862976810","event_type":"price_change"}
{"market":"0x1fad72fae204143ff1c3035e99e7c0f65ea8d5cd9bd1070987bd1a3316f772be","price_changes":[{"asset_id":"98022490269692409998126496127597032490334070080325855126491859374983463996227","price":"0.26","size":"339.31","side":"BUY","hash":"f4600243220ba020b092cf561de83129e3f09669","best_bid":"0.54","best_ask":"0.55"},{"asset_id":"53831553061883006530739877284105938919721408776239639687877978808906551086026","price":"0.74","size":"339.31","side":"SELL","hash":"0a01efc9d0e4f56cc1c178fcb51f8d2deefdf3c0","best_bid":"0.45","best_ask":"0.46"}],"timestamp":"1779862976901","event_type":"price_change"}
{"market":"0x1fad72fae204143ff1c3035e99e7c0f65ea8d5cd9bd1070987bd1a3316f772be","price_changes":[{"asset_id":"98022490269692409998126496127597032490334070080325855126491859374983463996227","price":"0.28","size":"1786","side":"BUY","hash":"aa6eb568bbc0bf38ecd415e21c485908731436d1","best_bid":"0.54","best_ask":"0.55"},{"asset_id":"53831553061883006530739877284105938919721408776239639687877978808906551086026","price":"0.72","size":"1786","side":"SELL","hash":"1ddb174fab63bb4250796142776072c775f980eb","best_bid":"0.45","best_ask":"0.46"}],"timestamp":"1779862976992","event_type":"price_change"}
{"market":"0x1fad72fae204143ff1c3035e99e7c0f65ea8d5cd9bd1070987bd1a3316f772be","price_changes":[{"asset_id":"98022490269692409998126496127597032490334070080325855126491859374983463996227","price":"0.7","size":"0","side":"SELL","hash":"cc1958507c8eca21d269612c97c29839b3cbca85","best_bid":"0.54","best_ask":"0.55"},{"asset_id":"53831553061883006530739877284105938919721408776239639687877978808906551086026","price":"0.3","size":"0","side":"BUY","hash":"61707b96b42193bdbd9d7c95662c4f25d2999963","best_bid":"0.45","best_ask":"0.46"}],"timestamp":"1779862978380","event_type":"price_change"}
{"market":"0x1fad72fae204143ff1c3035e99e7c0f65ea8d5cd9bd1070987bd1a3316f772be","price_changes":[{"asset_id":"98022490269692409998126496127597032490334070080325855126491859374983463996227","price":"0.06","size":"1074.77","side":"BUY","hash":"ca05573576c7af66aa3561e6ddd7872f0265ee11","best_bid":"0.54","best_ask":"0.55"},{"asset_id":"53831553061883006530739877284105938919721408776239639687877978808906551086026","price":"0.94","size":"1074.77","side":"SELL","hash":"4e8be634859590edaf4ea22d75ae6332c222b964","best_bid":"0.45","best_ask":"0.46"}],"timestamp":"1779862979767","event_type":"price_change"}
{"market":"0x1fad72fae204143ff1c3035e99e7c0f65ea8d5cd9bd1070987bd1a3316f772be","price_changes":[{"asset_id":"98022490269692409998126496127597032490334070080325855126491859374983463996227","price":"0.14","size":"1025","side":"BUY","hash":"f928bb9b19b4d2166bafb5b14fcc3811d80d790d","best_bid":"0.54","best_ask":"0.55"},{"asset_id":"53831553061883006530739877284105938919721408776239639687877978808906551086026","price":"0.86","size":"1025","side":"SELL","hash":"375c336218c36a6bfc8395793c6e2c55d1cf99c5","best_bid":"0.45","best_ask":"0.46"}],"timestamp":"1779862981270","event_type":"price_change"}
{"market":"0x1fad72fae204143ff1c3035e99e7c0f65ea8d5cd9bd1070987bd1a3316f772be","price_changes":[{"asset_id":"98022490269692409998126496127597032490334070080325855126491859374983463996227","price":"0.25","size":"650","side":"BUY","hash":"f928bb9b19b4d2166bafb5b14fcc3811d80d790d","best_bid":"0.54","best_ask":"0.55"},{"asset_id":"53831553061883006530739877284105938919721408776239639687877978808906551086026","price":"0.75","size":"650","side":"SELL","hash":"375c336218c36a6bfc8395793c6e2c55d1cf99c5","best_bid":"0.45","best_ask":"0.46"}],"timestamp":"1779862981270","event_type":"price_change"}
