[{"market":"0x375409bc5eeeff961e82b479caeccc20f33d15738e5bce1186d628aa3d9dfb1f","asset_id":"77121637225348873006259930776623502125079210522997384841464684944292365296940","timestamp":"1780150553779","hash":"c29ecb3c7225dba9fef64f242ed240977590b7d8","bids":[{"price":"0.001","size":"21319088.56"},{"price":"0.002","size":"5005.12"},{"price":"0.003","size":"14.23"},{"price":"0.005","size":"2222222"},{"price":"0.006","size":"2000000"},{"price":"0.007","size":"800"},{"price":"0.008","size":"5.22"},{"price":"0.013","size":"1728"},{"price":"0.014","size":"52"},{"price":"0.1","size":"2991.34"},{"price":"0.151","size":"5000"},{"price":"0.155","size":"200"},{"price":"0.16","size":"300"},{"price":"0.161","size":"300"},{"price":"0.163","size":"300"},{"price":"0.18","size":"300"},{"price":"0.2","size":"1000"},{"price":"0.22","size":"345.04"},{"price":"0.221","size":"200"},{"price":"0.222","size":"135.13"},{"price":"0.223","size":"5.22"},{"price":"0.23","size":"230.97"},{"price":"0.25","size":"300"},{"price":"0.26","size":"300"},{"price":"0.27","size":"300"},{"price":"0.3","size":"2974.99"},{"price":"0.301","size":"200"},{"price":"0.35","size":"293.98"},{"price":"0.38","size":"133.26"},{"price":"0.39","size":"105"},{"price":"0.4","size":"36025"},{"price":"0.408","size":"4900"},{"price":"0.409","size":"6100"},{"price":"0.44","size":"105"},{"price":"0.45","size":"100"},{"price":"0.451","size":"1009.54"},{"price":"0.493","size":"494.73"},{"price":"0.5","size":"27051.85"},{"price":"0.501","size":"4100"},{"price":"0.502","size":"144.67"},{"price":"0.51","size":"275.39"},{"price":"0.55","size":"302.74"},{"price":"0.56","size":"100"},{"price":"0.6","size":"22248.33"},{"price":"0.613","size":"100"},{"price":"0.62","size":"100"},{"price":"0.623","size":"105"},{"price":"0.643","size":"100"},{"price":"0.65","size":"16362.62"},{"price":"0.661","size":"5100"},{"price":"0.662","size":"2095.26"},{"price":"0.67","size":"11.2"},{"price":"0.671","size":"100"},{"price":"0.673","size":"100"},{"price":"0.68","size":"99.99"},{"price":"0.69","size":"242.85"},{"price":"0.7","size":"1709.85"},{"price":"0.703","size":"100"},{"price":"0.712","size":"1000"},{"price":"0.72","size":"252.85"},{"price":"0.721","size":"100"},{"price":"0.733","size":"100"},{"price":"0.74","size":"180.76"},{"price":"0.742","size":"1000"},{"price":"0.75","size":"4558.91"},{"price":"0.761","size":"99.99"},{"price":"0.762","size":"400"},{"price":"0.763","size":"100"},{"price":"0.767","size":"8608.24"},{"price":"0.77","size":"200"},{"price":"0.771","size":"200"},{"price":"0.772","size":"1000"},{"price":"0.774","size":"16354.68"},{"price":"0.776","size":"9000"},{"price":"0.79","size":"3113.4"},{"price":"0.792","size":"1100"},{"price":"0.8","size":"18652.43"},{"price":"0.802","size":"1006.22"},{"price":"0.804","size":"1486.78"},{"price":"0.805","size":"30"},{"price":"0.81","size":"888.99"},{"price":"0.812","size":"1100"},{"price":"0.813","size":"100"},{"price":"0.82","size":"3820"},{"price":"0.822","size":"1000"},{"price":"0.828","size":"5.43"},{"price":"0.83","size":"110"},{"price":"0.834","size":"436.03"},{"price":"0.835","size":"125"},{"price":"0.84","size":"390.66"},{"price":"0.842","size":"75"},{"price":"0.847","size":"263.15"},{"price":"0.85","size":"279.81"},{"price":"0.852","size":"1180.09"},{"price":"0.854","size":"847.46"},{"price":"0.855","size":"219.97"},{"price":"0.856","size":"118.44"},{"price":"0.857","size":"144"},{"price":"0.858","size":"167.16"},{"price":"0.86","size":"190.28"},{"price":"0.861","size":"232.7"},{"price":"0.862","size":"2611.44"},{"price":"0.863","size":"173.7"},{"price":"0.864","size":"145.37"},{"price":"0.865","size":"94.28"},{"price":"0.866","size":"111.44"},{"price":"0.867","size":"15000"},{"price":"0.868","size":"25121.44"},{"price":"0.869","size":"21"},{"price":"0.87","size":"60785.22"},{"price":"0.871","size":"4854.15"},{"price":"0.872","size":"55395.74"},{"price":"0.873","size":"1122.06"},{"price":"0.874","size":"312.33"},{"price":"0.875","size":"1879.28"},{"price":"0.876","size":"349.34"},{"price":"0.877","size":"20"},{"price":"0.878","size":"256.72"},{"price":"0.879","size":"99"},{"price":"0.88","size":"20849.13"},{"price":"0.881","size":"148797.59"},{"price":"0.882","size":"3293.19"},{"price":"0.883","size":"516048.24"},{"price":"0.884","size":"21720.12"},{"price":"0.885","size":"12999.15"},{"price":"0.886","size":"13106.41"},{"price":"0.887","size":"205630.56"},{"price":"0.888","size":"49735.43"}],"asks":[{"price":"0.999","size":"4816069"},{"price":"0.998","size":"1001693"},{"price":"0.996","size":"556755"},{"price":"0.995","size":"55655"},{"price":"0.994","size":"20000"},{"price":"0.993","size":"10800"},{"price":"0.992","size":"10000"},{"price":"0.991","size":"10000"},{"price":"0.99","size":"10000"},{"price":"0.989","size":"5000"},{"price":"0.988","size":"5000"},{"price":"0.987","size":"5000"},{"price":"0.986","size":"5000"},{"price":"0.985","size":"6000"},{"price":"0.984","size":"5000"},{"price":"0.983","size":"5000"},{"price":"0.982","size":"5060"},{"price":"0.981","size":"5000"},{"price":"0.98","size":"5375"},{"price":"0.979","size":"5020"},{"price":"0.978","size":"5000"},{"price":"0.977","size":"5000"},{"price":"0.976","size":"5000"},{"price":"0.96","size":"100"},{"price":"0.951","size":"100"},{"price":"0.95","size":"3975"},{"price":"0.948","size":"87.37"},{"price":"0.947","size":"1093.81"},{"price":"0.94","size":"50316.67"},{"price":"0.936","size":"169.92"},{"price":"0.935","size":"5000"},{"price":"0.93","size":"100"},{"price":"0.924","size":"267.15"},{"price":"0.92","size":"600"},{"price":"0.918","size":"105"},{"price":"0.912","size":"335.31"},{"price":"0.91","size":"500"},{"price":"0.907","size":"300"},{"price":"0.906","size":"16319"},{"price":"0.904","size":"11000"},{"price":"0.903","size":"500"},{"price":"0.9","size":"16088.38"},{"price":"0.899","size":"10000"},{"price":"0.898","size":"1010"},{"price":"0.897","size":"20"},{"price":"0.896","size":"2540"},{"price":"0.895","size":"600"},{"price":"0.894","size":"860"},{"price":"0.893","size":"5000"},{"price":"0.892","size":"9287.02"},{"price":"0.891","size":"11086.74"},{"price":"0.89","size":"150754.77"},{"price":"0.889","size":"242461.2"}],"tick_size":"0.001","event_type":"book","last_trade_price":"0.112"},{"market":"0x7976b8dbacf9077eb1453a62bcefd6ab2df199acd28aad276ff0d920d6992892","asset_id":"112680630004798425069810935278212000865453267506345451433803052322987302357330","timestamp":"1780150565226","hash":"2bf2ea3b30b5dca9bac1b83501f62b7b67cf0a4d","bids":[{"price":"0.001","size":"13320371.6"},{"price":"0.002","size":"9.57"},{"price":"0.003","size":"156.25"},{"price":"0.004","size":"13.49"},{"price":"0.009","size":"8400"},{"price":"0.01","size":"7.03"},{"price":"0.012","size":"666666"},{"price":"0.013","size":"600000"},{"price":"0.014","size":"2534.99"},{"price":"0.016","size":"125.09"},{"price":"0.02","size":"5012"},{"price":"0.021","size":"3999.99"},{"price":"0.022","size":"5.22"},{"price":"0.05","size":"3109.99"},{"price":"0.051","size":"10.45"},{"price":"0.08","size":"3005"},{"price":"0.11","size":"1000"},{"price":"0.12","size":"1000"},{"price":"0.13","size":"1000"},{"price":"0.14","size":"999.99"},{"price":"0.15","size":"1000"},{"price":"0.16","size":"1000"},{"price":"0.167","size":"17.61"},{"price":"0.168","size":"20"},{"price":"0.196","size":"301"},{"price":"0.2","size":"749.67"},{"price":"0.207","size":"400"},{"price":"0.208","size":"544.23"},{"price":"0.209","size":"300"},{"price":"0.21","size":"5.72"},{"price":"0.23","size":"408.6"},{"price":"0.25","size":"544.97"},{"price":"0.31","size":"305.55"},{"price":"0.32","size":"205"},{"price":"0.36","size":"231.25"},{"price":"0.384","size":"7223.76"},{"price":"0.39","size":"5"},{"price":"0.4","size":"34671.65"},{"price":"0.403","size":"1311"},{"price":"0.42","size":"211.4"},{"price":"0.421","size":"567.32"},{"price":"0.45","size":"510.51"},{"price":"0.451","size":"510.51"},{"price":"0.49","size":"220"},{"price":"0.5","size":"29664.87"},{"price":"0.501","size":"4216.7"},{"price":"0.502","size":"130"},{"price":"0.504","size":"457.83"},{"price":"0.505","size":"263.77"},{"price":"0.51","size":"264.58"},{"price":"0.52","size":"100"},{"price":"0.53","size":"100"},{"price":"0.54","size":"100"},{"price":"0.55","size":"726.73"},{"price":"0.56","size":"147"},{"price":"0.57","size":"100"},{"price":"0.58","size":"188.58"},{"price":"0.59","size":"110"},{"price":"0.598","size":"13.07"},{"price":"0.6","size":"26789.54"},{"price":"0.601","size":"274.25"},{"price":"0.602","size":"406.1"},{"price":"0.623","size":"5"},{"price":"0.628","size":"1000"},{"price":"0.63","size":"3300"},{"price":"0.65","size":"15514.62"},{"price":"0.654","size":"124.73"},{"price":"0.656","size":"122.73"},{"price":"0.658","size":"6141.34"},{"price":"0.66","size":"1046.85"},{"price":"0.664","size":"10100"},{"price":"0.666","size":"474.07"},{"price":"0.671","size":"100"},{"price":"0.68","size":"3006"},{"price":"0.681","size":"2095.26"},{"price":"0.688","size":"1000"},{"price":"0.691","size":"2359.94"},{"price":"0.696","size":"100"},{"price":"0.7","size":"282.21"},{"price":"0.701","size":"400"},{"price":"0.717","size":"100"},{"price":"0.718","size":"1000"},{"price":"0.72","size":"11.42"},{"price":"0.726","size":"16.03"},{"price":"0.738","size":"1100"},{"price":"0.748","size":"1000"},{"price":"0.75","size":"3963.47"},{"price":"0.751","size":"30"},{"price":"0.758","size":"1100"},{"price":"0.759","size":"100"},{"price":"0.76","size":"195"},{"price":"0.764","size":"7"},{"price":"0.765","size":"150"},{"price":"0.767","size":"5"},{"price":"0.768","size":"1000"},{"price":"0.77","size":"3823.69"},{"price":"0.774","size":"362.18"},{"price":"0.78","size":"225"},{"price":"0.782","size":"13.78"},{"price":"0.783","size":"16.02"},{"price":"0.785","size":"125"},{"price":"0.786","size":"50"},{"price":"0.79","size":"50"},{"price":"0.794","size":"25.37"},{"price":"0.795","size":"10"},{"price":"0.796","size":"25"},{"price":"0.798","size":"50"},{"price":"0.799","size":"382.17"},{"price":"0.8","size":"8356.84"},{"price":"0.802","size":"1019"},{"price":"0.803","size":"150"},{"price":"0.806","size":"181.36"},{"price":"0.807","size":"232.7"},{"price":"0.808","size":"30"},{"price":"0.809","size":"16007.3"},{"price":"0.812","size":"15279.71"},{"price":"0.814","size":"10"},{"price":"0.815","size":"405.96"},{"price":"0.816","size":"49.77"},{"price":"0.817","size":"50"},{"price":"0.818","size":"50.31"},{"price":"0.819","size":"1000"},{"price":"0.82","size":"12835.92"},{"price":"0.821","size":"41454.56"},{"price":"0.822","size":"930.5"},{"price":"0.823","size":"1627.85"},{"price":"0.824","size":"15407.48"},{"price":"0.825","size":"96558.27"},{"price":"0.826","size":"58022.86"},{"price":"0.827","size":"26925.87"},{"price":"0.828","size":"25913.26"},{"price":"0.829","size":"2301.97"},{"price":"0.83","size":"102064.74"},{"price":"0.831","size":"2054.06"},{"price":"0.832","size":"152279.84"}],"asks":[{"price":"0.999","size":"4816394"},{"price":"0.998","size":"2359"},{"price":"0.997","size":"100"},{"price":"0.996","size":"1111111"},{"price":"0.995","size":"255655"},{"price":"0.994","size":"100000"},{"price":"0.993","size":"10800"},{"price":"0.992","size":"10000"},{"price":"0.991","size":"10000"},{"price":"0.99","size":"10335"},{"price":"0.989","size":"10000"},{"price":"0.988","size":"10000"},{"price":"0.987","size":"5000"},{"price":"0.986","size":"5000"},{"price":"0.985","size":"5000"},{"price":"0.984","size":"5000"},{"price":"0.982","size":"5008.33"},{"price":"0.981","size":"5000"},{"price":"0.98","size":"7380"},{"price":"0.979","size":"3000"},{"price":"0.978","size":"3000"},{"price":"0.977","size":"3000"},{"price":"0.976","size":"3000"},{"price":"0.975","size":"3000"},{"price":"0.974","size":"3000"},{"price":"0.973","size":"3000"},{"price":"0.972","size":"3000"},{"price":"0.959","size":"731.7"},{"price":"0.951","size":"100"},{"price":"0.95","size":"56135"},{"price":"0.931","size":"20"},{"price":"0.93","size":"30"},{"price":"0.927","size":"30"},{"price":"0.926","size":"30"},{"price":"0.9","size":"10035"},{"price":"0.89","size":"91.09"},{"price":"0.889","size":"1077.83"},{"price":"0.88","size":"11038.99"},{"price":"0.879","size":"5"},{"price":"0.878","size":"93.8"},{"price":"0.877","size":"5"},{"price":"0.876","size":"5"},{"price":"0.875","size":"5"},{"price":"0.874","size":"5"},{"price":"0.873","size":"5"},{"price":"0.872","size":"5"},{"price":"0.871","size":"5"},{"price":"0.87","size":"165"},{"price":"0.869","size":"5"},{"price":"0.868","size":"105"},{"price":"0.867","size":"5"},{"price":"0.866","size":"156.01"},{"price":"0.865","size":"5"},{"price":"0.864","size":"5"},{"price":"0.863","size":"5"},{"price":"0.862","size":"5"},{"price":"0.861","size":"5"},{"price":"0.86","size":"2179.99"},{"price":"0.859","size":"6015"},{"price":"0.858","size":"5005"},{"price":"0.857","size":"2505"},{"price":"0.856","size":"15"},{"price":"0.855","size":"5"},{"price":"0.854","size":"6206.58"},{"price":"0.853","size":"3015"},{"price":"0.852","size":"7875"},{"price":"0.851","size":"3105"},{"price":"0.85","size":"47190"},{"price":"0.849","size":"26520"},{"price":"0.848","size":"4713.32"},{"price":"0.847","size":"18384.44"},{"price":"0.846","size":"7101.99"},{"price":"0.845","size":"2090"},{"price":"0.844","size":"3989.08"},{"price":"0.843","size":"30663.44"},{"price":"0.842","size":"7106.04"},{"price":"0.841","size":"538.42"},{"price":"0.84","size":"12647.71"},{"price":"0.839","size":"759"},{"price":"0.838","size":"2708.81"},{"price":"0.837","size":"3792.11"},{"price":"0.836","size":"29110.34"},{"price":"0.835","size":"26149.08"},{"price":"0.834","size":"4697.83"},{"price":"0.833","size":"64310.14"}],"tick_size":"0.001","event_type":"book","last_trade_price":"0.168"},{"market":"0x0c4cd2055d6ea89354ffddc55d6dbcef9355748112ea952fc925f3db6a5c457f","asset_id":"115428153746996892211798999366308897078723117634059783423375188043903703749062","timestamp":"1780150555624","hash":"d5542bc52de85310b04387592b1d1f3e139001cf","bids":[{"price":"0.001","size":"19311591.2"},{"price":"0.002","size":"55.07"},{"price":"0.013","size":"1716.7"},{"price":"0.015","size":"1904.95"},{"price":"0.016","size":"11.03"},{"price":"0.036","size":"36000"},{"price":"0.04","size":"333350"},{"price":"0.041","size":"300000"},{"price":"0.042","size":"800"},{"price":"0.05","size":"14660"},{"price":"0.051","size":"10.53"},{"price":"0.09","size":"19"},{"price":"0.15","size":"127.23"},{"price":"0.22","size":"128.36"},{"price":"0.221","size":"5.26"},{"price":"0.228","size":"131.57"},{"price":"0.27","size":"1904.95"},{"price":"0.39","size":"5"},{"price":"0.4","size":"34375"},{"price":"0.401","size":"10000"},{"price":"0.402","size":"1492"},{"price":"0.45","size":"22.5"},{"price":"0.5","size":"26767.96"},{"price":"0.501","size":"3000"},{"price":"0.502","size":"1077.83"},{"price":"0.6","size":"21522.45"},{"price":"0.601","size":"2000"},{"price":"0.603","size":"1164"},{"price":"0.623","size":"5"},{"price":"0.64","size":"1211"},{"price":"0.65","size":"27012.52"},{"price":"0.66","size":"46.4"},{"price":"0.696","size":"5000"},{"price":"0.7","size":"557.74"},{"price":"0.701","size":"30"},{"price":"0.73","size":"6500"},{"price":"0.738","size":"1000"},{"price":"0.74","size":"100"},{"price":"0.75","size":"3383.18"},{"price":"0.752","size":"2906.99"},{"price":"0.753","size":"25"},{"price":"0.755","size":"125"},{"price":"0.767","size":"5"},{"price":"0.768","size":"1000"},{"price":"0.778","size":"100"},{"price":"0.779","size":"400"},{"price":"0.798","size":"1000"},{"price":"0.799","size":"100"},{"price":"0.8","size":"12081.05"},{"price":"0.801","size":"2095.26"},{"price":"0.81","size":"100"},{"price":"0.818","size":"1000"},{"price":"0.82","size":"183.62"},{"price":"0.828","size":"1000"},{"price":"0.83","size":"2373"},{"price":"0.838","size":"1268.53"},{"price":"0.84","size":"12150"},{"price":"0.841","size":"100"},{"price":"0.843","size":"100"},{"price":"0.845","size":"144"},{"price":"0.848","size":"1000"},{"price":"0.85","size":"4045.57"},{"price":"0.855","size":"11634.31"},{"price":"0.856","size":"7"},{"price":"0.86","size":"716"},{"price":"0.861","size":"144283.19"},{"price":"0.862","size":"100"},{"price":"0.867","size":"438"},{"price":"0.868","size":"50"},{"price":"0.87","size":"996"},{"price":"0.871","size":"209826.98"},{"price":"0.875","size":"1020.47"},{"price":"0.877","size":"25"},{"price":"0.878","size":"45"},{"price":"0.879","size":"75"},{"price":"0.88","size":"15096.64"},{"price":"0.881","size":"19"},{"price":"0.882","size":"648.12"},{"price":"0.883","size":"125"},{"price":"0.884","size":"10789.73"},{"price":"0.886","size":"230.12"},{"price":"0.887","size":"1395.49"},{"price":"0.888","size":"236.32"},{"price":"0.889","size":"1186.28"},{"price":"0.89","size":"6421.54"},{"price":"0.891","size":"5069.15"},{"price":"0.892","size":"52728.52"},{"price":"0.894","size":"355.22"},{"price":"0.895","size":"5319.74"},{"price":"0.896","size":"52728.51"},{"price":"0.897","size":"114.3"},{"price":"0.898","size":"229.06"},{"price":"0.899","size":"27080.06"},{"price":"0.9","size":"35120.43"},{"price":"0.901","size":"34710.7"},{"price":"0.902","size":"84437.86"},{"price":"0.903","size":"1730.09"},{"price":"0.904","size":"1129.06"},{"price":"0.905","size":"2510"},{"price":"0.906","size":"229.06"},{"price":"0.907","size":"33247.87"},{"price":"0.908","size":"15415.06"},{"price":"0.909","size":"8064.56"},{"price":"0.91","size":"36872.79"},{"price":"0.911","size":"25024.11"},{"price":"0.912","size":"15129.46"},{"price":"0.913","size":"59775.19"},{"price":"0.914","size":"171031.75"}],"asks":[{"price":"0.999","size":"4912713.42"},{"price":"0.998","size":"1003359"},{"price":"0.997","size":"1111111"},{"price":"0.996","size":"55555"},{"price":"0.995","size":"500"},{"price":"0.994","size":"6000"},{"price":"0.99","size":"11200"},{"price":"0.985","size":"5.65"},{"price":"0.984","size":"5000000"},{"price":"0.983","size":"800"},{"price":"0.98","size":"5050"},{"price":"0.979","size":"2300"},{"price":"0.97","size":"4330"},{"price":"0.969","size":"367.48"},{"price":"0.959","size":"720"},{"price":"0.958","size":"725.45"},{"price":"0.952","size":"70"},{"price":"0.951","size":"71"},{"price":"0.95","size":"5879.09"},{"price":"0.93","size":"513068.11"},{"price":"0.929","size":"6800"},{"price":"0.928","size":"437"},{"price":"0.927","size":"333"},{"price":"0.925","size":"1245"},{"price":"0.924","size":"5000"},{"price":"0.922","size":"11231.85"},{"price":"0.921","size":"127"},{"price":"0.92","size":"44813"},{"price":"0.919","size":"39326.98"},{"price":"0.918","size":"47132.51"},{"price":"0.917","size":"184952.96"},{"price":"0.916","size":"13437.85"},{"price":"0.915","size":"110194.15"}],"tick_size":"0.001","event_type":"book","last_trade_price":"0.085"},{"market":"0x7876851632c295043c66536150a304cb785abdf712ba8489d298c6e6926be106","asset_id":"19291692040378529618917910599727571242305935029274321291612270922648172794670","timestamp":"1780150572640","hash":"c41a00560822117b6b0f3a5b2e55e55df6c619f3","bids":[{"price":"0.001","size":"21002524.32"},{"price":"0.002","size":"90011.18"},{"price":"0.003","size":"800"},{"price":"0.004","size":"70.1"},{"price":"0.031","size":"500"},{"price":"0.05","size":"40"},{"price":"0.051","size":"33.02"},{"price":"0.1","size":"2500"},{"price":"0.2","size":"1000"},{"price":"0.247","size":"121.45"},{"price":"0.3","size":"600"},{"price":"0.4","size":"34625"},{"price":"0.401","size":"18000"},{"price":"0.45","size":"100"},{"price":"0.451","size":"1330"},{"price":"0.5","size":"25000"},{"price":"0.501","size":"12000"},{"price":"0.51","size":"7.97"},{"price":"0.6","size":"20833.33"},{"price":"0.65","size":"15384.62"},{"price":"0.652","size":"2095.26"},{"price":"0.653","size":"1103"},{"price":"0.75","size":"100"},{"price":"0.778","size":"227.27"},{"price":"0.808","size":"8"},{"price":"0.841","size":"1000"},{"price":"0.85","size":"445.83"},{"price":"0.851","size":"400"},{"price":"0.871","size":"1000"},{"price":"0.891","size":"1000"},{"price":"0.9","size":"90.9"},{"price":"0.901","size":"1000"},{"price":"0.902","size":"30"},{"price":"0.904","size":"8"},{"price":"0.911","size":"1100"},{"price":"0.92","size":"1000"},{"price":"0.921","size":"1000"},{"price":"0.93","size":"3800"},{"price":"0.931","size":"125"},{"price":"0.935","size":"3500"},{"price":"0.936","size":"25"},{"price":"0.938","size":"3500"},{"price":"0.94","size":"2000"},{"price":"0.941","size":"50"},{"price":"0.943","size":"3000"},{"price":"0.944","size":"2000"},{"price":"0.95","size":"3309.92"},{"price":"0.951","size":"2045"},{"price":"0.952","size":"3833.33"},{"price":"0.953","size":"75"},{"price":"0.954","size":"19"},{"price":"0.955","size":"3067"},{"price":"0.956","size":"125"},{"price":"0.957","size":"3000"},{"price":"0.958","size":"3000"},{"price":"0.96","size":"232.7"},{"price":"0.961","size":"3007.2"},{"price":"0.964","size":"5000"},{"price":"0.965","size":"15430.62"},{"price":"0.967","size":"10424"},{"price":"0.968","size":"4287.08"},{"price":"0.97","size":"18916.9"},{"price":"0.971","size":"3000"},{"price":"0.972","size":"14648"},{"price":"0.974","size":"5000"},{"price":"0.975","size":"10372.72"},{"price":"0.976","size":"5500"},{"price":"0.978","size":"17239.4"},{"price":"0.979","size":"6000"},{"price":"0.98","size":"14721.53"},{"price":"0.981","size":"2790.7"},{"price":"0.982","size":"62681.81"},{"price":"0.983","size":"110028.15"},{"price":"0.984","size":"118582.98"},{"price":"0.985","size":"107389"},{"price":"0.986","size":"10"},{"price":"0.987","size":"8338.33"},{"price":"0.988","size":"4839211.94"},{"price":"0.989","size":"1798765.49"}],"asks":[{"price":"0.999","size":"3862270"},{"price":"0.998","size":"1322096"},{"price":"0.997","size":"451830"},{"price":"0.996","size":"72622"},{"price":"0.995","size":"30650"},{"price":"0.994","size":"11473.99"},{"price":"0.993","size":"31428.57"},{"price":"0.992","size":"328294"},{"price":"0.991","size":"247324.61"},{"price":"0.99","size":"1181235.89"}],"tick_size":"0.001","event_type":"book","last_trade_price":"0.010"},{"market":"0x4f3421fb2daf5cca7430ed8d8132463963081572d75434393a1808fdb8829fe8","asset_id":"31940783580344558651011323787577288681658737625185216525249046282994042503801","timestamp":"1780150555760","hash":"3e36bce57b491c7e64c7d057c7f1437bc14f429a","bids":[{"price":"0.001","size":"21074238.91"},{"price":"0.002","size":"37.76"},{"price":"0.01","size":"25929.6"},{"price":"0.011","size":"6.21"},{"price":"0.014","size":"1111111"},{"price":"0.015","size":"1000000"},{"price":"0.02","size":"36500"},{"price":"0.021","size":"800"},{"price":"0.022","size":"11.19"},{"price":"0.05","size":"40"},{"price":"0.077","size":"2000"},{"price":"0.078","size":"5.64"},{"price":"0.1","size":"2229.88"},{"price":"0.11","size":"1016"},{"price":"0.12","size":"1021"},{"price":"0.13","size":"1000"},{"price":"0.14","size":"999.99"},{"price":"0.15","size":"1153.71"},{"price":"0.2","size":"409.2"},{"price":"0.224","size":"433.92"},{"price":"0.225","size":"5.14"},{"price":"0.25","size":"453.7"},{"price":"0.253","size":"200"},{"price":"0.254","size":"200"},{"price":"0.27","size":"200"},{"price":"0.28","size":"200"},{"price":"0.31","size":"200"},{"price":"0.33","size":"215.15"},{"price":"0.34","size":"199.99"},{"price":"0.35","size":"102.46"},{"price":"0.36","size":"228"},{"price":"0.361","size":"100"},{"price":"0.4","size":"34637.29"},{"price":"0.401","size":"5000"},{"price":"0.41","size":"200"},{"price":"0.42","size":"200"},{"price":"0.43","size":"200"},{"price":"0.44","size":"200"},{"price":"0.45","size":"354.02"},{"price":"0.46","size":"200"},{"price":"0.461","size":"1077.83"},{"price":"0.5","size":"25496.62"},{"price":"0.501","size":"5100"},{"price":"0.51","size":"205.76"},{"price":"0.511","size":"100"},{"price":"0.52","size":"100"},{"price":"0.53","size":"100"},{"price":"0.54","size":"100"},{"price":"0.55","size":"100"},{"price":"0.56","size":"100"},{"price":"0.57","size":"100"},{"price":"0.58","size":"100"},{"price":"0.6","size":"21059.73"},{"price":"0.61","size":"100"},{"price":"0.62","size":"111.9"},{"price":"0.632","size":"5322.31"},{"price":"0.64","size":"28.8"},{"price":"0.643","size":"100"},{"price":"0.65","size":"16970.62"},{"price":"0.66","size":"100"},{"price":"0.67","size":"100"},{"price":"0.673","size":"100"},{"price":"0.674","size":"100"},{"price":"0.678","size":"100"},{"price":"0.68","size":"410.68"},{"price":"0.69","size":"100"},{"price":"0.7","size":"422.3"},{"price":"0.703","size":"100"},{"price":"0.704","size":"100"},{"price":"0.708","size":"100"},{"price":"0.71","size":"61.7"},{"price":"0.725","size":"1000"},{"price":"0.733","size":"100"},{"price":"0.75","size":"3192.15"},{"price":"0.755","size":"1000"},{"price":"0.76","size":"341.8"},{"price":"0.763","size":"100"},{"price":"0.764","size":"100"},{"price":"0.767","size":"100"},{"price":"0.768","size":"400"},{"price":"0.777","size":"100"},{"price":"0.78","size":"258.06"},{"price":"0.781","size":"100"},{"price":"0.785","size":"1000"},{"price":"0.79","size":"47.6"},{"price":"0.798","size":"1781.45"},{"price":"0.8","size":"246868.85"},{"price":"0.801","size":"100"},{"price":"0.803","size":"100"},{"price":"0.805","size":"1000"},{"price":"0.815","size":"1000"},{"price":"0.818","size":"30"},{"price":"0.819","size":"100"},{"price":"0.824","size":"100"},{"price":"0.825","size":"1000"},{"price":"0.83","size":"39.23"},{"price":"0.835","size":"1000"},{"price":"0.84","size":"356.45"},{"price":"0.845","size":"100"},{"price":"0.849","size":"2441.52"},{"price":"0.85","size":"19727.35"},{"price":"0.851","size":"800"},{"price":"0.852","size":"125"},{"price":"0.853","size":"118.33"},{"price":"0.855","size":"13.33"},{"price":"0.858","size":"35.21"},{"price":"0.859","size":"25"},{"price":"0.86","size":"34.6"},{"price":"0.861","size":"45"},{"price":"0.866","size":"75"},{"price":"0.867","size":"17.97"},{"price":"0.868","size":"144"},{"price":"0.87","size":"4000"},{"price":"0.872","size":"232.7"},{"price":"0.873","size":"7.26"},{"price":"0.875","size":"170"},{"price":"0.88","size":"197"},{"price":"0.882","size":"1000"},{"price":"0.885","size":"925.73"},{"price":"0.886","size":"100"},{"price":"0.887","size":"100"},{"price":"0.888","size":"100"},{"price":"0.889","size":"100"},{"price":"0.89","size":"16564.23"},{"price":"0.891","size":"1343.33"},{"price":"0.892","size":"7071.71"},{"price":"0.893","size":"15257.35"},{"price":"0.894","size":"120752.78"},{"price":"0.896","size":"28940.81"},{"price":"0.897","size":"18183.31"},{"price":"0.898","size":"126782.5"},{"price":"0.899","size":"98191.81"}],"asks":[{"price":"0.999","size":"4715397.01"},{"price":"0.998","size":"14"},{"price":"0.997","size":"1112792"},{"price":"0.996","size":"55564"},{"price":"0.995","size":"10009"},{"price":"0.994","size":"11109"},{"price":"0.993","size":"10009"},{"price":"0.992","size":"10009"},{"price":"0.991","size":"5009"},{"price":"0.99","size":"6209"},{"price":"0.989","size":"5009"},{"price":"0.988","size":"5009"},{"price":"0.987","size":"4309"},{"price":"0.986","size":"3009"},{"price":"0.985","size":"5009"},{"price":"0.984","size":"3009"},{"price":"0.983","size":"3009"},{"price":"0.982","size":"9"},{"price":"0.981","size":"5009"},{"price":"0.98","size":"6234"},{"price":"0.979","size":"4008.99"},{"price":"0.978","size":"4009"},{"price":"0.977","size":"4009"},{"price":"0.976","size":"3009"},{"price":"0.975","size":"3009"},{"price":"0.974","size":"4009"},{"price":"0.973","size":"3009"},{"price":"0.972","size":"4009"},{"price":"0.971","size":"2009"},{"price":"0.97","size":"4209"},{"price":"0.969","size":"2509"},{"price":"0.968","size":"2652.85"},{"price":"0.967","size":"2509"},{"price":"0.966","size":"2509"},{"price":"0.965","size":"9"},{"price":"0.964","size":"9"},{"price":"0.963","size":"9"},{"price":"0.962","size":"609"},{"price":"0.961","size":"9"},{"price":"0.96","size":"259"},{"price":"0.959","size":"9"},{"price":"0.958","size":"9"},{"price":"0.957","size":"9"},{"price":"0.956","size":"9"},{"price":"0.955","size":"9"},{"price":"0.954","size":"9"},{"price":"0.953","size":"9"},{"price":"0.952","size":"9"},{"price":"0.951","size":"9"},{"price":"0.95","size":"279"},{"price":"0.949","size":"10009"},{"price":"0.948","size":"9"},{"price":"0.947","size":"9"},{"price":"0.946","size":"9"},{"price":"0.945","size":"309"},{"price":"0.944","size":"9"},{"price":"0.943","size":"9"},{"price":"0.942","size":"9"},{"price":"0.941","size":"9"},{"price":"0.94","size":"19"},{"price":"0.939","size":"202"},{"price":"0.938","size":"10009"},{"price":"0.937","size":"5009"},{"price":"0.936","size":"7509"},{"price":"0.935","size":"5151"},{"price":"0.934","size":"6209"},{"price":"0.933","size":"4529"},{"price":"0.932","size":"2856.05"},{"price":"0.931","size":"2772.73"},{"price":"0.93","size":"13367.54"},{"price":"0.929","size":"1564"},{"price":"0.928","size":"5464.3"},{"price":"0.927","size":"1109"},{"price":"0.926","size":"357402.07"},{"price":"0.925","size":"36562.67"},{"price":"0.924","size":"5803.29"},{"price":"0.923","size":"434.15"},{"price":"0.922","size":"512.12"},{"price":"0.921","size":"25029"},{"price":"0.92","size":"15376.09"},{"price":"0.919","size":"1633.99"},{"price":"0.918","size":"14672.52"},{"price":"0.917","size":"3381.41"},{"price":"0.916","size":"9"},{"price":"0.915","size":"826.33"},{"price":"0.914","size":"22609"},{"price":"0.913","size":"4605.61"},{"price":"0.912","size":"1782.17"},{"price":"0.911","size":"570.79"},{"price":"0.91","size":"5344.55"},{"price":"0.909","size":"958.45"},{"price":"0.908","size":"909"},{"price":"0.907","size":"1609"},{"price":"0.906","size":"2240.91"},{"price":"0.905","size":"3928.99"},{"price":"0.904","size":"2009"},{"price":"0.903","size":"7534.46"},{"price":"0.902","size":"1468"},{"price":"0.901","size":"922.07"},{"price":"0.9","size":"139531.33"}],"tick_size":"0.001","event_type":"book","last_trade_price":"0.101"},{"market":"0x9b6fef249040fd17e9c107955b37ac2c3e923509b6b0ff01cc463a331ddeb894","asset_id":"32270411694523539495262303868629477861017829722282576458031815333486368239544","timestamp":"1780150570061","hash":"cafbd2d1452b60b8439914f20da9c3647db524b2","bids":[{"price":"0.001","size":"12219098.99"},{"price":"0.002","size":"178.57"},{"price":"0.003","size":"21.08"},{"price":"0.009","size":"18000"},{"price":"0.01","size":"100"},{"price":"0.011","size":"5.62"},{"price":"0.012","size":"1111111"},{"price":"0.013","size":"900000"},{"price":"0.014","size":"1300"},{"price":"0.015","size":"500"},{"price":"0.02","size":"99"},{"price":"0.021","size":"6.95"},{"price":"0.05","size":"246.52"},{"price":"0.051","size":"10.84"},{"price":"0.09","size":"5.98"},{"price":"0.1","size":"15"},{"price":"0.12","size":"5005"},{"price":"0.121","size":"12000"},{"price":"0.15","size":"67.49"},{"price":"0.178","size":"289.7"},{"price":"0.2","size":"796.33"},{"price":"0.209","size":"143.54"},{"price":"0.22","size":"100.48"},{"price":"0.221","size":"5.22"},{"price":"0.25","size":"3597"},{"price":"0.251","size":"6000"},{"price":"0.29","size":"9.75"},{"price":"0.3","size":"55.88"},{"price":"0.315","size":"1459.85"},{"price":"0.33","size":"1363.34"},{"price":"0.331","size":"3000"},{"price":"0.34","size":"5"},{"price":"0.35","size":"2159.92"},{"price":"0.4","size":"34587.44"},{"price":"0.401","size":"3000"},{"price":"0.47","size":"5688.73"},{"price":"0.5","size":"36499.86"},{"price":"0.502","size":"1529.99"},{"price":"0.503","size":"14000"},{"price":"0.51","size":"90.9"},{"price":"0.511","size":"1202.04"},{"price":"0.55","size":"513.44"},{"price":"0.56","size":"111.11"},{"price":"0.562","size":"655.13"},{"price":"0.563","size":"65.06"},{"price":"0.57","size":"3964.15"},{"price":"0.6","size":"22272.15"},{"price":"0.624","size":"27.04"},{"price":"0.631","size":"1000"},{"price":"0.636","size":"105.03"},{"price":"0.638","size":"23.57"},{"price":"0.64","size":"4479.3"},{"price":"0.648","size":"7.39"},{"price":"0.65","size":"15415.61"},{"price":"0.651","size":"2155.26"},{"price":"0.661","size":"1000"},{"price":"0.67","size":"18.11"},{"price":"0.672","size":"482.66"},{"price":"0.68","size":"38"},{"price":"0.691","size":"1000"},{"price":"0.699","size":"100"},{"price":"0.7","size":"456.89"},{"price":"0.701","size":"400"},{"price":"0.72","size":"267.14"},{"price":"0.721","size":"1000"},{"price":"0.741","size":"1100"},{"price":"0.75","size":"1422.54"},{"price":"0.751","size":"1201"},{"price":"0.752","size":"1367"},{"price":"0.754","size":"334.02"},{"price":"0.756","size":"30"},{"price":"0.76","size":"302"},{"price":"0.761","size":"1000"},{"price":"0.762","size":"200"},{"price":"0.77","size":"3800"},{"price":"0.771","size":"1000"},{"price":"0.777","size":"11.23"},{"price":"0.779","size":"334.02"},{"price":"0.78","size":"237"},{"price":"0.781","size":"125"},{"price":"0.783","size":"100"},{"price":"0.786","size":"15"},{"price":"0.788","size":"10"},{"price":"0.789","size":"5555.55"},{"price":"0.79","size":"122"},{"price":"0.792","size":"75"},{"price":"0.793","size":"10"},{"price":"0.794","size":"1000"},{"price":"0.795","size":"10"},{"price":"0.8","size":"17681.66"},{"price":"0.801","size":"100"},{"price":"0.802","size":"64"},{"price":"0.803","size":"35"},{"price":"0.804","size":"75"},{"price":"0.805","size":"500"},{"price":"0.806","size":"169"},{"price":"0.807","size":"135"},{"price":"0.808","size":"675.7"},{"price":"0.809","size":"2027"},{"price":"0.81","size":"7109.61"},{"price":"0.811","size":"38219.61"},{"price":"0.812","size":"1708.3"},{"price":"0.813","size":"782.67"},{"price":"0.814","size":"1703.37"},{"price":"0.815","size":"5571.35"},{"price":"0.816","size":"10909.83"},{"price":"0.817","size":"7549.45"},{"price":"0.818","size":"3441.57"},{"price":"0.819","size":"340"},{"price":"0.82","size":"5287.95"},{"price":"0.821","size":"1694.21"},{"price":"0.822","size":"22719.93"},{"price":"0.823","size":"44358.4"},{"price":"0.824","size":"47073"},{"price":"0.825","size":"47040.85"},{"price":"0.826","size":"200"},{"price":"0.827","size":"654.36"},{"price":"0.829","size":"20206.62"},{"price":"0.83","size":"26050"},{"price":"0.831","size":"3000"},{"price":"0.833","size":"3864.75"},{"price":"0.834","size":"32172"},{"price":"0.835","size":"246255.86"},{"price":"0.836","size":"34839.64"}],"asks":[{"price":"0.999","size":"2260279"},{"price":"0.998","size":"1557248"},{"price":"0.997","size":"1001200"},{"price":"0.996","size":"55555"},{"price":"0.995","size":"90100"},{"price":"0.99","size":"720"},{"price":"0.985","size":"5.01"},{"price":"0.984","size":"555555"},{"price":"0.983","size":"60000"},{"price":"0.982","size":"105435.9"},{"price":"0.981","size":"800"},{"price":"0.98","size":"5430"},{"price":"0.978","size":"3000"},{"price":"0.976","size":"3000"},{"price":"0.974","size":"3000"},{"price":"0.972","size":"3000"},{"price":"0.97","size":"3000"},{"price":"0.968","size":"3000"},{"price":"0.966","size":"3000"},{"price":"0.96","size":"750"},{"price":"0.951","size":"100"},{"price":"0.95","size":"150"},{"price":"0.94","size":"10"},{"price":"0.937","size":"30"},{"price":"0.936","size":"30"},{"price":"0.935","size":"10"},{"price":"0.934","size":"50"},{"price":"0.931","size":"10"},{"price":"0.93","size":"50"},{"price":"0.926","size":"50"},{"price":"0.925","size":"35"},{"price":"0.924","size":"30"},{"price":"0.923","size":"20"},{"price":"0.922","size":"20"},{"price":"0.921","size":"20"},{"price":"0.92","size":"140"},{"price":"0.91","size":"10100"},{"price":"0.905","size":"105.2"},{"price":"0.9","size":"10096.92"},{"price":"0.899","size":"1076.68"},{"price":"0.893","size":"37.72"},{"price":"0.892","size":"40"},{"price":"0.89","size":"145.45"},{"price":"0.889","size":"5000"},{"price":"0.885","size":"9"},{"price":"0.884","size":"90"},{"price":"0.88","size":"203.33"},{"price":"0.879","size":"7500"},{"price":"0.878","size":"5000"},{"price":"0.877","size":"100"},{"price":"0.875","size":"956.59"},{"price":"0.874","size":"2500"},{"price":"0.87","size":"328"},{"price":"0.869","size":"2537"},{"price":"0.868","size":"17"},{"price":"0.867","size":"1903.93"},{"price":"0.866","size":"27"},{"price":"0.865","size":"37"},{"price":"0.864","size":"5017"},{"price":"0.863","size":"3218"},{"price":"0.862","size":"7"},{"price":"0.861","size":"7"},{"price":"0.86","size":"717"},{"price":"0.859","size":"7"},{"price":"0.858","size":"507"},{"price":"0.857","size":"97"},{"price":"0.856","size":"7"},{"price":"0.855","size":"707"},{"price":"0.854","size":"7"},{"price":"0.853","size":"16722"},{"price":"0.852","size":"7"},{"price":"0.851","size":"707"},{"price":"0.85","size":"10136.66"},{"price":"0.849","size":"877"},{"price":"0.848","size":"107"},{"price":"0.847","size":"27"},{"price":"0.846","size":"257"},{"price":"0.845","size":"3060.64"},{"price":"0.844","size":"20417"},{"price":"0.843","size":"8647.14"},{"price":"0.842","size":"77"},{"price":"0.841","size":"1056.6"},{"price":"0.84","size":"18638"},{"price":"0.839","size":"39045"},{"price":"0.838","size":"7722.83"},{"price":"0.837","size":"28555.52"}],"tick_size":"0.001","event_type":"book","last_trade_price":"0.164"},{"market":"0x1595b4818eeb1ea1e0bec5de6f057218e557feee9b405a0e930d290384fa1d16","asset_id":"45484070731786948288366703334552551439356529561722304542938873238430842810537","timestamp":"1780150553755","hash":"9f47b3f321c0b1253ccc3015d6ad6da05a3243a9","bids":[{"price":"0.001","size":"21202713.62"},{"price":"0.002","size":"105"},{"price":"0.003","size":"32.43"},{"price":"0.01","size":"181.81"},{"price":"0.013","size":"1698.4"},{"price":"0.014","size":"17.32"},{"price":"0.05","size":"2236"},{"price":"0.054","size":"155555"},{"price":"0.055","size":"150000"},{"price":"0.056","size":"800"},{"price":"0.057","size":"5.16"},{"price":"0.1","size":"2500"},{"price":"0.14","size":"27"},{"price":"0.2","size":"1000"},{"price":"0.201","size":"6.67"},{"price":"0.237","size":"126.58"},{"price":"0.3","size":"600"},{"price":"0.348","size":"211.53"},{"price":"0.39","size":"5"},{"price":"0.4","size":"34625"},{"price":"0.401","size":"10000"},{"price":"0.402","size":"1492"},{"price":"0.5","size":"25100"},{"price":"0.501","size":"5000"},{"price":"0.51","size":"87.55"},{"price":"0.511","size":"1103"},{"price":"0.58","size":"17.54"},{"price":"0.584","size":"300"},{"price":"0.6","size":"20859.33"},{"price":"0.61","size":"76.92"},{"price":"0.623","size":"5"},{"price":"0.65","size":"15443.05"},{"price":"0.651","size":"2095.26"},{"price":"0.7","size":"780"},{"price":"0.701","size":"437"},{"price":"0.712","size":"50"},{"price":"0.72","size":"18"},{"price":"0.74","size":"476.92"},{"price":"0.75","size":"2198.07"},{"price":"0.751","size":"400"},{"price":"0.767","size":"5"},{"price":"0.77","size":"43.3"},{"price":"0.78","size":"192.53"},{"price":"0.792","size":"1100"},{"price":"0.8","size":"1307.15"},{"price":"0.801","size":"1500"},{"price":"0.82","size":"12201.05"},{"price":"0.821","size":"400"},{"price":"0.83","size":"1079.99"},{"price":"0.831","size":"1000"},{"price":"0.832","size":"50"},{"price":"0.838","size":"1913.7"},{"price":"0.84","size":"288"},{"price":"0.848","size":"33"},{"price":"0.85","size":"13781.98"},{"price":"0.851","size":"1000"},{"price":"0.855","size":"327.86"},{"price":"0.856","size":"7"},{"price":"0.86","size":"334.14"},{"price":"0.861","size":"1000"},{"price":"0.862","size":"30"},{"price":"0.863","size":"125"},{"price":"0.869","size":"20"},{"price":"0.87","size":"1713.81"},{"price":"0.871","size":"1100"},{"price":"0.878","size":"163.93"},{"price":"0.88","size":"613.23"},{"price":"0.881","size":"1000"},{"price":"0.885","size":"240"},{"price":"0.887","size":"370.37"},{"price":"0.89","size":"5031.81"},{"price":"0.896","size":"1592.3"},{"price":"0.899","size":"100"},{"price":"0.9","size":"23802.24"},{"price":"0.901","size":"100"},{"price":"0.902","size":"7772.33"},{"price":"0.904","size":"500"},{"price":"0.905","size":"5307.69"},{"price":"0.906","size":"25"},{"price":"0.91","size":"11147.07"},{"price":"0.911","size":"956.3"},{"price":"0.912","size":"75"},{"price":"0.913","size":"500"},{"price":"0.915","size":"173.07"},{"price":"0.916","size":"19"},{"price":"0.917","size":"125"},{"price":"0.918","size":"500"},{"price":"0.919","size":"532.55"},{"price":"0.92","size":"1979.21"},{"price":"0.924","size":"5917.15"},{"price":"0.925","size":"6585.96"},{"price":"0.926","size":"3944.76"},{"price":"0.927","size":"5259.68"},{"price":"0.928","size":"7012.91"},{"price":"0.929","size":"42450.48"},{"price":"0.93","size":"32653.14"},{"price":"0.931","size":"10000"},{"price":"0.932","size":"5905.04"},{"price":"0.933","size":"382.3"},{"price":"0.934","size":"6055.04"},{"price":"0.935","size":"22294.08"},{"price":"0.939","size":"950"},{"price":"0.94","size":"2357.57"},{"price":"0.941","size":"250009.76"},{"price":"0.942","size":"11012.52"},{"price":"0.943","size":"1999.94"},{"price":"0.944","size":"16846.47"},{"price":"0.945","size":"3838.22"},{"price":"0.946","size":"9385.11"},{"price":"0.947","size":"4752.36"},{"price":"0.948","size":"407658.91"}],"asks":[{"price":"0.999","size":"2259057"},{"price":"0.998","size":"1000005"},{"price":"0.997","size":"2224894"},{"price":"0.996","size":"56355"},{"price":"0.994","size":"300"},{"price":"0.993","size":"100"},{"price":"0.99","size":"2517.95"},{"price":"0.988","size":"100000"},{"price":"0.981","size":"200"},{"price":"0.98","size":"905"},{"price":"0.972","size":"100000"},{"price":"0.97","size":"1030"},{"price":"0.967","size":"30"},{"price":"0.966","size":"5000"},{"price":"0.965","size":"999.99"},{"price":"0.964","size":"2500"},{"price":"0.961","size":"1500"},{"price":"0.96","size":"8909.44"},{"price":"0.959","size":"1510"},{"price":"0.958","size":"4305"},{"price":"0.957","size":"4718"},{"price":"0.956","size":"1500"},{"price":"0.955","size":"2500"},{"price":"0.954","size":"2720"},{"price":"0.953","size":"2220"},{"price":"0.952","size":"29238.33"},{"price":"0.951","size":"39881.55"},{"price":"0.95","size":"91974.74"},{"price":"0.949","size":"588519.95"}],"tick_size":"0.001","event_type":"book","last_trade_price":"0.051"},{"market":"0x30d55d8124ee1e12dabe89201badc45669b81dff69e4ce44d961f32878ec178a","asset_id":"52986718774908357330412653486471347449818893503063830313445318937088822580057","timestamp":"1780150553752","hash":"328a87d7e507464fa8e8f2be721869b74ee91356","bids":[{"price":"0.001","size":"21109405.6"},{"price":"0.002","size":"23.15"},{"price":"0.004","size":"2222222"},{"price":"0.005","size":"2000000"},{"price":"0.006","size":"800"},{"price":"0.007","size":"9.04"},{"price":"0.01","size":"102.2"},{"price":"0.013","size":"1716.8"},{"price":"0.015","size":"750"},{"price":"0.016","size":"11.01"},{"price":"0.05","size":"40"},{"price":"0.051","size":"10.88"},{"price":"0.09","size":"5"},{"price":"0.1","size":"2500"},{"price":"0.13","size":"22.93"},{"price":"0.2","size":"1000"},{"price":"0.227","size":"132.15"},{"price":"0.228","size":"5.03"},{"price":"0.27","size":"750"},{"price":"0.3","size":"605"},{"price":"0.39","size":"5"},{"price":"0.4","size":"34625"},{"price":"0.401","size":"10000"},{"price":"0.402","size":"1492"},{"price":"0.442","size":"6.78"},{"price":"0.45","size":"21"},{"price":"0.451","size":"21"},{"price":"0.5","size":"25662.35"},{"price":"0.502","size":"2000"},{"price":"0.503","size":"3100"},{"price":"0.51","size":"100"},{"price":"0.52","size":"100"},{"price":"0.53","size":"100"},{"price":"0.54","size":"100"},{"price":"0.55","size":"200"},{"price":"0.56","size":"100"},{"price":"0.6","size":"20920.53"},{"price":"0.601","size":"3100"},{"price":"0.623","size":"105"},{"price":"0.637","size":"100"},{"price":"0.64","size":"1263"},{"price":"0.65","size":"15539.21"},{"price":"0.667","size":"100"},{"price":"0.67","size":"50"},{"price":"0.7","size":"503.29"},{"price":"0.733","size":"1000"},{"price":"0.75","size":"1265.57"},{"price":"0.751","size":"280"},{"price":"0.752","size":"2095.26"},{"price":"0.76","size":"117.48"},{"price":"0.763","size":"1000"},{"price":"0.767","size":"5"},{"price":"0.771","size":"100"},{"price":"0.78","size":"355"},{"price":"0.781","size":"400"},{"price":"0.79","size":"31.9"},{"price":"0.792","size":"100"},{"price":"0.793","size":"1000"},{"price":"0.8","size":"1500.76"},{"price":"0.81","size":"330.25"},{"price":"0.813","size":"1100"},{"price":"0.818","size":"862.62"},{"price":"0.82","size":"217.47"},{"price":"0.823","size":"1000"},{"price":"0.825","size":"600"},{"price":"0.827","size":"30"},{"price":"0.83","size":"471.36"},{"price":"0.833","size":"1100"},{"price":"0.834","size":"100"},{"price":"0.84","size":"68"},{"price":"0.843","size":"1000"},{"price":"0.846","size":"5.31"},{"price":"0.85","size":"4497.11"},{"price":"0.855","size":"263.04"},{"price":"0.856","size":"18.23"},{"price":"0.858","size":"12.56"},{"price":"0.86","size":"2499.34"},{"price":"0.862","size":"125"},{"price":"0.863","size":"75"},{"price":"0.868","size":"2500"},{"price":"0.87","size":"186.7"},{"price":"0.871","size":"437.5"},{"price":"0.872","size":"2500"},{"price":"0.873","size":"45"},{"price":"0.874","size":"75"},{"price":"0.875","size":"619"},{"price":"0.876","size":"6300"},{"price":"0.877","size":"5125"},{"price":"0.88","size":"88.12"},{"price":"0.882","size":"15265.93"},{"price":"0.883","size":"200"},{"price":"0.887","size":"437.5"},{"price":"0.888","size":"106.38"},{"price":"0.89","size":"30299.11"},{"price":"0.891","size":"23245"},{"price":"0.893","size":"4000"},{"price":"0.894","size":"4217.77"},{"price":"0.895","size":"10273.48"},{"price":"0.897","size":"62499.24"},{"price":"0.898","size":"56"},{"price":"0.9","size":"9398.5"},{"price":"0.901","size":"44793.63"},{"price":"0.902","size":"62749.23"},{"price":"0.903","size":"25213.57"},{"price":"0.904","size":"764967.01"},{"price":"0.905","size":"37498.61"},{"price":"0.906","size":"46794.57"},{"price":"0.907","size":"87424.83"},{"price":"0.908","size":"77337.54"},{"price":"0.909","size":"83176.45"}],"asks":[{"price":"0.999","size":"4833617.88"},{"price":"0.998","size":"1000671"},{"price":"0.997","size":"672"},{"price":"0.996","size":"501000"},{"price":"0.995","size":"30100"},{"price":"0.994","size":"1182511"},{"price":"0.993","size":"66355"},{"price":"0.992","size":"10000"},{"price":"0.991","size":"10000"},{"price":"0.99","size":"11815"},{"price":"0.989","size":"5000"},{"price":"0.988","size":"5000"},{"price":"0.987","size":"5000"},{"price":"0.986","size":"5000"},{"price":"0.985","size":"5000"},{"price":"0.984","size":"5000"},{"price":"0.983","size":"5000"},{"price":"0.982","size":"5000"},{"price":"0.981","size":"5000"},{"price":"0.98","size":"5375"},{"price":"0.979","size":"3999.99"},{"price":"0.978","size":"3000"},{"price":"0.977","size":"3000"},{"price":"0.976","size":"3000"},{"price":"0.975","size":"3000"},{"price":"0.974","size":"3000"},{"price":"0.973","size":"3000"},{"price":"0.972","size":"3000"},{"price":"0.97","size":"3800"},{"price":"0.966","size":"134.32"},{"price":"0.965","size":"45.64"},{"price":"0.96","size":"300"},{"price":"0.959","size":"300"},{"price":"0.957","size":"50"},{"price":"0.956","size":"134.85"},{"price":"0.955","size":"763.02"},{"price":"0.954","size":"237.14"},{"price":"0.953","size":"237.14"},{"price":"0.951","size":"10"},{"price":"0.95","size":"241"},{"price":"0.949","size":"6"},{"price":"0.948","size":"6"},{"price":"0.947","size":"6"},{"price":"0.946","size":"6"},{"price":"0.945","size":"6"},{"price":"0.944","size":"6"},{"price":"0.943","size":"6"},{"price":"0.942","size":"356.6"},{"price":"0.941","size":"6"},{"price":"0.94","size":"206"},{"price":"0.939","size":"6"},{"price":"0.938","size":"6"},{"price":"0.937","size":"6"},{"price":"0.936","size":"6"},{"price":"0.935","size":"6"},{"price":"0.934","size":"6"},{"price":"0.933","size":"6"},{"price":"0.932","size":"6"},{"price":"0.931","size":"6"},{"price":"0.93","size":"1238.01"},{"price":"0.929","size":"20006"},{"price":"0.928","size":"16"},{"price":"0.927","size":"6"},{"price":"0.926","size":"4806"},{"price":"0.925","size":"516"},{"price":"0.924","size":"38"},{"price":"0.923","size":"6"},{"price":"0.922","size":"6"},{"price":"0.921","size":"1386"},{"price":"0.92","size":"36680"},{"price":"0.919","size":"32011"},{"price":"0.918","size":"10413.85"},{"price":"0.917","size":"11106"},{"price":"0.916","size":"59297.99"},{"price":"0.915","size":"19118.35"},{"price":"0.914","size":"4477.13"},{"price":"0.913","size":"1903.84"},{"price":"0.912","size":"20654"},{"price":"0.911","size":"169555.05"},{"price":"0.91","size":"41517.84"}],"tick_size":"0.001","event_type":"book","last_trade_price":"0.909"}]

PONG
{"market":"0x1595b4818eeb1ea1e0bec5de6f057218e557feee9b405a0e930d290384fa1d16", "price_changes":[{"asset_id":"81739002353269632749850710185641576213562066971072676369728657545679630163887", "price":"0.054", "size":"9305.11", "side":"SELL", "hash":"d17ee8cb85a44cbf911d282fe1961e4fd7948c37", "best_bid":"0.051", "best_ask":"0.052"}, {"asset_id":"45484070731786948288366703334552551439356529561722304542938873238430842810537", "price":"0.946", "size":"9305.11", "side":"BUY", "hash":"645e6db20f429b9ce1103d79a9e875ff0fb78fa8", "best_bid":"0.948", "best_ask":"0.949"}], "timestamp":"1780150576119", "event_type":"price_change"}
{"market":"0x1595b4818eeb1ea1e0bec5de6f057218e557feee9b405a0e930d290384fa1d16", "price_changes":[{"asset_id":"81739002353269632749850710185641576213562066971072676369728657545679630163887", "price":"0.054", "size":"9385.11", "side":"SELL", "hash":"324f192e306a19d28539b5e5d5aec0e9c1988a2e", "best_bid":"0.051", "best_ask":"0.052"}, {"asset_id":"45484070731786948288366703334552551439356529561722304542938873238430842810537", "price":"0.946", "size":"9385.11", "side":"BUY", "hash":"ebdb2eb0a32300bb4c85178686ba6bfb48f4782f", "best_bid":"0.948", "best_ask":"0.949"}], "timestamp":"1780150576449", "event_type":"price_change"}
{"market":"0x4f3421fb2daf5cca7430ed8d8132463963081572d75434393a1808fdb8829fe8", "price_changes":[{"asset_id":"45415751658241142530386585138386640503488308219341470020075667342738719018629", "price":"0.05", "size":"79", "side":"BUY", "hash":"947dc48eb81465e49a63ed091bf4c43f852cba1d", "best_bid":"0.1", "best_ask":"0.101"}, {"asset_id":"31940783580344558651011323787577288681658737625185216525249046282994042503801", "price":"0.95", "size":"79", "side":"SELL", "hash":"f9c7864fbb201468d3a26436622a2a2e87faab4a", "best_bid":"0.899", "best_ask":"0.9"}], "timestamp":"1780150577413", "event_type":"price_change"}
{"market":"0x4f3421fb2daf5cca7430ed8d8132463963081572d75434393a1808fdb8829fe8", "price_changes":[{"asset_id":"45415751658241142530386585138386640503488308219341470020075667342738719018629", "price":"0.04", "size":"134", "side":"BUY", "hash":"d8827111639873dcc2b74f2bd81575a855172b22", "best_bid":"0.1", "best_ask":"0.101"}, {"asset_id":"31940783580344558651011323787577288681658737625185216525249046282994042503801", "price":"0.96", "size":"134", "side":"SELL", "hash":"058d8be46193d54f901c30786295e544d8764e0a", "best_bid":"0.899", "best_ask":"0.9"}], "timestamp":"1780150577879", "event_type":"price_change"}
{"market":"0x4f3421fb2daf5cca7430ed8d8132463963081572d75434393a1808fdb8829fe8", "price_changes":[{"asset_id":"45415751658241142530386585138386640503488308219341470020075667342738719018629", "price":"0.05", "size":"279", "side":"BUY", "hash":"4f659c50c4bba36152bc18d5f95bed7881bd25b1", "best_bid":"0.1", "best_ask":"0.101"}, {"asset_id":"31940783580344558651011323787577288681658737625185216525249046282994042503801", "price":"0.95", "size":"279", "side":"SELL", "hash":"4c62305a64bd6a6ef36ef184adf480304a3d35a8", "best_bid":"0.899", "best_ask":"0.9"}], "timestamp":"1780150579297", "event_type":"price_change"}
{"market":"0x7976b8dbacf9077eb1453a62bcefd6ab2df199acd28aad276ff0d920d6992892", "price_changes":[{"asset_id":"4394372887385518214471608448209527405727552777602031099972143344338178308080", "price":"0.171", "size":"2276.42", "side":"SELL", "hash":"89c6d36f8ce98ec58540a0327169ed0d8acdf846", "best_bid":"0.167", "best_ask":"0.168"}, {"asset_id":"112680630004798425069810935278212000865453267506345451433803052322987302357330", "price":"0.829", "size":"2276.42", "side":"BUY", "hash":"f838967d363dfa2b7c970405faa393a99b9659b4", "best_bid":"0.832", "best_ask":"0.833"}], "timestamp":"1780150579433", "event_type":"price_change"}
{"market":"0x7976b8dbacf9077eb1453a62bcefd6ab2df199acd28aad276ff0d920d6992892", "price_changes":[{"asset_id":"4394372887385518214471608448209527405727552777602031099972143344338178308080", "price":"0.171", "size":"2301.97", "side":"SELL", "hash":"b44148affc67d55b45d57bc6676b9e431a25765e", "best_bid":"0.167", "best_ask":"0.168"}, {"asset_id":"112680630004798425069810935278212000865453267506345451433803052322987302357330", "price":"0.829", "size":"2301.97", "side":"BUY", "hash":"efa37132fe7654b037bcb1a1f2e189b4fdb433cd", "best_bid":"0.832", "best_ask":"0.833"}], "timestamp":"1780150579505", "event_type":"price_change"}
{"market":"0x4f3421fb2daf5cca7430ed8d8132463963081572d75434393a1808fdb8829fe8", "price_changes":[{"asset_id":"45415751658241142530386585138386640503488308219341470020075667342738719018629", "price":"0.103", "size":"18122.51", "side":"SELL", "hash":"3ebc587baae2d004af5e2128965b57568d83b588", "best_bid":"0.1", "best_ask":"0.101"}, {"asset_id":"31940783580344558651011323787577288681658737625185216525249046282994042503801", "price":"0.897", "size":"18122.51", "side":"BUY", "hash":"37a851008856559144af0961f07fd9f43d36b9c4", "best_bid":"0.899", "best_ask":"0.9"}], "timestamp":"1780150579898", "event_type":"price_change"}
{"market":"0x375409bc5eeeff961e82b479caeccc20f33d15738e5bce1186d628aa3d9dfb1f", "price_changes":[{"asset_id":"115556263888245616435851357148058235707004733438163639091106356867234218207169", "price":"0.115", "size":"12919.15", "side":"SELL", "hash":"f6e57ac7a91f328492b9f69f03c7d1449869d332", "best_bid":"0.111", "best_ask":"0.112"}, {"asset_id":"77121637225348873006259930776623502125079210522997384841464684944292365296940", "price":"0.885", "size":"12919.15", "side":"BUY", "hash":"58375c1925511a12f58c6c36692fb295448ce9e3", "best_bid":"0.888", "best_ask":"0.889"}], "timestamp":"1780150579903", "event_type":"price_change"}
{"market":"0x30d55d8124ee1e12dabe89201badc45669b81dff69e4ce44d961f32878ec178a", "price_changes":[{"asset_id":"27576533317283401577758999384642760405921738493660383550832555714312627457443", "price":"0.093", "size":"87369.17", "side":"SELL", "hash":"1b6135e7359c542cc6584cea8d90fee783f570d0", "best_bid":"0.09", "best_ask":"0.091"}, {"asset_id":"52986718774908357330412653486471347449818893503063830313445318937088822580057", "price":"0.907", "size":"87369.17", "side":"BUY", "hash":"40873dc9345f89e7b127c331c6d76144d616e31f", "best_bid":"0.909", "best_ask":"0.91"}], "timestamp":"1780150579916", "event_type":"price_change"}
{"market":"0x9b6fef249040fd17e9c107955b37ac2c3e923509b6b0ff01cc463a331ddeb894", "price_changes":[{"asset_id":"108233603819467706476318984012158651931658302669301887462181073562758483842092", "price":"0.167", "size":"3784.75", "side":"SELL", "hash":"e6e613e3da65c911b8b02645a2265be8bc9cc30f", "best_bid":"0.163", "best_ask":"0.164"}, {"asset_id":"32270411694523539495262303868629477861017829722282576458031815333486368239544", "price":"0.833", "size":"3784.75", "side":"BUY", "hash":"72a1cb84e1270a12eb2a4ef62449220faf2cba15", "best_bid":"0.836", "best_ask":"0.837"}], "timestamp":"1780150579940", "event_type":"price_change"}
{"market":"0x375409bc5eeeff961e82b479caeccc20f33d15738e5bce1186d628aa3d9dfb1f", "price_changes":[{"asset_id":"115556263888245616435851357148058235707004733438163639091106356867234218207169", "price":"0.115", "size":"12999.15", "side":"SELL", "hash":"b581aabb9dbaf9c7f636805d8ff3d6e275d5f427", "best_bid":"0.111", "best_ask":"0.112"}, {"asset_id":"77121637225348873006259930776623502125079210522997384841464684944292365296940", "price":"0.885", "size":"12999.15", "side":"BUY", "hash":"5268b0f9921c37f888caaef1c89510b0444da670", "best_bid":"0.888", "best_ask":"0.889"}], "timestamp":"1780150579985", "event_type":"price_change"}
{"market":"0x4f3421fb2daf5cca7430ed8d8132463963081572d75434393a1808fdb8829fe8", "price_changes":[{"asset_id":"45415751658241142530386585138386640503488308219341470020075667342738719018629", "price":"0.103", "size":"18183.31", "side":"SELL", "hash":"84ca4a23dee16b2192ad7750b50ffe8afadd858c", "best_bid":"0.1", "best_ask":"0.101"}, {"asset_id":"31940783580344558651011323787577288681658737625185216525249046282994042503801", "price":"0.897", "size":"18183.31", "side":"BUY", "hash":"922ef86eb5c4fd8b427adcc491c3a45d841d875f", "best_bid":"0.899", "best_ask":"0.9"}], "timestamp":"1780150579988", "event_type":"price_change"}
{"market":"0x30d55d8124ee1e12dabe89201badc45669b81dff69e4ce44d961f32878ec178a", "price_changes":[{"asset_id":"27576533317283401577758999384642760405921738493660383550832555714312627457443", "price":"0.093", "size":"87424.83", "side":"SELL", "hash":"9e5776e2993cc2c4f6f8f97a6321d794d7b57256", "best_bid":"0.09", "best_ask":"0.091"}, {"asset_id":"52986718774908357330412653486471347449818893503063830313445318937088822580057", "price":"0.907", "size":"87424.83", "side":"BUY", "hash":"21168d9bda332cd8b37f19fd3137c52c97d90cfb", "best_bid":"0.909", "best_ask":"0.91"}], "timestamp":"1780150580021", "event_type":"price_change"}
{"market":"0x9b6fef249040fd17e9c107955b37ac2c3e923509b6b0ff01cc463a331ddeb894", "price_changes":[{"asset_id":"108233603819467706476318984012158651931658302669301887462181073562758483842092", "price":"0.167", "size":"3864.75", "side":"SELL", "hash":"8d02f0ab079b0ad526bf8619419849e71db62b07", "best_bid":"0.163", "best_ask":"0.164"}, {"asset_id":"32270411694523539495262303868629477861017829722282576458031815333486368239544", "price":"0.833", "size":"3864.75", "side":"BUY", "hash":"60d561ec65945bfc43a879ab96eae72aed8b018c", "best_bid":"0.836", "best_ask":"0.837"}], "timestamp":"1780150580053", "event_type":"price_change"}
{"market":"0x4f3421fb2daf5cca7430ed8d8132463963081572d75434393a1808fdb8829fe8", "price_changes":[{"asset_id":"45415751658241142530386585138386640503488308219341470020075667342738719018629", "price":"0.04", "size":"259", "side":"BUY", "hash":"58de444e696555729929beb387f6a66885e60455", "best_bid":"0.1", "best_ask":"0.101"}, {"asset_id":"31940783580344558651011323787577288681658737625185216525249046282994042503801", "price":"0.96", "size":"259", "side":"SELL", "hash":"36058a6982a454d27fa7a39957b3cc87b67bcd88", "best_bid":"0.899", "best_ask":"0.9"}], "timestamp":"1780150580130", "event_type":"price_change"}
{"market":"0x0c4cd2055d6ea89354ffddc55d6dbcef9355748112ea952fc925f3db6a5c457f", "price_changes":[{"asset_id":"18812649149814341758733697580460697418474693998558159483117100240528657629879", "price":"0.088", "size":"15049.46", "side":"SELL", "hash":"9bde424112cedc8f0b978c7efc6e5c354bd88b59", "best_bid":"0.085", "best_ask":"0.086"}, {"asset_id":"115428153746996892211798999366308897078723117634059783423375188043903703749062", "price":"0.912", "size":"15049.46", "side":"BUY", "hash":"cb80520c803102ef48c59c22eac79a4ab3e57aa3", "best_bid":"0.914", "best_ask":"0.915"}], "timestamp":"1780150581198", "event_type":"price_change"}
{"market":"0x0c4cd2055d6ea89354ffddc55d6dbcef9355748112ea952fc925f3db6a5c457f", "price_changes":[{"asset_id":"18812649149814341758733697580460697418474693998558159483117100240528657629879", "price":"0.088", "size":"15129.46", "side":"SELL", "hash":"a2917c7b4e81f3b036b2fa54db549cce9efca454", "best_bid":"0.085", "best_ask":"0.086"}, {"asset_id":"115428153746996892211798999366308897078723117634059783423375188043903703749062", "price":"0.912", "size":"15129.46", "side":"BUY", "hash":"25ad49d135f351941d3a542f057b3e4e2bfc2434", "best_bid":"0.914", "best_ask":"0.915"}], "timestamp":"1780150581301", "event_type":"price_change"}
{"market":"0x375409bc5eeeff961e82b479caeccc20f33d15738e5bce1186d628aa3d9dfb1f", "price_changes":[{"asset_id":"115556263888245616435851357148058235707004733438163639091106356867234218207169", "price":"0.06", "size":"50150", "side":"BUY", "hash":"734cdb89bff0df9f4442df7f22e5be8ea2257d1a", "best_bid":"0.111", "best_ask":"0.112"}, {"asset_id":"77121637225348873006259930776623502125079210522997384841464684944292365296940", "price":"0.94", "size":"50150", "side":"SELL", "hash":"17c0d6a730e05f2d79668b360b227d5370248ea4", "best_bid":"0.888", "best_ask":"0.889"}], "timestamp":"1780150581693", "event_type":"price_change"}
{"market":"0x375409bc5eeeff961e82b479caeccc20f33d15738e5bce1186d628aa3d9dfb1f", "price_changes":[{"asset_id":"115556263888245616435851357148058235707004733438163639091106356867234218207169", "price":"0.05", "size":"3875", "side":"BUY", "hash":"bf77bfa5bfea0a2b6f03c3746591610caefcd70c", "best_bid":"0.111", "best_ask":"0.112"}, {"asset_id":"77121637225348873006259930776623502125079210522997384841464684944292365296940", "price":"0.95", "size":"3875", "side":"SELL", "hash":"7c3b1188091072ce230fb6b0f5ee3771cab914a2", "best_bid":"0.888", "best_ask":"0.889"}], "timestamp":"1780150582078", "event_type":"price_change"}
{"market":"0x375409bc5eeeff961e82b479caeccc20f33d15738e5bce1186d628aa3d9dfb1f", "price_changes":[{"asset_id":"115556263888245616435851357148058235707004733438163639091106356867234218207169", "price":"0.06", "size":"50316.67", "side":"BUY", "hash":"df88da5ff1267d322f177cf104a80d2a701e54db", "best_bid":"0.111", "best_ask":"0.112"}, {"asset_id":"77121637225348873006259930776623502125079210522997384841464684944292365296940", "price":"0.94", "size":"50316.67", "side":"SELL", "hash":"78ac339c8897e72b7de2ce69e165913d16987b07", "best_bid":"0.888", "best_ask":"0.889"}], "timestamp":"1780150583536", "event_type":"price_change"}
PONG
{"market":"0x375409bc5eeeff961e82b479caeccc20f33d15738e5bce1186d628aa3d9dfb1f", "price_changes":[{"asset_id":"115556263888245616435851357148058235707004733438163639091106356867234218207169", "price":"0.115", "size":"12939.15", "side":"SELL", "hash":"84c5be35b0f9a2f23c53ea09b975848c5efd93f7", "best_bid":"0.111", "best_ask":"0.112"}, {"asset_id":"77121637225348873006259930776623502125079210522997384841464684944292365296940", "price":"0.885", "size":"12939.15", "side":"BUY", "hash":"a7051fd2c02df4d2ab6ffd796e99a59bd0bd1ee7", "best_bid":"0.888", "best_ask":"0.889"}], "timestamp":"1780150583875", "event_type":"price_change"}
{"market":"0x9b6fef249040fd17e9c107955b37ac2c3e923509b6b0ff01cc463a331ddeb894", "price_changes":[{"asset_id":"108233603819467706476318984012158651931658302669301887462181073562758483842092", "price":"0.167", "size":"3810.2", "side":"SELL", "hash":"40ee4e579e4283161e8f3275604ac0f7d941c4b0", "best_bid":"0.163", "best_ask":"0.164"}, {"asset_id":"32270411694523539495262303868629477861017829722282576458031815333486368239544", "price":"0.833", "size":"3810.2", "side":"BUY", "hash":"fa29853bac959595fd826c4fea9aca49c4469b67", "best_bid":"0.836", "best_ask":"0.837"}], "timestamp":"1780150583875", "event_type":"price_change"}
{"market":"0x1595b4818eeb1ea1e0bec5de6f057218e557feee9b405a0e930d290384fa1d16", "price_changes":[{"asset_id":"81739002353269632749850710185641576213562066971072676369728657545679630163887", "price":"0.054", "size":"9325.11", "side":"SELL", "hash":"13eb0610e596fb6e316dfa09b232ea1d75b2b25e", "best_bid":"0.051", "best_ask":"0.052"}, {"asset_id":"45484070731786948288366703334552551439356529561722304542938873238430842810537", "price":"0.946", "size":"9325.11", "side":"BUY", "hash":"9d77754ff72314e0bb987884f54ef656d35079be", "best_bid":"0.948", "best_ask":"0.949"}], "timestamp":"1780150583875", "event_type":"price_change"}
{"market":"0x30d55d8124ee1e12dabe89201badc45669b81dff69e4ce44d961f32878ec178a", "price_changes":[{"asset_id":"27576533317283401577758999384642760405921738493660383550832555714312627457443", "price":"0.093", "size":"87364.83", "side":"SELL", "hash":"65c4d2122fbe7e69d4daa69f06ac639a7603dd9f", "best_bid":"0.09", "best_ask":"0.091"}, {"asset_id":"52986718774908357330412653486471347449818893503063830313445318937088822580057", "price":"0.907", "size":"87364.83", "side":"BUY", "hash":"528442791ee2516e61fb0ac6fa57e0ab8c27bf41", "best_bid":"0.909", "best_ask":"0.91"}], "timestamp":"1780150583876", "event_type":"price_change"}
{"market":"0x375409bc5eeeff961e82b479caeccc20f33d15738e5bce1186d628aa3d9dfb1f", "price_changes":[{"asset_id":"115556263888245616435851357148058235707004733438163639091106356867234218207169", "price":"0.115", "size":"12999.15", "side":"SELL", "hash":"5c8208294c0ae88cd0074d69b8fb885dafa8e630", "best_bid":"0.111", "best_ask":"0.112"}, {"asset_id":"77121637225348873006259930776623502125079210522997384841464684944292365296940", "price":"0.885", "size":"12999.15", "side":"BUY", "hash":"59ea319fc64c68286cc9e9aff4a8fbbdd530c452", "best_bid":"0.888", "best_ask":"0.889"}], "timestamp":"1780150583945", "event_type":"price_change"}
{"market":"0x30d55d8124ee1e12dabe89201badc45669b81dff69e4ce44d961f32878ec178a", "price_changes":[{"asset_id":"27576533317283401577758999384642760405921738493660383550832555714312627457443", "price":"0.093", "size":"87424.83", "side":"SELL", "hash":"7051e16c18ce3feefb1f90d6fb830422453cb4e5", "best_bid":"0.09", "best_ask":"0.091"}, {"asset_id":"52986718774908357330412653486471347449818893503063830313445318937088822580057", "price":"0.907", "size":"87424.83", "side":"BUY", "hash":"3ffe9aad43e0cce8bc706cb029da4a48970c37d4", "best_bid":"0.909", "best_ask":"0.91"}], "timestamp":"1780150583946", "event_type":"price_change"}
{"market":"0x9b6fef249040fd17e9c107955b37ac2c3e923509b6b0ff01cc463a331ddeb894", "price_changes":[{"asset_id":"108233603819467706476318984012158651931658302669301887462181073562758483842092", "price":"0.167", "size":"3864.75", "side":"SELL", "hash":"4795b144ecb22c0ad1c8c68c0486ec6230511f79", "best_bid":"0.163", "best_ask":"0.164"}, {"asset_id":"32270411694523539495262303868629477861017829722282576458031815333486368239544", "price":"0.833", "size":"3864.75", "side":"BUY", "hash":"b4d3810168e708bc955eb6e170064adfc4fe523f", "best_bid":"0.836", "best_ask":"0.837"}], "timestamp":"1780150583952", "event_type":"price_change"}
{"market":"0x1595b4818eeb1ea1e0bec5de6f057218e557feee9b405a0e930d290384fa1d16", "price_changes":[{"asset_id":"81739002353269632749850710185641576213562066971072676369728657545679630163887", "price":"0.054", "size":"9385.11", "side":"SELL", "hash":"b8fdbbf189fb85697690c544d8e665d61073d5fb", "best_bid":"0.051", "best_ask":"0.052"}, {"asset_id":"45484070731786948288366703334552551439356529561722304542938873238430842810537", "price":"0.946", "size":"9385.11", "side":"BUY", "hash":"2763a9348b1fb3213d06e751a0d73105b9914bb7", "best_bid":"0.948", "best_ask":"0.949"}], "timestamp":"1780150583996", "event_type":"price_change"}
{"market":"0x375409bc5eeeff961e82b479caeccc20f33d15738e5bce1186d628aa3d9dfb1f", "price_changes":[{"asset_id":"115556263888245616435851357148058235707004733438163639091106356867234218207169", "price":"0.05", "size":"3975", "side":"BUY", "hash":"20b1c21c04a632cbb4382b83f5ca1665443177be", "best_bid":"0.111", "best_ask":"0.112"}, {"asset_id":"77121637225348873006259930776623502125079210522997384841464684944292365296940", "price":"0.95", "size":"3975", "side":"SELL", "hash":"92103476821fd87f3553830b58d17e3499a883bd", "best_bid":"0.888", "best_ask":"0.889"}], "timestamp":"1780150584367", "event_type":"price_change"}
{"market":"0x7976b8dbacf9077eb1453a62bcefd6ab2df199acd28aad276ff0d920d6992892", "price_changes":[{"asset_id":"4394372887385518214471608448209527405727552777602031099972143344338178308080", "price":"0.171", "size":"2247.95", "side":"SELL", "hash":"d0edccc3c177a5c994191b82d08a950221d72dcb", "best_bid":"0.167", "best_ask":"0.168"}, {"asset_id":"112680630004798425069810935278212000865453267506345451433803052322987302357330", "price":"0.829", "size":"2247.95", "side":"BUY", "hash":"7a30dc2c5ddfa511995794f0b994c2ac49b18c8e", "best_bid":"0.832", "best_ask":"0.833"}], "timestamp":"1780150585609", "event_type":"price_change"}
{"market":"0x7976b8dbacf9077eb1453a62bcefd6ab2df199acd28aad276ff0d920d6992892", "price_changes":[{"asset_id":"4394372887385518214471608448209527405727552777602031099972143344338178308080", "price":"0.171", "size":"2301.97", "side":"SELL", "hash":"37243c1fa007b5b92d6d3e6791c288841bb7030a", "best_bid":"0.167", "best_ask":"0.168"}, {"asset_id":"112680630004798425069810935278212000865453267506345451433803052322987302357330", "price":"0.829", "size":"2301.97", "side":"BUY", "hash":"782808f330554726d374d805c0744f7e99e264a2", "best_bid":"0.832", "best_ask":"0.833"}], "timestamp":"1780150585703", "event_type":"price_change"}
{"market":"0x0c4cd2055d6ea89354ffddc55d6dbcef9355748112ea952fc925f3db6a5c457f", "price_changes":[{"asset_id":"18812649149814341758733697580460697418474693998558159483117100240528657629879", "price":"0.088", "size":"15069.46", "side":"SELL", "hash":"7c12643c78eeffaa89be85bc62d77f0f07d140d5", "best_bid":"0.085", "best_ask":"0.086"}, {"asset_id":"115428153746996892211798999366308897078723117634059783423375188043903703749062", "price":"0.912", "size":"15069.46", "side":"BUY", "hash":"499fdf2c96025630ccd385ff30c6fd35ebc2b8be", "best_bid":"0.914", "best_ask":"0.915"}], "timestamp":"1780150585705", "event_type":"price_change"}
{"market":"0x0c4cd2055d6ea89354ffddc55d6dbcef9355748112ea952fc925f3db6a5c457f", "price_changes":[{"asset_id":"115428153746996892211798999366308897078723117634059783423375188043903703749062", "price":"0.75", "size":"3393.18", "side":"BUY", "hash":"3364c202d0575151b53fb824f647ca41624accca", "best_bid":"0.914", "best_ask":"0.915"}, {"asset_id":"18812649149814341758733697580460697418474693998558159483117100240528657629879", "price":"0.25", "size":"3393.18", "side":"SELL", "hash":"6da684a26cf8133031bfe87d048419a5731c6e1e", "best_bid":"0.085", "best_ask":"0.086"}], "timestamp":"1780150585773", "event_type":"price_change"}
{"market":"0x0c4cd2055d6ea89354ffddc55d6dbcef9355748112ea952fc925f3db6a5c457f", "price_changes":[{"asset_id":"18812649149814341758733697580460697418474693998558159483117100240528657629879", "price":"0.088", "size":"15129.46", "side":"SELL", "hash":"82ed794ec30dc4f0d4ac6d7d0c5e084e430d1d17", "best_bid":"0.085", "best_ask":"0.086"}, {"asset_id":"115428153746996892211798999366308897078723117634059783423375188043903703749062", "price":"0.912", "size":"15129.46", "side":"BUY", "hash":"61bba730b793872df23599eaf250c69d6b0d59ec", "best_bid":"0.914", "best_ask":"0.915"}], "timestamp":"1780150585775", "event_type":"price_change"}
{"market":"0x4f3421fb2daf5cca7430ed8d8132463963081572d75434393a1808fdb8829fe8", "price_changes":[{"asset_id":"45415751658241142530386585138386640503488308219341470020075667342738719018629", "price":"0.103", "size":"18123.31", "side":"SELL", "hash":"b8575f5fd04ab0989c8aceb2929f883adeb2ed80", "best_bid":"0.1", "best_ask":"0.101"}, {"asset_id":"31940783580344558651011323787577288681658737625185216525249046282994042503801", "price":"0.897", "size":"18123.31", "side":"BUY", "hash":"29211327b546dffd11b1c40691a04fe8a80f88c1", "best_bid":"0.899", "best_ask":"0.9"}], "timestamp":"1780150585855", "event_type":"price_change"}
{"market":"0x4f3421fb2daf5cca7430ed8d8132463963081572d75434393a1808fdb8829fe8", "price_changes":[{"asset_id":"45415751658241142530386585138386640503488308219341470020075667342738719018629", "price":"0.103", "size":"18183.31", "side":"SELL", "hash":"4767d0a5102f1298f9422a18c61d72c85bc31d47", "best_bid":"0.1", "best_ask":"0.101"}, {"asset_id":"31940783580344558651011323787577288681658737625185216525249046282994042503801", "price":"0.897", "size":"18183.31", "side":"BUY", "hash":"c35b30c12421d1d3f674a848f8257b7d173c8c4d", "best_bid":"0.899", "best_ask":"0.9"}], "timestamp":"1780150585984", "event_type":"price_change"}
{"market":"0x0c4cd2055d6ea89354ffddc55d6dbcef9355748112ea952fc925f3db6a5c457f", "price_changes":[{"asset_id":"18812649149814341758733697580460697418474693998558159483117100240528657629879", "price":"0.085", "size":"110129.28", "side":"BUY", "hash":"97087769c8dce2df5a28195f40a3fe4adcf61ff4", "best_bid":"0.085", "best_ask":"0.086"}, {"asset_id":"115428153746996892211798999366308897078723117634059783423375188043903703749062", "price":"0.915", "size":"110129.28", "side":"SELL", "hash":"f5ba1b909edd605ddb756bce73058a1980a0577b", "best_bid":"0.914", "best_ask":"0.915"}], "timestamp":"1780150587359", "event_type":"price_change"}
{"market":"0x7976b8dbacf9077eb1453a62bcefd6ab2df199acd28aad276ff0d920d6992892", "price_changes":[{"asset_id":"112680630004798425069810935278212000865453267506345451433803052322987302357330", "price":"0.803", "size":"125", "side":"BUY", "hash":"81bf9deffbb15eacc48512aeb93e8f490222eaf4", "best_bid":"0.832", "best_ask":"0.833"}, {"asset_id":"4394372887385518214471608448209527405727552777602031099972143344338178308080", "price":"0.197", "size":"125", "side":"SELL", "hash":"8e870b131f084d6dc05e0da985f5868430c2994b", "best_bid":"0.167", "best_ask":"0.168"}], "timestamp":"1780150589139", "event_type":"price_change"}
{"market":"0x7976b8dbacf9077eb1453a62bcefd6ab2df199acd28aad276ff0d920d6992892", "price_changes":[{"asset_id":"112680630004798425069810935278212000865453267506345451433803052322987302357330", "price":"0.786", "size":"75", "side":"BUY", "hash":"431f087d9d3981e405d9026c2b7af49cd90d1f91", "best_bid":"0.832", "best_ask":"0.833"}, {"asset_id":"4394372887385518214471608448209527405727552777602031099972143344338178308080", "price":"0.214", "size":"75", "side":"SELL", "hash":"9a2c6ff08c6c30426679d084e385cb93042d144d", "best_bid":"0.167", "best_ask":"0.168"}], "timestamp":"1780150590147", "event_type":"price_change"}
{"market":"0x9b6fef249040fd17e9c107955b37ac2c3e923509b6b0ff01cc463a331ddeb894", "price_changes":[{"asset_id":"108233603819467706476318984012158651931658302669301887462181073562758483842092", "price":"0.12", "size":"120", "side":"BUY", "hash":"98abd60888ab21504a0deb11056b098b613af863", "best_bid":"0.163", "best_ask":"0.164"}, {"asset_id":"32270411694523539495262303868629477861017829722282576458031815333486368239544", "price":"0.88", "size":"120", "side":"SELL", "hash":"c1d0266cada4bced7d049e8a852429685700e2ef", "best_bid":"0.836", "best_ask":"0.837"}], "timestamp":"1780150590305", "event_type":"price_change"}
{"market":"0x9b6fef249040fd17e9c107955b37ac2c3e923509b6b0ff01cc463a331ddeb894", "price_changes":[{"asset_id":"108233603819467706476318984012158651931658302669301887462181073562758483842092", "price":"0.11", "size":"100", "side":"BUY", "hash":"ad0c508d1eeaff724bc7aaab251ac45d41d6ed16", "best_bid":"0.163", "best_ask":"0.164"}, {"asset_id":"32270411694523539495262303868629477861017829722282576458031815333486368239544", "price":"0.89", "size":"100", "side":"SELL", "hash":"6efd4a3c8c78da312ee21011a876ca11d41ad432", "best_bid":"0.836", "best_ask":"0.837"}], "timestamp":"1780150590744", "event_type":"price_change"}
{"market":"0x7876851632c295043c66536150a304cb785abdf712ba8489d298c6e6926be106", "price_changes":[{"asset_id":"19291692040378529618917910599727571242305935029274321291612270922648172794670", "price":"0.902", "size":"0", "side":"BUY", "hash":"e539a742a74ff1bae6295caeb6cd22b7f947bea1", "best_bid":"0.989", "best_ask":"0.99"}, {"asset_id":"97239126062673310243763617236644392945530356142765650402171508075574679292913", "price":"0.098", "size":"0", "side":"SELL", "hash":"c915bbaabfb6cff1ff8abeee5393c36abbc9cbc4", "best_bid":"0.01", "best_ask":"0.011"}], "timestamp":"1780150591088", "event_type":"price_change"}
{"market":"0x7876851632c295043c66536150a304cb785abdf712ba8489d298c6e6926be106", "price_changes":[{"asset_id":"19291692040378529618917910599727571242305935029274321291612270922648172794670", "price":"0.903", "size":"30", "side":"BUY", "hash":"2f8423c39b53472ccf80165ba8ef2b4a4c24f752", "best_bid":"0.989", "best_ask":"0.99"}, {"asset_id":"97239126062673310243763617236644392945530356142765650402171508075574679292913", "price":"0.097", "size":"30", "side":"SELL", "hash":"1d074d9d6d2e6795f92d0db00bfbee5717dfadcd", "best_bid":"0.01", "best_ask":"0.011"}], "timestamp":"1780150591236", "event_type":"price_change"}
{"market":"0x1595b4818eeb1ea1e0bec5de6f057218e557feee9b405a0e930d290384fa1d16", "asset_id":"45484070731786948288366703334552551439356529561722304542938873238430842810537", "best_bid":"0.948", "best_ask":"0.949", "spread":"0.001", "timestamp":"1780150591615", "event_type":"best_bid_ask"}
{"market":"0x1595b4818eeb1ea1e0bec5de6f057218e557feee9b405a0e930d290384fa1d16", "price_changes":[{"asset_id":"81739002353269632749850710185641576213562066971072676369728657545679630163887", "price":"0.052", "size":"403812.75", "side":"SELL", "hash":"60aa220c1303c41543b195568af702c5da929c4b", "best_bid":"0.051", "best_ask":"0.052"}, {"asset_id":"45484070731786948288366703334552551439356529561722304542938873238430842810537", "price":"0.948", "size":"403812.75", "side":"BUY", "hash":"49c7765e4b45a45cb6513d700488161cfa56d6bc", "best_bid":"0.948", "best_ask":"0.949"}], "timestamp":"1780150591607", "event_type":"price_change"}
{"market":"0x1595b4818eeb1ea1e0bec5de6f057218e557feee9b405a0e930d290384fa1d16", "asset_id":"45484070731786948288366703334552551439356529561722304542938873238430842810537", "bids":[{"price":"0.001", "size":"21202713.62"}, {"price":"0.002", "size":"105"}, {"price":"0.003", "size":"32.43"}, {"price":"0.01", "size":"181.81"}, {"price":"0.013", "size":"1698.4"}, {"price":"0.014", "size":"17.32"}, {"price":"0.05", "size":"2236"}, {"price":"0.054", "size":"155555"}, {"price":"0.055", "size":"150000"}, {"price":"0.056", "size":"800"}, {"price":"0.057", "size":"5.16"}, {"price":"0.1", "size":"2500"}, {"price":"0.14", "size":"27"}, {"price":"0.2", "size":"1000"}, {"price":"0.201", "size":"6.67"}, {"price":"0.237", "size":"126.58"}, {"price":"0.3", "size":"600"}, {"price":"0.348", "size":"211.53"}, {"price":"0.39", "size":"5"}, {"price":"0.4", "size":"34625"}, {"price":"0.401", "size":"10000"}, {"price":"0.402", "size":"1492"}, {"price":"0.5", "size":"25100"}, {"price":"0.501", "size":"5000"}, {"price":"0.51", "size":"87.55"}, {"price":"0.511", "size":"1103"}, {"price":"0.58", "size":"17.54"}, {"price":"0.584", "size":"300"}, {"price":"0.6", "size":"20859.33"}, {"price":"0.61", "size":"76.92"}, {"price":"0.623", "size":"5"}, {"price":"0.65", "size":"15443.05"}, {"price":"0.651", "size":"2095.26"}, {"price":"0.7", "size":"780"}, {"price":"0.701", "size":"437"}, {"price":"0.712", "size":"50"}, {"price":"0.72", "size":"18"}, {"price":"0.74", "size":"476.92"}, {"price":"0.75", "size":"2198.07"}, {"price":"0.751", "size":"400"}, {"price":"0.767", "size":"5"}, {"price":"0.77", "size":"43.3"}, {"price":"0.78", "size":"192.53"}, {"price":"0.792", "size":"1100"}, {"price":"0.8", "size":"1307.15"}, {"price":"0.801", "size":"1500"}, {"price":"0.82", "size":"12201.05"}, {"price":"0.821", "size":"400"}, {"price":"0.83", "size":"1079.99"}, {"price":"0.831", "size":"1000"}, {"price":"0.832", "size":"50"}, {"price":"0.838", "size":"1913.7"}, {"price":"0.84", "size":"288"}, {"price":"0.848", "size":"33"}, {"price":"0.85", "size":"13781.98"}, {"price":"0.851", "size":"1000"}, {"price":"0.855", "size":"327.86"}, {"price":"0.856", "size":"7"}, {"price":"0.86", "size":"334.14"}, {"price":"0.861", "size":"1000"}, {"price":"0.862", "size":"30"}, {"price":"0.863", "size":"125"}, {"price":"0.869", "size":"20"}, {"price":"0.87", "size":"1713.81"}, {"price":"0.871", "size":"1100"}, {"price":"0.878", "size":"163.93"}, {"price":"0.88", "size":"613.23"}, {"price":"0.881", "size":"1000"}, {"price":"0.885", "size":"240"}, {"price":"0.887", "size":"370.37"}, {"price":"0.89", "size":"5031.81"}, {"price":"0.896", "size":"1592.3"}, {"price":"0.899", "size":"100"}, {"price":"0.9", "size":"23802.24"}, {"price":"0.901", "size":"100"}, {"price":"0.902", "size":"7772.33"}, {"price":"0.904", "size":"500"}, {"price":"0.905", "size":"5307.69"}, {"price":"0.906", "size":"25"}, {"price":"0.91", "size":"11147.07"}, {"price":"0.911", "size":"956.3"}, {"price":"0.912", "size":"75"}, {"price":"0.913", "size":"500"}, {"price":"0.915", "size":"173.07"}, {"price":"0.916", "size":"19"}, {"price":"0.917", "size":"125"}, {"price":"0.918", "size":"500"}, {"price":"0.919", "size":"532.55"}, {"price":"0.92", "size":"1979.21"}, {"price":"0.924", "size":"5917.15"}, {"price":"0.925", "size":"6585.96"}, {"price":"0.926", "size":"3944.76"}, {"price":"0.927", "size":"5259.68"}, {"price":"0.928", "size":"7012.91"}, {"price":"0.929", "size":"42450.48"}, {"price":"0.93", "size":"32653.14"}, {"price":"0.931", "size":"10000"}, {"price":"0.932", "size":"5905.04"}, {"price":"0.933", "size":"382.3"}, {"price":"0.934", "size":"6055.04"}, {"price":"0.935", "size":"22294.08"}, {"price":"0.939", "size":"950"}, {"price":"0.94", "size":"2357.57"}, {"price":"0.941", "size":"250009.76"}, {"price":"0.942", "size":"11012.52"}, {"price":"0.943", "size":"1999.94"}, {"price":"0.944", "size":"16846.47"}, {"price":"0.945", "size":"3838.22"}, {"price":"0.946", "size":"9385.11"}, {"price":"0.947", "size":"4752.36"}, {"price":"0.948", "size":"403812.75"}], "asks":[{"price":"0.999", "size":"2259057"}, {"price":"0.998", "size":"1000005"}, {"price":"0.997", "size":"2224894"}, {"price":"0.996", "size":"56355"}, {"price":"0.994", "size":"300"}, {"price":"0.993", "size":"100"}, {"price":"0.99", "size":"2517.95"}, {"price":"0.988", "size":"100000"}, {"price":"0.981", "size":"200"}, {"price":"0.98", "size":"905"}, {"price":"0.972", "size":"100000"}, {"price":"0.97", "size":"1030"}, {"price":"0.967", "size":"30"}, {"price":"0.966", "size":"5000"}, {"price":"0.965", "size":"999.99"}, {"price":"0.964", "size":"2500"}, {"price":"0.961", "size":"1500"}, {"price":"0.96", "size":"8909.44"}, {"price":"0.959", "size":"1510"}, {"price":"0.958", "size":"4305"}, {"price":"0.957", "size":"4718"}, {"price":"0.956", "size":"1500"}, {"price":"0.955", "size":"2500"}, {"price":"0.954", "size":"2720"}, {"price":"0.953", "size":"2220"}, {"price":"0.952", "size":"29238.33"}, {"price":"0.951", "size":"39881.55"}, {"price":"0.95", "size":"91974.74"}, {"price":"0.949", "size":"588519.95"}], "hash":"49c7765e4b45a45cb6513d700488161cfa56d6bc", "timestamp":"1780150591607", "event_type":"book"}
{"market":"0x9b6fef249040fd17e9c107955b37ac2c3e923509b6b0ff01cc463a331ddeb894", "price_changes":[{"asset_id":"108233603819467706476318984012158651931658302669301887462181073562758483842092", "price":"0.12", "size":"203.33", "side":"BUY", "hash":"0bd1fa8067481cbb765c1d72683faf2a77ef6af7", "best_bid":"0.163", "best_ask":"0.164"}, {"asset_id":"32270411694523539495262303868629477861017829722282576458031815333486368239544", "price":"0.88", "size":"203.33", "side":"SELL", "hash":"e64bbd42a41336cd28213877713d0641a507af8c", "best_bid":"0.836", "best_ask":"0.837"}], "timestamp":"1780150592180", "event_type":"price_change"}
{"market":"0x9b6fef249040fd17e9c107955b37ac2c3e923509b6b0ff01cc463a331ddeb894", "price_changes":[{"asset_id":"108233603819467706476318984012158651931658302669301887462181073562758483842092", "price":"0.11", "size":"145.45", "side":"BUY", "hash":"ff9027be7fb544cb2780d74810aa2b6605ca206a", "best_bid":"0.163", "best_ask":"0.164"}, {"asset_id":"32270411694523539495262303868629477861017829722282576458031815333486368239544", "price":"0.89", "size":"145.45", "side":"SELL", "hash":"c5b3ec8bf70be6c3fd5a406b0a51c5d63d611107", "best_bid":"0.836", "best_ask":"0.837"}], "timestamp":"1780150593021", "event_type":"price_change"}
PONG
{"market":"0x7976b8dbacf9077eb1453a62bcefd6ab2df199acd28aad276ff0d920d6992892", "price_changes":[{"asset_id":"4394372887385518214471608448209527405727552777602031099972143344338178308080", "price":"0.184", "size":"0", "side":"SELL", "hash":"5bd4bba938d24edefac00552f98ffd6d4ddc470b", "best_bid":"0.167", "best_ask":"0.168"}, {"asset_id":"112680630004798425069810935278212000865453267506345451433803052322987302357330", "price":"0.816", "size":"0", "side":"BUY", "hash":"c0affdd65f65b9b65bb8217b725bbdd0795b285f", "best_bid":"0.832", "best_ask":"0.833"}], "timestamp":"1780150599163", "event_type":"price_change"}
{"market":"0x7976b8dbacf9077eb1453a62bcefd6ab2df199acd28aad276ff0d920d6992892", "price_changes":[{"asset_id":"4394372887385518214471608448209527405727552777602031099972143344338178308080", "price":"0.833", "size":"0", "side":"SELL", "hash":"4ae15574f9a759f73b06f09809c45f145810407a", "best_bid":"0.167", "best_ask":"0.168"}, {"asset_id":"112680630004798425069810935278212000865453267506345451433803052322987302357330", "price":"0.167", "size":"0", "side":"BUY", "hash":"8f58a85e05bac83a6eaf77f672247e8aa12328ca", "best_bid":"0.832", "best_ask":"0.833"}], "timestamp":"1780150599196", "event_type":"price_change"}
{"market":"0x9b6fef249040fd17e9c107955b37ac2c3e923509b6b0ff01cc463a331ddeb894", "price_changes":[{"asset_id":"108233603819467706476318984012158651931658302669301887462181073562758483842092", "price":"0.837", "size":"36", "side":"SELL", "hash":"10700dd6668249fadf894dd10fa264c0df7ace00", "best_bid":"0.163", "best_ask":"0.164"}, {"asset_id":"32270411694523539495262303868629477861017829722282576458031815333486368239544", "price":"0.163", "size":"36", "side":"BUY", "hash":"a7dfee78e6c47bc1fde216babdc636c8bb9ea13f", "best_bid":"0.836", "best_ask":"0.837"}], "timestamp":"1780150599217", "event_type":"price_change"}
{"market":"0x7976b8dbacf9077eb1453a62bcefd6ab2df199acd28aad276ff0d920d6992892", "price_changes":[{"asset_id":"4394372887385518214471608448209527405727552777602031099972143344338178308080", "price":"0.184", "size":"49.77", "side":"SELL", "hash":"b7d2fb193cca670d69e9f55faca8129b7b02e9aa", "best_bid":"0.167", "best_ask":"0.168"}, {"asset_id":"112680630004798425069810935278212000865453267506345451433803052322987302357330", "price":"0.816", "size":"49.77", "side":"BUY", "hash":"6ee06a9480bbf912599ac9a2afdbf2fcad11b9b1", "best_bid":"0.832", "best_ask":"0.833"}], "timestamp":"1780150599415", "event_type":"price_change"}
{"market":"0x7876851632c295043c66536150a304cb785abdf712ba8489d298c6e6926be106", "price_changes":[{"asset_id":"97239126062673310243763617236644392945530356142765650402171508075574679292913", "price":"0.011", "size":"1798725.49", "side":"SELL", "hash":"d03aa89002205a0ba5aa8fe6e7f3343c9225f1c4", "best_bid":"0.01", "best_ask":"0.011"}, {"asset_id":"19291692040378529618917910599727571242305935029274321291612270922648172794670", "price":"0.989", "size":"1798725.49", "side":"BUY", "hash":"70fced51fd9d776a5e84ec3c2aa91e7f571d2a02", "best_bid":"0.989", "best_ask":"0.99"}], "timestamp":"1780150600000", "event_type":"price_change"}
{"market":"0x0c4cd2055d6ea89354ffddc55d6dbcef9355748112ea952fc925f3db6a5c457f", "asset_id":"115428153746996892211798999366308897078723117634059783423375188043903703749062", "best_bid":"0.914", "best_ask":"0.915", "spread":"0.001", "timestamp":"1780150602199", "event_type":"best_bid_ask"}
{"market":"0x0c4cd2055d6ea89354ffddc55d6dbcef9355748112ea952fc925f3db6a5c457f", "price_changes":[{"asset_id":"18812649149814341758733697580460697418474693998558159483117100240528657629879", "price":"0.086", "size":"167927.09", "side":"SELL", "hash":"9366071b5b8c841b72d3b7c9c170873951c23fe9", "best_bid":"0.085", "best_ask":"0.086"}, {"asset_id":"115428153746996892211798999366308897078723117634059783423375188043903703749062", "price":"0.914", "size":"167927.09", "side":"BUY", "hash":"075d96091dedc2c566137774f9a71b44aaf57776", "best_bid":"0.914", "best_ask":"0.915"}], "timestamp":"1780150602199", "event_type":"price_change"}
{"market":"0x0c4cd2055d6ea89354ffddc55d6dbcef9355748112ea952fc925f3db6a5c457f", "asset_id":"115428153746996892211798999366308897078723117634059783423375188043903703749062", "bids":[{"price":"0.001", "size":"19311591.2"}, {"price":"0.002", "size":"55.07"}, {"price":"0.013", "size":"1716.7"}, {"price":"0.015", "size":"1904.95"}, {"price":"0.016", "size":"11.03"}, {"price":"0.036", "size":"36000"}, {"price":"0.04", "size":"333350"}, {"price":"0.041", "size":"300000"}, {"price":"0.042", "size":"800"}, {"price":"0.05", "size":"14660"}, {"price":"0.051", "size":"10.53"}, {"price":"0.09", "size":"19"}, {"price":"0.15", "size":"127.23"}, {"price":"0.22", "size":"128.36"}, {"price":"0.221", "size":"5.26"}, {"price":"0.228", "size":"131.57"}, {"price":"0.27", "size":"1904.95"}, {"price":"0.39", "size":"5"}, {"price":"0.4", "size":"34375"}, {"price":"0.401", "size":"10000"}, {"price":"0.402", "size":"1492"}, {"price":"0.45", "size":"22.5"}, {"price":"0.5", "size":"26767.96"}, {"price":"0.501", "size":"3000"}, {"price":"0.502", "size":"1077.83"}, {"price":"0.6", "size":"21522.45"}, {"price":"0.601", "size":"2000"}, {"price":"0.603", "size":"1164"}, {"price":"0.623", "size":"5"}, {"price":"0.64", "size":"1211"}, {"price":"0.65", "size":"27012.52"}, {"price":"0.66", "size":"46.4"}, {"price":"0.696", "size":"5000"}, {"price":"0.7", "size":"557.74"}, {"price":"0.701", "size":"30"}, {"price":"0.73", "size":"6500"}, {"price":"0.738", "size":"1000"}, {"price":"0.74", "size":"100"}, {"price":"0.75", "size":"3393.18"}, {"price":"0.752", "size":"2906.99"}, {"price":"0.753", "size":"25"}, {"price":"0.755", "size":"125"}, {"price":"0.767", "size":"5"}, {"price":"0.768", "size":"1000"}, {"price":"0.778", "size":"100"}, {"price":"0.779", "size":"400"}, {"price":"0.798", "size":"1000"}, {"price":"0.799", "size":"100"}, {"price":"0.8", "size":"12081.05"}, {"price":"0.801", "size":"2095.26"}, {"price":"0.81", "size":"100"}, {"price":"0.818", "size":"1000"}, {"price":"0.82", "size":"183.62"}, {"price":"0.828", "size":"1000"}, {"price":"0.83", "size":"2373"}, {"price":"0.838", "size":"1268.53"}, {"price":"0.84", "size":"12150"}, {"price":"0.841", "size":"100"}, {"price":"0.843", "size":"100"}, {"price":"0.845", "size":"144"}, {"price":"0.848", "size":"1000"}, {"price":"0.85", "size":"4045.57"}, {"price":"0.855", "size":"11634.31"}, {"price":"0.856", "size":"7"}, {"price":"0.86", "size":"716"}, {"price":"0.861", "size":"144283.19"}, {"price":"0.862", "size":"100"}, {"price":"0.867", "size":"438"}, {"price":"0.868", "size":"50"}, {"price":"0.87", "size":"996"}, {"price":"0.871", "size":"209826.98"}, {"price":"0.875", "size":"1020.47"}, {"price":"0.877", "size":"25"}, {"price":"0.878", "size":"45"}, {"price":"0.879", "size":"75"}, {"price":"0.88", "size":"15096.64"}, {"price":"0.881", "size":"19"}, {"price":"0.882", "size":"648.12"}, {"price":"0.883", "size":"125"}, {"price":"0.884", "size":"10789.73"}, {"price":"0.886", "size":"230.12"}, {"price":"0.887", "size":"1395.49"}, {"price":"0.888", "size":"236.32"}, {"price":"0.889", "size":"1186.28"}, {"price":"0.89", "size":"6421.54"}, {"price":"0.891", "size":"5069.15"}, {"price":"0.892", "size":"52728.52"}, {"price":"0.894", "size":"355.22"}, {"price":"0.895", "size":"5319.74"}, {"price":"0.896", "size":"52728.51"}, {"price":"0.897", "size":"114.3"}, {"price":"0.898", "size":"229.06"}, {"price":"0.899", "size":"27080.06"}, {"price":"0.9", "size":"35120.43"}, {"price":"0.901", "size":"34710.7"}, {"price":"0.902", "size":"84437.86"}, {"price":"0.903", "size":"1730.09"}, {"price":"0.904", "size":"1129.06"}, {"price":"0.905", "size":"2510"}, {"price":"0.906", "size":"229.06"}, {"price":"0.907", "size":"33247.87"}, {"price":"0.908", "size":"15415.06"}, {"price":"0.909", "size":"8064.56"}, {"price":"0.91", "size":"36872.79"}, {"price":"0.911", "size":"25024.11"}, {"price":"0.912", "size":"15129.46"}, {"price":"0.913", "size":"59775.19"}, {"price":"0.914", "size":"167927.09"}], "asks":[{"price":"0.999", "size":"4912713.42"}, {"price":"0.998", "size":"1003359"}, {"price":"0.997", "size":"1111111"}, {"price":"0.996", "size":"55555"}, {"price":"0.995", "size":"500"}, {"price":"0.994", "size":"6000"}, {"price":"0.99", "size":"11200"}, {"price":"0.985", "size":"5.65"}, {"price":"0.984", "size":"5000000"}, {"price":"0.983", "size":"800"}, {"price":"0.98", "size":"5050"}, {"price":"0.979", "size":"2300"}, {"price":"0.97", "size":"4330"}, {"price":"0.969", "size":"367.48"}, {"price":"0.959", "size":"720"}, {"price":"0.958", "size":"725.45"}, {"price":"0.952", "size":"70"}, {"price":"0.951", "size":"71"}, {"price":"0.95", "size":"5879.09"}, {"price":"0.93", "size":"513068.11"}, {"price":"0.929", "size":"6800"}, {"price":"0.928", "size":"437"}, {"price":"0.927", "size":"333"}, {"price":"0.925", "size":"1245"}, {"price":"0.924", "size":"5000"}, {"price":"0.922", "size":"11231.85"}, {"price":"0.921", "size":"127"}, {"price":"0.92", "size":"44813"}, {"price":"0.919", "size":"39326.98"}, {"price":"0.918", "size":"47132.51"}, {"price":"0.917", "size":"184952.96"}, {"price":"0.916", "size":"13437.85"}, {"price":"0.915", "size":"110129.28"}], "hash":"075d96091dedc2c566137774f9a71b44aaf57776", "timestamp":"1780150602199", "event_type":"book"}
