{"market":"0x4f3421fb2daf5cca7430ed8d8132463963081572d75434393a1808fdb8829fe8", "asset_id":"31940783580344558651011323787577288681658737625185216525249046282994042503801", "bids":[{"price":"0.001", "size":"21074238.91"}, {"price":"0.002", "size":"37.76"}, {"price":"0.01", "size":"25929.6"}, {"price":"0.011", "size":"6.21"}, {"price":"0.014", "size":"1111111"}, {"price":"0.015", "size":"1000000"}, {"price":"0.02", "size":"36500"}, {"price":"0.021", "size":"800"}, {"price":"0.022", "size":"11.19"}, {"price":"0.05", "size":"40"}, {"price":"0.077", "size":"2000"}, {"price":"0.078", "size":"5.64"}, {"price":"0.1", "size":"2229.88"}, {"price":"0.11", "size":"1016"}, {"price":"0.12", "size":"1021"}, {"price":"0.13", "size":"1000"}, {"price":"0.14", "size":"999.99"}, {"price":"0.15", "size":"1153.71"}, {"price":"0.2", "size":"409.2"}, {"price":"0.224", "size":"433.92"}, {"price":"0.225", "size":"5.14"}, {"price":"0.25", "size":"453.7"}, {"price":"0.253", "size":"200"}, {"price":"0.254", "size":"200"}, {"price":"0.27", "size":"200"}, {"price":"0.28", "size":"200"}, {"price":"0.31", "size":"200"}, {"price":"0.33", "size":"215.15"}, {"price":"0.34", "size":"199.99"}, {"price":"0.35", "size":"102.46"}, {"price":"0.36", "size":"228"}, {"price":"0.361", "size":"100"}, {"price":"0.4", "size":"34637.29"}, {"price":"0.401", "size":"5000"}, {"price":"0.41", "size":"200"}, {"price":"0.42", "size":"200"}, {"price":"0.43", "size":"200"}, {"price":"0.44", "size":"200"}, {"price":"0.45", "size":"354.02"}, {"price":"0.46", "size":"200"}, {"price":"0.461", "size":"1077.83"}, {"price":"0.5", "size":"25496.62"}, {"price":"0.501", "size":"5100"}, {"price":"0.51", "size":"205.76"}, {"price":"0.511", "size":"100"}, {"price":"0.52", "size":"100"}, {"price":"0.53", "size":"100"}, {"price":"0.54", "size":"100"}, {"price":"0.55", "size":"100"}, {"price":"0.56", "size":"100"}, {"price":"0.57", "size":"100"}, {"price":"0.58", "size":"100"}, {"price":"0.6", "size":"21059.73"}, {"price":"0.61", "size":"100"}, {"price":"0.62", "size":"111.9"}, {"price":"0.632", "size":"5322.31"}, {"price":"0.64", "size":"28.8"}, {"price":"0.643", "size":"100"}, {"price":"0.65", "size":"16970.62"}, {"price":"0.66", "size":"100"}, {"price":"0.67", "size":"100"}, {"price":"0.673", "size":"100"}, {"price":"0.674", "size":"100"}, {"price":"0.678", "size":"100"}, {"price":"0.68", "size":"410.68"}, {"price":"0.69", "size":"100"}, {"price":"0.7", "size":"422.3"}, {"price":"0.703", "size":"100"}, {"price":"0.704", "size":"100"}, {"price":"0.708", "size":"100"}, {"price":"0.71", "size":"61.7"}, {"price":"0.729", "size":"1000"}, {"price":"0.733", "size":"100"}, {"price":"0.75", "size":"3192.15"}, {"price":"0.759", "size":"1000"}, {"price":"0.76", "size":"341.8"}, {"price":"0.763", "size":"100"}, {"price":"0.764", "size":"100"}, {"price":"0.769", "size":"100"}, {"price":"0.777", "size":"100"}, {"price":"0.778", "size":"400"}, {"price":"0.78", "size":"258.06"}, {"price":"0.781", "size":"100"}, {"price":"0.789", "size":"1000"}, {"price":"0.79", "size":"47.6"}, {"price":"0.798", "size":"1781.45"}, {"price":"0.8", "size":"246868.85"}, {"price":"0.801", "size":"100"}, {"price":"0.809", "size":"1000"}, {"price":"0.819", "size":"1000"}, {"price":"0.82", "size":"30"}, {"price":"0.826", "size":"100"}, {"price":"0.829", "size":"1100"}, {"price":"0.83", "size":"39.23"}, {"price":"0.839", "size":"1000"}, {"price":"0.84", "size":"356.45"}, {"price":"0.847", "size":"100"}, {"price":"0.849", "size":"3541.52"}, {"price":"0.85", "size":"15927.35"}, {"price":"0.851", "size":"800"}, {"price":"0.853", "size":"68.33"}, {"price":"0.855", "size":"13.33"}, {"price":"0.858", "size":"35.21"}, {"price":"0.859", "size":"671"}, {"price":"0.86", "size":"34.6"}, {"price":"0.862", "size":"75"}, {"price":"0.867", "size":"17.97"}, {"price":"0.869", "size":"666"}, {"price":"0.87", "size":"4000"}, {"price":"0.871", "size":"39.42"}, {"price":"0.875", "size":"170"}, {"price":"0.878", "size":"232.7"}, {"price":"0.88", "size":"197"}, {"price":"0.882", "size":"1000"}, {"price":"0.885", "size":"925.73"}, {"price":"0.886", "size":"100"}, {"price":"0.887", "size":"100"}, {"price":"0.888", "size":"100"}, {"price":"0.889", "size":"100"}, {"price":"0.89", "size":"649.23"}, {"price":"0.891", "size":"1343.33"}, {"price":"0.892", "size":"7071.71"}, {"price":"0.893", "size":"15257.35"}, {"price":"0.894", "size":"121650.88"}, {"price":"0.895", "size":"1515.46"}, {"price":"0.896", "size":"30940.81"}, {"price":"0.897", "size":"18263.31"}, {"price":"0.898", "size":"90693.2"}, {"price":"0.899", "size":"66403.3"}], "asks":[{"price":"0.999", "size":"4715397.01"}, {"price":"0.998", "size":"14"}, {"price":"0.997", "size":"1112792"}, {"price":"0.996", "size":"55564"}, {"price":"0.995", "size":"10009"}, {"price":"0.994", "size":"11109"}, {"price":"0.993", "size":"10009"}, {"price":"0.992", "size":"10009"}, {"price":"0.991", "size":"5009"}, {"price":"0.99", "size":"6209"}, {"price":"0.989", "size":"5009"}, {"price":"0.988", "size":"5009"}, {"price":"0.987", "size":"4309"}, {"price":"0.986", "size":"3009"}, {"price":"0.985", "size":"5009"}, {"price":"0.984", "size":"3009"}, {"price":"0.983", "size":"3009"}, {"price":"0.982", "size":"9"}, {"price":"0.981", "size":"5009"}, {"price":"0.98", "size":"6234"}, {"price":"0.979", "size":"4008.99"}, {"price":"0.978", "size":"4009"}, {"price":"0.977", "size":"4009"}, {"price":"0.976", "size":"3009"}, {"price":"0.975", "size":"3009"}, {"price":"0.974", "size":"4009"}, {"price":"0.973", "size":"3009"}, {"price":"0.972", "size":"4009"}, {"price":"0.971", "size":"2009"}, {"price":"0.97", "size":"409"}, {"price":"0.969", "size":"2509"}, {"price":"0.968", "size":"2652.85"}, {"price":"0.967", "size":"2509"}, {"price":"0.966", "size":"2509"}, {"price":"0.965", "size":"9"}, {"price":"0.964", "size":"9"}, {"price":"0.963", "size":"9"}, {"price":"0.962", "size":"609"}, {"price":"0.961", "size":"9"}, {"price":"0.96", "size":"134"}, {"price":"0.959", "size":"9"}, {"price":"0.958", "size":"9"}, {"price":"0.957", "size":"9"}, {"price":"0.956", "size":"9"}, {"price":"0.955", "size":"9"}, {"price":"0.954", "size":"9"}, {"price":"0.953", "size":"9"}, {"price":"0.952", "size":"9"}, {"price":"0.951", "size":"9"}, {"price":"0.95", "size":"79"}, {"price":"0.949", "size":"10009"}, {"price":"0.948", "size":"9"}, {"price":"0.947", "size":"9"}, {"price":"0.946", "size":"9"}, {"price":"0.945", "size":"309"}, {"price":"0.944", "size":"9"}, {"price":"0.943", "size":"9"}, {"price":"0.942", "size":"9"}, {"price":"0.941", "size":"9"}, {"price":"0.94", "size":"36"}, {"price":"0.939", "size":"202"}, {"price":"0.938", "size":"10009"}, {"price":"0.937", "size":"5009"}, {"price":"0.936", "size":"7509"}, {"price":"0.935", "size":"5151"}, {"price":"0.934", "size":"6209"}, {"price":"0.933", "size":"4603.78"}, {"price":"0.932", "size":"2856.05"}, {"price":"0.931", "size":"2772.73"}, {"price":"0.93", "size":"9438.97"}, {"price":"0.929", "size":"1564"}, {"price":"0.928", "size":"5464.3"}, {"price":"0.927", "size":"1109"}, {"price":"0.926", "size":"357402.07"}, {"price":"0.925", "size":"20562.67"}, {"price":"0.924", "size":"6753.29"}, {"price":"0.923", "size":"434.15"}, {"price":"0.922", "size":"512.12"}, {"price":"0.921", "size":"25029"}, {"price":"0.92", "size":"15376.09"}, {"price":"0.919", "size":"1633.99"}, {"price":"0.918", "size":"14672.52"}, {"price":"0.917", "size":"2431.41"}, {"price":"0.916", "size":"9"}, {"price":"0.915", "size":"821.33"}, {"price":"0.914", "size":"22609"}, {"price":"0.913", "size":"4605.61"}, {"price":"0.912", "size":"1782.17"}, {"price":"0.911", "size":"570.79"}, {"price":"0.91", "size":"6657.21"}, {"price":"0.909", "size":"958.45"}, {"price":"0.908", "size":"909"}, {"price":"0.907", "size":"3608.93"}, {"price":"0.906", "size":"1240.91"}, {"price":"0.905", "size":"3028.99"}, {"price":"0.904", "size":"1169.1"}, {"price":"0.903", "size":"6197.22"}, {"price":"0.902", "size":"6110.44"}, {"price":"0.901", "size":"7780.19"}, {"price":"0.9", "size":"9217.48"}], "hash":"838f867019b7e0ed97f7cde82213463c8ce5b543", "timestamp":"1780178885459", "event_type":"book"}
{"id":"2397655", "question":"O/U 0.5 Rounds", "market":"0xf7ebbeaae849d11f74548909479817d8bfadc26d15b99920a582a2f0792f7207", "slug":"ufc-ion-nav-2026-06-20-totals-0pt5", "description":"Each market will resolve to \"Over\" if the fight between Ion Cutelaba and Navajo Stirling at UFC Fight Night: Kape vs. Horiguchi, scheduled for June 20, 2026, lasts beyond the listed round threshold.\n\nEach market will resolve to \"Under\" if the fight does not last beyond the listed round threshold.\n\nFor example:\n\n\"Over 0.5 Rounds\" will resolve \"Yes\" if the fight continues past the 2:30 mark of Round 1.\n\n\"Under 0.5 Rounds\" will resolve \"Yes\" if the fight ends before the 2:30 mark of Round 1.\n\nIf the fight ends exactly at the threshold, it will resolve \"50-50.\"\n\nIf the bout is not scored, postponed beyond July 4, 2026, or canceled, all options will resolve \"50-50.\"\n\nThe resolution source for this market will be official information from the UFC.", "assets_ids":["89694939394106443013600597920770401711221445328780832733791763111329225473145", "99024077329811979601044377031267996487517569513349982669881936269068974382102"], "outcomes":["Over", "Under"], "event_message":{"id":"542616", "ticker":"ufc-ion-nav-2026-06-20", "slug":"ufc-ion-nav-2026-06-20", "title":"UFC Fight Night: Ion Cutelaba vs. Navajo Stirling (Light Heavyweight, Main Card)", "description":"This market will resolve to \"Ion Cutelaba\" if Ion Cutelaba is officially declared the winner of the fight against Navajo Stirling at UFC Fight Night: Kape vs. Horiguchi, scheduled for June 20, 2026.\n\nIt will resolve to \"Navajo Stirling\" if Navajo Stirling is officially declared the winner.\n\nIf the fight is declared a draw or technical draw, ruled a No Contest, not scored, canceled, or postponed beyond July 4, 2026, this market will resolve \"50-50.\"\n\nThe resolution source for this market will be official information from the UFC."}, "timestamp":"1780178886621", "event_type":"new_market", "tags":[], "condition_id":"0xf7ebbeaae849d11f74548909479817d8bfadc26d15b99920a582a2f0792f7207", "active":false, "clob_token_ids":["89694939394106443013600597920770401711221445328780832733791763111329225473145", "99024077329811979601044377031267996487517569513349982669881936269068974382102"], "sports_market_type":"totals", "line":"0.5", "game_start_time":"2026-06-20 17:00:00+00", "order_price_min_tick_size":"0.01", "group_item_title":"O/U 0.5 Rounds", "taker_base_fee":"1000", "fees_enabled":true, "fee_schedule":{"exponent":"1", "rate":"0.03", "taker_only":true, "rebate_rate":"0.25"}}
{"id":"2397848", "question":"Heilbronn: Completed Match: Frederico Ferreira Silva vs Pedro Martinez", "market":"0xcfa94f091073819183cabf67ff1d4b0c950522298e5589a21b38ca7aa7f44dee", "slug":"atp-sil-martine-2026-06-01-completed-match", "description":"This market refers to the tennis match between Frederico Ferreira Silva and Pedro Martinez in the Heilbronn, originally scheduled for June 1, 2026 at 5:00AM ET. This market will resolve to \"Yes\" if all games and sets required to determine a match winner under governing body or event organizer rules are played to completion through normal play. Otherwise, if the match is not completed for any reason, it will resolve to \"No.\" If a forfeit of any kind occurs, including but not limited to a walkover or retirement, this market will resolve \"No.\" If the match is canceled (not played at all), ends in a tie, or is delayed beyond 7 days from the scheduled date without a winner determined, this market will resolve to \"No.\" The primary resolution source for this market is the official statistics of the event as recognized by the governing body or event organizers. However, if the governing body or event organizers have not published final match statistics within 2 hours after the event's conclusion, a consensus of credible reporting may be used instead.", "assets_ids":["9432486683227903270212339499459372697452491342596231400223503270234201180323", "28518060825580905081742301896127124515005227823317072227435515604415404480640"], "outcomes":["Yes", "No"], "event_message":{"id":"542689", "ticker":"atp-sil-martine-2026-06-01", "slug":"atp-sil-martine-2026-06-01", "title":"Heilbronn: Frederico Ferreira Silva vs Pedro Martinez", "description":"This market refers to the tennis match between Frederico Ferreira Silva and Pedro Martinez in the Heilbronn, originally scheduled for June 1, 2026 at 5:00AM ET.\n\nThis market will resolve to 'Frederico Ferreira Silva' if Frederico Ferreira Silva advances against Pedro Martinez.\n\nThis market will resolve to 'Pedro Martinez' if Pedro Martinez advances against Frederico Ferreira Silva.\n\nIf the match is canceled (not played at all), ends in a tie, or is delayed beyond 7 days from the scheduled date without a winner determined, this market will resolve to 50-50.\n\nIf the match begins but is not completed, and one player advances due to the opponent's retirement, default, or disqualification, this market will resolve to the player who advances.\n\nIf the match ends in a walkover (player withdraws before the start and the other advances automatically), this market will resolve to 50-50.\n\nThe primary resolution source will be official information from the ATP Tour. A consensus of credible reporting may also be used."}, "timestamp":"1780178886890", "event_type":"new_market", "tags":[], "condition_id":"0xcfa94f091073819183cabf67ff1d4b0c950522298e5589a21b38ca7aa7f44dee", "active":false, "clob_token_ids":["9432486683227903270212339499459372697452491342596231400223503270234201180323", "28518060825580905081742301896127124515005227823317072227435515604415404480640"], "sports_market_type":"tennis_completed_match", "line":"", "game_start_time":"2026-06-01 09:00:00+00", "order_price_min_tick_size":"0.01", "group_item_title":"Completed Match", "taker_base_fee":"1000", "fees_enabled":true, "fee_schedule":{"exponent":"1", "rate":"0.03", "taker_only":true, "rebate_rate":"0.25"}}
{"id":"2397788", "question":"Birmingham: Completed Match: Tristan Schoolkate vs Arthur Fery", "market":"0xedfa343e52cee0f3be446499b0fc73bc4cf802395e2feb92205f915a86ba4347", "slug":"atp-schoolk-fery-2026-06-01-completed-match", "description":"This market refers to the tennis match between Tristan Schoolkate and Arthur Fery in the Birmingham, originally scheduled for June 1, 2026 at 5:30AM ET. This market will resolve to \"Yes\" if all games and sets required to determine a match winner under governing body or event organizer rules are played to completion through normal play. Otherwise, if the match is not completed for any reason, it will resolve to \"No.\" If a forfeit of any kind occurs, including but not limited to a walkover or retirement, this market will resolve \"No.\" If the match is canceled (not played at all), ends in a tie, or is delayed beyond 7 days from the scheduled date without a winner determined, this market will resolve to \"No.\" The primary resolution source for this market is the official statistics of the event as recognized by the governing body or event organizers. However, if the governing body or event organizers have not published final match statistics within 2 hours after the event's conclusion, a consensus of credible reporting may be used instead.", "assets_ids":["32874533164493184120842573617036371876666055438554922310357454657337761039839", "102607873696491440168936206757599003292481159587544820348662365788169205027831"], "outcomes":["Yes", "No"], "event_message":{"id":"542662", "ticker":"atp-schoolk-fery-2026-06-01", "slug":"atp-schoolk-fery-2026-06-01", "title":"Birmingham: Tristan Schoolkate vs Arthur Fery", "description":"This market refers to the tennis match between Tristan Schoolkate and Arthur Fery in the Birmingham, originally scheduled for June 1, 2026 at 5:30AM ET.\n\nThis market will resolve to 'Tristan Schoolkate' if Tristan Schoolkate advances against Arthur Fery.\n\nThis market will resolve to 'Arthur Fery' if Arthur Fery advances against Tristan Schoolkate.\n\nIf the match is canceled (not played at all), ends in a tie, or is delayed beyond 7 days from the scheduled date without a winner determined, this market will resolve to 50-50.\n\nIf the match begins but is not completed, and one player advances due to the opponent's retirement, default, or disqualification, this market will resolve to the player who advances.\n\nIf the match ends in a walkover (player withdraws before the start and the other advances automatically), this market will resolve to 50-50.\n\nThe primary resolution source will be official information from the ATP Tour. A consensus of credible reporting may also be used."}, "timestamp":"1780178888719", "event_type":"new_market", "tags":[], "condition_id":"0xedfa343e52cee0f3be446499b0fc73bc4cf802395e2feb92205f915a86ba4347", "active":false, "clob_token_ids":["32874533164493184120842573617036371876666055438554922310357454657337761039839", "102607873696491440168936206757599003292481159587544820348662365788169205027831"], "sports_market_type":"tennis_completed_match", "line":"", "game_start_time":"2026-06-01 09:30:00+00", "order_price_min_tick_size":"0.01", "group_item_title":"Completed Match", "taker_base_fee":"1000", "fees_enabled":true, "fee_schedule":{"exponent":"1", "rate":"0.03", "taker_only":true, "rebate_rate":"0.25"}}
{"market":"0x4f3421fb2daf5cca7430ed8d8132463963081572d75434393a1808fdb8829fe8", "price_changes":[{"asset_id":"45415751658241142530386585138386640503488308219341470020075667342738719018629", "price":"0.09", "size":"6647.21", "side":"BUY", "hash":"d1a911a96b5a85d27cfa1539db07b0ef21e3c5de", "best_bid":"0.1", "best_ask":"0.101"}, {"asset_id":"31940783580344558651011323787577288681658737625185216525249046282994042503801", "price":"0.91", "size":"6647.21", "side":"SELL", "hash":"a2a390d33b905c0284ab2c5755213cdc8eb09034", "best_bid":"0.899", "best_ask":"0.9"}], "timestamp":"1780178888897", "event_type":"price_change"}
{"market":"0x4f3421fb2daf5cca7430ed8d8132463963081572d75434393a1808fdb8829fe8", "price_changes":[{"asset_id":"45415751658241142530386585138386640503488308219341470020075667342738719018629", "price":"0.09", "size":"6657.21", "side":"BUY", "hash":"29e1332ca063f6b281abd462e3d1887ebc6a360a", "best_bid":"0.1", "best_ask":"0.101"}, {"asset_id":"31940783580344558651011323787577288681658737625185216525249046282994042503801", "price":"0.91", "size":"6657.21", "side":"SELL", "hash":"0b0b855f8c658401100cbf428362b9841f146d6c", "best_bid":"0.899", "best_ask":"0.9"}], "timestamp":"1780178889102", "event_type":"price_change"}
PONG
{"id":"2397676", "question":"Will the fight be won by submission?", "market":"0x52b531a3e420539e0e9eb3f52a786e9dd6572e129d49c0f5c71594391a393560", "slug":"ufc-chr15-hyd-2026-06-20-win-by-submission", "description":"This market will resolve to \"Yes\" if the fight between Christian Rodriguez and Hyder Amil at UFC Fight Night: Kape vs. Horiguchi, scheduled for June 20, 2026, ends by submission, including tapout, verbal submission, or technical submission (referee stoppage due to a submission hold). Otherwise, it will resolve to \"No.\"\n\nIf the fight ends in a draw or by disqualification (either fighter), it will resolve \"No.\"\n\nIf the bout is ruled a No Contest, not scored, canceled, or postponed beyond July 4, 2026, this market will resolve \"50-50.\"\n\nThe resolution source for this market will be official information from the UFC.", "assets_ids":["79878035299881422246004782093755509591649611543278258889741283766142918775371", "93087375579313700766849815210431415921438100932114304053716215604322549952366"], "outcomes":["Yes", "No"], "event_message":{"id":"542624", "ticker":"ufc-chr15-hyd-2026-06-20", "slug":"ufc-chr15-hyd-2026-06-20", "title":"UFC Fight Night: Christian Rodriguez vs. Hyder Amil (Featherweight, Main Card)", "description":"This market will resolve to \"Christian Rodriguez\" if Christian Rodriguez is officially declared the winner of the fight against Hyder Amil at UFC Fight Night: Kape vs. Horiguchi, scheduled for June 20, 2026.\n\nIt will resolve to \"Hyder Amil\" if Hyder Amil is officially declared the winner.\n\nIf the fight is declared a draw or technical draw, ruled a No Contest, not scored, canceled, or postponed beyond July 4, 2026, this market will resolve \"50-50.\"\n\nThe resolution source for this market will be official information from the UFC."}, "timestamp":"1780178890512", "event_type":"new_market", "tags":[], "condition_id":"0x52b531a3e420539e0e9eb3f52a786e9dd6572e129d49c0f5c71594391a393560", "active":false, "clob_token_ids":["79878035299881422246004782093755509591649611543278258889741283766142918775371", "93087375579313700766849815210431415921438100932114304053716215604322549952366"], "sports_market_type":"ufc_method_of_victory", "line":"", "game_start_time":"2026-06-20 17:00:00+00", "order_price_min_tick_size":"0.01", "group_item_title":"Fight won by submission?", "taker_base_fee":"1000", "fees_enabled":true, "fee_schedule":{"exponent":"1", "rate":"0.03", "taker_only":true, "rebate_rate":"0.25"}}
{"market":"0x4f3421fb2daf5cca7430ed8d8132463963081572d75434393a1808fdb8829fe8", "price_changes":[{"asset_id":"45415751658241142530386585138386640503488308219341470020075667342738719018629", "price":"0.103", "size":"18203.31", "side":"SELL", "hash":"c504526e7ae814a2a08bec1c30c88242d8799c12", "best_bid":"0.1", "best_ask":"0.101"}, {"asset_id":"31940783580344558651011323787577288681658737625185216525249046282994042503801", "price":"0.897", "size":"18203.31", "side":"BUY", "hash":"bd50056e8afbf58c70687aeaa1694c264f9dd062", "best_bid":"0.899", "best_ask":"0.9"}], "timestamp":"1780178892000", "event_type":"price_change"}
{"market":"0x4f3421fb2daf5cca7430ed8d8132463963081572d75434393a1808fdb8829fe8", "price_changes":[{"asset_id":"45415751658241142530386585138386640503488308219341470020075667342738719018629", "price":"0.103", "size":"18263.31", "side":"SELL", "hash":"bebc7b4e222c6e18bf45102a805b85af6f7e04cd", "best_bid":"0.1", "best_ask":"0.101"}, {"asset_id":"31940783580344558651011323787577288681658737625185216525249046282994042503801", "price":"0.897", "size":"18263.31", "side":"BUY", "hash":"a636ffcb2ea7db6227ddc1f7898c1552859ab0d1", "best_bid":"0.899", "best_ask":"0.9"}], "timestamp":"1780178892098", "event_type":"price_change"}
{"market":"0x9b6fef249040fd17e9c107955b37ac2c3e923509b6b0ff01cc463a331ddeb894", "price_changes":[{"asset_id":"108233603819467706476318984012158651931658302669301887462181073562758483842092", "price":"0.166", "size":"24952", "side":"SELL", "hash":"7506e40950e804b9afa38dcf724dbad55cef3d8d", "best_bid":"0.163", "best_ask":"0.164"}, {"asset_id":"32270411694523539495262303868629477861017829722282576458031815333486368239544", "price":"0.834", "size":"24952", "side":"BUY", "hash":"2c22d498076b45e9d82dec16c20aa383cb8fb0c9", "best_bid":"0.836", "best_ask":"0.837"}], "timestamp":"1780178892475", "event_type":"price_change"}
{"market":"0x9b6fef249040fd17e9c107955b37ac2c3e923509b6b0ff01cc463a331ddeb894", "price_changes":[{"asset_id":"108233603819467706476318984012158651931658302669301887462181073562758483842092", "price":"0.166", "size":"25006.68", "side":"SELL", "hash":"a483b79a9ad3b2a186c06c4070b5c94969b1e342", "best_bid":"0.163", "best_ask":"0.164"}, {"asset_id":"32270411694523539495262303868629477861017829722282576458031815333486368239544", "price":"0.834", "size":"25006.68", "side":"BUY", "hash":"2e529a3b0a9d898535714ea2eaa5c0761225ba3f", "best_bid":"0.836", "best_ask":"0.837"}], "timestamp":"1780178892578", "event_type":"price_change"}
{"id":"2397707", "question":"Centurion 2: Khololwam Montsi vs Calvin Hemery", "market":"0xde31746be3c739b3da773d0eafb5160c479c7ed56683526afb5b4fc8718f908b", "slug":"atp-montsi-hemery-2026-06-01", "description":"This market refers to the tennis match between Khololwam Montsi and Calvin Hemery in the Centurion 2, originally scheduled for June 1, 2026 at 4:00AM ET.\n\nThis market will resolve to 'Khololwam Montsi' if Khololwam Montsi advances against Calvin Hemery.\n\nThis market will resolve to 'Calvin Hemery' if Calvin Hemery advances against Khololwam Montsi.\n\nIf the match is canceled (not played at all), ends in a tie, or is delayed beyond 7 days from the scheduled date without a winner determined, this market will resolve to 50-50.\n\nIf the match begins but is not completed, and one player advances due to the opponent's retirement, default, or disqualification, this market will resolve to the player who advances.\n\nIf the match ends in a walkover (player withdraws before the start and the other advances automatically), this market will resolve to 50-50.\n\nThe primary resolution source will be official information from the ATP Tour. A consensus of credible reporting may also be used.", "assets_ids":["22969035644817756815253140279946658007621280709570745081921147772614331299619", "49605772125244640042694748817953845512631130097026815034705473277011804701917"], "outcomes":["Khololwam Montsi", "Calvin Hemery"], "event_message":{"id":"542638", "ticker":"atp-montsi-hemery-2026-06-01", "slug":"atp-montsi-hemery-2026-06-01", "title":"Centurion 2: Khololwam Montsi vs Calvin Hemery", "description":"This market refers to the tennis match between Khololwam Montsi and Calvin Hemery in the Centurion 2, originally scheduled for June 1, 2026 at 4:00AM ET.\n\nThis market will resolve to 'Khololwam Montsi' if Khololwam Montsi advances against Calvin Hemery.\n\nThis market will resolve to 'Calvin Hemery' if Calvin Hemery advances against Khololwam Montsi.\n\nIf the match is canceled (not played at all), ends in a tie, or is delayed beyond 7 days from the scheduled date without a winner determined, this market will resolve to 50-50.\n\nIf the match begins but is not completed, and one player advances due to the opponent's retirement, default, or disqualification, this market will resolve to the player who advances.\n\nIf the match ends in a walkover (player withdraws before the start and the other advances automatically), this market will resolve to 50-50.\n\nThe primary resolution source will be official information from the ATP Tour. A consensus of credible reporting may also be used."}, "timestamp":"1780178894131", "event_type":"new_market", "tags":[], "condition_id":"0xde31746be3c739b3da773d0eafb5160c479c7ed56683526afb5b4fc8718f908b", "active":false, "clob_token_ids":["22969035644817756815253140279946658007621280709570745081921147772614331299619", "49605772125244640042694748817953845512631130097026815034705473277011804701917"], "sports_market_type":"moneyline", "line":"", "game_start_time":"2026-06-01 08:00:00+00", "order_price_min_tick_size":"0.01", "group_item_title":"", "taker_base_fee":"1000", "fees_enabled":true, "fee_schedule":{"exponent":"1", "rate":"0.03", "taker_only":true, "rebate_rate":"0.25"}}
{"market":"0x30d55d8124ee1e12dabe89201badc45669b81dff69e4ce44d961f32878ec178a", "price_changes":[{"asset_id":"27576533317283401577758999384642760405921738493660383550832555714312627457443", "price":"0.092", "size":"78371.18", "side":"SELL", "hash":"82b00f24acee14d6219518978ce4a6232031ad62", "best_bid":"0.089", "best_ask":"0.09"}, {"asset_id":"52986718774908357330412653486471347449818893503063830313445318937088822580057", "price":"0.908", "size":"78371.18", "side":"BUY", "hash":"80b75198eef9163e78fd391d978de22ce84ebdf5", "best_bid":"0.91", "best_ask":"0.911"}], "timestamp":"1780178894204", "event_type":"price_change"}
{"market":"0x7976b8dbacf9077eb1453a62bcefd6ab2df199acd28aad276ff0d920d6992892", "price_changes":[{"asset_id":"4394372887385518214471608448209527405727552777602031099972143344338178308080", "price":"0.17", "size":"27598.28", "side":"SELL", "hash":"bc0173789fbac57f02fa6dd26c417f4a6658a543", "best_bid":"0.167", "best_ask":"0.168"}, {"asset_id":"112680630004798425069810935278212000865453267506345451433803052322987302357330", "price":"0.83", "size":"27598.28", "side":"BUY", "hash":"abf6ed277d98810aa83023a04dfd39b530b298e4", "best_bid":"0.832", "best_ask":"0.833"}], "timestamp":"1780178894207", "event_type":"price_change"}
{"market":"0x30d55d8124ee1e12dabe89201badc45669b81dff69e4ce44d961f32878ec178a", "price_changes":[{"asset_id":"27576533317283401577758999384642760405921738493660383550832555714312627457443", "price":"0.092", "size":"78431.18", "side":"SELL", "hash":"3a6daf73bbb3b7dd0391f0fce9c2e2deb3532168", "best_bid":"0.089", "best_ask":"0.09"}, {"asset_id":"52986718774908357330412653486471347449818893503063830313445318937088822580057", "price":"0.908", "size":"78431.18", "side":"BUY", "hash":"ff2deb7a95e44dba3563233b3d8816cb32b18bca", "best_bid":"0.91", "best_ask":"0.911"}], "timestamp":"1780178894333", "event_type":"price_change"}
{"market":"0x7976b8dbacf9077eb1453a62bcefd6ab2df199acd28aad276ff0d920d6992892", "price_changes":[{"asset_id":"4394372887385518214471608448209527405727552777602031099972143344338178308080", "price":"0.17", "size":"27652.43", "side":"SELL", "hash":"f78a265691a92add1292c3cd1d2ef2044257dc2d", "best_bid":"0.167", "best_ask":"0.168"}, {"asset_id":"112680630004798425069810935278212000865453267506345451433803052322987302357330", "price":"0.83", "size":"27652.43", "side":"BUY", "hash":"abf473ef0ee7b1b23da1e3497b915b46e87cb388", "best_bid":"0.832", "best_ask":"0.833"}], "timestamp":"1780178894331", "event_type":"price_change"}
{"market":"0x0c4cd2055d6ea89354ffddc55d6dbcef9355748112ea952fc925f3db6a5c457f", "price_changes":[{"asset_id":"18812649149814341758733697580460697418474693998558159483117100240528657629879", "price":"0.088", "size":"15069.46", "side":"SELL", "hash":"4ffd0ce3330dc01df87eb90bc0ae5a8c68cb8ff9", "best_bid":"0.085", "best_ask":"0.086"}, {"asset_id":"115428153746996892211798999366308897078723117634059783423375188043903703749062", "price":"0.912", "size":"15069.46", "side":"BUY", "hash":"6c190d080359bef306f78ea425754bdf957177d7", "best_bid":"0.914", "best_ask":"0.915"}], "timestamp":"1780178895496", "event_type":"price_change"}
{"market":"0x1595b4818eeb1ea1e0bec5de6f057218e557feee9b405a0e930d290384fa1d16", "price_changes":[{"asset_id":"81739002353269632749850710185641576213562066971072676369728657545679630163887", "price":"0.053", "size":"3311.26", "side":"SELL", "hash":"eab337c893187ccc67f426636235eff8fd4103fb", "best_bid":"0.051", "best_ask":"0.052"}, {"asset_id":"45484070731786948288366703334552551439356529561722304542938873238430842810537", "price":"0.947", "size":"3311.26", "side":"BUY", "hash":"6131ce611b8f972d55c65c3363caf0cd01eb7a78", "best_bid":"0.948", "best_ask":"0.949"}], "timestamp":"1780178895529", "event_type":"price_change"}
{"market":"0x375409bc5eeeff961e82b479caeccc20f33d15738e5bce1186d628aa3d9dfb1f", "price_changes":[{"asset_id":"115556263888245616435851357148058235707004733438163639091106356867234218207169", "price":"0.115", "size":"12019.15", "side":"SELL", "hash":"52370616e25a516aeb31f07756f0faca293f202e", "best_bid":"0.112", "best_ask":"0.113"}, {"asset_id":"77121637225348873006259930776623502125079210522997384841464684944292365296940", "price":"0.885", "size":"12019.15", "side":"BUY", "hash":"45e0bfe79cc7b2befd4381e052fd89355691f7ae", "best_bid":"0.887", "best_ask":"0.888"}], "timestamp":"1780178895530", "event_type":"price_change"}
{"market":"0x0c4cd2055d6ea89354ffddc55d6dbcef9355748112ea952fc925f3db6a5c457f", "price_changes":[{"asset_id":"18812649149814341758733697580460697418474693998558159483117100240528657629879", "price":"0.088", "size":"15129.46", "side":"SELL", "hash":"308df2a27d7ac51bf079dae44eda75e80bbcad72", "best_bid":"0.085", "best_ask":"0.086"}, {"asset_id":"115428153746996892211798999366308897078723117634059783423375188043903703749062", "price":"0.912", "size":"15129.46", "side":"BUY", "hash":"49dff99e2e4e1af19c90b5d1e7235755df3e3a4d", "best_bid":"0.914", "best_ask":"0.915"}], "timestamp":"1780178895601", "event_type":"price_change"}
{"market":"0x1595b4818eeb1ea1e0bec5de6f057218e557feee9b405a0e930d290384fa1d16", "price_changes":[{"asset_id":"81739002353269632749850710185641576213562066971072676369728657545679630163887", "price":"0.053", "size":"3371.26", "side":"SELL", "hash":"b5e002eb3d8b9c8e4ce7b703f24d4b30aabe02a7", "best_bid":"0.051", "best_ask":"0.052"}, {"asset_id":"45484070731786948288366703334552551439356529561722304542938873238430842810537", "price":"0.947", "size":"3371.26", "side":"BUY", "hash":"5adaedbca426ed7798b203cf34a50c679e14d59b", "best_bid":"0.948", "best_ask":"0.949"}], "timestamp":"1780178895656", "event_type":"price_change"}
{"market":"0x375409bc5eeeff961e82b479caeccc20f33d15738e5bce1186d628aa3d9dfb1f", "price_changes":[{"asset_id":"115556263888245616435851357148058235707004733438163639091106356867234218207169", "price":"0.115", "size":"12079.15", "side":"SELL", "hash":"af62206ffe6008283cfe2de032e26e2aed10e275", "best_bid":"0.112", "best_ask":"0.113"}, {"asset_id":"77121637225348873006259930776623502125079210522997384841464684944292365296940", "price":"0.885", "size":"12079.15", "side":"BUY", "hash":"c837692b2caf9cbbd0ff0e0ec1f27c25d8ed9e34", "best_bid":"0.887", "best_ask":"0.888"}], "timestamp":"1780178895661", "event_type":"price_change"}
{"id":"2397771", "question":"Prostejov: Miguel Damas vs Damir Dzumhur", "market":"0x9e74a62d13b32b06d6b604c08fa52d9f99ee7305111460d866c68e9bf6a3505c", "slug":"atp-damas-dzumhur-2026-06-01", "description":"This market refers to the tennis match between Miguel Damas and Damir Dzumhur in the Prostejov, originally scheduled for June 1, 2026 at 4:00AM ET.\n\nThis market will resolve to 'Miguel Damas' if Miguel Damas advances against Damir Dzumhur.\n\nThis market will resolve to 'Damir Dzumhur' if Damir Dzumhur advances against Miguel Damas.\n\nIf the match is canceled (not played at all), ends in a tie, or is delayed beyond 7 days from the scheduled date without a winner determined, this market will resolve to 50-50.\n\nIf the match begins but is not completed, and one player advances due to the opponent's retirement, default, or disqualification, this market will resolve to the player who advances.\n\nIf the match ends in a walkover (player withdraws before the start and the other advances automatically), this market will resolve to 50-50.\n\nThe primary resolution source will be official information from the ATP Tour. A consensus of credible reporting may also be used.", "assets_ids":["87605784357377965281396294132064796391562754381977748369220285974553763893148", "70820605034285400575066876596565807012169369485710507291444325131555946722429"], "outcomes":["Miguel Damas", "Damir Dzumhur"], "event_message":{"id":"542657", "ticker":"atp-damas-dzumhur-2026-06-01", "slug":"atp-damas-dzumhur-2026-06-01", "title":"Prostejov: Miguel Damas vs Damir Dzumhur", "description":"This market refers to the tennis match between Miguel Damas and Damir Dzumhur in the Prostejov, originally scheduled for June 1, 2026 at 4:00AM ET.\n\nThis market will resolve to 'Miguel Damas' if Miguel Damas advances against Damir Dzumhur.\n\nThis market will resolve to 'Damir Dzumhur' if Damir Dzumhur advances against Miguel Damas.\n\nIf the match is canceled (not played at all), ends in a tie, or is delayed beyond 7 days from the scheduled date without a winner determined, this market will resolve to 50-50.\n\nIf the match begins but is not completed, and one player advances due to the opponent's retirement, default, or disqualification, this market will resolve to the player who advances.\n\nIf the match ends in a walkover (player withdraws before the start and the other advances automatically), this market will resolve to 50-50.\n\nThe primary resolution source will be official information from the ATP Tour. A consensus of credible reporting may also be used."}, "timestamp":"1780178899520", "event_type":"new_market", "tags":[], "condition_id":"0x9e74a62d13b32b06d6b604c08fa52d9f99ee7305111460d866c68e9bf6a3505c", "active":false, "clob_token_ids":["87605784357377965281396294132064796391562754381977748369220285974553763893148", "70820605034285400575066876596565807012169369485710507291444325131555946722429"], "sports_market_type":"moneyline", "line":"", "game_start_time":"2026-06-01 08:00:00+00", "order_price_min_tick_size":"0.01", "group_item_title":"", "taker_base_fee":"1000", "fees_enabled":true, "fee_schedule":{"exponent":"1", "rate":"0.03", "taker_only":true, "rebate_rate":"0.25"}}
{"id":"2397876", "question":"Spread: Houston Astros (-2.5)", "market":"0x485703e334bab1fb3243a014dcfe33151ae967d4921343fb3f1e5bb2fe8825fa", "slug":"mlb-mil-hou-2026-05-31-spread-home-2pt5", "description":"In the upcoming MLB game between the Milwaukee Brewers and Houston Astros, scheduled for May 31 at 2:10 PM ET:\n\nThis market will resolve to \"Houston Astros\" if the Houston Astros win the game by 3 or more runs.\n\nOtherwise, this market will resolve to \"Milwaukee Brewers\". If the game ends in a tie, this market will resolve to \"Milwaukee Brewers\".\n\nIf the game is postponed, this market will remain open until the game has been completed. If the game is canceled entirely, with no make-up game, this market will resolve 50-50.\n\nTo know when a postponed game will be played, please check the home team's schedule on MLB.com for the listed team and look for the game described as a makeup game.\n\nThe primary resolution source for this market is the official final statistics of the event as recognized by the governing body or event organizers. However, if the governing body or event organizers have not published final match statistics within 24 hours after the event's conclusion, a consensus of credible reporting may be used instead.", "assets_ids":["92118986890129628437059777745352196878120399870541035122068531618938187312564", "87784966794690985141596684679413286023262652487819358627636508381384409206212"], "outcomes":["Houston Astros", "Milwaukee Brewers"], "event_message":{"id":"523536", "ticker":"mlb-mil-hou-2026-05-31", "slug":"mlb-mil-hou-2026-05-31", "title":"Milwaukee Brewers vs. Houston Astros", "description":"In the upcoming MLB game between the Milwaukee Brewers and Houston Astros, scheduled for May 31 at 2:10PM ET:\n\nThis market will resolve to \"Milwaukee Brewers\" if the Milwaukee Brewers win the game.\n\nThis market will resolve to \"Houston Astros\" if the Houston Astros win the game.\n\nIf the game is postponed, this market will remain open until the game has been completed. If the game is canceled entirely, with no make-up game, or ends in a tie, this market will resolve 50-50.\n\nThe primary resolution source for this market is the official final statistics of the event as recognized by the governing body or event organizers. However, if the governing body or event organizers have not published final match statistics within 24 hours after the event's conclusion, a consensus of credible reporting may be used instead."}, "timestamp":"1780178899773", "event_type":"new_market", "tags":[], "condition_id":"0x485703e334bab1fb3243a014dcfe33151ae967d4921343fb3f1e5bb2fe8825fa", "active":false, "clob_token_ids":["92118986890129628437059777745352196878120399870541035122068531618938187312564", "87784966794690985141596684679413286023262652487819358627636508381384409206212"], "sports_market_type":"spreads", "line":"-2.5", "game_start_time":"2026-05-31 18:10:00+00", "order_price_min_tick_size":"0.01", "group_item_title":"Spread -2.5", "taker_base_fee":"1000", "fees_enabled":true, "fee_schedule":{"exponent":"1", "rate":"0.03", "taker_only":true, "rebate_rate":"0.25"}}
PONG
{"market":"0x7876851632c295043c66536150a304cb785abdf712ba8489d298c6e6926be106", "price_changes":[{"asset_id":"97239126062673310243763617236644392945530356142765650402171508075574679292913", "price":"0.011", "size":"1818525.69", "side":"SELL", "hash":"27a7ad1c67833f4794cdb0bf30f823afc732dfec", "best_bid":"0.01", "best_ask":"0.011"}, {"asset_id":"19291692040378529618917910599727571242305935029274321291612270922648172794670", "price":"0.989", "size":"1818525.69", "side":"BUY", "hash":"626ffcf1639db44e810cad8add7c2b993859da74", "best_bid":"0.989", "best_ask":"0.99"}], "timestamp":"1780178902001", "event_type":"price_change"}
{"market":"0x30d55d8124ee1e12dabe89201badc45669b81dff69e4ce44d961f32878ec178a", "price_changes":[{"asset_id":"27576533317283401577758999384642760405921738493660383550832555714312627457443", "price":"0.092", "size":"78375.52", "side":"SELL", "hash":"4e280dd3242a50a51656b76861a42395ae675265", "best_bid":"0.089", "best_ask":"0.09"}, {"asset_id":"52986718774908357330412653486471347449818893503063830313445318937088822580057", "price":"0.908", "size":"78375.52", "side":"BUY", "hash":"492a5645b4ad0d8b6b4271c0779a214ec6d1c201", "best_bid":"0.91", "best_ask":"0.911"}], "timestamp":"1780178904420", "event_type":"price_change"}
{"market":"0x1595b4818eeb1ea1e0bec5de6f057218e557feee9b405a0e930d290384fa1d16", "price_changes":[{"asset_id":"81739002353269632749850710185641576213562066971072676369728657545679630163887", "price":"0.053", "size":"3291.26", "side":"SELL", "hash":"c951f074ffb8efc33e9a945b8b33ccc5db103eab", "best_bid":"0.051", "best_ask":"0.052"}, {"asset_id":"45484070731786948288366703334552551439356529561722304542938873238430842810537", "price":"0.947", "size":"3291.26", "side":"BUY", "hash":"d229d96ff0a8b1c9a3cc94fde02310779ade3667", "best_bid":"0.948", "best_ask":"0.949"}], "timestamp":"1780178904425", "event_type":"price_change"}
{"market":"0x0c4cd2055d6ea89354ffddc55d6dbcef9355748112ea952fc925f3db6a5c457f", "price_changes":[{"asset_id":"18812649149814341758733697580460697418474693998558159483117100240528657629879", "price":"0.088", "size":"15049.46", "side":"SELL", "hash":"d939eece362489826b12a1f1900af1b7f79806f4", "best_bid":"0.085", "best_ask":"0.086"}, {"asset_id":"115428153746996892211798999366308897078723117634059783423375188043903703749062", "price":"0.912", "size":"15049.46", "side":"BUY", "hash":"5a57392736dc166eb0034c31ce9ea9b6bdc98750", "best_bid":"0.914", "best_ask":"0.915"}], "timestamp":"1780178904426", "event_type":"price_change"}
{"market":"0x7976b8dbacf9077eb1453a62bcefd6ab2df199acd28aad276ff0d920d6992892", "price_changes":[{"asset_id":"4394372887385518214471608448209527405727552777602031099972143344338178308080", "price":"0.17", "size":"27626.88", "side":"SELL", "hash":"321ad18ba8bb97db9e5dcaf4333f6ebe2006df0b", "best_bid":"0.167", "best_ask":"0.168"}, {"asset_id":"112680630004798425069810935278212000865453267506345451433803052322987302357330", "price":"0.83", "size":"27626.88", "side":"BUY", "hash":"cd2aa683f37380b2c7483f188b2c91d1971e8569", "best_bid":"0.832", "best_ask":"0.833"}], "timestamp":"1780178904427", "event_type":"price_change"}
{"market":"0x30d55d8124ee1e12dabe89201badc45669b81dff69e4ce44d961f32878ec178a", "price_changes":[{"asset_id":"27576533317283401577758999384642760405921738493660383550832555714312627457443", "price":"0.092", "size":"78431.18", "side":"SELL", "hash":"2208301738156500bc1704fb9b9b56644664d6f3", "best_bid":"0.089", "best_ask":"0.09"}, {"asset_id":"52986718774908357330412653486471347449818893503063830313445318937088822580057", "price":"0.908", "size":"78431.18", "side":"BUY", "hash":"17622a6ce515d41e36b44b6224665656b198b1a6", "best_bid":"0.91", "best_ask":"0.911"}], "timestamp":"1780178904522", "event_type":"price_change"}
{"market":"0x0c4cd2055d6ea89354ffddc55d6dbcef9355748112ea952fc925f3db6a5c457f", "price_changes":[{"asset_id":"18812649149814341758733697580460697418474693998558159483117100240528657629879", "price":"0.088", "size":"15129.46", "side":"SELL", "hash":"c7e3ed3f6d1a7a71ea24902222515d1315cd3188", "best_bid":"0.085", "best_ask":"0.086"}, {"asset_id":"115428153746996892211798999366308897078723117634059783423375188043903703749062", "price":"0.912", "size":"15129.46", "side":"BUY", "hash":"97f4197a87f9e2eb0addb2d0c96626e6ea8960d6", "best_bid":"0.914", "best_ask":"0.915"}], "timestamp":"1780178904522", "event_type":"price_change"}
{"market":"0x1595b4818eeb1ea1e0bec5de6f057218e557feee9b405a0e930d290384fa1d16", "price_changes":[{"asset_id":"81739002353269632749850710185641576213562066971072676369728657545679630163887", "price":"0.053", "size":"3371.26", "side":"SELL", "hash":"f5f613bab402ec217e962327ff1edf00078546a4", "best_bid":"0.051", "best_ask":"0.052"}, {"asset_id":"45484070731786948288366703334552551439356529561722304542938873238430842810537", "price":"0.947", "size":"3371.26", "side":"BUY", "hash":"2d1fc49ddd0d30059c1c74772f37e422753971ac", "best_bid":"0.948", "best_ask":"0.949"}], "timestamp":"1780178904522", "event_type":"price_change"}
{"market":"0x7976b8dbacf9077eb1453a62bcefd6ab2df199acd28aad276ff0d920d6992892", "price_changes":[{"asset_id":"4394372887385518214471608448209527405727552777602031099972143344338178308080", "price":"0.17", "size":"27652.43", "side":"SELL", "hash":"45695fd5bbb2151c17df46c7fe750eba259674d7", "best_bid":"0.167", "best_ask":"0.168"}, {"asset_id":"112680630004798425069810935278212000865453267506345451433803052322987302357330", "price":"0.83", "size":"27652.43", "side":"BUY", "hash":"4ade372d05022168ea2da9ec2c4d3a4e9796cf16", "best_bid":"0.832", "best_ask":"0.833"}], "timestamp":"1780178904552", "event_type":"price_change"}
{"id":"2397764", "question":"Will Michael Aswell win by KO or TKO?", "market":"0x71a3cad862d5a37c9c253042937cfa9940e40615b73245a5452f3943c3db7e19", "slug":"ufc-gas-mic34-2026-06-20-aswell-win-by-ko-tko", "description":"This market will resolve to \"Yes\" if Michael Aswell defeats Gaston Bolaños at UFC Fight Night: Kape vs. Horiguchi, scheduled for June 20, 2026, by KO or TKO, including referee stoppage, doctor stoppage, or corner stoppage. Otherwise, it will resolve to \"No.\"\n\nIf the fight ends in a draw or by disqualification (either fighter), it will resolve \"No.\"\n\nIf the bout is ruled a No Contest, not scored, canceled, or postponed beyond July 4, 2026, this market will resolve \"50-50.\"\n\nThe resolution source for this market will be official information from the UFC.", "assets_ids":["97111231337126309413446885026231378052538682291498131165650138605074340933822", "78048400364325869050037598944840313540980863481456870766251027025310974647500"], "outcomes":["Yes", "No"], "event_message":{"id":"542654", "ticker":"ufc-gas-mic34-2026-06-20", "slug":"ufc-gas-mic34-2026-06-20", "title":"UFC Fight Night: Gaston Bolaños vs. Michael Aswell (Featherweight, Prelims)", "description":"This market will resolve to \"Gaston Bolaños\" if Gaston Bolaños is officially declared the winner of the fight against Michael Aswell at UFC Fight Night: Kape vs. Horiguchi, scheduled for June 20, 2026.\n\nIt will resolve to \"Michael Aswell\" if Michael Aswell is officially declared the winner.\n\nIf the fight is declared a draw or technical draw, ruled a No Contest, not scored, canceled, or postponed beyond July 4, 2026, this market will resolve \"50-50.\"\n\nThe resolution source for this market will be official information from the UFC."}, "timestamp":"1780178904675", "event_type":"new_market", "tags":[], "condition_id":"0x71a3cad862d5a37c9c253042937cfa9940e40615b73245a5452f3943c3db7e19", "active":false, "clob_token_ids":["97111231337126309413446885026231378052538682291498131165650138605074340933822", "78048400364325869050037598944840313540980863481456870766251027025310974647500"], "sports_market_type":"ufc_method_of_victory", "line":"", "game_start_time":"2026-06-20 17:00:00+00", "order_price_min_tick_size":"0.01", "group_item_title":"Aswell to win by KO/TKO?", "taker_base_fee":"1000", "fees_enabled":true, "fee_schedule":{"exponent":"1", "rate":"0.03", "taker_only":true, "rebate_rate":"0.25"}}
{"market":"0x375409bc5eeeff961e82b479caeccc20f33d15738e5bce1186d628aa3d9dfb1f", "price_changes":[{"asset_id":"115556263888245616435851357148058235707004733438163639091106356867234218207169", "price":"0.115", "size":"11999.15", "side":"SELL", "hash":"d0b617a18ac1e1b15b3d3f3729d644578a259600", "best_bid":"0.112", "best_ask":"0.113"}, {"asset_id":"77121637225348873006259930776623502125079210522997384841464684944292365296940", "price":"0.885", "size":"11999.15", "side":"BUY", "hash":"412893dfaa3468c17446648a1302cbc34e31569d", "best_bid":"0.887", "best_ask":"0.888"}], "timestamp":"1780178906948", "event_type":"price_change"}
{"market":"0x9b6fef249040fd17e9c107955b37ac2c3e923509b6b0ff01cc463a331ddeb894", "price_changes":[{"asset_id":"108233603819467706476318984012158651931658302669301887462181073562758483842092", "price":"0.166", "size":"24926.68", "side":"SELL", "hash":"92f864709ee39ddbcdc2a0ae85502bd666718a06", "best_bid":"0.163", "best_ask":"0.164"}, {"asset_id":"32270411694523539495262303868629477861017829722282576458031815333486368239544", "price":"0.834", "size":"24926.68", "side":"BUY", "hash":"7bea121b7a67eea4a72c6486bca7ec3068b35c6d", "best_bid":"0.836", "best_ask":"0.837"}], "timestamp":"1780178907004", "event_type":"price_change"}
{"market":"0x375409bc5eeeff961e82b479caeccc20f33d15738e5bce1186d628aa3d9dfb1f", "price_changes":[{"asset_id":"115556263888245616435851357148058235707004733438163639091106356867234218207169", "price":"0.115", "size":"12079.15", "side":"SELL", "hash":"6f9045be07cbed186084109f602d3a6b8c9f40d9", "best_bid":"0.112", "best_ask":"0.113"}, {"asset_id":"77121637225348873006259930776623502125079210522997384841464684944292365296940", "price":"0.885", "size":"12079.15", "side":"BUY", "hash":"0cb31f0abd8843fddf39e55dcaaf19956370dfc3", "best_bid":"0.887", "best_ask":"0.888"}], "timestamp":"1780178907079", "event_type":"price_change"}
{"market":"0x9b6fef249040fd17e9c107955b37ac2c3e923509b6b0ff01cc463a331ddeb894", "price_changes":[{"asset_id":"108233603819467706476318984012158651931658302669301887462181073562758483842092", "price":"0.166", "size":"25006.68", "side":"SELL", "hash":"b516e4ed3a4f76b648a57cd20126b0df8d9711d5", "best_bid":"0.163", "best_ask":"0.164"}, {"asset_id":"32270411694523539495262303868629477861017829722282576458031815333486368239544", "price":"0.834", "size":"25006.68", "side":"BUY", "hash":"164a62867935e2ea6f4a92f9c9a313ed7058aeb9", "best_bid":"0.836", "best_ask":"0.837"}], "timestamp":"1780178907104", "event_type":"price_change"}
{"market":"0x4f3421fb2daf5cca7430ed8d8132463963081572d75434393a1808fdb8829fe8", "price_changes":[{"asset_id":"45415751658241142530386585138386640503488308219341470020075667342738719018629", "price":"0.103", "size":"18202.51", "side":"SELL", "hash":"df3ece3013e0ce0b5d2c6821434ffc765edb7d68", "best_bid":"0.1", "best_ask":"0.101"}, {"asset_id":"31940783580344558651011323787577288681658737625185216525249046282994042503801", "price":"0.897", "size":"18202.51", "side":"BUY", "hash":"13eeb99bcd17a37ef0e358b2e0ee80fd1bb0b0fd", "best_bid":"0.899", "best_ask":"0.9"}], "timestamp":"1780178907352", "event_type":"price_change"}
{"market":"0x4f3421fb2daf5cca7430ed8d8132463963081572d75434393a1808fdb8829fe8", "price_changes":[{"asset_id":"45415751658241142530386585138386640503488308219341470020075667342738719018629", "price":"0.103", "size":"18263.31", "side":"SELL", "hash":"38e1da6007cc7457238cd89c3bbdea8ac4ac12cd", "best_bid":"0.1", "best_ask":"0.101"}, {"asset_id":"31940783580344558651011323787577288681658737625185216525249046282994042503801", "price":"0.897", "size":"18263.31", "side":"BUY", "hash":"cac09413ef53ecc2934b779e57c5231d72ba0e75", "best_bid":"0.899", "best_ask":"0.9"}], "timestamp":"1780178907439", "event_type":"price_change"}
{"id":"2397651", "question":"Will Navajo Stirling win by KO or TKO?", "market":"0xa80a69e7c2e8922f885a7fbeb474f3798b37fef1a041a239a7f6817cdae2c7ce", "slug":"ufc-ion-nav-2026-06-20-stirling-win-by-ko-tko", "description":"This market will resolve to \"Yes\" if Navajo Stirling defeats Ion Cutelaba at UFC Fight Night: Kape vs. Horiguchi, scheduled for June 20, 2026, by KO or TKO, including referee stoppage, doctor stoppage, or corner stoppage. Otherwise, it will resolve to \"No.\"\n\nIf the fight ends in a draw or by disqualification (either fighter), it will resolve \"No.\"\n\nIf the bout is ruled a No Contest, not scored, canceled, or postponed beyond July 4, 2026, this market will resolve \"50-50.\"\n\nThe resolution source for this market will be official information from the UFC.", "assets_ids":["37051649369401444297436383291497358332924215342116038274900286055156982521550", "106897300250920920940228169492940950637583185299027806092793158064419267088580"], "outcomes":["Yes", "No"], "event_message":{"id":"542616", "ticker":"ufc-ion-nav-2026-06-20", "slug":"ufc-ion-nav-2026-06-20", "title":"UFC Fight Night: Ion Cutelaba vs. Navajo Stirling (Light Heavyweight, Main Card)", "description":"This market will resolve to \"Ion Cutelaba\" if Ion Cutelaba is officially declared the winner of the fight against Navajo Stirling at UFC Fight Night: Kape vs. Horiguchi, scheduled for June 20, 2026.\n\nIt will resolve to \"Navajo Stirling\" if Navajo Stirling is officially declared the winner.\n\nIf the fight is declared a draw or technical draw, ruled a No Contest, not scored, canceled, or postponed beyond July 4, 2026, this market will resolve \"50-50.\"\n\nThe resolution source for this market will be official information from the UFC."}, "timestamp":"1780178907531", "event_type":"new_market", "tags":[], "condition_id":"0xa80a69e7c2e8922f885a7fbeb474f3798b37fef1a041a239a7f6817cdae2c7ce", "active":false, "clob_token_ids":["37051649369401444297436383291497358332924215342116038274900286055156982521550", "106897300250920920940228169492940950637583185299027806092793158064419267088580"], "sports_market_type":"ufc_method_of_victory", "line":"", "game_start_time":"2026-06-20 17:00:00+00", "order_price_min_tick_size":"0.01", "group_item_title":"Stirling to win by KO/TKO?", "taker_base_fee":"1000", "fees_enabled":true, "fee_schedule":{"exponent":"1", "rate":"0.03", "taker_only":true, "rebate_rate":"0.25"}}
{"market":"0x7876851632c295043c66536150a304cb785abdf712ba8489d298c6e6926be106", "price_changes":[{"asset_id":"97239126062673310243763617236644392945530356142765650402171508075574679292913", "price":"0.011", "size":"1818565.69", "side":"SELL", "hash":"1c9b3064214d7d91a91ee90ff67c48ef796ac885", "best_bid":"0.01", "best_ask":"0.011"}, {"asset_id":"19291692040378529618917910599727571242305935029274321291612270922648172794670", "price":"0.989", "size":"1818565.69", "side":"BUY", "hash":"9444ae65e452691c77bbb6564dc455a1c7d83270", "best_bid":"0.989", "best_ask":"0.99"}], "timestamp":"1780178907667", "event_type":"price_change"}
{"market":"0x30d55d8124ee1e12dabe89201badc45669b81dff69e4ce44d961f32878ec178a", "price_changes":[{"asset_id":"52986718774908357330412653486471347449818893503063830313445318937088822580057", "price":"0.781", "size":"0", "side":"BUY", "hash":"cabfb1799ba2c16959820455820732e71986ff4c", "best_bid":"0.91", "best_ask":"0.911"}, {"asset_id":"27576533317283401577758999384642760405921738493660383550832555714312627457443", "price":"0.219", "size":"0", "side":"SELL", "hash":"b329b02795e9e364798b834176671fb7b3e6dc80", "best_bid":"0.089", "best_ask":"0.09"}], "timestamp":"1780178908308", "event_type":"price_change"}
{"market":"0x30d55d8124ee1e12dabe89201badc45669b81dff69e4ce44d961f32878ec178a", "price_changes":[{"asset_id":"52986718774908357330412653486471347449818893503063830313445318937088822580057", "price":"0.79", "size":"431.9", "side":"BUY", "hash":"512d469c25278b85ff79765b707e6433f0d63ab6", "best_bid":"0.91", "best_ask":"0.911"}, {"asset_id":"27576533317283401577758999384642760405921738493660383550832555714312627457443", "price":"0.21", "size":"431.9", "side":"SELL", "hash":"3d9254dbb213e6bf1de7c57ccf06e582090d4e26", "best_bid":"0.089", "best_ask":"0.09"}], "timestamp":"1780178908334", "event_type":"price_change"}
{"market":"0x30d55d8124ee1e12dabe89201badc45669b81dff69e4ce44d961f32878ec178a", "price_changes":[{"asset_id":"52986718774908357330412653486471347449818893503063830313445318937088822580057", "price":"0.79", "size":"31.9", "side":"BUY", "hash":"b3d6d342907fdb76fac21255232de7754c0468c9", "best_bid":"0.91", "best_ask":"0.911"}, {"asset_id":"27576533317283401577758999384642760405921738493660383550832555714312627457443", "price":"0.21", "size":"31.9", "side":"SELL", "hash":"4701acb9e4332a55e68fbd811af6fc3e49323098", "best_bid":"0.089", "best_ask":"0.09"}], "timestamp":"1780178908356", "event_type":"price_change"}
{"market":"0x30d55d8124ee1e12dabe89201badc45669b81dff69e4ce44d961f32878ec178a", "price_changes":[{"asset_id":"52986718774908357330412653486471347449818893503063830313445318937088822580057", "price":"0.79", "size":"431.9", "side":"BUY", "hash":"aaf75fa12e824096e1c78e6901c4cea4d0c6581d", "best_bid":"0.91", "best_ask":"0.911"}, {"asset_id":"27576533317283401577758999384642760405921738493660383550832555714312627457443", "price":"0.21", "size":"431.9", "side":"SELL", "hash":"e78c37482293d340aada4eec0c6a34f44783220a", "best_bid":"0.089", "best_ask":"0.09"}], "timestamp":"1780178908385", "event_type":"price_change"}
{"market":"0x30d55d8124ee1e12dabe89201badc45669b81dff69e4ce44d961f32878ec178a", "price_changes":[{"asset_id":"52986718774908357330412653486471347449818893503063830313445318937088822580057", "price":"0.79", "size":"31.9", "side":"BUY", "hash":"301bd25b213132df6bf0a5a6d834a388f316aff8", "best_bid":"0.91", "best_ask":"0.911"}, {"asset_id":"27576533317283401577758999384642760405921738493660383550832555714312627457443", "price":"0.21", "size":"31.9", "side":"SELL", "hash":"1efe202ede84ebbb292e6a6689e8efb6568762f4", "best_bid":"0.089", "best_ask":"0.09"}], "timestamp":"1780178908404", "event_type":"price_change"}
{"market":"0x30d55d8124ee1e12dabe89201badc45669b81dff69e4ce44d961f32878ec178a", "price_changes":[{"asset_id":"52986718774908357330412653486471347449818893503063830313445318937088822580057", "price":"0.79", "size":"431.9", "side":"BUY", "hash":"c1cbfcadad1b341768b425c17599655a1364acf8", "best_bid":"0.91", "best_ask":"0.911"}, {"asset_id":"27576533317283401577758999384642760405921738493660383550832555714312627457443", "price":"0.21", "size":"431.9", "side":"SELL", "hash":"74f6858fc21bf9c300c264b17294b2b63e5bfde1", "best_bid":"0.089", "best_ask":"0.09"}], "timestamp":"1780178908441", "event_type":"price_change"}
{"market":"0x7976b8dbacf9077eb1453a62bcefd6ab2df199acd28aad276ff0d920d6992892", "price_changes":[{"asset_id":"4394372887385518214471608448209527405727552777602031099972143344338178308080", "price":"0.184", "size":"0", "side":"SELL", "hash":"89e24bbf9f5bdc0f6646ad2a1a9831398ec66a98", "best_bid":"0.167", "best_ask":"0.168"}, {"asset_id":"112680630004798425069810935278212000865453267506345451433803052322987302357330", "price":"0.816", "size":"0", "side":"BUY", "hash":"4b3ec1ee89b4e83b2d7fcb8dc9978fea9f38577b", "best_bid":"0.832", "best_ask":"0.833"}], "timestamp":"1780178908911", "event_type":"price_change"}
{"market":"0x7976b8dbacf9077eb1453a62bcefd6ab2df199acd28aad276ff0d920d6992892", "price_changes":[{"asset_id":"4394372887385518214471608448209527405727552777602031099972143344338178308080", "price":"0.184", "size":"49.77", "side":"SELL", "hash":"170ea97b42c821a5ded920e4b95b47810327f8bb", "best_bid":"0.167", "best_ask":"0.168"}, {"asset_id":"112680630004798425069810935278212000865453267506345451433803052322987302357330", "price":"0.816", "size":"49.77", "side":"BUY", "hash":"909dd3cbfed3514fe137af2b7dbf5c7f8c901d16", "best_bid":"0.832", "best_ask":"0.833"}], "timestamp":"1780178909102", "event_type":"price_change"}
PONG
{"id":"2397678", "question":"O/U 0.5 Rounds", "market":"0x97576a2b81e0ed7ce59b3c9809e60278ebd0b967484826602ac3eb7f4071f1a7", "slug":"ufc-chr15-hyd-2026-06-20-totals-0pt5", "description":"Each market will resolve to \"Over\" if the fight between Christian Rodriguez and Hyder Amil at UFC Fight Night: Kape vs. Horiguchi, scheduled for June 20, 2026, lasts beyond the listed round threshold.\n\nEach market will resolve to \"Under\" if the fight does not last beyond the listed round threshold.\n\nFor example:\n\n\"Over 0.5 Rounds\" will resolve \"Yes\" if the fight continues past the 2:30 mark of Round 1.\n\n\"Under 0.5 Rounds\" will resolve \"Yes\" if the fight ends before the 2:30 mark of Round 1.\n\nIf the fight ends exactly at the threshold, it will resolve \"50-50.\"\n\nIf the bout is not scored, postponed beyond July 4, 2026, or canceled, all options will resolve \"50-50.\"\n\nThe resolution source for this market will be official information from the UFC.", "assets_ids":["11660975511696913260270729872459250399156567132861539165493486258387654100096", "56505404098247202239506769950314474480184036904279466041381144206868237797602"], "outcomes":["Over", "Under"], "event_message":{"id":"542624", "ticker":"ufc-chr15-hyd-2026-06-20", "slug":"ufc-chr15-hyd-2026-06-20", "title":"UFC Fight Night: Christian Rodriguez vs. Hyder Amil (Featherweight, Main Card)", "description":"This market will resolve to \"Christian Rodriguez\" if Christian Rodriguez is officially declared the winner of the fight against Hyder Amil at UFC Fight Night: Kape vs. Horiguchi, scheduled for June 20, 2026.\n\nIt will resolve to \"Hyder Amil\" if Hyder Amil is officially declared the winner.\n\nIf the fight is declared a draw or technical draw, ruled a No Contest, not scored, canceled, or postponed beyond July 4, 2026, this market will resolve \"50-50.\"\n\nThe resolution source for this market will be official information from the UFC."}, "timestamp":"1780178911367", "event_type":"new_market", "tags":[], "condition_id":"0x97576a2b81e0ed7ce59b3c9809e60278ebd0b967484826602ac3eb7f4071f1a7", "active":false, "clob_token_ids":["11660975511696913260270729872459250399156567132861539165493486258387654100096", "56505404098247202239506769950314474480184036904279466041381144206868237797602"], "sports_market_type":"totals", "line":"0.5", "game_start_time":"2026-06-20 17:00:00+00", "order_price_min_tick_size":"0.01", "group_item_title":"O/U 0.5 Rounds", "taker_base_fee":"1000", "fees_enabled":true, "fee_schedule":{"exponent":"1", "rate":"0.03", "taker_only":true, "rebate_rate":"0.25"}}
{"id":"2397839", "question":"Heilbronn: Jan Choinski vs Tom Gentzsch", "market":"0x83b49d28a68f025d165517d541fb81e6797cb5d345c735c4fb050e4c1c2cf003", "slug":"atp-choinsk-gentzsc-2026-06-01", "description":"This market refers to the tennis match between Jan Choinski and Tom Gentzsch in the Heilbronn, originally scheduled for June 1, 2026 at 5:00AM ET.\n\nThis market will resolve to 'Jan Choinski' if Jan Choinski advances against Tom Gentzsch.\n\nThis market will resolve to 'Tom Gentzsch' if Tom Gentzsch advances against Jan Choinski.\n\nIf the match is canceled (not played at all), ends in a tie, or is delayed beyond 7 days from the scheduled date without a winner determined, this market will resolve to 50-50.\n\nIf the match begins but is not completed, and one player advances due to the opponent's retirement, default, or disqualification, this market will resolve to the player who advances.\n\nIf the match ends in a walkover (player withdraws before the start and the other advances automatically), this market will resolve to 50-50.\n\nThe primary resolution source will be official information from the ATP Tour. A consensus of credible reporting may also be used.", "assets_ids":["41835924484579485405634173037315447336070054978786385547434779455189029284351", "8431375459050352772724478158793810961618912441984191557342938714770961962820"], "outcomes":["Jan Choinski", "Tom Gentzsch"], "event_message":{"id":"542685", "ticker":"atp-choinsk-gentzsc-2026-06-01", "slug":"atp-choinsk-gentzsc-2026-06-01", "title":"Heilbronn: Jan Choinski vs Tom Gentzsch", "description":"This market refers to the tennis match between Jan Choinski and Tom Gentzsch in the Heilbronn, originally scheduled for June 1, 2026 at 5:00AM ET.\n\nThis market will resolve to 'Jan Choinski' if Jan Choinski advances against Tom Gentzsch.\n\nThis market will resolve to 'Tom Gentzsch' if Tom Gentzsch advances against Jan Choinski.\n\nIf the match is canceled (not played at all), ends in a tie, or is delayed beyond 7 days from the scheduled date without a winner determined, this market will resolve to 50-50.\n\nIf the match begins but is not completed, and one player advances due to the opponent's retirement, default, or disqualification, this market will resolve to the player who advances.\n\nIf the match ends in a walkover (player withdraws before the start and the other advances automatically), this market will resolve to 50-50.\n\nThe primary resolution source will be official information from the ATP Tour. A consensus of credible reporting may also be used."}, "timestamp":"1780178913418", "event_type":"new_market", "tags":[], "condition_id":"0x83b49d28a68f025d165517d541fb81e6797cb5d345c735c4fb050e4c1c2cf003", "active":false, "clob_token_ids":["41835924484579485405634173037315447336070054978786385547434779455189029284351", "8431375459050352772724478158793810961618912441984191557342938714770961962820"], "sports_market_type":"moneyline", "line":"", "game_start_time":"2026-06-01 09:00:00+00", "order_price_min_tick_size":"0.01", "group_item_title":"", "taker_base_fee":"1000", "fees_enabled":true, "fee_schedule":{"exponent":"1", "rate":"0.03", "taker_only":true, "rebate_rate":"0.25"}}
{"id":"2397892", "question":"Ethereum Up or Down - May 31, 6:00PM-6:15PM ET", "market":"0xa5cfd7ac3d40146af018d8663220816bc566915aba81fa8694bad4bbd02323fe", "slug":"eth-updown-15m-1780264800", "description":"This market will resolve to \"Up\" if the Ethereum price at the end of the time range specified in the title is greater than or equal to the price at the beginning of that range. Otherwise, it will resolve to \"Down\".\nThe resolution source for this market is information from Chainlink, specifically the ETH/USD data stream available at https://data.chain.link/streams/eth-usd.\nPlease note that this market is about the price according to Chainlink data stream ETH/USD, not according to other sources or spot markets.", "assets_ids":["34376803934437234272363123673916876394060053278724820270049849218847014235121", "60272702680190722915418155117441855636778066095318287197231206427784016369861"], "outcomes":["Up", "Down"], "event_message":{"id":"542714", "ticker":"eth-updown-15m-1780264800", "slug":"eth-updown-15m-1780264800", "title":"Ethereum Up or Down - May 31, 6:00PM-6:15PM ET", "description":"This market will resolve to \"Up\" if the Ethereum price at the end of the time range specified in the title is greater than or equal to the price at the beginning of that range. Otherwise, it will resolve to \"Down\".\nThe resolution source for this market is information from Chainlink, specifically the ETH/USD data stream available at https://data.chain.link/streams/eth-usd.\nPlease note that this market is about the price according to Chainlink data stream ETH/USD, not according to other sources or spot markets."}, "timestamp":"1780178913705", "event_type":"new_market", "tags":[], "condition_id":"0xa5cfd7ac3d40146af018d8663220816bc566915aba81fa8694bad4bbd02323fe", "active":false, "clob_token_ids":["34376803934437234272363123673916876394060053278724820270049849218847014235121", "60272702680190722915418155117441855636778066095318287197231206427784016369861"], "sports_market_type":"", "line":"", "game_start_time":"", "order_price_min_tick_size":"0.01", "group_item_title":"", "taker_base_fee":"1000", "fees_enabled":true, "fee_schedule":{"exponent":"1", "rate":"0.07", "taker_only":true, "rebate_rate":"0.2"}}
{"id":"2397768", "question":"O/U 0.5 Rounds", "market":"0x0376c5e63cb34812b7c92fb1ffe7d4190776d893f4d16f3b139919dd30c9f2f4", "slug":"ufc-gas-mic34-2026-06-20-totals-0pt5", "description":"Each market will resolve to \"Over\" if the fight between Gaston Bolaños and Michael Aswell at UFC Fight Night: Kape vs. Horiguchi, scheduled for June 20, 2026, lasts beyond the listed round threshold.\n\nEach market will resolve to \"Under\" if the fight does not last beyond the listed round threshold.\n\nFor example:\n\n\"Over 0.5 Rounds\" will resolve \"Yes\" if the fight continues past the 2:30 mark of Round 1.\n\n\"Under 0.5 Rounds\" will resolve \"Yes\" if the fight ends before the 2:30 mark of Round 1.\n\nIf the fight ends exactly at the threshold, it will resolve \"50-50.\"\n\nIf the bout is not scored, postponed beyond July 4, 2026, or canceled, all options will resolve \"50-50.\"\n\nThe resolution source for this market will be official information from the UFC.", "assets_ids":["47893815692654340201002941703055718137546765929791635201232881776170872259591", "274697282746444190214083409937842486014177593029931533849385789596727180736"], "outcomes":["Over", "Under"], "event_message":{"id":"542654", "ticker":"ufc-gas-mic34-2026-06-20", "slug":"ufc-gas-mic34-2026-06-20", "title":"UFC Fight Night: Gaston Bolaños vs. Michael Aswell (Featherweight, Prelims)", "description":"This market will resolve to \"Gaston Bolaños\" if Gaston Bolaños is officially declared the winner of the fight against Michael Aswell at UFC Fight Night: Kape vs. Horiguchi, scheduled for June 20, 2026.\n\nIt will resolve to \"Michael Aswell\" if Michael Aswell is officially declared the winner.\n\nIf the fight is declared a draw or technical draw, ruled a No Contest, not scored, canceled, or postponed beyond July 4, 2026, this market will resolve \"50-50.\"\n\nThe resolution source for this market will be official information from the UFC."}, "timestamp":"1780178914429", "event_type":"new_market", "tags":[], "condition_id":"0x0376c5e63cb34812b7c92fb1ffe7d4190776d893f4d16f3b139919dd30c9f2f4", "active":false, "clob_token_ids":["47893815692654340201002941703055718137546765929791635201232881776170872259591", "274697282746444190214083409937842486014177593029931533849385789596727180736"], "sports_market_type":"totals", "line":"0.5", "game_start_time":"2026-06-20 17:00:00+00", "order_price_min_tick_size":"0.01", "group_item_title":"O/U 0.5 Rounds", "taker_base_fee":"1000", "fees_enabled":true, "fee_schedule":{"exponent":"1", "rate":"0.03", "taker_only":true, "rebate_rate":"0.25"}}
{"id":"2397883", "question":"Hyperliquid Up or Down - May 31, 6:00PM-6:05PM ET", "market":"0x5d03ba6d1d17282af06f316b71d70a7c892297f2ab4dddce8eafed6a9fa2ce1e", "slug":"hype-updown-5m-1780264800", "description":"This market will resolve to \"Up\" if the Hyperliquid price at the end of the time range specified in the title is greater than or equal to the price at the beginning of that range. Otherwise, it will resolve to \"Down\".\nThe resolution source for this market is information from Chainlink, specifically the HYPE/USD data stream available at https://data.chain.link/streams/hype-usd.\nPlease note that this market is about the price according to Chainlink data stream HYPE/USD, not according to other sources or spot markets.", "assets_ids":["21951738162460465725697083632749142144719563579951210207651079982316450396798", "10228136694193488525014488776629748491001463541441770640633142930159429443153"], "outcomes":["Up", "Down"], "event_message":{"id":"542704", "ticker":"hype-updown-5m-1780264800", "slug":"hype-updown-5m-1780264800", "title":"Hyperliquid Up or Down - May 31, 6:00PM-6:05PM ET", "description":"This market will resolve to \"Up\" if the Hyperliquid price at the end of the time range specified in the title is greater than or equal to the price at the beginning of that range. Otherwise, it will resolve to \"Down\".\nThe resolution source for this market is information from Chainlink, specifically the HYPE/USD data stream available at https://data.chain.link/streams/hype-usd.\nPlease note that this market is about the price according to Chainlink data stream HYPE/USD, not according to other sources or spot markets."}, "timestamp":"1780178918513", "event_type":"new_market", "tags":[], "condition_id":"0x5d03ba6d1d17282af06f316b71d70a7c892297f2ab4dddce8eafed6a9fa2ce1e", "active":false, "clob_token_ids":["21951738162460465725697083632749142144719563579951210207651079982316450396798", "10228136694193488525014488776629748491001463541441770640633142930159429443153"], "sports_market_type":"", "line":"", "game_start_time":"", "order_price_min_tick_size":"0.01", "group_item_title":"", "taker_base_fee":"1000", "fees_enabled":true, "fee_schedule":{"exponent":"1", "rate":"0.07", "taker_only":true, "rebate_rate":"0.2"}}
PONG
{"market":"0x9b6fef249040fd17e9c107955b37ac2c3e923509b6b0ff01cc463a331ddeb894", "price_changes":[{"asset_id":"108233603819467706476318984012158651931658302669301887462181073562758483842092", "price":"0.837", "size":"0", "side":"SELL", "hash":"6bb95186fa992c1c4e3f7f4b380eb6ee1b43865b", "best_bid":"0.163", "best_ask":"0.164"}, {"asset_id":"32270411694523539495262303868629477861017829722282576458031815333486368239544", "price":"0.163", "size":"0", "side":"BUY", "hash":"b65c8f4b43d47116792740cba548e84cc2fa0b33", "best_bid":"0.836", "best_ask":"0.837"}], "timestamp":"1780178921190", "event_type":"price_change"}
{"market":"0x4f3421fb2daf5cca7430ed8d8132463963081572d75434393a1808fdb8829fe8", "price_changes":[{"asset_id":"45415751658241142530386585138386640503488308219341470020075667342738719018629", "price":"0.9", "size":"2254.88", "side":"SELL", "hash":"bb29af7085e14696237d966f1f0c795483ae3bd7", "best_bid":"0.1", "best_ask":"0.101"}, {"asset_id":"31940783580344558651011323787577288681658737625185216525249046282994042503801", "price":"0.1", "size":"2254.88", "side":"BUY", "hash":"d7d0f073179e4bd7d9e4ac2bc217e45a74dd7cd1", "best_bid":"0.899", "best_ask":"0.9"}], "timestamp":"1780178921229", "event_type":"price_change"}
{"market":"0x4f3421fb2daf5cca7430ed8d8132463963081572d75434393a1808fdb8829fe8", "price_changes":[{"asset_id":"45415751658241142530386585138386640503488308219341470020075667342738719018629", "price":"0.103", "size":"18203.31", "side":"SELL", "hash":"405844e124b913817f16180a95440c8b35842e7c", "best_bid":"0.1", "best_ask":"0.101"}, {"asset_id":"31940783580344558651011323787577288681658737625185216525249046282994042503801", "price":"0.897", "size":"18203.31", "side":"BUY", "hash":"bc9fd349e1e80e8b1ddd0c3b3a97e7d069affa64", "best_bid":"0.899", "best_ask":"0.9"}], "timestamp":"1780178922219", "event_type":"price_change"}
{"market":"0x4f3421fb2daf5cca7430ed8d8132463963081572d75434393a1808fdb8829fe8", "price_changes":[{"asset_id":"45415751658241142530386585138386640503488308219341470020075667342738719018629", "price":"0.103", "size":"18263.31", "side":"SELL", "hash":"6b6228071e8e64083cff6505caba0f875b2a2c73", "best_bid":"0.1", "best_ask":"0.101"}, {"asset_id":"31940783580344558651011323787577288681658737625185216525249046282994042503801", "price":"0.897", "size":"18263.31", "side":"BUY", "hash":"c37ffd308a809fe71e870601b6682fbb9874343e", "best_bid":"0.899", "best_ask":"0.9"}], "timestamp":"1780178922320", "event_type":"price_change"}
{"id":"2397791", "question":"Birmingham: Completed Match: Mackenzie McDonald vs Nicolai Budkov Kjaer", "market":"0x12e661fa6194fa0aff8e0214d2b514909a5e00923949f666055486db0a303f7c", "slug":"atp-mcdonal-kjaer-2026-06-01-completed-match", "description":"This market refers to the tennis match between Mackenzie McDonald and Nicolai Budkov Kjaer in the Birmingham, originally scheduled for June 1, 2026 at 5:30AM ET. This market will resolve to \"Yes\" if all games and sets required to determine a match winner under governing body or event organizer rules are played to completion through normal play. Otherwise, if the match is not completed for any reason, it will resolve to \"No.\" If a forfeit of any kind occurs, including but not limited to a walkover or retirement, this market will resolve \"No.\" If the match is canceled (not played at all), ends in a tie, or is delayed beyond 7 days from the scheduled date without a winner determined, this market will resolve to \"No.\" The primary resolution source for this market is the official statistics of the event as recognized by the governing body or event organizers. However, if the governing body or event organizers have not published final match statistics within 2 hours after the event's conclusion, a consensus of credible reporting may be used instead.", "assets_ids":["33630530075933260012741957739569795797481942468727851210935355092175833472114", "81344417717707641927008177668855273170751150645183791442739570154692094072488"], "outcomes":["Yes", "No"], "event_message":{"id":"542663", "ticker":"atp-mcdonal-kjaer-2026-06-01", "slug":"atp-mcdonal-kjaer-2026-06-01", "title":"Birmingham: Mackenzie McDonald vs Nicolai Budkov Kjaer", "description":"This market refers to the tennis match between Mackenzie McDonald and Nicolai Budkov Kjaer in the Birmingham, originally scheduled for June 1, 2026 at 5:30AM ET.\n\nThis market will resolve to 'Mackenzie McDonald' if Mackenzie McDonald advances against Nicolai Budkov Kjaer.\n\nThis market will resolve to 'Nicolai Budkov Kjaer' if Nicolai Budkov Kjaer advances against Mackenzie McDonald.\n\nIf the match is canceled (not played at all), ends in a tie, or is delayed beyond 7 days from the scheduled date without a winner determined, this market will resolve to 50-50.\n\nIf the match begins but is not completed, and one player advances due to the opponent's retirement, default, or disqualification, this market will resolve to the player who advances.\n\nIf the match ends in a walkover (player withdraws before the start and the other advances automatically), this market will resolve to 50-50.\n\nThe primary resolution source will be official information from the ATP Tour. A consensus of credible reporting may also be used."}, "timestamp":"1780178922478", "event_type":"new_market", "tags":[], "condition_id":"0x12e661fa6194fa0aff8e0214d2b514909a5e00923949f666055486db0a303f7c", "active":false, "clob_token_ids":["33630530075933260012741957739569795797481942468727851210935355092175833472114", "81344417717707641927008177668855273170751150645183791442739570154692094072488"], "sports_market_type":"tennis_completed_match", "line":"", "game_start_time":"2026-06-01 09:30:00+00", "order_price_min_tick_size":"0.01", "group_item_title":"Completed Match", "taker_base_fee":"1000", "fees_enabled":true, "fee_schedule":{"exponent":"1", "rate":"0.03", "taker_only":true, "rebate_rate":"0.25"}}
{"market":"0x9b6fef249040fd17e9c107955b37ac2c3e923509b6b0ff01cc463a331ddeb894", "price_changes":[{"asset_id":"108233603819467706476318984012158651931658302669301887462181073562758483842092", "price":"0.166", "size":"24952", "side":"SELL", "hash":"91d17e75f0214fb20198750638eeba52f698c70d", "best_bid":"0.163", "best_ask":"0.164"}, {"asset_id":"32270411694523539495262303868629477861017829722282576458031815333486368239544", "price":"0.834", "size":"24952", "side":"BUY", "hash":"293f454c926c623f77ec925d0b332e27b844cc82", "best_bid":"0.836", "best_ask":"0.837"}], "timestamp":"1780178922688", "event_type":"price_change"}
{"market":"0x9b6fef249040fd17e9c107955b37ac2c3e923509b6b0ff01cc463a331ddeb894", "price_changes":[{"asset_id":"108233603819467706476318984012158651931658302669301887462181073562758483842092", "price":"0.166", "size":"25006.68", "side":"SELL", "hash":"07646599ca4ddafa285563835c5bab3231dcf0d3", "best_bid":"0.163", "best_ask":"0.164"}, {"asset_id":"32270411694523539495262303868629477861017829722282576458031815333486368239544", "price":"0.834", "size":"25006.68", "side":"BUY", "hash":"dd1753ad5dc4a1cfbeaec11735fec6e16d9b7611", "best_bid":"0.836", "best_ask":"0.837"}], "timestamp":"1780178922798", "event_type":"price_change"}
{"market":"0x7976b8dbacf9077eb1453a62bcefd6ab2df199acd28aad276ff0d920d6992892", "price_changes":[{"asset_id":"4394372887385518214471608448209527405727552777602031099972143344338178308080", "price":"0.17", "size":"27598.28", "side":"SELL", "hash":"4ddabbe995b40a0240b3fe85c35143e7c49e55a1", "best_bid":"0.167", "best_ask":"0.168"}, {"asset_id":"112680630004798425069810935278212000865453267506345451433803052322987302357330", "price":"0.83", "size":"27598.28", "side":"BUY", "hash":"153cacd8a5e076d24f8a20673d4993fa0065093e", "best_bid":"0.832", "best_ask":"0.833"}], "timestamp":"1780178924456", "event_type":"price_change"}
{"market":"0x30d55d8124ee1e12dabe89201badc45669b81dff69e4ce44d961f32878ec178a", "price_changes":[{"asset_id":"27576533317283401577758999384642760405921738493660383550832555714312627457443", "price":"0.092", "size":"78371.18", "side":"SELL", "hash":"08404959ddd50b713dd61780f844459249c353ce", "best_bid":"0.089", "best_ask":"0.09"}, {"asset_id":"52986718774908357330412653486471347449818893503063830313445318937088822580057", "price":"0.908", "size":"78371.18", "side":"BUY", "hash":"4c3b931927b50645ed96428963089919672b800a", "best_bid":"0.91", "best_ask":"0.911"}], "timestamp":"1780178924457", "event_type":"price_change"}
{"id":"2397891", "question":"XRP Up or Down - May 31, 6:00PM-6:05PM ET", "market":"0x501fb81e6128b9f182a7d08618668029e6cfeb1ae678c74359984b0c008c030d", "slug":"xrp-updown-5m-1780264800", "description":"This market will resolve to \"Up\" if the XRP price at the end of the time range specified in the title is greater than or equal to the price at the beginning of that range. Otherwise, it will resolve to \"Down\".\nThe resolution source for this market is information from Chainlink, specifically the XRP/USD data stream available at https://data.chain.link/streams/xrp-usd.\nPlease note that this market is about the price according to Chainlink data stream XRP/USD, not according to other sources or spot markets.", "assets_ids":["2835875831623210635026786190633814575941981045396862186426597834261821924805", "31203376706193294585206093942327139082145315729205215270383431418141575298279"], "outcomes":["Up", "Down"], "event_message":{"id":"542713", "ticker":"xrp-updown-5m-1780264800", "slug":"xrp-updown-5m-1780264800", "title":"XRP Up or Down - May 31, 6:00PM-6:05PM ET", "description":"This market will resolve to \"Up\" if the XRP price at the end of the time range specified in the title is greater than or equal to the price at the beginning of that range. Otherwise, it will resolve to \"Down\".\nThe resolution source for this market is information from Chainlink, specifically the XRP/USD data stream available at https://data.chain.link/streams/xrp-usd.\nPlease note that this market is about the price according to Chainlink data stream XRP/USD, not according to other sources or spot markets."}, "timestamp":"1780178924531", "event_type":"new_market", "tags":[], "condition_id":"0x501fb81e6128b9f182a7d08618668029e6cfeb1ae678c74359984b0c008c030d", "active":false, "clob_token_ids":["2835875831623210635026786190633814575941981045396862186426597834261821924805", "31203376706193294585206093942327139082145315729205215270383431418141575298279"], "sports_market_type":"", "line":"", "game_start_time":"", "order_price_min_tick_size":"0.01", "group_item_title":"", "taker_base_fee":"1000", "fees_enabled":true, "fee_schedule":{"exponent":"1", "rate":"0.07", "taker_only":true, "rebate_rate":"0.2"}}
{"market":"0x7976b8dbacf9077eb1453a62bcefd6ab2df199acd28aad276ff0d920d6992892", "price_changes":[{"asset_id":"4394372887385518214471608448209527405727552777602031099972143344338178308080", "price":"0.17", "size":"27652.43", "side":"SELL", "hash":"26160934141e5d75b12902722cebf665cf8c0742", "best_bid":"0.167", "best_ask":"0.168"}, {"asset_id":"112680630004798425069810935278212000865453267506345451433803052322987302357330", "price":"0.83", "size":"27652.43", "side":"BUY", "hash":"eee53e79d0ce31b7cbfc703a12d3ffce5d8fc4ef", "best_bid":"0.832", "best_ask":"0.833"}], "timestamp":"1780178924558", "event_type":"price_change"}
{"market":"0x30d55d8124ee1e12dabe89201badc45669b81dff69e4ce44d961f32878ec178a", "price_changes":[{"asset_id":"27576533317283401577758999384642760405921738493660383550832555714312627457443", "price":"0.092", "size":"78431.18", "side":"SELL", "hash":"2d6824438f7721ad193e6bf65ab16ddb8b02ff30", "best_bid":"0.089", "best_ask":"0.09"}, {"asset_id":"52986718774908357330412653486471347449818893503063830313445318937088822580057", "price":"0.908", "size":"78431.18", "side":"BUY", "hash":"3b0eb0adce877bb9033ae3dba3ded3eae2fc5236", "best_bid":"0.91", "best_ask":"0.911"}], "timestamp":"1780178924593", "event_type":"price_change"}
{"market":"0x0c4cd2055d6ea89354ffddc55d6dbcef9355748112ea952fc925f3db6a5c457f", "price_changes":[{"asset_id":"18812649149814341758733697580460697418474693998558159483117100240528657629879", "price":"0.088", "size":"15069.46", "side":"SELL", "hash":"16d74b5d7fa2366a1a2f65ad76f4028fe9da2acc", "best_bid":"0.085", "best_ask":"0.086"}, {"asset_id":"115428153746996892211798999366308897078723117634059783423375188043903703749062", "price":"0.912", "size":"15069.46", "side":"BUY", "hash":"7ffd048f563816565ec21d3bccd7207ba5bc77ff", "best_bid":"0.914", "best_ask":"0.915"}], "timestamp":"1780178925727", "event_type":"price_change"}
{"market":"0x1595b4818eeb1ea1e0bec5de6f057218e557feee9b405a0e930d290384fa1d16", "price_changes":[{"asset_id":"81739002353269632749850710185641576213562066971072676369728657545679630163887", "price":"0.053", "size":"3311.26", "side":"SELL", "hash":"bcad9ffebae9d909035bcd4e5c9080723a4c312b", "best_bid":"0.051", "best_ask":"0.052"}, {"asset_id":"45484070731786948288366703334552551439356529561722304542938873238430842810537", "price":"0.947", "size":"3311.26", "side":"BUY", "hash":"07cc6574cbbfd88c730484ba2d99d2f86ff9189c", "best_bid":"0.948", "best_ask":"0.949"}], "timestamp":"1780178925774", "event_type":"price_change"}
{"market":"0x375409bc5eeeff961e82b479caeccc20f33d15738e5bce1186d628aa3d9dfb1f", "price_changes":[{"asset_id":"115556263888245616435851357148058235707004733438163639091106356867234218207169", "price":"0.115", "size":"12019.15", "side":"SELL", "hash":"aefbfb83c36df74b2fc92ee434d9e8eb0939be90", "best_bid":"0.112", "best_ask":"0.113"}, {"asset_id":"77121637225348873006259930776623502125079210522997384841464684944292365296940", "price":"0.885", "size":"12019.15", "side":"BUY", "hash":"5018687e470fcd01cd9965c6d5fe96ff393e9bf7", "best_bid":"0.887", "best_ask":"0.888"}], "timestamp":"1780178925780", "event_type":"price_change"}
{"market":"0x0c4cd2055d6ea89354ffddc55d6dbcef9355748112ea952fc925f3db6a5c457f", "price_changes":[{"asset_id":"18812649149814341758733697580460697418474693998558159483117100240528657629879", "price":"0.088", "size":"15129.46", "side":"SELL", "hash":"c280c6b383fdda15ebccd4a9b4e9089c41f04a1b", "best_bid":"0.085", "best_ask":"0.086"}, {"asset_id":"115428153746996892211798999366308897078723117634059783423375188043903703749062", "price":"0.912", "size":"15129.46", "side":"BUY", "hash":"72cbe18a95165197cc4571b3766bcbebba907a22", "best_bid":"0.914", "best_ask":"0.915"}], "timestamp":"1780178925863", "event_type":"price_change"}
{"market":"0x1595b4818eeb1ea1e0bec5de6f057218e557feee9b405a0e930d290384fa1d16", "price_changes":[{"asset_id":"81739002353269632749850710185641576213562066971072676369728657545679630163887", "price":"0.053", "size":"3371.26", "side":"SELL", "hash":"32313a9e4f65803e625a4392310d7fa8fe0028a4", "best_bid":"0.051", "best_ask":"0.052"}, {"asset_id":"45484070731786948288366703334552551439356529561722304542938873238430842810537", "price":"0.947", "size":"3371.26", "side":"BUY", "hash":"6ea1223d10d465b9faedc34390236dbd1cf04956", "best_bid":"0.948", "best_ask":"0.949"}], "timestamp":"1780178925905", "event_type":"price_change"}
{"market":"0x375409bc5eeeff961e82b479caeccc20f33d15738e5bce1186d628aa3d9dfb1f", "price_changes":[{"asset_id":"115556263888245616435851357148058235707004733438163639091106356867234218207169", "price":"0.115", "size":"12079.15", "side":"SELL", "hash":"b27f74f5f8a42b6f86e743ace9f8148b4da63e4f", "best_bid":"0.112", "best_ask":"0.113"}, {"asset_id":"77121637225348873006259930776623502125079210522997384841464684944292365296940", "price":"0.885", "size":"12079.15", "side":"BUY", "hash":"6a7e5b2323d3bfffc4673d99c0c45a10259248eb", "best_bid":"0.887", "best_ask":"0.888"}], "timestamp":"1780178925907", "event_type":"price_change"}
{"id":"2397619", "question":"Fight to Go the Distance?", "market":"0x322f0af40a251f7c226058ec09c96db0c64f5ab78818e3e22bc9c41ee1155160", "slug":"ufc-kyo-man1-2026-06-20-go-the-distance", "description":"This market will resolve to \"Yes\" if the fight between Kyoji Horiguchi and Manel Kape at UFC Fight Night: Kape vs. Horiguchi, scheduled for June 20, 2026, goes the full scheduled number of rounds and the result is determined by the judges' scorecards. Otherwise, it will resolve to \"No.\"\n\nDraws decided by the judges' scorecards after all scheduled rounds are completed will resolve \"Yes.\" Technical decisions or technical draws declared before all rounds are completed will resolve \"No.\"\n\nIf the bout is ruled a No Contest, not scored, canceled, or postponed beyond July 4, 2026, this market will resolve \"50-50.\"\n\nThe resolution source for this market will be official information from the UFC.", "assets_ids":["58260982764975783617486482712503703094371662829465565522379699404167015873627", "89829436961454606396844489381429920559072962723805744596444227459684548076307"], "outcomes":["Yes", "No"], "event_message":{"id":"542607", "ticker":"ufc-kyo-man1-2026-06-20", "slug":"ufc-kyo-man1-2026-06-20", "title":"UFC Fight Night: Kyoji Horiguchi vs. Manel Kape (Flyweight, Main Card)", "description":"This market will resolve to \"Kyoji Horiguchi\" if Kyoji Horiguchi is officially declared the winner of the fight against Manel Kape at UFC Fight Night: Kape vs. Horiguchi, scheduled for June 20, 2026.\n\nIt will resolve to \"Manel Kape\" if Manel Kape is officially declared the winner.\n\nIf the fight is declared a draw or technical draw, ruled a No Contest, not scored, canceled, or postponed beyond July 4, 2026, this market will resolve \"50-50.\"\n\nThe resolution source for this market will be official information from the UFC."}, "timestamp":"1780178926585", "event_type":"new_market", "tags":[], "condition_id":"0x322f0af40a251f7c226058ec09c96db0c64f5ab78818e3e22bc9c41ee1155160", "active":false, "clob_token_ids":["58260982764975783617486482712503703094371662829465565522379699404167015873627", "89829436961454606396844489381429920559072962723805744596444227459684548076307"], "sports_market_type":"ufc_go_the_distance", "line":"", "game_start_time":"2026-06-20 17:00:00+00", "order_price_min_tick_size":"0.01", "group_item_title":"Fight to Go the Distance?", "taker_base_fee":"1000", "fees_enabled":true, "fee_schedule":{"exponent":"1", "rate":"0.03", "taker_only":true, "rebate_rate":"0.25"}}
{"id":"2397846", "question":"Heilbronn: Completed Match: Mika Petkovic vs Alejandro Moro Canas", "market":"0xb7114a840ce06f7b64497bea3085d7cfae2a2697e493286a957e212ed48ee96d", "slug":"atp-petkovi-canas-2026-06-01-completed-match", "description":"This market refers to the tennis match between Mika Petkovic and Alejandro Moro Canas in the Heilbronn, originally scheduled for June 1, 2026 at 5:00AM ET. This market will resolve to \"Yes\" if all games and sets required to determine a match winner under governing body or event organizer rules are played to completion through normal play. Otherwise, if the match is not completed for any reason, it will resolve to \"No.\" If a forfeit of any kind occurs, including but not limited to a walkover or retirement, this market will resolve \"No.\" If the match is canceled (not played at all), ends in a tie, or is delayed beyond 7 days from the scheduled date without a winner determined, this market will resolve to \"No.\" The primary resolution source for this market is the official statistics of the event as recognized by the governing body or event organizers. However, if the governing body or event organizers have not published final match statistics within 2 hours after the event's conclusion, a consensus of credible reporting may be used instead.", "assets_ids":["41991675617705555247817583919647778796011211010667018092045571574084533322678", "74354420881652609613865742250886506432287531220911988615716509219891713270526"], "outcomes":["Yes", "No"], "event_message":{"id":"542688", "ticker":"atp-petkovi-canas-2026-06-01", "slug":"atp-petkovi-canas-2026-06-01", "title":"Heilbronn: Mika Petkovic vs Alejandro Moro Canas", "description":"This market refers to the tennis match between Mika Petkovic and Alejandro Moro Canas in the Heilbronn, originally scheduled for June 1, 2026 at 5:00AM ET.\n\nThis market will resolve to 'Mika Petkovic' if Mika Petkovic advances against Alejandro Moro Canas.\n\nThis market will resolve to 'Alejandro Moro Canas' if Alejandro Moro Canas advances against Mika Petkovic.\n\nIf the match is canceled (not played at all), ends in a tie, or is delayed beyond 7 days from the scheduled date without a winner determined, this market will resolve to 50-50.\n\nIf the match begins but is not completed, and one player advances due to the opponent's retirement, default, or disqualification, this market will resolve to the player who advances.\n\nIf the match ends in a walkover (player withdraws before the start and the other advances automatically), this market will resolve to 50-50.\n\nThe primary resolution source will be official information from the ATP Tour. A consensus of credible reporting may also be used."}, "timestamp":"1780178927591", "event_type":"new_market", "tags":[], "condition_id":"0xb7114a840ce06f7b64497bea3085d7cfae2a2697e493286a957e212ed48ee96d", "active":false, "clob_token_ids":["41991675617705555247817583919647778796011211010667018092045571574084533322678", "74354420881652609613865742250886506432287531220911988615716509219891713270526"], "sports_market_type":"tennis_completed_match", "line":"", "game_start_time":"2026-06-01 09:00:00+00", "order_price_min_tick_size":"0.01", "group_item_title":"Completed Match", "taker_base_fee":"1000", "fees_enabled":true, "fee_schedule":{"exponent":"1", "rate":"0.03", "taker_only":true, "rebate_rate":"0.25"}}
{"id":"2397807", "question":"Birmingham: Mark Lajal vs Leandro Riedi", "market":"0x1b93a4b0928ee303c1cb30888becc3dd1501737fd0a3ef6640ee61aa11796ba2", "slug":"atp-lajal-riedi-2026-06-01", "description":"This market refers to the tennis match between Mark Lajal and Leandro Riedi in the Birmingham, originally scheduled for June 1, 2026 at 5:30AM ET.\n\nThis market will resolve to 'Mark Lajal' if Mark Lajal advances against Leandro Riedi.\n\nThis market will resolve to 'Leandro Riedi' if Leandro Riedi advances against Mark Lajal.\n\nIf the match is canceled (not played at all), ends in a tie, or is delayed beyond 7 days from the scheduled date without a winner determined, this market will resolve to 50-50.\n\nIf the match begins but is not completed, and one player advances due to the opponent's retirement, default, or disqualification, this market will resolve to the player who advances.\n\nIf the match ends in a walkover (player withdraws before the start and the other advances automatically), this market will resolve to 50-50.\n\nThe primary resolution source will be official information from the ATP Tour. A consensus of credible reporting may also be used.", "assets_ids":["67503192213892667644088764782353034843601282881041407544384618544159630830642", "66508047428047799317136676858362808015480030381579496877326535843179212387652"], "outcomes":["Mark Lajal", "Leandro Riedi"], "event_message":{"id":"542669", "ticker":"atp-lajal-riedi-2026-06-01", "slug":"atp-lajal-riedi-2026-06-01", "title":"Birmingham: Mark Lajal vs Leandro Riedi", "description":"This market refers to the tennis match between Mark Lajal and Leandro Riedi in the Birmingham, originally scheduled for June 1, 2026 at 5:30AM ET.\n\nThis market will resolve to 'Mark Lajal' if Mark Lajal advances against Leandro Riedi.\n\nThis market will resolve to 'Leandro Riedi' if Leandro Riedi advances against Mark Lajal.\n\nIf the match is canceled (not played at all), ends in a tie, or is delayed beyond 7 days from the scheduled date without a winner determined, this market will resolve to 50-50.\n\nIf the match begins but is not completed, and one player advances due to the opponent's retirement, default, or disqualification, this market will resolve to the player who advances.\n\nIf the match ends in a walkover (player withdraws before the start and the other advances automatically), this market will resolve to 50-50.\n\nThe primary resolution source will be official information from the ATP Tour. A consensus of credible reporting may also be used."}, "timestamp":"1780178929606", "event_type":"new_market", "tags":[], "condition_id":"0x1b93a4b0928ee303c1cb30888becc3dd1501737fd0a3ef6640ee61aa11796ba2", "active":false, "clob_token_ids":["67503192213892667644088764782353034843601282881041407544384618544159630830642", "66508047428047799317136676858362808015480030381579496877326535843179212387652"], "sports_market_type":"moneyline", "line":"", "game_start_time":"2026-06-01 09:30:00+00", "order_price_min_tick_size":"0.01", "group_item_title":"", "taker_base_fee":"1000", "fees_enabled":true, "fee_schedule":{"exponent":"1", "rate":"0.03", "taker_only":true, "rebate_rate":"0.25"}}
PONG
{"id":"2397874", "question":"Spread: Los Angeles Angels (-1.5)", "market":"0x61c79f2314f7e221e42e437a044685fbb5fa05626be3b7e50a4f251306ca065a", "slug":"mlb-laa-tb-2026-05-31-spread-away-1pt5", "description":"In the upcoming MLB game between the Los Angeles Angels and Tampa Bay Rays, scheduled for May 31 at 1:40 PM ET:\n\nThis market will resolve to \"Los Angeles Angels\" if the Los Angeles Angels win the game by 2 or more runs.\n\nOtherwise, this market will resolve to \"Tampa Bay Rays\". If the game ends in a tie, this market will resolve to \"Tampa Bay Rays\".\n\nIf the game is postponed, this market will remain open until the game has been completed. If the game is canceled entirely, with no make-up game, this market will resolve 50-50.\n\nTo know when a postponed game will be played, please check the home team's schedule on MLB.com for the listed team and look for the game described as a makeup game.\n\nThe primary resolution source for this market is the official final statistics of the event as recognized by the governing body or event organizers. However, if the governing body or event organizers have not published final match statistics within 24 hours after the event's conclusion, a consensus of credible reporting may be used instead.", "assets_ids":["96417201500509786755921134084913484704638092227372582110064266022904361988815", "77944938500782056879741063955408921492931971737262756957903594660545644502226"], "outcomes":["Los Angeles Angels", "Tampa Bay Rays"], "event_message":{"id":"523533", "ticker":"mlb-laa-tb-2026-05-31", "slug":"mlb-laa-tb-2026-05-31", "title":"Los Angeles Angels vs. Tampa Bay Rays", "description":"In the upcoming MLB game between the Los Angeles Angels and Tampa Bay Rays, scheduled for May 31 at 1:40PM ET:\n\nThis market will resolve to \"Los Angeles Angels\" if the Los Angeles Angels win the game.\n\nThis market will resolve to \"Tampa Bay Rays\" if the Tampa Bay Rays win the game.\n\nIf the game is postponed, this market will remain open until the game has been completed. If the game is canceled entirely, with no make-up game, or ends in a tie, this market will resolve 50-50.\n\nThe primary resolution source for this market is the official final statistics of the event as recognized by the governing body or event organizers. However, if the governing body or event organizers have not published final match statistics within 24 hours after the event's conclusion, a consensus of credible reporting may be used instead."}, "timestamp":"1780178931589", "event_type":"new_market", "tags":[], "condition_id":"0x61c79f2314f7e221e42e437a044685fbb5fa05626be3b7e50a4f251306ca065a", "active":false, "clob_token_ids":["96417201500509786755921134084913484704638092227372582110064266022904361988815", "77944938500782056879741063955408921492931971737262756957903594660545644502226"], "sports_market_type":"spreads", "line":"-1.5", "game_start_time":"2026-05-31 17:40:00+00", "order_price_min_tick_size":"0.01", "group_item_title":"Spread -1.5", "taker_base_fee":"1000", "fees_enabled":true, "fee_schedule":{"exponent":"1", "rate":"0.03", "taker_only":true, "rebate_rate":"0.25"}}
{"id":"2397643", "question":"Vicenza: Completed Match: Jacopo Vasami vs Lukas Neumayer", "market":"0xe0e507698e55194bd1f05fb28b70d915afb5db2c2190ffc7ff61ec46630715ae", "slug":"atp-vasami-neumaye-2026-05-31-completed-match", "description":"This market refers to the tennis match between Jacopo Vasami and Lukas Neumayer in the Vicenza, originally scheduled for May 31, 2026 at 5:00AM ET. This market will resolve to \"Yes\" if all games and sets required to determine a match winner under governing body or event organizer rules are played to completion through normal play. Otherwise, if the match is not completed for any reason, it will resolve to \"No.\" If a forfeit of any kind occurs, including but not limited to a walkover or retirement, this market will resolve \"No.\" If the match is canceled (not played at all), ends in a tie, or is delayed beyond 7 days from the scheduled date without a winner determined, this market will resolve to \"No.\" The primary resolution source for this market is the official statistics of the event as recognized by the governing body or event organizers. However, if the governing body or event organizers have not published final match statistics within 2 hours after the event's conclusion, a consensus of credible reporting may be used instead.", "assets_ids":["56171749527989812804252429261593418085018228676071044603075073382543904747784", "7574493812697596789076544883142057030015048131078577377450735054145821933975"], "outcomes":["Yes", "No"], "event_message":{"id":"542614", "ticker":"atp-vasami-neumaye-2026-05-31", "slug":"atp-vasami-neumaye-2026-05-31", "title":"Vicenza: Jacopo Vasami vs Lukas Neumayer", "description":"This market refers to the tennis match between Jacopo Vasami and Lukas Neumayer in the Vicenza, originally scheduled for May 31, 2026 at 5:00AM ET.\n\nThis market will resolve to 'Jacopo Vasami' if Jacopo Vasami advances against Lukas Neumayer.\n\nThis market will resolve to 'Lukas Neumayer' if Lukas Neumayer advances against Jacopo Vasami.\n\nIf the match is canceled (not played at all), ends in a tie, or is delayed beyond 7 days from the scheduled date without a winner determined, this market will resolve to 50-50.\n\nIf the match begins but is not completed, and one player advances due to the opponent's retirement, default, or disqualification, this market will resolve to the player who advances.\n\nIf the match ends in a walkover (player withdraws before the start and the other advances automatically), this market will resolve to 50-50.\n\nThe primary resolution source will be official information from the ATP Tour. A consensus of credible reporting may also be used."}, "timestamp":"1780178932601", "event_type":"new_market", "tags":[], "condition_id":"0xe0e507698e55194bd1f05fb28b70d915afb5db2c2190ffc7ff61ec46630715ae", "active":false, "clob_token_ids":["56171749527989812804252429261593418085018228676071044603075073382543904747784", "7574493812697596789076544883142057030015048131078577377450735054145821933975"], "sports_market_type":"tennis_completed_match", "line":"", "game_start_time":"2026-05-31 09:00:00+00", "order_price_min_tick_size":"0.01", "group_item_title":"Completed Match", "taker_base_fee":"1000", "fees_enabled":true, "fee_schedule":{"exponent":"1", "rate":"0.03", "taker_only":true, "rebate_rate":"0.25"}}
{"market":"0x30d55d8124ee1e12dabe89201badc45669b81dff69e4ce44d961f32878ec178a", "price_changes":[{"asset_id":"27576533317283401577758999384642760405921738493660383550832555714312627457443", "price":"0.092", "size":"78375.52", "side":"SELL", "hash":"c865a686469423caff65717e5ed145c5883e11d8", "best_bid":"0.089", "best_ask":"0.09"}, {"asset_id":"52986718774908357330412653486471347449818893503063830313445318937088822580057", "price":"0.908", "size":"78375.52", "side":"BUY", "hash":"5b6bfc7f7f7ebe8b44b1daa16ea2c26728616109", "best_bid":"0.91", "best_ask":"0.911"}], "timestamp":"1780178934605", "event_type":"price_change"}
{"market":"0x1595b4818eeb1ea1e0bec5de6f057218e557feee9b405a0e930d290384fa1d16", "price_changes":[{"asset_id":"81739002353269632749850710185641576213562066971072676369728657545679630163887", "price":"0.053", "size":"3291.26", "side":"SELL", "hash":"18b46fa9244000d51fd7869e1a5a7a612b7e332b", "best_bid":"0.051", "best_ask":"0.052"}, {"asset_id":"45484070731786948288366703334552551439356529561722304542938873238430842810537", "price":"0.947", "size":"3291.26", "side":"BUY", "hash":"03140c6084c661a0f976430969cc100f2f76f64a", "best_bid":"0.948", "best_ask":"0.949"}], "timestamp":"1780178934606", "event_type":"price_change"}
{"market":"0x0c4cd2055d6ea89354ffddc55d6dbcef9355748112ea952fc925f3db6a5c457f", "price_changes":[{"asset_id":"18812649149814341758733697580460697418474693998558159483117100240528657629879", "price":"0.088", "size":"15049.46", "side":"SELL", "hash":"4854fd21c0f2e6fe112a538940b4af455f73a51e", "best_bid":"0.085", "best_ask":"0.086"}, {"asset_id":"115428153746996892211798999366308897078723117634059783423375188043903703749062", "price":"0.912", "size":"15049.46", "side":"BUY", "hash":"4ce56fe5b0656f79562e6643f3192d08ab572f65", "best_bid":"0.914", "best_ask":"0.915"}], "timestamp":"1780178934615", "event_type":"price_change"}
{"market":"0x7976b8dbacf9077eb1453a62bcefd6ab2df199acd28aad276ff0d920d6992892", "price_changes":[{"asset_id":"4394372887385518214471608448209527405727552777602031099972143344338178308080", "price":"0.17", "size":"27626.88", "side":"SELL", "hash":"5b1928635648ed0c1c09f36f4815673315d18dba", "best_bid":"0.167", "best_ask":"0.168"}, {"asset_id":"112680630004798425069810935278212000865453267506345451433803052322987302357330", "price":"0.83", "size":"27626.88", "side":"BUY", "hash":"448b59f6a3274dafb1f33c026b8f88677242cf30", "best_bid":"0.832", "best_ask":"0.833"}], "timestamp":"1780178934633", "event_type":"price_change"}
{"market":"0x0c4cd2055d6ea89354ffddc55d6dbcef9355748112ea952fc925f3db6a5c457f", "price_changes":[{"asset_id":"18812649149814341758733697580460697418474693998558159483117100240528657629879", "price":"0.088", "size":"15129.46", "side":"SELL", "hash":"1d2ca92e0d5ae624fb3c048593e0bce71b5994bd", "best_bid":"0.085", "best_ask":"0.086"}, {"asset_id":"115428153746996892211798999366308897078723117634059783423375188043903703749062", "price":"0.912", "size":"15129.46", "side":"BUY", "hash":"c47632261bb5dfe8a3435dca41859764214c102e", "best_bid":"0.914", "best_ask":"0.915"}], "timestamp":"1780178934739", "event_type":"price_change"}
{"market":"0x7976b8dbacf9077eb1453a62bcefd6ab2df199acd28aad276ff0d920d6992892", "price_changes":[{"asset_id":"4394372887385518214471608448209527405727552777602031099972143344338178308080", "price":"0.17", "size":"27652.43", "side":"SELL", "hash":"bcf9639611acbd332eb2bb20cfd49c166a40ae3c", "best_bid":"0.167", "best_ask":"0.168"}, {"asset_id":"112680630004798425069810935278212000865453267506345451433803052322987302357330", "price":"0.83", "size":"27652.43", "side":"BUY", "hash":"6c63337b31af61d82ecf0b2c90e328ed8ec75439", "best_bid":"0.832", "best_ask":"0.833"}], "timestamp":"1780178934740", "event_type":"price_change"}
{"market":"0x30d55d8124ee1e12dabe89201badc45669b81dff69e4ce44d961f32878ec178a", "price_changes":[{"asset_id":"27576533317283401577758999384642760405921738493660383550832555714312627457443", "price":"0.092", "size":"78431.18", "side":"SELL", "hash":"9a368c928288f542b76ab6b524e203d932d3fcc9", "best_bid":"0.089", "best_ask":"0.09"}, {"asset_id":"52986718774908357330412653486471347449818893503063830313445318937088822580057", "price":"0.908", "size":"78431.18", "side":"BUY", "hash":"a1efdb78ecb41b55e6f6b38649f13632bc457bfb", "best_bid":"0.91", "best_ask":"0.911"}], "timestamp":"1780178934742", "event_type":"price_change"}
{"market":"0x1595b4818eeb1ea1e0bec5de6f057218e557feee9b405a0e930d290384fa1d16", "price_changes":[{"asset_id":"81739002353269632749850710185641576213562066971072676369728657545679630163887", "price":"0.053", "size":"3371.26", "side":"SELL", "hash":"1f383593d37936bb56af3dbe6aac9cc9e10603b6", "best_bid":"0.051", "best_ask":"0.052"}, {"asset_id":"45484070731786948288366703334552551439356529561722304542938873238430842810537", "price":"0.947", "size":"3371.26", "side":"BUY", "hash":"aba03a200c2d2cdbe9fc2cd510b2334ec64d0631", "best_bid":"0.948", "best_ask":"0.949"}], "timestamp":"1780178934750", "event_type":"price_change"}
{"market":"0x7876851632c295043c66536150a304cb785abdf712ba8489d298c6e6926be106", "price_changes":[{"asset_id":"97239126062673310243763617236644392945530356142765650402171508075574679292913", "price":"0.49", "size":"0", "side":"SELL", "hash":"b8e5f9d81124bfcd8bdda20b305496fd29cfe0d9", "best_bid":"0.01", "best_ask":"0.011"}, {"asset_id":"19291692040378529618917910599727571242305935029274321291612270922648172794670", "price":"0.51", "size":"0", "side":"BUY", "hash":"43ca05568adb49d768e3f5e094c1c9fc3f018146", "best_bid":"0.989", "best_ask":"0.99"}], "timestamp":"1780178936340", "event_type":"price_change"}
{"market":"0x7876851632c295043c66536150a304cb785abdf712ba8489d298c6e6926be106", "price_changes":[{"asset_id":"97239126062673310243763617236644392945530356142765650402171508075574679292913", "price":"0.011", "size":"1818525.69", "side":"SELL", "hash":"1929be21cf8e9077487fe41eb547bae1b69c46bf", "best_bid":"0.01", "best_ask":"0.011"}, {"asset_id":"19291692040378529618917910599727571242305935029274321291612270922648172794670", "price":"0.989", "size":"1818525.69", "side":"BUY", "hash":"d0547f659747bb6de310ae9946c610963caf6876", "best_bid":"0.989", "best_ask":"0.99"}], "timestamp":"1780178937005", "event_type":"price_change"}
{"market":"0x9b6fef249040fd17e9c107955b37ac2c3e923509b6b0ff01cc463a331ddeb894", "price_changes":[{"asset_id":"108233603819467706476318984012158651931658302669301887462181073562758483842092", "price":"0.166", "size":"24926.68", "side":"SELL", "hash":"f1e2fc7455bd09a296317dee1d90128706f9361d", "best_bid":"0.163", "best_ask":"0.164"}, {"asset_id":"32270411694523539495262303868629477861017829722282576458031815333486368239544", "price":"0.834", "size":"24926.68", "side":"BUY", "hash":"84d8f7defa76c97f1d505d46d98190eabe460494", "best_bid":"0.836", "best_ask":"0.837"}], "timestamp":"1780178937204", "event_type":"price_change"}
{"market":"0x375409bc5eeeff961e82b479caeccc20f33d15738e5bce1186d628aa3d9dfb1f", "price_changes":[{"asset_id":"115556263888245616435851357148058235707004733438163639091106356867234218207169", "price":"0.115", "size":"11999.15", "side":"SELL", "hash":"403d2c5c99465f6fe137a85a40451c22ec7b9956", "best_bid":"0.112", "best_ask":"0.113"}, {"asset_id":"77121637225348873006259930776623502125079210522997384841464684944292365296940", "price":"0.885", "size":"11999.15", "side":"BUY", "hash":"625fbeafa22eb627e339d17dc159d51b1c0c35ea", "best_bid":"0.887", "best_ask":"0.888"}], "timestamp":"1780178937208", "event_type":"price_change"}
{"market":"0x9b6fef249040fd17e9c107955b37ac2c3e923509b6b0ff01cc463a331ddeb894", "price_changes":[{"asset_id":"108233603819467706476318984012158651931658302669301887462181073562758483842092", "price":"0.166", "size":"25006.68", "side":"SELL", "hash":"4c16ef8595a2228f2879ddac0030926c116fbbe0", "best_bid":"0.163", "best_ask":"0.164"}, {"asset_id":"32270411694523539495262303868629477861017829722282576458031815333486368239544", "price":"0.834", "size":"25006.68", "side":"BUY", "hash":"b2debd7e18a51c6799007ef75ea8bb66d61abe3b", "best_bid":"0.836", "best_ask":"0.837"}], "timestamp":"1780178937316", "event_type":"price_change"}
{"market":"0x375409bc5eeeff961e82b479caeccc20f33d15738e5bce1186d628aa3d9dfb1f", "price_changes":[{"asset_id":"115556263888245616435851357148058235707004733438163639091106356867234218207169", "price":"0.115", "size":"12079.15", "side":"SELL", "hash":"1c8d66a4730f05b9fbf2ba981bc44071aed66d42", "best_bid":"0.112", "best_ask":"0.113"}, {"asset_id":"77121637225348873006259930776623502125079210522997384841464684944292365296940", "price":"0.885", "size":"12079.15", "side":"BUY", "hash":"7da37c8583fa8d8b5b98ac1648e1fcf4148b3fad", "best_bid":"0.887", "best_ask":"0.888"}], "timestamp":"1780178937318", "event_type":"price_change"}
{"id":"2397624", "question":"Roland Garros WTA: Completed Match: Anastasia Potapova vs Anna Kalinskaya", "market":"0x39ce92f7343ce270960fb3abbc5dac567f0e94a91be9ffb1f406ae3a7530a371", "slug":"wta-potapov-kalinsk-2026-06-01-completed-match", "description":"This market refers to the tennis match between Anastasia Potapova and Anna Kalinskaya in the Roland Garros WTA, originally scheduled for June 1, 2026 at 5:00AM ET. This market will resolve to \"Yes\" if all games and sets required to determine a match winner under governing body or event organizer rules are played to completion through normal play. Otherwise, if the match is not completed for any reason, it will resolve to \"No.\" If a forfeit of any kind occurs, including but not limited to a walkover or retirement, this market will resolve \"No.\" If the match is canceled (not played at all), ends in a tie, or is delayed beyond 7 days from the scheduled date without a winner determined, this market will resolve to \"No.\" The primary resolution source for this market is the official statistics of the event as recognized by the governing body or event organizers. However, if the governing body or event organizers have not published final match statistics within 2 hours after the event's conclusion, a consensus of credible reporting may be used instead.", "assets_ids":["47946769821084466527728291928236596300525968511212189770450575511253097903933", "50872002204995694589360957185036303049234941091542349286228466031527018450564"], "outcomes":["Yes", "No"], "event_message":{"id":"542609", "ticker":"wta-potapov-kalinsk-2026-06-01", "slug":"wta-potapov-kalinsk-2026-06-01", "title":"Roland Garros WTA: Anastasia Potapova vs Anna Kalinskaya", "description":"This market refers to the tennis match between Anastasia Potapova and Anna Kalinskaya in the Roland Garros WTA, originally scheduled for June 1, 2026 at 5:00AM ET.\n\nThis market will resolve to 'Anastasia Potapova' if Anastasia Potapova advances against Anna Kalinskaya.\n\nThis market will resolve to 'Anna Kalinskaya' if Anna Kalinskaya advances against Anastasia Potapova.\n\nIf the match is canceled (not played at all), ends in a tie, or is delayed beyond 7 days from the scheduled date without a winner determined, this market will resolve to 50-50.\n\nIf the match begins but is not completed, and one player advances due to the opponent's retirement, default, or disqualification, this market will resolve to the player who advances.\n\nIf the match ends in a walkover (player withdraws before the start and the other advances automatically), this market will resolve to 50-50.\n\nThe primary resolution source will be official information from the WTA Tour. A consensus of credible reporting may also be used."}, "timestamp":"1780178937395", "event_type":"new_market", "tags":[], "condition_id":"0x39ce92f7343ce270960fb3abbc5dac567f0e94a91be9ffb1f406ae3a7530a371", "active":false, "clob_token_ids":["47946769821084466527728291928236596300525968511212189770450575511253097903933", "50872002204995694589360957185036303049234941091542349286228466031527018450564"], "sports_market_type":"tennis_completed_match", "line":"", "game_start_time":"2026-06-01 09:00:00+00", "order_price_min_tick_size":"0.01", "group_item_title":"Completed Match", "taker_base_fee":"1000", "fees_enabled":true, "fee_schedule":{"exponent":"1", "rate":"0.03", "taker_only":true, "rebate_rate":"0.25"}}
{"market":"0x4f3421fb2daf5cca7430ed8d8132463963081572d75434393a1808fdb8829fe8", "price_changes":[{"asset_id":"45415751658241142530386585138386640503488308219341470020075667342738719018629", "price":"0.103", "size":"18202.51", "side":"SELL", "hash":"8a180db4e532468b76f58dab4e50fe82fd377396", "best_bid":"0.1", "best_ask":"0.101"}, {"asset_id":"31940783580344558651011323787577288681658737625185216525249046282994042503801", "price":"0.897", "size":"18202.51", "side":"BUY", "hash":"88cbf795b5f5fcbfd8f02f31662e298ca2f2d961", "best_bid":"0.899", "best_ask":"0.9"}], "timestamp":"1780178937548", "event_type":"price_change"}
{"market":"0x4f3421fb2daf5cca7430ed8d8132463963081572d75434393a1808fdb8829fe8", "price_changes":[{"asset_id":"45415751658241142530386585138386640503488308219341470020075667342738719018629", "price":"0.103", "size":"18263.31", "side":"SELL", "hash":"7062b8c332f5a199ac5c8b3415884c034ef3df7f", "best_bid":"0.1", "best_ask":"0.101"}, {"asset_id":"31940783580344558651011323787577288681658737625185216525249046282994042503801", "price":"0.897", "size":"18263.31", "side":"BUY", "hash":"9788905ed7410d3cd7438663f6d69f4e287bb37a", "best_bid":"0.899", "best_ask":"0.9"}], "timestamp":"1780178937676", "event_type":"price_change"}
{"id":"2397662", "question":"Ethereum Up or Down - June 1, 6PM ET", "market":"0x596df2bfb79ff0e531ac9fffbced578ac1ab528d8b63a8232196e3b009036010", "slug":"ethereum-up-or-down-june-1-2026-6pm-et", "description":"This market will resolve to \"Up\" if the close price is greater than or equal to the open price for the ETH/USDT 1 hour candle that begins on the time and date specified in the title. Otherwise, this market will resolve to \"Down\".\n\nThe resolution source for this market is information from Binance, specifically the ETH/USDT pair (https://www.binance.com/en/trade/ETH_USDT). The close « C » and open « O » displayed at the top of the graph for the relevant \"1H\" candle will be used once the data for that candle is finalized.\n\nPlease note that this market is about the price according to Binance ETH/USDT, not according to other exchanges or trading pairs.", "assets_ids":["87497377039803089970718079387490838148210173547450347354809617899235764713967", "62900619383905385355144416729696540987607238955648256823324373709458310664442"], "outcomes":["Up", "Down"], "event_message":{"id":"542622", "ticker":"ethereum-up-or-down-june-1-2026-6pm-et", "slug":"ethereum-up-or-down-june-1-2026-6pm-et", "title":"Ethereum Up or Down - June 1, 6PM ET", "description":"This market will resolve to \"Up\" if the close price is greater than or equal to the open price for the ETH/USDT 1 hour candle that begins on the time and date specified in the title. Otherwise, this market will resolve to \"Down\".\n\nThe resolution source for this market is information from Binance, specifically the ETH/USDT pair (https://www.binance.com/en/trade/ETH_USDT). The close « C » and open « O » displayed at the top of the graph for the relevant \"1H\" candle will be used once the data for that candle is finalized.\n\nPlease note that this market is about the price according to Binance ETH/USDT, not according to other exchanges or trading pairs."}, "timestamp":"1780178939176", "event_type":"new_market", "tags":[], "condition_id":"0x596df2bfb79ff0e531ac9fffbced578ac1ab528d8b63a8232196e3b009036010", "active":false, "clob_token_ids":["87497377039803089970718079387490838148210173547450347354809617899235764713967", "62900619383905385355144416729696540987607238955648256823324373709458310664442"], "sports_market_type":"", "line":"", "game_start_time":"", "order_price_min_tick_size":"0.01", "group_item_title":"", "taker_base_fee":"1000", "fees_enabled":true, "fee_schedule":{"exponent":"1", "rate":"0.07", "taker_only":true, "rebate_rate":"0.2"}}
{"market":"0x1595b4818eeb1ea1e0bec5de6f057218e557feee9b405a0e930d290384fa1d16", "price_changes":[{"asset_id":"81739002353269632749850710185641576213562066971072676369728657545679630163887", "price":"0.49", "size":"0", "side":"SELL", "hash":"3a64325c973dba14a52b62a9f465960dc530e519", "best_bid":"0.051", "best_ask":"0.052"}, {"asset_id":"45484070731786948288366703334552551439356529561722304542938873238430842810537", "price":"0.51", "size":"0", "side":"BUY", "hash":"9c509be16383603df539a125dfe09300f8ef436a", "best_bid":"0.948", "best_ask":"0.949"}], "timestamp":"1780178939474", "event_type":"price_change"}
PONG
{"market":"0x7876851632c295043c66536150a304cb785abdf712ba8489d298c6e6926be106", "price_changes":[{"asset_id":"97239126062673310243763617236644392945530356142765650402171508075574679292913", "price":"0.011", "size":"1818565.69", "side":"SELL", "hash":"0c77134607998f0be3b5adec6ab5e194f1aef1e7", "best_bid":"0.01", "best_ask":"0.011"}, {"asset_id":"19291692040378529618917910599727571242305935029274321291612270922648172794670", "price":"0.989", "size":"1818565.69", "side":"BUY", "hash":"8ba8ea36361900ebf835a3cd3709fc809aed3c89", "best_bid":"0.989", "best_ask":"0.99"}], "timestamp":"1780178942665", "event_type":"price_change"}
{"market":"0x7976b8dbacf9077eb1453a62bcefd6ab2df199acd28aad276ff0d920d6992892", "price_changes":[{"asset_id":"4394372887385518214471608448209527405727552777602031099972143344338178308080", "price":"0.184", "size":"0", "side":"SELL", "hash":"50cf20e164af6c0b056b5771de2ae9139a2d097f", "best_bid":"0.167", "best_ask":"0.168"}, {"asset_id":"112680630004798425069810935278212000865453267506345451433803052322987302357330", "price":"0.816", "size":"0", "side":"BUY", "hash":"af6ed7acd3ca6791e90cf54b094b8b14ae9dea19", "best_bid":"0.832", "best_ask":"0.833"}], "timestamp":"1780178943414", "event_type":"price_change"}
{"market":"0x7976b8dbacf9077eb1453a62bcefd6ab2df199acd28aad276ff0d920d6992892", "price_changes":[{"asset_id":"4394372887385518214471608448209527405727552777602031099972143344338178308080", "price":"0.184", "size":"49.77", "side":"SELL", "hash":"b568ee453a04cf994918bb40c50ed7441444c4f1", "best_bid":"0.167", "best_ask":"0.168"}, {"asset_id":"112680630004798425069810935278212000865453267506345451433803052322987302357330", "price":"0.816", "size":"49.77", "side":"BUY", "hash":"a2a10acf09304cb7284ff0a6dd0f952662b4f299", "best_bid":"0.832", "best_ask":"0.833"}], "timestamp":"1780178943584", "event_type":"price_change"}
{"market":"0x4f3421fb2daf5cca7430ed8d8132463963081572d75434393a1808fdb8829fe8", "price_changes":[{"asset_id":"45415751658241142530386585138386640503488308219341470020075667342738719018629", "price":"0.49", "size":"119.6", "side":"SELL", "hash":"4c27a717c3206cdde113f4093defe2fa18db75d1", "best_bid":"0.1", "best_ask":"0.101"}, {"asset_id":"31940783580344558651011323787577288681658737625185216525249046282994042503801", "price":"0.51", "size":"119.6", "side":"BUY", "hash":"6d00bac2cbe95e0f4fe27342bc92d7858e47248f", "best_bid":"0.899", "best_ask":"0.9"}], "timestamp":"1780178943848", "event_type":"price_change"}
{"market":"0x4f3421fb2daf5cca7430ed8d8132463963081572d75434393a1808fdb8829fe8", "price_changes":[{"asset_id":"45415751658241142530386585138386640503488308219341470020075667342738719018629", "price":"0.49", "size":"205.76", "side":"SELL", "hash":"a64e5dbdeccddb530f9670d57ab0088071b8c71b", "best_bid":"0.1", "best_ask":"0.101"}, {"asset_id":"31940783580344558651011323787577288681658737625185216525249046282994042503801", "price":"0.51", "size":"205.76", "side":"BUY", "hash":"e1298d09611a5f511dd56f74ff8b64b338f26821", "best_bid":"0.899", "best_ask":"0.9"}], "timestamp":"1780178944010", "event_type":"price_change"}
{"market":"0x4f3421fb2daf5cca7430ed8d8132463963081572d75434393a1808fdb8829fe8", "price_changes":[{"asset_id":"31940783580344558651011323787577288681658737625185216525249046282994042503801", "price":"0.901", "size":"7769.08", "side":"SELL", "hash":"fab5f9d92f3f5abec9d15fb75b17e7b6f215e7ed", "best_bid":"0.899", "best_ask":"0.9"}, {"asset_id":"45415751658241142530386585138386640503488308219341470020075667342738719018629", "price":"0.099", "size":"7769.08", "side":"BUY", "hash":"d160123d3d59f77c10b677d8327a0ed64db48875", "best_bid":"0.1", "best_ask":"0.101"}], "timestamp":"1780178945225", "event_type":"price_change"}
{"market":"0x4f3421fb2daf5cca7430ed8d8132463963081572d75434393a1808fdb8829fe8", "price_changes":[{"asset_id":"31940783580344558651011323787577288681658737625185216525249046282994042503801", "price":"0.9", "size":"9228.59", "side":"SELL", "hash":"70cadcea131eba413701202c152c23f1986248bb", "best_bid":"0.899", "best_ask":"0.9"}, {"asset_id":"45415751658241142530386585138386640503488308219341470020075667342738719018629", "price":"0.1", "size":"9228.59", "side":"BUY", "hash":"8427da4a6f52063bd00fa90d1984c1bcc92007d3", "best_bid":"0.1", "best_ask":"0.101"}], "timestamp":"1780178945379", "event_type":"price_change"}
{"market":"0x7876851632c295043c66536150a304cb785abdf712ba8489d298c6e6926be106", "price_changes":[{"asset_id":"97239126062673310243763617236644392945530356142765650402171508075574679292913", "price":"0.49", "size":"7.97", "side":"SELL", "hash":"85ab3430afdb8787c85d27e05d39767bf26bf8c0", "best_bid":"0.01", "best_ask":"0.011"}, {"asset_id":"19291692040378529618917910599727571242305935029274321291612270922648172794670", "price":"0.51", "size":"7.97", "side":"BUY", "hash":"9bc06b9b4317f2c106affa9651ab247d5fef2bbd", "best_bid":"0.989", "best_ask":"0.99"}], "timestamp":"1780178945546", "event_type":"price_change"}
{"market":"0x1595b4818eeb1ea1e0bec5de6f057218e557feee9b405a0e930d290384fa1d16", "price_changes":[{"asset_id":"81739002353269632749850710185641576213562066971072676369728657545679630163887", "price":"0.49", "size":"87.55", "side":"SELL", "hash":"0c607dee8812b0ac283eed9b5c64868fd2f18da2", "best_bid":"0.051", "best_ask":"0.052"}, {"asset_id":"45484070731786948288366703334552551439356529561722304542938873238430842810537", "price":"0.51", "size":"87.55", "side":"BUY", "hash":"d5024338822619a6d690cce2d0016e4734513a85", "best_bid":"0.948", "best_ask":"0.949"}], "timestamp":"1780178947989", "event_type":"price_change"}
{"market":"0x4f3421fb2daf5cca7430ed8d8132463963081572d75434393a1808fdb8829fe8", "asset_id":"31940783580344558651011323787577288681658737625185216525249046282994042503801", "best_bid":"0.899", "best_ask":"0.9", "spread":"0.001", "timestamp":"1780178948499", "event_type":"best_bid_ask"}
{"market":"0x4f3421fb2daf5cca7430ed8d8132463963081572d75434393a1808fdb8829fe8", "price_changes":[{"asset_id":"45415751658241142530386585138386640503488308219341470020075667342738719018629", "price":"0.101", "size":"66345.14", "side":"SELL", "hash":"b4b7b4b6e47122e18ab0bef48d7a9d7641853134", "best_bid":"0.1", "best_ask":"0.101"}, {"asset_id":"31940783580344558651011323787577288681658737625185216525249046282994042503801", "price":"0.899", "size":"66345.14", "side":"BUY", "hash":"57ddc498f99b667a7ea428b59b4507501b572f42", "best_bid":"0.899", "best_ask":"0.9"}], "timestamp":"1780178948492", "event_type":"price_change"}
{"market":"0x4f3421fb2daf5cca7430ed8d8132463963081572d75434393a1808fdb8829fe8", "asset_id":"31940783580344558651011323787577288681658737625185216525249046282994042503801", "bids":[{"price":"0.001", "size":"21074238.91"}, {"price":"0.002", "size":"37.76"}, {"price":"0.01", "size":"25929.6"}, {"price":"0.011", "size":"6.21"}, {"price":"0.014", "size":"1111111"}, {"price":"0.015", "size":"1000000"}, {"price":"0.02", "size":"36500"}, {"price":"0.021", "size":"800"}, {"price":"0.022", "size":"11.19"}, {"price":"0.05", "size":"40"}, {"price":"0.077", "size":"2000"}, {"price":"0.078", "size":"5.64"}, {"price":"0.1", "size":"2254.88"}, {"price":"0.11", "size":"1016"}, {"price":"0.12", "size":"1021"}, {"price":"0.13", "size":"1000"}, {"price":"0.14", "size":"999.99"}, {"price":"0.15", "size":"1153.71"}, {"price":"0.2", "size":"409.2"}, {"price":"0.224", "size":"433.92"}, {"price":"0.225", "size":"5.14"}, {"price":"0.25", "size":"453.7"}, {"price":"0.253", "size":"200"}, {"price":"0.254", "size":"200"}, {"price":"0.27", "size":"200"}, {"price":"0.28", "size":"200"}, {"price":"0.31", "size":"200"}, {"price":"0.33", "size":"215.15"}, {"price":"0.34", "size":"199.99"}, {"price":"0.35", "size":"102.46"}, {"price":"0.36", "size":"228"}, {"price":"0.361", "size":"100"}, {"price":"0.4", "size":"34637.29"}, {"price":"0.401", "size":"5000"}, {"price":"0.41", "size":"200"}, {"price":"0.42", "size":"200"}, {"price":"0.43", "size":"200"}, {"price":"0.44", "size":"200"}, {"price":"0.45", "size":"354.02"}, {"price":"0.46", "size":"200"}, {"price":"0.461", "size":"1077.83"}, {"price":"0.5", "size":"25496.62"}, {"price":"0.501", "size":"5100"}, {"price":"0.51", "size":"205.76"}, {"price":"0.511", "size":"100"}, {"price":"0.52", "size":"100"}, {"price":"0.53", "size":"100"}, {"price":"0.54", "size":"100"}, {"price":"0.55", "size":"100"}, {"price":"0.56", "size":"100"}, {"price":"0.57", "size":"100"}, {"price":"0.58", "size":"100"}, {"price":"0.6", "size":"21059.73"}, {"price":"0.61", "size":"100"}, {"price":"0.62", "size":"111.9"}, {"price":"0.632", "size":"5322.31"}, {"price":"0.64", "size":"28.8"}, {"price":"0.643", "size":"100"}, {"price":"0.65", "size":"16970.62"}, {"price":"0.66", "size":"100"}, {"price":"0.67", "size":"100"}, {"price":"0.673", "size":"100"}, {"price":"0.674", "size":"100"}, {"price":"0.678", "size":"100"}, {"price":"0.68", "size":"410.68"}, {"price":"0.69", "size":"100"}, {"price":"0.7", "size":"422.3"}, {"price":"0.703", "size":"100"}, {"price":"0.704", "size":"100"}, {"price":"0.708", "size":"100"}, {"price":"0.71", "size":"61.7"}, {"price":"0.729", "size":"1000"}, {"price":"0.733", "size":"100"}, {"price":"0.75", "size":"3192.15"}, {"price":"0.759", "size":"1000"}, {"price":"0.76", "size":"341.8"}, {"price":"0.763", "size":"100"}, {"price":"0.764", "size":"100"}, {"price":"0.769", "size":"100"}, {"price":"0.777", "size":"100"}, {"price":"0.778", "size":"400"}, {"price":"0.78", "size":"258.06"}, {"price":"0.781", "size":"100"}, {"price":"0.789", "size":"1000"}, {"price":"0.79", "size":"47.6"}, {"price":"0.798", "size":"1781.45"}, {"price":"0.8", "size":"246868.85"}, {"price":"0.801", "size":"100"}, {"price":"0.809", "size":"1000"}, {"price":"0.819", "size":"1000"}, {"price":"0.82", "size":"30"}, {"price":"0.826", "size":"100"}, {"price":"0.829", "size":"1100"}, {"price":"0.83", "size":"39.23"}, {"price":"0.839", "size":"1000"}, {"price":"0.84", "size":"356.45"}, {"price":"0.847", "size":"100"}, {"price":"0.849", "size":"3541.52"}, {"price":"0.85", "size":"15927.35"}, {"price":"0.851", "size":"800"}, {"price":"0.853", "size":"68.33"}, {"price":"0.855", "size":"13.33"}, {"price":"0.858", "size":"35.21"}, {"price":"0.859", "size":"671"}, {"price":"0.86", "size":"34.6"}, {"price":"0.862", "size":"75"}, {"price":"0.867", "size":"17.97"}, {"price":"0.869", "size":"666"}, {"price":"0.87", "size":"4000"}, {"price":"0.871", "size":"39.42"}, {"price":"0.875", "size":"170"}, {"price":"0.878", "size":"232.7"}, {"price":"0.88", "size":"197"}, {"price":"0.882", "size":"1000"}, {"price":"0.885", "size":"925.73"}, {"price":"0.886", "size":"100"}, {"price":"0.887", "size":"100"}, {"price":"0.888", "size":"100"}, {"price":"0.889", "size":"100"}, {"price":"0.89", "size":"649.23"}, {"price":"0.891", "size":"1343.33"}, {"price":"0.892", "size":"7071.71"}, {"price":"0.893", "size":"15257.35"}, {"price":"0.894", "size":"121650.88"}, {"price":"0.895", "size":"1515.46"}, {"price":"0.896", "size":"30940.81"}, {"price":"0.897", "size":"18263.31"}, {"price":"0.898", "size":"90693.2"}, {"price":"0.899", "size":"66345.14"}], "asks":[{"price":"0.999", "size":"4715397.01"}, {"price":"0.998", "size":"14"}, {"price":"0.997", "size":"1112792"}, {"price":"0.996", "size":"55564"}, {"price":"0.995", "size":"10009"}, {"price":"0.994", "size":"11109"}, {"price":"0.993", "size":"10009"}, {"price":"0.992", "size":"10009"}, {"price":"0.991", "size":"5009"}, {"price":"0.99", "size":"6209"}, {"price":"0.989", "size":"5009"}, {"price":"0.988", "size":"5009"}, {"price":"0.987", "size":"4309"}, {"price":"0.986", "size":"3009"}, {"price":"0.985", "size":"5009"}, {"price":"0.984", "size":"3009"}, {"price":"0.983", "size":"3009"}, {"price":"0.982", "size":"9"}, {"price":"0.981", "size":"5009"}, {"price":"0.98", "size":"6234"}, {"price":"0.979", "size":"4008.99"}, {"price":"0.978", "size":"4009"}, {"price":"0.977", "size":"4009"}, {"price":"0.976", "size":"3009"}, {"price":"0.975", "size":"3009"}, {"price":"0.974", "size":"4009"}, {"price":"0.973", "size":"3009"}, {"price":"0.972", "size":"4009"}, {"price":"0.971", "size":"2009"}, {"price":"0.97", "size":"409"}, {"price":"0.969", "size":"2509"}, {"price":"0.968", "size":"2652.85"}, {"price":"0.967", "size":"2509"}, {"price":"0.966", "size":"2509"}, {"price":"0.965", "size":"9"}, {"price":"0.964", "size":"9"}, {"price":"0.963", "size":"9"}, {"price":"0.962", "size":"609"}, {"price":"0.961", "size":"9"}, {"price":"0.96", "size":"134"}, {"price":"0.959", "size":"9"}, {"price":"0.958", "size":"9"}, {"price":"0.957", "size":"9"}, {"price":"0.956", "size":"9"}, {"price":"0.955", "size":"9"}, {"price":"0.954", "size":"9"}, {"price":"0.953", "size":"9"}, {"price":"0.952", "size":"9"}, {"price":"0.951", "size":"9"}, {"price":"0.95", "size":"79"}, {"price":"0.949", "size":"10009"}, {"price":"0.948", "size":"9"}, {"price":"0.947", "size":"9"}, {"price":"0.946", "size":"9"}, {"price":"0.945", "size":"309"}, {"price":"0.944", "size":"9"}, {"price":"0.943", "size":"9"}, {"price":"0.942", "size":"9"}, {"price":"0.941", "size":"9"}, {"price":"0.94", "size":"36"}, {"price":"0.939", "size":"202"}, {"price":"0.938", "size":"10009"}, {"price":"0.937", "size":"5009"}, {"price":"0.936", "size":"7509"}, {"price":"0.935", "size":"5151"}, {"price":"0.934", "size":"6209"}, {"price":"0.933", "size":"4603.78"}, {"price":"0.932", "size":"2856.05"}, {"price":"0.931", "size":"2772.73"}, {"price":"0.93", "size":"9438.97"}, {"price":"0.929", "size":"1564"}, {"price":"0.928", "size":"5464.3"}, {"price":"0.927", "size":"1109"}, {"price":"0.926", "size":"357402.07"}, {"price":"0.925", "size":"20562.67"}, {"price":"0.924", "size":"6753.29"}, {"price":"0.923", "size":"434.15"}, {"price":"0.922", "size":"512.12"}, {"price":"0.921", "size":"25029"}, {"price":"0.92", "size":"15376.09"}, {"price":"0.919", "size":"1633.99"}, {"price":"0.918", "size":"14672.52"}, {"price":"0.917", "size":"2431.41"}, {"price":"0.916", "size":"9"}, {"price":"0.915", "size":"821.33"}, {"price":"0.914", "size":"22609"}, {"price":"0.913", "size":"4605.61"}, {"price":"0.912", "size":"1782.17"}, {"price":"0.911", "size":"570.79"}, {"price":"0.91", "size":"6657.21"}, {"price":"0.909", "size":"958.45"}, {"price":"0.908", "size":"909"}, {"price":"0.907", "size":"3608.93"}, {"price":"0.906", "size":"1240.91"}, {"price":"0.905", "size":"3028.99"}, {"price":"0.904", "size":"1169.1"}, {"price":"0.903", "size":"6197.22"}, {"price":"0.902", "size":"6110.44"}, {"price":"0.901", "size":"7769.08"}, {"price":"0.9", "size":"9228.59"}], "hash":"57ddc498f99b667a7ea428b59b4507501b572f42", "timestamp":"1780178948492", "event_type":"book"}
{"market":"0x4f3421fb2daf5cca7430ed8d8132463963081572d75434393a1808fdb8829fe8", "asset_id":"31940783580344558651011323787577288681658737625185216525249046282994042503801", "price":"0.899", "size":"58.16", "fee_rate_bps":"0", "side":"SELL", "timestamp":"1780178948543", "event_type":"last_trade_price", "transaction_hash":"0x98b9614a308377ee6d7a51a3140f6e7882c133c01d49a7b7dbbc077d3b690285"}
{"id":"2397868", "question":"Spread: Baltimore Orioles (-3.5)", "market":"0x59f924f3bf09bd1918696cb2c6c1d6605cbc8f85c2d3bc0369aa02b69e887d8b", "slug":"mlb-tor-bal-2026-05-31-spread-home-3pt5", "description":"In the upcoming MLB game between the Toronto Blue Jays and Baltimore Orioles, scheduled for May 31 at 12:15 PM ET:\n\nThis market will resolve to \"Baltimore Orioles\" if the Baltimore Orioles win the game by 4 or more runs.\n\nOtherwise, this market will resolve to \"Toronto Blue Jays\". If the game ends in a tie, this market will resolve to \"Toronto Blue Jays\".\n\nIf the game is postponed, this market will remain open until the game has been completed. If the game is canceled entirely, with no make-up game, this market will resolve 50-50.\n\nTo know when a postponed game will be played, please check the home team's schedule on MLB.com for the listed team and look for the game described as a makeup game.\n\nThe primary resolution source for this market is the official final statistics of the event as recognized by the governing body or event organizers. However, if the governing body or event organizers have not published final match statistics within 24 hours after the event's conclusion, a consensus of credible reporting may be used instead.", "assets_ids":["3724656636895473232774130673565629615821697727523243828523301808527465288490", "46227087899676083717192374216219923459697903882772942205762745780025282110921"], "outcomes":["Baltimore Orioles", "Toronto Blue Jays"], "event_message":{"id":"523526", "ticker":"mlb-tor-bal-2026-05-31", "slug":"mlb-tor-bal-2026-05-31", "title":"Toronto Blue Jays vs. Baltimore Orioles", "description":"In the upcoming MLB game between the Toronto Blue Jays and Baltimore Orioles, scheduled for May 31 at 12:15PM ET:\n\nThis market will resolve to \"Toronto Blue Jays\" if the Toronto Blue Jays win the game.\n\nThis market will resolve to \"Baltimore Orioles\" if the Baltimore Orioles win the game.\n\nIf the game is postponed, this market will remain open until the game has been completed. If the game is canceled entirely, with no make-up game, or ends in a tie, this market will resolve 50-50.\n\nThe primary resolution source for this market is the official final statistics of the event as recognized by the governing body or event organizers. However, if the governing body or event organizers have not published final match statistics within 24 hours after the event's conclusion, a consensus of credible reporting may be used instead."}, "timestamp":"1780178949076", "event_type":"new_market", "tags":[], "condition_id":"0x59f924f3bf09bd1918696cb2c6c1d6605cbc8f85c2d3bc0369aa02b69e887d8b", "active":false, "clob_token_ids":["3724656636895473232774130673565629615821697727523243828523301808527465288490", "46227087899676083717192374216219923459697903882772942205762745780025282110921"], "sports_market_type":"spreads", "line":"-3.5", "game_start_time":"2026-05-31 16:15:00+00", "order_price_min_tick_size":"0.01", "group_item_title":"Spread -3.5", "taker_base_fee":"1000", "fees_enabled":true, "fee_schedule":{"exponent":"1", "rate":"0.03", "taker_only":true, "rebate_rate":"0.25"}}
{"id":"2397819", "question":"Perugia: Moez Echargui vs Chun-Hsin Tseng", "market":"0xb8aa4631c9e61ad362d4b4a2fc59613cdc2aa2fa28f3ed6449e7d55b0830bd2b", "slug":"atp-echargu-tseng-2026-06-01", "description":"This market refers to the tennis match between Moez Echargui and Chun-Hsin Tseng in the Perugia, originally scheduled for June 1, 2026 at 4:00AM ET.\n\nThis market will resolve to 'Moez Echargui' if Moez Echargui advances against Chun-Hsin Tseng.\n\nThis market will resolve to 'Chun-Hsin Tseng' if Chun-Hsin Tseng advances against Moez Echargui.\n\nIf the match is canceled (not played at all), ends in a tie, or is delayed beyond 7 days from the scheduled date without a winner determined, this market will resolve to 50-50.\n\nIf the match begins but is not completed, and one player advances due to the opponent's retirement, default, or disqualification, this market will resolve to the player who advances.\n\nIf the match ends in a walkover (player withdraws before the start and the other advances automatically), this market will resolve to 50-50.\n\nThe primary resolution source will be official information from the ATP Tour. A consensus of credible reporting may also be used.", "assets_ids":["4589624401292675609617382123213680629560642983118485554254083735180916024629", "34358293897658717003620098547921206393043801296982159995887718199893420536607"], "outcomes":["Moez Echargui", "Chun-Hsin Tseng"], "event_message":{"id":"542675", "ticker":"atp-echargu-tseng-2026-06-01", "slug":"atp-echargu-tseng-2026-06-01", "title":"Perugia: Moez Echargui vs Chun-Hsin Tseng", "description":"This market refers to the tennis match between Moez Echargui and Chun-Hsin Tseng in the Perugia, originally scheduled for June 1, 2026 at 4:00AM ET.\n\nThis market will resolve to 'Moez Echargui' if Moez Echargui advances against Chun-Hsin Tseng.\n\nThis market will resolve to 'Chun-Hsin Tseng' if Chun-Hsin Tseng advances against Moez Echargui.\n\nIf the match is canceled (not played at all), ends in a tie, or is delayed beyond 7 days from the scheduled date without a winner determined, this market will resolve to 50-50.\n\nIf the match begins but is not completed, and one player advances due to the opponent's retirement, default, or disqualification, this market will resolve to the player who advances.\n\nIf the match ends in a walkover (player withdraws before the start and the other advances automatically), this market will resolve to 50-50.\n\nThe primary resolution source will be official information from the ATP Tour. A consensus of credible reporting may also be used."}, "timestamp":"1780178950182", "event_type":"new_market", "tags":[], "condition_id":"0xb8aa4631c9e61ad362d4b4a2fc59613cdc2aa2fa28f3ed6449e7d55b0830bd2b", "active":false, "clob_token_ids":["4589624401292675609617382123213680629560642983118485554254083735180916024629", "34358293897658717003620098547921206393043801296982159995887718199893420536607"], "sports_market_type":"moneyline", "line":"", "game_start_time":"2026-06-01 08:00:00+00", "order_price_min_tick_size":"0.01", "group_item_title":"", "taker_base_fee":"1000", "fees_enabled":true, "fee_schedule":{"exponent":"1", "rate":"0.03", "taker_only":true, "rebate_rate":"0.25"}}
PONG
{"market":"0x4f3421fb2daf5cca7430ed8d8132463963081572d75434393a1808fdb8829fe8", "price_changes":[{"asset_id":"45415751658241142530386585138386640503488308219341470020075667342738719018629", "price":"0.103", "size":"18203.31", "side":"SELL", "hash":"e1574a3f8436576022fc813784a6a873097d0190", "best_bid":"0.1", "best_ask":"0.101"}, {"asset_id":"31940783580344558651011323787577288681658737625185216525249046282994042503801", "price":"0.897", "size":"18203.31", "side":"BUY", "hash":"babd45bec58c94fb45e463803e3f07c5a0276902", "best_bid":"0.899", "best_ask":"0.9"}], "timestamp":"1780178952744", "event_type":"price_change"}
{"id":"2397884", "question":"Hyperliquid Up or Down - May 31, 6:00PM-6:15PM ET", "market":"0x8b5fcb174ea861828524e119fdca230b6ddd1860aa5cfbccae02abbf9bc4aa86", "slug":"hype-updown-15m-1780264800", "description":"This market will resolve to \"Up\" if the Hyperliquid price at the end of the time range specified in the title is greater than or equal to the price at the beginning of that range. Otherwise, it will resolve to \"Down\".\nThe resolution source for this market is information from Chainlink, specifically the HYPE/USD data stream available at https://data.chain.link/streams/hype-usd.\nPlease note that this market is about the price according to Chainlink data stream HYPE/USD, not according to other sources or spot markets.", "assets_ids":["111030135758445332193990386276442112696333245769996954852075848116591212352834", "49228478327103274095744860388814174565545787415905370337572130750213940565680"], "outcomes":["Up", "Down"], "event_message":{"id":"542706", "ticker":"hype-updown-15m-1780264800", "slug":"hype-updown-15m-1780264800", "title":"Hyperliquid Up or Down - May 31, 6:00PM-6:15PM ET", "description":"This market will resolve to \"Up\" if the Hyperliquid price at the end of the time range specified in the title is greater than or equal to the price at the beginning of that range. Otherwise, it will resolve to \"Down\".\nThe resolution source for this market is information from Chainlink, specifically the HYPE/USD data stream available at https://data.chain.link/streams/hype-usd.\nPlease note that this market is about the price according to Chainlink data stream HYPE/USD, not according to other sources or spot markets."}, "timestamp":"1780178952795", "event_type":"new_market", "tags":[], "condition_id":"0x8b5fcb174ea861828524e119fdca230b6ddd1860aa5cfbccae02abbf9bc4aa86", "active":false, "clob_token_ids":["111030135758445332193990386276442112696333245769996954852075848116591212352834", "49228478327103274095744860388814174565545787415905370337572130750213940565680"], "sports_market_type":"", "line":"", "game_start_time":"", "order_price_min_tick_size":"0.01", "group_item_title":"", "taker_base_fee":"1000", "fees_enabled":true, "fee_schedule":{"exponent":"1", "rate":"0.07", "taker_only":true, "rebate_rate":"0.2"}}
{"market":"0x9b6fef249040fd17e9c107955b37ac2c3e923509b6b0ff01cc463a331ddeb894", "price_changes":[{"asset_id":"108233603819467706476318984012158651931658302669301887462181073562758483842092", "price":"0.166", "size":"24952", "side":"SELL", "hash":"1d934936abe62bb5c987afec0c445e01cd9fdcdd", "best_bid":"0.163", "best_ask":"0.164"}, {"asset_id":"32270411694523539495262303868629477861017829722282576458031815333486368239544", "price":"0.834", "size":"24952", "side":"BUY", "hash":"c78ab29a878c8e2a030e488c4a250d0df07a7dde", "best_bid":"0.836", "best_ask":"0.837"}], "timestamp":"1780178952973", "event_type":"price_change"}
{"market":"0x4f3421fb2daf5cca7430ed8d8132463963081572d75434393a1808fdb8829fe8", "price_changes":[{"asset_id":"45415751658241142530386585138386640503488308219341470020075667342738719018629", "price":"0.103", "size":"18263.31", "side":"SELL", "hash":"1aabb05451df3a358ef68618bfa6d6ad68376ebe", "best_bid":"0.1", "best_ask":"0.101"}, {"asset_id":"31940783580344558651011323787577288681658737625185216525249046282994042503801", "price":"0.897", "size":"18263.31", "side":"BUY", "hash":"06490787551c1cc6658cb5253cb5ff92304a9d0d", "best_bid":"0.899", "best_ask":"0.9"}], "timestamp":"1780178953200", "event_type":"price_change"}
{"market":"0x9b6fef249040fd17e9c107955b37ac2c3e923509b6b0ff01cc463a331ddeb894", "price_changes":[{"asset_id":"108233603819467706476318984012158651931658302669301887462181073562758483842092", "price":"0.166", "size":"25006.68", "side":"SELL", "hash":"e873c3d747013e5647be2d3d7418598d656172e1", "best_bid":"0.163", "best_ask":"0.164"}, {"asset_id":"32270411694523539495262303868629477861017829722282576458031815333486368239544", "price":"0.834", "size":"25006.68", "side":"BUY", "hash":"4769e7a3c2cd49041a92d2e4ad29086bb1d84c49", "best_bid":"0.836", "best_ask":"0.837"}], "timestamp":"1780178953235", "event_type":"price_change"}
{"market":"0x30d55d8124ee1e12dabe89201badc45669b81dff69e4ce44d961f32878ec178a", "price_changes":[{"asset_id":"27576533317283401577758999384642760405921738493660383550832555714312627457443", "price":"0.092", "size":"78371.18", "side":"SELL", "hash":"16fa48da50dc496feadb964fad1aeef84cb494a5", "best_bid":"0.089", "best_ask":"0.09"}, {"asset_id":"52986718774908357330412653486471347449818893503063830313445318937088822580057", "price":"0.908", "size":"78371.18", "side":"BUY", "hash":"f7921b5d4bcdad8046abe3cf12fd16fa76d9e280", "best_bid":"0.91", "best_ask":"0.911"}], "timestamp":"1780178954669", "event_type":"price_change"}
{"market":"0x7976b8dbacf9077eb1453a62bcefd6ab2df199acd28aad276ff0d920d6992892", "price_changes":[{"asset_id":"4394372887385518214471608448209527405727552777602031099972143344338178308080", "price":"0.17", "size":"27598.28", "side":"SELL", "hash":"161dedb87ca679410d030160d315a7bc0a897741", "best_bid":"0.167", "best_ask":"0.168"}, {"asset_id":"112680630004798425069810935278212000865453267506345451433803052322987302357330", "price":"0.83", "size":"27598.28", "side":"BUY", "hash":"9e3a8302675e7d32219ec9346f167c1b1231f4d1", "best_bid":"0.832", "best_ask":"0.833"}], "timestamp":"1780178954670", "event_type":"price_change"}
{"market":"0x7976b8dbacf9077eb1453a62bcefd6ab2df199acd28aad276ff0d920d6992892", "price_changes":[{"asset_id":"4394372887385518214471608448209527405727552777602031099972143344338178308080", "price":"0.17", "size":"27652.43", "side":"SELL", "hash":"e8579aacc6be3217b1173da88968fff91b6c56cc", "best_bid":"0.167", "best_ask":"0.168"}, {"asset_id":"112680630004798425069810935278212000865453267506345451433803052322987302357330", "price":"0.83", "size":"27652.43", "side":"BUY", "hash":"5c40fcc0c697ca7485678c36c3185f99751f0fa5", "best_bid":"0.832", "best_ask":"0.833"}], "timestamp":"1780178954798", "event_type":"price_change"}
{"market":"0x30d55d8124ee1e12dabe89201badc45669b81dff69e4ce44d961f32878ec178a", "price_changes":[{"asset_id":"27576533317283401577758999384642760405921738493660383550832555714312627457443", "price":"0.092", "size":"78431.18", "side":"SELL", "hash":"5d4aae845eaad44b8e2f86ae7d3bb8477729b3d4", "best_bid":"0.089", "best_ask":"0.09"}, {"asset_id":"52986718774908357330412653486471347449818893503063830313445318937088822580057", "price":"0.908", "size":"78431.18", "side":"BUY", "hash":"2ff01829115003d345aca9f1fc3bbf45ee58216f", "best_bid":"0.91", "best_ask":"0.911"}], "timestamp":"1780178954816", "event_type":"price_change"}
{"market":"0x0c4cd2055d6ea89354ffddc55d6dbcef9355748112ea952fc925f3db6a5c457f", "price_changes":[{"asset_id":"18812649149814341758733697580460697418474693998558159483117100240528657629879", "price":"0.088", "size":"15069.46", "side":"SELL", "hash":"2ed39ba5bdd24c03c87017e2a73b3d74e4960717", "best_bid":"0.085", "best_ask":"0.086"}, {"asset_id":"115428153746996892211798999366308897078723117634059783423375188043903703749062", "price":"0.912", "size":"15069.46", "side":"BUY", "hash":"343a6e941b532a9eb1899815fc1ef83ee3b29480", "best_bid":"0.914", "best_ask":"0.915"}], "timestamp":"1780178955983", "event_type":"price_change"}
{"market":"0x375409bc5eeeff961e82b479caeccc20f33d15738e5bce1186d628aa3d9dfb1f", "price_changes":[{"asset_id":"115556263888245616435851357148058235707004733438163639091106356867234218207169", "price":"0.115", "size":"12019.15", "side":"SELL", "hash":"5cca95860a821044af7118513b1048642a593032", "best_bid":"0.112", "best_ask":"0.113"}, {"asset_id":"77121637225348873006259930776623502125079210522997384841464684944292365296940", "price":"0.885", "size":"12019.15", "side":"BUY", "hash":"d217c4c05790c3f1ead44e01cbe3e605ccf45430", "best_bid":"0.887", "best_ask":"0.888"}], "timestamp":"1780178955988", "event_type":"price_change"}
{"market":"0x1595b4818eeb1ea1e0bec5de6f057218e557feee9b405a0e930d290384fa1d16", "price_changes":[{"asset_id":"81739002353269632749850710185641576213562066971072676369728657545679630163887", "price":"0.053", "size":"3311.26", "side":"SELL", "hash":"9621cd66cf7c7ddafcd95c118d2dc8d4191a117b", "best_bid":"0.051", "best_ask":"0.052"}, {"asset_id":"45484070731786948288366703334552551439356529561722304542938873238430842810537", "price":"0.947", "size":"3311.26", "side":"BUY", "hash":"0ef3a2a5884ef576aa851014e429b2777c6322f2", "best_bid":"0.948", "best_ask":"0.949"}], "timestamp":"1780178956002", "event_type":"price_change"}
{"market":"0x0c4cd2055d6ea89354ffddc55d6dbcef9355748112ea952fc925f3db6a5c457f", "price_changes":[{"asset_id":"18812649149814341758733697580460697418474693998558159483117100240528657629879", "price":"0.088", "size":"15129.46", "side":"SELL", "hash":"7cb67c85441a31ac451cfbe4f2486380d8767f6c", "best_bid":"0.085", "best_ask":"0.086"}, {"asset_id":"115428153746996892211798999366308897078723117634059783423375188043903703749062", "price":"0.912", "size":"15129.46", "side":"BUY", "hash":"c9089a1ea5b2a5f309173194decbc16c0b2d309c", "best_bid":"0.914", "best_ask":"0.915"}], "timestamp":"1780178956080", "event_type":"price_change"}
{"market":"0x1595b4818eeb1ea1e0bec5de6f057218e557feee9b405a0e930d290384fa1d16", "price_changes":[{"asset_id":"81739002353269632749850710185641576213562066971072676369728657545679630163887", "price":"0.053", "size":"3371.26", "side":"SELL", "hash":"f389ed149e192685924ed054f98494c137c2595d", "best_bid":"0.051", "best_ask":"0.052"}, {"asset_id":"45484070731786948288366703334552551439356529561722304542938873238430842810537", "price":"0.947", "size":"3371.26", "side":"BUY", "hash":"086fe2b8375d6c7bf69b8c3307dadf3b0d4edc37", "best_bid":"0.948", "best_ask":"0.949"}], "timestamp":"1780178956115", "event_type":"price_change"}
{"market":"0x375409bc5eeeff961e82b479caeccc20f33d15738e5bce1186d628aa3d9dfb1f", "price_changes":[{"asset_id":"115556263888245616435851357148058235707004733438163639091106356867234218207169", "price":"0.115", "size":"12079.15", "side":"SELL", "hash":"4a893c78c566bed5ff51b6b490e401154b59bb69", "best_bid":"0.112", "best_ask":"0.113"}, {"asset_id":"77121637225348873006259930776623502125079210522997384841464684944292365296940", "price":"0.885", "size":"12079.15", "side":"BUY", "hash":"5a367684529f4df61e9b09f81330d3a36736dab1", "best_bid":"0.887", "best_ask":"0.888"}], "timestamp":"1780178956118", "event_type":"price_change"}
{"market":"0x4f3421fb2daf5cca7430ed8d8132463963081572d75434393a1808fdb8829fe8", "price_changes":[{"asset_id":"31940783580344558651011323787577288681658737625185216525249046282994042503801", "price":"0.901", "size":"7758", "side":"SELL", "hash":"29cb42501d54288b8024600bc66d43fee0b3b3cb", "best_bid":"0.899", "best_ask":"0.9"}, {"asset_id":"45415751658241142530386585138386640503488308219341470020075667342738719018629", "price":"0.099", "size":"7758", "side":"BUY", "hash":"9d3520e3379c918ae0ff9b770f42c1beb0dc8f1d", "best_bid":"0.1", "best_ask":"0.101"}], "timestamp":"1780178956312", "event_type":"price_change"}
{"market":"0x4f3421fb2daf5cca7430ed8d8132463963081572d75434393a1808fdb8829fe8", "price_changes":[{"asset_id":"31940783580344558651011323787577288681658737625185216525249046282994042503801", "price":"0.9", "size":"9239.67", "side":"SELL", "hash":"a82d4a350dffa821e27e2d7f57d4d2dddeb6fa39", "best_bid":"0.899", "best_ask":"0.9"}, {"asset_id":"45415751658241142530386585138386640503488308219341470020075667342738719018629", "price":"0.1", "size":"9239.67", "side":"BUY", "hash":"0575ef4fb0e6186ffc2905fb44e51efef4258ff6", "best_bid":"0.1", "best_ask":"0.101"}], "timestamp":"1780178956441", "event_type":"price_change"}
{"id":"2397730", "question":"Prostejov: Completed Match: Tristan Boyer vs Filip Jianu", "market":"0x5b1f77b9a961df086e2a9efb1eb1a2fa67963de95ee39b3c7dd2099d624cdb30", "slug":"atp-boyer-jianu-2026-06-01-completed-match", "description":"This market refers to the tennis match between Tristan Boyer and Filip Jianu in the Prostejov, originally scheduled for June 1, 2026 at 4:00AM ET. This market will resolve to \"Yes\" if all games and sets required to determine a match winner under governing body or event organizer rules are played to completion through normal play. Otherwise, if the match is not completed for any reason, it will resolve to \"No.\" If a forfeit of any kind occurs, including but not limited to a walkover or retirement, this market will resolve \"No.\" If the match is canceled (not played at all), ends in a tie, or is delayed beyond 7 days from the scheduled date without a winner determined, this market will resolve to \"No.\" The primary resolution source for this market is the official statistics of the event as recognized by the governing body or event organizers. However, if the governing body or event organizers have not published final match statistics within 2 hours after the event's conclusion, a consensus of credible reporting may be used instead.", "assets_ids":["63404145774551793647620091615595762650524019086682968110500204930976985430553", "43853742015525579137027029794988466882496072436229942038560911550779755772750"], "outcomes":["Yes", "No"], "event_message":{"id":"542645", "ticker":"atp-boyer-jianu-2026-06-01", "slug":"atp-boyer-jianu-2026-06-01", "title":"Prostejov: Tristan Boyer vs Filip Jianu", "description":"This market refers to the tennis match between Tristan Boyer and Filip Jianu in the Prostejov, originally scheduled for June 1, 2026 at 4:00AM ET.\n\nThis market will resolve to 'Tristan Boyer' if Tristan Boyer advances against Filip Jianu.\n\nThis market will resolve to 'Filip Jianu' if Filip Jianu advances against Tristan Boyer.\n\nIf the match is canceled (not played at all), ends in a tie, or is delayed beyond 7 days from the scheduled date without a winner determined, this market will resolve to 50-50.\n\nIf the match begins but is not completed, and one player advances due to the opponent's retirement, default, or disqualification, this market will resolve to the player who advances.\n\nIf the match ends in a walkover (player withdraws before the start and the other advances automatically), this market will resolve to 50-50.\n\nThe primary resolution source will be official information from the ATP Tour. A consensus of credible reporting may also be used."}, "timestamp":"1780178957412", "event_type":"new_market", "tags":[], "condition_id":"0x5b1f77b9a961df086e2a9efb1eb1a2fa67963de95ee39b3c7dd2099d624cdb30", "active":false, "clob_token_ids":["63404145774551793647620091615595762650524019086682968110500204930976985430553", "43853742015525579137027029794988466882496072436229942038560911550779755772750"], "sports_market_type":"tennis_completed_match", "line":"", "game_start_time":"2026-06-01 08:00:00+00", "order_price_min_tick_size":"0.01", "group_item_title":"Completed Match", "taker_base_fee":"1000", "fees_enabled":true, "fee_schedule":{"exponent":"1", "rate":"0.03", "taker_only":true, "rebate_rate":"0.25"}}
{"id":"2397888", "question":"Dogecoin Up or Down - May 31, 6:00PM-6:15PM ET", "market":"0x99f364b814b3b12038c86daf3058dbfbc737d1509d3f983213d60cbe3f77de27", "slug":"doge-updown-15m-1780264800", "description":"This market will resolve to \"Up\" if the Dogecoin price at the end of the time range specified in the title is greater than or equal to the price at the beginning of that range. Otherwise, it will resolve to \"Down\".\nThe resolution source for this market is information from Chainlink, specifically the DOGE/USD data stream available at https://data.chain.link/streams/doge-usd.\nPlease note that this market is about the price according to Chainlink data stream DOGE/USD, not according to other sources or spot markets.", "assets_ids":["114590103644619646785634197448960664626947272178195211528594976129559692824466", "14689022951549041335865876135992883998912579007688332112914093388545292784190"], "outcomes":["Up", "Down"], "event_message":{"id":"542709", "ticker":"doge-updown-15m-1780264800", "slug":"doge-updown-15m-1780264800", "title":"Dogecoin Up or Down - May 31, 6:00PM-6:15PM ET", "description":"This market will resolve to \"Up\" if the Dogecoin price at the end of the time range specified in the title is greater than or equal to the price at the beginning of that range. Otherwise, it will resolve to \"Down\".\nThe resolution source for this market is information from Chainlink, specifically the DOGE/USD data stream available at https://data.chain.link/streams/doge-usd.\nPlease note that this market is about the price according to Chainlink data stream DOGE/USD, not according to other sources or spot markets."}, "timestamp":"1780178960466", "event_type":"new_market", "tags":[], "condition_id":"0x99f364b814b3b12038c86daf3058dbfbc737d1509d3f983213d60cbe3f77de27", "active":false, "clob_token_ids":["114590103644619646785634197448960664626947272178195211528594976129559692824466", "14689022951549041335865876135992883998912579007688332112914093388545292784190"], "sports_market_type":"", "line":"", "game_start_time":"", "order_price_min_tick_size":"0.01", "group_item_title":"", "taker_base_fee":"1000", "fees_enabled":true, "fee_schedule":{"exponent":"1", "rate":"0.07", "taker_only":true, "rebate_rate":"0.2"}}
PONG
{"market":"0x1595b4818eeb1ea1e0bec5de6f057218e557feee9b405a0e930d290384fa1d16", "price_changes":[{"asset_id":"81739002353269632749850710185641576213562066971072676369728657545679630163887", "price":"0.053", "size":"3291.26", "side":"SELL", "hash":"ab2245588744ba163fe41d2f98195e6ecc630866", "best_bid":"0.051", "best_ask":"0.052"}, {"asset_id":"45484070731786948288366703334552551439356529561722304542938873238430842810537", "price":"0.947", "size":"3291.26", "side":"BUY", "hash":"282a09cea7515b26d223daa1163acdf731996171", "best_bid":"0.948", "best_ask":"0.949"}], "timestamp":"1780178965008", "event_type":"price_change"}
{"market":"0x0c4cd2055d6ea89354ffddc55d6dbcef9355748112ea952fc925f3db6a5c457f", "price_changes":[{"asset_id":"18812649149814341758733697580460697418474693998558159483117100240528657629879", "price":"0.088", "size":"15049.46", "side":"SELL", "hash":"93fbe6fd018d5e8fa1878ea15f19c5a1bd7178f4", "best_bid":"0.085", "best_ask":"0.086"}, {"asset_id":"115428153746996892211798999366308897078723117634059783423375188043903703749062", "price":"0.912", "size":"15049.46", "side":"BUY", "hash":"7163544608e134dadb11654e6919f306dc976ef2", "best_bid":"0.914", "best_ask":"0.915"}], "timestamp":"1780178965034", "event_type":"price_change"}
{"market":"0x7976b8dbacf9077eb1453a62bcefd6ab2df199acd28aad276ff0d920d6992892", "price_changes":[{"asset_id":"4394372887385518214471608448209527405727552777602031099972143344338178308080", "price":"0.17", "size":"27626.88", "side":"SELL", "hash":"aea4e4b599d325d1cbb041acbcf701eb485b83d2", "best_bid":"0.167", "best_ask":"0.168"}, {"asset_id":"112680630004798425069810935278212000865453267506345451433803052322987302357330", "price":"0.83", "size":"27626.88", "side":"BUY", "hash":"8581afab21e100bb64846692f907fa036cad323b", "best_bid":"0.832", "best_ask":"0.833"}], "timestamp":"1780178965077", "event_type":"price_change"}
{"market":"0x30d55d8124ee1e12dabe89201badc45669b81dff69e4ce44d961f32878ec178a", "price_changes":[{"asset_id":"27576533317283401577758999384642760405921738493660383550832555714312627457443", "price":"0.092", "size":"78375.52", "side":"SELL", "hash":"be5eb483206043f2166d2ecb4ab2cf00858fb048", "best_bid":"0.089", "best_ask":"0.09"}, {"asset_id":"52986718774908357330412653486471347449818893503063830313445318937088822580057", "price":"0.908", "size":"78375.52", "side":"BUY", "hash":"3288970b3183bd4e5a1b0cfd8295bc38f51c34fd", "best_bid":"0.91", "best_ask":"0.911"}], "timestamp":"1780178965180", "event_type":"price_change"}
{"id":"2397652", "question":"Centurion 2: Completed Match: Harold Mayot vs Yusuke Takahashi", "market":"0xf54081c0d08d2ac64d3e989e20a8e6f91b50bc87ec2f623e570fad0f272d4123", "slug":"atp-mayot-takahas-2026-06-01-completed-match", "description":"This market refers to the tennis match between Harold Mayot and Yusuke Takahashi in the Centurion 2, originally scheduled for June 1, 2026 at 4:00AM ET. This market will resolve to \"Yes\" if all games and sets required to determine a match winner under governing body or event organizer rules are played to completion through normal play. Otherwise, if the match is not completed for any reason, it will resolve to \"No.\" If a forfeit of any kind occurs, including but not limited to a walkover or retirement, this market will resolve \"No.\" If the match is canceled (not played at all), ends in a tie, or is delayed beyond 7 days from the scheduled date without a winner determined, this market will resolve to \"No.\" The primary resolution source for this market is the official statistics of the event as recognized by the governing body or event organizers. However, if the governing body or event organizers have not published final match statistics within 2 hours after the event's conclusion, a consensus of credible reporting may be used instead.", "assets_ids":["65276927944849082018102779204107934940181409491184151401133998609756539389485", "65532387777429734568113497203664092526649909726423920938785392385119179972868"], "outcomes":["Yes", "No"], "event_message":{"id":"542618", "ticker":"atp-mayot-takahas-2026-06-01", "slug":"atp-mayot-takahas-2026-06-01", "title":"Centurion 2: Harold Mayot vs Yusuke Takahashi", "description":"This market refers to the tennis match between Harold Mayot and Yusuke Takahashi in the Centurion 2, originally scheduled for June 1, 2026 at 4:00AM ET.\n\nThis market will resolve to 'Harold Mayot' if Harold Mayot advances against Yusuke Takahashi.\n\nThis market will resolve to 'Yusuke Takahashi' if Yusuke Takahashi advances against Harold Mayot.\n\nIf the match is canceled (not played at all), ends in a tie, or is delayed beyond 7 days from the scheduled date without a winner determined, this market will resolve to 50-50.\n\nIf the match begins but is not completed, and one player advances due to the opponent's retirement, default, or disqualification, this market will resolve to the player who advances.\n\nIf the match ends in a walkover (player withdraws before the start and the other advances automatically), this market will resolve to 50-50.\n\nThe primary resolution source will be official information from the ATP Tour. A consensus of credible reporting may also be used."}, "timestamp":"1780178965359", "event_type":"new_market", "tags":[], "condition_id":"0xf54081c0d08d2ac64d3e989e20a8e6f91b50bc87ec2f623e570fad0f272d4123", "active":false, "clob_token_ids":["65276927944849082018102779204107934940181409491184151401133998609756539389485", "65532387777429734568113497203664092526649909726423920938785392385119179972868"], "sports_market_type":"tennis_completed_match", "line":"", "game_start_time":"2026-06-01 08:00:00+00", "order_price_min_tick_size":"0.01", "group_item_title":"Completed Match", "taker_base_fee":"1000", "fees_enabled":true, "fee_schedule":{"exponent":"1", "rate":"0.03", "taker_only":true, "rebate_rate":"0.25"}}
{"id":"2397685", "question":"Centurion 2: Robert Strombachs vs Millen Hurrion", "market":"0x46630935c993558b27f9fdd22279943483f96bdbd7640b125cc8d47de76717c9", "slug":"atp-stromba-hurrion-2026-06-01", "description":"This market refers to the tennis match between Robert Strombachs and Millen Hurrion in the Centurion 2, originally scheduled for June 1, 2026 at 4:00AM ET.\n\nThis market will resolve to 'Robert Strombachs' if Robert Strombachs advances against Millen Hurrion.\n\nThis market will resolve to 'Millen Hurrion' if Millen Hurrion advances against Robert Strombachs.\n\nIf the match is canceled (not played at all), ends in a tie, or is delayed beyond 7 days from the scheduled date without a winner determined, this market will resolve to 50-50.\n\nIf the match begins but is not completed, and one player advances due to the opponent's retirement, default, or disqualification, this market will resolve to the player who advances.\n\nIf the match ends in a walkover (player withdraws before the start and the other advances automatically), this market will resolve to 50-50.\n\nThe primary resolution source will be official information from the ATP Tour. A consensus of credible reporting may also be used.", "assets_ids":["59726957746783075414851515171794029270506265089487837919762368246799262233234", "9993496874224387150094969763248716271596253072707770055255795564860824627589"], "outcomes":["Robert Strombachs", "Millen Hurrion"], "event_message":{"id":"542630", "ticker":"atp-stromba-hurrion-2026-06-01", "slug":"atp-stromba-hurrion-2026-06-01", "title":"Centurion 2: Robert Strombachs vs Millen Hurrion", "description":"This market refers to the tennis match between Robert Strombachs and Millen Hurrion in the Centurion 2, originally scheduled for June 1, 2026 at 4:00AM ET.\n\nThis market will resolve to 'Robert Strombachs' if Robert Strombachs advances against Millen Hurrion.\n\nThis market will resolve to 'Millen Hurrion' if Millen Hurrion advances against Robert Strombachs.\n\nIf the match is canceled (not played at all), ends in a tie, or is delayed beyond 7 days from the scheduled date without a winner determined, this market will resolve to 50-50.\n\nIf the match begins but is not completed, and one player advances due to the opponent's retirement, default, or disqualification, this market will resolve to the player who advances.\n\nIf the match ends in a walkover (player withdraws before the start and the other advances automatically), this market will resolve to 50-50.\n\nThe primary resolution source will be official information from the ATP Tour. A consensus of credible reporting may also be used."}, "timestamp":"1780178965370", "event_type":"new_market", "tags":[], "condition_id":"0x46630935c993558b27f9fdd22279943483f96bdbd7640b125cc8d47de76717c9", "active":false, "clob_token_ids":["59726957746783075414851515171794029270506265089487837919762368246799262233234", "9993496874224387150094969763248716271596253072707770055255795564860824627589"], "sports_market_type":"moneyline", "line":"", "game_start_time":"2026-06-01 08:00:00+00", "order_price_min_tick_size":"0.01", "group_item_title":"", "taker_base_fee":"1000", "fees_enabled":true, "fee_schedule":{"exponent":"1", "rate":"0.03", "taker_only":true, "rebate_rate":"0.25"}}
{"market":"0x30d55d8124ee1e12dabe89201badc45669b81dff69e4ce44d961f32878ec178a", "price_changes":[{"asset_id":"27576533317283401577758999384642760405921738493660383550832555714312627457443", "price":"0.092", "size":"78431.18", "side":"SELL", "hash":"172f5e85a7b0e43ef41e0dfd5d98de4a1139a066", "best_bid":"0.089", "best_ask":"0.09"}, {"asset_id":"52986718774908357330412653486471347449818893503063830313445318937088822580057", "price":"0.908", "size":"78431.18", "side":"BUY", "hash":"4f33f287cf8d1455882d3c6725b8c3674f0c6570", "best_bid":"0.91", "best_ask":"0.911"}], "timestamp":"1780178965409", "event_type":"price_change"}
{"market":"0x1595b4818eeb1ea1e0bec5de6f057218e557feee9b405a0e930d290384fa1d16", "price_changes":[{"asset_id":"81739002353269632749850710185641576213562066971072676369728657545679630163887", "price":"0.053", "size":"3371.26", "side":"SELL", "hash":"09807ad5b4dbd89ddf85a9222740480dc1bcd1bc", "best_bid":"0.051", "best_ask":"0.052"}, {"asset_id":"45484070731786948288366703334552551439356529561722304542938873238430842810537", "price":"0.947", "size":"3371.26", "side":"BUY", "hash":"5759b6a80d0aefad25f264cec43cecc9a7c94fdb", "best_bid":"0.948", "best_ask":"0.949"}], "timestamp":"1780178965409", "event_type":"price_change"}
{"market":"0x0c4cd2055d6ea89354ffddc55d6dbcef9355748112ea952fc925f3db6a5c457f", "price_changes":[{"asset_id":"18812649149814341758733697580460697418474693998558159483117100240528657629879", "price":"0.088", "size":"15129.46", "side":"SELL", "hash":"765d68cc46440990b9ace6b70d2206f310984ede", "best_bid":"0.085", "best_ask":"0.086"}, {"asset_id":"115428153746996892211798999366308897078723117634059783423375188043903703749062", "price":"0.912", "size":"15129.46", "side":"BUY", "hash":"6fab2a0a15d467ffd736e42901bd1a7e435e4abc", "best_bid":"0.914", "best_ask":"0.915"}], "timestamp":"1780178965422", "event_type":"price_change"}
{"market":"0x7976b8dbacf9077eb1453a62bcefd6ab2df199acd28aad276ff0d920d6992892", "price_changes":[{"asset_id":"4394372887385518214471608448209527405727552777602031099972143344338178308080", "price":"0.17", "size":"27652.43", "side":"SELL", "hash":"72b178d38003ed368d2953ab04971315fe47a8d1", "best_bid":"0.167", "best_ask":"0.168"}, {"asset_id":"112680630004798425069810935278212000865453267506345451433803052322987302357330", "price":"0.83", "size":"27652.43", "side":"BUY", "hash":"1640b7dcaf2398bd54d94fe8ee5bef4453cd71a3", "best_bid":"0.832", "best_ask":"0.833"}], "timestamp":"1780178965432", "event_type":"price_change"}
{"id":"2397824", "question":"Perugia: Completed Match: Gonzalo Bueno vs Dusan Lajovic", "market":"0xc353bdb781b68761d7092109d601dd7f9e0cd0598c0f16b7654b9d17414703da", "slug":"atp-bueno-lajovic-2026-06-01-completed-match", "description":"This market refers to the tennis match between Gonzalo Bueno and Dusan Lajovic in the Perugia, originally scheduled for June 1, 2026 at 4:00AM ET. This market will resolve to \"Yes\" if all games and sets required to determine a match winner under governing body or event organizer rules are played to completion through normal play. Otherwise, if the match is not completed for any reason, it will resolve to \"No.\" If a forfeit of any kind occurs, including but not limited to a walkover or retirement, this market will resolve \"No.\" If the match is canceled (not played at all), ends in a tie, or is delayed beyond 7 days from the scheduled date without a winner determined, this market will resolve to \"No.\" The primary resolution source for this market is the official statistics of the event as recognized by the governing body or event organizers. However, if the governing body or event organizers have not published final match statistics within 2 hours after the event's conclusion, a consensus of credible reporting may be used instead.", "assets_ids":["9035761863577337753320420818241950517759196812281541623820870950048183041694", "100369789352616398873023922323964205330143708550451326858280532552793300079618"], "outcomes":["Yes", "No"], "event_message":{"id":"542677", "ticker":"atp-bueno-lajovic-2026-06-01", "slug":"atp-bueno-lajovic-2026-06-01", "title":"Perugia: Gonzalo Bueno vs Dusan Lajovic", "description":"This market refers to the tennis match between Gonzalo Bueno and Dusan Lajovic in the Perugia, originally scheduled for June 1, 2026 at 4:00AM ET.\n\nThis market will resolve to 'Gonzalo Bueno' if Gonzalo Bueno advances against Dusan Lajovic.\n\nThis market will resolve to 'Dusan Lajovic' if Dusan Lajovic advances against Gonzalo Bueno.\n\nIf the match is canceled (not played at all), ends in a tie, or is delayed beyond 7 days from the scheduled date without a winner determined, this market will resolve to 50-50.\n\nIf the match begins but is not completed, and one player advances due to the opponent's retirement, default, or disqualification, this market will resolve to the player who advances.\n\nIf the match ends in a walkover (player withdraws before the start and the other advances automatically), this market will resolve to 50-50.\n\nThe primary resolution source will be official information from the ATP Tour. A consensus of credible reporting may also be used."}, "timestamp":"1780178967186", "event_type":"new_market", "tags":[], "condition_id":"0xc353bdb781b68761d7092109d601dd7f9e0cd0598c0f16b7654b9d17414703da", "active":false, "clob_token_ids":["9035761863577337753320420818241950517759196812281541623820870950048183041694", "100369789352616398873023922323964205330143708550451326858280532552793300079618"], "sports_market_type":"tennis_completed_match", "line":"", "game_start_time":"2026-06-01 08:00:00+00", "order_price_min_tick_size":"0.01", "group_item_title":"Completed Match", "taker_base_fee":"1000", "fees_enabled":true, "fee_schedule":{"exponent":"1", "rate":"0.03", "taker_only":true, "rebate_rate":"0.25"}}
{"market":"0x9b6fef249040fd17e9c107955b37ac2c3e923509b6b0ff01cc463a331ddeb894", "price_changes":[{"asset_id":"108233603819467706476318984012158651931658302669301887462181073562758483842092", "price":"0.166", "size":"24926.68", "side":"SELL", "hash":"dd10719a27c357ece87395228e20a150c3211401", "best_bid":"0.163", "best_ask":"0.164"}, {"asset_id":"32270411694523539495262303868629477861017829722282576458031815333486368239544", "price":"0.834", "size":"24926.68", "side":"BUY", "hash":"8422e7e65fbf278ee4c2ab0c804f3b545a4419b4", "best_bid":"0.836", "best_ask":"0.837"}], "timestamp":"1780178967377", "event_type":"price_change"}
{"market":"0x375409bc5eeeff961e82b479caeccc20f33d15738e5bce1186d628aa3d9dfb1f", "price_changes":[{"asset_id":"115556263888245616435851357148058235707004733438163639091106356867234218207169", "price":"0.115", "size":"11999.15", "side":"SELL", "hash":"26c162cc27ceee4b7a3be56c54807583114f805e", "best_bid":"0.112", "best_ask":"0.113"}, {"asset_id":"77121637225348873006259930776623502125079210522997384841464684944292365296940", "price":"0.885", "size":"11999.15", "side":"BUY", "hash":"bf0824e554cd0b78edc90463601feaa26547e7b3", "best_bid":"0.887", "best_ask":"0.888"}], "timestamp":"1780178967443", "event_type":"price_change"}
{"id":"2397642", "question":"ITF Women Tsaghkadzor: Completed Match: Kristina Kroitor vs Anna Bazderova", "market":"0x2dbf298c2d67bdd8144785628439df3da4d8a99828a4eda5e539169b16aaa481", "slug":"itf-kroitor-bazdero-2026-05-31-completed-match", "description":"This market refers to the tennis match between Kristina Kroitor and Anna Bazderova in the ITF Women Tsaghkadzor, originally scheduled for May 31, 2026 at 2:30AM ET. This market will resolve to \"Yes\" if all games and sets required to determine a match winner under governing body or event organizer rules are played to completion through normal play. Otherwise, if the match is not completed for any reason, it will resolve to \"No.\" If a forfeit of any kind occurs, including but not limited to a walkover or retirement, this market will resolve \"No.\" If the match is canceled (not played at all), ends in a tie, or is delayed beyond 7 days from the scheduled date without a winner determined, this market will resolve to \"No.\" The primary resolution source for this market is the official statistics of the event as recognized by the governing body or event organizers. However, if the governing body or event organizers have not published final match statistics within 2 hours after the event's conclusion, a consensus of credible reporting may be used instead.", "assets_ids":["114573902804332858279560509147767843147578107271602593369924050590466034532454", "50307293910670591044769918710243781347309285191555941600933785666047953479285"], "outcomes":["Yes", "No"], "event_message":{"id":"542615", "ticker":"itf-kroitor-bazdero-2026-05-31", "slug":"itf-kroitor-bazdero-2026-05-31", "title":"ITF Tsaghkadzor: Kristina Kroitor vs Anna Bazderova", "description":"This market refers to the tennis match between Kristina Kroitor and Anna Bazderova in the ITF Women Tsaghkadzor, originally scheduled for May 31, 2026 at 2:30AM ET.\n\nThis market will resolve to 'Kristina Kroitor' if Kristina Kroitor advances against Anna Bazderova.\n\nThis market will resolve to 'Anna Bazderova' if Anna Bazderova advances against Kristina Kroitor.\n\nIf the match is canceled (not played at all), ends in a tie, or is delayed beyond 7 days from the scheduled date without a winner determined, this market will resolve to 50-50.\n\nIf the match begins but is not completed, and one player advances due to the opponent's retirement, default, or disqualification, this market will resolve to the player who advances.\n\nIf the match ends in a walkover (player withdraws before the start and the other advances automatically), this market will resolve to 50-50.\n\nThe primary resolution source will be official information from the International Tennis Federation (ITF). A consensus of credible reporting may also be used."}, "timestamp":"1780178967456", "event_type":"new_market", "tags":[], "condition_id":"0x2dbf298c2d67bdd8144785628439df3da4d8a99828a4eda5e539169b16aaa481", "active":false, "clob_token_ids":["114573902804332858279560509147767843147578107271602593369924050590466034532454", "50307293910670591044769918710243781347309285191555941600933785666047953479285"], "sports_market_type":"tennis_completed_match", "line":"", "game_start_time":"2026-05-31 06:30:00+00", "order_price_min_tick_size":"0.01", "group_item_title":"Completed Match", "taker_base_fee":"1000", "fees_enabled":true, "fee_schedule":{"exponent":"1", "rate":"0.03", "taker_only":true, "rebate_rate":"0.25"}}
{"market":"0x9b6fef249040fd17e9c107955b37ac2c3e923509b6b0ff01cc463a331ddeb894", "price_changes":[{"asset_id":"108233603819467706476318984012158651931658302669301887462181073562758483842092", "price":"0.166", "size":"25006.68", "side":"SELL", "hash":"124495e7830dba465df951b174c7a4bfd18cbbb7", "best_bid":"0.163", "best_ask":"0.164"}, {"asset_id":"32270411694523539495262303868629477861017829722282576458031815333486368239544", "price":"0.834", "size":"25006.68", "side":"BUY", "hash":"5208cdc984b979a1e9fdcdfc79cefff95a5937bd", "best_bid":"0.836", "best_ask":"0.837"}], "timestamp":"1780178967482", "event_type":"price_change"}
{"market":"0x375409bc5eeeff961e82b479caeccc20f33d15738e5bce1186d628aa3d9dfb1f", "price_changes":[{"asset_id":"115556263888245616435851357148058235707004733438163639091106356867234218207169", "price":"0.115", "size":"12079.15", "side":"SELL", "hash":"e61d14e883161713fa3fbfe1b4bdf52958b728c0", "best_bid":"0.112", "best_ask":"0.113"}, {"asset_id":"77121637225348873006259930776623502125079210522997384841464684944292365296940", "price":"0.885", "size":"12079.15", "side":"BUY", "hash":"a6fe0dd62385d7b3e2c3e51c2f598955fc6e9529", "best_bid":"0.887", "best_ask":"0.888"}], "timestamp":"1780178967562", "event_type":"price_change"}
{"market":"0x4f3421fb2daf5cca7430ed8d8132463963081572d75434393a1808fdb8829fe8", "price_changes":[{"asset_id":"45415751658241142530386585138386640503488308219341470020075667342738719018629", "price":"0.103", "size":"18202.51", "side":"SELL", "hash":"a36c052341936fa355191427cd5d1aec93a04f7b", "best_bid":"0.1", "best_ask":"0.101"}, {"asset_id":"31940783580344558651011323787577288681658737625185216525249046282994042503801", "price":"0.897", "size":"18202.51", "side":"BUY", "hash":"9b65e1816c63b3f37897a1d46b84f9c0d9982195", "best_bid":"0.899", "best_ask":"0.9"}], "timestamp":"1780178967837", "event_type":"price_change"}
{"market":"0x4f3421fb2daf5cca7430ed8d8132463963081572d75434393a1808fdb8829fe8", "price_changes":[{"asset_id":"45415751658241142530386585138386640503488308219341470020075667342738719018629", "price":"0.103", "size":"18263.31", "side":"SELL", "hash":"9255db94a571cc9124db1f31adc08de946e5a09b", "best_bid":"0.1", "best_ask":"0.101"}, {"asset_id":"31940783580344558651011323787577288681658737625185216525249046282994042503801", "price":"0.897", "size":"18263.31", "side":"BUY", "hash":"44c9556f17eca0a7a970228874fef453c63b00f6", "best_bid":"0.899", "best_ask":"0.9"}], "timestamp":"1780178967919", "event_type":"price_change"}
{"id":"2397623", "question":"Kosice: Martin Krumich vs Kilian Feldbausch", "market":"0x7a0edd795195eb7e28b64011f97f3bc747dd37683014b21c9a47a9de4f283027", "slug":"atp-krumich-feldbau-2026-05-31", "description":"This market refers to the tennis match between Martin Krumich and Kilian Feldbausch in the Kosice, originally scheduled for May 31, 2026 at 8:00AM ET.\n\nThis market will resolve to 'Martin Krumich' if Martin Krumich advances against Kilian Feldbausch.\n\nThis market will resolve to 'Kilian Feldbausch' if Kilian Feldbausch advances against Martin Krumich.\n\nIf the match is canceled (not played at all), ends in a tie, or is delayed beyond 7 days from the scheduled date without a winner determined, this market will resolve to 50-50.\n\nIf the match begins but is not completed, and one player advances due to the opponent's retirement, default, or disqualification, this market will resolve to the player who advances.\n\nIf the match ends in a walkover (player withdraws before the start and the other advances automatically), this market will resolve to 50-50.\n\nThe primary resolution source will be official information from the ATP Tour. A consensus of credible reporting may also be used.", "assets_ids":["696851931808056175628058032446229396542136993935773920848151038544765696684", "88135117348929186730469592520419113712482899593805491726709786173388389366653"], "outcomes":["Martin Krumich", "Kilian Feldbausch"], "event_message":{"id":"542610", "ticker":"atp-krumich-feldbau-2026-05-31", "slug":"atp-krumich-feldbau-2026-05-31", "title":"Kosice: Martin Krumich vs Kilian Feldbausch", "description":"This market refers to the tennis match between Martin Krumich and Kilian Feldbausch in the Kosice, originally scheduled for May 31, 2026 at 8:00AM ET.\n\nThis market will resolve to 'Martin Krumich' if Martin Krumich advances against Kilian Feldbausch.\n\nThis market will resolve to 'Kilian Feldbausch' if Kilian Feldbausch advances against Martin Krumich.\n\nIf the match is canceled (not played at all), ends in a tie, or is delayed beyond 7 days from the scheduled date without a winner determined, this market will resolve to 50-50.\n\nIf the match begins but is not completed, and one player advances due to the opponent's retirement, default, or disqualification, this market will resolve to the player who advances.\n\nIf the match ends in a walkover (player withdraws before the start and the other advances automatically), this market will resolve to 50-50.\n\nThe primary resolution source will be official information from the ATP Tour. A consensus of credible reporting may also be used."}, "timestamp":"1780178970042", "event_type":"new_market", "tags":[], "condition_id":"0x7a0edd795195eb7e28b64011f97f3bc747dd37683014b21c9a47a9de4f283027", "active":false, "clob_token_ids":["696851931808056175628058032446229396542136993935773920848151038544765696684", "88135117348929186730469592520419113712482899593805491726709786173388389366653"], "sports_market_type":"moneyline", "line":"", "game_start_time":"2026-05-31 12:00:00+00", "order_price_min_tick_size":"0.01", "group_item_title":"", "taker_base_fee":"1000", "fees_enabled":true, "fee_schedule":{"exponent":"1", "rate":"0.03", "taker_only":true, "rebate_rate":"0.25"}}
PONG
{"market":"0x7876851632c295043c66536150a304cb785abdf712ba8489d298c6e6926be106", "price_changes":[{"asset_id":"97239126062673310243763617236644392945530356142765650402171508075574679292913", "price":"0.01", "size":"1265250", "side":"BUY", "hash":"de95e7fed848fc713da474386e91fd06f053a202", "best_bid":"0.01", "best_ask":"0.011"}, {"asset_id":"19291692040378529618917910599727571242305935029274321291612270922648172794670", "price":"0.99", "size":"1265250", "side":"SELL", "hash":"e794ad1d56c6b0ae81b2889c538cae091fb5142f", "best_bid":"0.989", "best_ask":"0.99"}], "timestamp":"1780178971274", "event_type":"price_change"}
{"market":"0x7876851632c295043c66536150a304cb785abdf712ba8489d298c6e6926be106", "price_changes":[{"asset_id":"97239126062673310243763617236644392945530356142765650402171508075574679292913", "price":"0.011", "size":"1818525.69", "side":"SELL", "hash":"5ec51ad56f9a418e9b6d508759b8b116934092a0", "best_bid":"0.01", "best_ask":"0.011"}, {"asset_id":"19291692040378529618917910599727571242305935029274321291612270922648172794670", "price":"0.989", "size":"1818525.69", "side":"BUY", "hash":"703a7f9684e85d04106458bfd04775b30e54917d", "best_bid":"0.989", "best_ask":"0.99"}], "timestamp":"1780178972007", "event_type":"price_change"}
{"id":"2397665", "question":"UFC Fight Night: Christian Rodriguez vs. Hyder Amil (Featherweight, Main Card)", "market":"0x29feee7a24fb5c99589b6271eeeadc6cb5bd85069af7496b16c255680eba77f7", "slug":"ufc-chr15-hyd-2026-06-20", "description":"This market will resolve to \"Christian Rodriguez\" if Christian Rodriguez is officially declared the winner of the fight against Hyder Amil at UFC Fight Night: Kape vs. Horiguchi, scheduled for June 20, 2026.\n\nIt will resolve to \"Hyder Amil\" if Hyder Amil is officially declared the winner.\n\nIf the fight is declared a draw or technical draw, ruled a No Contest, not scored, canceled, or postponed beyond July 4, 2026, this market will resolve \"50-50.\"\n\nThe resolution source for this market will be official information from the UFC.", "assets_ids":["70550194210229882366523940142722037298539276250565302851579524364382890585554", "61805553672876805574973818481700168931486164050773462729683431739335210244836"], "outcomes":["Christian Rodriguez", "Hyder Amil"], "event_message":{"id":"542624", "ticker":"ufc-chr15-hyd-2026-06-20", "slug":"ufc-chr15-hyd-2026-06-20", "title":"UFC Fight Night: Christian Rodriguez vs. Hyder Amil (Featherweight, Main Card)", "description":"This market will resolve to \"Christian Rodriguez\" if Christian Rodriguez is officially declared the winner of the fight against Hyder Amil at UFC Fight Night: Kape vs. Horiguchi, scheduled for June 20, 2026.\n\nIt will resolve to \"Hyder Amil\" if Hyder Amil is officially declared the winner.\n\nIf the fight is declared a draw or technical draw, ruled a No Contest, not scored, canceled, or postponed beyond July 4, 2026, this market will resolve \"50-50.\"\n\nThe resolution source for this market will be official information from the UFC."}, "timestamp":"1780178973179", "event_type":"new_market", "tags":[], "condition_id":"0x29feee7a24fb5c99589b6271eeeadc6cb5bd85069af7496b16c255680eba77f7", "active":false, "clob_token_ids":["70550194210229882366523940142722037298539276250565302851579524364382890585554", "61805553672876805574973818481700168931486164050773462729683431739335210244836"], "sports_market_type":"moneyline", "line":"", "game_start_time":"2026-06-20 17:00:00+00", "order_price_min_tick_size":"0.01", "group_item_title":"Christian Rodriguez vs. Hyder Amil", "taker_base_fee":"1000", "fees_enabled":true, "fee_schedule":{"exponent":"1", "rate":"0.03", "taker_only":true, "rebate_rate":"0.25"}}
{"id":"2397644", "question":"UFC Fight Night: Ion Cutelaba vs. Navajo Stirling (Light Heavyweight, Main Card)", "market":"0x8132b81ee6eeb1c9cb58ea57e4c6862b2a18689f6fb6f41b3d040fd356d693a9", "slug":"ufc-ion-nav-2026-06-20", "description":"This market will resolve to \"Ion Cutelaba\" if Ion Cutelaba is officially declared the winner of the fight against Navajo Stirling at UFC Fight Night: Kape vs. Horiguchi, scheduled for June 20, 2026.\n\nIt will resolve to \"Navajo Stirling\" if Navajo Stirling is officially declared the winner.\n\nIf the fight is declared a draw or technical draw, ruled a No Contest, not scored, canceled, or postponed beyond July 4, 2026, this market will resolve \"50-50.\"\n\nThe resolution source for this market will be official information from the UFC.", "assets_ids":["48058100918237234865887945713231211254199192169544497210686750923060920861275", "105301809248942601773034038494018609093660902214367518093947811142760465757430"], "outcomes":["Ion Cutelaba", "Navajo Stirling"], "event_message":{"id":"542616", "ticker":"ufc-ion-nav-2026-06-20", "slug":"ufc-ion-nav-2026-06-20", "title":"UFC Fight Night: Ion Cutelaba vs. Navajo Stirling (Light Heavyweight, Main Card)", "description":"This market will resolve to \"Ion Cutelaba\" if Ion Cutelaba is officially declared the winner of the fight against Navajo Stirling at UFC Fight Night: Kape vs. Horiguchi, scheduled for June 20, 2026.\n\nIt will resolve to \"Navajo Stirling\" if Navajo Stirling is officially declared the winner.\n\nIf the fight is declared a draw or technical draw, ruled a No Contest, not scored, canceled, or postponed beyond July 4, 2026, this market will resolve \"50-50.\"\n\nThe resolution source for this market will be official information from the UFC."}, "timestamp":"1780178975219", "event_type":"new_market", "tags":[], "condition_id":"0x8132b81ee6eeb1c9cb58ea57e4c6862b2a18689f6fb6f41b3d040fd356d693a9", "active":false, "clob_token_ids":["48058100918237234865887945713231211254199192169544497210686750923060920861275", "105301809248942601773034038494018609093660902214367518093947811142760465757430"], "sports_market_type":"moneyline", "line":"", "game_start_time":"2026-06-20 17:00:00+00", "order_price_min_tick_size":"0.01", "group_item_title":"Ion Cutelaba vs. Navajo Stirling", "taker_base_fee":"1000", "fees_enabled":true, "fee_schedule":{"exponent":"1", "rate":"0.03", "taker_only":true, "rebate_rate":"0.25"}}
{"market":"0x4f3421fb2daf5cca7430ed8d8132463963081572d75434393a1808fdb8829fe8", "price_changes":[{"asset_id":"45415751658241142530386585138386640503488308219341470020075667342738719018629", "price":"0.09", "size":"6647.21", "side":"BUY", "hash":"521112e87db456e3f1e226a26258bcff3307510b", "best_bid":"0.1", "best_ask":"0.101"}, {"asset_id":"31940783580344558651011323787577288681658737625185216525249046282994042503801", "price":"0.91", "size":"6647.21", "side":"SELL", "hash":"c4e9d5d8e245c9d5fe3a21b66ae42ab7ea3b10ea", "best_bid":"0.899", "best_ask":"0.9"}], "timestamp":"1780178976253", "event_type":"price_change"}
{"market":"0x9b6fef249040fd17e9c107955b37ac2c3e923509b6b0ff01cc463a331ddeb894", "price_changes":[{"asset_id":"32270411694523539495262303868629477861017829722282576458031815333486368239544", "price":"0.816", "size":"10939.83", "side":"BUY", "hash":"1b96b8105c8982f41a1b56cc82fb54dc8b37da33", "best_bid":"0.836", "best_ask":"0.837"}, {"asset_id":"108233603819467706476318984012158651931658302669301887462181073562758483842092", "price":"0.184", "size":"10939.83", "side":"SELL", "hash":"4c0379af9bb5c2c0062f322f5226e635cf877137", "best_bid":"0.163", "best_ask":"0.164"}], "timestamp":"1780178976371", "event_type":"price_change"}
{"market":"0x4f3421fb2daf5cca7430ed8d8132463963081572d75434393a1808fdb8829fe8", "price_changes":[{"asset_id":"45415751658241142530386585138386640503488308219341470020075667342738719018629", "price":"0.099", "size":"7768", "side":"BUY", "hash":"f62945faccd1921fc28b1ef339098363adf71f42", "best_bid":"0.1", "best_ask":"0.101"}, {"asset_id":"31940783580344558651011323787577288681658737625185216525249046282994042503801", "price":"0.901", "size":"7768", "side":"SELL", "hash":"c3cfa07f40889d6229b93d200cf3f5637024028f", "best_bid":"0.899", "best_ask":"0.9"}], "timestamp":"1780178976450", "event_type":"price_change"}
{"market":"0x7976b8dbacf9077eb1453a62bcefd6ab2df199acd28aad276ff0d920d6992892", "price_changes":[{"asset_id":"112680630004798425069810935278212000865453267506345451433803052322987302357330", "price":"0.813", "size":"30", "side":"BUY", "hash":"488315f59ac2e7ad62bffb575f9dc269d83d68ca", "best_bid":"0.832", "best_ask":"0.833"}, {"asset_id":"4394372887385518214471608448209527405727552777602031099972143344338178308080", "price":"0.187", "size":"30", "side":"SELL", "hash":"0c1bcbe47a3cab9da6d69d581e3355b45ae1df52", "best_bid":"0.167", "best_ask":"0.168"}], "timestamp":"1780178976807", "event_type":"price_change"}
{"id":"2397699", "question":"O/U 0.5 Rounds", "market":"0xdc9c88ffe664de495ab8580abce4fe31c5e8192b56fe97357413594331813fb1", "slug":"ufc-kev15-and26-2026-06-20-totals-0pt5", "description":"Each market will resolve to \"Over\" if the fight between Kevin Borjas and Andre Lima at UFC Fight Night: Kape vs. Horiguchi, scheduled for June 20, 2026, lasts beyond the listed round threshold.\n\nEach market will resolve to \"Under\" if the fight does not last beyond the listed round threshold.\n\nFor example:\n\n\"Over 0.5 Rounds\" will resolve \"Yes\" if the fight continues past the 2:30 mark of Round 1.\n\n\"Under 0.5 Rounds\" will resolve \"Yes\" if the fight ends before the 2:30 mark of Round 1.\n\nIf the fight ends exactly at the threshold, it will resolve \"50-50.\"\n\nIf the bout is not scored, postponed beyond July 4, 2026, or canceled, all options will resolve \"50-50.\"\n\nThe resolution source for this market will be official information from the UFC.", "assets_ids":["13230518870807318154733852200858619149968489448404487772256748045486646523061", "86374604471055459918521812309088133778981417511718021095942540574746502559348"], "outcomes":["Over", "Under"], "event_message":{"id":"542631", "ticker":"ufc-kev15-and26-2026-06-20", "slug":"ufc-kev15-and26-2026-06-20", "title":"UFC Fight Night: Kevin Borjas vs. Andre Lima (Flyweight, Main Card)", "description":"This market will resolve to \"Kevin Borjas\" if Kevin Borjas is officially declared the winner of the fight against Andre Lima at UFC Fight Night: Kape vs. Horiguchi, scheduled for June 20, 2026.\n\nIt will resolve to \"Andre Lima\" if Andre Lima is officially declared the winner.\n\nIf the fight is declared a draw or technical draw, ruled a No Contest, not scored, canceled, or postponed beyond July 4, 2026, this market will resolve \"50-50.\"\n\nThe resolution source for this market will be official information from the UFC."}, "timestamp":"1780178977022", "event_type":"new_market", "tags":[], "condition_id":"0xdc9c88ffe664de495ab8580abce4fe31c5e8192b56fe97357413594331813fb1", "active":false, "clob_token_ids":["13230518870807318154733852200858619149968489448404487772256748045486646523061", "86374604471055459918521812309088133778981417511718021095942540574746502559348"], "sports_market_type":"totals", "line":"0.5", "game_start_time":"2026-06-20 17:00:00+00", "order_price_min_tick_size":"0.01", "group_item_title":"O/U 0.5 Rounds", "taker_base_fee":"1000", "fees_enabled":true, "fee_schedule":{"exponent":"1", "rate":"0.03", "taker_only":true, "rebate_rate":"0.25"}}
{"market":"0x7876851632c295043c66536150a304cb785abdf712ba8489d298c6e6926be106", "price_changes":[{"asset_id":"19291692040378529618917910599727571242305935029274321291612270922648172794670", "price":"0.966", "size":"30", "side":"BUY", "hash":"28699322e4584e66c7e6d9409b60b3760b65e60f", "best_bid":"0.989", "best_ask":"0.99"}, {"asset_id":"97239126062673310243763617236644392945530356142765650402171508075574679292913", "price":"0.034", "size":"30", "side":"SELL", "hash":"f45560ae9845f8d7378a990370215d93e0d10824", "best_bid":"0.01", "best_ask":"0.011"}], "timestamp":"1780178977069", "event_type":"price_change"}
{"market":"0x4f3421fb2daf5cca7430ed8d8132463963081572d75434393a1808fdb8829fe8", "price_changes":[{"asset_id":"31940783580344558651011323787577288681658737625185216525249046282994042503801", "price":"0.878", "size":"30", "side":"BUY", "hash":"38d00039e8e3c4842218c1ca0b2ab254baf37f8a", "best_bid":"0.899", "best_ask":"0.9"}, {"asset_id":"45415751658241142530386585138386640503488308219341470020075667342738719018629", "price":"0.122", "size":"30", "side":"SELL", "hash":"4804153fbd6ecd6ae6fcd613e535a2518fd0737c", "best_bid":"0.1", "best_ask":"0.101"}], "timestamp":"1780178977097", "event_type":"price_change"}
{"market":"0x4f3421fb2daf5cca7430ed8d8132463963081572d75434393a1808fdb8829fe8", "price_changes":[{"asset_id":"31940783580344558651011323787577288681658737625185216525249046282994042503801", "price":"0.878", "size":"0", "side":"BUY", "hash":"b058d7dd7e1689d1295713fb65d1fe9ca0f404db", "best_bid":"0.899", "best_ask":"0.9"}, {"asset_id":"45415751658241142530386585138386640503488308219341470020075667342738719018629", "price":"0.122", "size":"0", "side":"SELL", "hash":"f192728bee0de069b9ae1186b15f1e84dff06b16", "best_bid":"0.1", "best_ask":"0.101"}], "timestamp":"1780178977123", "event_type":"price_change"}
{"market":"0x4f3421fb2daf5cca7430ed8d8132463963081572d75434393a1808fdb8829fe8", "price_changes":[{"asset_id":"31940783580344558651011323787577288681658737625185216525249046282994042503801", "price":"0.876", "size":"30", "side":"BUY", "hash":"acefeaef8362dcc46a34c04d9804efd5f4eba2c8", "best_bid":"0.899", "best_ask":"0.9"}, {"asset_id":"45415751658241142530386585138386640503488308219341470020075667342738719018629", "price":"0.124", "size":"30", "side":"SELL", "hash":"785e32ee13fdb627308f8d7f97d94664194fa105", "best_bid":"0.1", "best_ask":"0.101"}], "timestamp":"1780178977152", "event_type":"price_change"}
{"market":"0x7976b8dbacf9077eb1453a62bcefd6ab2df199acd28aad276ff0d920d6992892", "price_changes":[{"asset_id":"4394372887385518214471608448209527405727552777602031099972143344338178308080", "price":"0.184", "size":"0", "side":"SELL", "hash":"8da1ff443d77e4991f8aa832cd0304b4312450a3", "best_bid":"0.167", "best_ask":"0.168"}, {"asset_id":"112680630004798425069810935278212000865453267506345451433803052322987302357330", "price":"0.816", "size":"0", "side":"BUY", "hash":"34d79b0b8f8a9b9db1e118a7b68403d2fcacfe40", "best_bid":"0.832", "best_ask":"0.833"}], "timestamp":"1780178977418", "event_type":"price_change"}
{"market":"0x7976b8dbacf9077eb1453a62bcefd6ab2df199acd28aad276ff0d920d6992892", "price_changes":[{"asset_id":"4394372887385518214471608448209527405727552777602031099972143344338178308080", "price":"0.184", "size":"49.77", "side":"SELL", "hash":"6347461b644ef6b2843aa2a8a492fc919cbae324", "best_bid":"0.167", "best_ask":"0.168"}, {"asset_id":"112680630004798425069810935278212000865453267506345451433803052322987302357330", "price":"0.816", "size":"49.77", "side":"BUY", "hash":"ec8ec4c45b23e49c4556d2fe40a84674c7f3cf67", "best_bid":"0.832", "best_ask":"0.833"}], "timestamp":"1780178977778", "event_type":"price_change"}
{"market":"0x7876851632c295043c66536150a304cb785abdf712ba8489d298c6e6926be106", "price_changes":[{"asset_id":"97239126062673310243763617236644392945530356142765650402171508075574679292913", "price":"0.011", "size":"1818565.69", "side":"SELL", "hash":"796c87f9324dc9e63d1cd94cb6ab7cfb9df06bae", "best_bid":"0.01", "best_ask":"0.011"}, {"asset_id":"19291692040378529618917910599727571242305935029274321291612270922648172794670", "price":"0.989", "size":"1818565.69", "side":"BUY", "hash":"1d637a81721f86d7e8584a24a5a3d5ca82053887", "best_bid":"0.989", "best_ask":"0.99"}], "timestamp":"1780178978113", "event_type":"price_change"}
