{"market":"0x0c4cd2055d6ea89354ffddc55d6dbcef9355748112ea952fc925f3db6a5c457f", "asset_id":"115428153746996892211798999366308897078723117634059783423375188043903703749062", "bids":[{"price":"0.001", "size":"19311591.2"}, {"price":"0.002", "size":"55.07"}, {"price":"0.013", "size":"1716.7"}, {"price":"0.015", "size":"1904.95"}, {"price":"0.016", "size":"11.03"}, {"price":"0.036", "size":"36000"}, {"price":"0.04", "size":"333350"}, {"price":"0.041", "size":"300000"}, {"price":"0.042", "size":"800"}, {"price":"0.05", "size":"14660"}, {"price":"0.051", "size":"10.53"}, {"price":"0.09", "size":"19"}, {"price":"0.15", "size":"127.23"}, {"price":"0.22", "size":"128.36"}, {"price":"0.221", "size":"5.26"}, {"price":"0.228", "size":"131.57"}, {"price":"0.27", "size":"1904.95"}, {"price":"0.39", "size":"5"}, {"price":"0.4", "size":"34375"}, {"price":"0.401", "size":"10000"}, {"price":"0.402", "size":"1492"}, {"price":"0.45", "size":"22.5"}, {"price":"0.5", "size":"26767.96"}, {"price":"0.501", "size":"3000"}, {"price":"0.502", "size":"1077.83"}, {"price":"0.6", "size":"21522.45"}, {"price":"0.601", "size":"2000"}, {"price":"0.603", "size":"1164"}, {"price":"0.623", "size":"5"}, {"price":"0.64", "size":"1211"}, {"price":"0.65", "size":"27012.52"}, {"price":"0.66", "size":"46.4"}, {"price":"0.696", "size":"5000"}, {"price":"0.7", "size":"557.74"}, {"price":"0.73", "size":"6530"}, {"price":"0.74", "size":"100"}, {"price":"0.744", "size":"1000"}, {"price":"0.75", "size":"3383.18"}, {"price":"0.752", "size":"2906.99"}, {"price":"0.767", "size":"5"}, {"price":"0.774", "size":"1000"}, {"price":"0.775", "size":"400"}, {"price":"0.799", "size":"100"}, {"price":"0.8", "size":"12081.05"}, {"price":"0.801", "size":"2095.26"}, {"price":"0.804", "size":"1000"}, {"price":"0.81", "size":"100"}, {"price":"0.82", "size":"183.62"}, {"price":"0.824", "size":"1000"}, {"price":"0.83", "size":"2573"}, {"price":"0.834", "size":"1000"}, {"price":"0.838", "size":"168.53"}, {"price":"0.84", "size":"12150"}, {"price":"0.841", "size":"100"}, {"price":"0.843", "size":"100"}, {"price":"0.844", "size":"1100"}, {"price":"0.845", "size":"144"}, {"price":"0.85", "size":"245.57"}, {"price":"0.854", "size":"1000"}, {"price":"0.855", "size":"11634.31"}, {"price":"0.856", "size":"7"}, {"price":"0.86", "size":"716"}, {"price":"0.861", "size":"144283.19"}, {"price":"0.862", "size":"100"}, {"price":"0.864", "size":"1100"}, {"price":"0.867", "size":"438"}, {"price":"0.87", "size":"996"}, {"price":"0.871", "size":"209826.98"}, {"price":"0.874", "size":"1050"}, {"price":"0.875", "size":"1020.47"}, {"price":"0.876", "size":"75"}, {"price":"0.88", "size":"5096.64"}, {"price":"0.882", "size":"648.12"}, {"price":"0.884", "size":"11167.73"}, {"price":"0.886", "size":"230.12"}, {"price":"0.887", "size":"1162.79"}, {"price":"0.888", "size":"236.32"}, {"price":"0.889", "size":"1186.28"}, {"price":"0.89", "size":"6421.54"}, {"price":"0.891", "size":"5069.15"}, {"price":"0.892", "size":"52728.52"}, {"price":"0.893", "size":"232.7"}, {"price":"0.894", "size":"355.22"}, {"price":"0.895", "size":"5319.74"}, {"price":"0.896", "size":"52728.51"}, {"price":"0.897", "size":"114.3"}, {"price":"0.898", "size":"329.06"}, {"price":"0.899", "size":"27080.06"}, {"price":"0.9", "size":"35120.43"}, {"price":"0.901", "size":"4710.7"}, {"price":"0.902", "size":"84437.86"}, {"price":"0.903", "size":"1730.09"}, {"price":"0.904", "size":"629.06"}, {"price":"0.905", "size":"3010"}, {"price":"0.906", "size":"229.06"}, {"price":"0.907", "size":"33247.87"}, {"price":"0.908", "size":"15415.06"}, {"price":"0.909", "size":"7564.56"}, {"price":"0.91", "size":"37372.79"}, {"price":"0.911", "size":"25024.11"}, {"price":"0.912", "size":"15129.46"}, {"price":"0.913", "size":"59753.29"}, {"price":"0.914", "size":"294614.03"}], "asks":[{"price":"0.999", "size":"4912713.42"}, {"price":"0.998", "size":"1003359"}, {"price":"0.997", "size":"1111111"}, {"price":"0.996", "size":"55555"}, {"price":"0.995", "size":"500"}, {"price":"0.994", "size":"6000"}, {"price":"0.99", "size":"1200"}, {"price":"0.985", "size":"5.65"}, {"price":"0.984", "size":"5000000"}, {"price":"0.983", "size":"800"}, {"price":"0.98", "size":"5050"}, {"price":"0.979", "size":"2300"}, {"price":"0.97", "size":"530"}, {"price":"0.969", "size":"367.48"}, {"price":"0.959", "size":"720"}, {"price":"0.958", "size":"725.45"}, {"price":"0.952", "size":"70"}, {"price":"0.951", "size":"71"}, {"price":"0.95", "size":"5879.09"}, {"price":"0.93", "size":"13425.27"}, {"price":"0.929", "size":"6800"}, {"price":"0.928", "size":"437"}, {"price":"0.927", "size":"333"}, {"price":"0.925", "size":"1245"}, {"price":"0.924", "size":"5000"}, {"price":"0.922", "size":"11231.85"}, {"price":"0.921", "size":"127"}, {"price":"0.92", "size":"44813"}, {"price":"0.919", "size":"32326.98"}, {"price":"0.918", "size":"60985.56"}, {"price":"0.917", "size":"185052.96"}, {"price":"0.916", "size":"33873.67"}, {"price":"0.915", "size":"41577.24"}], "hash":"bfc044ca775d8c6c7bcaa505e882e3a1de79356c", "timestamp":"1780179024586", "event_type":"book"}
{"market":"0x0c4cd2055d6ea89354ffddc55d6dbcef9355748112ea952fc925f3db6a5c457f", "price_changes":[{"asset_id":"115428153746996892211798999366308897078723117634059783423375188043903703749062", "price":"0.76", "size":"10", "side":"BUY", "hash":"a5fa306284590415b3a7091358dd3a0be0273db2", "best_bid":"0.914", "best_ask":"0.915"}, {"asset_id":"18812649149814341758733697580460697418474693998558159483117100240528657629879", "price":"0.24", "size":"10", "side":"SELL", "hash":"cdf8dea8570865f8384fb09abaedea8499acd7f5", "best_bid":"0.085", "best_ask":"0.086"}], "timestamp":"1780179024652", "event_type":"price_change"}
{"market":"0x30d55d8124ee1e12dabe89201badc45669b81dff69e4ce44d961f32878ec178a", "price_changes":[{"asset_id":"27576533317283401577758999384642760405921738493660383550832555714312627457443", "price":"0.092", "size":"78375.52", "side":"SELL", "hash":"8b91800c72db62692154c94ccc7d2008a78ce634", "best_bid":"0.089", "best_ask":"0.09"}, {"asset_id":"52986718774908357330412653486471347449818893503063830313445318937088822580057", "price":"0.908", "size":"78375.52", "side":"BUY", "hash":"6e9744d3cbfe505a3fb70aee0116765bcaf67c29", "best_bid":"0.91", "best_ask":"0.911"}], "timestamp":"1780179025722", "event_type":"price_change"}
{"market":"0x1595b4818eeb1ea1e0bec5de6f057218e557feee9b405a0e930d290384fa1d16", "price_changes":[{"asset_id":"81739002353269632749850710185641576213562066971072676369728657545679630163887", "price":"0.053", "size":"3291.26", "side":"SELL", "hash":"914cdb2464ed665b7e0a4203d9925f8a8b43afee", "best_bid":"0.051", "best_ask":"0.052"}, {"asset_id":"45484070731786948288366703334552551439356529561722304542938873238430842810537", "price":"0.947", "size":"3291.26", "side":"BUY", "hash":"8370399c871f19fb2ece0ffd7be13dbee35be4cd", "best_bid":"0.948", "best_ask":"0.949"}], "timestamp":"1780179025754", "event_type":"price_change"}
{"market":"0x0c4cd2055d6ea89354ffddc55d6dbcef9355748112ea952fc925f3db6a5c457f", "price_changes":[{"asset_id":"18812649149814341758733697580460697418474693998558159483117100240528657629879", "price":"0.088", "size":"15049.46", "side":"SELL", "hash":"7966429183e3593a62cc0e140d6b4ce044a03afd", "best_bid":"0.085", "best_ask":"0.086"}, {"asset_id":"115428153746996892211798999366308897078723117634059783423375188043903703749062", "price":"0.912", "size":"15049.46", "side":"BUY", "hash":"a8e2dd71a1055391277f5c158796a4adefdf64df", "best_bid":"0.914", "best_ask":"0.915"}], "timestamp":"1780179025757", "event_type":"price_change"}
{"market":"0x7976b8dbacf9077eb1453a62bcefd6ab2df199acd28aad276ff0d920d6992892", "price_changes":[{"asset_id":"4394372887385518214471608448209527405727552777602031099972143344338178308080", "price":"0.17", "size":"27636.88", "side":"SELL", "hash":"9a03a940252888c4af92af5865cd83458d2e0d59", "best_bid":"0.167", "best_ask":"0.168"}, {"asset_id":"112680630004798425069810935278212000865453267506345451433803052322987302357330", "price":"0.83", "size":"27636.88", "side":"BUY", "hash":"067b9359e3231a17be73d9efad9cf559679f2e14", "best_bid":"0.832", "best_ask":"0.833"}], "timestamp":"1780179025772", "event_type":"price_change"}
{"market":"0x0c4cd2055d6ea89354ffddc55d6dbcef9355748112ea952fc925f3db6a5c457f", "price_changes":[{"asset_id":"115428153746996892211798999366308897078723117634059783423375188043903703749062", "price":"0.76", "size":"0", "side":"BUY", "hash":"bb5e088b10a46553286d57d937dc289f2a09b6e4", "best_bid":"0.914", "best_ask":"0.915"}, {"asset_id":"18812649149814341758733697580460697418474693998558159483117100240528657629879", "price":"0.24", "size":"0", "side":"SELL", "hash":"408d5c6dbfabab44f1eef9741ac9a27f0b773e7e", "best_bid":"0.085", "best_ask":"0.086"}], "timestamp":"1780179025811", "event_type":"price_change"}
{"market":"0x1595b4818eeb1ea1e0bec5de6f057218e557feee9b405a0e930d290384fa1d16", "price_changes":[{"asset_id":"81739002353269632749850710185641576213562066971072676369728657545679630163887", "price":"0.053", "size":"3371.26", "side":"SELL", "hash":"586c8bd1b14d203378783bfe1ee5930973bdf427", "best_bid":"0.051", "best_ask":"0.052"}, {"asset_id":"45484070731786948288366703334552551439356529561722304542938873238430842810537", "price":"0.947", "size":"3371.26", "side":"BUY", "hash":"3c61712659ff40351738e88364abcb5e6542a086", "best_bid":"0.948", "best_ask":"0.949"}], "timestamp":"1780179025860", "event_type":"price_change"}
{"market":"0x30d55d8124ee1e12dabe89201badc45669b81dff69e4ce44d961f32878ec178a", "price_changes":[{"asset_id":"27576533317283401577758999384642760405921738493660383550832555714312627457443", "price":"0.092", "size":"78431.18", "side":"SELL", "hash":"5039f740eefc6fde6c60b350a5b524432cdbabe0", "best_bid":"0.089", "best_ask":"0.09"}, {"asset_id":"52986718774908357330412653486471347449818893503063830313445318937088822580057", "price":"0.908", "size":"78431.18", "side":"BUY", "hash":"d9e1bfa4e630c8e234c650508f5f20cae737bf36", "best_bid":"0.91", "best_ask":"0.911"}], "timestamp":"1780179025860", "event_type":"price_change"}
{"market":"0x0c4cd2055d6ea89354ffddc55d6dbcef9355748112ea952fc925f3db6a5c457f", "price_changes":[{"asset_id":"18812649149814341758733697580460697418474693998558159483117100240528657629879", "price":"0.088", "size":"15129.46", "side":"SELL", "hash":"342eb71fe6bb483fd22c4ae31591cb930b386336", "best_bid":"0.085", "best_ask":"0.086"}, {"asset_id":"115428153746996892211798999366308897078723117634059783423375188043903703749062", "price":"0.912", "size":"15129.46", "side":"BUY", "hash":"8c86b28013176a4e1fc33c37a2fa4835ee7e65b9", "best_bid":"0.914", "best_ask":"0.915"}], "timestamp":"1780179025880", "event_type":"price_change"}
{"market":"0x7976b8dbacf9077eb1453a62bcefd6ab2df199acd28aad276ff0d920d6992892", "price_changes":[{"asset_id":"4394372887385518214471608448209527405727552777602031099972143344338178308080", "price":"0.17", "size":"27662.43", "side":"SELL", "hash":"9ceaa865dbe8a88ad614002991db648ac7966284", "best_bid":"0.167", "best_ask":"0.168"}, {"asset_id":"112680630004798425069810935278212000865453267506345451433803052322987302357330", "price":"0.83", "size":"27662.43", "side":"BUY", "hash":"c1bb6475820d765e066a7fd140955916d0365067", "best_bid":"0.832", "best_ask":"0.833"}], "timestamp":"1780179025881", "event_type":"price_change"}
{"market":"0x9b6fef249040fd17e9c107955b37ac2c3e923509b6b0ff01cc463a331ddeb894", "price_changes":[{"asset_id":"108233603819467706476318984012158651931658302669301887462181073562758483842092", "price":"0.166", "size":"24926.68", "side":"SELL", "hash":"fca9c52e81f4cb7a3e0908eae98e20f011469c94", "best_bid":"0.163", "best_ask":"0.164"}, {"asset_id":"32270411694523539495262303868629477861017829722282576458031815333486368239544", "price":"0.834", "size":"24926.68", "side":"BUY", "hash":"5e9b7d53993b48aecc2b4bec944ce2a15ff5ba60", "best_bid":"0.836", "best_ask":"0.837"}], "timestamp":"1780179027805", "event_type":"price_change"}
{"market":"0x375409bc5eeeff961e82b479caeccc20f33d15738e5bce1186d628aa3d9dfb1f", "price_changes":[{"asset_id":"115556263888245616435851357148058235707004733438163639091106356867234218207169", "price":"0.115", "size":"11999.15", "side":"SELL", "hash":"e6d5a332352b118f1795f7f87e868ec1e4cb5ced", "best_bid":"0.112", "best_ask":"0.113"}, {"asset_id":"77121637225348873006259930776623502125079210522997384841464684944292365296940", "price":"0.885", "size":"11999.15", "side":"BUY", "hash":"2ef2f95e298ab75ffe8337d39b202f0af02127ec", "best_bid":"0.887", "best_ask":"0.888"}], "timestamp":"1780179027893", "event_type":"price_change"}
{"market":"0x9b6fef249040fd17e9c107955b37ac2c3e923509b6b0ff01cc463a331ddeb894", "price_changes":[{"asset_id":"108233603819467706476318984012158651931658302669301887462181073562758483842092", "price":"0.166", "size":"25006.68", "side":"SELL", "hash":"7e977b1f0098c69568e281fff541066a43bc36fb", "best_bid":"0.163", "best_ask":"0.164"}, {"asset_id":"32270411694523539495262303868629477861017829722282576458031815333486368239544", "price":"0.834", "size":"25006.68", "side":"BUY", "hash":"11f63e92bdf7b4539e159ae95dbe38f79f1729e9", "best_bid":"0.836", "best_ask":"0.837"}], "timestamp":"1780179027944", "event_type":"price_change"}
{"market":"0x375409bc5eeeff961e82b479caeccc20f33d15738e5bce1186d628aa3d9dfb1f", "price_changes":[{"asset_id":"115556263888245616435851357148058235707004733438163639091106356867234218207169", "price":"0.115", "size":"12079.15", "side":"SELL", "hash":"43dcd0bed3385b5e8cecb61710c4be9a70fdc6a2", "best_bid":"0.112", "best_ask":"0.113"}, {"asset_id":"77121637225348873006259930776623502125079210522997384841464684944292365296940", "price":"0.885", "size":"12079.15", "side":"BUY", "hash":"de02603e78f7dabf1f03aaca73878f279a033fcc", "best_bid":"0.887", "best_ask":"0.888"}], "timestamp":"1780179028023", "event_type":"price_change"}
{"market":"0x4f3421fb2daf5cca7430ed8d8132463963081572d75434393a1808fdb8829fe8", "price_changes":[{"asset_id":"45415751658241142530386585138386640503488308219341470020075667342738719018629", "price":"0.103", "size":"18202.51", "side":"SELL", "hash":"391562a8c983611884c7af7d281eca4938a01efe", "best_bid":"0.1", "best_ask":"0.101"}, {"asset_id":"31940783580344558651011323787577288681658737625185216525249046282994042503801", "price":"0.897", "size":"18202.51", "side":"BUY", "hash":"efec6e9663127fac872261b85a3e95e20c2fb3c4", "best_bid":"0.899", "best_ask":"0.9"}], "timestamp":"1780179028262", "event_type":"price_change"}
{"market":"0x4f3421fb2daf5cca7430ed8d8132463963081572d75434393a1808fdb8829fe8", "price_changes":[{"asset_id":"45415751658241142530386585138386640503488308219341470020075667342738719018629", "price":"0.103", "size":"18263.31", "side":"SELL", "hash":"8c61857db6cd402727af416c84518943d69955d7", "best_bid":"0.1", "best_ask":"0.101"}, {"asset_id":"31940783580344558651011323787577288681658737625185216525249046282994042503801", "price":"0.897", "size":"18263.31", "side":"BUY", "hash":"21bc02457d040a4adec4ce34c2993e3461fb8f41", "best_bid":"0.899", "best_ask":"0.9"}], "timestamp":"1780179028347", "event_type":"price_change"}
{"id":"2397637", "question":"O/U 2.5 Rounds", "market":"0x789aa9b41285509d251863cffbc3fe256f86e5fed78cfd469d5b42c39408ad2e", "slug":"ufc-kyo-man1-2026-06-20-totals-2pt5", "description":"Each market will resolve to \"Over\" if the fight between Kyoji Horiguchi and Manel Kape at UFC Fight Night: Kape vs. Horiguchi, scheduled for June 20, 2026, lasts beyond the listed round threshold.\n\nEach market will resolve to \"Under\" if the fight does not last beyond the listed round threshold.\n\nFor example:\n\n\"Over 2.5 Rounds\" will resolve \"Yes\" if the fight continues past the 2:30 mark of Round 3.\n\n\"Under 2.5 Rounds\" will resolve \"Yes\" if the fight ends before the 2:30 mark of Round 3.\n\nIf the fight ends exactly at the threshold, it will resolve \"50-50.\"\n\nIf the bout is not scored, postponed beyond July 4, 2026, or canceled, all options will resolve \"50-50.\"\n\nThe resolution source for this market will be official information from the UFC.", "assets_ids":["40014080577104927905894926106636526542098807931029357684562991660200669965144", "18559204297731967394080213812818254841978080000326815766976997591967816997447"], "outcomes":["Over", "Under"], "event_message":{"id":"542607", "ticker":"ufc-kyo-man1-2026-06-20", "slug":"ufc-kyo-man1-2026-06-20", "title":"UFC Fight Night: Kyoji Horiguchi vs. Manel Kape (Flyweight, Main Card)", "description":"This market will resolve to \"Kyoji Horiguchi\" if Kyoji Horiguchi is officially declared the winner of the fight against Manel Kape at UFC Fight Night: Kape vs. Horiguchi, scheduled for June 20, 2026.\n\nIt will resolve to \"Manel Kape\" if Manel Kape is officially declared the winner.\n\nIf the fight is declared a draw or technical draw, ruled a No Contest, not scored, canceled, or postponed beyond July 4, 2026, this market will resolve \"50-50.\"\n\nThe resolution source for this market will be official information from the UFC."}, "timestamp":"1780179029000", "event_type":"new_market", "tags":[], "condition_id":"0x789aa9b41285509d251863cffbc3fe256f86e5fed78cfd469d5b42c39408ad2e", "active":false, "clob_token_ids":["40014080577104927905894926106636526542098807931029357684562991660200669965144", "18559204297731967394080213812818254841978080000326815766976997591967816997447"], "sports_market_type":"totals", "line":"2.5", "game_start_time":"2026-06-20 17:00:00+00", "order_price_min_tick_size":"0.01", "group_item_title":"O/U 2.5 Rounds", "taker_base_fee":"1000", "fees_enabled":true, "fee_schedule":{"exponent":"1", "rate":"0.03", "taker_only":true, "rebate_rate":"0.25"}}
{"id":"2397668", "question":"ITF Bol: Aurora Zantedeschi vs Valentina Ivanov", "market":"0x26d6b84d4cdbc31488933eefc21490ec390d6bb34e1a3eba8ad9125a54481e12", "slug":"itf-zantede-ivano-2026-05-31", "description":"This market refers to the tennis match between Aurora Zantedeschi and Valentina Ivanov in the ITF Women Bol, originally scheduled for May 31, 2026 at 4:00AM ET.\n\nThis market will resolve to 'Aurora Zantedeschi' if Aurora Zantedeschi advances against Valentina Ivanov.\n\nThis market will resolve to 'Valentina Ivanov' if Valentina Ivanov advances against Aurora Zantedeschi.\n\nIf the match is canceled (not played at all), ends in a tie, or is delayed beyond 7 days from the scheduled date without a winner determined, this market will resolve to 50-50.\n\nIf the match begins but is not completed, and one player advances due to the opponent's retirement, default, or disqualification, this market will resolve to the player who advances.\n\nIf the match ends in a walkover (player withdraws before the start and the other advances automatically), this market will resolve to 50-50.\n\nThe primary resolution source will be official information from the International Tennis Federation (ITF). A consensus of credible reporting may also be used.", "assets_ids":["93630026746348044903601229181793879935212573025901125801007442227546993556675", "34979915649701075155097876142067457532347493791175480962313934805663384295554"], "outcomes":["Aurora Zantedeschi", "Valentina Ivanov"], "event_message":{"id":"542625", "ticker":"itf-zantede-ivano-2026-05-31", "slug":"itf-zantede-ivano-2026-05-31", "title":"ITF Bol: Aurora Zantedeschi vs Valentina Ivanov", "description":"This market refers to the tennis match between Aurora Zantedeschi and Valentina Ivanov in the ITF Women Bol, originally scheduled for May 31, 2026 at 4:00AM ET.\n\nThis market will resolve to 'Aurora Zantedeschi' if Aurora Zantedeschi advances against Valentina Ivanov.\n\nThis market will resolve to 'Valentina Ivanov' if Valentina Ivanov advances against Aurora Zantedeschi.\n\nIf the match is canceled (not played at all), ends in a tie, or is delayed beyond 7 days from the scheduled date without a winner determined, this market will resolve to 50-50.\n\nIf the match begins but is not completed, and one player advances due to the opponent's retirement, default, or disqualification, this market will resolve to the player who advances.\n\nIf the match ends in a walkover (player withdraws before the start and the other advances automatically), this market will resolve to 50-50.\n\nThe primary resolution source will be official information from the International Tennis Federation (ITF). A consensus of credible reporting may also be used."}, "timestamp":"1780179031200", "event_type":"new_market", "tags":[], "condition_id":"0x26d6b84d4cdbc31488933eefc21490ec390d6bb34e1a3eba8ad9125a54481e12", "active":false, "clob_token_ids":["93630026746348044903601229181793879935212573025901125801007442227546993556675", "34979915649701075155097876142067457532347493791175480962313934805663384295554"], "sports_market_type":"moneyline", "line":"", "game_start_time":"2026-05-31 08:00:00+00", "order_price_min_tick_size":"0.01", "group_item_title":"", "taker_base_fee":"1000", "fees_enabled":true, "fee_schedule":{"exponent":"1", "rate":"0.03", "taker_only":true, "rebate_rate":"0.25"}}
PONG
{"market":"0x0c4cd2055d6ea89354ffddc55d6dbcef9355748112ea952fc925f3db6a5c457f", "price_changes":[{"asset_id":"18812649149814341758733697580460697418474693998558159483117100240528657629879", "price":"0.085", "size":"41587.24", "side":"BUY", "hash":"8b8d8c94dd09ee2e14ca039c1704e152600928f9", "best_bid":"0.085", "best_ask":"0.086"}, {"asset_id":"115428153746996892211798999366308897078723117634059783423375188043903703749062", "price":"0.915", "size":"41587.24", "side":"SELL", "hash":"342d61c5b64e84e35f19e9603297c6593f968517", "best_bid":"0.914", "best_ask":"0.915"}], "timestamp":"1780179033473", "event_type":"price_change"}
{"market":"0x7876851632c295043c66536150a304cb785abdf712ba8489d298c6e6926be106", "price_changes":[{"asset_id":"97239126062673310243763617236644392945530356142765650402171508075574679292913", "price":"0.01", "size":"1264650", "side":"BUY", "hash":"646f2286865a6d0b2818214735238b5768f44c5d", "best_bid":"0.01", "best_ask":"0.011"}, {"asset_id":"19291692040378529618917910599727571242305935029274321291612270922648172794670", "price":"0.99", "size":"1264650", "side":"SELL", "hash":"c617e01f09efd7312c161551e3bbd50ec19a645f", "best_bid":"0.989", "best_ask":"0.99"}], "timestamp":"1780179034006", "event_type":"price_change"}
{"market":"0x0c4cd2055d6ea89354ffddc55d6dbcef9355748112ea952fc925f3db6a5c457f", "price_changes":[{"asset_id":"115428153746996892211798999366308897078723117634059783423375188043903703749062", "price":"0.915", "size":"41609.94", "side":"SELL", "hash":"17886b586e2672bd00a3218ff369368ef6af3f3c", "best_bid":"0.914", "best_ask":"0.915"}, {"asset_id":"18812649149814341758733697580460697418474693998558159483117100240528657629879", "price":"0.085", "size":"41609.94", "side":"BUY", "hash":"5138dc77248a346a4757c297d30737c144db966b", "best_bid":"0.085", "best_ask":"0.086"}], "timestamp":"1780179037708", "event_type":"price_change"}
{"id":"2397793", "question":"Will the fight be won by KO or TKO?", "market":"0x4b6eb676483d260b0c340c5afbd84010f2e9309785efaa0a567fc2f5381fbd54", "slug":"ufc-jho1-jluiz-2026-06-20-win-by-ko-tko", "description":"This market will resolve to \"Yes\" if the fight between Jhonata Diniz and José Luiz at UFC Fight Night: Kape vs. Horiguchi, scheduled for June 20, 2026, ends by KO or TKO, including referee stoppage, doctor stoppage, or corner stoppage. Otherwise, it will resolve to \"No.\"\n\nIf the fight ends in a draw or by disqualification (either fighter), it will resolve \"No.\"\n\nIf the bout is ruled a No Contest, not scored, canceled, or postponed beyond July 4, 2026, this market will resolve \"50-50.\"\n\nThe resolution source for this market will be official information from the UFC.", "assets_ids":["61782309075040798001968682044049656812660057662810534024384632800310839744962", "95903063790780985563546097200489503054747165670795002461265285887725317624497"], "outcomes":["Yes", "No"], "event_message":{"id":"542664", "ticker":"ufc-jho1-jluiz-2026-06-20", "slug":"ufc-jho1-jluiz-2026-06-20", "title":"UFC Fight Night: Jhonata Diniz vs. José Luiz (Heavyweight, Prelims)", "description":"This market will resolve to \"Jhonata Diniz\" if Jhonata Diniz is officially declared the winner of the fight against José Luiz at UFC Fight Night: Kape vs. Horiguchi, scheduled for June 20, 2026.\n\nIt will resolve to \"José Luiz\" if José Luiz is officially declared the winner.\n\nIf the fight is declared a draw or technical draw, ruled a No Contest, not scored, canceled, or postponed beyond July 4, 2026, this market will resolve \"50-50.\"\n\nThe resolution source for this market will be official information from the UFC."}, "timestamp":"1780179038060", "event_type":"new_market", "tags":[], "condition_id":"0x4b6eb676483d260b0c340c5afbd84010f2e9309785efaa0a567fc2f5381fbd54", "active":false, "clob_token_ids":["61782309075040798001968682044049656812660057662810534024384632800310839744962", "95903063790780985563546097200489503054747165670795002461265285887725317624497"], "sports_market_type":"ufc_method_of_victory", "line":"", "game_start_time":"2026-06-20 17:00:00+00", "order_price_min_tick_size":"0.01", "group_item_title":"Fight won by KO/TKO?", "taker_base_fee":"1000", "fees_enabled":true, "fee_schedule":{"exponent":"1", "rate":"0.03", "taker_only":true, "rebate_rate":"0.25"}}
{"market":"0x0c4cd2055d6ea89354ffddc55d6dbcef9355748112ea952fc925f3db6a5c457f", "price_changes":[{"asset_id":"18812649149814341758733697580460697418474693998558159483117100240528657629879", "price":"0.085", "size":"41619.94", "side":"BUY", "hash":"2616eed244b103ee2225278ce92a763bde1c86bd", "best_bid":"0.085", "best_ask":"0.086"}, {"asset_id":"115428153746996892211798999366308897078723117634059783423375188043903703749062", "price":"0.915", "size":"41619.94", "side":"SELL", "hash":"0738dbbe1c8a888928ba3d82a44c50faef07e4c0", "best_bid":"0.914", "best_ask":"0.915"}], "timestamp":"1780179039409", "event_type":"price_change"}
{"id":"2397700", "question":"ITF Women Tauste-Zaragoza: Completed Match: Jennifer Ruggeri vs Kayla Day", "market":"0x9bc0b98082065f36b058b5edc01b10cea357a75ba6ae50940c6a1f9182b3144d", "slug":"itf-ruggeri-day-2026-05-31-completed-match", "description":"This market refers to the tennis match between Jennifer Ruggeri and Kayla Day in the ITF Women Tauste-Zaragoza, originally scheduled for May 31, 2026 at 5:30AM ET. This market will resolve to \"Yes\" if all games and sets required to determine a match winner under governing body or event organizer rules are played to completion through normal play. Otherwise, if the match is not completed for any reason, it will resolve to \"No.\" If a forfeit of any kind occurs, including but not limited to a walkover or retirement, this market will resolve \"No.\" If the match is canceled (not played at all), ends in a tie, or is delayed beyond 7 days from the scheduled date without a winner determined, this market will resolve to \"No.\" The primary resolution source for this market is the official statistics of the event as recognized by the governing body or event organizers. However, if the governing body or event organizers have not published final match statistics within 2 hours after the event's conclusion, a consensus of credible reporting may be used instead.", "assets_ids":["4629421716210016918519589764604717317539327477626440864694200580690680001069", "43256814496661729794444874894842231487149246205365563845435068394829692805019"], "outcomes":["Yes", "No"], "event_message":{"id":"542634", "ticker":"itf-ruggeri-day-2026-05-31", "slug":"itf-ruggeri-day-2026-05-31", "title":"ITF Tauste-Zaragoza: Jennifer Ruggeri vs Kayla Day", "description":"This market refers to the tennis match between Jennifer Ruggeri and Kayla Day in the ITF Women Tauste-Zaragoza, originally scheduled for May 31, 2026 at 5:30AM ET.\n\nThis market will resolve to 'Jennifer Ruggeri' if Jennifer Ruggeri advances against Kayla Day.\n\nThis market will resolve to 'Kayla Day' if Kayla Day advances against Jennifer Ruggeri.\n\nIf the match is canceled (not played at all), ends in a tie, or is delayed beyond 7 days from the scheduled date without a winner determined, this market will resolve to 50-50.\n\nIf the match begins but is not completed, and one player advances due to the opponent's retirement, default, or disqualification, this market will resolve to the player who advances.\n\nIf the match ends in a walkover (player withdraws before the start and the other advances automatically), this market will resolve to 50-50.\n\nThe primary resolution source will be official information from the International Tennis Federation (ITF). A consensus of credible reporting may also be used."}, "timestamp":"1780179040165", "event_type":"new_market", "tags":[], "condition_id":"0x9bc0b98082065f36b058b5edc01b10cea357a75ba6ae50940c6a1f9182b3144d", "active":false, "clob_token_ids":["4629421716210016918519589764604717317539327477626440864694200580690680001069", "43256814496661729794444874894842231487149246205365563845435068394829692805019"], "sports_market_type":"tennis_completed_match", "line":"", "game_start_time":"2026-05-31 09:30:00+00", "order_price_min_tick_size":"0.01", "group_item_title":"Completed Match", "taker_base_fee":"1000", "fees_enabled":true, "fee_schedule":{"exponent":"1", "rate":"0.03", "taker_only":true, "rebate_rate":"0.25"}}
{"market":"0x0c4cd2055d6ea89354ffddc55d6dbcef9355748112ea952fc925f3db6a5c457f", "price_changes":[{"asset_id":"18812649149814341758733697580460697418474693998558159483117100240528657629879", "price":"0.085", "size":"41629.94", "side":"BUY", "hash":"f0c04d54d059b6d3955d099a73226318c2cbb6f5", "best_bid":"0.085", "best_ask":"0.086"}, {"asset_id":"115428153746996892211798999366308897078723117634059783423375188043903703749062", "price":"0.915", "size":"41629.94", "side":"SELL", "hash":"765158e195b6571296e8c9c5ba6aa2c962387513", "best_bid":"0.914", "best_ask":"0.915"}], "timestamp":"1780179040213", "event_type":"price_change"}
{"id":"2397769", "question":"O/U 1.5 Rounds", "market":"0xc6317b04be67ca39caefcd4c8370a25106b10582637d4b870780a4e7668e30fd", "slug":"ufc-gas-mic34-2026-06-20-totals-1pt5", "description":"Each market will resolve to \"Over\" if the fight between Gaston Bolaños and Michael Aswell at UFC Fight Night: Kape vs. Horiguchi, scheduled for June 20, 2026, lasts beyond the listed round threshold.\n\nEach market will resolve to \"Under\" if the fight does not last beyond the listed round threshold.\n\nFor example:\n\n\"Over 1.5 Rounds\" will resolve \"Yes\" if the fight continues past the 2:30 mark of Round 2.\n\n\"Under 1.5 Rounds\" will resolve \"Yes\" if the fight ends before the 2:30 mark of Round 2.\n\nIf the fight ends exactly at the threshold, it will resolve \"50-50.\"\n\nIf the bout is not scored, postponed beyond July 4, 2026, or canceled, all options will resolve \"50-50.\"\n\nThe resolution source for this market will be official information from the UFC.", "assets_ids":["115666410769137261497122078228353727278161152643539047836766542526343400762526", "40819663825562537497254556526285978624016890213290426222795669878544137960786"], "outcomes":["Over", "Under"], "event_message":{"id":"542654", "ticker":"ufc-gas-mic34-2026-06-20", "slug":"ufc-gas-mic34-2026-06-20", "title":"UFC Fight Night: Gaston Bolaños vs. Michael Aswell (Featherweight, Prelims)", "description":"This market will resolve to \"Gaston Bolaños\" if Gaston Bolaños is officially declared the winner of the fight against Michael Aswell at UFC Fight Night: Kape vs. Horiguchi, scheduled for June 20, 2026.\n\nIt will resolve to \"Michael Aswell\" if Michael Aswell is officially declared the winner.\n\nIf the fight is declared a draw or technical draw, ruled a No Contest, not scored, canceled, or postponed beyond July 4, 2026, this market will resolve \"50-50.\"\n\nThe resolution source for this market will be official information from the UFC."}, "timestamp":"1780179040931", "event_type":"new_market", "tags":[], "condition_id":"0xc6317b04be67ca39caefcd4c8370a25106b10582637d4b870780a4e7668e30fd", "active":false, "clob_token_ids":["115666410769137261497122078228353727278161152643539047836766542526343400762526", "40819663825562537497254556526285978624016890213290426222795669878544137960786"], "sports_market_type":"totals", "line":"1.5", "game_start_time":"2026-06-20 17:00:00+00", "order_price_min_tick_size":"0.01", "group_item_title":"O/U 1.5 Rounds", "taker_base_fee":"1000", "fees_enabled":true, "fee_schedule":{"exponent":"1", "rate":"0.03", "taker_only":true, "rebate_rate":"0.25"}}
PONG
{"market":"0x7876851632c295043c66536150a304cb785abdf712ba8489d298c6e6926be106", "price_changes":[{"asset_id":"97239126062673310243763617236644392945530356142765650402171508075574679292913", "price":"0.011", "size":"1818525.69", "side":"SELL", "hash":"0da6d016545587933daebd3282d1053495db25d8", "best_bid":"0.01", "best_ask":"0.011"}, {"asset_id":"19291692040378529618917910599727571242305935029274321291612270922648172794670", "price":"0.989", "size":"1818525.69", "side":"BUY", "hash":"d9dff5825fe6156ae19a4b33f6fc107772142d11", "best_bid":"0.989", "best_ask":"0.99"}], "timestamp":"1780179042002", "event_type":"price_change"}
{"id":"2397838", "question":"Heilbronn: Completed Match: Joao Lucas Da Silva vs Alex Barrena", "market":"0x17820f7aaf9377850e24b633b4a45de0f1bb80fad037f0d7fa4d0e67b46f2fc6", "slug":"atp-silv-barrena-2026-06-01-completed-match", "description":"This market refers to the tennis match between Joao Lucas Da Silva and Alex Barrena in the Heilbronn, originally scheduled for June 1, 2026 at 5:00AM ET. This market will resolve to \"Yes\" if all games and sets required to determine a match winner under governing body or event organizer rules are played to completion through normal play. Otherwise, if the match is not completed for any reason, it will resolve to \"No.\" If a forfeit of any kind occurs, including but not limited to a walkover or retirement, this market will resolve \"No.\" If the match is canceled (not played at all), ends in a tie, or is delayed beyond 7 days from the scheduled date without a winner determined, this market will resolve to \"No.\" The primary resolution source for this market is the official statistics of the event as recognized by the governing body or event organizers. However, if the governing body or event organizers have not published final match statistics within 2 hours after the event's conclusion, a consensus of credible reporting may be used instead.", "assets_ids":["80689395211868875015400339470190871670092294579374426499666457505978472615393", "8602412948893506162788824439351200336802174958389287285214037228081568113842"], "outcomes":["Yes", "No"], "event_message":{"id":"542684", "ticker":"atp-silv-barrena-2026-06-01", "slug":"atp-silv-barrena-2026-06-01", "title":"Heilbronn: Joao Lucas Da Silva vs Alex Barrena", "description":"This market refers to the tennis match between Joao Lucas Da Silva and Alex Barrena in the Heilbronn, originally scheduled for June 1, 2026 at 5:00AM ET.\n\nThis market will resolve to 'Joao Lucas Da Silva' if Joao Lucas Da Silva advances against Alex Barrena.\n\nThis market will resolve to 'Alex Barrena' if Alex Barrena advances against Joao Lucas Da Silva.\n\nIf the match is canceled (not played at all), ends in a tie, or is delayed beyond 7 days from the scheduled date without a winner determined, this market will resolve to 50-50.\n\nIf the match begins but is not completed, and one player advances due to the opponent's retirement, default, or disqualification, this market will resolve to the player who advances.\n\nIf the match ends in a walkover (player withdraws before the start and the other advances automatically), this market will resolve to 50-50.\n\nThe primary resolution source will be official information from the ATP Tour. A consensus of credible reporting may also be used."}, "timestamp":"1780179042971", "event_type":"new_market", "tags":[], "condition_id":"0x17820f7aaf9377850e24b633b4a45de0f1bb80fad037f0d7fa4d0e67b46f2fc6", "active":false, "clob_token_ids":["80689395211868875015400339470190871670092294579374426499666457505978472615393", "8602412948893506162788824439351200336802174958389287285214037228081568113842"], "sports_market_type":"tennis_completed_match", "line":"", "game_start_time":"2026-06-01 09:00:00+00", "order_price_min_tick_size":"0.01", "group_item_title":"Completed Match", "taker_base_fee":"1000", "fees_enabled":true, "fee_schedule":{"exponent":"1", "rate":"0.03", "taker_only":true, "rebate_rate":"0.25"}}
{"market":"0x4f3421fb2daf5cca7430ed8d8132463963081572d75434393a1808fdb8829fe8", "price_changes":[{"asset_id":"45415751658241142530386585138386640503488308219341470020075667342738719018629", "price":"0.103", "size":"18203.31", "side":"SELL", "hash":"79bdb7d8abd282ac0dfe18fe9d0f698f297a4051", "best_bid":"0.1", "best_ask":"0.101"}, {"asset_id":"31940783580344558651011323787577288681658737625185216525249046282994042503801", "price":"0.897", "size":"18203.31", "side":"BUY", "hash":"b315415e2ef59aaf228d7e10e1fd92ae251a92b1", "best_bid":"0.899", "best_ask":"0.9"}], "timestamp":"1780179043435", "event_type":"price_change"}
{"market":"0x4f3421fb2daf5cca7430ed8d8132463963081572d75434393a1808fdb8829fe8", "price_changes":[{"asset_id":"45415751658241142530386585138386640503488308219341470020075667342738719018629", "price":"0.103", "size":"18263.31", "side":"SELL", "hash":"a0dcc02c94555e3630e8935a6a02d8de96a1024b", "best_bid":"0.1", "best_ask":"0.101"}, {"asset_id":"31940783580344558651011323787577288681658737625185216525249046282994042503801", "price":"0.897", "size":"18263.31", "side":"BUY", "hash":"6b34257043e2c7e5e8b8e2c34d39cef66c8ea44c", "best_bid":"0.899", "best_ask":"0.9"}], "timestamp":"1780179043538", "event_type":"price_change"}
{"market":"0x9b6fef249040fd17e9c107955b37ac2c3e923509b6b0ff01cc463a331ddeb894", "price_changes":[{"asset_id":"108233603819467706476318984012158651931658302669301887462181073562758483842092", "price":"0.166", "size":"24952", "side":"SELL", "hash":"583611723ea814e1447493d5a10016891d83f859", "best_bid":"0.163", "best_ask":"0.164"}, {"asset_id":"32270411694523539495262303868629477861017829722282576458031815333486368239544", "price":"0.834", "size":"24952", "side":"BUY", "hash":"b054316e898b7b88c1c696bda05b8763040ad78b", "best_bid":"0.836", "best_ask":"0.837"}], "timestamp":"1780179043789", "event_type":"price_change"}
{"market":"0x9b6fef249040fd17e9c107955b37ac2c3e923509b6b0ff01cc463a331ddeb894", "price_changes":[{"asset_id":"108233603819467706476318984012158651931658302669301887462181073562758483842092", "price":"0.166", "size":"25006.68", "side":"SELL", "hash":"ae618b933f61e33f03aae0506cc8700f466f6f63", "best_bid":"0.163", "best_ask":"0.164"}, {"asset_id":"32270411694523539495262303868629477861017829722282576458031815333486368239544", "price":"0.834", "size":"25006.68", "side":"BUY", "hash":"fdb1d38be8db4fecb8d0ced0e9bcb9f67f48f5d3", "best_bid":"0.836", "best_ask":"0.837"}], "timestamp":"1780179043916", "event_type":"price_change"}
{"market":"0x0c4cd2055d6ea89354ffddc55d6dbcef9355748112ea952fc925f3db6a5c457f", "price_changes":[{"asset_id":"18812649149814341758733697580460697418474693998558159483117100240528657629879", "price":"0.085", "size":"41639.94", "side":"BUY", "hash":"3c268375baca988066344729c881457b947707b1", "best_bid":"0.085", "best_ask":"0.086"}, {"asset_id":"115428153746996892211798999366308897078723117634059783423375188043903703749062", "price":"0.915", "size":"41639.94", "side":"SELL", "hash":"02a59ea516b8892af0f4ebb4a292d418ae453f70", "best_bid":"0.914", "best_ask":"0.915"}], "timestamp":"1780179044874", "event_type":"price_change"}
{"market":"0x30d55d8124ee1e12dabe89201badc45669b81dff69e4ce44d961f32878ec178a", "price_changes":[{"asset_id":"27576533317283401577758999384642760405921738493660383550832555714312627457443", "price":"0.092", "size":"78371.18", "side":"SELL", "hash":"6731a1c1e45f5b00f719ce09cbb05b0e6f5cc623", "best_bid":"0.089", "best_ask":"0.09"}, {"asset_id":"52986718774908357330412653486471347449818893503063830313445318937088822580057", "price":"0.908", "size":"78371.18", "side":"BUY", "hash":"39464ffa81c5f7555e92752c7aa216b2deb0ae59", "best_bid":"0.91", "best_ask":"0.911"}], "timestamp":"1780179045283", "event_type":"price_change"}
{"market":"0x7976b8dbacf9077eb1453a62bcefd6ab2df199acd28aad276ff0d920d6992892", "price_changes":[{"asset_id":"4394372887385518214471608448209527405727552777602031099972143344338178308080", "price":"0.17", "size":"27608.28", "side":"SELL", "hash":"a3ca59dce972208c92299d74940f38fc4ceeed23", "best_bid":"0.167", "best_ask":"0.168"}, {"asset_id":"112680630004798425069810935278212000865453267506345451433803052322987302357330", "price":"0.83", "size":"27608.28", "side":"BUY", "hash":"2723c3945ce4707a543f17a4e127067b126a4dd4", "best_bid":"0.832", "best_ask":"0.833"}], "timestamp":"1780179045291", "event_type":"price_change"}
{"market":"0x7976b8dbacf9077eb1453a62bcefd6ab2df199acd28aad276ff0d920d6992892", "price_changes":[{"asset_id":"4394372887385518214471608448209527405727552777602031099972143344338178308080", "price":"0.17", "size":"27662.43", "side":"SELL", "hash":"b13053ba733592a295d038b62f2a42ffe8154c23", "best_bid":"0.167", "best_ask":"0.168"}, {"asset_id":"112680630004798425069810935278212000865453267506345451433803052322987302357330", "price":"0.83", "size":"27662.43", "side":"BUY", "hash":"796ed57d51451f0e06c7435185ed812b877a51a5", "best_bid":"0.832", "best_ask":"0.833"}], "timestamp":"1780179045388", "event_type":"price_change"}
{"market":"0x30d55d8124ee1e12dabe89201badc45669b81dff69e4ce44d961f32878ec178a", "price_changes":[{"asset_id":"27576533317283401577758999384642760405921738493660383550832555714312627457443", "price":"0.092", "size":"78431.18", "side":"SELL", "hash":"25196c35429ca11f6ef766923e9bedd1e6f70aa2", "best_bid":"0.089", "best_ask":"0.09"}, {"asset_id":"52986718774908357330412653486471347449818893503063830313445318937088822580057", "price":"0.908", "size":"78431.18", "side":"BUY", "hash":"b1563b9ebea8aed4b08b4690a9e0ab0588bf304d", "best_bid":"0.91", "best_ask":"0.911"}], "timestamp":"1780179045390", "event_type":"price_change"}
{"market":"0x7976b8dbacf9077eb1453a62bcefd6ab2df199acd28aad276ff0d920d6992892", "price_changes":[{"asset_id":"4394372887385518214471608448209527405727552777602031099972143344338178308080", "price":"0.184", "size":"0", "side":"SELL", "hash":"ff3ba718167e416731cd0e2e0f173b83dce21930", "best_bid":"0.167", "best_ask":"0.168"}, {"asset_id":"112680630004798425069810935278212000865453267506345451433803052322987302357330", "price":"0.816", "size":"0", "side":"BUY", "hash":"86a3988e5d6320befd539ed67d0e6dc49ef90f6e", "best_bid":"0.832", "best_ask":"0.833"}], "timestamp":"1780179045652", "event_type":"price_change"}
{"market":"0x7976b8dbacf9077eb1453a62bcefd6ab2df199acd28aad276ff0d920d6992892", "price_changes":[{"asset_id":"4394372887385518214471608448209527405727552777602031099972143344338178308080", "price":"0.184", "size":"49.77", "side":"SELL", "hash":"f03ebb5591813d9a0a2e8fcd50b4460460f25edd", "best_bid":"0.167", "best_ask":"0.168"}, {"asset_id":"112680630004798425069810935278212000865453267506345451433803052322987302357330", "price":"0.816", "size":"49.77", "side":"BUY", "hash":"e878792525238cfaf7c586aca6df5b382fb87aaf", "best_bid":"0.832", "best_ask":"0.833"}], "timestamp":"1780179045828", "event_type":"price_change"}
{"market":"0x0c4cd2055d6ea89354ffddc55d6dbcef9355748112ea952fc925f3db6a5c457f", "price_changes":[{"asset_id":"18812649149814341758733697580460697418474693998558159483117100240528657629879", "price":"0.088", "size":"15069.46", "side":"SELL", "hash":"4cb89ed74eb63a16637f97169441857fb8837a21", "best_bid":"0.085", "best_ask":"0.086"}, {"asset_id":"115428153746996892211798999366308897078723117634059783423375188043903703749062", "price":"0.912", "size":"15069.46", "side":"BUY", "hash":"23a9bf127a85bdae5e2cd96f7feeae03c12737f3", "best_bid":"0.914", "best_ask":"0.915"}], "timestamp":"1780179046642", "event_type":"price_change"}
{"market":"0x1595b4818eeb1ea1e0bec5de6f057218e557feee9b405a0e930d290384fa1d16", "price_changes":[{"asset_id":"81739002353269632749850710185641576213562066971072676369728657545679630163887", "price":"0.053", "size":"3311.26", "side":"SELL", "hash":"47051ca17213a2c2517e0651607a6c252ca53a3d", "best_bid":"0.051", "best_ask":"0.052"}, {"asset_id":"45484070731786948288366703334552551439356529561722304542938873238430842810537", "price":"0.947", "size":"3311.26", "side":"BUY", "hash":"5cee1e3dc319e59f970da5d4892df6223025a3f0", "best_bid":"0.948", "best_ask":"0.949"}], "timestamp":"1780179046644", "event_type":"price_change"}
{"market":"0x375409bc5eeeff961e82b479caeccc20f33d15738e5bce1186d628aa3d9dfb1f", "price_changes":[{"asset_id":"115556263888245616435851357148058235707004733438163639091106356867234218207169", "price":"0.115", "size":"12019.15", "side":"SELL", "hash":"a683de53062f5a0462cd9428a12a764bc1ddf8e0", "best_bid":"0.112", "best_ask":"0.113"}, {"asset_id":"77121637225348873006259930776623502125079210522997384841464684944292365296940", "price":"0.885", "size":"12019.15", "side":"BUY", "hash":"f939f680bee274e54a1b4152271e21317cf7203a", "best_bid":"0.887", "best_ask":"0.888"}], "timestamp":"1780179046654", "event_type":"price_change"}
{"market":"0x0c4cd2055d6ea89354ffddc55d6dbcef9355748112ea952fc925f3db6a5c457f", "price_changes":[{"asset_id":"18812649149814341758733697580460697418474693998558159483117100240528657629879", "price":"0.088", "size":"15129.46", "side":"SELL", "hash":"c0c8180aea2059d3298f1efdb93dcdcad0a0399e", "best_bid":"0.085", "best_ask":"0.086"}, {"asset_id":"115428153746996892211798999366308897078723117634059783423375188043903703749062", "price":"0.912", "size":"15129.46", "side":"BUY", "hash":"fcec3045f3c0e55442ff244af29e6ac9ff66b484", "best_bid":"0.914", "best_ask":"0.915"}], "timestamp":"1780179046741", "event_type":"price_change"}
{"market":"0x1595b4818eeb1ea1e0bec5de6f057218e557feee9b405a0e930d290384fa1d16", "price_changes":[{"asset_id":"81739002353269632749850710185641576213562066971072676369728657545679630163887", "price":"0.053", "size":"3371.26", "side":"SELL", "hash":"a958a583cff2718a56b8dc427b9f48e178179a81", "best_bid":"0.051", "best_ask":"0.052"}, {"asset_id":"45484070731786948288366703334552551439356529561722304542938873238430842810537", "price":"0.947", "size":"3371.26", "side":"BUY", "hash":"52df87b61daca0383883672d8fef1521b41f7ff0", "best_bid":"0.948", "best_ask":"0.949"}], "timestamp":"1780179046747", "event_type":"price_change"}
{"market":"0x375409bc5eeeff961e82b479caeccc20f33d15738e5bce1186d628aa3d9dfb1f", "price_changes":[{"asset_id":"115556263888245616435851357148058235707004733438163639091106356867234218207169", "price":"0.115", "size":"12079.15", "side":"SELL", "hash":"bfa9b3b46e1d24fb75bdbbae78211734cd71cbca", "best_bid":"0.112", "best_ask":"0.113"}, {"asset_id":"77121637225348873006259930776623502125079210522997384841464684944292365296940", "price":"0.885", "size":"12079.15", "side":"BUY", "hash":"aee3efce58f0b8581c6a4a7366e35ce73a066175", "best_bid":"0.887", "best_ask":"0.888"}], "timestamp":"1780179046862", "event_type":"price_change"}
{"market":"0x7876851632c295043c66536150a304cb785abdf712ba8489d298c6e6926be106", "price_changes":[{"asset_id":"97239126062673310243763617236644392945530356142765650402171508075574679292913", "price":"0.011", "size":"1818565.69", "side":"SELL", "hash":"77989dd2a43c3ba7b3ad23ca079048cc758470ee", "best_bid":"0.01", "best_ask":"0.011"}, {"asset_id":"19291692040378529618917910599727571242305935029274321291612270922648172794670", "price":"0.989", "size":"1818565.69", "side":"BUY", "hash":"e115b08c2b1a549a8ad84c1f37e413cb0c77306f", "best_bid":"0.989", "best_ask":"0.99"}], "timestamp":"1780179047684", "event_type":"price_change"}
{"id":"2397723", "question":"O/U 2.5 Rounds", "market":"0xd51c305c1baf6b58dedc908dc90d87c61af9a17d02fcd9d2a33485d8e5fc4a56", "slug":"ufc-mel2-mur2-2026-06-20-totals-2pt5", "description":"Each market will resolve to \"Over\" if the fight between Melsik Baghdasaryan and Murtazali Magomedov at UFC Fight Night: Kape vs. Horiguchi, scheduled for June 20, 2026, lasts beyond the listed round threshold.\n\nEach market will resolve to \"Under\" if the fight does not last beyond the listed round threshold.\n\nFor example:\n\n\"Over 2.5 Rounds\" will resolve \"Yes\" if the fight continues past the 2:30 mark of Round 3.\n\n\"Under 2.5 Rounds\" will resolve \"Yes\" if the fight ends before the 2:30 mark of Round 3.\n\nIf the fight ends exactly at the threshold, it will resolve \"50-50.\"\n\nIf the bout is not scored, postponed beyond July 4, 2026, or canceled, all options will resolve \"50-50.\"\n\nThe resolution source for this market will be official information from the UFC.", "assets_ids":["106144535144953904373915020925848550882454590179585810910664022237171288338863", "82993776222789397331431805628325462346042471590472760272209149359550402533424"], "outcomes":["Over", "Under"], "event_message":{"id":"542639", "ticker":"ufc-mel2-mur2-2026-06-20", "slug":"ufc-mel2-mur2-2026-06-20", "title":"UFC Fight Night: Melsik Baghdasaryan vs. Murtazali Magomedov (Featherweight, Main Card)", "description":"This market will resolve to \"Melsik Baghdasaryan\" if Melsik Baghdasaryan is officially declared the winner of the fight against Murtazali Magomedov at UFC Fight Night: Kape vs. Horiguchi, scheduled for June 20, 2026.\n\nIt will resolve to \"Murtazali Magomedov\" if Murtazali Magomedov is officially declared the winner.\n\nIf the fight is declared a draw or technical draw, ruled a No Contest, not scored, canceled, or postponed beyond July 4, 2026, this market will resolve \"50-50.\"\n\nThe resolution source for this market will be official information from the UFC."}, "timestamp":"1780179050160", "event_type":"new_market", "tags":[], "condition_id":"0xd51c305c1baf6b58dedc908dc90d87c61af9a17d02fcd9d2a33485d8e5fc4a56", "active":false, "clob_token_ids":["106144535144953904373915020925848550882454590179585810910664022237171288338863", "82993776222789397331431805628325462346042471590472760272209149359550402533424"], "sports_market_type":"totals", "line":"2.5", "game_start_time":"2026-06-20 17:00:00+00", "order_price_min_tick_size":"0.01", "group_item_title":"O/U 2.5 Rounds", "taker_base_fee":"1000", "fees_enabled":true, "fee_schedule":{"exponent":"1", "rate":"0.03", "taker_only":true, "rebate_rate":"0.25"}}
PONG
{"market":"0x4f3421fb2daf5cca7430ed8d8132463963081572d75434393a1808fdb8829fe8", "price_changes":[{"asset_id":"45415751658241142530386585138386640503488308219341470020075667342738719018629", "price":"0.49", "size":"119.6", "side":"SELL", "hash":"a9b9884bcf4e394c0ab6c028a70f189353bc42aa", "best_bid":"0.1", "best_ask":"0.101"}, {"asset_id":"31940783580344558651011323787577288681658737625185216525249046282994042503801", "price":"0.51", "size":"119.6", "side":"BUY", "hash":"b0af3588a7cd1ef7368deadb4d3603fc61b933f1", "best_bid":"0.899", "best_ask":"0.9"}], "timestamp":"1780179053458", "event_type":"price_change"}
{"market":"0x7876851632c295043c66536150a304cb785abdf712ba8489d298c6e6926be106", "price_changes":[{"asset_id":"97239126062673310243763617236644392945530356142765650402171508075574679292913", "price":"0.49", "size":"0", "side":"SELL", "hash":"35c0e415700756f0879f86ca4506cc2e6619a787", "best_bid":"0.01", "best_ask":"0.011"}, {"asset_id":"19291692040378529618917910599727571242305935029274321291612270922648172794670", "price":"0.51", "size":"0", "side":"BUY", "hash":"1199375e990daca61f3dd0ac6ace96ed03310b58", "best_bid":"0.989", "best_ask":"0.99"}], "timestamp":"1780179054578", "event_type":"price_change"}
{"market":"0x30d55d8124ee1e12dabe89201badc45669b81dff69e4ce44d961f32878ec178a", "price_changes":[{"asset_id":"27576533317283401577758999384642760405921738493660383550832555714312627457443", "price":"0.092", "size":"78375.52", "side":"SELL", "hash":"83b461c4907fb8b2cd0229adf93747627ec68879", "best_bid":"0.089", "best_ask":"0.09"}, {"asset_id":"52986718774908357330412653486471347449818893503063830313445318937088822580057", "price":"0.908", "size":"78375.52", "side":"BUY", "hash":"43150e32dd1a39a2622ee7004bb78415bdefd73b", "best_bid":"0.91", "best_ask":"0.911"}], "timestamp":"1780179055939", "event_type":"price_change"}
{"market":"0x1595b4818eeb1ea1e0bec5de6f057218e557feee9b405a0e930d290384fa1d16", "price_changes":[{"asset_id":"81739002353269632749850710185641576213562066971072676369728657545679630163887", "price":"0.053", "size":"3291.26", "side":"SELL", "hash":"f216993671e859e3ebb7d63085457fc2d8271be9", "best_bid":"0.051", "best_ask":"0.052"}, {"asset_id":"45484070731786948288366703334552551439356529561722304542938873238430842810537", "price":"0.947", "size":"3291.26", "side":"BUY", "hash":"841eac1c1509cc0038738205dca7c0410b09747f", "best_bid":"0.948", "best_ask":"0.949"}], "timestamp":"1780179055983", "event_type":"price_change"}
{"market":"0x7976b8dbacf9077eb1453a62bcefd6ab2df199acd28aad276ff0d920d6992892", "price_changes":[{"asset_id":"4394372887385518214471608448209527405727552777602031099972143344338178308080", "price":"0.17", "size":"27636.88", "side":"SELL", "hash":"043363fd15c9cf83a5350049459517950dc3f73e", "best_bid":"0.167", "best_ask":"0.168"}, {"asset_id":"112680630004798425069810935278212000865453267506345451433803052322987302357330", "price":"0.83", "size":"27636.88", "side":"BUY", "hash":"5fdcf33a2e471f8133af04842ef84bdd86df8dd2", "best_bid":"0.832", "best_ask":"0.833"}], "timestamp":"1780179055983", "event_type":"price_change"}
{"market":"0x0c4cd2055d6ea89354ffddc55d6dbcef9355748112ea952fc925f3db6a5c457f", "price_changes":[{"asset_id":"18812649149814341758733697580460697418474693998558159483117100240528657629879", "price":"0.088", "size":"15049.46", "side":"SELL", "hash":"d825e90c99d245bc2db15c0ae5caf22d516bd656", "best_bid":"0.085", "best_ask":"0.086"}, {"asset_id":"115428153746996892211798999366308897078723117634059783423375188043903703749062", "price":"0.912", "size":"15049.46", "side":"BUY", "hash":"f5b5e82e55f089914a8d976ab18d5d9026113155", "best_bid":"0.914", "best_ask":"0.915"}], "timestamp":"1780179055984", "event_type":"price_change"}
{"market":"0x30d55d8124ee1e12dabe89201badc45669b81dff69e4ce44d961f32878ec178a", "price_changes":[{"asset_id":"27576533317283401577758999384642760405921738493660383550832555714312627457443", "price":"0.092", "size":"78431.18", "side":"SELL", "hash":"66b9d608a4b74959f4e78ed82ca4c55e0c969cfe", "best_bid":"0.089", "best_ask":"0.09"}, {"asset_id":"52986718774908357330412653486471347449818893503063830313445318937088822580057", "price":"0.908", "size":"78431.18", "side":"BUY", "hash":"b18081976f986141064fdf75ca8c72781f5c88ab", "best_bid":"0.91", "best_ask":"0.911"}], "timestamp":"1780179056066", "event_type":"price_change"}
{"market":"0x1595b4818eeb1ea1e0bec5de6f057218e557feee9b405a0e930d290384fa1d16", "price_changes":[{"asset_id":"81739002353269632749850710185641576213562066971072676369728657545679630163887", "price":"0.053", "size":"3371.26", "side":"SELL", "hash":"439b5204898d09dca9f6ee4a387868f56dd8b034", "best_bid":"0.051", "best_ask":"0.052"}, {"asset_id":"45484070731786948288366703334552551439356529561722304542938873238430842810537", "price":"0.947", "size":"3371.26", "side":"BUY", "hash":"a8a27034bc2952c3e81fa0e79115f8be1c103b2d", "best_bid":"0.948", "best_ask":"0.949"}], "timestamp":"1780179056106", "event_type":"price_change"}
{"market":"0x7976b8dbacf9077eb1453a62bcefd6ab2df199acd28aad276ff0d920d6992892", "price_changes":[{"asset_id":"4394372887385518214471608448209527405727552777602031099972143344338178308080", "price":"0.17", "size":"27662.43", "side":"SELL", "hash":"3bf3a92418f6be4fd041241db3ef63579f2777b3", "best_bid":"0.167", "best_ask":"0.168"}, {"asset_id":"112680630004798425069810935278212000865453267506345451433803052322987302357330", "price":"0.83", "size":"27662.43", "side":"BUY", "hash":"7a0f121e4937c18c7628b391178b57cbbe4c4a3c", "best_bid":"0.832", "best_ask":"0.833"}], "timestamp":"1780179056110", "event_type":"price_change"}
{"market":"0x0c4cd2055d6ea89354ffddc55d6dbcef9355748112ea952fc925f3db6a5c457f", "price_changes":[{"asset_id":"18812649149814341758733697580460697418474693998558159483117100240528657629879", "price":"0.088", "size":"15129.46", "side":"SELL", "hash":"2a5ce6fc7790bffb42d7b7798212b23cf2716862", "best_bid":"0.085", "best_ask":"0.086"}, {"asset_id":"115428153746996892211798999366308897078723117634059783423375188043903703749062", "price":"0.912", "size":"15129.46", "side":"BUY", "hash":"e70484bf1c68b899a4b13b60b2da271c16ce621c", "best_bid":"0.914", "best_ask":"0.915"}], "timestamp":"1780179056111", "event_type":"price_change"}
{"id":"2397659", "question":"Centurion 2: Completed Match: Luc Koenig vs Semen Pankin", "market":"0x67fbfe8a3be42b85c4f1283b8aa2662b8675e6e779c7af4f83ea31403b8af218", "slug":"atp-koenig-pankin-2026-06-01-completed-match", "description":"This market refers to the tennis match between Luc Koenig and Semen Pankin in the Centurion 2, originally scheduled for June 1, 2026 at 4:00AM ET. This market will resolve to \"Yes\" if all games and sets required to determine a match winner under governing body or event organizer rules are played to completion through normal play. Otherwise, if the match is not completed for any reason, it will resolve to \"No.\" If a forfeit of any kind occurs, including but not limited to a walkover or retirement, this market will resolve \"No.\" If the match is canceled (not played at all), ends in a tie, or is delayed beyond 7 days from the scheduled date without a winner determined, this market will resolve to \"No.\" The primary resolution source for this market is the official statistics of the event as recognized by the governing body or event organizers. However, if the governing body or event organizers have not published final match statistics within 2 hours after the event's conclusion, a consensus of credible reporting may be used instead.", "assets_ids":["94141692820554019004142772918508296552513159103175357306754485757276303502374", "77685767708603670145632567801258504062606279702435794088217210196364275066294"], "outcomes":["Yes", "No"], "event_message":{"id":"542620", "ticker":"atp-koenig-pankin-2026-06-01", "slug":"atp-koenig-pankin-2026-06-01", "title":"Centurion 2: Luc Koenig vs Semen Pankin", "description":"This market refers to the tennis match between Luc Koenig and Semen Pankin in the Centurion 2, originally scheduled for June 1, 2026 at 4:00AM ET.\n\nThis market will resolve to 'Luc Koenig' if Luc Koenig advances against Semen Pankin.\n\nThis market will resolve to 'Semen Pankin' if Semen Pankin advances against Luc Koenig.\n\nIf the match is canceled (not played at all), ends in a tie, or is delayed beyond 7 days from the scheduled date without a winner determined, this market will resolve to 50-50.\n\nIf the match begins but is not completed, and one player advances due to the opponent's retirement, default, or disqualification, this market will resolve to the player who advances.\n\nIf the match ends in a walkover (player withdraws before the start and the other advances automatically), this market will resolve to 50-50.\n\nThe primary resolution source will be official information from the ATP Tour. A consensus of credible reporting may also be used."}, "timestamp":"1780179056994", "event_type":"new_market", "tags":[], "condition_id":"0x67fbfe8a3be42b85c4f1283b8aa2662b8675e6e779c7af4f83ea31403b8af218", "active":false, "clob_token_ids":["94141692820554019004142772918508296552513159103175357306754485757276303502374", "77685767708603670145632567801258504062606279702435794088217210196364275066294"], "sports_market_type":"tennis_completed_match", "line":"", "game_start_time":"2026-06-01 08:00:00+00", "order_price_min_tick_size":"0.01", "group_item_title":"Completed Match", "taker_base_fee":"1000", "fees_enabled":true, "fee_schedule":{"exponent":"1", "rate":"0.03", "taker_only":true, "rebate_rate":"0.25"}}
{"market":"0x1595b4818eeb1ea1e0bec5de6f057218e557feee9b405a0e930d290384fa1d16", "price_changes":[{"asset_id":"81739002353269632749850710185641576213562066971072676369728657545679630163887", "price":"0.49", "size":"0", "side":"SELL", "hash":"3a0968050a97f9b87685349a713f658f1b53591c", "best_bid":"0.051", "best_ask":"0.052"}, {"asset_id":"45484070731786948288366703334552551439356529561722304542938873238430842810537", "price":"0.51", "size":"0", "side":"BUY", "hash":"5a9572a0de3adc06045d621868931aff970e1a90", "best_bid":"0.948", "best_ask":"0.949"}], "timestamp":"1780179057989", "event_type":"price_change"}
{"market":"0x375409bc5eeeff961e82b479caeccc20f33d15738e5bce1186d628aa3d9dfb1f", "price_changes":[{"asset_id":"115556263888245616435851357148058235707004733438163639091106356867234218207169", "price":"0.115", "size":"11999.15", "side":"SELL", "hash":"8af55d12aa05dce7dcec50e467a7bbbd08493042", "best_bid":"0.112", "best_ask":"0.113"}, {"asset_id":"77121637225348873006259930776623502125079210522997384841464684944292365296940", "price":"0.885", "size":"11999.15", "side":"BUY", "hash":"36ca1fda6779f53ce43ab31f1414c0091ac070d1", "best_bid":"0.887", "best_ask":"0.888"}], "timestamp":"1780179058000", "event_type":"price_change"}
{"market":"0x9b6fef249040fd17e9c107955b37ac2c3e923509b6b0ff01cc463a331ddeb894", "price_changes":[{"asset_id":"108233603819467706476318984012158651931658302669301887462181073562758483842092", "price":"0.166", "size":"24926.68", "side":"SELL", "hash":"c43e747b9a0b4b52330373dcb6cc0155f05f03c8", "best_bid":"0.163", "best_ask":"0.164"}, {"asset_id":"32270411694523539495262303868629477861017829722282576458031815333486368239544", "price":"0.834", "size":"24926.68", "side":"BUY", "hash":"e1ad5d2b82340a2b49d3a35a52f635c71a10d15f", "best_bid":"0.836", "best_ask":"0.837"}], "timestamp":"1780179058007", "event_type":"price_change"}
{"market":"0x375409bc5eeeff961e82b479caeccc20f33d15738e5bce1186d628aa3d9dfb1f", "price_changes":[{"asset_id":"115556263888245616435851357148058235707004733438163639091106356867234218207169", "price":"0.115", "size":"12079.15", "side":"SELL", "hash":"bd5a30f77c54e45902e8b9a06012cea458bb3529", "best_bid":"0.112", "best_ask":"0.113"}, {"asset_id":"77121637225348873006259930776623502125079210522997384841464684944292365296940", "price":"0.885", "size":"12079.15", "side":"BUY", "hash":"02c447e724a36ce1e38dc81da5d860719f6b4dbd", "best_bid":"0.887", "best_ask":"0.888"}], "timestamp":"1780179058077", "event_type":"price_change"}
{"market":"0x9b6fef249040fd17e9c107955b37ac2c3e923509b6b0ff01cc463a331ddeb894", "price_changes":[{"asset_id":"108233603819467706476318984012158651931658302669301887462181073562758483842092", "price":"0.166", "size":"25006.68", "side":"SELL", "hash":"5a7800c83b35b8eaf9982d5bec3be2cb8ec8fedf", "best_bid":"0.163", "best_ask":"0.164"}, {"asset_id":"32270411694523539495262303868629477861017829722282576458031815333486368239544", "price":"0.834", "size":"25006.68", "side":"BUY", "hash":"2f16cc853317d529fc4ac8568ab7fe9c3181530a", "best_bid":"0.836", "best_ask":"0.837"}], "timestamp":"1780179058140", "event_type":"price_change"}
{"market":"0x4f3421fb2daf5cca7430ed8d8132463963081572d75434393a1808fdb8829fe8", "price_changes":[{"asset_id":"45415751658241142530386585138386640503488308219341470020075667342738719018629", "price":"0.103", "size":"18202.51", "side":"SELL", "hash":"ab302a6b5492b0436e790b1e85555db4c973113f", "best_bid":"0.1", "best_ask":"0.101"}, {"asset_id":"31940783580344558651011323787577288681658737625185216525249046282994042503801", "price":"0.897", "size":"18202.51", "side":"BUY", "hash":"f8f3ca4891254078b5dca019890cbca1ae3ff1b5", "best_bid":"0.899", "best_ask":"0.9"}], "timestamp":"1780179058471", "event_type":"price_change"}
{"market":"0x4f3421fb2daf5cca7430ed8d8132463963081572d75434393a1808fdb8829fe8", "price_changes":[{"asset_id":"45415751658241142530386585138386640503488308219341470020075667342738719018629", "price":"0.103", "size":"18263.31", "side":"SELL", "hash":"d58d0fd26905fd3fd3af5296c04d1f226e66aef8", "best_bid":"0.1", "best_ask":"0.101"}, {"asset_id":"31940783580344558651011323787577288681658737625185216525249046282994042503801", "price":"0.897", "size":"18263.31", "side":"BUY", "hash":"629485a8a45898b69783721d796c7342484ec9d1", "best_bid":"0.899", "best_ask":"0.9"}], "timestamp":"1780179058586", "event_type":"price_change"}
{"id":"2397647", "question":"ITF Kayseri: Duru Soke vs Deniz Dilek", "market":"0x04430caa34091f519d328577c9703a567cfb14901ae34c26f8442eaa27f510d5", "slug":"itf-soke-dilek-2026-05-31", "description":"This market refers to the tennis match between Duru Soke and Deniz Dilek in the ITF Women Kayseri, originally scheduled for May 31, 2026 at 3:00AM ET.\n\nThis market will resolve to 'Duru Soke' if Duru Soke advances against Deniz Dilek.\n\nThis market will resolve to 'Deniz Dilek' if Deniz Dilek advances against Duru Soke.\n\nIf the match is canceled (not played at all), ends in a tie, or is delayed beyond 7 days from the scheduled date without a winner determined, this market will resolve to 50-50.\n\nIf the match begins but is not completed, and one player advances due to the opponent's retirement, default, or disqualification, this market will resolve to the player who advances.\n\nIf the match ends in a walkover (player withdraws before the start and the other advances automatically), this market will resolve to 50-50.\n\nThe primary resolution source will be official information from the International Tennis Federation (ITF). A consensus of credible reporting may also be used.", "assets_ids":["49319680916978724932130493522874313198013630597982588043019620305340355683596", "74396207527442901525398006708892187868230671094983366798958584326532126308362"], "outcomes":["Duru Soke", "Deniz Dilek"], "event_message":{"id":"542617", "ticker":"itf-soke-dilek-2026-05-31", "slug":"itf-soke-dilek-2026-05-31", "title":"ITF Kayseri: Duru Soke vs Deniz Dilek", "description":"This market refers to the tennis match between Duru Soke and Deniz Dilek in the ITF Women Kayseri, originally scheduled for May 31, 2026 at 3:00AM ET.\n\nThis market will resolve to 'Duru Soke' if Duru Soke advances against Deniz Dilek.\n\nThis market will resolve to 'Deniz Dilek' if Deniz Dilek advances against Duru Soke.\n\nIf the match is canceled (not played at all), ends in a tie, or is delayed beyond 7 days from the scheduled date without a winner determined, this market will resolve to 50-50.\n\nIf the match begins but is not completed, and one player advances due to the opponent's retirement, default, or disqualification, this market will resolve to the player who advances.\n\nIf the match ends in a walkover (player withdraws before the start and the other advances automatically), this market will resolve to 50-50.\n\nThe primary resolution source will be official information from the International Tennis Federation (ITF). A consensus of credible reporting may also be used."}, "timestamp":"1780179059264", "event_type":"new_market", "tags":[], "condition_id":"0x04430caa34091f519d328577c9703a567cfb14901ae34c26f8442eaa27f510d5", "active":false, "clob_token_ids":["49319680916978724932130493522874313198013630597982588043019620305340355683596", "74396207527442901525398006708892187868230671094983366798958584326532126308362"], "sports_market_type":"moneyline", "line":"", "game_start_time":"2026-05-31 07:00:00+00", "order_price_min_tick_size":"0.01", "group_item_title":"", "taker_base_fee":"1000", "fees_enabled":true, "fee_schedule":{"exponent":"1", "rate":"0.03", "taker_only":true, "rebate_rate":"0.25"}}
{"id":"2397805", "question":"BNB Up or Down - June 1, 6PM ET", "market":"0x5a2d67dd11713a0103250eae8c73490407ccf2d65f9b381921f859e1a0b2fb98", "slug":"bnb-up-or-down-june-1-2026-6pm-et", "description":"This market will resolve to \"Up\" if the close price is greater than or equal to the open price for the BNB/USDT 1 hour candle that begins on the time and date specified in the title. Otherwise, this market will resolve to \"Down\".\n\nThe resolution source for this market is information from Binance, specifically the BNB/USDT pair (https://www.binance.com/en/trade/BNB_USDT). The close « C » and open « O » displayed at the top of the graph for the relevant \"1H\" candle will be used once the data for that candle is finalized.\n\nPlease note that this market is about the price according to Binance BNB/USDT, not according to other exchanges or trading pairs.", "assets_ids":["104326186094686307779257598600778833108045763124877901693365890967533282733760", "58966758276439043690391170682516481824800570213345373445729729739500115288051"], "outcomes":["Up", "Down"], "event_message":{"id":"542668", "ticker":"bnb-up-or-down-june-1-2026-6pm-et", "slug":"bnb-up-or-down-june-1-2026-6pm-et", "title":"BNB Up or Down - June 1, 6PM ET", "description":"This market will resolve to \"Up\" if the close price is greater than or equal to the open price for the BNB/USDT 1 hour candle that begins on the time and date specified in the title. Otherwise, this market will resolve to \"Down\".\n\nThe resolution source for this market is information from Binance, specifically the BNB/USDT pair (https://www.binance.com/en/trade/BNB_USDT). The close « C » and open « O » displayed at the top of the graph for the relevant \"1H\" candle will be used once the data for that candle is finalized.\n\nPlease note that this market is about the price according to Binance BNB/USDT, not according to other exchanges or trading pairs."}, "timestamp":"1780179059520", "event_type":"new_market", "tags":[], "condition_id":"0x5a2d67dd11713a0103250eae8c73490407ccf2d65f9b381921f859e1a0b2fb98", "active":false, "clob_token_ids":["104326186094686307779257598600778833108045763124877901693365890967533282733760", "58966758276439043690391170682516481824800570213345373445729729739500115288051"], "sports_market_type":"", "line":"", "game_start_time":"", "order_price_min_tick_size":"0.01", "group_item_title":"", "taker_base_fee":"1000", "fees_enabled":true, "fee_schedule":{"exponent":"1", "rate":"0.07", "taker_only":true, "rebate_rate":"0.2"}}
{"market":"0x4f3421fb2daf5cca7430ed8d8132463963081572d75434393a1808fdb8829fe8", "price_changes":[{"asset_id":"45415751658241142530386585138386640503488308219341470020075667342738719018629", "price":"0.49", "size":"205.76", "side":"SELL", "hash":"71ea671787ca89db2251568ace044747dfb92100", "best_bid":"0.1", "best_ask":"0.101"}, {"asset_id":"31940783580344558651011323787577288681658737625185216525249046282994042503801", "price":"0.51", "size":"205.76", "side":"BUY", "hash":"5dc502594e92cf21b03f5dde84ecfe0662baad31", "best_bid":"0.899", "best_ask":"0.9"}], "timestamp":"1780179061362", "event_type":"price_change"}
PONG
{"market":"0x7876851632c295043c66536150a304cb785abdf712ba8489d298c6e6926be106", "price_changes":[{"asset_id":"97239126062673310243763617236644392945530356142765650402171508075574679292913", "price":"0.49", "size":"7.97", "side":"SELL", "hash":"ab468f32ff842c1d260c9145ba49ee3df61538bc", "best_bid":"0.01", "best_ask":"0.011"}, {"asset_id":"19291692040378529618917910599727571242305935029274321291612270922648172794670", "price":"0.51", "size":"7.97", "side":"BUY", "hash":"436624efad3921b338e5c832d37fc2e6a9d9b6cf", "best_bid":"0.989", "best_ask":"0.99"}], "timestamp":"1780179063630", "event_type":"price_change"}
{"id":"2397867", "question":"Spread: Toronto Blue Jays (-1.5)", "market":"0xc4f2e0df80bd58d8aa9f9ce0f70de658227cbf62fa40dd962ac4ee5d0ff49b44", "slug":"mlb-tor-bal-2026-05-31-spread-away-1pt5", "description":"In the upcoming MLB game between the Toronto Blue Jays and Baltimore Orioles, scheduled for May 31 at 12:15 PM ET:\n\nThis market will resolve to \"Toronto Blue Jays\" if the Toronto Blue Jays win the game by 2 or more runs.\n\nOtherwise, this market will resolve to \"Baltimore Orioles\". If the game ends in a tie, this market will resolve to \"Baltimore Orioles\".\n\nIf the game is postponed, this market will remain open until the game has been completed. If the game is canceled entirely, with no make-up game, this market will resolve 50-50.\n\nTo know when a postponed game will be played, please check the home team's schedule on MLB.com for the listed team and look for the game described as a makeup game.\n\nThe primary resolution source for this market is the official final statistics of the event as recognized by the governing body or event organizers. However, if the governing body or event organizers have not published final match statistics within 24 hours after the event's conclusion, a consensus of credible reporting may be used instead.", "assets_ids":["31546674302660750550175823391222263466879433921751867444881912863918555444469", "25788177316091352351887032959807925290810624647417110080091363316141534892625"], "outcomes":["Toronto Blue Jays", "Baltimore Orioles"], "event_message":{"id":"523526", "ticker":"mlb-tor-bal-2026-05-31", "slug":"mlb-tor-bal-2026-05-31", "title":"Toronto Blue Jays vs. Baltimore Orioles", "description":"In the upcoming MLB game between the Toronto Blue Jays and Baltimore Orioles, scheduled for May 31 at 12:15PM ET:\n\nThis market will resolve to \"Toronto Blue Jays\" if the Toronto Blue Jays win the game.\n\nThis market will resolve to \"Baltimore Orioles\" if the Baltimore Orioles win the game.\n\nIf the game is postponed, this market will remain open until the game has been completed. If the game is canceled entirely, with no make-up game, or ends in a tie, this market will resolve 50-50.\n\nThe primary resolution source for this market is the official final statistics of the event as recognized by the governing body or event organizers. However, if the governing body or event organizers have not published final match statistics within 24 hours after the event's conclusion, a consensus of credible reporting may be used instead."}, "timestamp":"1780179064124", "event_type":"new_market", "tags":[], "condition_id":"0xc4f2e0df80bd58d8aa9f9ce0f70de658227cbf62fa40dd962ac4ee5d0ff49b44", "active":false, "clob_token_ids":["31546674302660750550175823391222263466879433921751867444881912863918555444469", "25788177316091352351887032959807925290810624647417110080091363316141534892625"], "sports_market_type":"spreads", "line":"-1.5", "game_start_time":"2026-05-31 16:15:00+00", "order_price_min_tick_size":"0.01", "group_item_title":"Spread -1.5", "taker_base_fee":"1000", "fees_enabled":true, "fee_schedule":{"exponent":"1", "rate":"0.03", "taker_only":true, "rebate_rate":"0.25"}}
{"market":"0x1595b4818eeb1ea1e0bec5de6f057218e557feee9b405a0e930d290384fa1d16", "price_changes":[{"asset_id":"81739002353269632749850710185641576213562066971072676369728657545679630163887", "price":"0.49", "size":"87.55", "side":"SELL", "hash":"617dbdc6d70cab8345d32c72b9b6844af6a97a0d", "best_bid":"0.051", "best_ask":"0.052"}, {"asset_id":"45484070731786948288366703334552551439356529561722304542938873238430842810537", "price":"0.51", "size":"87.55", "side":"BUY", "hash":"42dae54a25455a2f8ac80bf6cbce7ce2fd09219d", "best_bid":"0.948", "best_ask":"0.949"}], "timestamp":"1780179065970", "event_type":"price_change"}
{"id":"2397800", "question":"O/U 1.5 Rounds", "market":"0x32678644a33b1bc6b1d5d972d364fa0600330b712cd90a6c8c4d65ac66c65b3c", "slug":"ufc-jho1-jluiz-2026-06-20-totals-1pt5", "description":"Each market will resolve to \"Over\" if the fight between Jhonata Diniz and José Luiz at UFC Fight Night: Kape vs. Horiguchi, scheduled for June 20, 2026, lasts beyond the listed round threshold.\n\nEach market will resolve to \"Under\" if the fight does not last beyond the listed round threshold.\n\nFor example:\n\n\"Over 1.5 Rounds\" will resolve \"Yes\" if the fight continues past the 2:30 mark of Round 2.\n\n\"Under 1.5 Rounds\" will resolve \"Yes\" if the fight ends before the 2:30 mark of Round 2.\n\nIf the fight ends exactly at the threshold, it will resolve \"50-50.\"\n\nIf the bout is not scored, postponed beyond July 4, 2026, or canceled, all options will resolve \"50-50.\"\n\nThe resolution source for this market will be official information from the UFC.", "assets_ids":["60025473830137034094884232105460056531090596259920634922052072329095620125086", "50990784395985953764280145216430002332471093570320675654106596292159221159483"], "outcomes":["Over", "Under"], "event_message":{"id":"542664", "ticker":"ufc-jho1-jluiz-2026-06-20", "slug":"ufc-jho1-jluiz-2026-06-20", "title":"UFC Fight Night: Jhonata Diniz vs. José Luiz (Heavyweight, Prelims)", "description":"This market will resolve to \"Jhonata Diniz\" if Jhonata Diniz is officially declared the winner of the fight against José Luiz at UFC Fight Night: Kape vs. Horiguchi, scheduled for June 20, 2026.\n\nIt will resolve to \"José Luiz\" if José Luiz is officially declared the winner.\n\nIf the fight is declared a draw or technical draw, ruled a No Contest, not scored, canceled, or postponed beyond July 4, 2026, this market will resolve \"50-50.\"\n\nThe resolution source for this market will be official information from the UFC."}, "timestamp":"1780179066272", "event_type":"new_market", "tags":[], "condition_id":"0x32678644a33b1bc6b1d5d972d364fa0600330b712cd90a6c8c4d65ac66c65b3c", "active":false, "clob_token_ids":["60025473830137034094884232105460056531090596259920634922052072329095620125086", "50990784395985953764280145216430002332471093570320675654106596292159221159483"], "sports_market_type":"totals", "line":"1.5", "game_start_time":"2026-06-20 17:00:00+00", "order_price_min_tick_size":"0.01", "group_item_title":"O/U 1.5 Rounds", "taker_base_fee":"1000", "fees_enabled":true, "fee_schedule":{"exponent":"1", "rate":"0.03", "taker_only":true, "rebate_rate":"0.25"}}
{"id":"2397613", "question":"ITF Wuning: Alexandra Shubladze vs Hina Inoue", "market":"0x7598cc67453bcc0305706001b348f5afa4faa630d492663cb22cbf804e61c5c3", "slug":"itf-shublad-inoue-2026-05-31", "description":"This market refers to the tennis match between Alexandra Shubladze and Hina Inoue in the ITF Women Wuning, originally scheduled for May 30, 2026 at 11:00PM ET.\n\nThis market will resolve to 'Alexandra Shubladze' if Alexandra Shubladze advances against Hina Inoue.\n\nThis market will resolve to 'Hina Inoue' if Hina Inoue advances against Alexandra Shubladze.\n\nIf the match is canceled (not played at all), ends in a tie, or is delayed beyond 7 days from the scheduled date without a winner determined, this market will resolve to 50-50.\n\nIf the match begins but is not completed, and one player advances due to the opponent's retirement, default, or disqualification, this market will resolve to the player who advances.\n\nIf the match ends in a walkover (player withdraws before the start and the other advances automatically), this market will resolve to 50-50.\n\nThe primary resolution source will be official information from the International Tennis Federation (ITF). A consensus of credible reporting may also be used.", "assets_ids":["36814734580494350230837913387093426372021978651394448830818952885207839690464", "102354121579332438686068321905489246391400400679160123190173201655347829226033"], "outcomes":["Alexandra Shubladze", "Hina Inoue"], "event_message":{"id":"542605", "ticker":"itf-shublad-inoue-2026-05-31", "slug":"itf-shublad-inoue-2026-05-31", "title":"ITF Wuning: Alexandra Shubladze vs Hina Inoue", "description":"This market refers to the tennis match between Alexandra Shubladze and Hina Inoue in the ITF Women Wuning, originally scheduled for May 30, 2026 at 11:00PM ET.\n\nThis market will resolve to 'Alexandra Shubladze' if Alexandra Shubladze advances against Hina Inoue.\n\nThis market will resolve to 'Hina Inoue' if Hina Inoue advances against Alexandra Shubladze.\n\nIf the match is canceled (not played at all), ends in a tie, or is delayed beyond 7 days from the scheduled date without a winner determined, this market will resolve to 50-50.\n\nIf the match begins but is not completed, and one player advances due to the opponent's retirement, default, or disqualification, this market will resolve to the player who advances.\n\nIf the match ends in a walkover (player withdraws before the start and the other advances automatically), this market will resolve to 50-50.\n\nThe primary resolution source will be official information from the International Tennis Federation (ITF). A consensus of credible reporting may also be used."}, "timestamp":"1780179068131", "event_type":"new_market", "tags":[], "condition_id":"0x7598cc67453bcc0305706001b348f5afa4faa630d492663cb22cbf804e61c5c3", "active":false, "clob_token_ids":["36814734580494350230837913387093426372021978651394448830818952885207839690464", "102354121579332438686068321905489246391400400679160123190173201655347829226033"], "sports_market_type":"moneyline", "line":"", "game_start_time":"2026-05-31 03:00:00+00", "order_price_min_tick_size":"0.01", "group_item_title":"", "taker_base_fee":"1000", "fees_enabled":true, "fee_schedule":{"exponent":"1", "rate":"0.03", "taker_only":true, "rebate_rate":"0.25"}}
{"id":"2397880", "question":"Dogecoin Up or Down - May 31, 6:00PM-6:05PM ET", "market":"0x821980b4433363a53068fd98aefbb91cd14a8f9f17100e0c8451e654ab937a12", "slug":"doge-updown-5m-1780264800", "description":"This market will resolve to \"Up\" if the Dogecoin price at the end of the time range specified in the title is greater than or equal to the price at the beginning of that range. Otherwise, it will resolve to \"Down\".\nThe resolution source for this market is information from Chainlink, specifically the DOGE/USD data stream available at https://data.chain.link/streams/doge-usd.\nPlease note that this market is about the price according to Chainlink data stream DOGE/USD, not according to other sources or spot markets.", "assets_ids":["89183881606899477820255597477392915732590882395515349236863940532505591852991", "19734858552617284093263561949183075542169244307145429125757148115337880505330"], "outcomes":["Up", "Down"], "event_message":{"id":"542702", "ticker":"doge-updown-5m-1780264800", "slug":"doge-updown-5m-1780264800", "title":"Dogecoin Up or Down - May 31, 6:00PM-6:05PM ET", "description":"This market will resolve to \"Up\" if the Dogecoin price at the end of the time range specified in the title is greater than or equal to the price at the beginning of that range. Otherwise, it will resolve to \"Down\".\nThe resolution source for this market is information from Chainlink, specifically the DOGE/USD data stream available at https://data.chain.link/streams/doge-usd.\nPlease note that this market is about the price according to Chainlink data stream DOGE/USD, not according to other sources or spot markets."}, "timestamp":"1780179069349", "event_type":"new_market", "tags":[], "condition_id":"0x821980b4433363a53068fd98aefbb91cd14a8f9f17100e0c8451e654ab937a12", "active":false, "clob_token_ids":["89183881606899477820255597477392915732590882395515349236863940532505591852991", "19734858552617284093263561949183075542169244307145429125757148115337880505330"], "sports_market_type":"", "line":"", "game_start_time":"", "order_price_min_tick_size":"0.01", "group_item_title":"", "taker_base_fee":"1000", "fees_enabled":true, "fee_schedule":{"exponent":"1", "rate":"0.07", "taker_only":true, "rebate_rate":"0.2"}}
{"market":"0x30d55d8124ee1e12dabe89201badc45669b81dff69e4ce44d961f32878ec178a", "price_changes":[{"asset_id":"52986718774908357330412653486471347449818893503063830313445318937088822580057", "price":"0.88", "size":"133.12", "side":"BUY", "hash":"5e273251873d2e4460b4ccf9a75331e175f3b565", "best_bid":"0.91", "best_ask":"0.911"}, {"asset_id":"27576533317283401577758999384642760405921738493660383550832555714312627457443", "price":"0.12", "size":"133.12", "side":"SELL", "hash":"91511cdf1c951316752d0a4ca8e91e838a9e74e0", "best_bid":"0.089", "best_ask":"0.09"}], "timestamp":"1780179071396", "event_type":"price_change"}
{"market":"0x7876851632c295043c66536150a304cb785abdf712ba8489d298c6e6926be106", "price_changes":[{"asset_id":"19291692040378529618917910599727571242305935029274321291612270922648172794670", "price":"0.957", "size":"3045", "side":"BUY", "hash":"6239e682a4bdc10b34c8005b52c562bdec64cad0", "best_bid":"0.989", "best_ask":"0.99"}, {"asset_id":"97239126062673310243763617236644392945530356142765650402171508075574679292913", "price":"0.043", "size":"3045", "side":"SELL", "hash":"d07bb4af752a624f9b542050c7d98c2810dafc96", "best_bid":"0.01", "best_ask":"0.011"}], "timestamp":"1780179071397", "event_type":"price_change"}
{"market":"0x0c4cd2055d6ea89354ffddc55d6dbcef9355748112ea952fc925f3db6a5c457f", "price_changes":[{"asset_id":"115428153746996892211798999366308897078723117634059783423375188043903703749062", "price":"0.884", "size":"10834.73", "side":"BUY", "hash":"b899c681271523d7dae9e02bc62a414f66c55eab", "best_bid":"0.914", "best_ask":"0.915"}, {"asset_id":"18812649149814341758733697580460697418474693998558159483117100240528657629879", "price":"0.116", "size":"10834.73", "side":"SELL", "hash":"bd27b3721d87be7f7a457b519bc2d5616e9ef8e5", "best_bid":"0.085", "best_ask":"0.086"}], "timestamp":"1780179071397", "event_type":"price_change"}
{"market":"0x7976b8dbacf9077eb1453a62bcefd6ab2df199acd28aad276ff0d920d6992892", "price_changes":[{"asset_id":"112680630004798425069810935278212000865453267506345451433803052322987302357330", "price":"0.804", "size":"45", "side":"BUY", "hash":"b019c657ef51c85eecceca791e5f7f282954e9cd", "best_bid":"0.832", "best_ask":"0.833"}, {"asset_id":"4394372887385518214471608448209527405727552777602031099972143344338178308080", "price":"0.196", "size":"45", "side":"SELL", "hash":"86922a02e90eb00863e8ce384c12d1a714ca109f", "best_bid":"0.167", "best_ask":"0.168"}], "timestamp":"1780179071394", "event_type":"price_change"}
{"market":"0x4f3421fb2daf5cca7430ed8d8132463963081572d75434393a1808fdb8829fe8", "price_changes":[{"asset_id":"31940783580344558651011323787577288681658737625185216525249046282994042503801", "price":"0.869", "size":"45", "side":"BUY", "hash":"a25674358d1685cbd9320ef0f0fa557c5f74bba9", "best_bid":"0.899", "best_ask":"0.9"}, {"asset_id":"45415751658241142530386585138386640503488308219341470020075667342738719018629", "price":"0.131", "size":"45", "side":"SELL", "hash":"54a72555e10f1fb2c53be93069584e119efb6ace", "best_bid":"0.1", "best_ask":"0.101"}], "timestamp":"1780179071404", "event_type":"price_change"}
{"market":"0x4f3421fb2daf5cca7430ed8d8132463963081572d75434393a1808fdb8829fe8", "price_changes":[{"asset_id":"31940783580344558651011323787577288681658737625185216525249046282994042503801", "price":"0.859", "size":"50", "side":"BUY", "hash":"34e26dc9d656adf1918c9338d8c444938778ae97", "best_bid":"0.899", "best_ask":"0.9"}, {"asset_id":"45415751658241142530386585138386640503488308219341470020075667342738719018629", "price":"0.141", "size":"50", "side":"SELL", "hash":"8d1423a1d3c093b25f28a9e721e9d7c769dcc953", "best_bid":"0.1", "best_ask":"0.101"}], "timestamp":"1780179071412", "event_type":"price_change"}
{"market":"0x1595b4818eeb1ea1e0bec5de6f057218e557feee9b405a0e930d290384fa1d16", "price_changes":[{"asset_id":"45484070731786948288366703334552551439356529561722304542938873238430842810537", "price":"0.917", "size":"45", "side":"BUY", "hash":"568c03e17534f27e34c07ad69951aab327b0f1fc", "best_bid":"0.948", "best_ask":"0.949"}, {"asset_id":"81739002353269632749850710185641576213562066971072676369728657545679630163887", "price":"0.083", "size":"45", "side":"SELL", "hash":"2f2695db16b2472b76704bb2f63e4bc60053051d", "best_bid":"0.051", "best_ask":"0.052"}], "timestamp":"1780179071407", "event_type":"price_change"}
{"market":"0x0c4cd2055d6ea89354ffddc55d6dbcef9355748112ea952fc925f3db6a5c457f", "price_changes":[{"asset_id":"115428153746996892211798999366308897078723117634059783423375188043903703749062", "price":"0.894", "size":"557.92", "side":"BUY", "hash":"a0a83978009c962449ab4bd3fdde414ad76f3780", "best_bid":"0.914", "best_ask":"0.915"}, {"asset_id":"18812649149814341758733697580460697418474693998558159483117100240528657629879", "price":"0.106", "size":"557.92", "side":"SELL", "hash":"337aa995d6d57c77797a881b2d0295ce60315bb9", "best_bid":"0.085", "best_ask":"0.086"}], "timestamp":"1780179071440", "event_type":"price_change"}
{"market":"0x9b6fef249040fd17e9c107955b37ac2c3e923509b6b0ff01cc463a331ddeb894", "price_changes":[{"asset_id":"32270411694523539495262303868629477861017829722282576458031815333486368239544", "price":"0.816", "size":"10939.83", "side":"BUY", "hash":"6d140436e87e6a95f22584d3bc61024b7eb14907", "best_bid":"0.836", "best_ask":"0.837"}, {"asset_id":"108233603819467706476318984012158651931658302669301887462181073562758483842092", "price":"0.184", "size":"10939.83", "side":"SELL", "hash":"210ebc64a1985cd37744b08dda5ca15a589c1cde", "best_bid":"0.163", "best_ask":"0.164"}], "timestamp":"1780179071449", "event_type":"price_change"}
{"market":"0x375409bc5eeeff961e82b479caeccc20f33d15738e5bce1186d628aa3d9dfb1f", "price_changes":[{"asset_id":"77121637225348873006259930776623502125079210522997384841464684944292365296940", "price":"0.866", "size":"141.44", "side":"BUY", "hash":"c9023e338275f421828031381018deac146f7c60", "best_bid":"0.887", "best_ask":"0.888"}, {"asset_id":"115556263888245616435851357148058235707004733438163639091106356867234218207169", "price":"0.134", "size":"141.44", "side":"SELL", "hash":"e2c8379c489831a8d8e1ac9d585113e96b71a9b9", "best_bid":"0.112", "best_ask":"0.113"}], "timestamp":"1780179071450", "event_type":"price_change"}
{"market":"0x7976b8dbacf9077eb1453a62bcefd6ab2df199acd28aad276ff0d920d6992892", "price_changes":[{"asset_id":"112680630004798425069810935278212000865453267506345451433803052322987302357330", "price":"0.804", "size":"0", "side":"BUY", "hash":"ad461ba0051a4abcd40d98364df4997ee7f72871", "best_bid":"0.832", "best_ask":"0.833"}, {"asset_id":"4394372887385518214471608448209527405727552777602031099972143344338178308080", "price":"0.196", "size":"0", "side":"SELL", "hash":"6a863639e7196cf6b949866d31b4e7f95700695b", "best_bid":"0.167", "best_ask":"0.168"}], "timestamp":"1780179071446", "event_type":"price_change"}
{"market":"0x1595b4818eeb1ea1e0bec5de6f057218e557feee9b405a0e930d290384fa1d16", "price_changes":[{"asset_id":"45484070731786948288366703334552551439356529561722304542938873238430842810537", "price":"0.926", "size":"3974.76", "side":"BUY", "hash":"f39f5e6c7c0e2981701852e493a4783f7af1067c", "best_bid":"0.948", "best_ask":"0.949"}, {"asset_id":"81739002353269632749850710185641576213562066971072676369728657545679630163887", "price":"0.074", "size":"3974.76", "side":"SELL", "hash":"02317a1105cb09bb13f0488b0669b83a9e2d2533", "best_bid":"0.051", "best_ask":"0.052"}], "timestamp":"1780179071442", "event_type":"price_change"}
{"market":"0x0c4cd2055d6ea89354ffddc55d6dbcef9355748112ea952fc925f3db6a5c457f", "price_changes":[{"asset_id":"115428153746996892211798999366308897078723117634059783423375188043903703749062", "price":"0.893", "size":"30", "side":"BUY", "hash":"fd23357434fa2d9ac681e5b011890a8ad96d4ff4", "best_bid":"0.914", "best_ask":"0.915"}, {"asset_id":"18812649149814341758733697580460697418474693998558159483117100240528657629879", "price":"0.107", "size":"30", "side":"SELL", "hash":"8101640749ac6cd2343374643606bc7e3a3aec74", "best_bid":"0.085", "best_ask":"0.086"}], "timestamp":"1780179071486", "event_type":"price_change"}
{"market":"0x4f3421fb2daf5cca7430ed8d8132463963081572d75434393a1808fdb8829fe8", "price_changes":[{"asset_id":"31940783580344558651011323787577288681658737625185216525249046282994042503801", "price":"0.878", "size":"0", "side":"BUY", "hash":"d1e340ed359359b10052db5f8a576236b5418b7f", "best_bid":"0.899", "best_ask":"0.9"}, {"asset_id":"45415751658241142530386585138386640503488308219341470020075667342738719018629", "price":"0.122", "size":"0", "side":"SELL", "hash":"40c54b5486e6dc6759a339e6aef76193a4e09d7e", "best_bid":"0.1", "best_ask":"0.101"}], "timestamp":"1780179071488", "event_type":"price_change"}
{"market":"0x7876851632c295043c66536150a304cb785abdf712ba8489d298c6e6926be106", "price_changes":[{"asset_id":"19291692040378529618917910599727571242305935029274321291612270922648172794670", "price":"0.966", "size":"30", "side":"BUY", "hash":"7718e650a2bdb86c7deac1eba95b885060c98b86", "best_bid":"0.989", "best_ask":"0.99"}, {"asset_id":"97239126062673310243763617236644392945530356142765650402171508075574679292913", "price":"0.034", "size":"30", "side":"SELL", "hash":"ff11938de1348cc912584e63d5c1c43d8a147f78", "best_bid":"0.01", "best_ask":"0.011"}], "timestamp":"1780179071487", "event_type":"price_change"}
{"market":"0x7976b8dbacf9077eb1453a62bcefd6ab2df199acd28aad276ff0d920d6992892", "price_changes":[{"asset_id":"112680630004798425069810935278212000865453267506345451433803052322987302357330", "price":"0.803", "size":"45", "side":"BUY", "hash":"6d890bca2002a6c4e001525458eebe157f210c78", "best_bid":"0.832", "best_ask":"0.833"}, {"asset_id":"4394372887385518214471608448209527405727552777602031099972143344338178308080", "price":"0.197", "size":"45", "side":"SELL", "hash":"1df03dbeb89bdf12d14475e69c55f1212a7b7dfc", "best_bid":"0.167", "best_ask":"0.168"}], "timestamp":"1780179071494", "event_type":"price_change"}
{"market":"0x30d55d8124ee1e12dabe89201badc45669b81dff69e4ce44d961f32878ec178a", "price_changes":[{"asset_id":"52986718774908357330412653486471347449818893503063830313445318937088822580057", "price":"0.889", "size":"30", "side":"BUY", "hash":"fb4cabb296f54c44800da3f2941091799ba69893", "best_bid":"0.91", "best_ask":"0.911"}, {"asset_id":"27576533317283401577758999384642760405921738493660383550832555714312627457443", "price":"0.111", "size":"30", "side":"SELL", "hash":"83d346253ca2a77a42456503ef6c111c37e593e5", "best_bid":"0.089", "best_ask":"0.09"}], "timestamp":"1780179071489", "event_type":"price_change"}
{"market":"0x1595b4818eeb1ea1e0bec5de6f057218e557feee9b405a0e930d290384fa1d16", "price_changes":[{"asset_id":"45484070731786948288366703334552551439356529561722304542938873238430842810537", "price":"0.927", "size":"5462.38", "side":"BUY", "hash":"a6c31b4596daaf7f92fb9501629d5fe31eaca464", "best_bid":"0.948", "best_ask":"0.949"}, {"asset_id":"81739002353269632749850710185641576213562066971072676369728657545679630163887", "price":"0.073", "size":"5462.38", "side":"SELL", "hash":"e243753b67b9368c4afbb40bf75785e4275f5a11", "best_bid":"0.051", "best_ask":"0.052"}], "timestamp":"1780179071504", "event_type":"price_change"}
{"market":"0x0c4cd2055d6ea89354ffddc55d6dbcef9355748112ea952fc925f3db6a5c457f", "price_changes":[{"asset_id":"115428153746996892211798999366308897078723117634059783423375188043903703749062", "price":"0.885", "size":"828", "side":"BUY", "hash":"d2b86bc30ef3a849cf4b1e853e66c084d902dc1b", "best_bid":"0.914", "best_ask":"0.915"}, {"asset_id":"18812649149814341758733697580460697418474693998558159483117100240528657629879", "price":"0.115", "size":"828", "side":"SELL", "hash":"5fee9720474e719d538fe76958eb0ea1dcf6b81e", "best_bid":"0.085", "best_ask":"0.086"}], "timestamp":"1780179071569", "event_type":"price_change"}
{"market":"0x7976b8dbacf9077eb1453a62bcefd6ab2df199acd28aad276ff0d920d6992892", "price_changes":[{"asset_id":"112680630004798425069810935278212000865453267506345451433803052322987302357330", "price":"0.804", "size":"1000", "side":"BUY", "hash":"f616b8e847da255028587030497aba4992315a8f", "best_bid":"0.832", "best_ask":"0.833"}, {"asset_id":"4394372887385518214471608448209527405727552777602031099972143344338178308080", "price":"0.196", "size":"1000", "side":"SELL", "hash":"69e62ec5a31cec3d0fde52f9c2b35ec7b00ea752", "best_bid":"0.167", "best_ask":"0.168"}], "timestamp":"1780179071578", "event_type":"price_change"}
{"market":"0x4f3421fb2daf5cca7430ed8d8132463963081572d75434393a1808fdb8829fe8", "price_changes":[{"asset_id":"31940783580344558651011323787577288681658737625185216525249046282994042503801", "price":"0.87", "size":"5000", "side":"BUY", "hash":"3c952e2a835fb988027af5c10a37cd106326644e", "best_bid":"0.899", "best_ask":"0.9"}, {"asset_id":"45415751658241142530386585138386640503488308219341470020075667342738719018629", "price":"0.13", "size":"5000", "side":"SELL", "hash":"fbf50f4e3c9a4d34dbb47aa3f53252b05a54bd50", "best_bid":"0.1", "best_ask":"0.101"}], "timestamp":"1780179071588", "event_type":"price_change"}
{"market":"0x375409bc5eeeff961e82b479caeccc20f33d15738e5bce1186d628aa3d9dfb1f", "price_changes":[{"asset_id":"77121637225348873006259930776623502125079210522997384841464684944292365296940", "price":"0.867", "size":"15212.7", "side":"BUY", "hash":"76461ac309cd4a4902059367fd8d48752fc46da1", "best_bid":"0.887", "best_ask":"0.888"}, {"asset_id":"115556263888245616435851357148058235707004733438163639091106356867234218207169", "price":"0.133", "size":"15212.7", "side":"SELL", "hash":"419d3aa3f17d9b600af823023702ed1c7695dd19", "best_bid":"0.112", "best_ask":"0.113"}], "timestamp":"1780179071611", "event_type":"price_change"}
{"market":"0x4f3421fb2daf5cca7430ed8d8132463963081572d75434393a1808fdb8829fe8", "price_changes":[{"asset_id":"31940783580344558651011323787577288681658737625185216525249046282994042503801", "price":"0.879", "size":"202.7", "side":"BUY", "hash":"aba9d97c8f3840085ca1345f3affb0819cc83959", "best_bid":"0.899", "best_ask":"0.9"}, {"asset_id":"45415751658241142530386585138386640503488308219341470020075667342738719018629", "price":"0.121", "size":"202.7", "side":"SELL", "hash":"124a19def00fb46276030a69f0ea99c33ea0f00a", "best_bid":"0.1", "best_ask":"0.101"}], "timestamp":"1780179071614", "event_type":"price_change"}
{"market":"0x7876851632c295043c66536150a304cb785abdf712ba8489d298c6e6926be106", "price_changes":[{"asset_id":"19291692040378529618917910599727571242305935029274321291612270922648172794670", "price":"0.958", "size":"3793", "side":"BUY", "hash":"e23de98811d535f63a5924d6498756cd20ea4170", "best_bid":"0.989", "best_ask":"0.99"}, {"asset_id":"97239126062673310243763617236644392945530356142765650402171508075574679292913", "price":"0.042", "size":"3793", "side":"SELL", "hash":"069c590bd7b938d77e31f4dfb3e79b757940b011", "best_bid":"0.01", "best_ask":"0.011"}], "timestamp":"1780179071636", "event_type":"price_change"}
{"market":"0x9b6fef249040fd17e9c107955b37ac2c3e923509b6b0ff01cc463a331ddeb894", "price_changes":[{"asset_id":"32270411694523539495262303868629477861017829722282576458031815333486368239544", "price":"0.817", "size":"7752.15", "side":"BUY", "hash":"cc9b920ec4d53362e8c3620379f7a3e7de338210", "best_bid":"0.836", "best_ask":"0.837"}, {"asset_id":"108233603819467706476318984012158651931658302669301887462181073562758483842092", "price":"0.183", "size":"7752.15", "side":"SELL", "hash":"6b1c7eceaf110265ddc9380f1eac66ae1f67199a", "best_bid":"0.163", "best_ask":"0.164"}], "timestamp":"1780179071639", "event_type":"price_change"}
{"market":"0x4f3421fb2daf5cca7430ed8d8132463963081572d75434393a1808fdb8829fe8", "price_changes":[{"asset_id":"31940783580344558651011323787577288681658737625185216525249046282994042503801", "price":"0.86", "size":"1034.6", "side":"BUY", "hash":"ce9ed33deaafd938b0109775cfad3bf3afdc2cd5", "best_bid":"0.899", "best_ask":"0.9"}, {"asset_id":"45415751658241142530386585138386640503488308219341470020075667342738719018629", "price":"0.14", "size":"1034.6", "side":"SELL", "hash":"c55ce9ed71c85d3e08638947efb5bb004cfb3df1", "best_bid":"0.1", "best_ask":"0.101"}], "timestamp":"1780179071643", "event_type":"price_change"}
{"market":"0x30d55d8124ee1e12dabe89201badc45669b81dff69e4ce44d961f32878ec178a", "price_changes":[{"asset_id":"52986718774908357330412653486471347449818893503063830313445318937088822580057", "price":"0.881", "size":"942", "side":"BUY", "hash":"84c9ed0b9be16ed116f2171ae75e7723a7b0e8c3", "best_bid":"0.91", "best_ask":"0.911"}, {"asset_id":"27576533317283401577758999384642760405921738493660383550832555714312627457443", "price":"0.119", "size":"942", "side":"SELL", "hash":"9f01afe272e741ab021190ec6299a7f56a21cfd7", "best_bid":"0.089", "best_ask":"0.09"}], "timestamp":"1780179071669", "event_type":"price_change"}
{"market":"0x30d55d8124ee1e12dabe89201badc45669b81dff69e4ce44d961f32878ec178a", "price_changes":[{"asset_id":"52986718774908357330412653486471347449818893503063830313445318937088822580057", "price":"0.89", "size":"30501.81", "side":"BUY", "hash":"324aec53a59a0368b1eb4c27720f910137c5e7dd", "best_bid":"0.91", "best_ask":"0.911"}, {"asset_id":"27576533317283401577758999384642760405921738493660383550832555714312627457443", "price":"0.11", "size":"30501.81", "side":"SELL", "hash":"311b1d880587fee720d97c06b84847fd3b20647e", "best_bid":"0.089", "best_ask":"0.09"}], "timestamp":"1780179071679", "event_type":"price_change"}
{"market":"0x1595b4818eeb1ea1e0bec5de6f057218e557feee9b405a0e930d290384fa1d16", "price_changes":[{"asset_id":"45484070731786948288366703334552551439356529561722304542938873238430842810537", "price":"0.918", "size":"1468", "side":"BUY", "hash":"a317df8444a2619ad0f9b0ae947d377ed4459e9d", "best_bid":"0.948", "best_ask":"0.949"}, {"asset_id":"81739002353269632749850710185641576213562066971072676369728657545679630163887", "price":"0.082", "size":"1468", "side":"SELL", "hash":"edb5e975a000094db716addec227df14dd9178cf", "best_bid":"0.051", "best_ask":"0.052"}], "timestamp":"1780179071687", "event_type":"price_change"}
{"market":"0x7876851632c295043c66536150a304cb785abdf712ba8489d298c6e6926be106", "price_changes":[{"asset_id":"19291692040378529618917910599727571242305935029274321291612270922648172794670", "price":"0.967", "size":"10626.7", "side":"BUY", "hash":"3fcae0186d04e4eea9438b9a282f154d5ac81ba5", "best_bid":"0.989", "best_ask":"0.99"}, {"asset_id":"97239126062673310243763617236644392945530356142765650402171508075574679292913", "price":"0.033", "size":"10626.7", "side":"SELL", "hash":"9311fb45a7761b0614aa3be32d4b8f385263f7ba", "best_bid":"0.01", "best_ask":"0.011"}], "timestamp":"1780179071689", "event_type":"price_change"}
PONG
{"market":"0x4f3421fb2daf5cca7430ed8d8132463963081572d75434393a1808fdb8829fe8", "price_changes":[{"asset_id":"45415751658241142530386585138386640503488308219341470020075667342738719018629", "price":"0.103", "size":"18203.31", "side":"SELL", "hash":"8e40a73f5057f280de1c6adcffda07794f70eebd", "best_bid":"0.1", "best_ask":"0.101"}, {"asset_id":"31940783580344558651011323787577288681658737625185216525249046282994042503801", "price":"0.897", "size":"18203.31", "side":"BUY", "hash":"d47f20c7ed851853e2ae83e02512236ea1c80492", "best_bid":"0.899", "best_ask":"0.9"}], "timestamp":"1780179074118", "event_type":"price_change"}
{"market":"0x9b6fef249040fd17e9c107955b37ac2c3e923509b6b0ff01cc463a331ddeb894", "price_changes":[{"asset_id":"108233603819467706476318984012158651931658302669301887462181073562758483842092", "price":"0.166", "size":"24952", "side":"SELL", "hash":"1cc168e8a1f17664f88c2be71f6b09f93adfb3f7", "best_bid":"0.163", "best_ask":"0.164"}, {"asset_id":"32270411694523539495262303868629477861017829722282576458031815333486368239544", "price":"0.834", "size":"24952", "side":"BUY", "hash":"1a151eba40fedd6bbbc03c4ed11287bb8face429", "best_bid":"0.836", "best_ask":"0.837"}], "timestamp":"1780179074120", "event_type":"price_change"}
{"market":"0x9b6fef249040fd17e9c107955b37ac2c3e923509b6b0ff01cc463a331ddeb894", "price_changes":[{"asset_id":"108233603819467706476318984012158651931658302669301887462181073562758483842092", "price":"0.166", "size":"25006.71", "side":"SELL", "hash":"7425e315ef77d6ca7171546a70c4efb0ac42eb46", "best_bid":"0.163", "best_ask":"0.164"}, {"asset_id":"32270411694523539495262303868629477861017829722282576458031815333486368239544", "price":"0.834", "size":"25006.71", "side":"BUY", "hash":"fc370ed2deebe55e9d08e0ef6951007540156fa5", "best_bid":"0.836", "best_ask":"0.837"}], "timestamp":"1780179074207", "event_type":"price_change"}
{"market":"0x4f3421fb2daf5cca7430ed8d8132463963081572d75434393a1808fdb8829fe8", "price_changes":[{"asset_id":"45415751658241142530386585138386640503488308219341470020075667342738719018629", "price":"0.103", "size":"18263.31", "side":"SELL", "hash":"57b8790eebdb4285e46990c5aea5fd9439a750a4", "best_bid":"0.1", "best_ask":"0.101"}, {"asset_id":"31940783580344558651011323787577288681658737625185216525249046282994042503801", "price":"0.897", "size":"18263.31", "side":"BUY", "hash":"c912f1a59c397fdc6e4ef1183ffe8e7f1bad3174", "best_bid":"0.899", "best_ask":"0.9"}], "timestamp":"1780179074219", "event_type":"price_change"}
{"market":"0x7976b8dbacf9077eb1453a62bcefd6ab2df199acd28aad276ff0d920d6992892", "price_changes":[{"asset_id":"4394372887385518214471608448209527405727552777602031099972143344338178308080", "price":"0.17", "size":"27608.28", "side":"SELL", "hash":"b7eea72d48d8128a809b399ad4ce8a39227ab605", "best_bid":"0.167", "best_ask":"0.168"}, {"asset_id":"112680630004798425069810935278212000865453267506345451433803052322987302357330", "price":"0.83", "size":"27608.28", "side":"BUY", "hash":"58d26bc86e5c385e62c82bebefddce261910f9c7", "best_bid":"0.832", "best_ask":"0.833"}], "timestamp":"1780179075519", "event_type":"price_change"}
{"market":"0x30d55d8124ee1e12dabe89201badc45669b81dff69e4ce44d961f32878ec178a", "price_changes":[{"asset_id":"27576533317283401577758999384642760405921738493660383550832555714312627457443", "price":"0.092", "size":"78371.18", "side":"SELL", "hash":"ffd2f16f34576b07cd2736a3966b28518b28da93", "best_bid":"0.089", "best_ask":"0.09"}, {"asset_id":"52986718774908357330412653486471347449818893503063830313445318937088822580057", "price":"0.908", "size":"78371.18", "side":"BUY", "hash":"07d449d2383dff55f8906272c160d685c3813718", "best_bid":"0.91", "best_ask":"0.911"}], "timestamp":"1780179075519", "event_type":"price_change"}
{"market":"0x7976b8dbacf9077eb1453a62bcefd6ab2df199acd28aad276ff0d920d6992892", "price_changes":[{"asset_id":"4394372887385518214471608448209527405727552777602031099972143344338178308080", "price":"0.17", "size":"27662.46", "side":"SELL", "hash":"8a9d609cb5132040bf4c52bf0c5bfbb6bf8ab9fe", "best_bid":"0.167", "best_ask":"0.168"}, {"asset_id":"112680630004798425069810935278212000865453267506345451433803052322987302357330", "price":"0.83", "size":"27662.46", "side":"BUY", "hash":"44ed3ec1aa6c5989d4eb3c063fd093031f9c6ba1", "best_bid":"0.832", "best_ask":"0.833"}], "timestamp":"1780179075616", "event_type":"price_change"}
{"market":"0x30d55d8124ee1e12dabe89201badc45669b81dff69e4ce44d961f32878ec178a", "price_changes":[{"asset_id":"27576533317283401577758999384642760405921738493660383550832555714312627457443", "price":"0.092", "size":"78431.18", "side":"SELL", "hash":"3e8acd01d16cfff0dcf59f3567ffb318bc6fc432", "best_bid":"0.089", "best_ask":"0.09"}, {"asset_id":"52986718774908357330412653486471347449818893503063830313445318937088822580057", "price":"0.908", "size":"78431.18", "side":"BUY", "hash":"3bdecd35218b941e37b7bc463391ede198507fb6", "best_bid":"0.91", "best_ask":"0.911"}], "timestamp":"1780179075618", "event_type":"price_change"}
{"market":"0x1595b4818eeb1ea1e0bec5de6f057218e557feee9b405a0e930d290384fa1d16", "price_changes":[{"asset_id":"81739002353269632749850710185641576213562066971072676369728657545679630163887", "price":"0.053", "size":"3311.26", "side":"SELL", "hash":"cebd6e335a278e77f7b1abf5fdc33e98b3d1a7e5", "best_bid":"0.051", "best_ask":"0.052"}, {"asset_id":"45484070731786948288366703334552551439356529561722304542938873238430842810537", "price":"0.947", "size":"3311.26", "side":"BUY", "hash":"49726e4bf21063d7739dc5331ad327164c51ed8b", "best_bid":"0.948", "best_ask":"0.949"}], "timestamp":"1780179076841", "event_type":"price_change"}
{"market":"0x0c4cd2055d6ea89354ffddc55d6dbcef9355748112ea952fc925f3db6a5c457f", "price_changes":[{"asset_id":"18812649149814341758733697580460697418474693998558159483117100240528657629879", "price":"0.088", "size":"15069.46", "side":"SELL", "hash":"74406066cea42623917a53d2b3844b85e3b95e78", "best_bid":"0.085", "best_ask":"0.086"}, {"asset_id":"115428153746996892211798999366308897078723117634059783423375188043903703749062", "price":"0.912", "size":"15069.46", "side":"BUY", "hash":"b412d0e98dd52187143c4be126fa9f3e2b85713f", "best_bid":"0.914", "best_ask":"0.915"}], "timestamp":"1780179076844", "event_type":"price_change"}
{"market":"0x0c4cd2055d6ea89354ffddc55d6dbcef9355748112ea952fc925f3db6a5c457f", "price_changes":[{"asset_id":"18812649149814341758733697580460697418474693998558159483117100240528657629879", "price":"0.088", "size":"15129.46", "side":"SELL", "hash":"35f95f742c9f83a15a95d94d9d7f3ad61cb55a1c", "best_bid":"0.085", "best_ask":"0.086"}, {"asset_id":"115428153746996892211798999366308897078723117634059783423375188043903703749062", "price":"0.912", "size":"15129.46", "side":"BUY", "hash":"3286130f8d83838390505a5993e5e0334ac8b8b5", "best_bid":"0.914", "best_ask":"0.915"}], "timestamp":"1780179076939", "event_type":"price_change"}
{"market":"0x1595b4818eeb1ea1e0bec5de6f057218e557feee9b405a0e930d290384fa1d16", "price_changes":[{"asset_id":"81739002353269632749850710185641576213562066971072676369728657545679630163887", "price":"0.053", "size":"3371.26", "side":"SELL", "hash":"5b7514ed10e997032b57793c2fb6520e9eb5d006", "best_bid":"0.051", "best_ask":"0.052"}, {"asset_id":"45484070731786948288366703334552551439356529561722304542938873238430842810537", "price":"0.947", "size":"3371.26", "side":"BUY", "hash":"f68f1a1750c18e759607cc1f112889835d1892bd", "best_bid":"0.948", "best_ask":"0.949"}], "timestamp":"1780179076944", "event_type":"price_change"}
{"market":"0x375409bc5eeeff961e82b479caeccc20f33d15738e5bce1186d628aa3d9dfb1f", "price_changes":[{"asset_id":"115556263888245616435851357148058235707004733438163639091106356867234218207169", "price":"0.115", "size":"12019.15", "side":"SELL", "hash":"f27931deb7dc6f0fe69a28c26d37cb0c2f1e7140", "best_bid":"0.112", "best_ask":"0.113"}, {"asset_id":"77121637225348873006259930776623502125079210522997384841464684944292365296940", "price":"0.885", "size":"12019.15", "side":"BUY", "hash":"8b8dda7ff5eb4c71a3f4d78757893d1444b0bd25", "best_bid":"0.887", "best_ask":"0.888"}], "timestamp":"1780179076998", "event_type":"price_change"}
{"market":"0x7876851632c295043c66536150a304cb785abdf712ba8489d298c6e6926be106", "price_changes":[{"asset_id":"97239126062673310243763617236644392945530356142765650402171508075574679292913", "price":"0.011", "size":"1818525.69", "side":"SELL", "hash":"b5c89de98a9de75859a8e84163b81b669b485a00", "best_bid":"0.01", "best_ask":"0.011"}, {"asset_id":"19291692040378529618917910599727571242305935029274321291612270922648172794670", "price":"0.989", "size":"1818525.69", "side":"BUY", "hash":"b0600f9fe3e40b4dbcd63f1b5e9b42c543ea9783", "best_bid":"0.989", "best_ask":"0.99"}], "timestamp":"1780179077001", "event_type":"price_change"}
{"market":"0x9b6fef249040fd17e9c107955b37ac2c3e923509b6b0ff01cc463a331ddeb894", "price_changes":[{"asset_id":"108233603819467706476318984012158651931658302669301887462181073562758483842092", "price":"0.08", "size":"152.5", "side":"BUY", "hash":"0d86ee76190734aad56c14b1087afa299cec9c2f", "best_bid":"0.163", "best_ask":"0.164"}, {"asset_id":"32270411694523539495262303868629477861017829722282576458031815333486368239544", "price":"0.92", "size":"152.5", "side":"SELL", "hash":"a992a9dc6fa73708f4606887e1fd7723b4d214d1", "best_bid":"0.836", "best_ask":"0.837"}], "timestamp":"1780179077125", "event_type":"price_change"}
{"market":"0x375409bc5eeeff961e82b479caeccc20f33d15738e5bce1186d628aa3d9dfb1f", "price_changes":[{"asset_id":"115556263888245616435851357148058235707004733438163639091106356867234218207169", "price":"0.115", "size":"12079.15", "side":"SELL", "hash":"62a9ff11bce36cb59e3ac9dd2ae9ae399851c11c", "best_bid":"0.112", "best_ask":"0.113"}, {"asset_id":"77121637225348873006259930776623502125079210522997384841464684944292365296940", "price":"0.885", "size":"12079.15", "side":"BUY", "hash":"fa9995352ab53f5db6b8624137d2effef54b246f", "best_bid":"0.887", "best_ask":"0.888"}], "timestamp":"1780179077126", "event_type":"price_change"}
{"market":"0x7976b8dbacf9077eb1453a62bcefd6ab2df199acd28aad276ff0d920d6992892", "price_changes":[{"asset_id":"4394372887385518214471608448209527405727552777602031099972143344338178308080", "price":"0.09", "size":"11.11", "side":"BUY", "hash":"1d0922a7e2b0df92fea10f6eafb1326c2ddf159d", "best_bid":"0.167", "best_ask":"0.168"}, {"asset_id":"112680630004798425069810935278212000865453267506345451433803052322987302357330", "price":"0.91", "size":"11.11", "side":"SELL", "hash":"ca845dd3b93b9a0fe2c4d534a1fe0453f5cb23d3", "best_bid":"0.832", "best_ask":"0.833"}], "timestamp":"1780179077558", "event_type":"price_change"}
{"id":"2397882", "question":"BNB Up or Down - May 31, 6:00PM-6:05PM ET", "market":"0xf29acf8fc427ff80479b956f202e294806402d3d14a433b9daeb3ecae4eb64f1", "slug":"bnb-updown-5m-1780264800", "description":"This market will resolve to \"Up\" if the BNB price at the end of the time range specified in the title is greater than or equal to the price at the beginning of that range. Otherwise, it will resolve to \"Down\".\nThe resolution source for this market is information from Chainlink, specifically the BNB/USD data stream available at https://data.chain.link/streams/bnb-usd.\nPlease note that this market is about the price according to Chainlink data stream BNB/USD, not according to other sources or spot markets.", "assets_ids":["37015324854404101868022733400151172131383485756247466437201938520838952641531", "25132649795310829686599059969477591099903745226421729073409384010698427042434"], "outcomes":["Up", "Down"], "event_message":{"id":"542703", "ticker":"bnb-updown-5m-1780264800", "slug":"bnb-updown-5m-1780264800", "title":"BNB Up or Down - May 31, 6:00PM-6:05PM ET", "description":"This market will resolve to \"Up\" if the BNB price at the end of the time range specified in the title is greater than or equal to the price at the beginning of that range. Otherwise, it will resolve to \"Down\".\nThe resolution source for this market is information from Chainlink, specifically the BNB/USD data stream available at https://data.chain.link/streams/bnb-usd.\nPlease note that this market is about the price according to Chainlink data stream BNB/USD, not according to other sources or spot markets."}, "timestamp":"1780179078224", "event_type":"new_market", "tags":[], "condition_id":"0xf29acf8fc427ff80479b956f202e294806402d3d14a433b9daeb3ecae4eb64f1", "active":false, "clob_token_ids":["37015324854404101868022733400151172131383485756247466437201938520838952641531", "25132649795310829686599059969477591099903745226421729073409384010698427042434"], "sports_market_type":"", "line":"", "game_start_time":"", "order_price_min_tick_size":"0.01", "group_item_title":"", "taker_base_fee":"1000", "fees_enabled":true, "fee_schedule":{"exponent":"1", "rate":"0.07", "taker_only":true, "rebate_rate":"0.2"}}
{"market":"0x7976b8dbacf9077eb1453a62bcefd6ab2df199acd28aad276ff0d920d6992892", "price_changes":[{"asset_id":"4394372887385518214471608448209527405727552777602031099972143344338178308080", "price":"0.184", "size":"0", "side":"SELL", "hash":"62b7cd72709ecc742e5be4b0d44402d6546874c8", "best_bid":"0.167", "best_ask":"0.168"}, {"asset_id":"112680630004798425069810935278212000865453267506345451433803052322987302357330", "price":"0.816", "size":"0", "side":"BUY", "hash":"c3b1a02fca09d1eaf38683e395e29d65bab3f525", "best_bid":"0.832", "best_ask":"0.833"}], "timestamp":"1780179079882", "event_type":"price_change"}
{"market":"0x7976b8dbacf9077eb1453a62bcefd6ab2df199acd28aad276ff0d920d6992892", "price_changes":[{"asset_id":"4394372887385518214471608448209527405727552777602031099972143344338178308080", "price":"0.184", "size":"49.77", "side":"SELL", "hash":"0035dcdf7d7f8366505fa0afd5b5ed4da03b8228", "best_bid":"0.167", "best_ask":"0.168"}, {"asset_id":"112680630004798425069810935278212000865453267506345451433803052322987302357330", "price":"0.816", "size":"49.77", "side":"BUY", "hash":"030cfd6e034f40a41f3fba56789a211f58223f31", "best_bid":"0.832", "best_ask":"0.833"}], "timestamp":"1780179080062", "event_type":"price_change"}
{"market":"0x0c4cd2055d6ea89354ffddc55d6dbcef9355748112ea952fc925f3db6a5c457f", "price_changes":[{"asset_id":"18812649149814341758733697580460697418474693998558159483117100240528657629879", "price":"0.085", "size":"41629.94", "side":"BUY", "hash":"4fb50c10a0563f8ee3d4d470a162236f70b03736", "best_bid":"0.085", "best_ask":"0.086"}, {"asset_id":"115428153746996892211798999366308897078723117634059783423375188043903703749062", "price":"0.915", "size":"41629.94", "side":"SELL", "hash":"93ba1d1a0f838a8c996b4d83d5bb56bb778ba8bb", "best_bid":"0.914", "best_ask":"0.915"}], "timestamp":"1780179081378", "event_type":"price_change"}
PONG
{"market":"0x7876851632c295043c66536150a304cb785abdf712ba8489d298c6e6926be106", "price_changes":[{"asset_id":"97239126062673310243763617236644392945530356142765650402171508075574679292913", "price":"0.011", "size":"1818565.69", "side":"SELL", "hash":"8f0095c8a66266825a62f1c2c1a697612c0ab65c", "best_bid":"0.01", "best_ask":"0.011"}, {"asset_id":"19291692040378529618917910599727571242305935029274321291612270922648172794670", "price":"0.989", "size":"1818565.69", "side":"BUY", "hash":"d0b3eefd9910b135f4533130420f555e326de1ac", "best_bid":"0.989", "best_ask":"0.99"}], "timestamp":"1780179082598", "event_type":"price_change"}
{"id":"2397755", "question":"Dogecoin Up or Down - June 1, 6PM ET", "market":"0x49d5525d2c9cb75b7ea86b7169c7178412bf08efc8c9d3daec896b80e0c82222", "slug":"dogecoin-up-or-down-june-1-2026-6pm-et", "description":"This market will resolve to \"Up\" if the close price is greater than or equal to the open price for the DOGE/USDT 1 hour candle that begins on the time and date specified in the title. Otherwise, this market will resolve to \"Down\".\n\nThe resolution source for this market is information from Binance, specifically the DOGE/USDT pair (https://www.binance.com/en/trade/DOGE_USDT). The close « C » and open « O » displayed at the top of the graph for the relevant \"1H\" candle will be used once the data for that candle is finalized.\n\nPlease note that this market is about the price according to Binance DOGE/USDT, not according to other exchanges or trading pairs.", "assets_ids":["5181239375243232778214497434074055820159687541428104340268480643011960898257", "13682947484099989853575515771486089250042806086955716810654524824257928758275"], "outcomes":["Up", "Down"], "event_message":{"id":"542652", "ticker":"dogecoin-up-or-down-june-1-2026-6pm-et", "slug":"dogecoin-up-or-down-june-1-2026-6pm-et", "title":"Dogecoin Up or Down - June 1, 6PM ET", "description":"This market will resolve to \"Up\" if the close price is greater than or equal to the open price for the DOGE/USDT 1 hour candle that begins on the time and date specified in the title. Otherwise, this market will resolve to \"Down\".\n\nThe resolution source for this market is information from Binance, specifically the DOGE/USDT pair (https://www.binance.com/en/trade/DOGE_USDT). The close « C » and open « O » displayed at the top of the graph for the relevant \"1H\" candle will be used once the data for that candle is finalized.\n\nPlease note that this market is about the price according to Binance DOGE/USDT, not according to other exchanges or trading pairs."}, "timestamp":"1780179083095", "event_type":"new_market", "tags":[], "condition_id":"0x49d5525d2c9cb75b7ea86b7169c7178412bf08efc8c9d3daec896b80e0c82222", "active":false, "clob_token_ids":["5181239375243232778214497434074055820159687541428104340268480643011960898257", "13682947484099989853575515771486089250042806086955716810654524824257928758275"], "sports_market_type":"", "line":"", "game_start_time":"", "order_price_min_tick_size":"0.01", "group_item_title":"", "taker_base_fee":"1000", "fees_enabled":true, "fee_schedule":{"exponent":"1", "rate":"0.07", "taker_only":true, "rebate_rate":"0.2"}}
{"market":"0x0c4cd2055d6ea89354ffddc55d6dbcef9355748112ea952fc925f3db6a5c457f", "price_changes":[{"asset_id":"115428153746996892211798999366308897078723117634059783423375188043903703749062", "price":"0.864", "size":"1000", "side":"BUY", "hash":"675f31379415e3b4d76751ebc699fbc81055ad79", "best_bid":"0.914", "best_ask":"0.915"}, {"asset_id":"18812649149814341758733697580460697418474693998558159483117100240528657629879", "price":"0.136", "size":"1000", "side":"SELL", "hash":"c09f81aa06fb7358785a9edc51316960d9b8c543", "best_bid":"0.085", "best_ask":"0.086"}], "timestamp":"1780179084771", "event_type":"price_change"}
{"market":"0x9b6fef249040fd17e9c107955b37ac2c3e923509b6b0ff01cc463a331ddeb894", "price_changes":[{"asset_id":"32270411694523539495262303868629477861017829722282576458031815333486368239544", "price":"0.787", "size":"1000", "side":"BUY", "hash":"acf0475b77dc441a1734232a1dff1a53cd7c263b", "best_bid":"0.836", "best_ask":"0.837"}, {"asset_id":"108233603819467706476318984012158651931658302669301887462181073562758483842092", "price":"0.213", "size":"1000", "side":"SELL", "hash":"af83183774189c2ee224f5410e932e0d1a02114c", "best_bid":"0.163", "best_ask":"0.164"}], "timestamp":"1780179084771", "event_type":"price_change"}
{"market":"0x7976b8dbacf9077eb1453a62bcefd6ab2df199acd28aad276ff0d920d6992892", "price_changes":[{"asset_id":"112680630004798425069810935278212000865453267506345451433803052322987302357330", "price":"0.783", "size":"16.02", "side":"BUY", "hash":"6130c5d900d02eec662f3b212be58a43e448e04f", "best_bid":"0.832", "best_ask":"0.833"}, {"asset_id":"4394372887385518214471608448209527405727552777602031099972143344338178308080", "price":"0.217", "size":"16.02", "side":"SELL", "hash":"fd185c5519f548f408925722973f8c0a430e7fb5", "best_bid":"0.167", "best_ask":"0.168"}], "timestamp":"1780179084771", "event_type":"price_change"}
{"market":"0x4f3421fb2daf5cca7430ed8d8132463963081572d75434393a1808fdb8829fe8", "price_changes":[{"asset_id":"31940783580344558651011323787577288681658737625185216525249046282994042503801", "price":"0.849", "size":"3441.52", "side":"BUY", "hash":"d7ab5283e2ec4a4b8ad8c2611adea741e75c0c3e", "best_bid":"0.899", "best_ask":"0.9"}, {"asset_id":"45415751658241142530386585138386640503488308219341470020075667342738719018629", "price":"0.151", "size":"3441.52", "side":"SELL", "hash":"5d91544dbc2a7020a961b9027a7c93fd70ab0363", "best_bid":"0.1", "best_ask":"0.101"}], "timestamp":"1780179084771", "event_type":"price_change"}
{"market":"0x375409bc5eeeff961e82b479caeccc20f33d15738e5bce1186d628aa3d9dfb1f", "price_changes":[{"asset_id":"77121637225348873006259930776623502125079210522997384841464684944292365296940", "price":"0.837", "size":"1000", "side":"BUY", "hash":"626ebfbcda5a6bb6a31d0c86bd0c1b1dd8226a5c", "best_bid":"0.887", "best_ask":"0.888"}, {"asset_id":"115556263888245616435851357148058235707004733438163639091106356867234218207169", "price":"0.163", "size":"1000", "side":"SELL", "hash":"a0f2493b903a22efbc42f88c91abd5ba5c7da3ac", "best_bid":"0.112", "best_ask":"0.113"}], "timestamp":"1780179084771", "event_type":"price_change"}
{"market":"0x4f3421fb2daf5cca7430ed8d8132463963081572d75434393a1808fdb8829fe8", "price_changes":[{"asset_id":"31940783580344558651011323787577288681658737625185216525249046282994042503801", "price":"0.769", "size":"0", "side":"BUY", "hash":"d7ab5283e2ec4a4b8ad8c2611adea741e75c0c3e", "best_bid":"0.899", "best_ask":"0.9"}, {"asset_id":"45415751658241142530386585138386640503488308219341470020075667342738719018629", "price":"0.231", "size":"0", "side":"SELL", "hash":"5d91544dbc2a7020a961b9027a7c93fd70ab0363", "best_bid":"0.1", "best_ask":"0.101"}], "timestamp":"1780179084771", "event_type":"price_change"}
{"market":"0x30d55d8124ee1e12dabe89201badc45669b81dff69e4ce44d961f32878ec178a", "price_changes":[{"asset_id":"52986718774908357330412653486471347449818893503063830313445318937088822580057", "price":"0.86", "size":"3499.34", "side":"BUY", "hash":"90ccb12fe07348d4e650a25cedf55052ecfe1875", "best_bid":"0.91", "best_ask":"0.911"}, {"asset_id":"27576533317283401577758999384642760405921738493660383550832555714312627457443", "price":"0.14", "size":"3499.34", "side":"SELL", "hash":"a169299625272f8fc15b20c83b3e23ae3fd3b693", "best_bid":"0.089", "best_ask":"0.09"}], "timestamp":"1780179084772", "event_type":"price_change"}
{"market":"0x4f3421fb2daf5cca7430ed8d8132463963081572d75434393a1808fdb8829fe8", "price_changes":[{"asset_id":"31940783580344558651011323787577288681658737625185216525249046282994042503801", "price":"0.77", "size":"100", "side":"BUY", "hash":"e8b73cdcdc156830a0185275286c2a3ba607036a", "best_bid":"0.899", "best_ask":"0.9"}, {"asset_id":"45415751658241142530386585138386640503488308219341470020075667342738719018629", "price":"0.23", "size":"100", "side":"SELL", "hash":"e49f0b49fa7811f5996f3bb54666b37fef832155", "best_bid":"0.1", "best_ask":"0.101"}], "timestamp":"1780179084825", "event_type":"price_change"}
{"market":"0x9b6fef249040fd17e9c107955b37ac2c3e923509b6b0ff01cc463a331ddeb894", "price_changes":[{"asset_id":"32270411694523539495262303868629477861017829722282576458031815333486368239544", "price":"0.788", "size":"110", "side":"BUY", "hash":"bf0f904f5fe5a798224785d9c295b769d264d733", "best_bid":"0.836", "best_ask":"0.837"}, {"asset_id":"108233603819467706476318984012158651931658302669301887462181073562758483842092", "price":"0.212", "size":"110", "side":"SELL", "hash":"9e22010566287d53a7c1714fca4f2179b33ccc6b", "best_bid":"0.163", "best_ask":"0.164"}], "timestamp":"1780179084840", "event_type":"price_change"}
{"market":"0x4f3421fb2daf5cca7430ed8d8132463963081572d75434393a1808fdb8829fe8", "price_changes":[{"asset_id":"31940783580344558651011323787577288681658737625185216525249046282994042503801", "price":"0.85", "size":"16027.35", "side":"BUY", "hash":"39b30cc078848e9f2a3d29d314749631c12822c9", "best_bid":"0.899", "best_ask":"0.9"}, {"asset_id":"45415751658241142530386585138386640503488308219341470020075667342738719018629", "price":"0.15", "size":"16027.35", "side":"SELL", "hash":"211855a4af68b2824886d966122552ae1832ca04", "best_bid":"0.1", "best_ask":"0.101"}], "timestamp":"1780179084853", "event_type":"price_change"}
{"market":"0x7976b8dbacf9077eb1453a62bcefd6ab2df199acd28aad276ff0d920d6992892", "price_changes":[{"asset_id":"112680630004798425069810935278212000865453267506345451433803052322987302357330", "price":"0.784", "size":"1100", "side":"BUY", "hash":"80ea13641c89d82a4b6566372ebe73a64be10186", "best_bid":"0.832", "best_ask":"0.833"}, {"asset_id":"4394372887385518214471608448209527405727552777602031099972143344338178308080", "price":"0.216", "size":"1100", "side":"SELL", "hash":"7a476241362da619d6ee5923da3f48f20b6ff255", "best_bid":"0.167", "best_ask":"0.168"}], "timestamp":"1780179084868", "event_type":"price_change"}
{"market":"0x375409bc5eeeff961e82b479caeccc20f33d15738e5bce1186d628aa3d9dfb1f", "price_changes":[{"asset_id":"77121637225348873006259930776623502125079210522997384841464684944292365296940", "price":"0.838", "size":"100", "side":"BUY", "hash":"e50fedf332aceece49469d5e1ddbad2e62fc6630", "best_bid":"0.887", "best_ask":"0.888"}, {"asset_id":"115556263888245616435851357148058235707004733438163639091106356867234218207169", "price":"0.162", "size":"100", "side":"SELL", "hash":"315b675f71eb59a15e4bc2b4883cab9abf689ec9", "best_bid":"0.112", "best_ask":"0.113"}], "timestamp":"1780179084880", "event_type":"price_change"}
{"market":"0x0c4cd2055d6ea89354ffddc55d6dbcef9355748112ea952fc925f3db6a5c457f", "price_changes":[{"asset_id":"115428153746996892211798999366308897078723117634059783423375188043903703749062", "price":"0.865", "size":"100", "side":"BUY", "hash":"c86e61e4848ce944254211c062f940b604e38881", "best_bid":"0.914", "best_ask":"0.915"}, {"asset_id":"18812649149814341758733697580460697418474693998558159483117100240528657629879", "price":"0.135", "size":"100", "side":"SELL", "hash":"97fe67bee77f3cc75ba9255d4ee05eadb20826c4", "best_bid":"0.085", "best_ask":"0.086"}], "timestamp":"1780179084903", "event_type":"price_change"}
{"market":"0x30d55d8124ee1e12dabe89201badc45669b81dff69e4ce44d961f32878ec178a", "price_changes":[{"asset_id":"52986718774908357330412653486471347449818893503063830313445318937088822580057", "price":"0.861", "size":"100", "side":"BUY", "hash":"292fc648f2a0c9ed3f6b95adad4be21020abe73d", "best_bid":"0.91", "best_ask":"0.911"}, {"asset_id":"27576533317283401577758999384642760405921738493660383550832555714312627457443", "price":"0.139", "size":"100", "side":"SELL", "hash":"ef9adb66777eeaf6c6c99d653f144383d965d052", "best_bid":"0.089", "best_ask":"0.09"}], "timestamp":"1780179084928", "event_type":"price_change"}
{"market":"0x1595b4818eeb1ea1e0bec5de6f057218e557feee9b405a0e930d290384fa1d16", "price_changes":[{"asset_id":"81739002353269632749850710185641576213562066971072676369728657545679630163887", "price":"0.053", "size":"3291.26", "side":"SELL", "hash":"b1962e81bc8baaa41ad0a8f967cdc70bcdbae42e", "best_bid":"0.051", "best_ask":"0.052"}, {"asset_id":"45484070731786948288366703334552551439356529561722304542938873238430842810537", "price":"0.947", "size":"3291.26", "side":"BUY", "hash":"578cdf982264623e7f9f20193255b0a58a797520", "best_bid":"0.948", "best_ask":"0.949"}], "timestamp":"1780179086208", "event_type":"price_change"}
{"market":"0x30d55d8124ee1e12dabe89201badc45669b81dff69e4ce44d961f32878ec178a", "price_changes":[{"asset_id":"27576533317283401577758999384642760405921738493660383550832555714312627457443", "price":"0.092", "size":"78375.52", "side":"SELL", "hash":"a15647738f61a29a3f4cd64d13ec9bdce257b465", "best_bid":"0.089", "best_ask":"0.09"}, {"asset_id":"52986718774908357330412653486471347449818893503063830313445318937088822580057", "price":"0.908", "size":"78375.52", "side":"BUY", "hash":"359fd5439a4d11f1dfec704d72dcded71354303c", "best_bid":"0.91", "best_ask":"0.911"}], "timestamp":"1780179086180", "event_type":"price_change"}
{"market":"0x7976b8dbacf9077eb1453a62bcefd6ab2df199acd28aad276ff0d920d6992892", "price_changes":[{"asset_id":"4394372887385518214471608448209527405727552777602031099972143344338178308080", "price":"0.17", "size":"27636.91", "side":"SELL", "hash":"a46c4596f49d0c4504bfdab4222d94d911b3eae9", "best_bid":"0.167", "best_ask":"0.168"}, {"asset_id":"112680630004798425069810935278212000865453267506345451433803052322987302357330", "price":"0.83", "size":"27636.91", "side":"BUY", "hash":"1e7e5f49a6eb99eb0e1190473eb2a2af371a3dfd", "best_bid":"0.832", "best_ask":"0.833"}], "timestamp":"1780179086205", "event_type":"price_change"}
{"market":"0x0c4cd2055d6ea89354ffddc55d6dbcef9355748112ea952fc925f3db6a5c457f", "price_changes":[{"asset_id":"18812649149814341758733697580460697418474693998558159483117100240528657629879", "price":"0.088", "size":"15049.46", "side":"SELL", "hash":"a957bfd99d13c6e97a4d4813c14e7abb1568939c", "best_bid":"0.085", "best_ask":"0.086"}, {"asset_id":"115428153746996892211798999366308897078723117634059783423375188043903703749062", "price":"0.912", "size":"15049.46", "side":"BUY", "hash":"f5108573266ea1db2ac79dcce46acf71777b0461", "best_bid":"0.914", "best_ask":"0.915"}], "timestamp":"1780179086201", "event_type":"price_change"}
{"id":"2397786", "question":"O/U 2.5 Rounds", "market":"0xab583224d87a3c7566209ec228c94679308a0de6b6a5278b48c3add26230bb7b", "slug":"ufc-kar3-lua4-2026-06-20-totals-2pt5", "description":"Each market will resolve to \"Over\" if the fight between Karol Rosa and Luana Santos at UFC Fight Night: Kape vs. Horiguchi, scheduled for June 20, 2026, lasts beyond the listed round threshold.\n\nEach market will resolve to \"Under\" if the fight does not last beyond the listed round threshold.\n\nFor example:\n\n\"Over 2.5 Rounds\" will resolve \"Yes\" if the fight continues past the 2:30 mark of Round 3.\n\n\"Under 2.5 Rounds\" will resolve \"Yes\" if the fight ends before the 2:30 mark of Round 3.\n\nIf the fight ends exactly at the threshold, it will resolve \"50-50.\"\n\nIf the bout is not scored, postponed beyond July 4, 2026, or canceled, all options will resolve \"50-50.\"\n\nThe resolution source for this market will be official information from the UFC.", "assets_ids":["35803836382584473631001388596949959637818194403460689434056128850965501541858", "99068681130001510391341960255850181729345672801462351802913538563110156496444"], "outcomes":["Over", "Under"], "event_message":{"id":"542659", "ticker":"ufc-kar3-lua4-2026-06-20", "slug":"ufc-kar3-lua4-2026-06-20", "title":"UFC Fight Night: Karol Rosa vs. Luana Santos (Women's Bantamweight, Prelims)", "description":"This market will resolve to \"Karol Rosa\" if Karol Rosa is officially declared the winner of the fight against Luana Santos at UFC Fight Night: Kape vs. Horiguchi, scheduled for June 20, 2026.\n\nIt will resolve to \"Luana Santos\" if Luana Santos is officially declared the winner.\n\nIf the fight is declared a draw or technical draw, ruled a No Contest, not scored, canceled, or postponed beyond July 4, 2026, this market will resolve \"50-50.\"\n\nThe resolution source for this market will be official information from the UFC."}, "timestamp":"1780179086658", "event_type":"new_market", "tags":[], "condition_id":"0xab583224d87a3c7566209ec228c94679308a0de6b6a5278b48c3add26230bb7b", "active":false, "clob_token_ids":["35803836382584473631001388596949959637818194403460689434056128850965501541858", "99068681130001510391341960255850181729345672801462351802913538563110156496444"], "sports_market_type":"totals", "line":"2.5", "game_start_time":"2026-06-20 17:00:00+00", "order_price_min_tick_size":"0.01", "group_item_title":"O/U 2.5 Rounds", "taker_base_fee":"1000", "fees_enabled":true, "fee_schedule":{"exponent":"1", "rate":"0.03", "taker_only":true, "rebate_rate":"0.25"}}
{"market":"0x7976b8dbacf9077eb1453a62bcefd6ab2df199acd28aad276ff0d920d6992892", "price_changes":[{"asset_id":"4394372887385518214471608448209527405727552777602031099972143344338178308080", "price":"0.17", "size":"27662.46", "side":"SELL", "hash":"400b8a7ea57543e6006699e3b02bbcb1628fd8ec", "best_bid":"0.167", "best_ask":"0.168"}, {"asset_id":"112680630004798425069810935278212000865453267506345451433803052322987302357330", "price":"0.83", "size":"27662.46", "side":"BUY", "hash":"12fa77f3804d0cd155bd5b4e361e860acee95ae0", "best_bid":"0.832", "best_ask":"0.833"}], "timestamp":"1780179086759", "event_type":"price_change"}
{"market":"0x30d55d8124ee1e12dabe89201badc45669b81dff69e4ce44d961f32878ec178a", "price_changes":[{"asset_id":"27576533317283401577758999384642760405921738493660383550832555714312627457443", "price":"0.092", "size":"78431.18", "side":"SELL", "hash":"6a1d5aace145e797aca48753d3a797067eadd889", "best_bid":"0.089", "best_ask":"0.09"}, {"asset_id":"52986718774908357330412653486471347449818893503063830313445318937088822580057", "price":"0.908", "size":"78431.18", "side":"BUY", "hash":"1ae128be77d2fea2db00e3379c20b7b9e654e2db", "best_bid":"0.91", "best_ask":"0.911"}], "timestamp":"1780179086759", "event_type":"price_change"}
{"market":"0x1595b4818eeb1ea1e0bec5de6f057218e557feee9b405a0e930d290384fa1d16", "price_changes":[{"asset_id":"81739002353269632749850710185641576213562066971072676369728657545679630163887", "price":"0.053", "size":"3371.26", "side":"SELL", "hash":"ada14bde88190e708837688af0f95a12885e8de0", "best_bid":"0.051", "best_ask":"0.052"}, {"asset_id":"45484070731786948288366703334552551439356529561722304542938873238430842810537", "price":"0.947", "size":"3371.26", "side":"BUY", "hash":"841c837e78b25a20173c7996422cce6c9ecdd250", "best_bid":"0.948", "best_ask":"0.949"}], "timestamp":"1780179086760", "event_type":"price_change"}
{"market":"0x0c4cd2055d6ea89354ffddc55d6dbcef9355748112ea952fc925f3db6a5c457f", "price_changes":[{"asset_id":"18812649149814341758733697580460697418474693998558159483117100240528657629879", "price":"0.088", "size":"15129.46", "side":"SELL", "hash":"0c77ac03f780b6f250719b14d55a07ba31c89501", "best_bid":"0.085", "best_ask":"0.086"}, {"asset_id":"115428153746996892211798999366308897078723117634059783423375188043903703749062", "price":"0.912", "size":"15129.46", "side":"BUY", "hash":"6e3e1e59ba59dddc8d621ed0896bbeadcafe83b0", "best_bid":"0.914", "best_ask":"0.915"}], "timestamp":"1780179086759", "event_type":"price_change"}
{"market":"0x375409bc5eeeff961e82b479caeccc20f33d15738e5bce1186d628aa3d9dfb1f", "price_changes":[{"asset_id":"115556263888245616435851357148058235707004733438163639091106356867234218207169", "price":"0.115", "size":"11999.15", "side":"SELL", "hash":"d965212a83fa7ebd10bbb7d1ac33a4ad3f02e02c", "best_bid":"0.112", "best_ask":"0.113"}, {"asset_id":"77121637225348873006259930776623502125079210522997384841464684944292365296940", "price":"0.885", "size":"11999.15", "side":"BUY", "hash":"e9ac6568ee6d72d9e1765aabcae4d7753ee449f1", "best_bid":"0.887", "best_ask":"0.888"}], "timestamp":"1780179088188", "event_type":"price_change"}
{"market":"0x9b6fef249040fd17e9c107955b37ac2c3e923509b6b0ff01cc463a331ddeb894", "price_changes":[{"asset_id":"108233603819467706476318984012158651931658302669301887462181073562758483842092", "price":"0.166", "size":"24926.71", "side":"SELL", "hash":"d9c72262b0a52ad932488e50ec956f725a485913", "best_bid":"0.163", "best_ask":"0.164"}, {"asset_id":"32270411694523539495262303868629477861017829722282576458031815333486368239544", "price":"0.834", "size":"24926.71", "side":"BUY", "hash":"2079c473375a955e3a471afb0e24ad0d21f8d035", "best_bid":"0.836", "best_ask":"0.837"}], "timestamp":"1780179088250", "event_type":"price_change"}
{"market":"0x375409bc5eeeff961e82b479caeccc20f33d15738e5bce1186d628aa3d9dfb1f", "price_changes":[{"asset_id":"115556263888245616435851357148058235707004733438163639091106356867234218207169", "price":"0.115", "size":"12079.15", "side":"SELL", "hash":"2a1fb61601b61b2275b241e089f0b89a2290c993", "best_bid":"0.112", "best_ask":"0.113"}, {"asset_id":"77121637225348873006259930776623502125079210522997384841464684944292365296940", "price":"0.885", "size":"12079.15", "side":"BUY", "hash":"010fe27cdf8da8c614e3d47d140db13a1b63c2e9", "best_bid":"0.887", "best_ask":"0.888"}], "timestamp":"1780179088291", "event_type":"price_change"}
{"market":"0x9b6fef249040fd17e9c107955b37ac2c3e923509b6b0ff01cc463a331ddeb894", "price_changes":[{"asset_id":"108233603819467706476318984012158651931658302669301887462181073562758483842092", "price":"0.166", "size":"25006.71", "side":"SELL", "hash":"e08fc97f387ee8585f4207ad8eb1e32a8dfb1213", "best_bid":"0.163", "best_ask":"0.164"}, {"asset_id":"32270411694523539495262303868629477861017829722282576458031815333486368239544", "price":"0.834", "size":"25006.71", "side":"BUY", "hash":"abe84f4b2633ad5e2b855c6b618021b5ff260905", "best_bid":"0.836", "best_ask":"0.837"}], "timestamp":"1780179088376", "event_type":"price_change"}
{"market":"0x4f3421fb2daf5cca7430ed8d8132463963081572d75434393a1808fdb8829fe8", "price_changes":[{"asset_id":"45415751658241142530386585138386640503488308219341470020075667342738719018629", "price":"0.103", "size":"18202.51", "side":"SELL", "hash":"0a5598ccc672176f36e115bafe8675b5617b1896", "best_bid":"0.1", "best_ask":"0.101"}, {"asset_id":"31940783580344558651011323787577288681658737625185216525249046282994042503801", "price":"0.897", "size":"18202.51", "side":"BUY", "hash":"39ed3170c25db4471c705e701eacc6bcbb3af47e", "best_bid":"0.899", "best_ask":"0.9"}], "timestamp":"1780179088713", "event_type":"price_change"}
{"market":"0x4f3421fb2daf5cca7430ed8d8132463963081572d75434393a1808fdb8829fe8", "price_changes":[{"asset_id":"45415751658241142530386585138386640503488308219341470020075667342738719018629", "price":"0.103", "size":"18263.31", "side":"SELL", "hash":"d150344fa4df50d650fd77a78acb0f75f1fac507", "best_bid":"0.1", "best_ask":"0.101"}, {"asset_id":"31940783580344558651011323787577288681658737625185216525249046282994042503801", "price":"0.897", "size":"18263.31", "side":"BUY", "hash":"23d7992251e962597b0018d25e6ff9bc35dd5634", "best_bid":"0.899", "best_ask":"0.9"}], "timestamp":"1780179088794", "event_type":"price_change"}
{"market":"0x9b6fef249040fd17e9c107955b37ac2c3e923509b6b0ff01cc463a331ddeb894", "asset_id":"32270411694523539495262303868629477861017829722282576458031815333486368239544", "best_bid":"0.836", "best_ask":"0.837", "spread":"0.001", "timestamp":"1780179092107", "event_type":"best_bid_ask"}
{"market":"0x9b6fef249040fd17e9c107955b37ac2c3e923509b6b0ff01cc463a331ddeb894", "price_changes":[{"asset_id":"108233603819467706476318984012158651931658302669301887462181073562758483842092", "price":"0.164", "size":"38045.12", "side":"SELL", "hash":"5e65c6e32c2f867d48898d444a9710ab3bfca0dc", "best_bid":"0.163", "best_ask":"0.164"}, {"asset_id":"32270411694523539495262303868629477861017829722282576458031815333486368239544", "price":"0.836", "size":"38045.12", "side":"BUY", "hash":"34eec204520dd5b1f99dc556c1b6b23ba3b7a5d9", "best_bid":"0.836", "best_ask":"0.837"}], "timestamp":"1780179092107", "event_type":"price_change"}
{"market":"0x9b6fef249040fd17e9c107955b37ac2c3e923509b6b0ff01cc463a331ddeb894", "asset_id":"32270411694523539495262303868629477861017829722282576458031815333486368239544", "bids":[{"price":"0.001", "size":"12219098.99"}, {"price":"0.002", "size":"178.57"}, {"price":"0.003", "size":"21.08"}, {"price":"0.009", "size":"18000"}, {"price":"0.01", "size":"100"}, {"price":"0.011", "size":"5.62"}, {"price":"0.012", "size":"1111111"}, {"price":"0.013", "size":"900000"}, {"price":"0.014", "size":"1300"}, {"price":"0.015", "size":"500"}, {"price":"0.02", "size":"99"}, {"price":"0.021", "size":"6.95"}, {"price":"0.05", "size":"246.52"}, {"price":"0.051", "size":"10.84"}, {"price":"0.09", "size":"5.98"}, {"price":"0.1", "size":"15"}, {"price":"0.12", "size":"5005"}, {"price":"0.121", "size":"12000"}, {"price":"0.15", "size":"67.49"}, {"price":"0.163", "size":"36"}, {"price":"0.178", "size":"289.7"}, {"price":"0.2", "size":"796.33"}, {"price":"0.209", "size":"143.54"}, {"price":"0.22", "size":"100.48"}, {"price":"0.221", "size":"5.22"}, {"price":"0.245", "size":"304.87"}, {"price":"0.25", "size":"3597"}, {"price":"0.251", "size":"6000"}, {"price":"0.29", "size":"9.75"}, {"price":"0.3", "size":"55.88"}, {"price":"0.315", "size":"1459.85"}, {"price":"0.33", "size":"1363.34"}, {"price":"0.331", "size":"3000"}, {"price":"0.34", "size":"5"}, {"price":"0.35", "size":"2159.92"}, {"price":"0.4", "size":"34587.44"}, {"price":"0.401", "size":"3000"}, {"price":"0.47", "size":"5688.73"}, {"price":"0.5", "size":"36470.75"}, {"price":"0.502", "size":"1529.99"}, {"price":"0.503", "size":"14000"}, {"price":"0.51", "size":"90.9"}, {"price":"0.511", "size":"1202.04"}, {"price":"0.55", "size":"513.44"}, {"price":"0.56", "size":"111.11"}, {"price":"0.562", "size":"655.13"}, {"price":"0.563", "size":"65.06"}, {"price":"0.57", "size":"3964.15"}, {"price":"0.6", "size":"22272.15"}, {"price":"0.624", "size":"27.04"}, {"price":"0.636", "size":"105.03"}, {"price":"0.637", "size":"1000"}, {"price":"0.638", "size":"23.57"}, {"price":"0.64", "size":"4479.3"}, {"price":"0.648", "size":"7.39"}, {"price":"0.65", "size":"15415.61"}, {"price":"0.651", "size":"2155.26"}, {"price":"0.667", "size":"1000"}, {"price":"0.67", "size":"18.11"}, {"price":"0.672", "size":"482.66"}, {"price":"0.68", "size":"38"}, {"price":"0.697", "size":"1000"}, {"price":"0.7", "size":"487.37"}, {"price":"0.701", "size":"400"}, {"price":"0.72", "size":"167.14"}, {"price":"0.722", "size":"100"}, {"price":"0.727", "size":"1000"}, {"price":"0.743", "size":"100"}, {"price":"0.747", "size":"1000"}, {"price":"0.75", "size":"1422.54"}, {"price":"0.751", "size":"201"}, {"price":"0.752", "size":"1367"}, {"price":"0.754", "size":"334.02"}, {"price":"0.757", "size":"1000"}, {"price":"0.76", "size":"302"}, {"price":"0.764", "size":"130"}, {"price":"0.767", "size":"1100"}, {"price":"0.777", "size":"1011.23"}, {"price":"0.779", "size":"334.02"}, {"price":"0.78", "size":"237"}, {"price":"0.785", "size":"100"}, {"price":"0.786", "size":"15"}, {"price":"0.787", "size":"1000"}, {"price":"0.788", "size":"110"}, {"price":"0.789", "size":"5555.55"}, {"price":"0.79", "size":"122"}, {"price":"0.793", "size":"10"}, {"price":"0.794", "size":"1000"}, {"price":"0.795", "size":"10"}, {"price":"0.797", "size":"1050"}, {"price":"0.8", "size":"17681.66"}, {"price":"0.801", "size":"100"}, {"price":"0.803", "size":"110"}, {"price":"0.806", "size":"44"}, {"price":"0.807", "size":"1180"}, {"price":"0.808", "size":"675.7"}, {"price":"0.809", "size":"2027"}, {"price":"0.81", "size":"6609.61"}, {"price":"0.811", "size":"4653.91"}, {"price":"0.812", "size":"1708.3"}, {"price":"0.813", "size":"782.67"}, {"price":"0.814", "size":"1703.37"}, {"price":"0.815", "size":"5571.35"}, {"price":"0.816", "size":"10939.83"}, {"price":"0.817", "size":"7752.15"}, {"price":"0.818", "size":"6032.61"}, {"price":"0.819", "size":"340"}, {"price":"0.82", "size":"1037.95"}, {"price":"0.821", "size":"1694.21"}, {"price":"0.822", "size":"22719.93"}, {"price":"0.823", "size":"44358.4"}, {"price":"0.824", "size":"47073"}, {"price":"0.825", "size":"47040.85"}, {"price":"0.827", "size":"654.36"}, {"price":"0.829", "size":"19937.62"}, {"price":"0.83", "size":"26050"}, {"price":"0.831", "size":"3000"}, {"price":"0.832", "size":"2000"}, {"price":"0.833", "size":"4950.42"}, {"price":"0.834", "size":"25006.71"}, {"price":"0.835", "size":"182736.01"}, {"price":"0.836", "size":"38045.12"}], "asks":[{"price":"0.999", "size":"2260279"}, {"price":"0.998", "size":"1557248"}, {"price":"0.997", "size":"1001200"}, {"price":"0.996", "size":"55555"}, {"price":"0.995", "size":"90100"}, {"price":"0.99", "size":"720"}, {"price":"0.985", "size":"5.01"}, {"price":"0.984", "size":"555555"}, {"price":"0.983", "size":"60000"}, {"price":"0.982", "size":"105435.9"}, {"price":"0.981", "size":"800"}, {"price":"0.98", "size":"5430"}, {"price":"0.978", "size":"3000"}, {"price":"0.976", "size":"3000"}, {"price":"0.974", "size":"3000"}, {"price":"0.972", "size":"3000"}, {"price":"0.97", "size":"3000"}, {"price":"0.968", "size":"3000"}, {"price":"0.966", "size":"3000"}, {"price":"0.96", "size":"750"}, {"price":"0.951", "size":"100"}, {"price":"0.95", "size":"150"}, {"price":"0.94", "size":"10"}, {"price":"0.937", "size":"16.27"}, {"price":"0.936", "size":"30"}, {"price":"0.935", "size":"10"}, {"price":"0.934", "size":"20"}, {"price":"0.931", "size":"10"}, {"price":"0.93", "size":"50"}, {"price":"0.926", "size":"20"}, {"price":"0.925", "size":"5"}, {"price":"0.924", "size":"30"}, {"price":"0.923", "size":"20"}, {"price":"0.922", "size":"20"}, {"price":"0.921", "size":"20"}, {"price":"0.92", "size":"152.5"}, {"price":"0.91", "size":"10100"}, {"price":"0.905", "size":"105.2"}, {"price":"0.9", "size":"6296.92"}, {"price":"0.899", "size":"1076.68"}, {"price":"0.893", "size":"37.72"}, {"price":"0.892", "size":"40"}, {"price":"0.89", "size":"400"}, {"price":"0.889", "size":"5000"}, {"price":"0.885", "size":"9"}, {"price":"0.884", "size":"90"}, {"price":"0.88", "size":"120"}, {"price":"0.879", "size":"7500"}, {"price":"0.878", "size":"5000"}, {"price":"0.877", "size":"100"}, {"price":"0.875", "size":"956.59"}, {"price":"0.874", "size":"2500"}, {"price":"0.87", "size":"328"}, {"price":"0.869", "size":"2567"}, {"price":"0.868", "size":"47"}, {"price":"0.867", "size":"1933.93"}, {"price":"0.866", "size":"57"}, {"price":"0.865", "size":"37"}, {"price":"0.864", "size":"5017"}, {"price":"0.863", "size":"3727"}, {"price":"0.862", "size":"7"}, {"price":"0.861", "size":"7"}, {"price":"0.86", "size":"717"}, {"price":"0.859", "size":"7"}, {"price":"0.858", "size":"507"}, {"price":"0.857", "size":"97"}, {"price":"0.856", "size":"7"}, {"price":"0.855", "size":"37"}, {"price":"0.854", "size":"37"}, {"price":"0.853", "size":"722"}, {"price":"0.852", "size":"7"}, {"price":"0.851", "size":"707"}, {"price":"0.85", "size":"6520"}, {"price":"0.849", "size":"877"}, {"price":"0.848", "size":"7"}, {"price":"0.847", "size":"27"}, {"price":"0.846", "size":"287"}, {"price":"0.845", "size":"3760.64"}, {"price":"0.844", "size":"20417"}, {"price":"0.843", "size":"28647.14"}, {"price":"0.842", "size":"10076.94"}, {"price":"0.841", "size":"56.6"}, {"price":"0.84", "size":"67783.1"}, {"price":"0.839", "size":"12119.44"}, {"price":"0.838", "size":"4311.83"}, {"price":"0.837", "size":"15084.23"}], "hash":"34eec204520dd5b1f99dc556c1b6b23ba3b7a5d9", "timestamp":"1780179092107", "event_type":"book"}
{"market":"0x9b6fef249040fd17e9c107955b37ac2c3e923509b6b0ff01cc463a331ddeb894", "price_changes":[{"asset_id":"32270411694523539495262303868629477861017829722282576458031815333486368239544", "price":"0.818", "size":"6235.31", "side":"BUY", "hash":"7f1a9d20d65248bd0a8e2e97e7076d862c2c1a84", "best_bid":"0.836", "best_ask":"0.837"}, {"asset_id":"108233603819467706476318984012158651931658302669301887462181073562758483842092", "price":"0.182", "size":"6235.31", "side":"SELL", "hash":"26cda116c1d17ee61f0996ef9569f4fdbf74ff2f", "best_bid":"0.163", "best_ask":"0.164"}], "timestamp":"1780179092121", "event_type":"price_change"}
{"market":"0x375409bc5eeeff961e82b479caeccc20f33d15738e5bce1186d628aa3d9dfb1f", "price_changes":[{"asset_id":"77121637225348873006259930776623502125079210522997384841464684944292365296940", "price":"0.867", "size":"15010", "side":"BUY", "hash":"32112b3c5b785dfbc1c75d3fae515b56d4f2f3cb", "best_bid":"0.887", "best_ask":"0.888"}, {"asset_id":"115556263888245616435851357148058235707004733438163639091106356867234218207169", "price":"0.133", "size":"15010", "side":"SELL", "hash":"7965d0946d9375a9793f3871100e61c046af4f19", "best_bid":"0.112", "best_ask":"0.113"}], "timestamp":"1780179092133", "event_type":"price_change"}
{"market":"0x4f3421fb2daf5cca7430ed8d8132463963081572d75434393a1808fdb8829fe8", "price_changes":[{"asset_id":"31940783580344558651011323787577288681658737625185216525249046282994042503801", "price":"0.879", "size":"0", "side":"BUY", "hash":"285e0b511f9b35995f83c30bc42862303c117ff8", "best_bid":"0.899", "best_ask":"0.9"}, {"asset_id":"45415751658241142530386585138386640503488308219341470020075667342738719018629", "price":"0.121", "size":"0", "side":"SELL", "hash":"175d0b76235fb198dac0956e0410ee2033b5e307", "best_bid":"0.1", "best_ask":"0.101"}], "timestamp":"1780179092133", "event_type":"price_change"}
{"market":"0x9b6fef249040fd17e9c107955b37ac2c3e923509b6b0ff01cc463a331ddeb894", "price_changes":[{"asset_id":"32270411694523539495262303868629477861017829722282576458031815333486368239544", "price":"0.817", "size":"7549.45", "side":"BUY", "hash":"b064ad82bf062a410e629c834ce74de688ba6182", "best_bid":"0.836", "best_ask":"0.837"}, {"asset_id":"108233603819467706476318984012158651931658302669301887462181073562758483842092", "price":"0.183", "size":"7549.45", "side":"SELL", "hash":"72d5a8bcf8033b95f34aebfbf653f5971646d105", "best_bid":"0.163", "best_ask":"0.164"}], "timestamp":"1780179092137", "event_type":"price_change"}
{"market":"0x0c4cd2055d6ea89354ffddc55d6dbcef9355748112ea952fc925f3db6a5c457f", "price_changes":[{"asset_id":"115428153746996892211798999366308897078723117634059783423375188043903703749062", "price":"0.894", "size":"355.22", "side":"BUY", "hash":"d6c941ab21898dbcf8fe5ab163e06de3fb8912d5", "best_bid":"0.914", "best_ask":"0.915"}, {"asset_id":"18812649149814341758733697580460697418474693998558159483117100240528657629879", "price":"0.106", "size":"355.22", "side":"SELL", "hash":"eb80143024a3dabeb675ab419a98a675d70efb73", "best_bid":"0.085", "best_ask":"0.086"}], "timestamp":"1780179092133", "event_type":"price_change"}
{"market":"0x7976b8dbacf9077eb1453a62bcefd6ab2df199acd28aad276ff0d920d6992892", "price_changes":[{"asset_id":"112680630004798425069810935278212000865453267506345451433803052322987302357330", "price":"0.813", "size":"30", "side":"BUY", "hash":"d964789857d8855424ff539ab5f318e6392da85e", "best_bid":"0.832", "best_ask":"0.833"}, {"asset_id":"4394372887385518214471608448209527405727552777602031099972143344338178308080", "price":"0.187", "size":"30", "side":"SELL", "hash":"5a3b96d1d961b8d1716ee355ec15708c0482f3aa", "best_bid":"0.167", "best_ask":"0.168"}], "timestamp":"1780179092137", "event_type":"price_change"}
{"market":"0x1595b4818eeb1ea1e0bec5de6f057218e557feee9b405a0e930d290384fa1d16", "price_changes":[{"asset_id":"45484070731786948288366703334552551439356529561722304542938873238430842810537", "price":"0.927", "size":"5259.68", "side":"BUY", "hash":"d4e3fb368703f27f09a28ea594416f8be3fe1488", "best_bid":"0.948", "best_ask":"0.949"}, {"asset_id":"81739002353269632749850710185641576213562066971072676369728657545679630163887", "price":"0.073", "size":"5259.68", "side":"SELL", "hash":"1fbdac5bcca611ba95fe8ea2ff9f984de73ada82", "best_bid":"0.051", "best_ask":"0.052"}], "timestamp":"1780179092140", "event_type":"price_change"}
PONG
{"market":"0x7876851632c295043c66536150a304cb785abdf712ba8489d298c6e6926be106", "price_changes":[{"asset_id":"19291692040378529618917910599727571242305935029274321291612270922648172794670", "price":"0.967", "size":"10424", "side":"BUY", "hash":"a97f76e8213b6e71e3222d359d11390177767493", "best_bid":"0.989", "best_ask":"0.99"}, {"asset_id":"97239126062673310243763617236644392945530356142765650402171508075574679292913", "price":"0.033", "size":"10424", "side":"SELL", "hash":"d8efd6170da3461ef08b423332e757434b0af314", "best_bid":"0.01", "best_ask":"0.011"}], "timestamp":"1780179092141", "event_type":"price_change"}
{"market":"0x30d55d8124ee1e12dabe89201badc45669b81dff69e4ce44d961f32878ec178a", "price_changes":[{"asset_id":"52986718774908357330412653486471347449818893503063830313445318937088822580057", "price":"0.89", "size":"30299.11", "side":"BUY", "hash":"2e00101409109cf4a06d158d21fa3649b0d763bd", "best_bid":"0.91", "best_ask":"0.911"}, {"asset_id":"27576533317283401577758999384642760405921738493660383550832555714312627457443", "price":"0.11", "size":"30299.11", "side":"SELL", "hash":"d647734dce0fa17b64fc6ece62237603015e3336", "best_bid":"0.089", "best_ask":"0.09"}], "timestamp":"1780179092146", "event_type":"price_change"}
{"market":"0x375409bc5eeeff961e82b479caeccc20f33d15738e5bce1186d628aa3d9dfb1f", "price_changes":[{"asset_id":"77121637225348873006259930776623502125079210522997384841464684944292365296940", "price":"0.868", "size":"25314.14", "side":"BUY", "hash":"d960c2b7a854002b6851196b1e6dddeb37319d39", "best_bid":"0.887", "best_ask":"0.888"}, {"asset_id":"115556263888245616435851357148058235707004733438163639091106356867234218207169", "price":"0.132", "size":"25314.14", "side":"SELL", "hash":"ab8f8f5fd380818ed5e3cc1bfd42999b192e44b8", "best_bid":"0.112", "best_ask":"0.113"}], "timestamp":"1780179092172", "event_type":"price_change"}
{"market":"0x1595b4818eeb1ea1e0bec5de6f057218e557feee9b405a0e930d290384fa1d16", "price_changes":[{"asset_id":"45484070731786948288366703334552551439356529561722304542938873238430842810537", "price":"0.928", "size":"7215.61", "side":"BUY", "hash":"fc8e73f716c4efad44363dd1fc0c2c8cd3bca0c7", "best_bid":"0.948", "best_ask":"0.949"}, {"asset_id":"81739002353269632749850710185641576213562066971072676369728657545679630163887", "price":"0.072", "size":"7215.61", "side":"SELL", "hash":"9bf60d7d0b8aa3845a373d9bb5b9cbe7d0279f90", "best_bid":"0.051", "best_ask":"0.052"}], "timestamp":"1780179092176", "event_type":"price_change"}
{"market":"0x30d55d8124ee1e12dabe89201badc45669b81dff69e4ce44d961f32878ec178a", "price_changes":[{"asset_id":"52986718774908357330412653486471347449818893503063830313445318937088822580057", "price":"0.891", "size":"7447.7", "side":"BUY", "hash":"f99558114af8c383507b48f63c6e07bcc3cc3bcd", "best_bid":"0.91", "best_ask":"0.911"}, {"asset_id":"27576533317283401577758999384642760405921738493660383550832555714312627457443", "price":"0.109", "size":"7447.7", "side":"SELL", "hash":"5d68e8dc1ad2487648daced44c7f40e5cea2ed59", "best_bid":"0.089", "best_ask":"0.09"}], "timestamp":"1780179092208", "event_type":"price_change"}
{"market":"0x4f3421fb2daf5cca7430ed8d8132463963081572d75434393a1808fdb8829fe8", "price_changes":[{"asset_id":"31940783580344558651011323787577288681658737625185216525249046282994042503801", "price":"0.88", "size":"399.7", "side":"BUY", "hash":"412bbc0b261c914be11ae7dc40260a2bc7385930", "best_bid":"0.899", "best_ask":"0.9"}, {"asset_id":"45415751658241142530386585138386640503488308219341470020075667342738719018629", "price":"0.12", "size":"399.7", "side":"SELL", "hash":"3e353cfa54a8db3cd61aaf4e4c8e7910a4e933fa", "best_bid":"0.1", "best_ask":"0.101"}], "timestamp":"1780179092248", "event_type":"price_change"}
{"market":"0x7976b8dbacf9077eb1453a62bcefd6ab2df199acd28aad276ff0d920d6992892", "price_changes":[{"asset_id":"112680630004798425069810935278212000865453267506345451433803052322987302357330", "price":"0.814", "size":"212.7", "side":"BUY", "hash":"70bb0f3d41f9ff9d88e91fd1592754ca56debd5c", "best_bid":"0.832", "best_ask":"0.833"}, {"asset_id":"4394372887385518214471608448209527405727552777602031099972143344338178308080", "price":"0.186", "size":"212.7", "side":"SELL", "hash":"df784289a99a404ff7ef6925ca3eb0e9ab98667a", "best_bid":"0.167", "best_ask":"0.168"}], "timestamp":"1780179092440", "event_type":"price_change"}
{"market":"0x7876851632c295043c66536150a304cb785abdf712ba8489d298c6e6926be106", "price_changes":[{"asset_id":"19291692040378529618917910599727571242305935029274321291612270922648172794670", "price":"0.968", "size":"4489.78", "side":"BUY", "hash":"9c77a1dc46188ae5b2800781ad236d5641a18009", "best_bid":"0.989", "best_ask":"0.99"}, {"asset_id":"97239126062673310243763617236644392945530356142765650402171508075574679292913", "price":"0.032", "size":"4489.78", "side":"SELL", "hash":"7e03b27c74e9c093c7653074ba1ae0b33c3f9ebb", "best_bid":"0.01", "best_ask":"0.011"}], "timestamp":"1780179092443", "event_type":"price_change"}
{"market":"0x0c4cd2055d6ea89354ffddc55d6dbcef9355748112ea952fc925f3db6a5c457f", "price_changes":[{"asset_id":"115428153746996892211798999366308897078723117634059783423375188043903703749062", "price":"0.895", "size":"5522.44", "side":"BUY", "hash":"d40c1d83d7a9294cfd8be56b7791527ccd54b0de", "best_bid":"0.914", "best_ask":"0.915"}, {"asset_id":"18812649149814341758733697580460697418474693998558159483117100240528657629879", "price":"0.105", "size":"5522.44", "side":"SELL", "hash":"e0953e759ec290ef674ae10489d94874a24af13f", "best_bid":"0.085", "best_ask":"0.086"}], "timestamp":"1780179092452", "event_type":"price_change"}
{"market":"0x0c4cd2055d6ea89354ffddc55d6dbcef9355748112ea952fc925f3db6a5c457f", "price_changes":[{"asset_id":"115428153746996892211798999366308897078723117634059783423375188043903703749062", "price":"0.75", "size":"3393.18", "side":"BUY", "hash":"d90f611a49bd55871e85a0e89a1004bb30c28211", "best_bid":"0.914", "best_ask":"0.915"}, {"asset_id":"18812649149814341758733697580460697418474693998558159483117100240528657629879", "price":"0.25", "size":"3393.18", "side":"SELL", "hash":"b5e14c1be3de340697b82ae312128d19a5d7812b", "best_bid":"0.085", "best_ask":"0.086"}], "timestamp":"1780179092513", "event_type":"price_change"}
{"market":"0x7876851632c295043c66536150a304cb785abdf712ba8489d298c6e6926be106", "price_changes":[{"asset_id":"97239126062673310243763617236644392945530356142765650402171508075574679292913", "price":"0.01", "size":"1265250", "side":"BUY", "hash":"59ca2bff61d1eb12bd2de5f09fafb35e5a4862ac", "best_bid":"0.01", "best_ask":"0.011"}, {"asset_id":"19291692040378529618917910599727571242305935029274321291612270922648172794670", "price":"0.99", "size":"1265250", "side":"SELL", "hash":"a19a438a2574e06fe80de3a9c1ad321637485b10", "best_bid":"0.989", "best_ask":"0.99"}], "timestamp":"1780179093493", "event_type":"price_change"}
{"market":"0x9b6fef249040fd17e9c107955b37ac2c3e923509b6b0ff01cc463a331ddeb894", "price_changes":[{"asset_id":"108233603819467706476318984012158651931658302669301887462181073562758483842092", "price":"0.837", "size":"0", "side":"SELL", "hash":"8abc4c1858fc73eadc1248b6f1a0283310d2626f", "best_bid":"0.163", "best_ask":"0.164"}, {"asset_id":"32270411694523539495262303868629477861017829722282576458031815333486368239544", "price":"0.163", "size":"0", "side":"BUY", "hash":"df9215090b80fc30702ba482cffdfa7c56ddafa7", "best_bid":"0.836", "best_ask":"0.837"}], "timestamp":"1780179097796", "event_type":"price_change"}
{"market":"0x7976b8dbacf9077eb1453a62bcefd6ab2df199acd28aad276ff0d920d6992892", "price_changes":[{"asset_id":"4394372887385518214471608448209527405727552777602031099972143344338178308080", "price":"0.833", "size":"0", "side":"SELL", "hash":"2a1471b165c2caa4d6585effd315f2b695e391ac", "best_bid":"0.167", "best_ask":"0.168"}, {"asset_id":"112680630004798425069810935278212000865453267506345451433803052322987302357330", "price":"0.167", "size":"0", "side":"BUY", "hash":"b056e8c961f89accf0811e70fbd4d5c3d623528b", "best_bid":"0.832", "best_ask":"0.833"}], "timestamp":"1780179097819", "event_type":"price_change"}
{"market":"0x4f3421fb2daf5cca7430ed8d8132463963081572d75434393a1808fdb8829fe8", "price_changes":[{"asset_id":"45415751658241142530386585138386640503488308219341470020075667342738719018629", "price":"0.9", "size":"2254.88", "side":"SELL", "hash":"195935ae648e6acbc428d02f84ac778bbace7c7a", "best_bid":"0.1", "best_ask":"0.101"}, {"asset_id":"31940783580344558651011323787577288681658737625185216525249046282994042503801", "price":"0.1", "size":"2254.88", "side":"BUY", "hash":"050df07a198bda3b2da6947ce176af089f8d0795", "best_bid":"0.899", "best_ask":"0.9"}], "timestamp":"1780179097978", "event_type":"price_change"}
{"id":"2397889", "question":"Solana Up or Down - May 31, 6:00PM-6:05PM ET", "market":"0xde508c71ffdc4afbfcf699e3ca428278d57807e008841e90fa6f415fa194f6a4", "slug":"sol-updown-5m-1780264800", "description":"This market will resolve to \"Up\" if the Solana price at the end of the time range specified in the title is greater than or equal to the price at the beginning of that range. Otherwise, it will resolve to \"Down\".\nThe resolution source for this market is information from Chainlink, specifically the SOL/USD data stream available at https://data.chain.link/streams/sol-usd.\nPlease note that this market is about the price according to Chainlink data stream SOL/USD, not according to other sources or spot markets.", "assets_ids":["4227413890839322448836463842382078118302165910944336019620145193200082042145", "85114573420789905771748383049875738993280112025434604727883629699391680072512"], "outcomes":["Up", "Down"], "event_message":{"id":"542711", "ticker":"sol-updown-5m-1780264800", "slug":"sol-updown-5m-1780264800", "title":"Solana Up or Down - May 31, 6:00PM-6:05PM ET", "description":"This market will resolve to \"Up\" if the Solana price at the end of the time range specified in the title is greater than or equal to the price at the beginning of that range. Otherwise, it will resolve to \"Down\".\nThe resolution source for this market is information from Chainlink, specifically the SOL/USD data stream available at https://data.chain.link/streams/sol-usd.\nPlease note that this market is about the price according to Chainlink data stream SOL/USD, not according to other sources or spot markets."}, "timestamp":"1780179101026", "event_type":"new_market", "tags":[], "condition_id":"0xde508c71ffdc4afbfcf699e3ca428278d57807e008841e90fa6f415fa194f6a4", "active":false, "clob_token_ids":["4227413890839322448836463842382078118302165910944336019620145193200082042145", "85114573420789905771748383049875738993280112025434604727883629699391680072512"], "sports_market_type":"", "line":"", "game_start_time":"", "order_price_min_tick_size":"0.01", "group_item_title":"", "taker_base_fee":"1000", "fees_enabled":true, "fee_schedule":{"exponent":"1", "rate":"0.07", "taker_only":true, "rebate_rate":"0.2"}}
PONG
{"market":"0x4f3421fb2daf5cca7430ed8d8132463963081572d75434393a1808fdb8829fe8", "price_changes":[{"asset_id":"45415751658241142530386585138386640503488308219341470020075667342738719018629", "price":"0.103", "size":"18203.31", "side":"SELL", "hash":"e935b14db334741ff40ac0fb64fc2d076643ace5", "best_bid":"0.1", "best_ask":"0.101"}, {"asset_id":"31940783580344558651011323787577288681658737625185216525249046282994042503801", "price":"0.897", "size":"18203.31", "side":"BUY", "hash":"42b963511ec7ac83572e5cdee38568b5ea36300c", "best_bid":"0.899", "best_ask":"0.9"}], "timestamp":"1780179104307", "event_type":"price_change"}
{"market":"0x9b6fef249040fd17e9c107955b37ac2c3e923509b6b0ff01cc463a331ddeb894", "price_changes":[{"asset_id":"108233603819467706476318984012158651931658302669301887462181073562758483842092", "price":"0.166", "size":"24952", "side":"SELL", "hash":"9e1ad265cdd9e22d43a867bfbf85204adc476363", "best_bid":"0.163", "best_ask":"0.164"}, {"asset_id":"32270411694523539495262303868629477861017829722282576458031815333486368239544", "price":"0.834", "size":"24952", "side":"BUY", "hash":"67734e4d6d3a3882ffdc8e9b18c46136df0cca2c", "best_bid":"0.836", "best_ask":"0.837"}], "timestamp":"1780179104309", "event_type":"price_change"}
{"market":"0x9b6fef249040fd17e9c107955b37ac2c3e923509b6b0ff01cc463a331ddeb894", "price_changes":[{"asset_id":"108233603819467706476318984012158651931658302669301887462181073562758483842092", "price":"0.166", "size":"25006.72", "side":"SELL", "hash":"c85a24fe52e82631f7734d397a4b74faa9d4b975", "best_bid":"0.163", "best_ask":"0.164"}, {"asset_id":"32270411694523539495262303868629477861017829722282576458031815333486368239544", "price":"0.834", "size":"25006.72", "side":"BUY", "hash":"b6fce12bbc5830221d12f5b8802090466f9960fc", "best_bid":"0.836", "best_ask":"0.837"}], "timestamp":"1780179104424", "event_type":"price_change"}
{"market":"0x4f3421fb2daf5cca7430ed8d8132463963081572d75434393a1808fdb8829fe8", "price_changes":[{"asset_id":"45415751658241142530386585138386640503488308219341470020075667342738719018629", "price":"0.103", "size":"18263.31", "side":"SELL", "hash":"5538418ff470982094ec1fc26553884becbdfcf7", "best_bid":"0.1", "best_ask":"0.101"}, {"asset_id":"31940783580344558651011323787577288681658737625185216525249046282994042503801", "price":"0.897", "size":"18263.31", "side":"BUY", "hash":"f19fcb301ded947537749fb372a5f86f1b740b7e", "best_bid":"0.899", "best_ask":"0.9"}], "timestamp":"1780179104433", "event_type":"price_change"}
{"market":"0x7976b8dbacf9077eb1453a62bcefd6ab2df199acd28aad276ff0d920d6992892", "price_changes":[{"asset_id":"112680630004798425069810935278212000865453267506345451433803052322987302357330", "price":"0.784", "size":"1000", "side":"BUY", "hash":"00f34b5294bd1073f830eb123ef4041aff561068", "best_bid":"0.832", "best_ask":"0.833"}, {"asset_id":"4394372887385518214471608448209527405727552777602031099972143344338178308080", "price":"0.216", "size":"1000", "side":"SELL", "hash":"0ac26e4b6f9881f53f9595ee2c26e075ba8f7b6c", "best_bid":"0.167", "best_ask":"0.168"}], "timestamp":"1780179104769", "event_type":"price_change"}
{"market":"0x30d55d8124ee1e12dabe89201badc45669b81dff69e4ce44d961f32878ec178a", "price_changes":[{"asset_id":"52986718774908357330412653486471347449818893503063830313445318937088822580057", "price":"0.861", "size":"0", "side":"BUY", "hash":"5d89f9e6d6a4e3d8c2b60b38b9f8224d6705a6da", "best_bid":"0.91", "best_ask":"0.911"}, {"asset_id":"27576533317283401577758999384642760405921738493660383550832555714312627457443", "price":"0.139", "size":"0", "side":"SELL", "hash":"05474b21eb8c906796b5acfad875b046399b61e8", "best_bid":"0.089", "best_ask":"0.09"}], "timestamp":"1780179104770", "event_type":"price_change"}
{"market":"0x4f3421fb2daf5cca7430ed8d8132463963081572d75434393a1808fdb8829fe8", "price_changes":[{"asset_id":"31940783580344558651011323787577288681658737625185216525249046282994042503801", "price":"0.85", "size":"15927.35", "side":"BUY", "hash":"662341e196004427d6af9336a0e5c03d2b3fa353", "best_bid":"0.899", "best_ask":"0.9"}, {"asset_id":"45415751658241142530386585138386640503488308219341470020075667342738719018629", "price":"0.15", "size":"15927.35", "side":"SELL", "hash":"89dd99872380e148c6b5dfc5bb2d602908d44222", "best_bid":"0.1", "best_ask":"0.101"}], "timestamp":"1780179104769", "event_type":"price_change"}
{"market":"0x375409bc5eeeff961e82b479caeccc20f33d15738e5bce1186d628aa3d9dfb1f", "price_changes":[{"asset_id":"77121637225348873006259930776623502125079210522997384841464684944292365296940", "price":"0.838", "size":"0", "side":"BUY", "hash":"e904c2b0674e9a054ee6ab4224eace420b7581ea", "best_bid":"0.887", "best_ask":"0.888"}, {"asset_id":"115556263888245616435851357148058235707004733438163639091106356867234218207169", "price":"0.162", "size":"0", "side":"SELL", "hash":"a0c5c92d373cddcd3b89deefdf69f3c8b7e3f896", "best_bid":"0.112", "best_ask":"0.113"}], "timestamp":"1780179104769", "event_type":"price_change"}
{"market":"0x4f3421fb2daf5cca7430ed8d8132463963081572d75434393a1808fdb8829fe8", "price_changes":[{"asset_id":"31940783580344558651011323787577288681658737625185216525249046282994042503801", "price":"0.77", "size":"0", "side":"BUY", "hash":"662341e196004427d6af9336a0e5c03d2b3fa353", "best_bid":"0.899", "best_ask":"0.9"}, {"asset_id":"45415751658241142530386585138386640503488308219341470020075667342738719018629", "price":"0.23", "size":"0", "side":"SELL", "hash":"89dd99872380e148c6b5dfc5bb2d602908d44222", "best_bid":"0.1", "best_ask":"0.101"}], "timestamp":"1780179104769", "event_type":"price_change"}
{"market":"0x0c4cd2055d6ea89354ffddc55d6dbcef9355748112ea952fc925f3db6a5c457f", "price_changes":[{"asset_id":"115428153746996892211798999366308897078723117634059783423375188043903703749062", "price":"0.865", "size":"0", "side":"BUY", "hash":"2b87ffe5f305cf23434419591bd284ef1d16fd3b", "best_bid":"0.914", "best_ask":"0.915"}, {"asset_id":"18812649149814341758733697580460697418474693998558159483117100240528657629879", "price":"0.135", "size":"0", "side":"SELL", "hash":"7a8472050a1ad9ff425c717f5d5a1bea6f7f0aa5", "best_bid":"0.085", "best_ask":"0.086"}], "timestamp":"1780179104769", "event_type":"price_change"}
{"market":"0x9b6fef249040fd17e9c107955b37ac2c3e923509b6b0ff01cc463a331ddeb894", "price_changes":[{"asset_id":"32270411694523539495262303868629477861017829722282576458031815333486368239544", "price":"0.788", "size":"10", "side":"BUY", "hash":"ae35cc3949eadc010851ff8e7dbad675586aaebb", "best_bid":"0.836", "best_ask":"0.837"}, {"asset_id":"108233603819467706476318984012158651931658302669301887462181073562758483842092", "price":"0.212", "size":"10", "side":"SELL", "hash":"d2129f967f5147e36447f8c43c4544bec2c1472a", "best_bid":"0.163", "best_ask":"0.164"}], "timestamp":"1780179104770", "event_type":"price_change"}
{"market":"0x4f3421fb2daf5cca7430ed8d8132463963081572d75434393a1808fdb8829fe8", "price_changes":[{"asset_id":"31940783580344558651011323787577288681658737625185216525249046282994042503801", "price":"0.771", "size":"100", "side":"BUY", "hash":"d660f35f3bbe5f40e69701457e0b80622baff9e7", "best_bid":"0.899", "best_ask":"0.9"}, {"asset_id":"45415751658241142530386585138386640503488308219341470020075667342738719018629", "price":"0.229", "size":"100", "side":"SELL", "hash":"42ea2ec70148623da5900f435cb7d65c52222cdb", "best_bid":"0.1", "best_ask":"0.101"}], "timestamp":"1780179104779", "event_type":"price_change"}
{"market":"0x4f3421fb2daf5cca7430ed8d8132463963081572d75434393a1808fdb8829fe8", "price_changes":[{"asset_id":"31940783580344558651011323787577288681658737625185216525249046282994042503801", "price":"0.851", "size":"900", "side":"BUY", "hash":"6463a85d49709a78e1105fc161b26c6562322d06", "best_bid":"0.899", "best_ask":"0.9"}, {"asset_id":"45415751658241142530386585138386640503488308219341470020075667342738719018629", "price":"0.149", "size":"900", "side":"SELL", "hash":"f60b56fe89823805d71fcf2dbbbc0493c069b5f6", "best_bid":"0.1", "best_ask":"0.101"}], "timestamp":"1780179104785", "event_type":"price_change"}
{"market":"0x375409bc5eeeff961e82b479caeccc20f33d15738e5bce1186d628aa3d9dfb1f", "price_changes":[{"asset_id":"77121637225348873006259930776623502125079210522997384841464684944292365296940", "price":"0.839", "size":"100", "side":"BUY", "hash":"4fa3706862c6ea4e75fa7ba820314b91a5d09424", "best_bid":"0.887", "best_ask":"0.888"}, {"asset_id":"115556263888245616435851357148058235707004733438163639091106356867234218207169", "price":"0.161", "size":"100", "side":"SELL", "hash":"fbe37825fcd1926dfaa9027ca07dc284bcf1f420", "best_bid":"0.112", "best_ask":"0.113"}], "timestamp":"1780179104799", "event_type":"price_change"}
{"market":"0x9b6fef249040fd17e9c107955b37ac2c3e923509b6b0ff01cc463a331ddeb894", "price_changes":[{"asset_id":"32270411694523539495262303868629477861017829722282576458031815333486368239544", "price":"0.789", "size":"5655.55", "side":"BUY", "hash":"db4764ca024cbe4c11cb257e952d999c37ed8e9e", "best_bid":"0.836", "best_ask":"0.837"}, {"asset_id":"108233603819467706476318984012158651931658302669301887462181073562758483842092", "price":"0.211", "size":"5655.55", "side":"SELL", "hash":"6b63fabbe47f08f299da2477bcac912e118e6917", "best_bid":"0.163", "best_ask":"0.164"}], "timestamp":"1780179104813", "event_type":"price_change"}
{"market":"0x0c4cd2055d6ea89354ffddc55d6dbcef9355748112ea952fc925f3db6a5c457f", "price_changes":[{"asset_id":"115428153746996892211798999366308897078723117634059783423375188043903703749062", "price":"0.866", "size":"100", "side":"BUY", "hash":"3e279977142a39d4cd0256ae68ed550a8f221347", "best_bid":"0.914", "best_ask":"0.915"}, {"asset_id":"18812649149814341758733697580460697418474693998558159483117100240528657629879", "price":"0.134", "size":"100", "side":"SELL", "hash":"ba9058a91bdcde5dfef344d85a795dfa0f40bdbc", "best_bid":"0.085", "best_ask":"0.086"}], "timestamp":"1780179104828", "event_type":"price_change"}
{"market":"0x7976b8dbacf9077eb1453a62bcefd6ab2df199acd28aad276ff0d920d6992892", "price_changes":[{"asset_id":"112680630004798425069810935278212000865453267506345451433803052322987302357330", "price":"0.785", "size":"100", "side":"BUY", "hash":"56dc4f3335ef9ccfbb61ce3de42c42e05f68de27", "best_bid":"0.832", "best_ask":"0.833"}, {"asset_id":"4394372887385518214471608448209527405727552777602031099972143344338178308080", "price":"0.215", "size":"100", "side":"SELL", "hash":"f6b449e4c60c1701f106a7d56080b9747015c551", "best_bid":"0.167", "best_ask":"0.168"}], "timestamp":"1780179104837", "event_type":"price_change"}
{"market":"0x30d55d8124ee1e12dabe89201badc45669b81dff69e4ce44d961f32878ec178a", "price_changes":[{"asset_id":"52986718774908357330412653486471347449818893503063830313445318937088822580057", "price":"0.862", "size":"100", "side":"BUY", "hash":"451050166369fb206192816afeda556856f89e11", "best_bid":"0.91", "best_ask":"0.911"}, {"asset_id":"27576533317283401577758999384642760405921738493660383550832555714312627457443", "price":"0.138", "size":"100", "side":"SELL", "hash":"38a2a8f750b3596a5da31a4075710c8bbe0d9ea5", "best_bid":"0.089", "best_ask":"0.09"}], "timestamp":"1780179104845", "event_type":"price_change"}
{"market":"0x0c4cd2055d6ea89354ffddc55d6dbcef9355748112ea952fc925f3db6a5c457f", "price_changes":[{"asset_id":"115428153746996892211798999366308897078723117634059783423375188043903703749062", "price":"0.75", "size":"3383.18", "side":"BUY", "hash":"a483715f4a658c00cce31bfe5a2c75721c41fb21", "best_bid":"0.914", "best_ask":"0.915"}, {"asset_id":"18812649149814341758733697580460697418474693998558159483117100240528657629879", "price":"0.25", "size":"3383.18", "side":"SELL", "hash":"b949663687ac77f443f8a6ecfaed65699b5d5b4c", "best_bid":"0.085", "best_ask":"0.086"}], "timestamp":"1780179104895", "event_type":"price_change"}
{"market":"0x0c4cd2055d6ea89354ffddc55d6dbcef9355748112ea952fc925f3db6a5c457f", "price_changes":[{"asset_id":"115428153746996892211798999366308897078723117634059783423375188043903703749062", "price":"0.76", "size":"10", "side":"BUY", "hash":"899d1856d30f8d0089e29c965656a5e499989e8a", "best_bid":"0.914", "best_ask":"0.915"}, {"asset_id":"18812649149814341758733697580460697418474693998558159483117100240528657629879", "price":"0.24", "size":"10", "side":"SELL", "hash":"a0d06cf049ef0175629268463f82b9e8834ab0f1", "best_bid":"0.085", "best_ask":"0.086"}], "timestamp":"1780179105320", "event_type":"price_change"}
{"market":"0x7976b8dbacf9077eb1453a62bcefd6ab2df199acd28aad276ff0d920d6992892", "price_changes":[{"asset_id":"4394372887385518214471608448209527405727552777602031099972143344338178308080", "price":"0.17", "size":"27608.28", "side":"SELL", "hash":"f02e041e9add014c23d12375a3dd82f4bc1ddc01", "best_bid":"0.167", "best_ask":"0.168"}, {"asset_id":"112680630004798425069810935278212000865453267506345451433803052322987302357330", "price":"0.83", "size":"27608.28", "side":"BUY", "hash":"c252715f0aa9c297f54e27ac5c24b77bb68be9df", "best_bid":"0.832", "best_ask":"0.833"}], "timestamp":"1780179105742", "event_type":"price_change"}
{"market":"0x30d55d8124ee1e12dabe89201badc45669b81dff69e4ce44d961f32878ec178a", "price_changes":[{"asset_id":"27576533317283401577758999384642760405921738493660383550832555714312627457443", "price":"0.092", "size":"78371.18", "side":"SELL", "hash":"72f0963c5ff7b7a27dbd3093006f90023bed18ab", "best_bid":"0.089", "best_ask":"0.09"}, {"asset_id":"52986718774908357330412653486471347449818893503063830313445318937088822580057", "price":"0.908", "size":"78371.18", "side":"BUY", "hash":"8aad0a5ddd6d9693b775e650b2323f370845b84d", "best_bid":"0.91", "best_ask":"0.911"}], "timestamp":"1780179105745", "event_type":"price_change"}
{"market":"0x7976b8dbacf9077eb1453a62bcefd6ab2df199acd28aad276ff0d920d6992892", "price_changes":[{"asset_id":"4394372887385518214471608448209527405727552777602031099972143344338178308080", "price":"0.17", "size":"27662.47", "side":"SELL", "hash":"ae1c5064b73071c191d15ef35d4f5426bd62ec6c", "best_bid":"0.167", "best_ask":"0.168"}, {"asset_id":"112680630004798425069810935278212000865453267506345451433803052322987302357330", "price":"0.83", "size":"27662.47", "side":"BUY", "hash":"8d09b4b1a7a22bcddf7fea31a621fb99026dc2ed", "best_bid":"0.832", "best_ask":"0.833"}], "timestamp":"1780179105875", "event_type":"price_change"}
{"market":"0x30d55d8124ee1e12dabe89201badc45669b81dff69e4ce44d961f32878ec178a", "price_changes":[{"asset_id":"27576533317283401577758999384642760405921738493660383550832555714312627457443", "price":"0.092", "size":"78431.18", "side":"SELL", "hash":"8de77baf1ffa24b2cdb94fa582f2727eaef36dd4", "best_bid":"0.089", "best_ask":"0.09"}, {"asset_id":"52986718774908357330412653486471347449818893503063830313445318937088822580057", "price":"0.908", "size":"78431.18", "side":"BUY", "hash":"737f777b4c227a599fe2d6994b6b37d842972ec2", "best_bid":"0.91", "best_ask":"0.911"}], "timestamp":"1780179105877", "event_type":"price_change"}
{"market":"0x1595b4818eeb1ea1e0bec5de6f057218e557feee9b405a0e930d290384fa1d16", "price_changes":[{"asset_id":"81739002353269632749850710185641576213562066971072676369728657545679630163887", "price":"0.053", "size":"3311.26", "side":"SELL", "hash":"df0ddb2123c62affc547eac641123d8d68c8d38e", "best_bid":"0.051", "best_ask":"0.052"}, {"asset_id":"45484070731786948288366703334552551439356529561722304542938873238430842810537", "price":"0.947", "size":"3311.26", "side":"BUY", "hash":"369d89bec5c4be0f694153930f59485fb23d4901", "best_bid":"0.948", "best_ask":"0.949"}], "timestamp":"1780179107004", "event_type":"price_change"}
{"market":"0x0c4cd2055d6ea89354ffddc55d6dbcef9355748112ea952fc925f3db6a5c457f", "price_changes":[{"asset_id":"18812649149814341758733697580460697418474693998558159483117100240528657629879", "price":"0.088", "size":"15069.46", "side":"SELL", "hash":"887a45b3903313a2920527535e2e782b76aa9bac", "best_bid":"0.085", "best_ask":"0.086"}, {"asset_id":"115428153746996892211798999366308897078723117634059783423375188043903703749062", "price":"0.912", "size":"15069.46", "side":"BUY", "hash":"2e4db08832b858853d415b109412cc27bb0ece19", "best_bid":"0.914", "best_ask":"0.915"}], "timestamp":"1780179107007", "event_type":"price_change"}
{"market":"0x1595b4818eeb1ea1e0bec5de6f057218e557feee9b405a0e930d290384fa1d16", "price_changes":[{"asset_id":"81739002353269632749850710185641576213562066971072676369728657545679630163887", "price":"0.053", "size":"3371.26", "side":"SELL", "hash":"1dfff51f34beae5cd82add9299703d74d5d23628", "best_bid":"0.051", "best_ask":"0.052"}, {"asset_id":"45484070731786948288366703334552551439356529561722304542938873238430842810537", "price":"0.947", "size":"3371.26", "side":"BUY", "hash":"4a0d6710d001dbca2767f8c0fddb8a27f3d4b063", "best_bid":"0.948", "best_ask":"0.949"}], "timestamp":"1780179107155", "event_type":"price_change"}
{"market":"0x0c4cd2055d6ea89354ffddc55d6dbcef9355748112ea952fc925f3db6a5c457f", "price_changes":[{"asset_id":"18812649149814341758733697580460697418474693998558159483117100240528657629879", "price":"0.088", "size":"15129.46", "side":"SELL", "hash":"72a809903ecf783949e5e3c1f23d2dcc22456bcb", "best_bid":"0.085", "best_ask":"0.086"}, {"asset_id":"115428153746996892211798999366308897078723117634059783423375188043903703749062", "price":"0.912", "size":"15129.46", "side":"BUY", "hash":"72e432d8b29f3b5425b2e04256ccfa64b7fc0a1b", "best_bid":"0.914", "best_ask":"0.915"}], "timestamp":"1780179107186", "event_type":"price_change"}
{"market":"0x375409bc5eeeff961e82b479caeccc20f33d15738e5bce1186d628aa3d9dfb1f", "price_changes":[{"asset_id":"115556263888245616435851357148058235707004733438163639091106356867234218207169", "price":"0.115", "size":"12019.15", "side":"SELL", "hash":"01de9dd59cb7a2923e090476606918329ff2292e", "best_bid":"0.112", "best_ask":"0.113"}, {"asset_id":"77121637225348873006259930776623502125079210522997384841464684944292365296940", "price":"0.885", "size":"12019.15", "side":"BUY", "hash":"5bcc354590ecee1b39ac2ab73d4a6aa52853f5d2", "best_bid":"0.887", "best_ask":"0.888"}], "timestamp":"1780179107239", "event_type":"price_change"}
{"market":"0x375409bc5eeeff961e82b479caeccc20f33d15738e5bce1186d628aa3d9dfb1f", "price_changes":[{"asset_id":"115556263888245616435851357148058235707004733438163639091106356867234218207169", "price":"0.115", "size":"12079.15", "side":"SELL", "hash":"bde5784028ac8e42d18e1d275ca29689beffc642", "best_bid":"0.112", "best_ask":"0.113"}, {"asset_id":"77121637225348873006259930776623502125079210522997384841464684944292365296940", "price":"0.885", "size":"12079.15", "side":"BUY", "hash":"3c5a5ff5ab6b7bc81657e97b501b319e78923cd2", "best_bid":"0.887", "best_ask":"0.888"}], "timestamp":"1780179107374", "event_type":"price_change"}
{"id":"2397873", "question":"Spread: New York Mets (-3.5)", "market":"0xf922964391d1533688d453b303e1c161c8743e25585da89a078a54b7cd7da361", "slug":"mlb-mia-nym-2026-05-31-spread-home-3pt5", "description":"In the upcoming MLB game between the Miami Marlins and New York Mets, scheduled for May 31 at 1:40 PM ET:\n\nThis market will resolve to \"New York Mets\" if the New York Mets win the game by 4 or more runs.\n\nOtherwise, this market will resolve to \"Miami Marlins\". If the game ends in a tie, this market will resolve to \"Miami Marlins\".\n\nIf the game is postponed, this market will remain open until the game has been completed. If the game is canceled entirely, with no make-up game, this market will resolve 50-50.\n\nTo know when a postponed game will be played, please check the home team's schedule on MLB.com for the listed team and look for the game described as a makeup game.\n\nThe primary resolution source for this market is the official final statistics of the event as recognized by the governing body or event organizers. However, if the governing body or event organizers have not published final match statistics within 24 hours after the event's conclusion, a consensus of credible reporting may be used instead.", "assets_ids":["6352319440761644810192414985992480590521314975024603819389406244872649065891", "503930066859859630722540506599597681271949418139593730972479568799973719267"], "outcomes":["New York Mets", "Miami Marlins"], "event_message":{"id":"523532", "ticker":"mlb-mia-nym-2026-05-31", "slug":"mlb-mia-nym-2026-05-31", "title":"Miami Marlins vs. New York Mets", "description":"In the upcoming MLB game between the Miami Marlins and New York Mets, scheduled for May 31 at 1:40PM ET:\n\nThis market will resolve to \"Miami Marlins\" if the Miami Marlins win the game.\n\nThis market will resolve to \"New York Mets\" if the New York Mets win the game.\n\nIf the game is postponed, this market will remain open until the game has been completed. If the game is canceled entirely, with no make-up game, or ends in a tie, this market will resolve 50-50.\n\nThe primary resolution source for this market is the official final statistics of the event as recognized by the governing body or event organizers. However, if the governing body or event organizers have not published final match statistics within 24 hours after the event's conclusion, a consensus of credible reporting may be used instead."}, "timestamp":"1780179110781", "event_type":"new_market", "tags":[], "condition_id":"0xf922964391d1533688d453b303e1c161c8743e25585da89a078a54b7cd7da361", "active":false, "clob_token_ids":["6352319440761644810192414985992480590521314975024603819389406244872649065891", "503930066859859630722540506599597681271949418139593730972479568799973719267"], "sports_market_type":"spreads", "line":"-3.5", "game_start_time":"2026-05-31 17:40:00+00", "order_price_min_tick_size":"0.01", "group_item_title":"Spread -3.5", "taker_base_fee":"1000", "fees_enabled":true, "fee_schedule":{"exponent":"1", "rate":"0.03", "taker_only":true, "rebate_rate":"0.25"}}
{"market":"0x7876851632c295043c66536150a304cb785abdf712ba8489d298c6e6926be106", "price_changes":[{"asset_id":"97239126062673310243763617236644392945530356142765650402171508075574679292913", "price":"0.011", "size":"1818525.69", "side":"SELL", "hash":"a7ede37fd6d030b9d04f2edfd2ee3c73e06c6ff1", "best_bid":"0.01", "best_ask":"0.011"}, {"asset_id":"19291692040378529618917910599727571242305935029274321291612270922648172794670", "price":"0.989", "size":"1818525.69", "side":"BUY", "hash":"5a6642c2500ce7e367956679e9970038e769750f", "best_bid":"0.989", "best_ask":"0.99"}], "timestamp":"1780179112007", "event_type":"price_change"}
PONG
{"market":"0x7976b8dbacf9077eb1453a62bcefd6ab2df199acd28aad276ff0d920d6992892", "price_changes":[{"asset_id":"4394372887385518214471608448209527405727552777602031099972143344338178308080", "price":"0.184", "size":"0", "side":"SELL", "hash":"24553d76753c5c9ef747c9a29028d156cb5354b2", "best_bid":"0.167", "best_ask":"0.168"}, {"asset_id":"112680630004798425069810935278212000865453267506345451433803052322987302357330", "price":"0.816", "size":"0", "side":"BUY", "hash":"2dfb1c458721a9252522a47f557288de65ccbc37", "best_bid":"0.832", "best_ask":"0.833"}], "timestamp":"1780179113919", "event_type":"price_change"}
{"market":"0x7976b8dbacf9077eb1453a62bcefd6ab2df199acd28aad276ff0d920d6992892", "price_changes":[{"asset_id":"4394372887385518214471608448209527405727552777602031099972143344338178308080", "price":"0.184", "size":"49.77", "side":"SELL", "hash":"43b76c20467ac8c2737a5f6ef916511cc68292b6", "best_bid":"0.167", "best_ask":"0.168"}, {"asset_id":"112680630004798425069810935278212000865453267506345451433803052322987302357330", "price":"0.816", "size":"49.77", "side":"BUY", "hash":"c021f9bd18f6986788bd71ff61c12b600b467bc6", "best_bid":"0.832", "best_ask":"0.833"}], "timestamp":"1780179114102", "event_type":"price_change"}
{"market":"0x7876851632c295043c66536150a304cb785abdf712ba8489d298c6e6926be106", "price_changes":[{"asset_id":"97239126062673310243763617236644392945530356142765650402171508075574679292913", "price":"0.011", "size":"1818565.69", "side":"SELL", "hash":"05f19bd09ac46e83c8323584e0ab062c57473f25", "best_bid":"0.01", "best_ask":"0.011"}, {"asset_id":"19291692040378529618917910599727571242305935029274321291612270922648172794670", "price":"0.989", "size":"1818565.69", "side":"BUY", "hash":"8b229b8290d7cc9449fe7ae9827111a56afa0148", "best_bid":"0.989", "best_ask":"0.99"}], "timestamp":"1780179114152", "event_type":"price_change"}
{"market":"0x1595b4818eeb1ea1e0bec5de6f057218e557feee9b405a0e930d290384fa1d16", "price_changes":[{"asset_id":"81739002353269632749850710185641576213562066971072676369728657545679630163887", "price":"0.053", "size":"3291.26", "side":"SELL", "hash":"0d6bb9eec9db03a8c020f277ccc1ae7a1132386a", "best_bid":"0.051", "best_ask":"0.052"}, {"asset_id":"45484070731786948288366703334552551439356529561722304542938873238430842810537", "price":"0.947", "size":"3291.26", "side":"BUY", "hash":"ac6311de32830c9ad0ae33d7e6029042e9b3d9e1", "best_bid":"0.948", "best_ask":"0.949"}], "timestamp":"1780179116856", "event_type":"price_change"}
{"market":"0x30d55d8124ee1e12dabe89201badc45669b81dff69e4ce44d961f32878ec178a", "price_changes":[{"asset_id":"27576533317283401577758999384642760405921738493660383550832555714312627457443", "price":"0.092", "size":"78375.52", "side":"SELL", "hash":"bcb41f92d0d5f73985e65f668988c3f33321ffd0", "best_bid":"0.089", "best_ask":"0.09"}, {"asset_id":"52986718774908357330412653486471347449818893503063830313445318937088822580057", "price":"0.908", "size":"78375.52", "side":"BUY", "hash":"d0e1e97c33d00a2a26fc3a9ca80d6af39b4e315d", "best_bid":"0.91", "best_ask":"0.911"}], "timestamp":"1780179116865", "event_type":"price_change"}
{"market":"0x7976b8dbacf9077eb1453a62bcefd6ab2df199acd28aad276ff0d920d6992892", "price_changes":[{"asset_id":"4394372887385518214471608448209527405727552777602031099972143344338178308080", "price":"0.17", "size":"27636.92", "side":"SELL", "hash":"caf681d17cf146d25adc7e5ad90a9f84bf1c9c93", "best_bid":"0.167", "best_ask":"0.168"}, {"asset_id":"112680630004798425069810935278212000865453267506345451433803052322987302357330", "price":"0.83", "size":"27636.92", "side":"BUY", "hash":"bd2ba84e62411a288724915f08404d8c4775b2eb", "best_bid":"0.832", "best_ask":"0.833"}], "timestamp":"1780179116856", "event_type":"price_change"}
{"market":"0x0c4cd2055d6ea89354ffddc55d6dbcef9355748112ea952fc925f3db6a5c457f", "price_changes":[{"asset_id":"18812649149814341758733697580460697418474693998558159483117100240528657629879", "price":"0.088", "size":"15049.46", "side":"SELL", "hash":"e854eba4182bf83ad9d15899fe86ebbbde9de199", "best_bid":"0.085", "best_ask":"0.086"}, {"asset_id":"115428153746996892211798999366308897078723117634059783423375188043903703749062", "price":"0.912", "size":"15049.46", "side":"BUY", "hash":"d034b2a26084b8286d1c09e56e99902237bd9309", "best_bid":"0.914", "best_ask":"0.915"}], "timestamp":"1780179116867", "event_type":"price_change"}
{"market":"0x0c4cd2055d6ea89354ffddc55d6dbcef9355748112ea952fc925f3db6a5c457f", "price_changes":[{"asset_id":"18812649149814341758733697580460697418474693998558159483117100240528657629879", "price":"0.088", "size":"15129.46", "side":"SELL", "hash":"8beab4be9836ac2b18725645e106918c4b3edfeb", "best_bid":"0.085", "best_ask":"0.086"}, {"asset_id":"115428153746996892211798999366308897078723117634059783423375188043903703749062", "price":"0.912", "size":"15129.46", "side":"BUY", "hash":"0ee8eb7af0e46ca6787591830e61e6e2325ac38e", "best_bid":"0.914", "best_ask":"0.915"}], "timestamp":"1780179117019", "event_type":"price_change"}
{"market":"0x1595b4818eeb1ea1e0bec5de6f057218e557feee9b405a0e930d290384fa1d16", "price_changes":[{"asset_id":"81739002353269632749850710185641576213562066971072676369728657545679630163887", "price":"0.053", "size":"3371.26", "side":"SELL", "hash":"b9032b0983c75c7989d566de92c077bb7545ac5e", "best_bid":"0.051", "best_ask":"0.052"}, {"asset_id":"45484070731786948288366703334552551439356529561722304542938873238430842810537", "price":"0.947", "size":"3371.26", "side":"BUY", "hash":"40124052130c41db40cf3961844fb7f486b96fc1", "best_bid":"0.948", "best_ask":"0.949"}], "timestamp":"1780179117057", "event_type":"price_change"}
{"market":"0x7976b8dbacf9077eb1453a62bcefd6ab2df199acd28aad276ff0d920d6992892", "price_changes":[{"asset_id":"4394372887385518214471608448209527405727552777602031099972143344338178308080", "price":"0.17", "size":"27662.47", "side":"SELL", "hash":"4d9352762f373eec720cb5161a462e46386c565c", "best_bid":"0.167", "best_ask":"0.168"}, {"asset_id":"112680630004798425069810935278212000865453267506345451433803052322987302357330", "price":"0.83", "size":"27662.47", "side":"BUY", "hash":"482f65f2adf4f6425a76bfe51af8b5cbbdbc3bb4", "best_bid":"0.832", "best_ask":"0.833"}], "timestamp":"1780179117056", "event_type":"price_change"}
{"market":"0x30d55d8124ee1e12dabe89201badc45669b81dff69e4ce44d961f32878ec178a", "price_changes":[{"asset_id":"27576533317283401577758999384642760405921738493660383550832555714312627457443", "price":"0.092", "size":"78431.18", "side":"SELL", "hash":"68b67ac072fd9663cce4d06df79c90afb331f920", "best_bid":"0.089", "best_ask":"0.09"}, {"asset_id":"52986718774908357330412653486471347449818893503063830313445318937088822580057", "price":"0.908", "size":"78431.18", "side":"BUY", "hash":"be4ff6aa0da840a9f42b7f4c06d32a8ec188e1fd", "best_bid":"0.91", "best_ask":"0.911"}], "timestamp":"1780179117078", "event_type":"price_change"}
{"market":"0x375409bc5eeeff961e82b479caeccc20f33d15738e5bce1186d628aa3d9dfb1f", "price_changes":[{"asset_id":"115556263888245616435851357148058235707004733438163639091106356867234218207169", "price":"0.115", "size":"11999.15", "side":"SELL", "hash":"56cb261de6cfa51633501b94226a71e8e47c0961", "best_bid":"0.112", "best_ask":"0.113"}, {"asset_id":"77121637225348873006259930776623502125079210522997384841464684944292365296940", "price":"0.885", "size":"11999.15", "side":"BUY", "hash":"d4553c35e171d2d8e88ca5cf5caa1b55af347997", "best_bid":"0.887", "best_ask":"0.888"}], "timestamp":"1780179118382", "event_type":"price_change"}
{"market":"0x9b6fef249040fd17e9c107955b37ac2c3e923509b6b0ff01cc463a331ddeb894", "price_changes":[{"asset_id":"108233603819467706476318984012158651931658302669301887462181073562758483842092", "price":"0.166", "size":"24926.72", "side":"SELL", "hash":"cca26af4473df09cd3a4eda752de6c1a18de6e53", "best_bid":"0.163", "best_ask":"0.164"}, {"asset_id":"32270411694523539495262303868629477861017829722282576458031815333486368239544", "price":"0.834", "size":"24926.72", "side":"BUY", "hash":"d6f23f9dc092becc99dda5114ea70001758fa092", "best_bid":"0.836", "best_ask":"0.837"}], "timestamp":"1780179118473", "event_type":"price_change"}
{"market":"0x375409bc5eeeff961e82b479caeccc20f33d15738e5bce1186d628aa3d9dfb1f", "price_changes":[{"asset_id":"115556263888245616435851357148058235707004733438163639091106356867234218207169", "price":"0.115", "size":"12079.15", "side":"SELL", "hash":"f67af731aa04d4eda68a0da7502dd6c7945dbffb", "best_bid":"0.112", "best_ask":"0.113"}, {"asset_id":"77121637225348873006259930776623502125079210522997384841464684944292365296940", "price":"0.885", "size":"12079.15", "side":"BUY", "hash":"fd70709ac4e064f6b14f16e452eeff7db9d0d073", "best_bid":"0.887", "best_ask":"0.888"}], "timestamp":"1780179118482", "event_type":"price_change"}
{"market":"0x9b6fef249040fd17e9c107955b37ac2c3e923509b6b0ff01cc463a331ddeb894", "price_changes":[{"asset_id":"108233603819467706476318984012158651931658302669301887462181073562758483842092", "price":"0.166", "size":"25006.72", "side":"SELL", "hash":"19282a63df4da12460506eea08e53026fe3d4aa6", "best_bid":"0.163", "best_ask":"0.164"}, {"asset_id":"32270411694523539495262303868629477861017829722282576458031815333486368239544", "price":"0.834", "size":"25006.72", "side":"BUY", "hash":"eab5bda62c1c789784c34ab033049bb4287dbadb", "best_bid":"0.836", "best_ask":"0.837"}], "timestamp":"1780179118580", "event_type":"price_change"}
{"market":"0x4f3421fb2daf5cca7430ed8d8132463963081572d75434393a1808fdb8829fe8", "price_changes":[{"asset_id":"45415751658241142530386585138386640503488308219341470020075667342738719018629", "price":"0.103", "size":"18202.51", "side":"SELL", "hash":"840927cc98a73af0aa9ca60f9421baf349d471e1", "best_bid":"0.1", "best_ask":"0.101"}, {"asset_id":"31940783580344558651011323787577288681658737625185216525249046282994042503801", "price":"0.897", "size":"18202.51", "side":"BUY", "hash":"623599348648212897bb96d44110a3faed5bfde9", "best_bid":"0.899", "best_ask":"0.9"}], "timestamp":"1780179118858", "event_type":"price_change"}
{"market":"0x4f3421fb2daf5cca7430ed8d8132463963081572d75434393a1808fdb8829fe8", "price_changes":[{"asset_id":"45415751658241142530386585138386640503488308219341470020075667342738719018629", "price":"0.103", "size":"18263.31", "side":"SELL", "hash":"c65ed6437057a423af099869bffaf2f6cbbca7fb", "best_bid":"0.1", "best_ask":"0.101"}, {"asset_id":"31940783580344558651011323787577288681658737625185216525249046282994042503801", "price":"0.897", "size":"18263.31", "side":"BUY", "hash":"410cce37891eacca6966e827e7bc2abe6a2a52e3", "best_bid":"0.899", "best_ask":"0.9"}], "timestamp":"1780179118992", "event_type":"price_change"}
PONG
{"id":"2397790", "question":"UFC Fight Night: Jhonata Diniz vs. José Luiz (Heavyweight, Prelims)", "market":"0xbe0e5441f468c636ab43bbaaa338f3e8d9410d7417ddaf937e101fd95a4383dd", "slug":"ufc-jho1-jluiz-2026-06-20", "description":"This market will resolve to \"Jhonata Diniz\" if Jhonata Diniz is officially declared the winner of the fight against José Luiz at UFC Fight Night: Kape vs. Horiguchi, scheduled for June 20, 2026.\n\nIt will resolve to \"José Luiz\" if José Luiz is officially declared the winner.\n\nIf the fight is declared a draw or technical draw, ruled a No Contest, not scored, canceled, or postponed beyond July 4, 2026, this market will resolve \"50-50.\"\n\nThe resolution source for this market will be official information from the UFC.", "assets_ids":["78018087786054870613637126069129285717824798719876842841372004017165683188646", "71052367865355640983630731352276173565094188035055568500762604430116013951539"], "outcomes":["Jhonata Diniz", "José Luiz"], "event_message":{"id":"542664", "ticker":"ufc-jho1-jluiz-2026-06-20", "slug":"ufc-jho1-jluiz-2026-06-20", "title":"UFC Fight Night: Jhonata Diniz vs. José Luiz (Heavyweight, Prelims)", "description":"This market will resolve to \"Jhonata Diniz\" if Jhonata Diniz is officially declared the winner of the fight against José Luiz at UFC Fight Night: Kape vs. Horiguchi, scheduled for June 20, 2026.\n\nIt will resolve to \"José Luiz\" if José Luiz is officially declared the winner.\n\nIf the fight is declared a draw or technical draw, ruled a No Contest, not scored, canceled, or postponed beyond July 4, 2026, this market will resolve \"50-50.\"\n\nThe resolution source for this market will be official information from the UFC."}, "timestamp":"1780179123873", "event_type":"new_market", "tags":[], "condition_id":"0xbe0e5441f468c636ab43bbaaa338f3e8d9410d7417ddaf937e101fd95a4383dd", "active":false, "clob_token_ids":["78018087786054870613637126069129285717824798719876842841372004017165683188646", "71052367865355640983630731352276173565094188035055568500762604430116013951539"], "sports_market_type":"moneyline", "line":"", "game_start_time":"2026-06-20 17:00:00+00", "order_price_min_tick_size":"0.01", "group_item_title":"Jhonata Diniz vs. José Luiz", "taker_base_fee":"1000", "fees_enabled":true, "fee_schedule":{"exponent":"1", "rate":"0.03", "taker_only":true, "rebate_rate":"0.25"}}
