{"market":"0x9b6fef249040fd17e9c107955b37ac2c3e923509b6b0ff01cc463a331ddeb894", "asset_id":"32270411694523539495262303868629477861017829722282576458031815333486368239544", "bids":[{"price":"0.001", "size":"12219098.99"}, {"price":"0.002", "size":"178.57"}, {"price":"0.003", "size":"21.08"}, {"price":"0.009", "size":"18000"}, {"price":"0.01", "size":"100"}, {"price":"0.011", "size":"5.62"}, {"price":"0.012", "size":"1111111"}, {"price":"0.013", "size":"900000"}, {"price":"0.014", "size":"1300"}, {"price":"0.015", "size":"500"}, {"price":"0.02", "size":"99"}, {"price":"0.021", "size":"6.95"}, {"price":"0.05", "size":"246.52"}, {"price":"0.051", "size":"10.84"}, {"price":"0.09", "size":"5.98"}, {"price":"0.1", "size":"15"}, {"price":"0.12", "size":"5005"}, {"price":"0.121", "size":"12000"}, {"price":"0.15", "size":"67.49"}, {"price":"0.163", "size":"36"}, {"price":"0.178", "size":"289.7"}, {"price":"0.2", "size":"796.33"}, {"price":"0.209", "size":"143.54"}, {"price":"0.22", "size":"100.48"}, {"price":"0.221", "size":"5.22"}, {"price":"0.245", "size":"304.87"}, {"price":"0.25", "size":"3597"}, {"price":"0.251", "size":"6000"}, {"price":"0.29", "size":"9.75"}, {"price":"0.3", "size":"55.88"}, {"price":"0.315", "size":"1459.85"}, {"price":"0.33", "size":"1363.34"}, {"price":"0.331", "size":"3000"}, {"price":"0.34", "size":"5"}, {"price":"0.35", "size":"2159.92"}, {"price":"0.4", "size":"34587.44"}, {"price":"0.401", "size":"3000"}, {"price":"0.47", "size":"5688.73"}, {"price":"0.5", "size":"36470.75"}, {"price":"0.502", "size":"1529.99"}, {"price":"0.503", "size":"14000"}, {"price":"0.51", "size":"90.9"}, {"price":"0.511", "size":"1202.04"}, {"price":"0.55", "size":"513.44"}, {"price":"0.56", "size":"111.11"}, {"price":"0.562", "size":"655.13"}, {"price":"0.563", "size":"65.06"}, {"price":"0.57", "size":"3964.15"}, {"price":"0.6", "size":"22272.15"}, {"price":"0.624", "size":"27.04"}, {"price":"0.636", "size":"105.03"}, {"price":"0.637", "size":"1000"}, {"price":"0.638", "size":"23.57"}, {"price":"0.64", "size":"4479.3"}, {"price":"0.648", "size":"7.39"}, {"price":"0.65", "size":"15415.61"}, {"price":"0.651", "size":"2155.26"}, {"price":"0.667", "size":"1000"}, {"price":"0.67", "size":"18.11"}, {"price":"0.672", "size":"482.66"}, {"price":"0.68", "size":"38"}, {"price":"0.697", "size":"1000"}, {"price":"0.7", "size":"487.37"}, {"price":"0.701", "size":"400"}, {"price":"0.72", "size":"167.14"}, {"price":"0.722", "size":"100"}, {"price":"0.727", "size":"1000"}, {"price":"0.743", "size":"100"}, {"price":"0.744", "size":"30"}, {"price":"0.747", "size":"1000"}, {"price":"0.75", "size":"1422.54"}, {"price":"0.751", "size":"201"}, {"price":"0.752", "size":"1367"}, {"price":"0.754", "size":"334.02"}, {"price":"0.757", "size":"1000"}, {"price":"0.76", "size":"302"}, {"price":"0.764", "size":"100"}, {"price":"0.767", "size":"1100"}, {"price":"0.777", "size":"1011.23"}, {"price":"0.779", "size":"334.02"}, {"price":"0.78", "size":"237"}, {"price":"0.785", "size":"100"}, {"price":"0.786", "size":"15"}, {"price":"0.787", "size":"1100"}, {"price":"0.788", "size":"10"}, {"price":"0.789", "size":"5555.55"}, {"price":"0.79", "size":"122"}, {"price":"0.793", "size":"10"}, {"price":"0.794", "size":"1000"}, {"price":"0.795", "size":"10"}, {"price":"0.797", "size":"1050"}, {"price":"0.8", "size":"17681.66"}, {"price":"0.801", "size":"100"}, {"price":"0.803", "size":"110"}, {"price":"0.806", "size":"44"}, {"price":"0.807", "size":"1180"}, {"price":"0.808", "size":"675.7"}, {"price":"0.809", "size":"2027"}, {"price":"0.81", "size":"6609.61"}, {"price":"0.811", "size":"4653.91"}, {"price":"0.812", "size":"1708.3"}, {"price":"0.813", "size":"782.67"}, {"price":"0.814", "size":"1703.37"}, {"price":"0.815", "size":"5571.35"}, {"price":"0.816", "size":"11142.53"}, {"price":"0.817", "size":"7549.45"}, {"price":"0.818", "size":"6032.61"}, {"price":"0.819", "size":"340"}, {"price":"0.82", "size":"1037.95"}, {"price":"0.821", "size":"1694.21"}, {"price":"0.822", "size":"22719.93"}, {"price":"0.823", "size":"44358.4"}, {"price":"0.824", "size":"47073"}, {"price":"0.825", "size":"47040.85"}, {"price":"0.827", "size":"654.36"}, {"price":"0.829", "size":"19937.62"}, {"price":"0.83", "size":"26050"}, {"price":"0.831", "size":"3000"}, {"price":"0.832", "size":"2000"}, {"price":"0.833", "size":"4950.42"}, {"price":"0.834", "size":"25006.68"}, {"price":"0.835", "size":"182736.01"}, {"price":"0.836", "size":"38075.62"}], "asks":[{"price":"0.999", "size":"2260279"}, {"price":"0.998", "size":"1557248"}, {"price":"0.997", "size":"1001200"}, {"price":"0.996", "size":"55555"}, {"price":"0.995", "size":"90100"}, {"price":"0.99", "size":"720"}, {"price":"0.985", "size":"5.01"}, {"price":"0.984", "size":"555555"}, {"price":"0.983", "size":"60000"}, {"price":"0.982", "size":"105435.9"}, {"price":"0.981", "size":"800"}, {"price":"0.98", "size":"5430"}, {"price":"0.978", "size":"3000"}, {"price":"0.976", "size":"3000"}, {"price":"0.974", "size":"3000"}, {"price":"0.972", "size":"3000"}, {"price":"0.97", "size":"3000"}, {"price":"0.968", "size":"3000"}, {"price":"0.966", "size":"3000"}, {"price":"0.96", "size":"750"}, {"price":"0.951", "size":"100"}, {"price":"0.95", "size":"150"}, {"price":"0.94", "size":"10"}, {"price":"0.937", "size":"16.27"}, {"price":"0.936", "size":"30"}, {"price":"0.935", "size":"10"}, {"price":"0.934", "size":"20"}, {"price":"0.931", "size":"10"}, {"price":"0.93", "size":"50"}, {"price":"0.926", "size":"20"}, {"price":"0.925", "size":"5"}, {"price":"0.924", "size":"30"}, {"price":"0.923", "size":"20"}, {"price":"0.922", "size":"20"}, {"price":"0.921", "size":"20"}, {"price":"0.92", "size":"140"}, {"price":"0.91", "size":"10100"}, {"price":"0.905", "size":"105.2"}, {"price":"0.9", "size":"6296.92"}, {"price":"0.899", "size":"1076.68"}, {"price":"0.893", "size":"37.72"}, {"price":"0.892", "size":"40"}, {"price":"0.89", "size":"400"}, {"price":"0.889", "size":"5000"}, {"price":"0.885", "size":"9"}, {"price":"0.884", "size":"90"}, {"price":"0.88", "size":"120"}, {"price":"0.879", "size":"7500"}, {"price":"0.878", "size":"5000"}, {"price":"0.877", "size":"100"}, {"price":"0.875", "size":"956.59"}, {"price":"0.874", "size":"2500"}, {"price":"0.87", "size":"328"}, {"price":"0.869", "size":"2567"}, {"price":"0.868", "size":"47"}, {"price":"0.867", "size":"1933.93"}, {"price":"0.866", "size":"57"}, {"price":"0.865", "size":"37"}, {"price":"0.864", "size":"5017"}, {"price":"0.863", "size":"3727"}, {"price":"0.862", "size":"7"}, {"price":"0.861", "size":"7"}, {"price":"0.86", "size":"717"}, {"price":"0.859", "size":"7"}, {"price":"0.858", "size":"507"}, {"price":"0.857", "size":"97"}, {"price":"0.856", "size":"7"}, {"price":"0.855", "size":"37"}, {"price":"0.854", "size":"37"}, {"price":"0.853", "size":"722"}, {"price":"0.852", "size":"7"}, {"price":"0.851", "size":"707"}, {"price":"0.85", "size":"6520"}, {"price":"0.849", "size":"877"}, {"price":"0.848", "size":"7"}, {"price":"0.847", "size":"27"}, {"price":"0.846", "size":"287"}, {"price":"0.845", "size":"3760.64"}, {"price":"0.844", "size":"20417"}, {"price":"0.843", "size":"28647.14"}, {"price":"0.842", "size":"10076.94"}, {"price":"0.841", "size":"56.6"}, {"price":"0.84", "size":"67783.1"}, {"price":"0.839", "size":"12119.44"}, {"price":"0.838", "size":"4311.83"}, {"price":"0.837", "size":"15230.42"}], "hash":"11a201452fcb0dfb4c5258188e2c6f06bed6f580", "timestamp":"1780178843184", "event_type":"book"}
{"id":"2397770", "question":"O/U 2.5 Rounds", "market":"0xb3b42ceaafcee0c0c18c5d000a1e6d294ab0f87c96729e3c30f60847289f5172", "slug":"ufc-gas-mic34-2026-06-20-totals-2pt5", "description":"Each market will resolve to \"Over\" if the fight between Gaston Bolaños and Michael Aswell at UFC Fight Night: Kape vs. Horiguchi, scheduled for June 20, 2026, lasts beyond the listed round threshold.\n\nEach market will resolve to \"Under\" if the fight does not last beyond the listed round threshold.\n\nFor example:\n\n\"Over 2.5 Rounds\" will resolve \"Yes\" if the fight continues past the 2:30 mark of Round 3.\n\n\"Under 2.5 Rounds\" will resolve \"Yes\" if the fight ends before the 2:30 mark of Round 3.\n\nIf the fight ends exactly at the threshold, it will resolve \"50-50.\"\n\nIf the bout is not scored, postponed beyond July 4, 2026, or canceled, all options will resolve \"50-50.\"\n\nThe resolution source for this market will be official information from the UFC.", "assets_ids":["88525614583222220665608299724875984646367346395112438132083534618161201879766", "89070209356927979114683636209602052206540307694330064598691650235368361005298"], "outcomes":["Over", "Under"], "event_message":{"id":"542654", "ticker":"ufc-gas-mic34-2026-06-20", "slug":"ufc-gas-mic34-2026-06-20", "title":"UFC Fight Night: Gaston Bolaños vs. Michael Aswell (Featherweight, Prelims)", "description":"This market will resolve to \"Gaston Bolaños\" if Gaston Bolaños is officially declared the winner of the fight against Michael Aswell at UFC Fight Night: Kape vs. Horiguchi, scheduled for June 20, 2026.\n\nIt will resolve to \"Michael Aswell\" if Michael Aswell is officially declared the winner.\n\nIf the fight is declared a draw or technical draw, ruled a No Contest, not scored, canceled, or postponed beyond July 4, 2026, this market will resolve \"50-50.\"\n\nThe resolution source for this market will be official information from the UFC."}, "timestamp":"1780178843427", "event_type":"new_market", "tags":[], "condition_id":"0xb3b42ceaafcee0c0c18c5d000a1e6d294ab0f87c96729e3c30f60847289f5172", "active":false, "clob_token_ids":["88525614583222220665608299724875984646367346395112438132083534618161201879766", "89070209356927979114683636209602052206540307694330064598691650235368361005298"], "sports_market_type":"totals", "line":"2.5", "game_start_time":"2026-06-20 17:00:00+00", "order_price_min_tick_size":"0.01", "group_item_title":"O/U 2.5 Rounds", "taker_base_fee":"1000", "fees_enabled":true, "fee_schedule":{"exponent":"1", "rate":"0.03", "taker_only":true, "rebate_rate":"0.25"}}
{"market":"0x1595b4818eeb1ea1e0bec5de6f057218e557feee9b405a0e930d290384fa1d16", "price_changes":[{"asset_id":"81739002353269632749850710185641576213562066971072676369728657545679630163887", "price":"0.053", "size":"3291.26", "side":"SELL", "hash":"5713c772b689b4e6dc59dc146c6dae6633e4f622", "best_bid":"0.051", "best_ask":"0.052"}, {"asset_id":"45484070731786948288366703334552551439356529561722304542938873238430842810537", "price":"0.947", "size":"3291.26", "side":"BUY", "hash":"1dd3d4dbdb2e8e17c309eab2ddca7b84e5322cd0", "best_bid":"0.948", "best_ask":"0.949"}], "timestamp":"1780178844000", "event_type":"price_change"}
{"market":"0x0c4cd2055d6ea89354ffddc55d6dbcef9355748112ea952fc925f3db6a5c457f", "price_changes":[{"asset_id":"18812649149814341758733697580460697418474693998558159483117100240528657629879", "price":"0.088", "size":"16049.46", "side":"SELL", "hash":"d3e0ddff542a49f173e5adf75bb0db547f72a61d", "best_bid":"0.085", "best_ask":"0.086"}, {"asset_id":"115428153746996892211798999366308897078723117634059783423375188043903703749062", "price":"0.912", "size":"16049.46", "side":"BUY", "hash":"54af28ae41bcb6bbcda62d57960abe65deb52c86", "best_bid":"0.914", "best_ask":"0.915"}], "timestamp":"1780178844001", "event_type":"price_change"}
{"market":"0x30d55d8124ee1e12dabe89201badc45669b81dff69e4ce44d961f32878ec178a", "price_changes":[{"asset_id":"27576533317283401577758999384642760405921738493660383550832555714312627457443", "price":"0.092", "size":"78375.52", "side":"SELL", "hash":"5a18c7768126136d0f930d33a7e6d2ec05633b1f", "best_bid":"0.089", "best_ask":"0.09"}, {"asset_id":"52986718774908357330412653486471347449818893503063830313445318937088822580057", "price":"0.908", "size":"78375.52", "side":"BUY", "hash":"93296a36910cd4699daa84ff626ad85fa96d76a6", "best_bid":"0.91", "best_ask":"0.911"}], "timestamp":"1780178844001", "event_type":"price_change"}
{"market":"0x7976b8dbacf9077eb1453a62bcefd6ab2df199acd28aad276ff0d920d6992892", "price_changes":[{"asset_id":"4394372887385518214471608448209527405727552777602031099972143344338178308080", "price":"0.17", "size":"27626.88", "side":"SELL", "hash":"c1eff75f5ce9aca653c93105038e00844723f86a", "best_bid":"0.167", "best_ask":"0.168"}, {"asset_id":"112680630004798425069810935278212000865453267506345451433803052322987302357330", "price":"0.83", "size":"27626.88", "side":"BUY", "hash":"73b0421c49186146dcbcd0e71b0646601456563e", "best_bid":"0.832", "best_ask":"0.833"}], "timestamp":"1780178844002", "event_type":"price_change"}
{"market":"0x0c4cd2055d6ea89354ffddc55d6dbcef9355748112ea952fc925f3db6a5c457f", "price_changes":[{"asset_id":"18812649149814341758733697580460697418474693998558159483117100240528657629879", "price":"0.088", "size":"16129.46", "side":"SELL", "hash":"24a2572f2beb0966f6dd6126fcdac1da086217a3", "best_bid":"0.085", "best_ask":"0.086"}, {"asset_id":"115428153746996892211798999366308897078723117634059783423375188043903703749062", "price":"0.912", "size":"16129.46", "side":"BUY", "hash":"52f05392f90e6188a1ce54991f59a44303bf74d3", "best_bid":"0.914", "best_ask":"0.915"}], "timestamp":"1780178844088", "event_type":"price_change"}
{"market":"0x1595b4818eeb1ea1e0bec5de6f057218e557feee9b405a0e930d290384fa1d16", "price_changes":[{"asset_id":"81739002353269632749850710185641576213562066971072676369728657545679630163887", "price":"0.053", "size":"3371.26", "side":"SELL", "hash":"24c6efcccdcc30ee1d37dd6b1bcbd3d5fcdc5bcd", "best_bid":"0.051", "best_ask":"0.052"}, {"asset_id":"45484070731786948288366703334552551439356529561722304542938873238430842810537", "price":"0.947", "size":"3371.26", "side":"BUY", "hash":"15161a2c5613e02132f25182e803381ff9c89548", "best_bid":"0.948", "best_ask":"0.949"}], "timestamp":"1780178844091", "event_type":"price_change"}
{"market":"0x7976b8dbacf9077eb1453a62bcefd6ab2df199acd28aad276ff0d920d6992892", "price_changes":[{"asset_id":"4394372887385518214471608448209527405727552777602031099972143344338178308080", "price":"0.17", "size":"27652.43", "side":"SELL", "hash":"05928169dbe0ee3b3134c27de7222785fea560eb", "best_bid":"0.167", "best_ask":"0.168"}, {"asset_id":"112680630004798425069810935278212000865453267506345451433803052322987302357330", "price":"0.83", "size":"27652.43", "side":"BUY", "hash":"dc444b592cc129068cac497e7a6ac64d048518d2", "best_bid":"0.832", "best_ask":"0.833"}], "timestamp":"1780178844095", "event_type":"price_change"}
{"market":"0x30d55d8124ee1e12dabe89201badc45669b81dff69e4ce44d961f32878ec178a", "price_changes":[{"asset_id":"27576533317283401577758999384642760405921738493660383550832555714312627457443", "price":"0.092", "size":"78431.18", "side":"SELL", "hash":"fc0218bf7aa01656abdb92af3bbfdaf2baf84e75", "best_bid":"0.089", "best_ask":"0.09"}, {"asset_id":"52986718774908357330412653486471347449818893503063830313445318937088822580057", "price":"0.908", "size":"78431.18", "side":"BUY", "hash":"33c24bc2f308efcc33408cd0f07e71b5f47182e8", "best_bid":"0.91", "best_ask":"0.911"}], "timestamp":"1780178844098", "event_type":"price_change"}
{"id":"2397799", "question":"O/U 0.5 Rounds", "market":"0x6edc1556bfce261d5e42c95b4e4297087de9dc1f92b00eee1ae6340fa04ba39c", "slug":"ufc-jho1-jluiz-2026-06-20-totals-0pt5", "description":"Each market will resolve to \"Over\" if the fight between Jhonata Diniz and José Luiz at UFC Fight Night: Kape vs. Horiguchi, scheduled for June 20, 2026, lasts beyond the listed round threshold.\n\nEach market will resolve to \"Under\" if the fight does not last beyond the listed round threshold.\n\nFor example:\n\n\"Over 0.5 Rounds\" will resolve \"Yes\" if the fight continues past the 2:30 mark of Round 1.\n\n\"Under 0.5 Rounds\" will resolve \"Yes\" if the fight ends before the 2:30 mark of Round 1.\n\nIf the fight ends exactly at the threshold, it will resolve \"50-50.\"\n\nIf the bout is not scored, postponed beyond July 4, 2026, or canceled, all options will resolve \"50-50.\"\n\nThe resolution source for this market will be official information from the UFC.", "assets_ids":["61210781125768494596020564136919972356626075575140350756704789130193962130137", "20910827944848244545571386863772930156183124377703083224179098151035316072549"], "outcomes":["Over", "Under"], "event_message":{"id":"542664", "ticker":"ufc-jho1-jluiz-2026-06-20", "slug":"ufc-jho1-jluiz-2026-06-20", "title":"UFC Fight Night: Jhonata Diniz vs. José Luiz (Heavyweight, Prelims)", "description":"This market will resolve to \"Jhonata Diniz\" if Jhonata Diniz is officially declared the winner of the fight against José Luiz at UFC Fight Night: Kape vs. Horiguchi, scheduled for June 20, 2026.\n\nIt will resolve to \"José Luiz\" if José Luiz is officially declared the winner.\n\nIf the fight is declared a draw or technical draw, ruled a No Contest, not scored, canceled, or postponed beyond July 4, 2026, this market will resolve \"50-50.\"\n\nThe resolution source for this market will be official information from the UFC."}, "timestamp":"1780178845210", "event_type":"new_market", "tags":[], "condition_id":"0x6edc1556bfce261d5e42c95b4e4297087de9dc1f92b00eee1ae6340fa04ba39c", "active":false, "clob_token_ids":["61210781125768494596020564136919972356626075575140350756704789130193962130137", "20910827944848244545571386863772930156183124377703083224179098151035316072549"], "sports_market_type":"totals", "line":"0.5", "game_start_time":"2026-06-20 17:00:00+00", "order_price_min_tick_size":"0.01", "group_item_title":"O/U 0.5 Rounds", "taker_base_fee":"1000", "fees_enabled":true, "fee_schedule":{"exponent":"1", "rate":"0.03", "taker_only":true, "rebate_rate":"0.25"}}
{"market":"0x375409bc5eeeff961e82b479caeccc20f33d15738e5bce1186d628aa3d9dfb1f", "price_changes":[{"asset_id":"115556263888245616435851357148058235707004733438163639091106356867234218207169", "price":"0.115", "size":"11999.15", "side":"SELL", "hash":"e89f6a4aa259d26e2f521d2af72389f94362953a", "best_bid":"0.112", "best_ask":"0.113"}, {"asset_id":"77121637225348873006259930776623502125079210522997384841464684944292365296940", "price":"0.885", "size":"11999.15", "side":"BUY", "hash":"1c3d487ce4403aa5923077a00fb5136c11f76205", "best_bid":"0.887", "best_ask":"0.888"}], "timestamp":"1780178845951", "event_type":"price_change"}
{"market":"0x9b6fef249040fd17e9c107955b37ac2c3e923509b6b0ff01cc463a331ddeb894", "price_changes":[{"asset_id":"108233603819467706476318984012158651931658302669301887462181073562758483842092", "price":"0.166", "size":"24926.68", "side":"SELL", "hash":"4b7fa9c2e9d85db98ce8085e3375a8551b196563", "best_bid":"0.163", "best_ask":"0.164"}, {"asset_id":"32270411694523539495262303868629477861017829722282576458031815333486368239544", "price":"0.834", "size":"24926.68", "side":"BUY", "hash":"9465b2820927c270598dbeee05a9c1c01d6bdc8e", "best_bid":"0.836", "best_ask":"0.837"}], "timestamp":"1780178846294", "event_type":"price_change"}
{"market":"0x375409bc5eeeff961e82b479caeccc20f33d15738e5bce1186d628aa3d9dfb1f", "price_changes":[{"asset_id":"115556263888245616435851357148058235707004733438163639091106356867234218207169", "price":"0.115", "size":"12079.15", "side":"SELL", "hash":"d68561a1ce6c838a769bbb381f1eced0db47e65d", "best_bid":"0.112", "best_ask":"0.113"}, {"asset_id":"77121637225348873006259930776623502125079210522997384841464684944292365296940", "price":"0.885", "size":"12079.15", "side":"BUY", "hash":"ae54eba98d75ff6e0f6d86ab6c8581c1b88b659b", "best_bid":"0.887", "best_ask":"0.888"}], "timestamp":"1780178846576", "event_type":"price_change"}
{"market":"0x4f3421fb2daf5cca7430ed8d8132463963081572d75434393a1808fdb8829fe8", "price_changes":[{"asset_id":"45415751658241142530386585138386640503488308219341470020075667342738719018629", "price":"0.103", "size":"18202.51", "side":"SELL", "hash":"5a0708b8add39d3d42549eec203f683fc5be3979", "best_bid":"0.1", "best_ask":"0.101"}, {"asset_id":"31940783580344558651011323787577288681658737625185216525249046282994042503801", "price":"0.897", "size":"18202.51", "side":"BUY", "hash":"6a8446f9b6d2ed0c3d9647f428e261363781284f", "best_bid":"0.899", "best_ask":"0.9"}], "timestamp":"1780178846593", "event_type":"price_change"}
{"market":"0x9b6fef249040fd17e9c107955b37ac2c3e923509b6b0ff01cc463a331ddeb894", "price_changes":[{"asset_id":"108233603819467706476318984012158651931658302669301887462181073562758483842092", "price":"0.166", "size":"25006.68", "side":"SELL", "hash":"e14b863598daaffd6aa4c421aa2c4ed13c4d4c5f", "best_bid":"0.163", "best_ask":"0.164"}, {"asset_id":"32270411694523539495262303868629477861017829722282576458031815333486368239544", "price":"0.834", "size":"25006.68", "side":"BUY", "hash":"30bd7b1fe1f44e766ffc6706d0bfb30496588a74", "best_bid":"0.836", "best_ask":"0.837"}], "timestamp":"1780178846609", "event_type":"price_change"}
{"market":"0x4f3421fb2daf5cca7430ed8d8132463963081572d75434393a1808fdb8829fe8", "price_changes":[{"asset_id":"45415751658241142530386585138386640503488308219341470020075667342738719018629", "price":"0.103", "size":"18263.31", "side":"SELL", "hash":"47570bb7191f107ae0196de560ee80f84bebe648", "best_bid":"0.1", "best_ask":"0.101"}, {"asset_id":"31940783580344558651011323787577288681658737625185216525249046282994042503801", "price":"0.897", "size":"18263.31", "side":"BUY", "hash":"a63f232682ecba1aef5b8d52f08a0e47962a67af", "best_bid":"0.899", "best_ask":"0.9"}], "timestamp":"1780178847028", "event_type":"price_change"}
{"id":"2397728", "question":"Prostejov: Tristan Boyer vs Filip Jianu", "market":"0x1724f3aae5308f7d3702763cf7b7a79086dfc319567f70d20bd4c748c49cc23c", "slug":"atp-boyer-jianu-2026-06-01", "description":"This market refers to the tennis match between Tristan Boyer and Filip Jianu in the Prostejov, originally scheduled for June 1, 2026 at 4:00AM ET.\n\nThis market will resolve to 'Tristan Boyer' if Tristan Boyer advances against Filip Jianu.\n\nThis market will resolve to 'Filip Jianu' if Filip Jianu advances against Tristan Boyer.\n\nIf the match is canceled (not played at all), ends in a tie, or is delayed beyond 7 days from the scheduled date without a winner determined, this market will resolve to 50-50.\n\nIf the match begins but is not completed, and one player advances due to the opponent's retirement, default, or disqualification, this market will resolve to the player who advances.\n\nIf the match ends in a walkover (player withdraws before the start and the other advances automatically), this market will resolve to 50-50.\n\nThe primary resolution source will be official information from the ATP Tour. A consensus of credible reporting may also be used.", "assets_ids":["4752267248959219036318105909652084152212172067331863843165057611668402625577", "110906916572386347565488562707074599649342686075787981401411002169502882707963"], "outcomes":["Tristan Boyer", "Filip Jianu"], "event_message":{"id":"542645", "ticker":"atp-boyer-jianu-2026-06-01", "slug":"atp-boyer-jianu-2026-06-01", "title":"Prostejov: Tristan Boyer vs Filip Jianu", "description":"This market refers to the tennis match between Tristan Boyer and Filip Jianu in the Prostejov, originally scheduled for June 1, 2026 at 4:00AM ET.\n\nThis market will resolve to 'Tristan Boyer' if Tristan Boyer advances against Filip Jianu.\n\nThis market will resolve to 'Filip Jianu' if Filip Jianu advances against Tristan Boyer.\n\nIf the match is canceled (not played at all), ends in a tie, or is delayed beyond 7 days from the scheduled date without a winner determined, this market will resolve to 50-50.\n\nIf the match begins but is not completed, and one player advances due to the opponent's retirement, default, or disqualification, this market will resolve to the player who advances.\n\nIf the match ends in a walkover (player withdraws before the start and the other advances automatically), this market will resolve to 50-50.\n\nThe primary resolution source will be official information from the ATP Tour. A consensus of credible reporting may also be used."}, "timestamp":"1780178847301", "event_type":"new_market", "tags":[], "condition_id":"0x1724f3aae5308f7d3702763cf7b7a79086dfc319567f70d20bd4c748c49cc23c", "active":false, "clob_token_ids":["4752267248959219036318105909652084152212172067331863843165057611668402625577", "110906916572386347565488562707074599649342686075787981401411002169502882707963"], "sports_market_type":"moneyline", "line":"", "game_start_time":"2026-06-01 08:00:00+00", "order_price_min_tick_size":"0.01", "group_item_title":"", "taker_base_fee":"1000", "fees_enabled":true, "fee_schedule":{"exponent":"1", "rate":"0.03", "taker_only":true, "rebate_rate":"0.25"}}
{"id":"2397734", "question":"Will the fight be won by submission?", "market":"0x84d53af66d70177914117868054b508680db6aed9ad865e1c90ac447f2adb60b", "slug":"ufc-mel7-bia1-2026-06-20-win-by-submission", "description":"This market will resolve to \"Yes\" if the fight between Melissa Mullins and Bia Mesquita at UFC Fight Night: Kape vs. Horiguchi, scheduled for June 20, 2026, ends by submission, including tapout, verbal submission, or technical submission (referee stoppage due to a submission hold). Otherwise, it will resolve to \"No.\"\n\nIf the fight ends in a draw or by disqualification (either fighter), it will resolve \"No.\"\n\nIf the bout is ruled a No Contest, not scored, canceled, or postponed beyond July 4, 2026, this market will resolve \"50-50.\"\n\nThe resolution source for this market will be official information from the UFC.", "assets_ids":["104832562566005544059248849505317424244201797614587062002253759164076485746781", "56275346251017414816034462335277651323944126210249109798955891181444818192368"], "outcomes":["Yes", "No"], "event_message":{"id":"542644", "ticker":"ufc-mel7-bia1-2026-06-20", "slug":"ufc-mel7-bia1-2026-06-20", "title":"UFC Fight Night: Melissa Mullins vs. Bia Mesquita (Women's Bantamweight, Prelims)", "description":"This market will resolve to \"Melissa Mullins\" if Melissa Mullins is officially declared the winner of the fight against Bia Mesquita at UFC Fight Night: Kape vs. Horiguchi, scheduled for June 20, 2026.\n\nIt will resolve to \"Bia Mesquita\" if Bia Mesquita is officially declared the winner.\n\nIf the fight is declared a draw or technical draw, ruled a No Contest, not scored, canceled, or postponed beyond July 4, 2026, this market will resolve \"50-50.\"\n\nThe resolution source for this market will be official information from the UFC."}, "timestamp":"1780178848321", "event_type":"new_market", "tags":[], "condition_id":"0x84d53af66d70177914117868054b508680db6aed9ad865e1c90ac447f2adb60b", "active":false, "clob_token_ids":["104832562566005544059248849505317424244201797614587062002253759164076485746781", "56275346251017414816034462335277651323944126210249109798955891181444818192368"], "sports_market_type":"ufc_method_of_victory", "line":"", "game_start_time":"2026-06-20 17:00:00+00", "order_price_min_tick_size":"0.01", "group_item_title":"Fight won by submission?", "taker_base_fee":"1000", "fees_enabled":true, "fee_schedule":{"exponent":"1", "rate":"0.03", "taker_only":true, "rebate_rate":"0.25"}}
{"id":"2397709", "question":"UFC Fight Night: Melsik Baghdasaryan vs. Murtazali Magomedov (Featherweight, Main Card)", "market":"0x58b670899c087c59740efa7db53bc52aefed9b3aa7d1fb861a863624484e6dd4", "slug":"ufc-mel2-mur2-2026-06-20", "description":"This market will resolve to \"Melsik Baghdasaryan\" if Melsik Baghdasaryan is officially declared the winner of the fight against Murtazali Magomedov at UFC Fight Night: Kape vs. Horiguchi, scheduled for June 20, 2026.\n\nIt will resolve to \"Murtazali Magomedov\" if Murtazali Magomedov is officially declared the winner.\n\nIf the fight is declared a draw or technical draw, ruled a No Contest, not scored, canceled, or postponed beyond July 4, 2026, this market will resolve \"50-50.\"\n\nThe resolution source for this market will be official information from the UFC.", "assets_ids":["46513150770715004805706761520410868184130412374986565346688436810072108025573", "70920764832903699558559115276358349002423979740667732575934033669442611985449"], "outcomes":["Melsik Baghdasaryan", "Murtazali Magomedov"], "event_message":{"id":"542639", "ticker":"ufc-mel2-mur2-2026-06-20", "slug":"ufc-mel2-mur2-2026-06-20", "title":"UFC Fight Night: Melsik Baghdasaryan vs. Murtazali Magomedov (Featherweight, Main Card)", "description":"This market will resolve to \"Melsik Baghdasaryan\" if Melsik Baghdasaryan is officially declared the winner of the fight against Murtazali Magomedov at UFC Fight Night: Kape vs. Horiguchi, scheduled for June 20, 2026.\n\nIt will resolve to \"Murtazali Magomedov\" if Murtazali Magomedov is officially declared the winner.\n\nIf the fight is declared a draw or technical draw, ruled a No Contest, not scored, canceled, or postponed beyond July 4, 2026, this market will resolve \"50-50.\"\n\nThe resolution source for this market will be official information from the UFC."}, "timestamp":"1780178848546", "event_type":"new_market", "tags":[], "condition_id":"0x58b670899c087c59740efa7db53bc52aefed9b3aa7d1fb861a863624484e6dd4", "active":false, "clob_token_ids":["46513150770715004805706761520410868184130412374986565346688436810072108025573", "70920764832903699558559115276358349002423979740667732575934033669442611985449"], "sports_market_type":"moneyline", "line":"", "game_start_time":"2026-06-20 17:00:00+00", "order_price_min_tick_size":"0.01", "group_item_title":"Melsik Baghdasaryan vs. Murtazali Magomedov", "taker_base_fee":"1000", "fees_enabled":true, "fee_schedule":{"exponent":"1", "rate":"0.03", "taker_only":true, "rebate_rate":"0.25"}}
PONG
{"id":"2397763", "question":"Will Gaston Bolaños win by KO or TKO?", "market":"0xef4f04036d1abe12517c681ce6119ec114aa584f04b888e4dbc75ba195974d43", "slug":"ufc-gas-mic34-2026-06-20-bolanos-win-by-ko-tko", "description":"This market will resolve to \"Yes\" if Gaston Bolaños defeats Michael Aswell at UFC Fight Night: Kape vs. Horiguchi, scheduled for June 20, 2026, by KO or TKO, including referee stoppage, doctor stoppage, or corner stoppage. Otherwise, it will resolve to \"No.\"\n\nIf the fight ends in a draw or by disqualification (either fighter), it will resolve \"No.\"\n\nIf the bout is ruled a No Contest, not scored, canceled, or postponed beyond July 4, 2026, this market will resolve \"50-50.\"\n\nThe resolution source for this market will be official information from the UFC.", "assets_ids":["93630474381029536527310387665300886321179520149223810157306274869519342178711", "96462388668177479569700984242805838734868434672309501967484224786481814878228"], "outcomes":["Yes", "No"], "event_message":{"id":"542654", "ticker":"ufc-gas-mic34-2026-06-20", "slug":"ufc-gas-mic34-2026-06-20", "title":"UFC Fight Night: Gaston Bolaños vs. Michael Aswell (Featherweight, Prelims)", "description":"This market will resolve to \"Gaston Bolaños\" if Gaston Bolaños is officially declared the winner of the fight against Michael Aswell at UFC Fight Night: Kape vs. Horiguchi, scheduled for June 20, 2026.\n\nIt will resolve to \"Michael Aswell\" if Michael Aswell is officially declared the winner.\n\nIf the fight is declared a draw or technical draw, ruled a No Contest, not scored, canceled, or postponed beyond July 4, 2026, this market will resolve \"50-50.\"\n\nThe resolution source for this market will be official information from the UFC."}, "timestamp":"1780178850330", "event_type":"new_market", "tags":[], "condition_id":"0xef4f04036d1abe12517c681ce6119ec114aa584f04b888e4dbc75ba195974d43", "active":false, "clob_token_ids":["93630474381029536527310387665300886321179520149223810157306274869519342178711", "96462388668177479569700984242805838734868434672309501967484224786481814878228"], "sports_market_type":"ufc_method_of_victory", "line":"", "game_start_time":"2026-06-20 17:00:00+00", "order_price_min_tick_size":"0.01", "group_item_title":"Bolaños to win by KO/TKO?", "taker_base_fee":"1000", "fees_enabled":true, "fee_schedule":{"exponent":"1", "rate":"0.03", "taker_only":true, "rebate_rate":"0.25"}}
{"market":"0x4f3421fb2daf5cca7430ed8d8132463963081572d75434393a1808fdb8829fe8", "asset_id":"31940783580344558651011323787577288681658737625185216525249046282994042503801", "best_bid":"0.899", "best_ask":"0.9", "spread":"0.001", "timestamp":"1780178851491", "event_type":"best_bid_ask"}
{"market":"0x4f3421fb2daf5cca7430ed8d8132463963081572d75434393a1808fdb8829fe8", "price_changes":[{"asset_id":"45415751658241142530386585138386640503488308219341470020075667342738719018629", "price":"0.101", "size":"66452.82", "side":"SELL", "hash":"7aac05385019ab1fcb2b27196822a3623b012383", "best_bid":"0.1", "best_ask":"0.101"}, {"asset_id":"31940783580344558651011323787577288681658737625185216525249046282994042503801", "price":"0.899", "size":"66452.82", "side":"BUY", "hash":"07f897635bf7bfd15e51162b28c1a57a5209a737", "best_bid":"0.899", "best_ask":"0.9"}], "timestamp":"1780178851490", "event_type":"price_change"}
{"market":"0x4f3421fb2daf5cca7430ed8d8132463963081572d75434393a1808fdb8829fe8", "asset_id":"31940783580344558651011323787577288681658737625185216525249046282994042503801", "bids":[{"price":"0.001", "size":"21074238.91"}, {"price":"0.002", "size":"37.76"}, {"price":"0.01", "size":"25929.6"}, {"price":"0.011", "size":"6.21"}, {"price":"0.014", "size":"1111111"}, {"price":"0.015", "size":"1000000"}, {"price":"0.02", "size":"36500"}, {"price":"0.021", "size":"800"}, {"price":"0.022", "size":"11.19"}, {"price":"0.05", "size":"40"}, {"price":"0.077", "size":"2000"}, {"price":"0.078", "size":"5.64"}, {"price":"0.1", "size":"2229.88"}, {"price":"0.11", "size":"1016"}, {"price":"0.12", "size":"1021"}, {"price":"0.13", "size":"1000"}, {"price":"0.14", "size":"999.99"}, {"price":"0.15", "size":"1153.71"}, {"price":"0.2", "size":"409.2"}, {"price":"0.224", "size":"433.92"}, {"price":"0.225", "size":"5.14"}, {"price":"0.25", "size":"453.7"}, {"price":"0.253", "size":"200"}, {"price":"0.254", "size":"200"}, {"price":"0.27", "size":"200"}, {"price":"0.28", "size":"200"}, {"price":"0.31", "size":"200"}, {"price":"0.33", "size":"215.15"}, {"price":"0.34", "size":"199.99"}, {"price":"0.35", "size":"102.46"}, {"price":"0.36", "size":"228"}, {"price":"0.361", "size":"100"}, {"price":"0.4", "size":"34637.29"}, {"price":"0.401", "size":"5000"}, {"price":"0.41", "size":"200"}, {"price":"0.42", "size":"200"}, {"price":"0.43", "size":"200"}, {"price":"0.44", "size":"200"}, {"price":"0.45", "size":"354.02"}, {"price":"0.46", "size":"200"}, {"price":"0.461", "size":"1077.83"}, {"price":"0.5", "size":"25496.62"}, {"price":"0.501", "size":"5100"}, {"price":"0.51", "size":"205.76"}, {"price":"0.511", "size":"100"}, {"price":"0.52", "size":"100"}, {"price":"0.53", "size":"100"}, {"price":"0.54", "size":"100"}, {"price":"0.55", "size":"100"}, {"price":"0.56", "size":"100"}, {"price":"0.57", "size":"100"}, {"price":"0.58", "size":"100"}, {"price":"0.6", "size":"21059.73"}, {"price":"0.61", "size":"100"}, {"price":"0.62", "size":"111.9"}, {"price":"0.632", "size":"5322.31"}, {"price":"0.64", "size":"28.8"}, {"price":"0.643", "size":"100"}, {"price":"0.65", "size":"16970.62"}, {"price":"0.66", "size":"100"}, {"price":"0.67", "size":"100"}, {"price":"0.673", "size":"100"}, {"price":"0.674", "size":"100"}, {"price":"0.678", "size":"100"}, {"price":"0.68", "size":"410.68"}, {"price":"0.69", "size":"100"}, {"price":"0.7", "size":"422.3"}, {"price":"0.703", "size":"100"}, {"price":"0.704", "size":"100"}, {"price":"0.708", "size":"100"}, {"price":"0.71", "size":"61.7"}, {"price":"0.729", "size":"1000"}, {"price":"0.733", "size":"100"}, {"price":"0.75", "size":"3192.15"}, {"price":"0.759", "size":"1000"}, {"price":"0.76", "size":"341.8"}, {"price":"0.763", "size":"100"}, {"price":"0.764", "size":"100"}, {"price":"0.769", "size":"100"}, {"price":"0.777", "size":"100"}, {"price":"0.778", "size":"400"}, {"price":"0.78", "size":"258.06"}, {"price":"0.781", "size":"100"}, {"price":"0.789", "size":"1000"}, {"price":"0.79", "size":"47.6"}, {"price":"0.798", "size":"1781.45"}, {"price":"0.8", "size":"246868.85"}, {"price":"0.801", "size":"100"}, {"price":"0.804", "size":"30"}, {"price":"0.809", "size":"1000"}, {"price":"0.819", "size":"1000"}, {"price":"0.826", "size":"100"}, {"price":"0.829", "size":"1100"}, {"price":"0.83", "size":"39.23"}, {"price":"0.839", "size":"1000"}, {"price":"0.84", "size":"356.45"}, {"price":"0.847", "size":"100"}, {"price":"0.849", "size":"3541.52"}, {"price":"0.85", "size":"15927.35"}, {"price":"0.851", "size":"800"}, {"price":"0.853", "size":"68.33"}, {"price":"0.855", "size":"13.33"}, {"price":"0.858", "size":"35.21"}, {"price":"0.859", "size":"671"}, {"price":"0.86", "size":"34.6"}, {"price":"0.862", "size":"75"}, {"price":"0.867", "size":"17.97"}, {"price":"0.869", "size":"666"}, {"price":"0.87", "size":"4000"}, {"price":"0.871", "size":"39.42"}, {"price":"0.875", "size":"170"}, {"price":"0.878", "size":"232.7"}, {"price":"0.88", "size":"197"}, {"price":"0.882", "size":"1000"}, {"price":"0.885", "size":"925.73"}, {"price":"0.886", "size":"100"}, {"price":"0.887", "size":"100"}, {"price":"0.888", "size":"100"}, {"price":"0.889", "size":"100"}, {"price":"0.89", "size":"649.23"}, {"price":"0.891", "size":"1343.33"}, {"price":"0.892", "size":"7071.71"}, {"price":"0.893", "size":"15257.35"}, {"price":"0.894", "size":"121650.88"}, {"price":"0.895", "size":"1515.46"}, {"price":"0.896", "size":"30940.81"}, {"price":"0.897", "size":"18263.31"}, {"price":"0.898", "size":"90693.2"}, {"price":"0.899", "size":"66452.82"}], "asks":[{"price":"0.999", "size":"4715397.01"}, {"price":"0.998", "size":"14"}, {"price":"0.997", "size":"1112792"}, {"price":"0.996", "size":"55564"}, {"price":"0.995", "size":"10009"}, {"price":"0.994", "size":"11109"}, {"price":"0.993", "size":"10009"}, {"price":"0.992", "size":"10009"}, {"price":"0.991", "size":"5009"}, {"price":"0.99", "size":"6209"}, {"price":"0.989", "size":"5009"}, {"price":"0.988", "size":"5009"}, {"price":"0.987", "size":"4309"}, {"price":"0.986", "size":"3009"}, {"price":"0.985", "size":"5009"}, {"price":"0.984", "size":"3009"}, {"price":"0.983", "size":"3009"}, {"price":"0.982", "size":"9"}, {"price":"0.981", "size":"5009"}, {"price":"0.98", "size":"6234"}, {"price":"0.979", "size":"4008.99"}, {"price":"0.978", "size":"4009"}, {"price":"0.977", "size":"4009"}, {"price":"0.976", "size":"3009"}, {"price":"0.975", "size":"3009"}, {"price":"0.974", "size":"4009"}, {"price":"0.973", "size":"3009"}, {"price":"0.972", "size":"4009"}, {"price":"0.971", "size":"2009"}, {"price":"0.97", "size":"409"}, {"price":"0.969", "size":"2509"}, {"price":"0.968", "size":"2652.85"}, {"price":"0.967", "size":"2509"}, {"price":"0.966", "size":"2509"}, {"price":"0.965", "size":"9"}, {"price":"0.964", "size":"9"}, {"price":"0.963", "size":"9"}, {"price":"0.962", "size":"609"}, {"price":"0.961", "size":"9"}, {"price":"0.96", "size":"134"}, {"price":"0.959", "size":"9"}, {"price":"0.958", "size":"9"}, {"price":"0.957", "size":"9"}, {"price":"0.956", "size":"9"}, {"price":"0.955", "size":"9"}, {"price":"0.954", "size":"9"}, {"price":"0.953", "size":"9"}, {"price":"0.952", "size":"9"}, {"price":"0.951", "size":"9"}, {"price":"0.95", "size":"79"}, {"price":"0.949", "size":"10009"}, {"price":"0.948", "size":"9"}, {"price":"0.947", "size":"9"}, {"price":"0.946", "size":"9"}, {"price":"0.945", "size":"309"}, {"price":"0.944", "size":"9"}, {"price":"0.943", "size":"9"}, {"price":"0.942", "size":"9"}, {"price":"0.941", "size":"9"}, {"price":"0.94", "size":"36"}, {"price":"0.939", "size":"202"}, {"price":"0.938", "size":"10009"}, {"price":"0.937", "size":"5009"}, {"price":"0.936", "size":"7509"}, {"price":"0.935", "size":"5151"}, {"price":"0.934", "size":"6209"}, {"price":"0.933", "size":"4603.78"}, {"price":"0.932", "size":"2856.05"}, {"price":"0.931", "size":"2772.73"}, {"price":"0.93", "size":"9438.97"}, {"price":"0.929", "size":"1564"}, {"price":"0.928", "size":"5464.3"}, {"price":"0.927", "size":"1109"}, {"price":"0.926", "size":"357402.07"}, {"price":"0.925", "size":"20562.67"}, {"price":"0.924", "size":"6753.29"}, {"price":"0.923", "size":"434.15"}, {"price":"0.922", "size":"512.12"}, {"price":"0.921", "size":"25029"}, {"price":"0.92", "size":"15376.09"}, {"price":"0.919", "size":"1633.99"}, {"price":"0.918", "size":"14672.52"}, {"price":"0.917", "size":"2431.41"}, {"price":"0.916", "size":"9"}, {"price":"0.915", "size":"821.33"}, {"price":"0.914", "size":"22609"}, {"price":"0.913", "size":"4605.61"}, {"price":"0.912", "size":"1782.17"}, {"price":"0.911", "size":"570.79"}, {"price":"0.91", "size":"6647.21"}, {"price":"0.909", "size":"958.45"}, {"price":"0.908", "size":"909"}, {"price":"0.907", "size":"3608.93"}, {"price":"0.906", "size":"1240.91"}, {"price":"0.905", "size":"3028.99"}, {"price":"0.904", "size":"1169.1"}, {"price":"0.903", "size":"6197.22"}, {"price":"0.902", "size":"6110.44"}, {"price":"0.901", "size":"7790.19"}, {"price":"0.9", "size":"9217.48"}], "hash":"07f897635bf7bfd15e51162b28c1a57a5209a737", "timestamp":"1780178851490", "event_type":"book"}
{"market":"0x4f3421fb2daf5cca7430ed8d8132463963081572d75434393a1808fdb8829fe8", "price_changes":[{"asset_id":"45415751658241142530386585138386640503488308219341470020075667342738719018629", "price":"0.099", "size":"7780.19", "side":"BUY", "hash":"88fd3d106fe267f278a9307f0d422855a7b063d3", "best_bid":"0.1", "best_ask":"0.101"}, {"asset_id":"31940783580344558651011323787577288681658737625185216525249046282994042503801", "price":"0.901", "size":"7780.19", "side":"SELL", "hash":"4b7fd1690b261a46d88bff7514040dd90ccd98b9", "best_bid":"0.899", "best_ask":"0.9"}], "timestamp":"1780178851677", "event_type":"price_change"}
{"market":"0x4f3421fb2daf5cca7430ed8d8132463963081572d75434393a1808fdb8829fe8", "price_changes":[{"asset_id":"45415751658241142530386585138386640503488308219341470020075667342738719018629", "price":"0.09", "size":"6657.21", "side":"BUY", "hash":"4da8f88d2de70dfa1db687d3baf6a9515bfb2b59", "best_bid":"0.1", "best_ask":"0.101"}, {"asset_id":"31940783580344558651011323787577288681658737625185216525249046282994042503801", "price":"0.91", "size":"6657.21", "side":"SELL", "hash":"8e548543427dc59a947224c227e4eb14d1d1df51", "best_bid":"0.899", "best_ask":"0.9"}], "timestamp":"1780178851887", "event_type":"price_change"}
{"id":"2397688", "question":"Fight to Go the Distance?", "market":"0xbf8ee2e5038ecceac1c38e33902f89fc86f176c274d7bc7f1aac440beb804616", "slug":"ufc-kev15-and26-2026-06-20-go-the-distance", "description":"This market will resolve to \"Yes\" if the fight between Kevin Borjas and Andre Lima at UFC Fight Night: Kape vs. Horiguchi, scheduled for June 20, 2026, goes the full scheduled number of rounds and the result is determined by the judges' scorecards. Otherwise, it will resolve to \"No.\"\n\nDraws decided by the judges' scorecards after all scheduled rounds are completed will resolve \"Yes.\" Technical decisions or technical draws declared before all rounds are completed will resolve \"No.\"\n\nIf the bout is ruled a No Contest, not scored, canceled, or postponed beyond July 4, 2026, this market will resolve \"50-50.\"\n\nThe resolution source for this market will be official information from the UFC.", "assets_ids":["9752723066022188772512202253023752813013618514483823710152339747327656587741", "27666084844944598896343998508598794322956854944597868112953503129812651168444"], "outcomes":["Yes", "No"], "event_message":{"id":"542631", "ticker":"ufc-kev15-and26-2026-06-20", "slug":"ufc-kev15-and26-2026-06-20", "title":"UFC Fight Night: Kevin Borjas vs. Andre Lima (Flyweight, Main Card)", "description":"This market will resolve to \"Kevin Borjas\" if Kevin Borjas is officially declared the winner of the fight against Andre Lima at UFC Fight Night: Kape vs. Horiguchi, scheduled for June 20, 2026.\n\nIt will resolve to \"Andre Lima\" if Andre Lima is officially declared the winner.\n\nIf the fight is declared a draw or technical draw, ruled a No Contest, not scored, canceled, or postponed beyond July 4, 2026, this market will resolve \"50-50.\"\n\nThe resolution source for this market will be official information from the UFC."}, "timestamp":"1780178852329", "event_type":"new_market", "tags":[], "condition_id":"0xbf8ee2e5038ecceac1c38e33902f89fc86f176c274d7bc7f1aac440beb804616", "active":false, "clob_token_ids":["9752723066022188772512202253023752813013618514483823710152339747327656587741", "27666084844944598896343998508598794322956854944597868112953503129812651168444"], "sports_market_type":"ufc_go_the_distance", "line":"", "game_start_time":"2026-06-20 17:00:00+00", "order_price_min_tick_size":"0.01", "group_item_title":"Fight to Go the Distance?", "taker_base_fee":"1000", "fees_enabled":true, "fee_schedule":{"exponent":"1", "rate":"0.03", "taker_only":true, "rebate_rate":"0.25"}}
{"id":"2397634", "question":"O/U 0.5 Rounds", "market":"0xa6108395fc2fe1e6c2363dd4d368cf50f4f1ee2c1a808a07fea4a376e5ef73a0", "slug":"ufc-kyo-man1-2026-06-20-totals-0pt5", "description":"Each market will resolve to \"Over\" if the fight between Kyoji Horiguchi and Manel Kape at UFC Fight Night: Kape vs. Horiguchi, scheduled for June 20, 2026, lasts beyond the listed round threshold.\n\nEach market will resolve to \"Under\" if the fight does not last beyond the listed round threshold.\n\nFor example:\n\n\"Over 0.5 Rounds\" will resolve \"Yes\" if the fight continues past the 2:30 mark of Round 1.\n\n\"Under 0.5 Rounds\" will resolve \"Yes\" if the fight ends before the 2:30 mark of Round 1.\n\nIf the fight ends exactly at the threshold, it will resolve \"50-50.\"\n\nIf the bout is not scored, postponed beyond July 4, 2026, or canceled, all options will resolve \"50-50.\"\n\nThe resolution source for this market will be official information from the UFC.", "assets_ids":["69443750196198256622148962641712840641795747284812987242557832832531355341650", "55655431721683419775775080423836785744702521967420038940410561876641457330485"], "outcomes":["Over", "Under"], "event_message":{"id":"542607", "ticker":"ufc-kyo-man1-2026-06-20", "slug":"ufc-kyo-man1-2026-06-20", "title":"UFC Fight Night: Kyoji Horiguchi vs. Manel Kape (Flyweight, Main Card)", "description":"This market will resolve to \"Kyoji Horiguchi\" if Kyoji Horiguchi is officially declared the winner of the fight against Manel Kape at UFC Fight Night: Kape vs. Horiguchi, scheduled for June 20, 2026.\n\nIt will resolve to \"Manel Kape\" if Manel Kape is officially declared the winner.\n\nIf the fight is declared a draw or technical draw, ruled a No Contest, not scored, canceled, or postponed beyond July 4, 2026, this market will resolve \"50-50.\"\n\nThe resolution source for this market will be official information from the UFC."}, "timestamp":"1780178853380", "event_type":"new_market", "tags":[], "condition_id":"0xa6108395fc2fe1e6c2363dd4d368cf50f4f1ee2c1a808a07fea4a376e5ef73a0", "active":false, "clob_token_ids":["69443750196198256622148962641712840641795747284812987242557832832531355341650", "55655431721683419775775080423836785744702521967420038940410561876641457330485"], "sports_market_type":"totals", "line":"0.5", "game_start_time":"2026-06-20 17:00:00+00", "order_price_min_tick_size":"0.01", "group_item_title":"O/U 0.5 Rounds", "taker_base_fee":"1000", "fees_enabled":true, "fee_schedule":{"exponent":"1", "rate":"0.03", "taker_only":true, "rebate_rate":"0.25"}}
{"id":"2397616", "question":"Roland Garros ATP (Doubles): Droguet/Gaston vs Halys/Herbert", "market":"0xc4eb90d46c0ee0b6c49752edef941c6c29fd287f7888d0ab684b43789f45f6ea", "slug":"atp-doubles-droggas-halyher-2026-06-01", "description":"This market refers to the doubles tennis match between Droguet/Gaston and Halys/Herbert in the Roland Garros ATP, originally scheduled for June 1, 2026 at 5:00AM ET.\n\nThis market will resolve to 'Droguet/Gaston' if the team of Droguet/Gaston advances against Halys/Herbert.\n\nThis market will resolve to 'Halys/Herbert' if the team of Halys/Herbert advances against Droguet/Gaston.\n\nIf the match is canceled (not played at all), ends in a tie, or is delayed beyond 7 days from the scheduled date without a winner determined, this market will resolve to 50-50.\n\nIf the match begins but is not completed, and one team advances due to the opponent's retirement, default, or disqualification, this market will resolve to the team who advances.\n\nIf the match ends in a walkover (a team withdraws before the start and the other advances automatically), this market will resolve to 50-50.\n\nThe primary resolution source will be official information from the ATP Tour. A consensus of credible reporting may also be used.", "assets_ids":["62459901524788742450201420539627816372593710289597606793039948939305652186039", "24531110410764312079221496400069770784760526912149579157175886734033100240991"], "outcomes":["Droguet/Gaston", "Halys/Herbert"], "event_message":{"id":"542608", "ticker":"atp-doubles-droggas-halyher-2026-06-01", "slug":"atp-doubles-droggas-halyher-2026-06-01", "title":"Roland Garros ATP (Doubles): Droguet/Gaston vs Halys/Herbert", "description":"This market refers to the doubles tennis match between Droguet/Gaston and Halys/Herbert in the Roland Garros ATP, originally scheduled for June 1, 2026 at 5:00AM ET.\n\nThis market will resolve to 'Droguet/Gaston' if the team of Droguet/Gaston advances against Halys/Herbert.\n\nThis market will resolve to 'Halys/Herbert' if the team of Halys/Herbert advances against Droguet/Gaston.\n\nIf the match is canceled (not played at all), ends in a tie, or is delayed beyond 7 days from the scheduled date without a winner determined, this market will resolve to 50-50.\n\nIf the match begins but is not completed, and one team advances due to the opponent's retirement, default, or disqualification, this market will resolve to the team who advances.\n\nIf the match ends in a walkover (a team withdraws before the start and the other advances automatically), this market will resolve to 50-50.\n\nThe primary resolution source will be official information from the ATP Tour. A consensus of credible reporting may also be used."}, "timestamp":"1780178855634", "event_type":"new_market", "tags":[], "condition_id":"0xc4eb90d46c0ee0b6c49752edef941c6c29fd287f7888d0ab684b43789f45f6ea", "active":false, "clob_token_ids":["62459901524788742450201420539627816372593710289597606793039948939305652186039", "24531110410764312079221496400069770784760526912149579157175886734033100240991"], "sports_market_type":"moneyline", "line":"", "game_start_time":"2026-06-01 09:00:00+00", "order_price_min_tick_size":"0.01", "group_item_title":"", "taker_base_fee":"1000", "fees_enabled":true, "fee_schedule":{"exponent":"1", "rate":"0.03", "taker_only":true, "rebate_rate":"0.25"}}
{"id":"2397666", "question":"Centurion 2: Completed Match: Filip Peliwo vs Eliakim Coulibaly", "market":"0xd080fec332d46f5de91924b8877045ad7b93826922f820db1cd9bdb651423e41", "slug":"atp-peliwo-couliba-2026-06-01-completed-match", "description":"This market refers to the tennis match between Filip Peliwo and Eliakim Coulibaly in the Centurion 2, originally scheduled for June 1, 2026 at 4:00AM ET. This market will resolve to \"Yes\" if all games and sets required to determine a match winner under governing body or event organizer rules are played to completion through normal play. Otherwise, if the match is not completed for any reason, it will resolve to \"No.\" If a forfeit of any kind occurs, including but not limited to a walkover or retirement, this market will resolve \"No.\" If the match is canceled (not played at all), ends in a tie, or is delayed beyond 7 days from the scheduled date without a winner determined, this market will resolve to \"No.\" The primary resolution source for this market is the official statistics of the event as recognized by the governing body or event organizers. However, if the governing body or event organizers have not published final match statistics within 2 hours after the event's conclusion, a consensus of credible reporting may be used instead.", "assets_ids":["37853876408176874646253041509224614828403064712011405426416137986733785638400", "45834063061940368072239630516087580787650198348110568544069054358972974855403"], "outcomes":["Yes", "No"], "event_message":{"id":"542623", "ticker":"atp-peliwo-couliba-2026-06-01", "slug":"atp-peliwo-couliba-2026-06-01", "title":"Centurion 2: Filip Peliwo vs Eliakim Coulibaly", "description":"This market refers to the tennis match between Filip Peliwo and Eliakim Coulibaly in the Centurion 2, originally scheduled for June 1, 2026 at 4:00AM ET.\n\nThis market will resolve to 'Filip Peliwo' if Filip Peliwo advances against Eliakim Coulibaly.\n\nThis market will resolve to 'Eliakim Coulibaly' if Eliakim Coulibaly advances against Filip Peliwo.\n\nIf the match is canceled (not played at all), ends in a tie, or is delayed beyond 7 days from the scheduled date without a winner determined, this market will resolve to 50-50.\n\nIf the match begins but is not completed, and one player advances due to the opponent's retirement, default, or disqualification, this market will resolve to the player who advances.\n\nIf the match ends in a walkover (player withdraws before the start and the other advances automatically), this market will resolve to 50-50.\n\nThe primary resolution source will be official information from the ATP Tour. A consensus of credible reporting may also be used."}, "timestamp":"1780178858156", "event_type":"new_market", "tags":[], "condition_id":"0xd080fec332d46f5de91924b8877045ad7b93826922f820db1cd9bdb651423e41", "active":false, "clob_token_ids":["37853876408176874646253041509224614828403064712011405426416137986733785638400", "45834063061940368072239630516087580787650198348110568544069054358972974855403"], "sports_market_type":"tennis_completed_match", "line":"", "game_start_time":"2026-06-01 08:00:00+00", "order_price_min_tick_size":"0.01", "group_item_title":"Completed Match", "taker_base_fee":"1000", "fees_enabled":true, "fee_schedule":{"exponent":"1", "rate":"0.03", "taker_only":true, "rebate_rate":"0.25"}}
{"id":"2397620", "question":"Roland Garros ATP: Completed Match: Droguet/Gaston vs Halys/Herbert", "market":"0xfdb98c502b9685426b304af083276978bcb3466a3e9423cc6c38b73de86f7183", "slug":"atp-doubles-droggas-halyher-2026-06-01-completed-match", "description":"This market refers to the doubles tennis match between Droguet/Gaston and Halys/Herbert in the Roland Garros ATP, originally scheduled for June 1, 2026 at 5:00AM ET. This market will resolve to \"Yes\" if all games and sets required to determine a match winner under governing body or event organizer rules are played to completion through normal play. Otherwise, if the match is not completed for any reason, it will resolve to \"No.\" If a forfeit of any kind occurs, including but not limited to a walkover or retirement, this market will resolve \"No.\" If the match is canceled (not played at all), ends in a tie, or is delayed beyond 7 days from the scheduled date without a winner determined, this market will resolve to \"No.\" The primary resolution source for this market is the official statistics of the event as recognized by the governing body or event organizers. However, if the governing body or event organizers have not published final match statistics within 2 hours after the event's conclusion, a consensus of credible reporting may be used instead.", "assets_ids":["88831241605284761995750921335266872039268365041707339707507276974670419973523", "58019806799885847751841770183676292159285838886260477961781352831236770261336"], "outcomes":["Yes", "No"], "event_message":{"id":"542608", "ticker":"atp-doubles-droggas-halyher-2026-06-01", "slug":"atp-doubles-droggas-halyher-2026-06-01", "title":"Roland Garros ATP (Doubles): Droguet/Gaston vs Halys/Herbert", "description":"This market refers to the doubles tennis match between Droguet/Gaston and Halys/Herbert in the Roland Garros ATP, originally scheduled for June 1, 2026 at 5:00AM ET.\n\nThis market will resolve to 'Droguet/Gaston' if the team of Droguet/Gaston advances against Halys/Herbert.\n\nThis market will resolve to 'Halys/Herbert' if the team of Halys/Herbert advances against Droguet/Gaston.\n\nIf the match is canceled (not played at all), ends in a tie, or is delayed beyond 7 days from the scheduled date without a winner determined, this market will resolve to 50-50.\n\nIf the match begins but is not completed, and one team advances due to the opponent's retirement, default, or disqualification, this market will resolve to the team who advances.\n\nIf the match ends in a walkover (a team withdraws before the start and the other advances automatically), this market will resolve to 50-50.\n\nThe primary resolution source will be official information from the ATP Tour. A consensus of credible reporting may also be used."}, "timestamp":"1780178858296", "event_type":"new_market", "tags":[], "condition_id":"0xfdb98c502b9685426b304af083276978bcb3466a3e9423cc6c38b73de86f7183", "active":false, "clob_token_ids":["88831241605284761995750921335266872039268365041707339707507276974670419973523", "58019806799885847751841770183676292159285838886260477961781352831236770261336"], "sports_market_type":"tennis_completed_match", "line":"", "game_start_time":"2026-06-01 09:00:00+00", "order_price_min_tick_size":"0.01", "group_item_title":"Completed Match", "taker_base_fee":"1000", "fees_enabled":true, "fee_schedule":{"exponent":"1", "rate":"0.03", "taker_only":true, "rebate_rate":"0.25"}}
{"id":"2397767", "question":"Prostejov: Completed Match: Roberto Bautista Agut vs Hynek Barton", "market":"0x685303b5abf859f21812902f357f4f93c0ec589566e18368891030e6d4c6992b", "slug":"atp-agut-barton-2026-06-01-completed-match", "description":"This market refers to the tennis match between Roberto Bautista Agut and Hynek Barton in the Prostejov, originally scheduled for June 1, 2026 at 4:00AM ET. This market will resolve to \"Yes\" if all games and sets required to determine a match winner under governing body or event organizer rules are played to completion through normal play. Otherwise, if the match is not completed for any reason, it will resolve to \"No.\" If a forfeit of any kind occurs, including but not limited to a walkover or retirement, this market will resolve \"No.\" If the match is canceled (not played at all), ends in a tie, or is delayed beyond 7 days from the scheduled date without a winner determined, this market will resolve to \"No.\" The primary resolution source for this market is the official statistics of the event as recognized by the governing body or event organizers. However, if the governing body or event organizers have not published final match statistics within 2 hours after the event's conclusion, a consensus of credible reporting may be used instead.", "assets_ids":["81461552370025530299481124902519514611579794988221283597063264985524449563742", "89070295937235712321654931955838987490352484426768892782722833732763278707249"], "outcomes":["Yes", "No"], "event_message":{"id":"542656", "ticker":"atp-agut-barton-2026-06-01", "slug":"atp-agut-barton-2026-06-01", "title":"Prostejov: Roberto Bautista Agut vs Hynek Barton", "description":"This market refers to the tennis match between Roberto Bautista Agut and Hynek Barton in the Prostejov, originally scheduled for June 1, 2026 at 4:00AM ET.\n\nThis market will resolve to 'Roberto Bautista Agut' if Roberto Bautista Agut advances against Hynek Barton.\n\nThis market will resolve to 'Hynek Barton' if Hynek Barton advances against Roberto Bautista Agut.\n\nIf the match is canceled (not played at all), ends in a tie, or is delayed beyond 7 days from the scheduled date without a winner determined, this market will resolve to 50-50.\n\nIf the match begins but is not completed, and one player advances due to the opponent's retirement, default, or disqualification, this market will resolve to the player who advances.\n\nIf the match ends in a walkover (player withdraws before the start and the other advances automatically), this market will resolve to 50-50.\n\nThe primary resolution source will be official information from the ATP Tour. A consensus of credible reporting may also be used."}, "timestamp":"1780178858565", "event_type":"new_market", "tags":[], "condition_id":"0x685303b5abf859f21812902f357f4f93c0ec589566e18368891030e6d4c6992b", "active":false, "clob_token_ids":["81461552370025530299481124902519514611579794988221283597063264985524449563742", "89070295937235712321654931955838987490352484426768892782722833732763278707249"], "sports_market_type":"tennis_completed_match", "line":"", "game_start_time":"2026-06-01 08:00:00+00", "order_price_min_tick_size":"0.01", "group_item_title":"Completed Match", "taker_base_fee":"1000", "fees_enabled":true, "fee_schedule":{"exponent":"1", "rate":"0.03", "taker_only":true, "rebate_rate":"0.25"}}
{"market":"0x4f3421fb2daf5cca7430ed8d8132463963081572d75434393a1808fdb8829fe8", "price_changes":[{"asset_id":"45415751658241142530386585138386640503488308219341470020075667342738719018629", "price":"0.09", "size":"6647.21", "side":"BUY", "hash":"4da2f9b06a5054e31ba68a4c6c0bead233c4fc39", "best_bid":"0.1", "best_ask":"0.101"}, {"asset_id":"31940783580344558651011323787577288681658737625185216525249046282994042503801", "price":"0.91", "size":"6647.21", "side":"SELL", "hash":"683a14905994cd1cd6a258e8638b380eb29e1d61", "best_bid":"0.899", "best_ask":"0.9"}], "timestamp":"1780178859411", "event_type":"price_change"}
{"market":"0x4f3421fb2daf5cca7430ed8d8132463963081572d75434393a1808fdb8829fe8", "price_changes":[{"asset_id":"45415751658241142530386585138386640503488308219341470020075667342738719018629", "price":"0.099", "size":"7790.19", "side":"BUY", "hash":"d05c2197635f0da07cac30056de1d6ac0630f97a", "best_bid":"0.1", "best_ask":"0.101"}, {"asset_id":"31940783580344558651011323787577288681658737625185216525249046282994042503801", "price":"0.901", "size":"7790.19", "side":"SELL", "hash":"436acd0b5f512cdc54c6b132605f58af9a316955", "best_bid":"0.899", "best_ask":"0.9"}], "timestamp":"1780178859616", "event_type":"price_change"}
PONG
{"id":"2397865", "question":"Total Kills Over/Under 20.5 in Game 3?", "market":"0xb8339e5a5e2e3430d9f58a3699ef6d28d753661f4ccc7c90fa6e844cbc652a94", "slug":"lol-fly-sen-2026-05-30-game3-kill-over-20pt5", "description":"In the upcoming Lower bracket quarterfinal 1 match between FlyQuest and Sentinels in the LCS Playoffs, initially scheduled for May 30 at 4:00PM ET:\n\nThis market is about the total kills in Game 3.\n\nThis market will resolve to \"Over\" if the total kills in Game 3 is 21 or more. Otherwise, it will resolve to \"Under\".\n\nIf the match is canceled (not played at all) or is delayed beyond 7 days from the scheduled date, this market will resolve to 50-50.\n\nIf Game 3 is never played due to forfeit, disqualification, or walkover, this market will resolve to 50-50.\n\nIf Game 3 begins but is not completed, this market will resolve to 50-50.\n\nIf Game 3 is remade, resolution will be based on the total kills in the remade game only.\n\nThe resolution source for this market will be official information from https://gol.gg/esports/home. However, if https://gol.gg/esports/home has not published final results within 2 hours after the event’s conclusion, a consensus of credible reporting may be used instead including video evidence.\n", "assets_ids":["66730575084260283338007697399713576759312024521617534775141973228887998357041", "31188785663962547253728904701926897536195416723314794016065811432850916473230"], "outcomes":["Over", "Under"], "event_message":{"id":"519766", "ticker":"lol-fly-sen-2026-05-30", "slug":"lol-fly-sen-2026-05-30", "title":"LoL: FlyQuest vs Sentinels (BO5) - LCS Playoffs", "description":"This market refers to the LoL Lower bracket quarterfinal 1 match between FlyQuest and Sentinels in the LCS Playoffs, initially scheduled for May 30 at 4:00PM ET.\n\nThis market will resolve to \"FlyQuest\" if FlyQuest win the match against Sentinels.\n\nThis market will resolve to \"Sentinels\" if Sentinels win the match against FlyQuest.\n\nIf the match is canceled (not played at all), ends in a tie, or is delayed beyond 7 days from the scheduled date without a winner determined, this market will resolve to 50-50. \n\nIf the match begins but is not completed, and one team wins due to the opponent's forfeiture, disqualification, or walkover, this market will resolve to the team who wins. \n\nIf the match ends in a forfeit, disqualification, or walkover (team withdraws before the start and the other wins automatically), this market will resolve to 50-50. \n\nThe resolution source for this market will be official information from https://gol.gg/esports/home. However, if https://gol.gg/esports/home has not published final results within 2 hours after the event’s conclusion, a consensus of credible reporting may be used instead including video evidence.\n\nIn cases where a team’s listed name includes minor discrepancies from the resolution source, this market will resolve based on the underlying real-world match rather than exact name matching. Recognizable abbreviations, alternate or erroneous spellings, sponsor tags, affiliate or academy designations, regional identifiers, and minor formatting differences will be treated as referring to the same team, provided the intended team can be clearly and uniquely identified within the relevant competition. If a listed team name has no reasonable connection to any participating team, or if it matches or could reasonably refer to another team in the same competition such that the intended team cannot be unambiguously determined, this market will resolve 50-50."}, "timestamp":"1780178860403", "event_type":"new_market", "tags":[], "condition_id":"0xb8339e5a5e2e3430d9f58a3699ef6d28d753661f4ccc7c90fa6e844cbc652a94", "active":false, "clob_token_ids":["66730575084260283338007697399713576759312024521617534775141973228887998357041", "31188785663962547253728904701926897536195416723314794016065811432850916473230"], "sports_market_type":"kill_over_under_game", "line":"20.5", "game_start_time":"2026-05-30 20:00:00+00", "order_price_min_tick_size":"0.01", "group_item_title":"Total Kills Over/Under 20.5 in Game 3?", "taker_base_fee":"1000", "fees_enabled":true, "fee_schedule":{"exponent":"1", "rate":"0.03", "taker_only":true, "rebate_rate":"0.25"}}
{"market":"0x375409bc5eeeff961e82b479caeccc20f33d15738e5bce1186d628aa3d9dfb1f", "price_changes":[{"asset_id":"115556263888245616435851357148058235707004733438163639091106356867234218207169", "price":"0.12", "size":"20849.13", "side":"SELL", "hash":"f18cb39fb8cf718fd697dcd635c2b62d2fdd4143", "best_bid":"0.112", "best_ask":"0.113"}, {"asset_id":"77121637225348873006259930776623502125079210522997384841464684944292365296940", "price":"0.88", "size":"20849.13", "side":"BUY", "hash":"aebc2129b5583a91a5e0d76e4112b3ab15fa5fa0", "best_bid":"0.887", "best_ask":"0.888"}], "timestamp":"1780178860435", "event_type":"price_change"}
{"market":"0x375409bc5eeeff961e82b479caeccc20f33d15738e5bce1186d628aa3d9dfb1f", "price_changes":[{"asset_id":"115556263888245616435851357148058235707004733438163639091106356867234218207169", "price":"0.113", "size":"231388.42", "side":"SELL", "hash":"ce42661fe5791628c00457b2f37018e4834e6ae9", "best_bid":"0.112", "best_ask":"0.113"}, {"asset_id":"77121637225348873006259930776623502125079210522997384841464684944292365296940", "price":"0.887", "size":"231388.42", "side":"BUY", "hash":"8098909bf98a3a060645d61f3923f82fbb625093", "best_bid":"0.887", "best_ask":"0.888"}], "timestamp":"1780178860645", "event_type":"price_change"}
{"market":"0x4f3421fb2daf5cca7430ed8d8132463963081572d75434393a1808fdb8829fe8", "asset_id":"31940783580344558651011323787577288681658737625185216525249046282994042503801", "best_bid":"0.899", "best_ask":"0.9", "spread":"0.001", "timestamp":"1780178861410", "event_type":"best_bid_ask"}
{"market":"0x4f3421fb2daf5cca7430ed8d8132463963081572d75434393a1808fdb8829fe8", "price_changes":[{"asset_id":"45415751658241142530386585138386640503488308219341470020075667342738719018629", "price":"0.101", "size":"66442.91", "side":"SELL", "hash":"7e4e0b923791e317a57a5be8da4b4c1e5b192935", "best_bid":"0.1", "best_ask":"0.101"}, {"asset_id":"31940783580344558651011323787577288681658737625185216525249046282994042503801", "price":"0.899", "size":"66442.91", "side":"BUY", "hash":"34bf43b2d5bfa78755d8b4d70879be09acc1c1bf", "best_bid":"0.899", "best_ask":"0.9"}], "timestamp":"1780178861410", "event_type":"price_change"}
{"market":"0x4f3421fb2daf5cca7430ed8d8132463963081572d75434393a1808fdb8829fe8", "asset_id":"31940783580344558651011323787577288681658737625185216525249046282994042503801", "bids":[{"price":"0.001", "size":"21074238.91"}, {"price":"0.002", "size":"37.76"}, {"price":"0.01", "size":"25929.6"}, {"price":"0.011", "size":"6.21"}, {"price":"0.014", "size":"1111111"}, {"price":"0.015", "size":"1000000"}, {"price":"0.02", "size":"36500"}, {"price":"0.021", "size":"800"}, {"price":"0.022", "size":"11.19"}, {"price":"0.05", "size":"40"}, {"price":"0.077", "size":"2000"}, {"price":"0.078", "size":"5.64"}, {"price":"0.1", "size":"2229.88"}, {"price":"0.11", "size":"1016"}, {"price":"0.12", "size":"1021"}, {"price":"0.13", "size":"1000"}, {"price":"0.14", "size":"999.99"}, {"price":"0.15", "size":"1153.71"}, {"price":"0.2", "size":"409.2"}, {"price":"0.224", "size":"433.92"}, {"price":"0.225", "size":"5.14"}, {"price":"0.25", "size":"453.7"}, {"price":"0.253", "size":"200"}, {"price":"0.254", "size":"200"}, {"price":"0.27", "size":"200"}, {"price":"0.28", "size":"200"}, {"price":"0.31", "size":"200"}, {"price":"0.33", "size":"215.15"}, {"price":"0.34", "size":"199.99"}, {"price":"0.35", "size":"102.46"}, {"price":"0.36", "size":"228"}, {"price":"0.361", "size":"100"}, {"price":"0.4", "size":"34637.29"}, {"price":"0.401", "size":"5000"}, {"price":"0.41", "size":"200"}, {"price":"0.42", "size":"200"}, {"price":"0.43", "size":"200"}, {"price":"0.44", "size":"200"}, {"price":"0.45", "size":"354.02"}, {"price":"0.46", "size":"200"}, {"price":"0.461", "size":"1077.83"}, {"price":"0.5", "size":"25496.62"}, {"price":"0.501", "size":"5100"}, {"price":"0.51", "size":"205.76"}, {"price":"0.511", "size":"100"}, {"price":"0.52", "size":"100"}, {"price":"0.53", "size":"100"}, {"price":"0.54", "size":"100"}, {"price":"0.55", "size":"100"}, {"price":"0.56", "size":"100"}, {"price":"0.57", "size":"100"}, {"price":"0.58", "size":"100"}, {"price":"0.6", "size":"21059.73"}, {"price":"0.61", "size":"100"}, {"price":"0.62", "size":"111.9"}, {"price":"0.632", "size":"5322.31"}, {"price":"0.64", "size":"28.8"}, {"price":"0.643", "size":"100"}, {"price":"0.65", "size":"16970.62"}, {"price":"0.66", "size":"100"}, {"price":"0.67", "size":"100"}, {"price":"0.673", "size":"100"}, {"price":"0.674", "size":"100"}, {"price":"0.678", "size":"100"}, {"price":"0.68", "size":"410.68"}, {"price":"0.69", "size":"100"}, {"price":"0.7", "size":"422.3"}, {"price":"0.703", "size":"100"}, {"price":"0.704", "size":"100"}, {"price":"0.708", "size":"100"}, {"price":"0.71", "size":"61.7"}, {"price":"0.729", "size":"1000"}, {"price":"0.733", "size":"100"}, {"price":"0.75", "size":"3192.15"}, {"price":"0.759", "size":"1000"}, {"price":"0.76", "size":"341.8"}, {"price":"0.763", "size":"100"}, {"price":"0.764", "size":"100"}, {"price":"0.769", "size":"100"}, {"price":"0.777", "size":"100"}, {"price":"0.778", "size":"400"}, {"price":"0.78", "size":"258.06"}, {"price":"0.781", "size":"100"}, {"price":"0.789", "size":"1000"}, {"price":"0.79", "size":"47.6"}, {"price":"0.798", "size":"1781.45"}, {"price":"0.8", "size":"246868.85"}, {"price":"0.801", "size":"100"}, {"price":"0.804", "size":"30"}, {"price":"0.809", "size":"1000"}, {"price":"0.819", "size":"1000"}, {"price":"0.826", "size":"100"}, {"price":"0.829", "size":"1100"}, {"price":"0.83", "size":"39.23"}, {"price":"0.839", "size":"1000"}, {"price":"0.84", "size":"356.45"}, {"price":"0.847", "size":"100"}, {"price":"0.849", "size":"3541.52"}, {"price":"0.85", "size":"15927.35"}, {"price":"0.851", "size":"800"}, {"price":"0.853", "size":"68.33"}, {"price":"0.855", "size":"13.33"}, {"price":"0.858", "size":"35.21"}, {"price":"0.859", "size":"671"}, {"price":"0.86", "size":"34.6"}, {"price":"0.862", "size":"75"}, {"price":"0.867", "size":"17.97"}, {"price":"0.869", "size":"666"}, {"price":"0.87", "size":"4000"}, {"price":"0.871", "size":"39.42"}, {"price":"0.875", "size":"170"}, {"price":"0.878", "size":"232.7"}, {"price":"0.88", "size":"197"}, {"price":"0.882", "size":"1000"}, {"price":"0.885", "size":"925.73"}, {"price":"0.886", "size":"100"}, {"price":"0.887", "size":"100"}, {"price":"0.888", "size":"100"}, {"price":"0.889", "size":"100"}, {"price":"0.89", "size":"649.23"}, {"price":"0.891", "size":"1343.33"}, {"price":"0.892", "size":"7071.71"}, {"price":"0.893", "size":"15257.35"}, {"price":"0.894", "size":"121650.88"}, {"price":"0.895", "size":"1515.46"}, {"price":"0.896", "size":"30940.81"}, {"price":"0.897", "size":"18263.31"}, {"price":"0.898", "size":"90693.2"}, {"price":"0.899", "size":"66442.91"}], "asks":[{"price":"0.999", "size":"4715397.01"}, {"price":"0.998", "size":"14"}, {"price":"0.997", "size":"1112792"}, {"price":"0.996", "size":"55564"}, {"price":"0.995", "size":"10009"}, {"price":"0.994", "size":"11109"}, {"price":"0.993", "size":"10009"}, {"price":"0.992", "size":"10009"}, {"price":"0.991", "size":"5009"}, {"price":"0.99", "size":"6209"}, {"price":"0.989", "size":"5009"}, {"price":"0.988", "size":"5009"}, {"price":"0.987", "size":"4309"}, {"price":"0.986", "size":"3009"}, {"price":"0.985", "size":"5009"}, {"price":"0.984", "size":"3009"}, {"price":"0.983", "size":"3009"}, {"price":"0.982", "size":"9"}, {"price":"0.981", "size":"5009"}, {"price":"0.98", "size":"6234"}, {"price":"0.979", "size":"4008.99"}, {"price":"0.978", "size":"4009"}, {"price":"0.977", "size":"4009"}, {"price":"0.976", "size":"3009"}, {"price":"0.975", "size":"3009"}, {"price":"0.974", "size":"4009"}, {"price":"0.973", "size":"3009"}, {"price":"0.972", "size":"4009"}, {"price":"0.971", "size":"2009"}, {"price":"0.97", "size":"409"}, {"price":"0.969", "size":"2509"}, {"price":"0.968", "size":"2652.85"}, {"price":"0.967", "size":"2509"}, {"price":"0.966", "size":"2509"}, {"price":"0.965", "size":"9"}, {"price":"0.964", "size":"9"}, {"price":"0.963", "size":"9"}, {"price":"0.962", "size":"609"}, {"price":"0.961", "size":"9"}, {"price":"0.96", "size":"134"}, {"price":"0.959", "size":"9"}, {"price":"0.958", "size":"9"}, {"price":"0.957", "size":"9"}, {"price":"0.956", "size":"9"}, {"price":"0.955", "size":"9"}, {"price":"0.954", "size":"9"}, {"price":"0.953", "size":"9"}, {"price":"0.952", "size":"9"}, {"price":"0.951", "size":"9"}, {"price":"0.95", "size":"79"}, {"price":"0.949", "size":"10009"}, {"price":"0.948", "size":"9"}, {"price":"0.947", "size":"9"}, {"price":"0.946", "size":"9"}, {"price":"0.945", "size":"309"}, {"price":"0.944", "size":"9"}, {"price":"0.943", "size":"9"}, {"price":"0.942", "size":"9"}, {"price":"0.941", "size":"9"}, {"price":"0.94", "size":"36"}, {"price":"0.939", "size":"202"}, {"price":"0.938", "size":"10009"}, {"price":"0.937", "size":"5009"}, {"price":"0.936", "size":"7509"}, {"price":"0.935", "size":"5151"}, {"price":"0.934", "size":"6209"}, {"price":"0.933", "size":"4603.78"}, {"price":"0.932", "size":"2856.05"}, {"price":"0.931", "size":"2772.73"}, {"price":"0.93", "size":"9438.97"}, {"price":"0.929", "size":"1564"}, {"price":"0.928", "size":"5464.3"}, {"price":"0.927", "size":"1109"}, {"price":"0.926", "size":"357402.07"}, {"price":"0.925", "size":"20562.67"}, {"price":"0.924", "size":"6753.29"}, {"price":"0.923", "size":"434.15"}, {"price":"0.922", "size":"512.12"}, {"price":"0.921", "size":"25029"}, {"price":"0.92", "size":"15376.09"}, {"price":"0.919", "size":"1633.99"}, {"price":"0.918", "size":"14672.52"}, {"price":"0.917", "size":"2431.41"}, {"price":"0.916", "size":"9"}, {"price":"0.915", "size":"821.33"}, {"price":"0.914", "size":"22609"}, {"price":"0.913", "size":"4605.61"}, {"price":"0.912", "size":"1782.17"}, {"price":"0.911", "size":"570.79"}, {"price":"0.91", "size":"6647.21"}, {"price":"0.909", "size":"958.45"}, {"price":"0.908", "size":"909"}, {"price":"0.907", "size":"3608.93"}, {"price":"0.906", "size":"1240.91"}, {"price":"0.905", "size":"3028.99"}, {"price":"0.904", "size":"1169.1"}, {"price":"0.903", "size":"6197.22"}, {"price":"0.902", "size":"6110.44"}, {"price":"0.901", "size":"7790.19"}, {"price":"0.9", "size":"9217.48"}], "hash":"34bf43b2d5bfa78755d8b4d70879be09acc1c1bf", "timestamp":"1780178861410", "event_type":"book"}
{"market":"0x4f3421fb2daf5cca7430ed8d8132463963081572d75434393a1808fdb8829fe8", "price_changes":[{"asset_id":"45415751658241142530386585138386640503488308219341470020075667342738719018629", "price":"0.099", "size":"7780.19", "side":"BUY", "hash":"56c75bbd9075a3a48da82ad52e66d973e833e2e9", "best_bid":"0.1", "best_ask":"0.101"}, {"asset_id":"31940783580344558651011323787577288681658737625185216525249046282994042503801", "price":"0.901", "size":"7780.19", "side":"SELL", "hash":"9cd05c7a8577b5c23fc1f2446f42489ba6586e0f", "best_bid":"0.899", "best_ask":"0.9"}], "timestamp":"1780178861605", "event_type":"price_change"}
{"market":"0x4f3421fb2daf5cca7430ed8d8132463963081572d75434393a1808fdb8829fe8", "price_changes":[{"asset_id":"45415751658241142530386585138386640503488308219341470020075667342738719018629", "price":"0.09", "size":"6657.21", "side":"BUY", "hash":"898345215b8c3bf093645c6805c527979b83c07d", "best_bid":"0.1", "best_ask":"0.101"}, {"asset_id":"31940783580344558651011323787577288681658737625185216525249046282994042503801", "price":"0.91", "size":"6657.21", "side":"SELL", "hash":"63da3b84065a6c632b85542453bcc6411e1d3dc8", "best_bid":"0.899", "best_ask":"0.9"}], "timestamp":"1780178861815", "event_type":"price_change"}
{"market":"0x4f3421fb2daf5cca7430ed8d8132463963081572d75434393a1808fdb8829fe8", "price_changes":[{"asset_id":"45415751658241142530386585138386640503488308219341470020075667342738719018629", "price":"0.103", "size":"18203.31", "side":"SELL", "hash":"34634a952aaef434678b0a7bc49fe47fcc845639", "best_bid":"0.1", "best_ask":"0.101"}, {"asset_id":"31940783580344558651011323787577288681658737625185216525249046282994042503801", "price":"0.897", "size":"18203.31", "side":"BUY", "hash":"36b0cc1e6cbeb9dadf9500090c6474e7eb8e3d79", "best_bid":"0.899", "best_ask":"0.9"}], "timestamp":"1780178861870", "event_type":"price_change"}
{"market":"0x4f3421fb2daf5cca7430ed8d8132463963081572d75434393a1808fdb8829fe8", "price_changes":[{"asset_id":"45415751658241142530386585138386640503488308219341470020075667342738719018629", "price":"0.103", "size":"18263.31", "side":"SELL", "hash":"812111631dc1d0808a96c40f88ac031688d97ba4", "best_bid":"0.1", "best_ask":"0.101"}, {"asset_id":"31940783580344558651011323787577288681658737625185216525249046282994042503801", "price":"0.897", "size":"18263.31", "side":"BUY", "hash":"4c7599f8339c2c556f7e9a04673332296b7ec23d", "best_bid":"0.899", "best_ask":"0.9"}], "timestamp":"1780178862069", "event_type":"price_change"}
{"market":"0x9b6fef249040fd17e9c107955b37ac2c3e923509b6b0ff01cc463a331ddeb894", "price_changes":[{"asset_id":"108233603819467706476318984012158651931658302669301887462181073562758483842092", "price":"0.166", "size":"24952", "side":"SELL", "hash":"7e17d656f724b3b68436dbe45ab59bed29d78dec", "best_bid":"0.163", "best_ask":"0.164"}, {"asset_id":"32270411694523539495262303868629477861017829722282576458031815333486368239544", "price":"0.834", "size":"24952", "side":"BUY", "hash":"d9ead58a161492fca5844bdc58b2895c3de273be", "best_bid":"0.836", "best_ask":"0.837"}], "timestamp":"1780178862212", "event_type":"price_change"}
{"market":"0x9b6fef249040fd17e9c107955b37ac2c3e923509b6b0ff01cc463a331ddeb894", "price_changes":[{"asset_id":"108233603819467706476318984012158651931658302669301887462181073562758483842092", "price":"0.166", "size":"25006.68", "side":"SELL", "hash":"dd86fff7ac197e5091307f88851941d1f4dbbb47", "best_bid":"0.163", "best_ask":"0.164"}, {"asset_id":"32270411694523539495262303868629477861017829722282576458031815333486368239544", "price":"0.834", "size":"25006.68", "side":"BUY", "hash":"0a0b6c145b65cef291d6bec7e86a9c30eaa90dbb", "best_bid":"0.836", "best_ask":"0.837"}], "timestamp":"1780178862316", "event_type":"price_change"}
{"market":"0x1595b4818eeb1ea1e0bec5de6f057218e557feee9b405a0e930d290384fa1d16", "price_changes":[{"asset_id":"45484070731786948288366703334552551439356529561722304542938873238430842810537", "price":"0.201", "size":"0", "side":"BUY", "hash":"e31f0ad07d451f0a759ecbe7560d6ae9f8bc9f0b", "best_bid":"0.948", "best_ask":"0.949"}, {"asset_id":"81739002353269632749850710185641576213562066971072676369728657545679630163887", "price":"0.799", "size":"0", "side":"SELL", "hash":"6117a971b880e1ee24a6e7601f3429b0a7e0d093", "best_bid":"0.051", "best_ask":"0.052"}], "timestamp":"1780178862377", "event_type":"price_change"}
{"id":"2397670", "question":"ITF Women Bol: Completed Match: Aurora Zantedeschi vs Valentina Ivanov", "market":"0x42f021c61f393195cb6054429e744c0c296998ba8056ab8cab7ef686184ee540", "slug":"itf-zantede-ivano-2026-05-31-completed-match", "description":"This market refers to the tennis match between Aurora Zantedeschi and Valentina Ivanov in the ITF Women Bol, originally scheduled for May 31, 2026 at 4:00AM ET. This market will resolve to \"Yes\" if all games and sets required to determine a match winner under governing body or event organizer rules are played to completion through normal play. Otherwise, if the match is not completed for any reason, it will resolve to \"No.\" If a forfeit of any kind occurs, including but not limited to a walkover or retirement, this market will resolve \"No.\" If the match is canceled (not played at all), ends in a tie, or is delayed beyond 7 days from the scheduled date without a winner determined, this market will resolve to \"No.\" The primary resolution source for this market is the official statistics of the event as recognized by the governing body or event organizers. However, if the governing body or event organizers have not published final match statistics within 2 hours after the event's conclusion, a consensus of credible reporting may be used instead.", "assets_ids":["23904731721916711568653588070933587036763598982627962794580924256973789403332", "114110950462083061429442997886760556894305202555896802661289635364217110396584"], "outcomes":["Yes", "No"], "event_message":{"id":"542625", "ticker":"itf-zantede-ivano-2026-05-31", "slug":"itf-zantede-ivano-2026-05-31", "title":"ITF Bol: Aurora Zantedeschi vs Valentina Ivanov", "description":"This market refers to the tennis match between Aurora Zantedeschi and Valentina Ivanov in the ITF Women Bol, originally scheduled for May 31, 2026 at 4:00AM ET.\n\nThis market will resolve to 'Aurora Zantedeschi' if Aurora Zantedeschi advances against Valentina Ivanov.\n\nThis market will resolve to 'Valentina Ivanov' if Valentina Ivanov advances against Aurora Zantedeschi.\n\nIf the match is canceled (not played at all), ends in a tie, or is delayed beyond 7 days from the scheduled date without a winner determined, this market will resolve to 50-50.\n\nIf the match begins but is not completed, and one player advances due to the opponent's retirement, default, or disqualification, this market will resolve to the player who advances.\n\nIf the match ends in a walkover (player withdraws before the start and the other advances automatically), this market will resolve to 50-50.\n\nThe primary resolution source will be official information from the International Tennis Federation (ITF). A consensus of credible reporting may also be used."}, "timestamp":"1780178862487", "event_type":"new_market", "tags":[], "condition_id":"0x42f021c61f393195cb6054429e744c0c296998ba8056ab8cab7ef686184ee540", "active":false, "clob_token_ids":["23904731721916711568653588070933587036763598982627962794580924256973789403332", "114110950462083061429442997886760556894305202555896802661289635364217110396584"], "sports_market_type":"tennis_completed_match", "line":"", "game_start_time":"2026-05-31 08:00:00+00", "order_price_min_tick_size":"0.01", "group_item_title":"Completed Match", "taker_base_fee":"1000", "fees_enabled":true, "fee_schedule":{"exponent":"1", "rate":"0.03", "taker_only":true, "rebate_rate":"0.25"}}
{"market":"0x1595b4818eeb1ea1e0bec5de6f057218e557feee9b405a0e930d290384fa1d16", "price_changes":[{"asset_id":"45484070731786948288366703334552551439356529561722304542938873238430842810537", "price":"0.202", "size":"6.68", "side":"BUY", "hash":"cb9b4c210427977079975858b068161212c37e0c", "best_bid":"0.948", "best_ask":"0.949"}, {"asset_id":"81739002353269632749850710185641576213562066971072676369728657545679630163887", "price":"0.798", "size":"6.68", "side":"SELL", "hash":"2c5d3b60d2458a81edbc5d6efb79550fabfe5582", "best_bid":"0.051", "best_ask":"0.052"}], "timestamp":"1780178862902", "event_type":"price_change"}
{"market":"0x375409bc5eeeff961e82b479caeccc20f33d15738e5bce1186d628aa3d9dfb1f", "price_changes":[{"asset_id":"77121637225348873006259930776623502125079210522997384841464684944292365296940", "price":"0.793", "size":"0", "side":"BUY", "hash":"d21181652e093540193a26607f6b3af017cc1ece", "best_bid":"0.887", "best_ask":"0.888"}, {"asset_id":"115556263888245616435851357148058235707004733438163639091106356867234218207169", "price":"0.207", "size":"0", "side":"SELL", "hash":"03b370ddd3656a469a135a8cbcc948fdc5eac450", "best_bid":"0.112", "best_ask":"0.113"}], "timestamp":"1780178863061", "event_type":"price_change"}
{"market":"0x4f3421fb2daf5cca7430ed8d8132463963081572d75434393a1808fdb8829fe8", "price_changes":[{"asset_id":"31940783580344558651011323787577288681658737625185216525249046282994042503801", "price":"0.804", "size":"0", "side":"BUY", "hash":"b85b7ef892af09033f884b4c596e29cac70121a2", "best_bid":"0.899", "best_ask":"0.9"}, {"asset_id":"45415751658241142530386585138386640503488308219341470020075667342738719018629", "price":"0.196", "size":"0", "side":"SELL", "hash":"60f5374d6df37a8d3fd7c49bd1c6db7fbcf2f0d9", "best_bid":"0.1", "best_ask":"0.101"}], "timestamp":"1780178863229", "event_type":"price_change"}
{"market":"0x1595b4818eeb1ea1e0bec5de6f057218e557feee9b405a0e930d290384fa1d16", "price_changes":[{"asset_id":"45484070731786948288366703334552551439356529561722304542938873238430842810537", "price":"0.851", "size":"0", "side":"BUY", "hash":"fdf040e87304c4efa5b4b4f0d255bc2e7655e7bb", "best_bid":"0.948", "best_ask":"0.949"}, {"asset_id":"81739002353269632749850710185641576213562066971072676369728657545679630163887", "price":"0.149", "size":"0", "side":"SELL", "hash":"9645a3cc3b6005afb726839ce94b14222d277424", "best_bid":"0.051", "best_ask":"0.052"}], "timestamp":"1780178863237", "event_type":"price_change"}
{"market":"0x30d55d8124ee1e12dabe89201badc45669b81dff69e4ce44d961f32878ec178a", "price_changes":[{"asset_id":"52986718774908357330412653486471347449818893503063830313445318937088822580057", "price":"0.815", "size":"100", "side":"BUY", "hash":"e4c175effd25ae6dbddc86a6feab874a63de6ac1", "best_bid":"0.91", "best_ask":"0.911"}, {"asset_id":"27576533317283401577758999384642760405921738493660383550832555714312627457443", "price":"0.185", "size":"100", "side":"SELL", "hash":"4dc99389e1bef2fc47f7f8532cf8c25c9d81b664", "best_bid":"0.089", "best_ask":"0.09"}], "timestamp":"1780178863229", "event_type":"price_change"}
{"market":"0x375409bc5eeeff961e82b479caeccc20f33d15738e5bce1186d628aa3d9dfb1f", "price_changes":[{"asset_id":"77121637225348873006259930776623502125079210522997384841464684944292365296940", "price":"0.813", "size":"130", "side":"BUY", "hash":"5e0cbd116a6cda1e10e3f0210df375b974c89493", "best_bid":"0.887", "best_ask":"0.888"}, {"asset_id":"115556263888245616435851357148058235707004733438163639091106356867234218207169", "price":"0.187", "size":"130", "side":"SELL", "hash":"09a3712cc12fa2b4818ee1f07e0cf01c7036f0de", "best_bid":"0.112", "best_ask":"0.113"}], "timestamp":"1780178863340", "event_type":"price_change"}
{"market":"0x7976b8dbacf9077eb1453a62bcefd6ab2df199acd28aad276ff0d920d6992892", "price_changes":[{"asset_id":"112680630004798425069810935278212000865453267506345451433803052322987302357330", "price":"0.741", "size":"0", "side":"BUY", "hash":"1e04a48a30fbdc961ac479f46c081b26cf1c3eb7", "best_bid":"0.832", "best_ask":"0.833"}, {"asset_id":"4394372887385518214471608448209527405727552777602031099972143344338178308080", "price":"0.259", "size":"0", "side":"SELL", "hash":"62ee89f4f2deb5b8fdddf3c4cc1f85d6625d9ed8", "best_bid":"0.167", "best_ask":"0.168"}], "timestamp":"1780178863380", "event_type":"price_change"}
{"market":"0x9b6fef249040fd17e9c107955b37ac2c3e923509b6b0ff01cc463a331ddeb894", "price_changes":[{"asset_id":"32270411694523539495262303868629477861017829722282576458031815333486368239544", "price":"0.744", "size":"0", "side":"BUY", "hash":"760b7ae80a231059d7076d0264fd450bc3cf79df", "best_bid":"0.836", "best_ask":"0.837"}, {"asset_id":"108233603819467706476318984012158651931658302669301887462181073562758483842092", "price":"0.256", "size":"0", "side":"SELL", "hash":"02619e3899a9343436dd89a99c54b17afe01e908", "best_bid":"0.163", "best_ask":"0.164"}], "timestamp":"1780178863376", "event_type":"price_change"}
{"market":"0x4f3421fb2daf5cca7430ed8d8132463963081572d75434393a1808fdb8829fe8", "price_changes":[{"asset_id":"31940783580344558651011323787577288681658737625185216525249046282994042503801", "price":"0.82", "size":"30", "side":"BUY", "hash":"d57274550de903f587c4e38c5d81ee7c3b058859", "best_bid":"0.899", "best_ask":"0.9"}, {"asset_id":"45415751658241142530386585138386640503488308219341470020075667342738719018629", "price":"0.18", "size":"30", "side":"SELL", "hash":"e785a47ee0f0f6fc531e54bef77b3e2c6912cf22", "best_bid":"0.1", "best_ask":"0.101"}], "timestamp":"1780178863461", "event_type":"price_change"}
{"market":"0x30d55d8124ee1e12dabe89201badc45669b81dff69e4ce44d961f32878ec178a", "price_changes":[{"asset_id":"52986718774908357330412653486471347449818893503063830313445318937088822580057", "price":"0.831", "size":"30", "side":"BUY", "hash":"e50da0278d7dd825e3c2f03313b15cf31709ff62", "best_bid":"0.91", "best_ask":"0.911"}, {"asset_id":"27576533317283401577758999384642760405921738493660383550832555714312627457443", "price":"0.169", "size":"30", "side":"SELL", "hash":"ece7c827cc2b90205903e7e50a7bfc1b0f3fef74", "best_bid":"0.089", "best_ask":"0.09"}], "timestamp":"1780178863655", "event_type":"price_change"}
{"market":"0x1595b4818eeb1ea1e0bec5de6f057218e557feee9b405a0e930d290384fa1d16", "price_changes":[{"asset_id":"45484070731786948288366703334552551439356529561722304542938873238430842810537", "price":"0.871", "size":"30", "side":"BUY", "hash":"37681c33cda029e239ffd2d3402df05f19bb6f5b", "best_bid":"0.948", "best_ask":"0.949"}, {"asset_id":"81739002353269632749850710185641576213562066971072676369728657545679630163887", "price":"0.129", "size":"30", "side":"SELL", "hash":"4248483672bcf9fd712a834cbabd83163d23bf05", "best_bid":"0.051", "best_ask":"0.052"}], "timestamp":"1780178863674", "event_type":"price_change"}
{"market":"0x9b6fef249040fd17e9c107955b37ac2c3e923509b6b0ff01cc463a331ddeb894", "price_changes":[{"asset_id":"32270411694523539495262303868629477861017829722282576458031815333486368239544", "price":"0.764", "size":"130", "side":"BUY", "hash":"3e994c9cd0ddb61ed3418dafa453a406ef9e7cba", "best_bid":"0.836", "best_ask":"0.837"}, {"asset_id":"108233603819467706476318984012158651931658302669301887462181073562758483842092", "price":"0.236", "size":"130", "side":"SELL", "hash":"d5d54bbdf5e86e48b194798254568af440c430d3", "best_bid":"0.163", "best_ask":"0.164"}], "timestamp":"1780178863703", "event_type":"price_change"}
{"market":"0x7976b8dbacf9077eb1453a62bcefd6ab2df199acd28aad276ff0d920d6992892", "price_changes":[{"asset_id":"112680630004798425069810935278212000865453267506345451433803052322987302357330", "price":"0.761", "size":"30", "side":"BUY", "hash":"029ad00ac10430526bf3e640280798e12b9cba68", "best_bid":"0.832", "best_ask":"0.833"}, {"asset_id":"4394372887385518214471608448209527405727552777602031099972143344338178308080", "price":"0.239", "size":"30", "side":"SELL", "hash":"02d9af51100f38dec0c6da21d76e0e1d3191d90f", "best_bid":"0.167", "best_ask":"0.168"}], "timestamp":"1780178863745", "event_type":"price_change"}
{"market":"0x30d55d8124ee1e12dabe89201badc45669b81dff69e4ce44d961f32878ec178a", "price_changes":[{"asset_id":"27576533317283401577758999384642760405921738493660383550832555714312627457443", "price":"0.092", "size":"78371.18", "side":"SELL", "hash":"d3aaee74cb9cc98f7ac2a960ea8dc65f257911df", "best_bid":"0.089", "best_ask":"0.09"}, {"asset_id":"52986718774908357330412653486471347449818893503063830313445318937088822580057", "price":"0.908", "size":"78371.18", "side":"BUY", "hash":"2607f3a4845366d347f7a32c163d34f03886ff14", "best_bid":"0.91", "best_ask":"0.911"}], "timestamp":"1780178864000", "event_type":"price_change"}
{"market":"0x7976b8dbacf9077eb1453a62bcefd6ab2df199acd28aad276ff0d920d6992892", "price_changes":[{"asset_id":"4394372887385518214471608448209527405727552777602031099972143344338178308080", "price":"0.17", "size":"27598.28", "side":"SELL", "hash":"5384a65c0a469f39376dd217f5e651254cccb4b8", "best_bid":"0.167", "best_ask":"0.168"}, {"asset_id":"112680630004798425069810935278212000865453267506345451433803052322987302357330", "price":"0.83", "size":"27598.28", "side":"BUY", "hash":"65d26ec949f16d33f44538430f174ab8d7537cf0", "best_bid":"0.832", "best_ask":"0.833"}], "timestamp":"1780178864000", "event_type":"price_change"}
{"market":"0x30d55d8124ee1e12dabe89201badc45669b81dff69e4ce44d961f32878ec178a", "price_changes":[{"asset_id":"27576533317283401577758999384642760405921738493660383550832555714312627457443", "price":"0.092", "size":"78431.18", "side":"SELL", "hash":"3ed42e14682d32e1c60ef169ec9fd89fdcdba06e", "best_bid":"0.089", "best_ask":"0.09"}, {"asset_id":"52986718774908357330412653486471347449818893503063830313445318937088822580057", "price":"0.908", "size":"78431.18", "side":"BUY", "hash":"f7dfb34b018ec5450c12883da3ad6814a6ccb718", "best_bid":"0.91", "best_ask":"0.911"}], "timestamp":"1780178864074", "event_type":"price_change"}
{"market":"0x7976b8dbacf9077eb1453a62bcefd6ab2df199acd28aad276ff0d920d6992892", "price_changes":[{"asset_id":"4394372887385518214471608448209527405727552777602031099972143344338178308080", "price":"0.17", "size":"27652.43", "side":"SELL", "hash":"3189515bd88f2c120201cea0489abef3ad880c92", "best_bid":"0.167", "best_ask":"0.168"}, {"asset_id":"112680630004798425069810935278212000865453267506345451433803052322987302357330", "price":"0.83", "size":"27652.43", "side":"BUY", "hash":"37fa918c40d1db5f79d805c1fa45ba6b44e19b92", "best_bid":"0.832", "best_ask":"0.833"}], "timestamp":"1780178864114", "event_type":"price_change"}
{"id":"2397733", "question":"Prostejov: Yosuke Watanuki vs Pedro Boscardin Dias", "market":"0xa10b517cefbe88eb7117fb65b1d75c45a4b7752fd99d65938ec6c55c8d83aca8", "slug":"atp-watanuk-dias-2026-06-01", "description":"This market refers to the tennis match between Yosuke Watanuki and Pedro Boscardin Dias in the Prostejov, originally scheduled for June 1, 2026 at 4:00AM ET.\n\nThis market will resolve to 'Yosuke Watanuki' if Yosuke Watanuki advances against Pedro Boscardin Dias.\n\nThis market will resolve to 'Pedro Boscardin Dias' if Pedro Boscardin Dias advances against Yosuke Watanuki.\n\nIf the match is canceled (not played at all), ends in a tie, or is delayed beyond 7 days from the scheduled date without a winner determined, this market will resolve to 50-50.\n\nIf the match begins but is not completed, and one player advances due to the opponent's retirement, default, or disqualification, this market will resolve to the player who advances.\n\nIf the match ends in a walkover (player withdraws before the start and the other advances automatically), this market will resolve to 50-50.\n\nThe primary resolution source will be official information from the ATP Tour. A consensus of credible reporting may also be used.", "assets_ids":["79247532003948004549009985008443329922681361167202491851343319483967804210956", "63230556085503033592206053819292495053992421953150343633156018798086327352044"], "outcomes":["Yosuke Watanuki", "Pedro Boscardin Dias"], "event_message":{"id":"542646", "ticker":"atp-watanuk-dias-2026-06-01", "slug":"atp-watanuk-dias-2026-06-01", "title":"Prostejov: Yosuke Watanuki vs Pedro Boscardin Dias", "description":"This market refers to the tennis match between Yosuke Watanuki and Pedro Boscardin Dias in the Prostejov, originally scheduled for June 1, 2026 at 4:00AM ET.\n\nThis market will resolve to 'Yosuke Watanuki' if Yosuke Watanuki advances against Pedro Boscardin Dias.\n\nThis market will resolve to 'Pedro Boscardin Dias' if Pedro Boscardin Dias advances against Yosuke Watanuki.\n\nIf the match is canceled (not played at all), ends in a tie, or is delayed beyond 7 days from the scheduled date without a winner determined, this market will resolve to 50-50.\n\nIf the match begins but is not completed, and one player advances due to the opponent's retirement, default, or disqualification, this market will resolve to the player who advances.\n\nIf the match ends in a walkover (player withdraws before the start and the other advances automatically), this market will resolve to 50-50.\n\nThe primary resolution source will be official information from the ATP Tour. A consensus of credible reporting may also be used."}, "timestamp":"1780178864736", "event_type":"new_market", "tags":[], "condition_id":"0xa10b517cefbe88eb7117fb65b1d75c45a4b7752fd99d65938ec6c55c8d83aca8", "active":false, "clob_token_ids":["79247532003948004549009985008443329922681361167202491851343319483967804210956", "63230556085503033592206053819292495053992421953150343633156018798086327352044"], "sports_market_type":"moneyline", "line":"", "game_start_time":"2026-06-01 08:00:00+00", "order_price_min_tick_size":"0.01", "group_item_title":"", "taker_base_fee":"1000", "fees_enabled":true, "fee_schedule":{"exponent":"1", "rate":"0.03", "taker_only":true, "rebate_rate":"0.25"}}
{"market":"0x0c4cd2055d6ea89354ffddc55d6dbcef9355748112ea952fc925f3db6a5c457f", "price_changes":[{"asset_id":"18812649149814341758733697580460697418474693998558159483117100240528657629879", "price":"0.088", "size":"16069.46", "side":"SELL", "hash":"ced05654f17b9d4cb0d570db8338959af31b3a7e", "best_bid":"0.085", "best_ask":"0.086"}, {"asset_id":"115428153746996892211798999366308897078723117634059783423375188043903703749062", "price":"0.912", "size":"16069.46", "side":"BUY", "hash":"70b8e360d9fb21764949fdf80e5a2024a5ee0c36", "best_bid":"0.914", "best_ask":"0.915"}], "timestamp":"1780178864895", "event_type":"price_change"}
{"market":"0x375409bc5eeeff961e82b479caeccc20f33d15738e5bce1186d628aa3d9dfb1f", "price_changes":[{"asset_id":"115556263888245616435851357148058235707004733438163639091106356867234218207169", "price":"0.115", "size":"12019.15", "side":"SELL", "hash":"ac854f171c3eabf65f78e78d383a63a7a75180b6", "best_bid":"0.112", "best_ask":"0.113"}, {"asset_id":"77121637225348873006259930776623502125079210522997384841464684944292365296940", "price":"0.885", "size":"12019.15", "side":"BUY", "hash":"099548ef2b66a94b9c0f7f56356f28197d134310", "best_bid":"0.887", "best_ask":"0.888"}], "timestamp":"1780178864949", "event_type":"price_change"}
{"market":"0x1595b4818eeb1ea1e0bec5de6f057218e557feee9b405a0e930d290384fa1d16", "price_changes":[{"asset_id":"81739002353269632749850710185641576213562066971072676369728657545679630163887", "price":"0.053", "size":"3311.26", "side":"SELL", "hash":"4118c2e870789e6ef7f8568f07164ba8c51fa69e", "best_bid":"0.051", "best_ask":"0.052"}, {"asset_id":"45484070731786948288366703334552551439356529561722304542938873238430842810537", "price":"0.947", "size":"3311.26", "side":"BUY", "hash":"94f9a7d52305658fa070977ec63f39557f171a16", "best_bid":"0.948", "best_ask":"0.949"}], "timestamp":"1780178864982", "event_type":"price_change"}
{"market":"0x0c4cd2055d6ea89354ffddc55d6dbcef9355748112ea952fc925f3db6a5c457f", "price_changes":[{"asset_id":"18812649149814341758733697580460697418474693998558159483117100240528657629879", "price":"0.088", "size":"16129.46", "side":"SELL", "hash":"3740552bafc3cc4109d9394e38e70cdefcae93c9", "best_bid":"0.085", "best_ask":"0.086"}, {"asset_id":"115428153746996892211798999366308897078723117634059783423375188043903703749062", "price":"0.912", "size":"16129.46", "side":"BUY", "hash":"2ce72609b1f95834afa95886c6493fa9db09def5", "best_bid":"0.914", "best_ask":"0.915"}], "timestamp":"1780178865312", "event_type":"price_change"}
{"market":"0x1595b4818eeb1ea1e0bec5de6f057218e557feee9b405a0e930d290384fa1d16", "price_changes":[{"asset_id":"81739002353269632749850710185641576213562066971072676369728657545679630163887", "price":"0.053", "size":"3371.26", "side":"SELL", "hash":"92e5d18257e871d8daf666276ecd2522754947ad", "best_bid":"0.051", "best_ask":"0.052"}, {"asset_id":"45484070731786948288366703334552551439356529561722304542938873238430842810537", "price":"0.947", "size":"3371.26", "side":"BUY", "hash":"53524393d1bb7e2ecc7f675d9a38d3e7f65120ea", "best_bid":"0.948", "best_ask":"0.949"}], "timestamp":"1780178865333", "event_type":"price_change"}
{"market":"0x375409bc5eeeff961e82b479caeccc20f33d15738e5bce1186d628aa3d9dfb1f", "price_changes":[{"asset_id":"115556263888245616435851357148058235707004733438163639091106356867234218207169", "price":"0.115", "size":"12079.15", "side":"SELL", "hash":"fda1b8534304ac03e6a673ff4354a81805798554", "best_bid":"0.112", "best_ask":"0.113"}, {"asset_id":"77121637225348873006259930776623502125079210522997384841464684944292365296940", "price":"0.885", "size":"12079.15", "side":"BUY", "hash":"e0d806e9fe6da49881988752b79a3a5219132e73", "best_bid":"0.887", "best_ask":"0.888"}], "timestamp":"1780178865373", "event_type":"price_change"}
{"id":"2397878", "question":"Spread: Texas Rangers (-2.5)", "market":"0x7196e11ba1a7f8c38e39fd7d603185cc6a3a2f6f47298222293d78a9502cf4cc", "slug":"mlb-kc-tex-2026-05-31-spread-home-2pt5", "description":"In the upcoming MLB game between the Kansas City Royals and Texas Rangers, scheduled for May 31 at 2:35 PM ET:\n\nThis market will resolve to \"Texas Rangers\" if the Texas Rangers win the game by 3 or more runs.\n\nOtherwise, this market will resolve to \"Kansas City Royals\". If the game ends in a tie, this market will resolve to \"Kansas City Royals\".\n\nIf the game is postponed, this market will remain open until the game has been completed. If the game is canceled entirely, with no make-up game, this market will resolve 50-50.\n\nTo know when a postponed game will be played, please check the home team's schedule on MLB.com for the listed team and look for the game described as a makeup game.\n\nThe primary resolution source for this market is the official final statistics of the event as recognized by the governing body or event organizers. However, if the governing body or event organizers have not published final match statistics within 24 hours after the event's conclusion, a consensus of credible reporting may be used instead.", "assets_ids":["25496160888925217689064168310869766581747983499778060749438274019293847244348", "86001499353429554141399111344011356534558552254938713576666212215834267296656"], "outcomes":["Texas Rangers", "Kansas City Royals"], "event_message":{"id":"523537", "ticker":"mlb-kc-tex-2026-05-31", "slug":"mlb-kc-tex-2026-05-31", "title":"Kansas City Royals vs. Texas Rangers", "description":"In the upcoming MLB game between the Kansas City Royals and Texas Rangers, scheduled for May 31 at 2:35PM ET:\n\nThis market will resolve to \"Kansas City Royals\" if the Kansas City Royals win the game.\n\nThis market will resolve to \"Texas Rangers\" if the Texas Rangers win the game.\n\nIf the game is postponed, this market will remain open until the game has been completed. If the game is canceled entirely, with no make-up game, or ends in a tie, this market will resolve 50-50.\n\nThe primary resolution source for this market is the official final statistics of the event as recognized by the governing body or event organizers. However, if the governing body or event organizers have not published final match statistics within 24 hours after the event's conclusion, a consensus of credible reporting may be used instead."}, "timestamp":"1780178865694", "event_type":"new_market", "tags":[], "condition_id":"0x7196e11ba1a7f8c38e39fd7d603185cc6a3a2f6f47298222293d78a9502cf4cc", "active":false, "clob_token_ids":["25496160888925217689064168310869766581747983499778060749438274019293847244348", "86001499353429554141399111344011356534558552254938713576666212215834267296656"], "sports_market_type":"spreads", "line":"-2.5", "game_start_time":"2026-05-31 18:35:00+00", "order_price_min_tick_size":"0.01", "group_item_title":"Spread -2.5", "taker_base_fee":"1000", "fees_enabled":true, "fee_schedule":{"exponent":"1", "rate":"0.03", "taker_only":true, "rebate_rate":"0.25"}}
{"market":"0x0c4cd2055d6ea89354ffddc55d6dbcef9355748112ea952fc925f3db6a5c457f", "price_changes":[{"asset_id":"18812649149814341758733697580460697418474693998558159483117100240528657629879", "price":"0.082", "size":"60985.56", "side":"BUY", "hash":"40d62ea923c2558bcddc5b393e1f161545301e81", "best_bid":"0.085", "best_ask":"0.086"}, {"asset_id":"115428153746996892211798999366308897078723117634059783423375188043903703749062", "price":"0.918", "size":"60985.56", "side":"SELL", "hash":"9be9df441e7de597e257d7730e0904c35ce2d533", "best_bid":"0.914", "best_ask":"0.915"}], "timestamp":"1780178865937", "event_type":"price_change"}
{"market":"0x0c4cd2055d6ea89354ffddc55d6dbcef9355748112ea952fc925f3db6a5c457f", "price_changes":[{"asset_id":"115428153746996892211798999366308897078723117634059783423375188043903703749062", "price":"0.912", "size":"15129.46", "side":"BUY", "hash":"1dcd79c79675876d0480883a49b2f22eb74eebf0", "best_bid":"0.914", "best_ask":"0.915"}, {"asset_id":"18812649149814341758733697580460697418474693998558159483117100240528657629879", "price":"0.088", "size":"15129.46", "side":"SELL", "hash":"95cb304a8831a8ddc4ede0ba357d1e8c592f33d9", "best_bid":"0.085", "best_ask":"0.086"}], "timestamp":"1780178865942", "event_type":"price_change"}
{"market":"0x0c4cd2055d6ea89354ffddc55d6dbcef9355748112ea952fc925f3db6a5c457f", "price_changes":[{"asset_id":"115428153746996892211798999366308897078723117634059783423375188043903703749062", "price":"0.913", "size":"59753.29", "side":"BUY", "hash":"1dcd79c79675876d0480883a49b2f22eb74eebf0", "best_bid":"0.914", "best_ask":"0.915"}, {"asset_id":"18812649149814341758733697580460697418474693998558159483117100240528657629879", "price":"0.087", "size":"59753.29", "side":"SELL", "hash":"95cb304a8831a8ddc4ede0ba357d1e8c592f33d9", "best_bid":"0.085", "best_ask":"0.086"}], "timestamp":"1780178865942", "event_type":"price_change"}
{"market":"0x0c4cd2055d6ea89354ffddc55d6dbcef9355748112ea952fc925f3db6a5c457f", "price_changes":[{"asset_id":"115428153746996892211798999366308897078723117634059783423375188043903703749062", "price":"0.75", "size":"3383.18", "side":"BUY", "hash":"3e62a549745acd6626283597088ea404a51d1d65", "best_bid":"0.914", "best_ask":"0.915"}, {"asset_id":"18812649149814341758733697580460697418474693998558159483117100240528657629879", "price":"0.25", "size":"3383.18", "side":"SELL", "hash":"b420292069754107b79846f799b982750a08e179", "best_bid":"0.085", "best_ask":"0.086"}], "timestamp":"1780178866040", "event_type":"price_change"}
{"market":"0x0c4cd2055d6ea89354ffddc55d6dbcef9355748112ea952fc925f3db6a5c457f", "price_changes":[{"asset_id":"115428153746996892211798999366308897078723117634059783423375188043903703749062", "price":"0.911", "size":"25024.11", "side":"BUY", "hash":"4aae5fe0edcb19eccba840f3e88a199a882ad1e6", "best_bid":"0.914", "best_ask":"0.915"}, {"asset_id":"18812649149814341758733697580460697418474693998558159483117100240528657629879", "price":"0.089", "size":"25024.11", "side":"SELL", "hash":"b25e3375d59497006d591b8cc2ba9c4916530a30", "best_bid":"0.085", "best_ask":"0.086"}], "timestamp":"1780178866054", "event_type":"price_change"}
{"market":"0x0c4cd2055d6ea89354ffddc55d6dbcef9355748112ea952fc925f3db6a5c457f", "price_changes":[{"asset_id":"115428153746996892211798999366308897078723117634059783423375188043903703749062", "price":"0.91", "size":"37372.79", "side":"BUY", "hash":"15ec34fa4a0bc1964f2773a02d6f532d7d4c0891", "best_bid":"0.914", "best_ask":"0.915"}, {"asset_id":"18812649149814341758733697580460697418474693998558159483117100240528657629879", "price":"0.09", "size":"37372.79", "side":"SELL", "hash":"983071575644337e1d0ceba1b3fe905cee9899d5", "best_bid":"0.085", "best_ask":"0.086"}], "timestamp":"1780178866058", "event_type":"price_change"}
{"market":"0x0c4cd2055d6ea89354ffddc55d6dbcef9355748112ea952fc925f3db6a5c457f", "price_changes":[{"asset_id":"18812649149814341758733697580460697418474693998558159483117100240528657629879", "price":"0.085", "size":"41577.24", "side":"BUY", "hash":"9e603d2e6d06eaa9b77fa82092f0b836853e87f3", "best_bid":"0.085", "best_ask":"0.086"}, {"asset_id":"115428153746996892211798999366308897078723117634059783423375188043903703749062", "price":"0.915", "size":"41577.24", "side":"SELL", "hash":"cd1c5c4addc59df8e33804f6b6580350a8756517", "best_bid":"0.914", "best_ask":"0.915"}], "timestamp":"1780178866061", "event_type":"price_change"}
{"market":"0x0c4cd2055d6ea89354ffddc55d6dbcef9355748112ea952fc925f3db6a5c457f", "price_changes":[{"asset_id":"115428153746996892211798999366308897078723117634059783423375188043903703749062", "price":"0.909", "size":"7564.56", "side":"BUY", "hash":"e4da5cad2fb41ee0c5b66b16d7482157d0d8ef2c", "best_bid":"0.914", "best_ask":"0.915"}, {"asset_id":"18812649149814341758733697580460697418474693998558159483117100240528657629879", "price":"0.091", "size":"7564.56", "side":"SELL", "hash":"9c53a37cfa7c5c81b1455615852a0a3e9c412527", "best_bid":"0.085", "best_ask":"0.086"}], "timestamp":"1780178866065", "event_type":"price_change"}
{"market":"0x7876851632c295043c66536150a304cb785abdf712ba8489d298c6e6926be106", "price_changes":[{"asset_id":"97239126062673310243763617236644392945530356142765650402171508075574679292913", "price":"0.011", "size":"1818525.69", "side":"SELL", "hash":"0906264dfd4191d06d53655de5a55c9efd991f1d", "best_bid":"0.01", "best_ask":"0.011"}, {"asset_id":"19291692040378529618917910599727571242305935029274321291612270922648172794670", "price":"0.989", "size":"1818525.69", "side":"BUY", "hash":"a2bf9cbf262a8f0b6e23c43524519fcb676643d9", "best_bid":"0.989", "best_ask":"0.99"}], "timestamp":"1780178867001", "event_type":"price_change"}
{"id":"2397828", "question":"Perugia: Completed Match: Pablo Llamas Ruiz vs Michele Ribecai", "market":"0xe364aec98b2dc5b0adbb848f58e0f2e36404512dd0afb9a3e5303ce8681882cb", "slug":"atp-ruiz-ribecai-2026-06-01-completed-match", "description":"This market refers to the tennis match between Pablo Llamas Ruiz and Michele Ribecai in the Perugia, originally scheduled for June 1, 2026 at 4:00AM ET. This market will resolve to \"Yes\" if all games and sets required to determine a match winner under governing body or event organizer rules are played to completion through normal play. Otherwise, if the match is not completed for any reason, it will resolve to \"No.\" If a forfeit of any kind occurs, including but not limited to a walkover or retirement, this market will resolve \"No.\" If the match is canceled (not played at all), ends in a tie, or is delayed beyond 7 days from the scheduled date without a winner determined, this market will resolve to \"No.\" The primary resolution source for this market is the official statistics of the event as recognized by the governing body or event organizers. However, if the governing body or event organizers have not published final match statistics within 2 hours after the event's conclusion, a consensus of credible reporting may be used instead.", "assets_ids":["102360597231164358022118409706675080164361537211443201204799522912791091877947", "77048476438025188286896188862739013294803272263946528721089249241673744121111"], "outcomes":["Yes", "No"], "event_message":{"id":"542679", "ticker":"atp-ruiz-ribecai-2026-06-01", "slug":"atp-ruiz-ribecai-2026-06-01", "title":"Perugia: Pablo Llamas Ruiz vs Michele Ribecai", "description":"This market refers to the tennis match between Pablo Llamas Ruiz and Michele Ribecai in the Perugia, originally scheduled for June 1, 2026 at 4:00AM ET.\n\nThis market will resolve to 'Pablo Llamas Ruiz' if Pablo Llamas Ruiz advances against Michele Ribecai.\n\nThis market will resolve to 'Michele Ribecai' if Michele Ribecai advances against Pablo Llamas Ruiz.\n\nIf the match is canceled (not played at all), ends in a tie, or is delayed beyond 7 days from the scheduled date without a winner determined, this market will resolve to 50-50.\n\nIf the match begins but is not completed, and one player advances due to the opponent's retirement, default, or disqualification, this market will resolve to the player who advances.\n\nIf the match ends in a walkover (player withdraws before the start and the other advances automatically), this market will resolve to 50-50.\n\nThe primary resolution source will be official information from the ATP Tour. A consensus of credible reporting may also be used."}, "timestamp":"1780178867621", "event_type":"new_market", "tags":[], "condition_id":"0xe364aec98b2dc5b0adbb848f58e0f2e36404512dd0afb9a3e5303ce8681882cb", "active":false, "clob_token_ids":["102360597231164358022118409706675080164361537211443201204799522912791091877947", "77048476438025188286896188862739013294803272263946528721089249241673744121111"], "sports_market_type":"tennis_completed_match", "line":"", "game_start_time":"2026-06-01 08:00:00+00", "order_price_min_tick_size":"0.01", "group_item_title":"Completed Match", "taker_base_fee":"1000", "fees_enabled":true, "fee_schedule":{"exponent":"1", "rate":"0.03", "taker_only":true, "rebate_rate":"0.25"}}
{"id":"2397689", "question":"ITF Monastir: Toufik Sahtali vs Yassine Dlimi", "market":"0x28da27ce208d58d7e64e013a0f0035e094acab867f7dce418b452b76301a5d61", "slug":"itf-sahtali-dlimi-2026-05-31", "description":"This market refers to the tennis match between Toufik Sahtali and Yassine Dlimi in the ITF Men Monastir, originally scheduled for May 31, 2026 at 5:00AM ET.\n\nThis market will resolve to 'Toufik Sahtali' if Toufik Sahtali advances against Yassine Dlimi.\n\nThis market will resolve to 'Yassine Dlimi' if Yassine Dlimi advances against Toufik Sahtali.\n\nIf the match is canceled (not played at all), ends in a tie, or is delayed beyond 7 days from the scheduled date without a winner determined, this market will resolve to 50-50.\n\nIf the match begins but is not completed, and one player advances due to the opponent's retirement, default, or disqualification, this market will resolve to the player who advances.\n\nIf the match ends in a walkover (player withdraws before the start and the other advances automatically), this market will resolve to 50-50.\n\nThe primary resolution source will be official information from the International Tennis Federation (ITF). A consensus of credible reporting may also be used.", "assets_ids":["22668382433901071107205023988287434015167204376379086331001757835379005142007", "80550753701097374466751609452863973873627292439902643904749290785391903603392"], "outcomes":["Toufik Sahtali", "Yassine Dlimi"], "event_message":{"id":"542632", "ticker":"itf-sahtali-dlimi-2026-05-31", "slug":"itf-sahtali-dlimi-2026-05-31", "title":"ITF Monastir: Toufik Sahtali vs Yassine Dlimi", "description":"This market refers to the tennis match between Toufik Sahtali and Yassine Dlimi in the ITF Men Monastir, originally scheduled for May 31, 2026 at 5:00AM ET.\n\nThis market will resolve to 'Toufik Sahtali' if Toufik Sahtali advances against Yassine Dlimi.\n\nThis market will resolve to 'Yassine Dlimi' if Yassine Dlimi advances against Toufik Sahtali.\n\nIf the match is canceled (not played at all), ends in a tie, or is delayed beyond 7 days from the scheduled date without a winner determined, this market will resolve to 50-50.\n\nIf the match begins but is not completed, and one player advances due to the opponent's retirement, default, or disqualification, this market will resolve to the player who advances.\n\nIf the match ends in a walkover (player withdraws before the start and the other advances automatically), this market will resolve to 50-50.\n\nThe primary resolution source will be official information from the International Tennis Federation (ITF). A consensus of credible reporting may also be used."}, "timestamp":"1780178869729", "event_type":"new_market", "tags":[], "condition_id":"0x28da27ce208d58d7e64e013a0f0035e094acab867f7dce418b452b76301a5d61", "active":false, "clob_token_ids":["22668382433901071107205023988287434015167204376379086331001757835379005142007", "80550753701097374466751609452863973873627292439902643904749290785391903603392"], "sports_market_type":"moneyline", "line":"", "game_start_time":"2026-05-31 09:00:00+00", "order_price_min_tick_size":"0.01", "group_item_title":"", "taker_base_fee":"1000", "fees_enabled":true, "fee_schedule":{"exponent":"1", "rate":"0.03", "taker_only":true, "rebate_rate":"0.25"}}
PONG
{"id":"2397864", "question":"Total Kills Over/Under 22.5 in Game 3?", "market":"0xa5bf7b9052c2896313c615e8f530f477249990bc7d1310d43636538cff242247", "slug":"lol-fly-sen-2026-05-30-game3-kill-over-22pt5", "description":"In the upcoming Lower bracket quarterfinal 1 match between FlyQuest and Sentinels in the LCS Playoffs, initially scheduled for May 30 at 4:00PM ET:\n\nThis market is about the total kills in Game 3.\n\nThis market will resolve to \"Over\" if the total kills in Game 3 is 23 or more. Otherwise, it will resolve to \"Under\".\n\nIf the match is canceled (not played at all) or is delayed beyond 7 days from the scheduled date, this market will resolve to 50-50.\n\nIf Game 3 is never played due to forfeit, disqualification, or walkover, this market will resolve to 50-50.\n\nIf Game 3 begins but is not completed, this market will resolve to 50-50.\n\nIf Game 3 is remade, resolution will be based on the total kills in the remade game only.\n\nThe resolution source for this market will be official information from https://gol.gg/esports/home. However, if https://gol.gg/esports/home has not published final results within 2 hours after the event’s conclusion, a consensus of credible reporting may be used instead including video evidence.\n", "assets_ids":["20113250895337027511708435383807064869539864824351412322426995280520113184595", "15739974080183724765200359593890631026868213834899004766659226530670501671638"], "outcomes":["Over", "Under"], "event_message":{"id":"519766", "ticker":"lol-fly-sen-2026-05-30", "slug":"lol-fly-sen-2026-05-30", "title":"LoL: FlyQuest vs Sentinels (BO5) - LCS Playoffs", "description":"This market refers to the LoL Lower bracket quarterfinal 1 match between FlyQuest and Sentinels in the LCS Playoffs, initially scheduled for May 30 at 4:00PM ET.\n\nThis market will resolve to \"FlyQuest\" if FlyQuest win the match against Sentinels.\n\nThis market will resolve to \"Sentinels\" if Sentinels win the match against FlyQuest.\n\nIf the match is canceled (not played at all), ends in a tie, or is delayed beyond 7 days from the scheduled date without a winner determined, this market will resolve to 50-50. \n\nIf the match begins but is not completed, and one team wins due to the opponent's forfeiture, disqualification, or walkover, this market will resolve to the team who wins. \n\nIf the match ends in a forfeit, disqualification, or walkover (team withdraws before the start and the other wins automatically), this market will resolve to 50-50. \n\nThe resolution source for this market will be official information from https://gol.gg/esports/home. However, if https://gol.gg/esports/home has not published final results within 2 hours after the event’s conclusion, a consensus of credible reporting may be used instead including video evidence.\n\nIn cases where a team’s listed name includes minor discrepancies from the resolution source, this market will resolve based on the underlying real-world match rather than exact name matching. Recognizable abbreviations, alternate or erroneous spellings, sponsor tags, affiliate or academy designations, regional identifiers, and minor formatting differences will be treated as referring to the same team, provided the intended team can be clearly and uniquely identified within the relevant competition. If a listed team name has no reasonable connection to any participating team, or if it matches or could reasonably refer to another team in the same competition such that the intended team cannot be unambiguously determined, this market will resolve 50-50."}, "timestamp":"1780178871584", "event_type":"new_market", "tags":[], "condition_id":"0xa5bf7b9052c2896313c615e8f530f477249990bc7d1310d43636538cff242247", "active":false, "clob_token_ids":["20113250895337027511708435383807064869539864824351412322426995280520113184595", "15739974080183724765200359593890631026868213834899004766659226530670501671638"], "sports_market_type":"kill_over_under_game", "line":"22.5", "game_start_time":"2026-05-30 20:00:00+00", "order_price_min_tick_size":"0.01", "group_item_title":"Total Kills Over/Under 22.5 in Game 3?", "taker_base_fee":"1000", "fees_enabled":true, "fee_schedule":{"exponent":"1", "rate":"0.03", "taker_only":true, "rebate_rate":"0.25"}}
{"market":"0x375409bc5eeeff961e82b479caeccc20f33d15738e5bce1186d628aa3d9dfb1f", "price_changes":[{"asset_id":"77121637225348873006259930776623502125079210522997384841464684944292365296940", "price":"0.807", "size":"1006.18", "side":"BUY", "hash":"3be722f6bfd5ecd11e079f0e7120e2a60fd08f04", "best_bid":"0.887", "best_ask":"0.888"}, {"asset_id":"115556263888245616435851357148058235707004733438163639091106356867234218207169", "price":"0.193", "size":"1006.18", "side":"SELL", "hash":"6264a2123f030d5010771e70a40595b6318cc8ff", "best_bid":"0.112", "best_ask":"0.113"}], "timestamp":"1780178872253", "event_type":"price_change"}
{"market":"0x7876851632c295043c66536150a304cb785abdf712ba8489d298c6e6926be106", "price_changes":[{"asset_id":"97239126062673310243763617236644392945530356142765650402171508075574679292913", "price":"0.011", "size":"1818565.69", "side":"SELL", "hash":"c16c0edc08595334027374fc7dfccdebc4fae7de", "best_bid":"0.01", "best_ask":"0.011"}, {"asset_id":"19291692040378529618917910599727571242305935029274321291612270922648172794670", "price":"0.989", "size":"1818565.69", "side":"BUY", "hash":"72918196f5f892efb87c9ee673296ec7b09508b2", "best_bid":"0.989", "best_ask":"0.99"}], "timestamp":"1780178872626", "event_type":"price_change"}
{"id":"2397802", "question":"Birmingham: James Duckworth vs Billy Harris", "market":"0x2498e6c657c1ae5cb94984e69f936aed59eafd285c9c4d6f5a5cf902dda819b3", "slug":"atp-duckwor-harris-2026-06-01", "description":"This market refers to the tennis match between James Duckworth and Billy Harris in the Birmingham, originally scheduled for June 1, 2026 at 5:30AM ET.\n\nThis market will resolve to 'James Duckworth' if James Duckworth advances against Billy Harris.\n\nThis market will resolve to 'Billy Harris' if Billy Harris advances against James Duckworth.\n\nIf the match is canceled (not played at all), ends in a tie, or is delayed beyond 7 days from the scheduled date without a winner determined, this market will resolve to 50-50.\n\nIf the match begins but is not completed, and one player advances due to the opponent's retirement, default, or disqualification, this market will resolve to the player who advances.\n\nIf the match ends in a walkover (player withdraws before the start and the other advances automatically), this market will resolve to 50-50.\n\nThe primary resolution source will be official information from the ATP Tour. A consensus of credible reporting may also be used.", "assets_ids":["39765680390689310068208529624870238504813792518926664271603038431112880457877", "106783999863613621712682562332088275147720953573480530060010283350896981071913"], "outcomes":["James Duckworth", "Billy Harris"], "event_message":{"id":"542666", "ticker":"atp-duckwor-harris-2026-06-01", "slug":"atp-duckwor-harris-2026-06-01", "title":"Birmingham: James Duckworth vs Billy Harris", "description":"This market refers to the tennis match between James Duckworth and Billy Harris in the Birmingham, originally scheduled for June 1, 2026 at 5:30AM ET.\n\nThis market will resolve to 'James Duckworth' if James Duckworth advances against Billy Harris.\n\nThis market will resolve to 'Billy Harris' if Billy Harris advances against James Duckworth.\n\nIf the match is canceled (not played at all), ends in a tie, or is delayed beyond 7 days from the scheduled date without a winner determined, this market will resolve to 50-50.\n\nIf the match begins but is not completed, and one player advances due to the opponent's retirement, default, or disqualification, this market will resolve to the player who advances.\n\nIf the match ends in a walkover (player withdraws before the start and the other advances automatically), this market will resolve to 50-50.\n\nThe primary resolution source will be official information from the ATP Tour. A consensus of credible reporting may also be used."}, "timestamp":"1780178873700", "event_type":"new_market", "tags":[], "condition_id":"0x2498e6c657c1ae5cb94984e69f936aed59eafd285c9c4d6f5a5cf902dda819b3", "active":false, "clob_token_ids":["39765680390689310068208529624870238504813792518926664271603038431112880457877", "106783999863613621712682562332088275147720953573480530060010283350896981071913"], "sports_market_type":"moneyline", "line":"", "game_start_time":"2026-06-01 09:30:00+00", "order_price_min_tick_size":"0.01", "group_item_title":"", "taker_base_fee":"1000", "fees_enabled":true, "fee_schedule":{"exponent":"1", "rate":"0.03", "taker_only":true, "rebate_rate":"0.25"}}
{"id":"2397633", "question":"Roland Garros WTA: Madison Keys vs Diana Shnaider", "market":"0x96b64425b06d5568006229caf73242fc0cf3f92b6bbfa1836ef0e42a571d6335", "slug":"wta-keys-shnaide-2026-06-01", "description":"This market refers to the tennis match between Madison Keys and Diana Shnaider in the Roland Garros WTA, originally scheduled for June 1, 2026 at 5:00AM ET.\n\nThis market will resolve to 'Madison Keys' if Madison Keys advances against Diana Shnaider.\n\nThis market will resolve to 'Diana Shnaider' if Diana Shnaider advances against Madison Keys.\n\nIf the match is canceled (not played at all), ends in a tie, or is delayed beyond 7 days from the scheduled date without a winner determined, this market will resolve to 50-50.\n\nIf the match begins but is not completed, and one player advances due to the opponent's retirement, default, or disqualification, this market will resolve to the player who advances.\n\nIf the match ends in a walkover (player withdraws before the start and the other advances automatically), this market will resolve to 50-50.\n\nThe primary resolution source will be official information from the WTA Tour. A consensus of credible reporting may also be used.", "assets_ids":["59289238992525751185198686717345587897929295894230894052618778816774311315920", "41310062743542072796764625542051995911101548464291716361017583688773606226891"], "outcomes":["Madison Keys", "Diana Shnaider"], "event_message":{"id":"542613", "ticker":"wta-keys-shnaide-2026-06-01", "slug":"wta-keys-shnaide-2026-06-01", "title":"Roland Garros WTA: Madison Keys vs Diana Shnaider", "description":"This market refers to the tennis match between Madison Keys and Diana Shnaider in the Roland Garros WTA, originally scheduled for June 1, 2026 at 5:00AM ET.\n\nThis market will resolve to 'Madison Keys' if Madison Keys advances against Diana Shnaider.\n\nThis market will resolve to 'Diana Shnaider' if Diana Shnaider advances against Madison Keys.\n\nIf the match is canceled (not played at all), ends in a tie, or is delayed beyond 7 days from the scheduled date without a winner determined, this market will resolve to 50-50.\n\nIf the match begins but is not completed, and one player advances due to the opponent's retirement, default, or disqualification, this market will resolve to the player who advances.\n\nIf the match ends in a walkover (player withdraws before the start and the other advances automatically), this market will resolve to 50-50.\n\nThe primary resolution source will be official information from the WTA Tour. A consensus of credible reporting may also be used."}, "timestamp":"1780178873962", "event_type":"new_market", "tags":[], "condition_id":"0x96b64425b06d5568006229caf73242fc0cf3f92b6bbfa1836ef0e42a571d6335", "active":false, "clob_token_ids":["59289238992525751185198686717345587897929295894230894052618778816774311315920", "41310062743542072796764625542051995911101548464291716361017583688773606226891"], "sports_market_type":"moneyline", "line":"", "game_start_time":"2026-06-01 09:00:00+00", "order_price_min_tick_size":"0.01", "group_item_title":"", "taker_base_fee":"1000", "fees_enabled":true, "fee_schedule":{"exponent":"1", "rate":"0.03", "taker_only":true, "rebate_rate":"0.25"}}
{"market":"0x0c4cd2055d6ea89354ffddc55d6dbcef9355748112ea952fc925f3db6a5c457f", "price_changes":[{"asset_id":"18812649149814341758733697580460697418474693998558159483117100240528657629879", "price":"0.088", "size":"15049.46", "side":"SELL", "hash":"0e2a016a47e104f12bd049a80c4ab009db822482", "best_bid":"0.085", "best_ask":"0.086"}, {"asset_id":"115428153746996892211798999366308897078723117634059783423375188043903703749062", "price":"0.912", "size":"15049.46", "side":"BUY", "hash":"491e800a439760f7a8fedde8e990ca60d7ec48ed", "best_bid":"0.914", "best_ask":"0.915"}], "timestamp":"1780178874142", "event_type":"price_change"}
{"market":"0x30d55d8124ee1e12dabe89201badc45669b81dff69e4ce44d961f32878ec178a", "price_changes":[{"asset_id":"27576533317283401577758999384642760405921738493660383550832555714312627457443", "price":"0.092", "size":"78375.52", "side":"SELL", "hash":"2650fd69d60e9a4c4ef342060f9f80ebbe983247", "best_bid":"0.089", "best_ask":"0.09"}, {"asset_id":"52986718774908357330412653486471347449818893503063830313445318937088822580057", "price":"0.908", "size":"78375.52", "side":"BUY", "hash":"8f212a06226507fb422cff7bcb4ae9fe4e4b5406", "best_bid":"0.91", "best_ask":"0.911"}], "timestamp":"1780178874176", "event_type":"price_change"}
{"market":"0x7976b8dbacf9077eb1453a62bcefd6ab2df199acd28aad276ff0d920d6992892", "price_changes":[{"asset_id":"4394372887385518214471608448209527405727552777602031099972143344338178308080", "price":"0.17", "size":"27626.88", "side":"SELL", "hash":"b62634eab13c419475146298070b7432b4c5571c", "best_bid":"0.167", "best_ask":"0.168"}, {"asset_id":"112680630004798425069810935278212000865453267506345451433803052322987302357330", "price":"0.83", "size":"27626.88", "side":"BUY", "hash":"608418ee30635340235d3588fe74309fab15bec4", "best_bid":"0.832", "best_ask":"0.833"}], "timestamp":"1780178874176", "event_type":"price_change"}
{"market":"0x1595b4818eeb1ea1e0bec5de6f057218e557feee9b405a0e930d290384fa1d16", "price_changes":[{"asset_id":"81739002353269632749850710185641576213562066971072676369728657545679630163887", "price":"0.053", "size":"3291.26", "side":"SELL", "hash":"c34a3fc360f5202c1b307249ff31ee55cebf6b3a", "best_bid":"0.051", "best_ask":"0.052"}, {"asset_id":"45484070731786948288366703334552551439356529561722304542938873238430842810537", "price":"0.947", "size":"3291.26", "side":"BUY", "hash":"7c42cdc4b612570857e3c4a5f935593bce532823", "best_bid":"0.948", "best_ask":"0.949"}], "timestamp":"1780178874177", "event_type":"price_change"}
{"market":"0x0c4cd2055d6ea89354ffddc55d6dbcef9355748112ea952fc925f3db6a5c457f", "price_changes":[{"asset_id":"18812649149814341758733697580460697418474693998558159483117100240528657629879", "price":"0.088", "size":"15129.46", "side":"SELL", "hash":"4fb2cc67984dbd1d8336b660ad4e528ab56dd5ee", "best_bid":"0.085", "best_ask":"0.086"}, {"asset_id":"115428153746996892211798999366308897078723117634059783423375188043903703749062", "price":"0.912", "size":"15129.46", "side":"BUY", "hash":"52bc472ae3082609c4c34b210494977b0f5bc36b", "best_bid":"0.914", "best_ask":"0.915"}], "timestamp":"1780178874303", "event_type":"price_change"}
{"market":"0x30d55d8124ee1e12dabe89201badc45669b81dff69e4ce44d961f32878ec178a", "price_changes":[{"asset_id":"27576533317283401577758999384642760405921738493660383550832555714312627457443", "price":"0.092", "size":"78431.18", "side":"SELL", "hash":"91ba7ca599491481bbd4acbc97a6d8c4edc4f73c", "best_bid":"0.089", "best_ask":"0.09"}, {"asset_id":"52986718774908357330412653486471347449818893503063830313445318937088822580057", "price":"0.908", "size":"78431.18", "side":"BUY", "hash":"83b3e8d8fe8dc5f069b4f45fb12d715ff21de87b", "best_bid":"0.91", "best_ask":"0.911"}], "timestamp":"1780178874304", "event_type":"price_change"}
{"market":"0x1595b4818eeb1ea1e0bec5de6f057218e557feee9b405a0e930d290384fa1d16", "price_changes":[{"asset_id":"81739002353269632749850710185641576213562066971072676369728657545679630163887", "price":"0.053", "size":"3371.26", "side":"SELL", "hash":"4a26767acdd3a377f5dc148c0e267f0993a5b399", "best_bid":"0.051", "best_ask":"0.052"}, {"asset_id":"45484070731786948288366703334552551439356529561722304542938873238430842810537", "price":"0.947", "size":"3371.26", "side":"BUY", "hash":"11c6b7f70b7d19e936eb6ee20f5b6c43ea7feab0", "best_bid":"0.948", "best_ask":"0.949"}], "timestamp":"1780178874313", "event_type":"price_change"}
{"market":"0x7976b8dbacf9077eb1453a62bcefd6ab2df199acd28aad276ff0d920d6992892", "price_changes":[{"asset_id":"4394372887385518214471608448209527405727552777602031099972143344338178308080", "price":"0.17", "size":"27652.43", "side":"SELL", "hash":"24f9a1c2893d00baa2227df77418d484f9c3477b", "best_bid":"0.167", "best_ask":"0.168"}, {"asset_id":"112680630004798425069810935278212000865453267506345451433803052322987302357330", "price":"0.83", "size":"27652.43", "side":"BUY", "hash":"acd47694d658bb4055f306e82ef6bbfda833d859", "best_bid":"0.832", "best_ask":"0.833"}], "timestamp":"1780178874329", "event_type":"price_change"}
{"market":"0x7876851632c295043c66536150a304cb785abdf712ba8489d298c6e6926be106", "price_changes":[{"asset_id":"97239126062673310243763617236644392945530356142765650402171508075574679292913", "price":"0.011", "size":"1818503.69", "side":"SELL", "hash":"523ac8865b165e75275dd56ef4ed7e4c223c0b70", "best_bid":"0.01", "best_ask":"0.011"}, {"asset_id":"19291692040378529618917910599727571242305935029274321291612270922648172794670", "price":"0.989", "size":"1818503.69", "side":"BUY", "hash":"0868a202a7745ec919f475ee7598515125e0cb73", "best_bid":"0.989", "best_ask":"0.99"}], "timestamp":"1780178874666", "event_type":"price_change"}
{"market":"0x7976b8dbacf9077eb1453a62bcefd6ab2df199acd28aad276ff0d920d6992892", "price_changes":[{"asset_id":"4394372887385518214471608448209527405727552777602031099972143344338178308080", "price":"0.184", "size":"0", "side":"SELL", "hash":"14316e8b7fe75752292759baf3b06dd421f1c1f4", "best_bid":"0.167", "best_ask":"0.168"}, {"asset_id":"112680630004798425069810935278212000865453267506345451433803052322987302357330", "price":"0.816", "size":"0", "side":"BUY", "hash":"773f96fec33d01d67b504817c94b32d39df7e5d1", "best_bid":"0.832", "best_ask":"0.833"}], "timestamp":"1780178874986", "event_type":"price_change"}
{"market":"0x7976b8dbacf9077eb1453a62bcefd6ab2df199acd28aad276ff0d920d6992892", "price_changes":[{"asset_id":"4394372887385518214471608448209527405727552777602031099972143344338178308080", "price":"0.184", "size":"49.77", "side":"SELL", "hash":"b5e1396cb880350b12fb5d042a40d57843da8556", "best_bid":"0.167", "best_ask":"0.168"}, {"asset_id":"112680630004798425069810935278212000865453267506345451433803052322987302357330", "price":"0.816", "size":"49.77", "side":"BUY", "hash":"91c302abe15391da1578bacfb2bda6fbe077b3b7", "best_bid":"0.832", "best_ask":"0.833"}], "timestamp":"1780178875151", "event_type":"price_change"}
{"market":"0x7876851632c295043c66536150a304cb785abdf712ba8489d298c6e6926be106", "price_changes":[{"asset_id":"97239126062673310243763617236644392945530356142765650402171508075574679292913", "price":"0.011", "size":"1818565.69", "side":"SELL", "hash":"94f31a39012c03bcfd54377d24ae0258edcc4451", "best_bid":"0.01", "best_ask":"0.011"}, {"asset_id":"19291692040378529618917910599727571242305935029274321291612270922648172794670", "price":"0.989", "size":"1818565.69", "side":"BUY", "hash":"8676d21d3b2dc47027071bcecebf1b59767faadb", "best_bid":"0.989", "best_ask":"0.99"}], "timestamp":"1780178875453", "event_type":"price_change"}
{"id":"2397661", "question":"ITF Bol: Noa Vukadin vs Duje Ajdukovic", "market":"0x3bbe298980f8aff974bdeeb5ab007aa5846f59b1dbb26dc8149d61f12e25442a", "slug":"itf-vukadin-ajdukov-2026-05-31", "description":"This market refers to the tennis match between Noa Vukadin and Duje Ajdukovic in the ITF Men Bol, originally scheduled for May 31, 2026 at 4:00AM ET.\n\nThis market will resolve to 'Noa Vukadin' if Noa Vukadin advances against Duje Ajdukovic.\n\nThis market will resolve to 'Duje Ajdukovic' if Duje Ajdukovic advances against Noa Vukadin.\n\nIf the match is canceled (not played at all), ends in a tie, or is delayed beyond 7 days from the scheduled date without a winner determined, this market will resolve to 50-50.\n\nIf the match begins but is not completed, and one player advances due to the opponent's retirement, default, or disqualification, this market will resolve to the player who advances.\n\nIf the match ends in a walkover (player withdraws before the start and the other advances automatically), this market will resolve to 50-50.\n\nThe primary resolution source will be official information from the International Tennis Federation (ITF). A consensus of credible reporting may also be used.", "assets_ids":["113570090986623497420400236593345799045374173800552665422674423038389880356771", "77059128472987014718855128389211563492425840180695540461669415324138927592417"], "outcomes":["Noa Vukadin", "Duje Ajdukovic"], "event_message":{"id":"542621", "ticker":"itf-vukadin-ajdukov-2026-05-31", "slug":"itf-vukadin-ajdukov-2026-05-31", "title":"ITF Bol: Noa Vukadin vs Duje Ajdukovic", "description":"This market refers to the tennis match between Noa Vukadin and Duje Ajdukovic in the ITF Men Bol, originally scheduled for May 31, 2026 at 4:00AM ET.\n\nThis market will resolve to 'Noa Vukadin' if Noa Vukadin advances against Duje Ajdukovic.\n\nThis market will resolve to 'Duje Ajdukovic' if Duje Ajdukovic advances against Noa Vukadin.\n\nIf the match is canceled (not played at all), ends in a tie, or is delayed beyond 7 days from the scheduled date without a winner determined, this market will resolve to 50-50.\n\nIf the match begins but is not completed, and one player advances due to the opponent's retirement, default, or disqualification, this market will resolve to the player who advances.\n\nIf the match ends in a walkover (player withdraws before the start and the other advances automatically), this market will resolve to 50-50.\n\nThe primary resolution source will be official information from the International Tennis Federation (ITF). A consensus of credible reporting may also be used."}, "timestamp":"1780178876511", "event_type":"new_market", "tags":[], "condition_id":"0x3bbe298980f8aff974bdeeb5ab007aa5846f59b1dbb26dc8149d61f12e25442a", "active":false, "clob_token_ids":["113570090986623497420400236593345799045374173800552665422674423038389880356771", "77059128472987014718855128389211563492425840180695540461669415324138927592417"], "sports_market_type":"moneyline", "line":"", "game_start_time":"2026-05-31 08:00:00+00", "order_price_min_tick_size":"0.01", "group_item_title":"", "taker_base_fee":"1000", "fees_enabled":true, "fee_schedule":{"exponent":"1", "rate":"0.03", "taker_only":true, "rebate_rate":"0.25"}}
{"market":"0x375409bc5eeeff961e82b479caeccc20f33d15738e5bce1186d628aa3d9dfb1f", "price_changes":[{"asset_id":"115556263888245616435851357148058235707004733438163639091106356867234218207169", "price":"0.115", "size":"11999.15", "side":"SELL", "hash":"047276efea69c29842e1dbe11914c5bc974af5d3", "best_bid":"0.112", "best_ask":"0.113"}, {"asset_id":"77121637225348873006259930776623502125079210522997384841464684944292365296940", "price":"0.885", "size":"11999.15", "side":"BUY", "hash":"e5afc253ec81a6e0167a3700d443216a592cb968", "best_bid":"0.887", "best_ask":"0.888"}], "timestamp":"1780178876673", "event_type":"price_change"}
{"market":"0x9b6fef249040fd17e9c107955b37ac2c3e923509b6b0ff01cc463a331ddeb894", "price_changes":[{"asset_id":"108233603819467706476318984012158651931658302669301887462181073562758483842092", "price":"0.166", "size":"24926.68", "side":"SELL", "hash":"60a0913a152fc64df27355b3dbb83ccd301e897e", "best_bid":"0.163", "best_ask":"0.164"}, {"asset_id":"32270411694523539495262303868629477861017829722282576458031815333486368239544", "price":"0.834", "size":"24926.68", "side":"BUY", "hash":"2f66d7733b7389027754e2def28730d7463f8f18", "best_bid":"0.836", "best_ask":"0.837"}], "timestamp":"1780178876725", "event_type":"price_change"}
{"market":"0x375409bc5eeeff961e82b479caeccc20f33d15738e5bce1186d628aa3d9dfb1f", "price_changes":[{"asset_id":"115556263888245616435851357148058235707004733438163639091106356867234218207169", "price":"0.115", "size":"12079.15", "side":"SELL", "hash":"d87899fa204e40c061dad5b416aaf8fb7093f20d", "best_bid":"0.112", "best_ask":"0.113"}, {"asset_id":"77121637225348873006259930776623502125079210522997384841464684944292365296940", "price":"0.885", "size":"12079.15", "side":"BUY", "hash":"17cbfea8ba2336f0116e7003897dee0178a2414a", "best_bid":"0.887", "best_ask":"0.888"}], "timestamp":"1780178876840", "event_type":"price_change"}
{"market":"0x9b6fef249040fd17e9c107955b37ac2c3e923509b6b0ff01cc463a331ddeb894", "price_changes":[{"asset_id":"108233603819467706476318984012158651931658302669301887462181073562758483842092", "price":"0.166", "size":"25006.68", "side":"SELL", "hash":"6b28ff87d06b666cab8b240a60a76cdcdfa03ba8", "best_bid":"0.163", "best_ask":"0.164"}, {"asset_id":"32270411694523539495262303868629477861017829722282576458031815333486368239544", "price":"0.834", "size":"25006.68", "side":"BUY", "hash":"572bc9716ef68fa1f8569fd1fe5685b8f24fcb1a", "best_bid":"0.836", "best_ask":"0.837"}], "timestamp":"1780178876897", "event_type":"price_change"}
{"market":"0x4f3421fb2daf5cca7430ed8d8132463963081572d75434393a1808fdb8829fe8", "price_changes":[{"asset_id":"45415751658241142530386585138386640503488308219341470020075667342738719018629", "price":"0.103", "size":"18202.51", "side":"SELL", "hash":"c419aa146a34513147eeed36bbf24272e5bc692a", "best_bid":"0.1", "best_ask":"0.101"}, {"asset_id":"31940783580344558651011323787577288681658737625185216525249046282994042503801", "price":"0.897", "size":"18202.51", "side":"BUY", "hash":"163a5e6b3cc35581c39d73b702c1d2135699e5a4", "best_bid":"0.899", "best_ask":"0.9"}], "timestamp":"1780178877008", "event_type":"price_change"}
{"market":"0x4f3421fb2daf5cca7430ed8d8132463963081572d75434393a1808fdb8829fe8", "price_changes":[{"asset_id":"45415751658241142530386585138386640503488308219341470020075667342738719018629", "price":"0.103", "size":"18263.31", "side":"SELL", "hash":"2eb7d86aaa99167570131e4fe5e73dec647a7e79", "best_bid":"0.1", "best_ask":"0.101"}, {"asset_id":"31940783580344558651011323787577288681658737625185216525249046282994042503801", "price":"0.897", "size":"18263.31", "side":"BUY", "hash":"537fec75577b3ef35446d2252390ae7f04e29105", "best_bid":"0.899", "best_ask":"0.9"}], "timestamp":"1780178877184", "event_type":"price_change"}
{"id":"2397879", "question":"Bitcoin Up or Down - May 31, 6:00PM-6:05PM ET", "market":"0x08eed769b38c6712fce893cbe4904bcecc38d1df9c454c25c7170486c87edda3", "slug":"btc-updown-5m-1780264800", "description":"This market will resolve to \"Up\" if the Bitcoin price at the end of the time range specified in the title is greater than or equal to the price at the beginning of that range. Otherwise, it will resolve to \"Down\".\nThe resolution source for this market is information from Chainlink, specifically the BTC/USD data stream available at https://data.chain.link/streams/btc-usd.\nPlease note that this market is about the price according to Chainlink data stream BTC/USD, not according to other sources or spot markets.", "assets_ids":["59482798079136810935713304231511964007746194641640223887924551970845230181096", "74812004195438284927816065673663430462263806065682274332647215183869897766822"], "outcomes":["Up", "Down"], "event_message":{"id":"542701", "ticker":"btc-updown-5m-1780264800", "slug":"btc-updown-5m-1780264800", "title":"Bitcoin Up or Down - May 31, 6:00PM-6:05PM ET", "description":"This market will resolve to \"Up\" if the Bitcoin price at the end of the time range specified in the title is greater than or equal to the price at the beginning of that range. Otherwise, it will resolve to \"Down\".\nThe resolution source for this market is information from Chainlink, specifically the BTC/USD data stream available at https://data.chain.link/streams/btc-usd.\nPlease note that this market is about the price according to Chainlink data stream BTC/USD, not according to other sources or spot markets."}, "timestamp":"1780178878361", "event_type":"new_market", "tags":[], "condition_id":"0x08eed769b38c6712fce893cbe4904bcecc38d1df9c454c25c7170486c87edda3", "active":false, "clob_token_ids":["59482798079136810935713304231511964007746194641640223887924551970845230181096", "74812004195438284927816065673663430462263806065682274332647215183869897766822"], "sports_market_type":"", "line":"", "game_start_time":"", "order_price_min_tick_size":"0.01", "group_item_title":"", "taker_base_fee":"1000", "fees_enabled":true, "fee_schedule":{"exponent":"1", "rate":"0.07", "taker_only":true, "rebate_rate":"0.2"}}
{"id":"2397686", "question":"UFC Fight Night: Kevin Borjas vs. Andre Lima (Flyweight, Main Card)", "market":"0xc11d3a1a9a9b9ebca7a926ac6a97acd3aae4b4d2e9e9306b88735ebd74f8dcbf", "slug":"ufc-kev15-and26-2026-06-20", "description":"This market will resolve to \"Kevin Borjas\" if Kevin Borjas is officially declared the winner of the fight against Andre Lima at UFC Fight Night: Kape vs. Horiguchi, scheduled for June 20, 2026.\n\nIt will resolve to \"Andre Lima\" if Andre Lima is officially declared the winner.\n\nIf the fight is declared a draw or technical draw, ruled a No Contest, not scored, canceled, or postponed beyond July 4, 2026, this market will resolve \"50-50.\"\n\nThe resolution source for this market will be official information from the UFC.", "assets_ids":["82697789498338550905644976603871525223368783641204499530047643510555849404620", "45151685048404425822903873724502495731614009402273112171591273545263998491154"], "outcomes":["Kevin Borjas", "Andre Lima"], "event_message":{"id":"542631", "ticker":"ufc-kev15-and26-2026-06-20", "slug":"ufc-kev15-and26-2026-06-20", "title":"UFC Fight Night: Kevin Borjas vs. Andre Lima (Flyweight, Main Card)", "description":"This market will resolve to \"Kevin Borjas\" if Kevin Borjas is officially declared the winner of the fight against Andre Lima at UFC Fight Night: Kape vs. Horiguchi, scheduled for June 20, 2026.\n\nIt will resolve to \"Andre Lima\" if Andre Lima is officially declared the winner.\n\nIf the fight is declared a draw or technical draw, ruled a No Contest, not scored, canceled, or postponed beyond July 4, 2026, this market will resolve \"50-50.\"\n\nThe resolution source for this market will be official information from the UFC."}, "timestamp":"1780178879359", "event_type":"new_market", "tags":[], "condition_id":"0xc11d3a1a9a9b9ebca7a926ac6a97acd3aae4b4d2e9e9306b88735ebd74f8dcbf", "active":false, "clob_token_ids":["82697789498338550905644976603871525223368783641204499530047643510555849404620", "45151685048404425822903873724502495731614009402273112171591273545263998491154"], "sports_market_type":"moneyline", "line":"", "game_start_time":"2026-06-20 17:00:00+00", "order_price_min_tick_size":"0.01", "group_item_title":"Kevin Borjas vs. Andre Lima", "taker_base_fee":"1000", "fees_enabled":true, "fee_schedule":{"exponent":"1", "rate":"0.03", "taker_only":true, "rebate_rate":"0.25"}}
{"market":"0x1595b4818eeb1ea1e0bec5de6f057218e557feee9b405a0e930d290384fa1d16", "price_changes":[{"asset_id":"81739002353269632749850710185641576213562066971072676369728657545679630163887", "price":"0.052", "size":"346089.69", "side":"SELL", "hash":"bba8aad03ae67b64636359f953d1ba48c6bdef3a", "best_bid":"0.051", "best_ask":"0.052"}, {"asset_id":"45484070731786948288366703334552551439356529561722304542938873238430842810537", "price":"0.948", "size":"346089.69", "side":"BUY", "hash":"bd25dc9e8fafe3ed3a7c50228d6fe63eca28f1e7", "best_bid":"0.948", "best_ask":"0.949"}], "timestamp":"1780178880376", "event_type":"price_change"}
PONG
{"market":"0x1595b4818eeb1ea1e0bec5de6f057218e557feee9b405a0e930d290384fa1d16", "price_changes":[{"asset_id":"81739002353269632749850710185641576213562066971072676369728657545679630163887", "price":"0.052", "size":"346131.69", "side":"SELL", "hash":"fb9f583184c4790d55d21d7106c3004e8c5338a9", "best_bid":"0.051", "best_ask":"0.052"}, {"asset_id":"45484070731786948288366703334552551439356529561722304542938873238430842810537", "price":"0.948", "size":"346131.69", "side":"BUY", "hash":"d0cda5ccc7a1557b1196ba4b04364f4cd80f4a30", "best_bid":"0.948", "best_ask":"0.949"}], "timestamp":"1780178881930", "event_type":"price_change"}
{"id":"2397743", "question":"Fight to Go the Distance?", "market":"0x97032b15fe3593aa1e74b541293204bc59859263d978afbc0409445cfc66ee4e", "slug":"ufc-all2-mit2-2026-06-20-go-the-distance", "description":"This market will resolve to \"Yes\" if the fight between Allan Nascimento and Mitch Raposo at UFC Fight Night: Kape vs. Horiguchi, scheduled for June 20, 2026, goes the full scheduled number of rounds and the result is determined by the judges' scorecards. Otherwise, it will resolve to \"No.\"\n\nDraws decided by the judges' scorecards after all scheduled rounds are completed will resolve \"Yes.\" Technical decisions or technical draws declared before all rounds are completed will resolve \"No.\"\n\nIf the bout is ruled a No Contest, not scored, canceled, or postponed beyond July 4, 2026, this market will resolve \"50-50.\"\n\nThe resolution source for this market will be official information from the UFC.", "assets_ids":["55537968937031442674644454795649432059842484504825681465313969342936992135780", "32632911262318270849977313749466162578825386087143327004431823055195463974800"], "outcomes":["Yes", "No"], "event_message":{"id":"542649", "ticker":"ufc-all2-mit2-2026-06-20", "slug":"ufc-all2-mit2-2026-06-20", "title":"UFC Fight Night: Allan Nascimento vs. Mitch Raposo (Flyweight, Prelims)", "description":"This market will resolve to \"Allan Nascimento\" if Allan Nascimento is officially declared the winner of the fight against Mitch Raposo at UFC Fight Night: Kape vs. Horiguchi, scheduled for June 20, 2026.\n\nIt will resolve to \"Mitch Raposo\" if Mitch Raposo is officially declared the winner.\n\nIf the fight is declared a draw or technical draw, ruled a No Contest, not scored, canceled, or postponed beyond July 4, 2026, this market will resolve \"50-50.\"\n\nThe resolution source for this market will be official information from the UFC."}, "timestamp":"1780178881973", "event_type":"new_market", "tags":[], "condition_id":"0x97032b15fe3593aa1e74b541293204bc59859263d978afbc0409445cfc66ee4e", "active":false, "clob_token_ids":["55537968937031442674644454795649432059842484504825681465313969342936992135780", "32632911262318270849977313749466162578825386087143327004431823055195463974800"], "sports_market_type":"ufc_go_the_distance", "line":"", "game_start_time":"2026-06-20 17:00:00+00", "order_price_min_tick_size":"0.01", "group_item_title":"Fight to Go the Distance?", "taker_base_fee":"1000", "fees_enabled":true, "fee_schedule":{"exponent":"1", "rate":"0.03", "taker_only":true, "rebate_rate":"0.25"}}
{"market":"0x4f3421fb2daf5cca7430ed8d8132463963081572d75434393a1808fdb8829fe8", "asset_id":"31940783580344558651011323787577288681658737625185216525249046282994042503801", "best_bid":"0.899", "best_ask":"0.9", "spread":"0.001", "timestamp":"1780178885459", "event_type":"best_bid_ask"}
{"market":"0x4f3421fb2daf5cca7430ed8d8132463963081572d75434393a1808fdb8829fe8", "price_changes":[{"asset_id":"45415751658241142530386585138386640503488308219341470020075667342738719018629", "price":"0.101", "size":"66403.3", "side":"SELL", "hash":"e2add37a72b37ebb8d45109884b8a86e89ee9ca8", "best_bid":"0.1", "best_ask":"0.101"}, {"asset_id":"31940783580344558651011323787577288681658737625185216525249046282994042503801", "price":"0.899", "size":"66403.3", "side":"BUY", "hash":"838f867019b7e0ed97f7cde82213463c8ce5b543", "best_bid":"0.899", "best_ask":"0.9"}], "timestamp":"1780178885459", "event_type":"price_change"}
