{"market":"0x1595b4818eeb1ea1e0bec5de6f057218e557feee9b405a0e930d290384fa1d16", "price_changes":[{"asset_id":"45484070731786948288366703334552551439356529561722304542938873238430842810537", "price":"0.926", "size":"3974.76", "side":"BUY", "hash":"581aa5c6ade1ea940d7ebb43bab804ef75a748c2", "best_bid":"0.948", "best_ask":"0.949"}, {"asset_id":"81739002353269632749850710185641576213562066971072676369728657545679630163887", "price":"0.074", "size":"3974.76", "side":"SELL", "hash":"7768c76c97c24a7259d5cbd7a4bf726a2c502273", "best_bid":"0.051", "best_ask":"0.052"}], "timestamp":"1780178978135", "event_type":"price_change"}
{"market":"0x30d55d8124ee1e12dabe89201badc45669b81dff69e4ce44d961f32878ec178a", "price_changes":[{"asset_id":"52986718774908357330412653486471347449818893503063830313445318937088822580057", "price":"0.889", "size":"30", "side":"BUY", "hash":"921bd0a3c91a69c7fb8a7ab09e54336e050e3807", "best_bid":"0.91", "best_ask":"0.911"}, {"asset_id":"27576533317283401577758999384642760405921738493660383550832555714312627457443", "price":"0.111", "size":"30", "side":"SELL", "hash":"ec9d624e80ba2b768789ca1327ad0be3e4ee2f67", "best_bid":"0.089", "best_ask":"0.09"}], "timestamp":"1780178978135", "event_type":"price_change"}
{"market":"0x0c4cd2055d6ea89354ffddc55d6dbcef9355748112ea952fc925f3db6a5c457f", "price_changes":[{"asset_id":"115428153746996892211798999366308897078723117634059783423375188043903703749062", "price":"0.893", "size":"30", "side":"BUY", "hash":"b7ee59526110811e7a379002257614a4eb6024cb", "best_bid":"0.914", "best_ask":"0.915"}, {"asset_id":"18812649149814341758733697580460697418474693998558159483117100240528657629879", "price":"0.107", "size":"30", "side":"SELL", "hash":"54fa728d9f2784e23df3c9d8fe3dde5a2a2553dd", "best_bid":"0.085", "best_ask":"0.086"}], "timestamp":"1780178978125", "event_type":"price_change"}
{"market":"0x375409bc5eeeff961e82b479caeccc20f33d15738e5bce1186d628aa3d9dfb1f", "price_changes":[{"asset_id":"77121637225348873006259930776623502125079210522997384841464684944292365296940", "price":"0.866", "size":"141.44", "side":"BUY", "hash":"1c456e78c51fdc6169dc0302daa82ee5f1a8472a", "best_bid":"0.887", "best_ask":"0.888"}, {"asset_id":"115556263888245616435851357148058235707004733438163639091106356867234218207169", "price":"0.134", "size":"141.44", "side":"SELL", "hash":"e3689235d7649ab3a38e8554d6fb9c0c1a5c2705", "best_bid":"0.112", "best_ask":"0.113"}], "timestamp":"1780178978124", "event_type":"price_change"}
{"market":"0x375409bc5eeeff961e82b479caeccc20f33d15738e5bce1186d628aa3d9dfb1f", "price_changes":[{"asset_id":"115556263888245616435851357148058235707004733438163639091106356867234218207169", "price":"0.12", "size":"20554.13", "side":"SELL", "hash":"5419ff3fdf4310befe5db484244a02d6a45e95ee", "best_bid":"0.112", "best_ask":"0.113"}, {"asset_id":"77121637225348873006259930776623502125079210522997384841464684944292365296940", "price":"0.88", "size":"20554.13", "side":"BUY", "hash":"b543efb55e6927bfec02318f3d330fcd2ca0cdd7", "best_bid":"0.887", "best_ask":"0.888"}], "timestamp":"1780178979673", "event_type":"price_change"}
{"market":"0x375409bc5eeeff961e82b479caeccc20f33d15738e5bce1186d628aa3d9dfb1f", "price_changes":[{"asset_id":"115556263888245616435851357148058235707004733438163639091106356867234218207169", "price":"0.12", "size":"20804.13", "side":"SELL", "hash":"f03aa68504ab0e170c3babcc684455b52173a123", "best_bid":"0.112", "best_ask":"0.113"}, {"asset_id":"77121637225348873006259930776623502125079210522997384841464684944292365296940", "price":"0.88", "size":"20804.13", "side":"BUY", "hash":"9bd4f425ff9524e2378dbb9989ff5213ab2103a4", "best_bid":"0.887", "best_ask":"0.888"}], "timestamp":"1780178979870", "event_type":"price_change"}
{"id":"2397681", "question":"Centurion 2: Completed Match: Sasikumar Mukund vs Giles Hussey", "market":"0x631880a07714f1299e95d57e15c0cb33f4680fe29a044801dca45b6da1e80fe6", "slug":"atp-mukund-hussey-2026-06-01-completed-match", "description":"This market refers to the tennis match between Sasikumar Mukund and Giles Hussey in the Centurion 2, originally scheduled for June 1, 2026 at 4:00AM ET. This market will resolve to \"Yes\" if all games and sets required to determine a match winner under governing body or event organizer rules are played to completion through normal play. Otherwise, if the match is not completed for any reason, it will resolve to \"No.\" If a forfeit of any kind occurs, including but not limited to a walkover or retirement, this market will resolve \"No.\" If the match is canceled (not played at all), ends in a tie, or is delayed beyond 7 days from the scheduled date without a winner determined, this market will resolve to \"No.\" The primary resolution source for this market is the official statistics of the event as recognized by the governing body or event organizers. However, if the governing body or event organizers have not published final match statistics within 2 hours after the event's conclusion, a consensus of credible reporting may be used instead.", "assets_ids":["51004548714158342646076132335905878579334319177558572793306431850191025350852", "66879020577790721007624862094200186390414961085042065837142977656809946893487"], "outcomes":["Yes", "No"], "event_message":{"id":"542628", "ticker":"atp-mukund-hussey-2026-06-01", "slug":"atp-mukund-hussey-2026-06-01", "title":"Centurion 2: Sasikumar Mukund vs Giles Hussey", "description":"This market refers to the tennis match between Sasikumar Mukund and Giles Hussey in the Centurion 2, originally scheduled for June 1, 2026 at 4:00AM ET.\n\nThis market will resolve to 'Sasikumar Mukund' if Sasikumar Mukund advances against Giles Hussey.\n\nThis market will resolve to 'Giles Hussey' if Giles Hussey advances against Sasikumar Mukund.\n\nIf the match is canceled (not played at all), ends in a tie, or is delayed beyond 7 days from the scheduled date without a winner determined, this market will resolve to 50-50.\n\nIf the match begins but is not completed, and one player advances due to the opponent's retirement, default, or disqualification, this market will resolve to the player who advances.\n\nIf the match ends in a walkover (player withdraws before the start and the other advances automatically), this market will resolve to 50-50.\n\nThe primary resolution source will be official information from the ATP Tour. A consensus of credible reporting may also be used."}, "timestamp":"1780178980190", "event_type":"new_market", "tags":[], "condition_id":"0x631880a07714f1299e95d57e15c0cb33f4680fe29a044801dca45b6da1e80fe6", "active":false, "clob_token_ids":["51004548714158342646076132335905878579334319177558572793306431850191025350852", "66879020577790721007624862094200186390414961085042065837142977656809946893487"], "sports_market_type":"tennis_completed_match", "line":"", "game_start_time":"2026-06-01 08:00:00+00", "order_price_min_tick_size":"0.01", "group_item_title":"Completed Match", "taker_base_fee":"1000", "fees_enabled":true, "fee_schedule":{"exponent":"1", "rate":"0.03", "taker_only":true, "rebate_rate":"0.25"}}
{"id":"2397877", "question":"Spread: Texas Rangers (-1.5)", "market":"0x4be8d23f76a6fab6e7cb806736c42a51a21a362d70ced1bc92baeed5e63e1532", "slug":"mlb-kc-tex-2026-05-31-spread-home-1pt5", "description":"In the upcoming MLB game between the Kansas City Royals and Texas Rangers, scheduled for May 31 at 2:35 PM ET:\n\nThis market will resolve to \"Texas Rangers\" if the Texas Rangers win the game by 2 or more runs.\n\nOtherwise, this market will resolve to \"Kansas City Royals\". If the game ends in a tie, this market will resolve to \"Kansas City Royals\".\n\nIf the game is postponed, this market will remain open until the game has been completed. If the game is canceled entirely, with no make-up game, this market will resolve 50-50.\n\nTo know when a postponed game will be played, please check the home team's schedule on MLB.com for the listed team and look for the game described as a makeup game.\n\nThe primary resolution source for this market is the official final statistics of the event as recognized by the governing body or event organizers. However, if the governing body or event organizers have not published final match statistics within 24 hours after the event's conclusion, a consensus of credible reporting may be used instead.", "assets_ids":["11099660423928872323324249376740884078740085751836753584767030264043725890419", "94056604847084851633243831102672472377618115655951468451321313891420075782175"], "outcomes":["Texas Rangers", "Kansas City Royals"], "event_message":{"id":"523537", "ticker":"mlb-kc-tex-2026-05-31", "slug":"mlb-kc-tex-2026-05-31", "title":"Kansas City Royals vs. Texas Rangers", "description":"In the upcoming MLB game between the Kansas City Royals and Texas Rangers, scheduled for May 31 at 2:35PM ET:\n\nThis market will resolve to \"Kansas City Royals\" if the Kansas City Royals win the game.\n\nThis market will resolve to \"Texas Rangers\" if the Texas Rangers win the game.\n\nIf the game is postponed, this market will remain open until the game has been completed. If the game is canceled entirely, with no make-up game, or ends in a tie, this market will resolve 50-50.\n\nThe primary resolution source for this market is the official final statistics of the event as recognized by the governing body or event organizers. However, if the governing body or event organizers have not published final match statistics within 24 hours after the event's conclusion, a consensus of credible reporting may be used instead."}, "timestamp":"1780178980467", "event_type":"new_market", "tags":[], "condition_id":"0x4be8d23f76a6fab6e7cb806736c42a51a21a362d70ced1bc92baeed5e63e1532", "active":false, "clob_token_ids":["11099660423928872323324249376740884078740085751836753584767030264043725890419", "94056604847084851633243831102672472377618115655951468451321313891420075782175"], "sports_market_type":"spreads", "line":"-1.5", "game_start_time":"2026-05-31 18:35:00+00", "order_price_min_tick_size":"0.01", "group_item_title":"Spread -1.5", "taker_base_fee":"1000", "fees_enabled":true, "fee_schedule":{"exponent":"1", "rate":"0.03", "taker_only":true, "rebate_rate":"0.25"}}
{"market":"0x375409bc5eeeff961e82b479caeccc20f33d15738e5bce1186d628aa3d9dfb1f", "price_changes":[{"asset_id":"115556263888245616435851357148058235707004733438163639091106356867234218207169", "price":"0.12", "size":"20809.13", "side":"SELL", "hash":"7ec1370a9cc9a1f6bdc2dbf5882c665db5c34484", "best_bid":"0.112", "best_ask":"0.113"}, {"asset_id":"77121637225348873006259930776623502125079210522997384841464684944292365296940", "price":"0.88", "size":"20809.13", "side":"BUY", "hash":"a0d4901f32319feeb045ec7797833fa572be34cf", "best_bid":"0.887", "best_ask":"0.888"}], "timestamp":"1780178980584", "event_type":"price_change"}
PONG
{"market":"0x375409bc5eeeff961e82b479caeccc20f33d15738e5bce1186d628aa3d9dfb1f", "price_changes":[{"asset_id":"115556263888245616435851357148058235707004733438163639091106356867234218207169", "price":"0.12", "size":"20814.13", "side":"SELL", "hash":"162b005df4dbc99ca3c2a4d67ca379053d85bb5b", "best_bid":"0.112", "best_ask":"0.113"}, {"asset_id":"77121637225348873006259930776623502125079210522997384841464684944292365296940", "price":"0.88", "size":"20814.13", "side":"BUY", "hash":"0d4ee1b6003758ef45d7f56a0140555284ad7ad3", "best_bid":"0.887", "best_ask":"0.888"}], "timestamp":"1780178981306", "event_type":"price_change"}
{"market":"0x375409bc5eeeff961e82b479caeccc20f33d15738e5bce1186d628aa3d9dfb1f", "price_changes":[{"asset_id":"115556263888245616435851357148058235707004733438163639091106356867234218207169", "price":"0.12", "size":"20819.13", "side":"SELL", "hash":"5181d18b514f088f94969a32e9844e5d0319b660", "best_bid":"0.112", "best_ask":"0.113"}, {"asset_id":"77121637225348873006259930776623502125079210522997384841464684944292365296940", "price":"0.88", "size":"20819.13", "side":"BUY", "hash":"b8bd90ddaaff609b0363b55cea1754e642e50009", "best_bid":"0.887", "best_ask":"0.888"}], "timestamp":"1780178982023", "event_type":"price_change"}
{"market":"0x375409bc5eeeff961e82b479caeccc20f33d15738e5bce1186d628aa3d9dfb1f", "price_changes":[{"asset_id":"115556263888245616435851357148058235707004733438163639091106356867234218207169", "price":"0.12", "size":"20824.13", "side":"SELL", "hash":"8d00ba996ae28c76accc897ae307e9d4380a5b55", "best_bid":"0.112", "best_ask":"0.113"}, {"asset_id":"77121637225348873006259930776623502125079210522997384841464684944292365296940", "price":"0.88", "size":"20824.13", "side":"BUY", "hash":"e86262fecdad5118fa00e1cf0ccb63e453359678", "best_bid":"0.887", "best_ask":"0.888"}], "timestamp":"1780178982741", "event_type":"price_change"}
{"market":"0x4f3421fb2daf5cca7430ed8d8132463963081572d75434393a1808fdb8829fe8", "price_changes":[{"asset_id":"45415751658241142530386585138386640503488308219341470020075667342738719018629", "price":"0.103", "size":"18203.31", "side":"SELL", "hash":"ff9747ce28951dec4061daf6961051b18dfd61ab", "best_bid":"0.1", "best_ask":"0.101"}, {"asset_id":"31940783580344558651011323787577288681658737625185216525249046282994042503801", "price":"0.897", "size":"18203.31", "side":"BUY", "hash":"b872043e6b30c20cb92ba811b85b011d12d62af3", "best_bid":"0.899", "best_ask":"0.9"}], "timestamp":"1780178983002", "event_type":"price_change"}
{"market":"0x4f3421fb2daf5cca7430ed8d8132463963081572d75434393a1808fdb8829fe8", "price_changes":[{"asset_id":"45415751658241142530386585138386640503488308219341470020075667342738719018629", "price":"0.103", "size":"18263.31", "side":"SELL", "hash":"42ab50880c8eadc4045cffde45250dfe352a177d", "best_bid":"0.1", "best_ask":"0.101"}, {"asset_id":"31940783580344558651011323787577288681658737625185216525249046282994042503801", "price":"0.897", "size":"18263.31", "side":"BUY", "hash":"eb8cb761bd3161a1bec689a31a23a9ec722c1e9b", "best_bid":"0.899", "best_ask":"0.9"}], "timestamp":"1780178983100", "event_type":"price_change"}
{"market":"0x9b6fef249040fd17e9c107955b37ac2c3e923509b6b0ff01cc463a331ddeb894", "price_changes":[{"asset_id":"108233603819467706476318984012158651931658302669301887462181073562758483842092", "price":"0.166", "size":"24952", "side":"SELL", "hash":"8595297e86fa2c5a3b415efe2a269083641bf3e3", "best_bid":"0.163", "best_ask":"0.164"}, {"asset_id":"32270411694523539495262303868629477861017829722282576458031815333486368239544", "price":"0.834", "size":"24952", "side":"BUY", "hash":"d5d5c4129b5a54df383d9d4bb0c2b78d9936fec2", "best_bid":"0.836", "best_ask":"0.837"}], "timestamp":"1780178983355", "event_type":"price_change"}
{"market":"0x9b6fef249040fd17e9c107955b37ac2c3e923509b6b0ff01cc463a331ddeb894", "price_changes":[{"asset_id":"108233603819467706476318984012158651931658302669301887462181073562758483842092", "price":"0.166", "size":"25006.68", "side":"SELL", "hash":"ffd321ec6981e5e0bb0bf69d72cdc8266fd60c6b", "best_bid":"0.163", "best_ask":"0.164"}, {"asset_id":"32270411694523539495262303868629477861017829722282576458031815333486368239544", "price":"0.834", "size":"25006.68", "side":"BUY", "hash":"de4618205caa22fa5bd77914b52fe1c8da2f16d7", "best_bid":"0.836", "best_ask":"0.837"}], "timestamp":"1780178983451", "event_type":"price_change"}
{"market":"0x375409bc5eeeff961e82b479caeccc20f33d15738e5bce1186d628aa3d9dfb1f", "price_changes":[{"asset_id":"115556263888245616435851357148058235707004733438163639091106356867234218207169", "price":"0.12", "size":"20829.13", "side":"SELL", "hash":"c1333ade0622c29f3caaa9af1a6cfd03f3b58817", "best_bid":"0.112", "best_ask":"0.113"}, {"asset_id":"77121637225348873006259930776623502125079210522997384841464684944292365296940", "price":"0.88", "size":"20829.13", "side":"BUY", "hash":"c7857e2d3a64b6ae5008bf72a83d6127be02ba30", "best_bid":"0.887", "best_ask":"0.888"}], "timestamp":"1780178983458", "event_type":"price_change"}
{"market":"0x375409bc5eeeff961e82b479caeccc20f33d15738e5bce1186d628aa3d9dfb1f", "price_changes":[{"asset_id":"115556263888245616435851357148058235707004733438163639091106356867234218207169", "price":"0.12", "size":"20834.13", "side":"SELL", "hash":"b1e1ee85fce04331c350a00cea40073d34bbd948", "best_bid":"0.112", "best_ask":"0.113"}, {"asset_id":"77121637225348873006259930776623502125079210522997384841464684944292365296940", "price":"0.88", "size":"20834.13", "side":"BUY", "hash":"bc8aa88edfb07f8c3dd75a2cac8321741222476e", "best_bid":"0.887", "best_ask":"0.888"}], "timestamp":"1780178984176", "event_type":"price_change"}
{"id":"2397683", "question":"ITF Monastir: Andre Lukosiute vs Anastasia Bertacchi", "market":"0xcf5783f631ee97ba283d5bdb1c7c95336696ff455873016af1374b412ab23412", "slug":"itf-lukosiu-bertacc-2026-05-31", "description":"This market refers to the tennis match between Andre Lukosiute and Anastasia Bertacchi in the ITF Women Monastir, originally scheduled for May 31, 2026 at 5:00AM ET.\n\nThis market will resolve to 'Andre Lukosiute' if Andre Lukosiute advances against Anastasia Bertacchi.\n\nThis market will resolve to 'Anastasia Bertacchi' if Anastasia Bertacchi advances against Andre Lukosiute.\n\nIf the match is canceled (not played at all), ends in a tie, or is delayed beyond 7 days from the scheduled date without a winner determined, this market will resolve to 50-50.\n\nIf the match begins but is not completed, and one player advances due to the opponent's retirement, default, or disqualification, this market will resolve to the player who advances.\n\nIf the match ends in a walkover (player withdraws before the start and the other advances automatically), this market will resolve to 50-50.\n\nThe primary resolution source will be official information from the International Tennis Federation (ITF). A consensus of credible reporting may also be used.", "assets_ids":["98564355605675769349018591837428882998516514153837607938602236812733147085454", "57675540686461699800311732611495839925783631956980348091093257925636682099531"], "outcomes":["Andre Lukosiute", "Anastasia Bertacchi"], "event_message":{"id":"542629", "ticker":"itf-lukosiu-bertacc-2026-05-31", "slug":"itf-lukosiu-bertacc-2026-05-31", "title":"ITF Monastir: Andre Lukosiute vs Anastasia Bertacchi", "description":"This market refers to the tennis match between Andre Lukosiute and Anastasia Bertacchi in the ITF Women Monastir, originally scheduled for May 31, 2026 at 5:00AM ET.\n\nThis market will resolve to 'Andre Lukosiute' if Andre Lukosiute advances against Anastasia Bertacchi.\n\nThis market will resolve to 'Anastasia Bertacchi' if Anastasia Bertacchi advances against Andre Lukosiute.\n\nIf the match is canceled (not played at all), ends in a tie, or is delayed beyond 7 days from the scheduled date without a winner determined, this market will resolve to 50-50.\n\nIf the match begins but is not completed, and one player advances due to the opponent's retirement, default, or disqualification, this market will resolve to the player who advances.\n\nIf the match ends in a walkover (player withdraws before the start and the other advances automatically), this market will resolve to 50-50.\n\nThe primary resolution source will be official information from the International Tennis Federation (ITF). A consensus of credible reporting may also be used."}, "timestamp":"1780178984293", "event_type":"new_market", "tags":[], "condition_id":"0xcf5783f631ee97ba283d5bdb1c7c95336696ff455873016af1374b412ab23412", "active":false, "clob_token_ids":["98564355605675769349018591837428882998516514153837607938602236812733147085454", "57675540686461699800311732611495839925783631956980348091093257925636682099531"], "sports_market_type":"moneyline", "line":"", "game_start_time":"2026-05-31 09:00:00+00", "order_price_min_tick_size":"0.01", "group_item_title":"", "taker_base_fee":"1000", "fees_enabled":true, "fee_schedule":{"exponent":"1", "rate":"0.03", "taker_only":true, "rebate_rate":"0.25"}}
{"market":"0x375409bc5eeeff961e82b479caeccc20f33d15738e5bce1186d628aa3d9dfb1f", "price_changes":[{"asset_id":"115556263888245616435851357148058235707004733438163639091106356867234218207169", "price":"0.12", "size":"20839.13", "side":"SELL", "hash":"2a37117b5fb05aecd8a25900c7d6ad1614fbd49e", "best_bid":"0.112", "best_ask":"0.113"}, {"asset_id":"77121637225348873006259930776623502125079210522997384841464684944292365296940", "price":"0.88", "size":"20839.13", "side":"BUY", "hash":"1b68046df1b8849369157ba9475f77a5cf7c5112", "best_bid":"0.887", "best_ask":"0.888"}], "timestamp":"1780178984892", "event_type":"price_change"}
{"market":"0x7976b8dbacf9077eb1453a62bcefd6ab2df199acd28aad276ff0d920d6992892", "price_changes":[{"asset_id":"4394372887385518214471608448209527405727552777602031099972143344338178308080", "price":"0.17", "size":"27598.28", "side":"SELL", "hash":"51f10e9f0ed98cabc70efb380f607907c1e52b94", "best_bid":"0.167", "best_ask":"0.168"}, {"asset_id":"112680630004798425069810935278212000865453267506345451433803052322987302357330", "price":"0.83", "size":"27598.28", "side":"BUY", "hash":"4da8f330fac91154da07f130d86b8d333a6c48fc", "best_bid":"0.832", "best_ask":"0.833"}], "timestamp":"1780178984913", "event_type":"price_change"}
{"market":"0x30d55d8124ee1e12dabe89201badc45669b81dff69e4ce44d961f32878ec178a", "price_changes":[{"asset_id":"27576533317283401577758999384642760405921738493660383550832555714312627457443", "price":"0.092", "size":"78371.18", "side":"SELL", "hash":"f3433ba98bc5445f30079365c390bb6268540c51", "best_bid":"0.089", "best_ask":"0.09"}, {"asset_id":"52986718774908357330412653486471347449818893503063830313445318937088822580057", "price":"0.908", "size":"78371.18", "side":"BUY", "hash":"e94b5e3649bd49daf72d09d6823e40f11a39e325", "best_bid":"0.91", "best_ask":"0.911"}], "timestamp":"1780178984915", "event_type":"price_change"}
{"market":"0x7976b8dbacf9077eb1453a62bcefd6ab2df199acd28aad276ff0d920d6992892", "price_changes":[{"asset_id":"4394372887385518214471608448209527405727552777602031099972143344338178308080", "price":"0.17", "size":"27652.43", "side":"SELL", "hash":"2226d616d2536b0722da984d72e7b011edbf20b6", "best_bid":"0.167", "best_ask":"0.168"}, {"asset_id":"112680630004798425069810935278212000865453267506345451433803052322987302357330", "price":"0.83", "size":"27652.43", "side":"BUY", "hash":"9cb3c2a80d490c3c860c811cb8cdb81a6be7722f", "best_bid":"0.832", "best_ask":"0.833"}], "timestamp":"1780178985032", "event_type":"price_change"}
{"market":"0x30d55d8124ee1e12dabe89201badc45669b81dff69e4ce44d961f32878ec178a", "price_changes":[{"asset_id":"27576533317283401577758999384642760405921738493660383550832555714312627457443", "price":"0.092", "size":"78431.18", "side":"SELL", "hash":"20c12ed0bf7125f9c21ef861ea7f7788e687234a", "best_bid":"0.089", "best_ask":"0.09"}, {"asset_id":"52986718774908357330412653486471347449818893503063830313445318937088822580057", "price":"0.908", "size":"78431.18", "side":"BUY", "hash":"14e892b7aa805529b88c57f99deb8df396a107fa", "best_bid":"0.91", "best_ask":"0.911"}], "timestamp":"1780178985036", "event_type":"price_change"}
{"id":"2397875", "question":"Spread: Los Angeles Angels (-2.5)", "market":"0xf181f2ee3c599d5dedb849a5a5ff855d05cda19bfcf07356b6bcd196d6bb0c2a", "slug":"mlb-laa-tb-2026-05-31-spread-away-2pt5", "description":"In the upcoming MLB game between the Los Angeles Angels and Tampa Bay Rays, scheduled for May 31 at 1:40 PM ET:\n\nThis market will resolve to \"Los Angeles Angels\" if the Los Angeles Angels win the game by 3 or more runs.\n\nOtherwise, this market will resolve to \"Tampa Bay Rays\". If the game ends in a tie, this market will resolve to \"Tampa Bay Rays\".\n\nIf the game is postponed, this market will remain open until the game has been completed. If the game is canceled entirely, with no make-up game, this market will resolve 50-50.\n\nTo know when a postponed game will be played, please check the home team's schedule on MLB.com for the listed team and look for the game described as a makeup game.\n\nThe primary resolution source for this market is the official final statistics of the event as recognized by the governing body or event organizers. However, if the governing body or event organizers have not published final match statistics within 24 hours after the event's conclusion, a consensus of credible reporting may be used instead.", "assets_ids":["77227739157459141333108518824773301718460229295612276110196441157521404671230", "6899011472078097289737252163341497079956089073659781512517704453449972645288"], "outcomes":["Los Angeles Angels", "Tampa Bay Rays"], "event_message":{"id":"523533", "ticker":"mlb-laa-tb-2026-05-31", "slug":"mlb-laa-tb-2026-05-31", "title":"Los Angeles Angels vs. Tampa Bay Rays", "description":"In the upcoming MLB game between the Los Angeles Angels and Tampa Bay Rays, scheduled for May 31 at 1:40PM ET:\n\nThis market will resolve to \"Los Angeles Angels\" if the Los Angeles Angels win the game.\n\nThis market will resolve to \"Tampa Bay Rays\" if the Tampa Bay Rays win the game.\n\nIf the game is postponed, this market will remain open until the game has been completed. If the game is canceled entirely, with no make-up game, or ends in a tie, this market will resolve 50-50.\n\nThe primary resolution source for this market is the official final statistics of the event as recognized by the governing body or event organizers. However, if the governing body or event organizers have not published final match statistics within 24 hours after the event's conclusion, a consensus of credible reporting may be used instead."}, "timestamp":"1780178985272", "event_type":"new_market", "tags":[], "condition_id":"0xf181f2ee3c599d5dedb849a5a5ff855d05cda19bfcf07356b6bcd196d6bb0c2a", "active":false, "clob_token_ids":["77227739157459141333108518824773301718460229295612276110196441157521404671230", "6899011472078097289737252163341497079956089073659781512517704453449972645288"], "sports_market_type":"spreads", "line":"-2.5", "game_start_time":"2026-05-31 17:40:00+00", "order_price_min_tick_size":"0.01", "group_item_title":"Spread -2.5", "taker_base_fee":"1000", "fees_enabled":true, "fee_schedule":{"exponent":"1", "rate":"0.03", "taker_only":true, "rebate_rate":"0.25"}}
{"market":"0x375409bc5eeeff961e82b479caeccc20f33d15738e5bce1186d628aa3d9dfb1f", "price_changes":[{"asset_id":"115556263888245616435851357148058235707004733438163639091106356867234218207169", "price":"0.12", "size":"20844.13", "side":"SELL", "hash":"1b7dd2f54acb51464c6aa138d33763f044f00fde", "best_bid":"0.112", "best_ask":"0.113"}, {"asset_id":"77121637225348873006259930776623502125079210522997384841464684944292365296940", "price":"0.88", "size":"20844.13", "side":"BUY", "hash":"bb8a9aff4fa727c059b69dffc4311a72e99e2e0e", "best_bid":"0.887", "best_ask":"0.888"}], "timestamp":"1780178985608", "event_type":"price_change"}
{"market":"0x375409bc5eeeff961e82b479caeccc20f33d15738e5bce1186d628aa3d9dfb1f", "price_changes":[{"asset_id":"115556263888245616435851357148058235707004733438163639091106356867234218207169", "price":"0.115", "size":"12019.15", "side":"SELL", "hash":"fd85daf2e7fec21d799d4831e74160fc5b7d65e3", "best_bid":"0.112", "best_ask":"0.113"}, {"asset_id":"77121637225348873006259930776623502125079210522997384841464684944292365296940", "price":"0.885", "size":"12019.15", "side":"BUY", "hash":"4edb6dea6cc1ecbdcf0121d6a17ba027b556c396", "best_bid":"0.887", "best_ask":"0.888"}], "timestamp":"1780178986205", "event_type":"price_change"}
{"market":"0x1595b4818eeb1ea1e0bec5de6f057218e557feee9b405a0e930d290384fa1d16", "price_changes":[{"asset_id":"81739002353269632749850710185641576213562066971072676369728657545679630163887", "price":"0.053", "size":"3311.26", "side":"SELL", "hash":"858a00bb2e7bb06d95e154939a1cff2c3a5b63b0", "best_bid":"0.051", "best_ask":"0.052"}, {"asset_id":"45484070731786948288366703334552551439356529561722304542938873238430842810537", "price":"0.947", "size":"3311.26", "side":"BUY", "hash":"4763c24d73b47c89fa1942fbdf84e60b17d3b832", "best_bid":"0.948", "best_ask":"0.949"}], "timestamp":"1780178986205", "event_type":"price_change"}
{"market":"0x0c4cd2055d6ea89354ffddc55d6dbcef9355748112ea952fc925f3db6a5c457f", "price_changes":[{"asset_id":"18812649149814341758733697580460697418474693998558159483117100240528657629879", "price":"0.088", "size":"15069.46", "side":"SELL", "hash":"9b6d0fa9cb585cf4da850627873575ab06d3895c", "best_bid":"0.085", "best_ask":"0.086"}, {"asset_id":"115428153746996892211798999366308897078723117634059783423375188043903703749062", "price":"0.912", "size":"15069.46", "side":"BUY", "hash":"a0cd8cdee728c6638a677b6c44de9ca0350897ac", "best_bid":"0.914", "best_ask":"0.915"}], "timestamp":"1780178986205", "event_type":"price_change"}
{"market":"0x0c4cd2055d6ea89354ffddc55d6dbcef9355748112ea952fc925f3db6a5c457f", "price_changes":[{"asset_id":"18812649149814341758733697580460697418474693998558159483117100240528657629879", "price":"0.088", "size":"15129.46", "side":"SELL", "hash":"ac3a22f247efa4ff41a7cdd887a4d80b4d87222e", "best_bid":"0.085", "best_ask":"0.086"}, {"asset_id":"115428153746996892211798999366308897078723117634059783423375188043903703749062", "price":"0.912", "size":"15129.46", "side":"BUY", "hash":"72807b7943cfa6c839beee4fea2657fea473c7a5", "best_bid":"0.914", "best_ask":"0.915"}], "timestamp":"1780178986308", "event_type":"price_change"}
{"market":"0x375409bc5eeeff961e82b479caeccc20f33d15738e5bce1186d628aa3d9dfb1f", "price_changes":[{"asset_id":"115556263888245616435851357148058235707004733438163639091106356867234218207169", "price":"0.115", "size":"12079.15", "side":"SELL", "hash":"0147e83ba550edb7d2dfb47518eac90c247f01d7", "best_bid":"0.112", "best_ask":"0.113"}, {"asset_id":"77121637225348873006259930776623502125079210522997384841464684944292365296940", "price":"0.885", "size":"12079.15", "side":"BUY", "hash":"f1bfaa63117dd9be99928c5ef9136c656e1063fd", "best_bid":"0.887", "best_ask":"0.888"}], "timestamp":"1780178986311", "event_type":"price_change"}
{"market":"0x1595b4818eeb1ea1e0bec5de6f057218e557feee9b405a0e930d290384fa1d16", "price_changes":[{"asset_id":"81739002353269632749850710185641576213562066971072676369728657545679630163887", "price":"0.053", "size":"3371.26", "side":"SELL", "hash":"14c7a5ecd152da42a5d9a3add9bbcf6d82201900", "best_bid":"0.051", "best_ask":"0.052"}, {"asset_id":"45484070731786948288366703334552551439356529561722304542938873238430842810537", "price":"0.947", "size":"3371.26", "side":"BUY", "hash":"2a2eba00edc5e5bf792eb54a78f03a90e19437d0", "best_bid":"0.948", "best_ask":"0.949"}], "timestamp":"1780178986322", "event_type":"price_change"}
{"market":"0x375409bc5eeeff961e82b479caeccc20f33d15738e5bce1186d628aa3d9dfb1f", "price_changes":[{"asset_id":"115556263888245616435851357148058235707004733438163639091106356867234218207169", "price":"0.12", "size":"20849.13", "side":"SELL", "hash":"1ea6a566103b3f06764f8d69b71a7acb67ef15d4", "best_bid":"0.112", "best_ask":"0.113"}, {"asset_id":"77121637225348873006259930776623502125079210522997384841464684944292365296940", "price":"0.88", "size":"20849.13", "side":"BUY", "hash":"9a406036a685a08a847e1534c15383b6b25f051b", "best_bid":"0.887", "best_ask":"0.888"}], "timestamp":"1780178986323", "event_type":"price_change"}
{"market":"0x0c4cd2055d6ea89354ffddc55d6dbcef9355748112ea952fc925f3db6a5c457f", "price_changes":[{"asset_id":"18812649149814341758733697580460697418474693998558159483117100240528657629879", "price":"0.145", "size":"11627.9", "side":"SELL", "hash":"81e27a8637d77abac6e5c6e60af873c99bec2218", "best_bid":"0.085", "best_ask":"0.086"}, {"asset_id":"115428153746996892211798999366308897078723117634059783423375188043903703749062", "price":"0.855", "size":"11627.9", "side":"BUY", "hash":"6f728a10d3ab2f3581f7eecefa24701517603ddf", "best_bid":"0.914", "best_ask":"0.915"}], "timestamp":"1780178987122", "event_type":"price_change"}
{"market":"0x0c4cd2055d6ea89354ffddc55d6dbcef9355748112ea952fc925f3db6a5c457f", "price_changes":[{"asset_id":"18812649149814341758733697580460697418474693998558159483117100240528657629879", "price":"0.145", "size":"11634.31", "side":"SELL", "hash":"b7b475cf45509eb6dd7a178b066b9e7d6dcb27aa", "best_bid":"0.085", "best_ask":"0.086"}, {"asset_id":"115428153746996892211798999366308897078723117634059783423375188043903703749062", "price":"0.855", "size":"11634.31", "side":"BUY", "hash":"0d216b8127f7fcebaf960d3c8ee9dd8076a3d4b0", "best_bid":"0.914", "best_ask":"0.915"}], "timestamp":"1780178987255", "event_type":"price_change"}
{"market":"0x9b6fef249040fd17e9c107955b37ac2c3e923509b6b0ff01cc463a331ddeb894", "asset_id":"32270411694523539495262303868629477861017829722282576458031815333486368239544", "best_bid":"0.836", "best_ask":"0.837", "spread":"0.001", "timestamp":"1780178988583", "event_type":"best_bid_ask"}
{"market":"0x9b6fef249040fd17e9c107955b37ac2c3e923509b6b0ff01cc463a331ddeb894", "price_changes":[{"asset_id":"108233603819467706476318984012158651931658302669301887462181073562758483842092", "price":"0.164", "size":"38057.32", "side":"SELL", "hash":"0a3e3b8500461bdc6c765cfc9b12355a2848d568", "best_bid":"0.163", "best_ask":"0.164"}, {"asset_id":"32270411694523539495262303868629477861017829722282576458031815333486368239544", "price":"0.836", "size":"38057.32", "side":"BUY", "hash":"e75c6cd9d69ccad4e7ca6ca082a7a7824318cf64", "best_bid":"0.836", "best_ask":"0.837"}], "timestamp":"1780178988583", "event_type":"price_change"}
{"market":"0x9b6fef249040fd17e9c107955b37ac2c3e923509b6b0ff01cc463a331ddeb894", "asset_id":"32270411694523539495262303868629477861017829722282576458031815333486368239544", "bids":[{"price":"0.001", "size":"12219098.99"}, {"price":"0.002", "size":"178.57"}, {"price":"0.003", "size":"21.08"}, {"price":"0.009", "size":"18000"}, {"price":"0.01", "size":"100"}, {"price":"0.011", "size":"5.62"}, {"price":"0.012", "size":"1111111"}, {"price":"0.013", "size":"900000"}, {"price":"0.014", "size":"1300"}, {"price":"0.015", "size":"500"}, {"price":"0.02", "size":"99"}, {"price":"0.021", "size":"6.95"}, {"price":"0.05", "size":"246.52"}, {"price":"0.051", "size":"10.84"}, {"price":"0.09", "size":"5.98"}, {"price":"0.1", "size":"15"}, {"price":"0.12", "size":"5005"}, {"price":"0.121", "size":"12000"}, {"price":"0.15", "size":"67.49"}, {"price":"0.178", "size":"289.7"}, {"price":"0.2", "size":"796.33"}, {"price":"0.209", "size":"143.54"}, {"price":"0.22", "size":"100.48"}, {"price":"0.221", "size":"5.22"}, {"price":"0.245", "size":"304.87"}, {"price":"0.25", "size":"3597"}, {"price":"0.251", "size":"6000"}, {"price":"0.29", "size":"9.75"}, {"price":"0.3", "size":"55.88"}, {"price":"0.315", "size":"1459.85"}, {"price":"0.33", "size":"1363.34"}, {"price":"0.331", "size":"3000"}, {"price":"0.34", "size":"5"}, {"price":"0.35", "size":"2159.92"}, {"price":"0.4", "size":"34587.44"}, {"price":"0.401", "size":"3000"}, {"price":"0.47", "size":"5688.73"}, {"price":"0.5", "size":"36470.75"}, {"price":"0.502", "size":"1529.99"}, {"price":"0.503", "size":"14000"}, {"price":"0.51", "size":"90.9"}, {"price":"0.511", "size":"1202.04"}, {"price":"0.55", "size":"513.44"}, {"price":"0.56", "size":"111.11"}, {"price":"0.562", "size":"655.13"}, {"price":"0.563", "size":"65.06"}, {"price":"0.57", "size":"3964.15"}, {"price":"0.6", "size":"22272.15"}, {"price":"0.624", "size":"27.04"}, {"price":"0.636", "size":"105.03"}, {"price":"0.637", "size":"1000"}, {"price":"0.638", "size":"23.57"}, {"price":"0.64", "size":"4479.3"}, {"price":"0.648", "size":"7.39"}, {"price":"0.65", "size":"15415.61"}, {"price":"0.651", "size":"2155.26"}, {"price":"0.667", "size":"1000"}, {"price":"0.67", "size":"18.11"}, {"price":"0.672", "size":"482.66"}, {"price":"0.68", "size":"38"}, {"price":"0.697", "size":"1000"}, {"price":"0.7", "size":"487.37"}, {"price":"0.701", "size":"400"}, {"price":"0.72", "size":"167.14"}, {"price":"0.722", "size":"100"}, {"price":"0.727", "size":"1000"}, {"price":"0.743", "size":"100"}, {"price":"0.747", "size":"1000"}, {"price":"0.75", "size":"1422.54"}, {"price":"0.751", "size":"201"}, {"price":"0.752", "size":"1367"}, {"price":"0.754", "size":"334.02"}, {"price":"0.757", "size":"1000"}, {"price":"0.76", "size":"302"}, {"price":"0.764", "size":"130"}, {"price":"0.767", "size":"1100"}, {"price":"0.777", "size":"1011.23"}, {"price":"0.779", "size":"334.02"}, {"price":"0.78", "size":"237"}, {"price":"0.785", "size":"100"}, {"price":"0.786", "size":"15"}, {"price":"0.787", "size":"1100"}, {"price":"0.788", "size":"10"}, {"price":"0.789", "size":"5555.55"}, {"price":"0.79", "size":"122"}, {"price":"0.793", "size":"10"}, {"price":"0.794", "size":"1000"}, {"price":"0.795", "size":"10"}, {"price":"0.797", "size":"1050"}, {"price":"0.8", "size":"17681.66"}, {"price":"0.801", "size":"100"}, {"price":"0.803", "size":"110"}, {"price":"0.806", "size":"44"}, {"price":"0.807", "size":"1180"}, {"price":"0.808", "size":"675.7"}, {"price":"0.809", "size":"2027"}, {"price":"0.81", "size":"6609.61"}, {"price":"0.811", "size":"4653.91"}, {"price":"0.812", "size":"1708.3"}, {"price":"0.813", "size":"782.67"}, {"price":"0.814", "size":"1703.37"}, {"price":"0.815", "size":"5571.35"}, {"price":"0.816", "size":"10939.83"}, {"price":"0.817", "size":"7549.45"}, {"price":"0.818", "size":"6032.61"}, {"price":"0.819", "size":"340"}, {"price":"0.82", "size":"1037.95"}, {"price":"0.821", "size":"1694.21"}, {"price":"0.822", "size":"22719.93"}, {"price":"0.823", "size":"44358.4"}, {"price":"0.824", "size":"47073"}, {"price":"0.825", "size":"47040.85"}, {"price":"0.827", "size":"654.36"}, {"price":"0.829", "size":"19937.62"}, {"price":"0.83", "size":"26050"}, {"price":"0.831", "size":"3000"}, {"price":"0.832", "size":"2000"}, {"price":"0.833", "size":"4950.42"}, {"price":"0.834", "size":"25006.68"}, {"price":"0.835", "size":"182736.01"}, {"price":"0.836", "size":"38057.32"}], "asks":[{"price":"0.999", "size":"2260279"}, {"price":"0.998", "size":"1557248"}, {"price":"0.997", "size":"1001200"}, {"price":"0.996", "size":"55555"}, {"price":"0.995", "size":"90100"}, {"price":"0.99", "size":"720"}, {"price":"0.985", "size":"5.01"}, {"price":"0.984", "size":"555555"}, {"price":"0.983", "size":"60000"}, {"price":"0.982", "size":"105435.9"}, {"price":"0.981", "size":"800"}, {"price":"0.98", "size":"5430"}, {"price":"0.978", "size":"3000"}, {"price":"0.976", "size":"3000"}, {"price":"0.974", "size":"3000"}, {"price":"0.972", "size":"3000"}, {"price":"0.97", "size":"3000"}, {"price":"0.968", "size":"3000"}, {"price":"0.966", "size":"3000"}, {"price":"0.96", "size":"750"}, {"price":"0.951", "size":"100"}, {"price":"0.95", "size":"150"}, {"price":"0.94", "size":"10"}, {"price":"0.937", "size":"16.27"}, {"price":"0.936", "size":"30"}, {"price":"0.935", "size":"10"}, {"price":"0.934", "size":"20"}, {"price":"0.931", "size":"10"}, {"price":"0.93", "size":"50"}, {"price":"0.926", "size":"20"}, {"price":"0.925", "size":"5"}, {"price":"0.924", "size":"30"}, {"price":"0.923", "size":"20"}, {"price":"0.922", "size":"20"}, {"price":"0.921", "size":"20"}, {"price":"0.92", "size":"140"}, {"price":"0.91", "size":"10100"}, {"price":"0.905", "size":"105.2"}, {"price":"0.9", "size":"6296.92"}, {"price":"0.899", "size":"1076.68"}, {"price":"0.893", "size":"37.72"}, {"price":"0.892", "size":"40"}, {"price":"0.89", "size":"400"}, {"price":"0.889", "size":"5000"}, {"price":"0.885", "size":"9"}, {"price":"0.884", "size":"90"}, {"price":"0.88", "size":"120"}, {"price":"0.879", "size":"7500"}, {"price":"0.878", "size":"5000"}, {"price":"0.877", "size":"100"}, {"price":"0.875", "size":"956.59"}, {"price":"0.874", "size":"2500"}, {"price":"0.87", "size":"328"}, {"price":"0.869", "size":"2567"}, {"price":"0.868", "size":"47"}, {"price":"0.867", "size":"1933.93"}, {"price":"0.866", "size":"57"}, {"price":"0.865", "size":"37"}, {"price":"0.864", "size":"5017"}, {"price":"0.863", "size":"3727"}, {"price":"0.862", "size":"7"}, {"price":"0.861", "size":"7"}, {"price":"0.86", "size":"717"}, {"price":"0.859", "size":"7"}, {"price":"0.858", "size":"507"}, {"price":"0.857", "size":"97"}, {"price":"0.856", "size":"7"}, {"price":"0.855", "size":"37"}, {"price":"0.854", "size":"37"}, {"price":"0.853", "size":"722"}, {"price":"0.852", "size":"7"}, {"price":"0.851", "size":"707"}, {"price":"0.85", "size":"6520"}, {"price":"0.849", "size":"877"}, {"price":"0.848", "size":"7"}, {"price":"0.847", "size":"27"}, {"price":"0.846", "size":"287"}, {"price":"0.845", "size":"3760.64"}, {"price":"0.844", "size":"20417"}, {"price":"0.843", "size":"28647.14"}, {"price":"0.842", "size":"10076.94"}, {"price":"0.841", "size":"56.6"}, {"price":"0.84", "size":"67783.1"}, {"price":"0.839", "size":"12119.44"}, {"price":"0.838", "size":"4311.83"}, {"price":"0.837", "size":"15230.42"}], "hash":"e75c6cd9d69ccad4e7ca6ca082a7a7824318cf64", "timestamp":"1780178988583", "event_type":"book"}
{"id":"2397617", "question":"ITF Women Wuning: Completed Match: Alexandra Shubladze vs Hina Inoue", "market":"0x9132a2bd494dc10208107e3231578393fb6650b11a2ed4596c8c231780917975", "slug":"itf-shublad-inoue-2026-05-31-completed-match", "description":"This market refers to the tennis match between Alexandra Shubladze and Hina Inoue in the ITF Women Wuning, originally scheduled for May 30, 2026 at 11:00PM ET. This market will resolve to \"Yes\" if all games and sets required to determine a match winner under governing body or event organizer rules are played to completion through normal play. Otherwise, if the match is not completed for any reason, it will resolve to \"No.\" If a forfeit of any kind occurs, including but not limited to a walkover or retirement, this market will resolve \"No.\" If the match is canceled (not played at all), ends in a tie, or is delayed beyond 7 days from the scheduled date without a winner determined, this market will resolve to \"No.\" The primary resolution source for this market is the official statistics of the event as recognized by the governing body or event organizers. However, if the governing body or event organizers have not published final match statistics within 2 hours after the event's conclusion, a consensus of credible reporting may be used instead.", "assets_ids":["98796396763305490037019681051437390601383492686140948371946121223512903291388", "75934685435482098164456554001385097165864796265322382487631377712845566116001"], "outcomes":["Yes", "No"], "event_message":{"id":"542605", "ticker":"itf-shublad-inoue-2026-05-31", "slug":"itf-shublad-inoue-2026-05-31", "title":"ITF Wuning: Alexandra Shubladze vs Hina Inoue", "description":"This market refers to the tennis match between Alexandra Shubladze and Hina Inoue in the ITF Women Wuning, originally scheduled for May 30, 2026 at 11:00PM ET.\n\nThis market will resolve to 'Alexandra Shubladze' if Alexandra Shubladze advances against Hina Inoue.\n\nThis market will resolve to 'Hina Inoue' if Hina Inoue advances against Alexandra Shubladze.\n\nIf the match is canceled (not played at all), ends in a tie, or is delayed beyond 7 days from the scheduled date without a winner determined, this market will resolve to 50-50.\n\nIf the match begins but is not completed, and one player advances due to the opponent's retirement, default, or disqualification, this market will resolve to the player who advances.\n\nIf the match ends in a walkover (player withdraws before the start and the other advances automatically), this market will resolve to 50-50.\n\nThe primary resolution source will be official information from the International Tennis Federation (ITF). A consensus of credible reporting may also be used."}, "timestamp":"1780178989314", "event_type":"new_market", "tags":[], "condition_id":"0x9132a2bd494dc10208107e3231578393fb6650b11a2ed4596c8c231780917975", "active":false, "clob_token_ids":["98796396763305490037019681051437390601383492686140948371946121223512903291388", "75934685435482098164456554001385097165864796265322382487631377712845566116001"], "sports_market_type":"tennis_completed_match", "line":"", "game_start_time":"2026-05-31 03:00:00+00", "order_price_min_tick_size":"0.01", "group_item_title":"Completed Match", "taker_base_fee":"1000", "fees_enabled":true, "fee_schedule":{"exponent":"1", "rate":"0.03", "taker_only":true, "rebate_rate":"0.25"}}
PONG
{"id":"2397795", "question":"Birmingham: Jacob Fearnley vs Rinky Hijikata", "market":"0x4f38c5f10f9a52bb438cd419bec8e206faa2b3155d319a3603cbf1898ec12f05", "slug":"atp-fearnle-hijikat-2026-06-01", "description":"This market refers to the tennis match between Jacob Fearnley and Rinky Hijikata in the Birmingham, originally scheduled for June 1, 2026 at 5:30AM ET.\n\nThis market will resolve to 'Jacob Fearnley' if Jacob Fearnley advances against Rinky Hijikata.\n\nThis market will resolve to 'Rinky Hijikata' if Rinky Hijikata advances against Jacob Fearnley.\n\nIf the match is canceled (not played at all), ends in a tie, or is delayed beyond 7 days from the scheduled date without a winner determined, this market will resolve to 50-50.\n\nIf the match begins but is not completed, and one player advances due to the opponent's retirement, default, or disqualification, this market will resolve to the player who advances.\n\nIf the match ends in a walkover (player withdraws before the start and the other advances automatically), this market will resolve to 50-50.\n\nThe primary resolution source will be official information from the ATP Tour. A consensus of credible reporting may also be used.", "assets_ids":["84258881483846613448057480813614536201023199311304580654999092204677576359150", "16913883410659428764162199288693910217772740861639927917046682092665012631001"], "outcomes":["Jacob Fearnley", "Rinky Hijikata"], "event_message":{"id":"542665", "ticker":"atp-fearnle-hijikat-2026-06-01", "slug":"atp-fearnle-hijikat-2026-06-01", "title":"Birmingham: Jacob Fearnley vs Rinky Hijikata", "description":"This market refers to the tennis match between Jacob Fearnley and Rinky Hijikata in the Birmingham, originally scheduled for June 1, 2026 at 5:30AM ET.\n\nThis market will resolve to 'Jacob Fearnley' if Jacob Fearnley advances against Rinky Hijikata.\n\nThis market will resolve to 'Rinky Hijikata' if Rinky Hijikata advances against Jacob Fearnley.\n\nIf the match is canceled (not played at all), ends in a tie, or is delayed beyond 7 days from the scheduled date without a winner determined, this market will resolve to 50-50.\n\nIf the match begins but is not completed, and one player advances due to the opponent's retirement, default, or disqualification, this market will resolve to the player who advances.\n\nIf the match ends in a walkover (player withdraws before the start and the other advances automatically), this market will resolve to 50-50.\n\nThe primary resolution source will be official information from the ATP Tour. A consensus of credible reporting may also be used."}, "timestamp":"1780178991957", "event_type":"new_market", "tags":[], "condition_id":"0x4f38c5f10f9a52bb438cd419bec8e206faa2b3155d319a3603cbf1898ec12f05", "active":false, "clob_token_ids":["84258881483846613448057480813614536201023199311304580654999092204677576359150", "16913883410659428764162199288693910217772740861639927917046682092665012631001"], "sports_market_type":"moneyline", "line":"", "game_start_time":"2026-06-01 09:30:00+00", "order_price_min_tick_size":"0.01", "group_item_title":"", "taker_base_fee":"1000", "fees_enabled":true, "fee_schedule":{"exponent":"1", "rate":"0.03", "taker_only":true, "rebate_rate":"0.25"}}
{"market":"0x4f3421fb2daf5cca7430ed8d8132463963081572d75434393a1808fdb8829fe8", "price_changes":[{"asset_id":"45415751658241142530386585138386640503488308219341470020075667342738719018629", "price":"0.076", "size":"6553.29", "side":"BUY", "hash":"26eb931785b99250d549f8cc1b77e4ea18c4aa31", "best_bid":"0.1", "best_ask":"0.101"}, {"asset_id":"31940783580344558651011323787577288681658737625185216525249046282994042503801", "price":"0.924", "size":"6553.29", "side":"SELL", "hash":"a305722fc42f30c1d7298cbd5106f4d2f9a1249c", "best_bid":"0.899", "best_ask":"0.9"}], "timestamp":"1780178992841", "event_type":"price_change"}
{"market":"0x30d55d8124ee1e12dabe89201badc45669b81dff69e4ce44d961f32878ec178a", "price_changes":[{"asset_id":"27576533317283401577758999384642760405921738493660383550832555714312627457443", "price":"0.092", "size":"78375.52", "side":"SELL", "hash":"2a14880b431e9e7a528d13db195f825340e02446", "best_bid":"0.089", "best_ask":"0.09"}, {"asset_id":"52986718774908357330412653486471347449818893503063830313445318937088822580057", "price":"0.908", "size":"78375.52", "side":"BUY", "hash":"b661b013e4787ef0aec6d6660338610732eb984b", "best_bid":"0.91", "best_ask":"0.911"}], "timestamp":"1780178995510", "event_type":"price_change"}
{"market":"0x1595b4818eeb1ea1e0bec5de6f057218e557feee9b405a0e930d290384fa1d16", "price_changes":[{"asset_id":"81739002353269632749850710185641576213562066971072676369728657545679630163887", "price":"0.053", "size":"3291.26", "side":"SELL", "hash":"944b37eda41f97ea8128be0adfccf3ec12e76a58", "best_bid":"0.051", "best_ask":"0.052"}, {"asset_id":"45484070731786948288366703334552551439356529561722304542938873238430842810537", "price":"0.947", "size":"3291.26", "side":"BUY", "hash":"1051fcbe7cf2b4f06682f5ca7eb4b594806acb14", "best_bid":"0.948", "best_ask":"0.949"}], "timestamp":"1780178995513", "event_type":"price_change"}
{"market":"0x7976b8dbacf9077eb1453a62bcefd6ab2df199acd28aad276ff0d920d6992892", "price_changes":[{"asset_id":"4394372887385518214471608448209527405727552777602031099972143344338178308080", "price":"0.17", "size":"27626.88", "side":"SELL", "hash":"3e208f3897732e0464ff2bd9b1cac87d82b56b28", "best_bid":"0.167", "best_ask":"0.168"}, {"asset_id":"112680630004798425069810935278212000865453267506345451433803052322987302357330", "price":"0.83", "size":"27626.88", "side":"BUY", "hash":"2833bbe004e08f146b126055853eaee031e43c28", "best_bid":"0.832", "best_ask":"0.833"}], "timestamp":"1780178995539", "event_type":"price_change"}
{"market":"0x0c4cd2055d6ea89354ffddc55d6dbcef9355748112ea952fc925f3db6a5c457f", "price_changes":[{"asset_id":"18812649149814341758733697580460697418474693998558159483117100240528657629879", "price":"0.088", "size":"15049.46", "side":"SELL", "hash":"29bc6dd3b0c7512b695227b08d5640e65ee8adc9", "best_bid":"0.085", "best_ask":"0.086"}, {"asset_id":"115428153746996892211798999366308897078723117634059783423375188043903703749062", "price":"0.912", "size":"15049.46", "side":"BUY", "hash":"237e05050abeae15916b13dcb4fb2bb4267460c5", "best_bid":"0.914", "best_ask":"0.915"}], "timestamp":"1780178995540", "event_type":"price_change"}
{"market":"0x30d55d8124ee1e12dabe89201badc45669b81dff69e4ce44d961f32878ec178a", "price_changes":[{"asset_id":"27576533317283401577758999384642760405921738493660383550832555714312627457443", "price":"0.092", "size":"78431.18", "side":"SELL", "hash":"694d26c1d3a8f256a86fb64787e0608b3510ad2c", "best_bid":"0.089", "best_ask":"0.09"}, {"asset_id":"52986718774908357330412653486471347449818893503063830313445318937088822580057", "price":"0.908", "size":"78431.18", "side":"BUY", "hash":"2320c3446547d9cf834fad1f90296982c7434235", "best_bid":"0.91", "best_ask":"0.911"}], "timestamp":"1780178995609", "event_type":"price_change"}
{"market":"0x1595b4818eeb1ea1e0bec5de6f057218e557feee9b405a0e930d290384fa1d16", "price_changes":[{"asset_id":"81739002353269632749850710185641576213562066971072676369728657545679630163887", "price":"0.053", "size":"3371.26", "side":"SELL", "hash":"7f199a5baefb5ae339238da9900e50bbda7db04e", "best_bid":"0.051", "best_ask":"0.052"}, {"asset_id":"45484070731786948288366703334552551439356529561722304542938873238430842810537", "price":"0.947", "size":"3371.26", "side":"BUY", "hash":"5dd2bb42f84315d8932597509c5cc6f3d767de09", "best_bid":"0.948", "best_ask":"0.949"}], "timestamp":"1780178995641", "event_type":"price_change"}
{"market":"0x7976b8dbacf9077eb1453a62bcefd6ab2df199acd28aad276ff0d920d6992892", "price_changes":[{"asset_id":"4394372887385518214471608448209527405727552777602031099972143344338178308080", "price":"0.17", "size":"27652.43", "side":"SELL", "hash":"c96cff99ff6a8a187ae1b90c168d45b33c0ebd38", "best_bid":"0.167", "best_ask":"0.168"}, {"asset_id":"112680630004798425069810935278212000865453267506345451433803052322987302357330", "price":"0.83", "size":"27652.43", "side":"BUY", "hash":"45b48d8f8dfc14d984ff628a928c35606e71f252", "best_bid":"0.832", "best_ask":"0.833"}], "timestamp":"1780178995643", "event_type":"price_change"}
{"market":"0x0c4cd2055d6ea89354ffddc55d6dbcef9355748112ea952fc925f3db6a5c457f", "price_changes":[{"asset_id":"18812649149814341758733697580460697418474693998558159483117100240528657629879", "price":"0.088", "size":"15129.46", "side":"SELL", "hash":"59ce01b5b91ead5642b2d96b086ba2198a4f513b", "best_bid":"0.085", "best_ask":"0.086"}, {"asset_id":"115428153746996892211798999366308897078723117634059783423375188043903703749062", "price":"0.912", "size":"15129.46", "side":"BUY", "hash":"a9327e184da82e07e26caf7acb08af55dadf1a8b", "best_bid":"0.914", "best_ask":"0.915"}], "timestamp":"1780178995643", "event_type":"price_change"}
{"id":"2397852", "question":"Heilbronn: Completed Match: Pavel Kotov vs Guy Den Ouden", "market":"0xfd91cbc7af618ad6e9565ed0d0878d72c96bbad54397b2f4a1a8acae70a49bb1", "slug":"atp-kotov-ouden-2026-06-01-completed-match", "description":"This market refers to the tennis match between Pavel Kotov and Guy Den Ouden in the Heilbronn, originally scheduled for June 1, 2026 at 5:00AM ET. This market will resolve to \"Yes\" if all games and sets required to determine a match winner under governing body or event organizer rules are played to completion through normal play. Otherwise, if the match is not completed for any reason, it will resolve to \"No.\" If a forfeit of any kind occurs, including but not limited to a walkover or retirement, this market will resolve \"No.\" If the match is canceled (not played at all), ends in a tie, or is delayed beyond 7 days from the scheduled date without a winner determined, this market will resolve to \"No.\" The primary resolution source for this market is the official statistics of the event as recognized by the governing body or event organizers. However, if the governing body or event organizers have not published final match statistics within 2 hours after the event's conclusion, a consensus of credible reporting may be used instead.", "assets_ids":["74634124842513978181990948964879374127322336549031322428490502539871744084263", "54630119443976806036546999638200237393789705798488407780198328186326911814505"], "outcomes":["Yes", "No"], "event_message":{"id":"542691", "ticker":"atp-kotov-ouden-2026-06-01", "slug":"atp-kotov-ouden-2026-06-01", "title":"Heilbronn: Pavel Kotov vs Guy Den Ouden", "description":"This market refers to the tennis match between Pavel Kotov and Guy Den Ouden in the Heilbronn, originally scheduled for June 1, 2026 at 5:00AM ET.\n\nThis market will resolve to 'Pavel Kotov' if Pavel Kotov advances against Guy Den Ouden.\n\nThis market will resolve to 'Guy Den Ouden' if Guy Den Ouden advances against Pavel Kotov.\n\nIf the match is canceled (not played at all), ends in a tie, or is delayed beyond 7 days from the scheduled date without a winner determined, this market will resolve to 50-50.\n\nIf the match begins but is not completed, and one player advances due to the opponent's retirement, default, or disqualification, this market will resolve to the player who advances.\n\nIf the match ends in a walkover (player withdraws before the start and the other advances automatically), this market will resolve to 50-50.\n\nThe primary resolution source will be official information from the ATP Tour. A consensus of credible reporting may also be used."}, "timestamp":"1780178996082", "event_type":"new_market", "tags":[], "condition_id":"0xfd91cbc7af618ad6e9565ed0d0878d72c96bbad54397b2f4a1a8acae70a49bb1", "active":false, "clob_token_ids":["74634124842513978181990948964879374127322336549031322428490502539871744084263", "54630119443976806036546999638200237393789705798488407780198328186326911814505"], "sports_market_type":"tennis_completed_match", "line":"", "game_start_time":"2026-06-01 09:00:00+00", "order_price_min_tick_size":"0.01", "group_item_title":"Completed Match", "taker_base_fee":"1000", "fees_enabled":true, "fee_schedule":{"exponent":"1", "rate":"0.03", "taker_only":true, "rebate_rate":"0.25"}}
{"id":"2397840", "question":"Heilbronn: Completed Match: Jan Choinski vs Tom Gentzsch", "market":"0xd62fe850b0a4e3950db57a41d401df8181b047b106a3c6ba7a24c0bffcc61638", "slug":"atp-choinsk-gentzsc-2026-06-01-completed-match", "description":"This market refers to the tennis match between Jan Choinski and Tom Gentzsch in the Heilbronn, originally scheduled for June 1, 2026 at 5:00AM ET. This market will resolve to \"Yes\" if all games and sets required to determine a match winner under governing body or event organizer rules are played to completion through normal play. Otherwise, if the match is not completed for any reason, it will resolve to \"No.\" If a forfeit of any kind occurs, including but not limited to a walkover or retirement, this market will resolve \"No.\" If the match is canceled (not played at all), ends in a tie, or is delayed beyond 7 days from the scheduled date without a winner determined, this market will resolve to \"No.\" The primary resolution source for this market is the official statistics of the event as recognized by the governing body or event organizers. However, if the governing body or event organizers have not published final match statistics within 2 hours after the event's conclusion, a consensus of credible reporting may be used instead.", "assets_ids":["112124545521795336153444636098497907075444997674444117470215143472149165847519", "2651960651055301785157319533106491848238256259935088128851700072963172389011"], "outcomes":["Yes", "No"], "event_message":{"id":"542685", "ticker":"atp-choinsk-gentzsc-2026-06-01", "slug":"atp-choinsk-gentzsc-2026-06-01", "title":"Heilbronn: Jan Choinski vs Tom Gentzsch", "description":"This market refers to the tennis match between Jan Choinski and Tom Gentzsch in the Heilbronn, originally scheduled for June 1, 2026 at 5:00AM ET.\n\nThis market will resolve to 'Jan Choinski' if Jan Choinski advances against Tom Gentzsch.\n\nThis market will resolve to 'Tom Gentzsch' if Tom Gentzsch advances against Jan Choinski.\n\nIf the match is canceled (not played at all), ends in a tie, or is delayed beyond 7 days from the scheduled date without a winner determined, this market will resolve to 50-50.\n\nIf the match begins but is not completed, and one player advances due to the opponent's retirement, default, or disqualification, this market will resolve to the player who advances.\n\nIf the match ends in a walkover (player withdraws before the start and the other advances automatically), this market will resolve to 50-50.\n\nThe primary resolution source will be official information from the ATP Tour. A consensus of credible reporting may also be used."}, "timestamp":"1780178996404", "event_type":"new_market", "tags":[], "condition_id":"0xd62fe850b0a4e3950db57a41d401df8181b047b106a3c6ba7a24c0bffcc61638", "active":false, "clob_token_ids":["112124545521795336153444636098497907075444997674444117470215143472149165847519", "2651960651055301785157319533106491848238256259935088128851700072963172389011"], "sports_market_type":"tennis_completed_match", "line":"", "game_start_time":"2026-06-01 09:00:00+00", "order_price_min_tick_size":"0.01", "group_item_title":"Completed Match", "taker_base_fee":"1000", "fees_enabled":true, "fee_schedule":{"exponent":"1", "rate":"0.03", "taker_only":true, "rebate_rate":"0.25"}}
{"market":"0x9b6fef249040fd17e9c107955b37ac2c3e923509b6b0ff01cc463a331ddeb894", "price_changes":[{"asset_id":"108233603819467706476318984012158651931658302669301887462181073562758483842092", "price":"0.166", "size":"24926.68", "side":"SELL", "hash":"e485edd014c35790f88da7f0a82674149c142f03", "best_bid":"0.163", "best_ask":"0.164"}, {"asset_id":"32270411694523539495262303868629477861017829722282576458031815333486368239544", "price":"0.834", "size":"24926.68", "side":"BUY", "hash":"d9671933532204bcd5e360fa134dd34357870236", "best_bid":"0.836", "best_ask":"0.837"}], "timestamp":"1780178997584", "event_type":"price_change"}
{"market":"0x375409bc5eeeff961e82b479caeccc20f33d15738e5bce1186d628aa3d9dfb1f", "price_changes":[{"asset_id":"115556263888245616435851357148058235707004733438163639091106356867234218207169", "price":"0.115", "size":"11999.15", "side":"SELL", "hash":"6d597a09e5c74e8c63ed4e9fac7e54d88e9c8ec1", "best_bid":"0.112", "best_ask":"0.113"}, {"asset_id":"77121637225348873006259930776623502125079210522997384841464684944292365296940", "price":"0.885", "size":"11999.15", "side":"BUY", "hash":"ce512c4f384fb90590a79e856e12f40209da3b6c", "best_bid":"0.887", "best_ask":"0.888"}], "timestamp":"1780178997638", "event_type":"price_change"}
{"market":"0x9b6fef249040fd17e9c107955b37ac2c3e923509b6b0ff01cc463a331ddeb894", "price_changes":[{"asset_id":"108233603819467706476318984012158651931658302669301887462181073562758483842092", "price":"0.166", "size":"25006.68", "side":"SELL", "hash":"df15e9b4815088cf2f476489bc8863ed560baf92", "best_bid":"0.163", "best_ask":"0.164"}, {"asset_id":"32270411694523539495262303868629477861017829722282576458031815333486368239544", "price":"0.834", "size":"25006.68", "side":"BUY", "hash":"5b1b62eb0c08a2395eb8822536926745e38f8782", "best_bid":"0.836", "best_ask":"0.837"}], "timestamp":"1780178997678", "event_type":"price_change"}
{"market":"0x375409bc5eeeff961e82b479caeccc20f33d15738e5bce1186d628aa3d9dfb1f", "price_changes":[{"asset_id":"115556263888245616435851357148058235707004733438163639091106356867234218207169", "price":"0.115", "size":"12079.15", "side":"SELL", "hash":"026d780a5b2475e99602de95f571bc858aa8aede", "best_bid":"0.112", "best_ask":"0.113"}, {"asset_id":"77121637225348873006259930776623502125079210522997384841464684944292365296940", "price":"0.885", "size":"12079.15", "side":"BUY", "hash":"2703caf914f15a4dcc36955833cd69176dc6a531", "best_bid":"0.887", "best_ask":"0.888"}], "timestamp":"1780178997771", "event_type":"price_change"}
{"market":"0x4f3421fb2daf5cca7430ed8d8132463963081572d75434393a1808fdb8829fe8", "price_changes":[{"asset_id":"45415751658241142530386585138386640503488308219341470020075667342738719018629", "price":"0.103", "size":"18202.51", "side":"SELL", "hash":"4c56ec4e86ceca94e1451d4b7b4b17b4c3c737f5", "best_bid":"0.1", "best_ask":"0.101"}, {"asset_id":"31940783580344558651011323787577288681658737625185216525249046282994042503801", "price":"0.897", "size":"18202.51", "side":"BUY", "hash":"6e0bfa5a20eb53e985250cf54a42f062991815fe", "best_bid":"0.899", "best_ask":"0.9"}], "timestamp":"1780178998001", "event_type":"price_change"}
{"market":"0x4f3421fb2daf5cca7430ed8d8132463963081572d75434393a1808fdb8829fe8", "price_changes":[{"asset_id":"45415751658241142530386585138386640503488308219341470020075667342738719018629", "price":"0.103", "size":"18263.31", "side":"SELL", "hash":"cfd3581ad4857c80acd90eb6b6749154c8b445eb", "best_bid":"0.1", "best_ask":"0.101"}, {"asset_id":"31940783580344558651011323787577288681658737625185216525249046282994042503801", "price":"0.897", "size":"18263.31", "side":"BUY", "hash":"f48866c280e2225964e87b298f566a57935d345d", "best_bid":"0.899", "best_ask":"0.9"}], "timestamp":"1780178998100", "event_type":"price_change"}
{"id":"2397781", "question":"Birmingham: Mattia Bellucci vs Alex Bolt", "market":"0x447a77ff31430eeb2a3e1b60cc6c8703c062d3d997816582fa598614701a18b4", "slug":"atp-bellucc-bolt-2026-06-01", "description":"This market refers to the tennis match between Mattia Bellucci and Alex Bolt in the Birmingham, originally scheduled for June 1, 2026 at 5:30AM ET.\n\nThis market will resolve to 'Mattia Bellucci' if Mattia Bellucci advances against Alex Bolt.\n\nThis market will resolve to 'Alex Bolt' if Alex Bolt advances against Mattia Bellucci.\n\nIf the match is canceled (not played at all), ends in a tie, or is delayed beyond 7 days from the scheduled date without a winner determined, this market will resolve to 50-50.\n\nIf the match begins but is not completed, and one player advances due to the opponent's retirement, default, or disqualification, this market will resolve to the player who advances.\n\nIf the match ends in a walkover (player withdraws before the start and the other advances automatically), this market will resolve to 50-50.\n\nThe primary resolution source will be official information from the ATP Tour. A consensus of credible reporting may also be used.", "assets_ids":["46546742241474235982699312886275854846328556990387328269019280229794152545156", "5283333582746621079620140721864597609577344088131616067656963137513976276880"], "outcomes":["Mattia Bellucci", "Alex Bolt"], "event_message":{"id":"542661", "ticker":"atp-bellucc-bolt-2026-06-01", "slug":"atp-bellucc-bolt-2026-06-01", "title":"Birmingham: Mattia Bellucci vs Alex Bolt", "description":"This market refers to the tennis match between Mattia Bellucci and Alex Bolt in the Birmingham, originally scheduled for June 1, 2026 at 5:30AM ET.\n\nThis market will resolve to 'Mattia Bellucci' if Mattia Bellucci advances against Alex Bolt.\n\nThis market will resolve to 'Alex Bolt' if Alex Bolt advances against Mattia Bellucci.\n\nIf the match is canceled (not played at all), ends in a tie, or is delayed beyond 7 days from the scheduled date without a winner determined, this market will resolve to 50-50.\n\nIf the match begins but is not completed, and one player advances due to the opponent's retirement, default, or disqualification, this market will resolve to the player who advances.\n\nIf the match ends in a walkover (player withdraws before the start and the other advances automatically), this market will resolve to 50-50.\n\nThe primary resolution source will be official information from the ATP Tour. A consensus of credible reporting may also be used."}, "timestamp":"1780178998104", "event_type":"new_market", "tags":[], "condition_id":"0x447a77ff31430eeb2a3e1b60cc6c8703c062d3d997816582fa598614701a18b4", "active":false, "clob_token_ids":["46546742241474235982699312886275854846328556990387328269019280229794152545156", "5283333582746621079620140721864597609577344088131616067656963137513976276880"], "sports_market_type":"moneyline", "line":"", "game_start_time":"2026-06-01 09:30:00+00", "order_price_min_tick_size":"0.01", "group_item_title":"", "taker_base_fee":"1000", "fees_enabled":true, "fee_schedule":{"exponent":"1", "rate":"0.03", "taker_only":true, "rebate_rate":"0.25"}}
{"id":"2397710", "question":"Fight to Go the Distance?", "market":"0x9518df7d6863320acc6bede604d2889facee9b0d8eb2fb3725bc39f5ef57441a", "slug":"ufc-mel2-mur2-2026-06-20-go-the-distance", "description":"This market will resolve to \"Yes\" if the fight between Melsik Baghdasaryan and Murtazali Magomedov at UFC Fight Night: Kape vs. Horiguchi, scheduled for June 20, 2026, goes the full scheduled number of rounds and the result is determined by the judges' scorecards. Otherwise, it will resolve to \"No.\"\n\nDraws decided by the judges' scorecards after all scheduled rounds are completed will resolve \"Yes.\" Technical decisions or technical draws declared before all rounds are completed will resolve \"No.\"\n\nIf the bout is ruled a No Contest, not scored, canceled, or postponed beyond July 4, 2026, this market will resolve \"50-50.\"\n\nThe resolution source for this market will be official information from the UFC.", "assets_ids":["13441523265980325159417927352016056624901666634548424942397181571079243122808", "77996420494021390007211512337414488845727211205593010021517808505856471348205"], "outcomes":["Yes", "No"], "event_message":{"id":"542639", "ticker":"ufc-mel2-mur2-2026-06-20", "slug":"ufc-mel2-mur2-2026-06-20", "title":"UFC Fight Night: Melsik Baghdasaryan vs. Murtazali Magomedov (Featherweight, Main Card)", "description":"This market will resolve to \"Melsik Baghdasaryan\" if Melsik Baghdasaryan is officially declared the winner of the fight against Murtazali Magomedov at UFC Fight Night: Kape vs. Horiguchi, scheduled for June 20, 2026.\n\nIt will resolve to \"Murtazali Magomedov\" if Murtazali Magomedov is officially declared the winner.\n\nIf the fight is declared a draw or technical draw, ruled a No Contest, not scored, canceled, or postponed beyond July 4, 2026, this market will resolve \"50-50.\"\n\nThe resolution source for this market will be official information from the UFC."}, "timestamp":"1780178999073", "event_type":"new_market", "tags":[], "condition_id":"0x9518df7d6863320acc6bede604d2889facee9b0d8eb2fb3725bc39f5ef57441a", "active":false, "clob_token_ids":["13441523265980325159417927352016056624901666634548424942397181571079243122808", "77996420494021390007211512337414488845727211205593010021517808505856471348205"], "sports_market_type":"ufc_go_the_distance", "line":"", "game_start_time":"2026-06-20 17:00:00+00", "order_price_min_tick_size":"0.01", "group_item_title":"Fight to Go the Distance?", "taker_base_fee":"1000", "fees_enabled":true, "fee_schedule":{"exponent":"1", "rate":"0.03", "taker_only":true, "rebate_rate":"0.25"}}
{"market":"0x7976b8dbacf9077eb1453a62bcefd6ab2df199acd28aad276ff0d920d6992892", "price_changes":[{"asset_id":"112680630004798425069810935278212000865453267506345451433803052322987302357330", "price":"0.421", "size":"566.22", "side":"BUY", "hash":"8f32a6c2addbd0b0996ed57a80c2d7a889797f92", "best_bid":"0.832", "best_ask":"0.833"}, {"asset_id":"4394372887385518214471608448209527405727552777602031099972143344338178308080", "price":"0.579", "size":"566.22", "side":"SELL", "hash":"5439e126750d6e2ba4bec5490b6035f9b870cb30", "best_bid":"0.167", "best_ask":"0.168"}], "timestamp":"1780179001023", "event_type":"price_change"}
PONG
{"id":"2397886", "question":"XRP Up or Down - May 31, 6:00PM-6:15PM ET", "market":"0x53b19fa7681c80c9a089958a6561b5020115ae842d12e5fcb091e4b442cc44e5", "slug":"xrp-updown-15m-1780264800", "description":"This market will resolve to \"Up\" if the XRP price at the end of the time range specified in the title is greater than or equal to the price at the beginning of that range. Otherwise, it will resolve to \"Down\".\nThe resolution source for this market is information from Chainlink, specifically the XRP/USD data stream available at https://data.chain.link/streams/xrp-usd.\nPlease note that this market is about the price according to Chainlink data stream XRP/USD, not according to other sources or spot markets.", "assets_ids":["100603934844826627572134818948003595853043811357250221755800170938208461449526", "1731863427536977778613089466438936321074295582181752873242527865142328686013"], "outcomes":["Up", "Down"], "event_message":{"id":"542708", "ticker":"xrp-updown-15m-1780264800", "slug":"xrp-updown-15m-1780264800", "title":"XRP Up or Down - May 31, 6:00PM-6:15PM ET", "description":"This market will resolve to \"Up\" if the XRP price at the end of the time range specified in the title is greater than or equal to the price at the beginning of that range. Otherwise, it will resolve to \"Down\".\nThe resolution source for this market is information from Chainlink, specifically the XRP/USD data stream available at https://data.chain.link/streams/xrp-usd.\nPlease note that this market is about the price according to Chainlink data stream XRP/USD, not according to other sources or spot markets."}, "timestamp":"1780179001218", "event_type":"new_market", "tags":[], "condition_id":"0x53b19fa7681c80c9a089958a6561b5020115ae842d12e5fcb091e4b442cc44e5", "active":false, "clob_token_ids":["100603934844826627572134818948003595853043811357250221755800170938208461449526", "1731863427536977778613089466438936321074295582181752873242527865142328686013"], "sports_market_type":"", "line":"", "game_start_time":"", "order_price_min_tick_size":"0.01", "group_item_title":"", "taker_base_fee":"1000", "fees_enabled":true, "fee_schedule":{"exponent":"1", "rate":"0.07", "taker_only":true, "rebate_rate":"0.2"}}
{"id":"2397754", "question":"O/U 2.5 Rounds", "market":"0x64c4341812a1438498dd880eed1e030f7228c8c7cf063f3cc12ef9685ab578bc", "slug":"ufc-all2-mit2-2026-06-20-totals-2pt5", "description":"Each market will resolve to \"Over\" if the fight between Allan Nascimento and Mitch Raposo at UFC Fight Night: Kape vs. Horiguchi, scheduled for June 20, 2026, lasts beyond the listed round threshold.\n\nEach market will resolve to \"Under\" if the fight does not last beyond the listed round threshold.\n\nFor example:\n\n\"Over 2.5 Rounds\" will resolve \"Yes\" if the fight continues past the 2:30 mark of Round 3.\n\n\"Under 2.5 Rounds\" will resolve \"Yes\" if the fight ends before the 2:30 mark of Round 3.\n\nIf the fight ends exactly at the threshold, it will resolve \"50-50.\"\n\nIf the bout is not scored, postponed beyond July 4, 2026, or canceled, all options will resolve \"50-50.\"\n\nThe resolution source for this market will be official information from the UFC.", "assets_ids":["40328349595188766660691390431874479364666122848603184367890573102084807862721", "16862313034937194748683336050812361740790700384031556606034325141408010595816"], "outcomes":["Over", "Under"], "event_message":{"id":"542649", "ticker":"ufc-all2-mit2-2026-06-20", "slug":"ufc-all2-mit2-2026-06-20", "title":"UFC Fight Night: Allan Nascimento vs. Mitch Raposo (Flyweight, Prelims)", "description":"This market will resolve to \"Allan Nascimento\" if Allan Nascimento is officially declared the winner of the fight against Mitch Raposo at UFC Fight Night: Kape vs. Horiguchi, scheduled for June 20, 2026.\n\nIt will resolve to \"Mitch Raposo\" if Mitch Raposo is officially declared the winner.\n\nIf the fight is declared a draw or technical draw, ruled a No Contest, not scored, canceled, or postponed beyond July 4, 2026, this market will resolve \"50-50.\"\n\nThe resolution source for this market will be official information from the UFC."}, "timestamp":"1780179001461", "event_type":"new_market", "tags":[], "condition_id":"0x64c4341812a1438498dd880eed1e030f7228c8c7cf063f3cc12ef9685ab578bc", "active":false, "clob_token_ids":["40328349595188766660691390431874479364666122848603184367890573102084807862721", "16862313034937194748683336050812361740790700384031556606034325141408010595816"], "sports_market_type":"totals", "line":"2.5", "game_start_time":"2026-06-20 17:00:00+00", "order_price_min_tick_size":"0.01", "group_item_title":"O/U 2.5 Rounds", "taker_base_fee":"1000", "fees_enabled":true, "fee_schedule":{"exponent":"1", "rate":"0.03", "taker_only":true, "rebate_rate":"0.25"}}
{"market":"0x30d55d8124ee1e12dabe89201badc45669b81dff69e4ce44d961f32878ec178a", "price_changes":[{"asset_id":"52986718774908357330412653486471347449818893503063830313445318937088822580057", "price":"0.4", "size":"34375", "side":"BUY", "hash":"be24d08c287d1d141dd91c96c199f8b55a3f055e", "best_bid":"0.91", "best_ask":"0.911"}, {"asset_id":"27576533317283401577758999384642760405921738493660383550832555714312627457443", "price":"0.6", "size":"34375", "side":"SELL", "hash":"4183c96e1c66fa962b904db17c3753729936d080", "best_bid":"0.089", "best_ask":"0.09"}], "timestamp":"1780179007009", "event_type":"price_change"}
{"market":"0x0c4cd2055d6ea89354ffddc55d6dbcef9355748112ea952fc925f3db6a5c457f", "price_changes":[{"asset_id":"115428153746996892211798999366308897078723117634059783423375188043903703749062", "price":"0.05", "size":"60", "side":"BUY", "hash":"32d8b1eecb91ea9fd45e357bc8e8cacc2040c727", "best_bid":"0.914", "best_ask":"0.915"}, {"asset_id":"18812649149814341758733697580460697418474693998558159483117100240528657629879", "price":"0.95", "size":"60", "side":"SELL", "hash":"7db0d18e2d02ffe2bdac4a30731dad8195312a35", "best_bid":"0.085", "best_ask":"0.086"}], "timestamp":"1780179007013", "event_type":"price_change"}
{"market":"0x1595b4818eeb1ea1e0bec5de6f057218e557feee9b405a0e930d290384fa1d16", "price_changes":[{"asset_id":"45484070731786948288366703334552551439356529561722304542938873238430842810537", "price":"0.2", "size":"0", "side":"BUY", "hash":"2fe9175d00ddf16ecfe5b3da9ed5009082ebc77a", "best_bid":"0.948", "best_ask":"0.949"}, {"asset_id":"81739002353269632749850710185641576213562066971072676369728657545679630163887", "price":"0.8", "size":"0", "side":"SELL", "hash":"e8a6e16df65dd086d3ea541f93bdfb1b31f87a39", "best_bid":"0.051", "best_ask":"0.052"}], "timestamp":"1780179007020", "event_type":"price_change"}
{"market":"0x1595b4818eeb1ea1e0bec5de6f057218e557feee9b405a0e930d290384fa1d16", "price_changes":[{"asset_id":"45484070731786948288366703334552551439356529561722304542938873238430842810537", "price":"0.3", "size":"0", "side":"BUY", "hash":"2fe9175d00ddf16ecfe5b3da9ed5009082ebc77a", "best_bid":"0.948", "best_ask":"0.949"}, {"asset_id":"81739002353269632749850710185641576213562066971072676369728657545679630163887", "price":"0.7", "size":"0", "side":"SELL", "hash":"e8a6e16df65dd086d3ea541f93bdfb1b31f87a39", "best_bid":"0.051", "best_ask":"0.052"}], "timestamp":"1780179007020", "event_type":"price_change"}
{"market":"0x375409bc5eeeff961e82b479caeccc20f33d15738e5bce1186d628aa3d9dfb1f", "price_changes":[{"asset_id":"77121637225348873006259930776623502125079210522997384841464684944292365296940", "price":"0.2", "size":"0", "side":"BUY", "hash":"b01a8a4f3d536761564fea93ee888022ab13be3c", "best_bid":"0.887", "best_ask":"0.888"}, {"asset_id":"115556263888245616435851357148058235707004733438163639091106356867234218207169", "price":"0.8", "size":"0", "side":"SELL", "hash":"5f7f269ba275cd667e2b944f21a012923b8a5f7a", "best_bid":"0.112", "best_ask":"0.113"}], "timestamp":"1780179007008", "event_type":"price_change"}
{"market":"0x375409bc5eeeff961e82b479caeccc20f33d15738e5bce1186d628aa3d9dfb1f", "price_changes":[{"asset_id":"77121637225348873006259930776623502125079210522997384841464684944292365296940", "price":"0.4", "size":"35775", "side":"BUY", "hash":"f1d27c1a43b2fe596386d709f1f15f2e680c1bd6", "best_bid":"0.887", "best_ask":"0.888"}, {"asset_id":"115556263888245616435851357148058235707004733438163639091106356867234218207169", "price":"0.6", "size":"35775", "side":"SELL", "hash":"add3fd62b30ade693fde05e085ca01ff02ff1d47", "best_bid":"0.112", "best_ask":"0.113"}], "timestamp":"1780179007009", "event_type":"price_change"}
{"market":"0x1595b4818eeb1ea1e0bec5de6f057218e557feee9b405a0e930d290384fa1d16", "price_changes":[{"asset_id":"45484070731786948288366703334552551439356529561722304542938873238430842810537", "price":"0.4", "size":"34375", "side":"BUY", "hash":"4bfe83575fa97b8a0ee2348a68a333536f27a978", "best_bid":"0.948", "best_ask":"0.949"}, {"asset_id":"81739002353269632749850710185641576213562066971072676369728657545679630163887", "price":"0.6", "size":"34375", "side":"SELL", "hash":"b51bab4076bf1195dc7f66173875fbbbed3db50b", "best_bid":"0.051", "best_ask":"0.052"}], "timestamp":"1780179007021", "event_type":"price_change"}
{"market":"0x7876851632c295043c66536150a304cb785abdf712ba8489d298c6e6926be106", "price_changes":[{"asset_id":"19291692040378529618917910599727571242305935029274321291612270922648172794670", "price":"0.4", "size":"34375", "side":"BUY", "hash":"94622dc93a04544d20a26aa4b6f0a16b64e87611", "best_bid":"0.989", "best_ask":"0.99"}, {"asset_id":"97239126062673310243763617236644392945530356142765650402171508075574679292913", "price":"0.6", "size":"34375", "side":"SELL", "hash":"ae15b27e649f5895e4cee44eaf8cfd7f40db4850", "best_bid":"0.01", "best_ask":"0.011"}], "timestamp":"1780179007020", "event_type":"price_change"}
{"market":"0x4f3421fb2daf5cca7430ed8d8132463963081572d75434393a1808fdb8829fe8", "price_changes":[{"asset_id":"31940783580344558651011323787577288681658737625185216525249046282994042503801", "price":"0.02", "size":"0", "side":"BUY", "hash":"c6e0caaa7bd7ca422dee86b79e8a6d2b13ce1fe6", "best_bid":"0.899", "best_ask":"0.9"}, {"asset_id":"45415751658241142530386585138386640503488308219341470020075667342738719018629", "price":"0.98", "size":"0", "side":"SELL", "hash":"e4262988745320f4457e62ef821e772faea0ec22", "best_bid":"0.1", "best_ask":"0.101"}], "timestamp":"1780179007019", "event_type":"price_change"}
{"market":"0x375409bc5eeeff961e82b479caeccc20f33d15738e5bce1186d628aa3d9dfb1f", "price_changes":[{"asset_id":"77121637225348873006259930776623502125079210522997384841464684944292365296940", "price":"0.1", "size":"491.34", "side":"BUY", "hash":"673f0ac1c2ccf50a9038e9f740d3fc3baf9b23b0", "best_bid":"0.887", "best_ask":"0.888"}, {"asset_id":"115556263888245616435851357148058235707004733438163639091106356867234218207169", "price":"0.9", "size":"491.34", "side":"SELL", "hash":"2e8f9af533a0fd90b845d48ea57e7a5421db7e30", "best_bid":"0.112", "best_ask":"0.113"}], "timestamp":"1780179007010", "event_type":"price_change"}
{"market":"0x375409bc5eeeff961e82b479caeccc20f33d15738e5bce1186d628aa3d9dfb1f", "price_changes":[{"asset_id":"77121637225348873006259930776623502125079210522997384841464684944292365296940", "price":"0.3", "size":"2374.99", "side":"BUY", "hash":"af60d09df2000c44f5cbae92771841ffbaffc6b2", "best_bid":"0.887", "best_ask":"0.888"}, {"asset_id":"115556263888245616435851357148058235707004733438163639091106356867234218207169", "price":"0.7", "size":"2374.99", "side":"SELL", "hash":"df29aa0b38b70fe2c74bbed76a9f38ff89a0d2f8", "best_bid":"0.112", "best_ask":"0.113"}], "timestamp":"1780179007018", "event_type":"price_change"}
{"market":"0x7876851632c295043c66536150a304cb785abdf712ba8489d298c6e6926be106", "price_changes":[{"asset_id":"97239126062673310243763617236644392945530356142765650402171508075574679292913", "price":"0.011", "size":"1818525.69", "side":"SELL", "hash":"ae15b27e649f5895e4cee44eaf8cfd7f40db4850", "best_bid":"0.01", "best_ask":"0.011"}, {"asset_id":"19291692040378529618917910599727571242305935029274321291612270922648172794670", "price":"0.989", "size":"1818525.69", "side":"BUY", "hash":"94622dc93a04544d20a26aa4b6f0a16b64e87611", "best_bid":"0.989", "best_ask":"0.99"}], "timestamp":"1780179007020", "event_type":"price_change"}
{"market":"0x0c4cd2055d6ea89354ffddc55d6dbcef9355748112ea952fc925f3db6a5c457f", "price_changes":[{"asset_id":"115428153746996892211798999366308897078723117634059783423375188043903703749062", "price":"0.05", "size":"60", "side":"BUY", "hash":"9249fc11579290f532e1a0eb75148bf5f8dfe264", "best_bid":"0.914", "best_ask":"0.915"}, {"asset_id":"18812649149814341758733697580460697418474693998558159483117100240528657629879", "price":"0.95", "size":"60", "side":"SELL", "hash":"809afc483061403c3fa815be6ab0df6c84ecebb7", "best_bid":"0.085", "best_ask":"0.086"}], "timestamp":"1780179007020", "event_type":"price_change"}
{"market":"0x4f3421fb2daf5cca7430ed8d8132463963081572d75434393a1808fdb8829fe8", "price_changes":[{"asset_id":"31940783580344558651011323787577288681658737625185216525249046282994042503801", "price":"0.02", "size":"0", "side":"BUY", "hash":"852c9334e969e3c3d958bed5642192d61d884aaf", "best_bid":"0.899", "best_ask":"0.9"}, {"asset_id":"45415751658241142530386585138386640503488308219341470020075667342738719018629", "price":"0.98", "size":"0", "side":"SELL", "hash":"ca41bc00c68559f5f96a1a9fdb4638948fd044e4", "best_bid":"0.1", "best_ask":"0.101"}], "timestamp":"1780179007020", "event_type":"price_change"}
{"market":"0x7876851632c295043c66536150a304cb785abdf712ba8489d298c6e6926be106", "price_changes":[{"asset_id":"19291692040378529618917910599727571242305935029274321291612270922648172794670", "price":"0.3", "size":"0", "side":"BUY", "hash":"cf8ad9da495faf8cac59f60496493993c5c4b22a", "best_bid":"0.989", "best_ask":"0.99"}, {"asset_id":"97239126062673310243763617236644392945530356142765650402171508075574679292913", "price":"0.7", "size":"0", "side":"SELL", "hash":"975b1f79292266e7b3081c507b7d5064a5d28182", "best_bid":"0.01", "best_ask":"0.011"}], "timestamp":"1780179007021", "event_type":"price_change"}
{"market":"0x30d55d8124ee1e12dabe89201badc45669b81dff69e4ce44d961f32878ec178a", "price_changes":[{"asset_id":"52986718774908357330412653486471347449818893503063830313445318937088822580057", "price":"0.1", "size":"0", "side":"BUY", "hash":"92e4629a115b9290b81c8b7c9434693534b57e14", "best_bid":"0.91", "best_ask":"0.911"}, {"asset_id":"27576533317283401577758999384642760405921738493660383550832555714312627457443", "price":"0.9", "size":"0", "side":"SELL", "hash":"25c3721248ac353afe5b63d94daa26d74f2adcd4", "best_bid":"0.089", "best_ask":"0.09"}], "timestamp":"1780179007017", "event_type":"price_change"}
{"market":"0x30d55d8124ee1e12dabe89201badc45669b81dff69e4ce44d961f32878ec178a", "price_changes":[{"asset_id":"52986718774908357330412653486471347449818893503063830313445318937088822580057", "price":"0.2", "size":"0", "side":"BUY", "hash":"54926acecd80888bf206aeae238501a19ecbfa69", "best_bid":"0.91", "best_ask":"0.911"}, {"asset_id":"27576533317283401577758999384642760405921738493660383550832555714312627457443", "price":"0.8", "size":"0", "side":"SELL", "hash":"7fa4ec6188c39780ad78344cbdab99904b4da9a1", "best_bid":"0.089", "best_ask":"0.09"}], "timestamp":"1780179007029", "event_type":"price_change"}
{"market":"0x1595b4818eeb1ea1e0bec5de6f057218e557feee9b405a0e930d290384fa1d16", "price_changes":[{"asset_id":"45484070731786948288366703334552551439356529561722304542938873238430842810537", "price":"0.1", "size":"0", "side":"BUY", "hash":"21dd6fd6336a4773af621c67ffe734dab8cd3ecb", "best_bid":"0.948", "best_ask":"0.949"}, {"asset_id":"81739002353269632749850710185641576213562066971072676369728657545679630163887", "price":"0.9", "size":"0", "side":"SELL", "hash":"1cbae1844b236cd13c54f03192b649a2a7a19287", "best_bid":"0.051", "best_ask":"0.052"}], "timestamp":"1780179007028", "event_type":"price_change"}
{"market":"0x30d55d8124ee1e12dabe89201badc45669b81dff69e4ce44d961f32878ec178a", "price_changes":[{"asset_id":"52986718774908357330412653486471347449818893503063830313445318937088822580057", "price":"0.3", "size":"5", "side":"BUY", "hash":"52e470fcc0e2a26d4b0a485fbf0346326096d6ff", "best_bid":"0.91", "best_ask":"0.911"}, {"asset_id":"27576533317283401577758999384642760405921738493660383550832555714312627457443", "price":"0.7", "size":"5", "side":"SELL", "hash":"d283ee8e909feb117b2183c28990091e5fbad0f1", "best_bid":"0.089", "best_ask":"0.09"}], "timestamp":"1780179007030", "event_type":"price_change"}
{"market":"0x0c4cd2055d6ea89354ffddc55d6dbcef9355748112ea952fc925f3db6a5c457f", "price_changes":[{"asset_id":"115428153746996892211798999366308897078723117634059783423375188043903703749062", "price":"0.05", "size":"60", "side":"BUY", "hash":"a83a48cf225e759342844637bb488736340c0d36", "best_bid":"0.914", "best_ask":"0.915"}, {"asset_id":"18812649149814341758733697580460697418474693998558159483117100240528657629879", "price":"0.95", "size":"60", "side":"SELL", "hash":"230c7270d8a3adb5ce3ac23017b2cd5b174a1514", "best_bid":"0.085", "best_ask":"0.086"}], "timestamp":"1780179007021", "event_type":"price_change"}
{"market":"0x0c4cd2055d6ea89354ffddc55d6dbcef9355748112ea952fc925f3db6a5c457f", "price_changes":[{"asset_id":"115428153746996892211798999366308897078723117634059783423375188043903703749062", "price":"0.05", "size":"60", "side":"BUY", "hash":"5e6e2c27e0893547c7abebfc3aa3d078ec1151a8", "best_bid":"0.914", "best_ask":"0.915"}, {"asset_id":"18812649149814341758733697580460697418474693998558159483117100240528657629879", "price":"0.95", "size":"60", "side":"SELL", "hash":"ded27ee52ce7830a02c128776e16715b0e22584a", "best_bid":"0.085", "best_ask":"0.086"}], "timestamp":"1780179007032", "event_type":"price_change"}
{"market":"0x7876851632c295043c66536150a304cb785abdf712ba8489d298c6e6926be106", "price_changes":[{"asset_id":"19291692040378529618917910599727571242305935029274321291612270922648172794670", "price":"0.2", "size":"0", "side":"BUY", "hash":"3d5031901e8b4b143d72d066bc61863085df68d0", "best_bid":"0.989", "best_ask":"0.99"}, {"asset_id":"97239126062673310243763617236644392945530356142765650402171508075574679292913", "price":"0.8", "size":"0", "side":"SELL", "hash":"e7fdac102c10ceba501aabb7dbe1f61a70de0e9a", "best_bid":"0.01", "best_ask":"0.011"}], "timestamp":"1780179007032", "event_type":"price_change"}
{"market":"0x4f3421fb2daf5cca7430ed8d8132463963081572d75434393a1808fdb8829fe8", "price_changes":[{"asset_id":"31940783580344558651011323787577288681658737625185216525249046282994042503801", "price":"0.02", "size":"0", "side":"BUY", "hash":"6a50e0197decdb887183de2a18e43fecb959da45", "best_bid":"0.899", "best_ask":"0.9"}, {"asset_id":"45415751658241142530386585138386640503488308219341470020075667342738719018629", "price":"0.98", "size":"0", "side":"SELL", "hash":"92d0a4772f70905e7e085f443912b6b197de7dc9", "best_bid":"0.1", "best_ask":"0.101"}], "timestamp":"1780179007032", "event_type":"price_change"}
{"market":"0x7876851632c295043c66536150a304cb785abdf712ba8489d298c6e6926be106", "price_changes":[{"asset_id":"19291692040378529618917910599727571242305935029274321291612270922648172794670", "price":"0.1", "size":"0", "side":"BUY", "hash":"fdbe3e638957c038347709cdbfae28dfa1086b1c", "best_bid":"0.989", "best_ask":"0.99"}, {"asset_id":"97239126062673310243763617236644392945530356142765650402171508075574679292913", "price":"0.9", "size":"0", "side":"SELL", "hash":"2f9515dc2580b61e47cd328cd7a5b40166da28f1", "best_bid":"0.01", "best_ask":"0.011"}], "timestamp":"1780179007033", "event_type":"price_change"}
{"market":"0x4f3421fb2daf5cca7430ed8d8132463963081572d75434393a1808fdb8829fe8", "price_changes":[{"asset_id":"31940783580344558651011323787577288681658737625185216525249046282994042503801", "price":"0.02", "size":"0", "side":"BUY", "hash":"5413fb43cdfab28aceef3781ef4615b66f9d0c20", "best_bid":"0.899", "best_ask":"0.9"}, {"asset_id":"45415751658241142530386585138386640503488308219341470020075667342738719018629", "price":"0.98", "size":"0", "side":"SELL", "hash":"686d9f55a060ed189faab5d537ab303814856731", "best_bid":"0.1", "best_ask":"0.101"}], "timestamp":"1780179007033", "event_type":"price_change"}
{"id":"2397706", "question":"ITF Men Brcko: Completed Match: Josip Simundza vs Matyas Fuele", "market":"0x0fae505acdd5571d812232d154120be5803dc19ba799cfbb665b69b80900bbad", "slug":"itf-simundz-fuele-2026-05-31-completed-match", "description":"This market refers to the tennis match between Josip Simundza and Matyas Fuele in the ITF Men Brcko, originally scheduled for May 31, 2026 at 6:00AM ET. This market will resolve to \"Yes\" if all games and sets required to determine a match winner under governing body or event organizer rules are played to completion through normal play. Otherwise, if the match is not completed for any reason, it will resolve to \"No.\" If a forfeit of any kind occurs, including but not limited to a walkover or retirement, this market will resolve \"No.\" If the match is canceled (not played at all), ends in a tie, or is delayed beyond 7 days from the scheduled date without a winner determined, this market will resolve to \"No.\" The primary resolution source for this market is the official statistics of the event as recognized by the governing body or event organizers. However, if the governing body or event organizers have not published final match statistics within 2 hours after the event's conclusion, a consensus of credible reporting may be used instead.", "assets_ids":["63848024792111907013259549619525334579528597413318009418175871804721549724267", "100775504552940152385129394827622714263459246572352904236453845813105711068785"], "outcomes":["Yes", "No"], "event_message":{"id":"542637", "ticker":"itf-simundz-fuele-2026-05-31", "slug":"itf-simundz-fuele-2026-05-31", "title":"ITF Brcko: Josip Simundza vs Matyas Fuele", "description":"This market refers to the tennis match between Josip Simundza and Matyas Fuele in the ITF Men Brcko, originally scheduled for May 31, 2026 at 6:00AM ET.\n\nThis market will resolve to 'Josip Simundza' if Josip Simundza advances against Matyas Fuele.\n\nThis market will resolve to 'Matyas Fuele' if Matyas Fuele advances against Josip Simundza.\n\nIf the match is canceled (not played at all), ends in a tie, or is delayed beyond 7 days from the scheduled date without a winner determined, this market will resolve to 50-50.\n\nIf the match begins but is not completed, and one player advances due to the opponent's retirement, default, or disqualification, this market will resolve to the player who advances.\n\nIf the match ends in a walkover (player withdraws before the start and the other advances automatically), this market will resolve to 50-50.\n\nThe primary resolution source will be official information from the International Tennis Federation (ITF). A consensus of credible reporting may also be used."}, "timestamp":"1780179008193", "event_type":"new_market", "tags":[], "condition_id":"0x0fae505acdd5571d812232d154120be5803dc19ba799cfbb665b69b80900bbad", "active":false, "clob_token_ids":["63848024792111907013259549619525334579528597413318009418175871804721549724267", "100775504552940152385129394827622714263459246572352904236453845813105711068785"], "sports_market_type":"tennis_completed_match", "line":"", "game_start_time":"2026-05-31 10:00:00+00", "order_price_min_tick_size":"0.01", "group_item_title":"Completed Match", "taker_base_fee":"1000", "fees_enabled":true, "fee_schedule":{"exponent":"1", "rate":"0.03", "taker_only":true, "rebate_rate":"0.25"}}
{"market":"0x4f3421fb2daf5cca7430ed8d8132463963081572d75434393a1808fdb8829fe8", "price_changes":[{"asset_id":"45415751658241142530386585138386640503488308219341470020075667342738719018629", "price":"0.9", "size":"2229.88", "side":"SELL", "hash":"8d8ffa1fe2f57d17ac0ab8994e1f2eede9a242c3", "best_bid":"0.1", "best_ask":"0.101"}, {"asset_id":"31940783580344558651011323787577288681658737625185216525249046282994042503801", "price":"0.1", "size":"2229.88", "side":"BUY", "hash":"68df0cdd13ac4a59ebb875960c58df04b15ed273", "best_bid":"0.899", "best_ask":"0.9"}], "timestamp":"1780179009463", "event_type":"price_change"}
{"market":"0x9b6fef249040fd17e9c107955b37ac2c3e923509b6b0ff01cc463a331ddeb894", "price_changes":[{"asset_id":"108233603819467706476318984012158651931658302669301887462181073562758483842092", "price":"0.837", "size":"36", "side":"SELL", "hash":"cfe52de5364076b7dda85859cb7b5f5f37e50db7", "best_bid":"0.163", "best_ask":"0.164"}, {"asset_id":"32270411694523539495262303868629477861017829722282576458031815333486368239544", "price":"0.163", "size":"36", "side":"BUY", "hash":"6d3c84dcf6565d3184d2214163dbca6051409786", "best_bid":"0.836", "best_ask":"0.837"}], "timestamp":"1780179009471", "event_type":"price_change"}
{"market":"0x7976b8dbacf9077eb1453a62bcefd6ab2df199acd28aad276ff0d920d6992892", "asset_id":"112680630004798425069810935278212000865453267506345451433803052322987302357330", "best_bid":"0.832", "best_ask":"0.833", "spread":"0.001", "timestamp":"1780179010837", "event_type":"best_bid_ask"}
{"market":"0x7976b8dbacf9077eb1453a62bcefd6ab2df199acd28aad276ff0d920d6992892", "price_changes":[{"asset_id":"4394372887385518214471608448209527405727552777602031099972143344338178308080", "price":"0.167", "size":"83184.81", "side":"BUY", "hash":"09fa15b88dde1ff38190df7b5f356b54582f98d2", "best_bid":"0.167", "best_ask":"0.168"}, {"asset_id":"112680630004798425069810935278212000865453267506345451433803052322987302357330", "price":"0.833", "size":"83184.81", "side":"SELL", "hash":"b026c5801b655901acec5245a543f626422b543f", "best_bid":"0.832", "best_ask":"0.833"}], "timestamp":"1780179010836", "event_type":"price_change"}
{"market":"0x7976b8dbacf9077eb1453a62bcefd6ab2df199acd28aad276ff0d920d6992892", "asset_id":"112680630004798425069810935278212000865453267506345451433803052322987302357330", "bids":[{"price":"0.001", "size":"13320371.6"}, {"price":"0.002", "size":"9.57"}, {"price":"0.003", "size":"156.25"}, {"price":"0.004", "size":"13.49"}, {"price":"0.009", "size":"8400"}, {"price":"0.01", "size":"7.03"}, {"price":"0.012", "size":"666666"}, {"price":"0.013", "size":"600000"}, {"price":"0.014", "size":"2534.99"}, {"price":"0.016", "size":"125.09"}, {"price":"0.02", "size":"5012"}, {"price":"0.021", "size":"3999.99"}, {"price":"0.022", "size":"5.22"}, {"price":"0.05", "size":"3109.99"}, {"price":"0.051", "size":"10.45"}, {"price":"0.08", "size":"3005"}, {"price":"0.11", "size":"1000"}, {"price":"0.12", "size":"1000"}, {"price":"0.13", "size":"1000"}, {"price":"0.14", "size":"999.99"}, {"price":"0.15", "size":"1000"}, {"price":"0.16", "size":"1000"}, {"price":"0.167", "size":"17.61"}, {"price":"0.196", "size":"301"}, {"price":"0.2", "size":"749.67"}, {"price":"0.207", "size":"400"}, {"price":"0.208", "size":"544.23"}, {"price":"0.209", "size":"300"}, {"price":"0.21", "size":"5.72"}, {"price":"0.23", "size":"408.6"}, {"price":"0.25", "size":"544.97"}, {"price":"0.31", "size":"305.55"}, {"price":"0.32", "size":"205"}, {"price":"0.36", "size":"231.25"}, {"price":"0.384", "size":"7223.76"}, {"price":"0.39", "size":"5"}, {"price":"0.4", "size":"34671.65"}, {"price":"0.403", "size":"1311"}, {"price":"0.42", "size":"211.4"}, {"price":"0.421", "size":"566.22"}, {"price":"0.45", "size":"510.51"}, {"price":"0.451", "size":"510.51"}, {"price":"0.49", "size":"220"}, {"price":"0.5", "size":"29664.87"}, {"price":"0.501", "size":"4216.7"}, {"price":"0.502", "size":"130"}, {"price":"0.504", "size":"457.83"}, {"price":"0.505", "size":"263.77"}, {"price":"0.51", "size":"264.58"}, {"price":"0.52", "size":"100"}, {"price":"0.53", "size":"100"}, {"price":"0.54", "size":"100"}, {"price":"0.55", "size":"726.73"}, {"price":"0.56", "size":"147"}, {"price":"0.57", "size":"100"}, {"price":"0.58", "size":"188.58"}, {"price":"0.59", "size":"110"}, {"price":"0.598", "size":"13.07"}, {"price":"0.6", "size":"26789.54"}, {"price":"0.601", "size":"274.25"}, {"price":"0.602", "size":"406.1"}, {"price":"0.604", "size":"1000"}, {"price":"0.623", "size":"5"}, {"price":"0.63", "size":"3300"}, {"price":"0.634", "size":"1000"}, {"price":"0.65", "size":"15514.62"}, {"price":"0.654", "size":"124.73"}, {"price":"0.656", "size":"122.73"}, {"price":"0.658", "size":"5141.34"}, {"price":"0.66", "size":"1046.85"}, {"price":"0.664", "size":"11100"}, {"price":"0.666", "size":"474.07"}, {"price":"0.671", "size":"100"}, {"price":"0.68", "size":"3006"}, {"price":"0.681", "size":"2095.26"}, {"price":"0.691", "size":"2359.94"}, {"price":"0.694", "size":"1000"}, {"price":"0.7", "size":"311.97"}, {"price":"0.701", "size":"400"}, {"price":"0.718", "size":"100"}, {"price":"0.72", "size":"11.42"}, {"price":"0.724", "size":"1000"}, {"price":"0.726", "size":"16.03"}, {"price":"0.739", "size":"100"}, {"price":"0.744", "size":"1000"}, {"price":"0.75", "size":"371.36"}, {"price":"0.754", "size":"1000"}, {"price":"0.76", "size":"295"}, {"price":"0.761", "size":"30"}, {"price":"0.764", "size":"1107"}, {"price":"0.765", "size":"150"}, {"price":"0.767", "size":"5"}, {"price":"0.77", "size":"17.85"}, {"price":"0.774", "size":"1362.18"}, {"price":"0.78", "size":"125"}, {"price":"0.781", "size":"100"}, {"price":"0.783", "size":"116.02"}, {"price":"0.784", "size":"1000"}, {"price":"0.79", "size":"50"}, {"price":"0.794", "size":"1050"}, {"price":"0.795", "size":"10"}, {"price":"0.796", "size":"100"}, {"price":"0.798", "size":"5"}, {"price":"0.799", "size":"382.17"}, {"price":"0.8", "size":"8271.84"}, {"price":"0.802", "size":"1000"}, {"price":"0.804", "size":"322"}, {"price":"0.806", "size":"145"}, {"price":"0.808", "size":"30"}, {"price":"0.809", "size":"7.3"}, {"price":"0.812", "size":"15279.71"}, {"price":"0.813", "size":"30"}, {"price":"0.814", "size":"10"}, {"price":"0.815", "size":"105.96"}, {"price":"0.816", "size":"49.77"}, {"price":"0.817", "size":"50"}, {"price":"0.818", "size":"9.7"}, {"price":"0.819", "size":"1000"}, {"price":"0.82", "size":"12535.92"}, {"price":"0.821", "size":"8121.56"}, {"price":"0.822", "size":"930.5"}, {"price":"0.823", "size":"1627.85"}, {"price":"0.824", "size":"15407.48"}, {"price":"0.825", "size":"96558.27"}, {"price":"0.826", "size":"58022.86"}, {"price":"0.827", "size":"26925.87"}, {"price":"0.828", "size":"25913.26"}, {"price":"0.829", "size":"2722.4"}, {"price":"0.83", "size":"27652.43"}, {"price":"0.831", "size":"2030"}, {"price":"0.832", "size":"126550.85"}], "asks":[{"price":"0.999", "size":"4816394"}, {"price":"0.998", "size":"2359"}, {"price":"0.997", "size":"100"}, {"price":"0.996", "size":"1111111"}, {"price":"0.995", "size":"255655"}, {"price":"0.994", "size":"100000"}, {"price":"0.993", "size":"10800"}, {"price":"0.992", "size":"10000"}, {"price":"0.991", "size":"10000"}, {"price":"0.99", "size":"10535"}, {"price":"0.989", "size":"10000"}, {"price":"0.988", "size":"10000"}, {"price":"0.987", "size":"5000"}, {"price":"0.986", "size":"5000"}, {"price":"0.985", "size":"5000"}, {"price":"0.984", "size":"5000"}, {"price":"0.982", "size":"5008.33"}, {"price":"0.981", "size":"5000"}, {"price":"0.98", "size":"7380"}, {"price":"0.979", "size":"3000"}, {"price":"0.978", "size":"3000"}, {"price":"0.977", "size":"3000"}, {"price":"0.976", "size":"3000"}, {"price":"0.975", "size":"3000"}, {"price":"0.974", "size":"3000"}, {"price":"0.973", "size":"3000"}, {"price":"0.972", "size":"3000"}, {"price":"0.959", "size":"731.7"}, {"price":"0.951", "size":"100"}, {"price":"0.95", "size":"56135"}, {"price":"0.931", "size":"20"}, {"price":"0.93", "size":"30"}, {"price":"0.927", "size":"30"}, {"price":"0.926", "size":"30"}, {"price":"0.9", "size":"6230"}, {"price":"0.89", "size":"50"}, {"price":"0.889", "size":"1076.32"}, {"price":"0.88", "size":"11038.99"}, {"price":"0.879", "size":"5"}, {"price":"0.878", "size":"5"}, {"price":"0.877", "size":"5"}, {"price":"0.876", "size":"5"}, {"price":"0.875", "size":"5"}, {"price":"0.874", "size":"5"}, {"price":"0.873", "size":"5"}, {"price":"0.872", "size":"5"}, {"price":"0.871", "size":"5"}, {"price":"0.87", "size":"165"}, {"price":"0.869", "size":"5"}, {"price":"0.868", "size":"105"}, {"price":"0.867", "size":"5"}, {"price":"0.866", "size":"5"}, {"price":"0.865", "size":"5"}, {"price":"0.864", "size":"5"}, {"price":"0.863", "size":"5"}, {"price":"0.862", "size":"5"}, {"price":"0.861", "size":"5"}, {"price":"0.86", "size":"2179.99"}, {"price":"0.859", "size":"6015"}, {"price":"0.858", "size":"5005"}, {"price":"0.857", "size":"2505"}, {"price":"0.856", "size":"15"}, {"price":"0.855", "size":"5"}, {"price":"0.854", "size":"6005"}, {"price":"0.853", "size":"3015"}, {"price":"0.852", "size":"775"}, {"price":"0.851", "size":"3105"}, {"price":"0.85", "size":"10190.34"}, {"price":"0.849", "size":"26420"}, {"price":"0.848", "size":"4713.32"}, {"price":"0.847", "size":"18374.44"}, {"price":"0.846", "size":"7112.99"}, {"price":"0.845", "size":"2890"}, {"price":"0.844", "size":"3989.08"}, {"price":"0.843", "size":"30663.44"}, {"price":"0.842", "size":"6895"}, {"price":"0.841", "size":"538.42"}, {"price":"0.84", "size":"3947.71"}, {"price":"0.839", "size":"759"}, {"price":"0.838", "size":"2688.81"}, {"price":"0.837", "size":"8782.11"}, {"price":"0.836", "size":"29232.29"}, {"price":"0.835", "size":"26149.08"}, {"price":"0.834", "size":"4656.87"}, {"price":"0.833", "size":"83184.81"}], "hash":"b026c5801b655901acec5245a543f626422b543f", "timestamp":"1780179010836", "event_type":"book"}
{"market":"0x7976b8dbacf9077eb1453a62bcefd6ab2df199acd28aad276ff0d920d6992892", "price_changes":[{"asset_id":"4394372887385518214471608448209527405727552777602031099972143344338178308080", "price":"0.168", "size":"126540.85", "side":"SELL", "hash":"030fbec09a147687b6ae6a3213685c81fc2f7eed", "best_bid":"0.167", "best_ask":"0.168"}, {"asset_id":"112680630004798425069810935278212000865453267506345451433803052322987302357330", "price":"0.832", "size":"126540.85", "side":"BUY", "hash":"39e4465d10e7d773e56cc540391aac4e688117c4", "best_bid":"0.832", "best_ask":"0.833"}], "timestamp":"1780179011038", "event_type":"price_change"}
{"market":"0x7976b8dbacf9077eb1453a62bcefd6ab2df199acd28aad276ff0d920d6992892", "price_changes":[{"asset_id":"4394372887385518214471608448209527405727552777602031099972143344338178308080", "price":"0.178", "size":"940.5", "side":"SELL", "hash":"c8715550dd27e6dccc5f30f45808933120bc6b7c", "best_bid":"0.167", "best_ask":"0.168"}, {"asset_id":"112680630004798425069810935278212000865453267506345451433803052322987302357330", "price":"0.822", "size":"940.5", "side":"BUY", "hash":"d88d62999883d911c0ac1bb6055adee738431923", "best_bid":"0.832", "best_ask":"0.833"}], "timestamp":"1780179011256", "event_type":"price_change"}
PONG
{"market":"0x7976b8dbacf9077eb1453a62bcefd6ab2df199acd28aad276ff0d920d6992892", "price_changes":[{"asset_id":"4394372887385518214471608448209527405727552777602031099972143344338178308080", "price":"0.184", "size":"0", "side":"SELL", "hash":"925244dbc327368d83e12e2d0546311be30dac01", "best_bid":"0.167", "best_ask":"0.168"}, {"asset_id":"112680630004798425069810935278212000865453267506345451433803052322987302357330", "price":"0.816", "size":"0", "side":"BUY", "hash":"16fe82f0177eb00a02506daa84fe4b43e5268a61", "best_bid":"0.832", "best_ask":"0.833"}], "timestamp":"1780179011695", "event_type":"price_change"}
{"market":"0x7976b8dbacf9077eb1453a62bcefd6ab2df199acd28aad276ff0d920d6992892", "price_changes":[{"asset_id":"4394372887385518214471608448209527405727552777602031099972143344338178308080", "price":"0.184", "size":"49.77", "side":"SELL", "hash":"ad861bc6876b451cadd4d0d207ba5057dfb1c68f", "best_bid":"0.167", "best_ask":"0.168"}, {"asset_id":"112680630004798425069810935278212000865453267506345451433803052322987302357330", "price":"0.816", "size":"49.77", "side":"BUY", "hash":"48ecff74fa994ae4e858b4aa6b70c4cf33daa70f", "best_bid":"0.832", "best_ask":"0.833"}], "timestamp":"1780179011860", "event_type":"price_change"}
{"id":"2397766", "question":"Will the fight be won by submission?", "market":"0x25ceb67868699563837742ab8dfc44a464af5e6f6796e32ec37ea07480109ca0", "slug":"ufc-gas-mic34-2026-06-20-win-by-submission", "description":"This market will resolve to \"Yes\" if the fight between Gaston Bolaños and Michael Aswell at UFC Fight Night: Kape vs. Horiguchi, scheduled for June 20, 2026, ends by submission, including tapout, verbal submission, or technical submission (referee stoppage due to a submission hold). Otherwise, it will resolve to \"No.\"\n\nIf the fight ends in a draw or by disqualification (either fighter), it will resolve \"No.\"\n\nIf the bout is ruled a No Contest, not scored, canceled, or postponed beyond July 4, 2026, this market will resolve \"50-50.\"\n\nThe resolution source for this market will be official information from the UFC.", "assets_ids":["94478983718026142818699791002276831323735288023991769397155031998465951497073", "43151256948844312912609886453790131283175911354874926751273669882607272931676"], "outcomes":["Yes", "No"], "event_message":{"id":"542654", "ticker":"ufc-gas-mic34-2026-06-20", "slug":"ufc-gas-mic34-2026-06-20", "title":"UFC Fight Night: Gaston Bolaños vs. Michael Aswell (Featherweight, Prelims)", "description":"This market will resolve to \"Gaston Bolaños\" if Gaston Bolaños is officially declared the winner of the fight against Michael Aswell at UFC Fight Night: Kape vs. Horiguchi, scheduled for June 20, 2026.\n\nIt will resolve to \"Michael Aswell\" if Michael Aswell is officially declared the winner.\n\nIf the fight is declared a draw or technical draw, ruled a No Contest, not scored, canceled, or postponed beyond July 4, 2026, this market will resolve \"50-50.\"\n\nThe resolution source for this market will be official information from the UFC."}, "timestamp":"1780179012011", "event_type":"new_market", "tags":[], "condition_id":"0x25ceb67868699563837742ab8dfc44a464af5e6f6796e32ec37ea07480109ca0", "active":false, "clob_token_ids":["94478983718026142818699791002276831323735288023991769397155031998465951497073", "43151256948844312912609886453790131283175911354874926751273669882607272931676"], "sports_market_type":"ufc_method_of_victory", "line":"", "game_start_time":"2026-06-20 17:00:00+00", "order_price_min_tick_size":"0.01", "group_item_title":"Fight won by submission?", "taker_base_fee":"1000", "fees_enabled":true, "fee_schedule":{"exponent":"1", "rate":"0.03", "taker_only":true, "rebate_rate":"0.25"}}
{"market":"0x7876851632c295043c66536150a304cb785abdf712ba8489d298c6e6926be106", "price_changes":[{"asset_id":"97239126062673310243763617236644392945530356142765650402171508075574679292913", "price":"0.011", "size":"1818565.69", "side":"SELL", "hash":"f6bf9bccfccc637aaf6175bebf5cffdb9cf5944a", "best_bid":"0.01", "best_ask":"0.011"}, {"asset_id":"19291692040378529618917910599727571242305935029274321291612270922648172794670", "price":"0.989", "size":"1818565.69", "side":"BUY", "hash":"6b6014c0bbbc8e04d0127067b3099ced6ce63bd8", "best_bid":"0.989", "best_ask":"0.99"}], "timestamp":"1780179012852", "event_type":"price_change"}
{"market":"0x4f3421fb2daf5cca7430ed8d8132463963081572d75434393a1808fdb8829fe8", "price_changes":[{"asset_id":"45415751658241142530386585138386640503488308219341470020075667342738719018629", "price":"0.103", "size":"18203.31", "side":"SELL", "hash":"c24438748198793fe4a7d77f3130df129e4c3204", "best_bid":"0.1", "best_ask":"0.101"}, {"asset_id":"31940783580344558651011323787577288681658737625185216525249046282994042503801", "price":"0.897", "size":"18203.31", "side":"BUY", "hash":"6404690e15d02660facc7edf521142307a0767ad", "best_bid":"0.899", "best_ask":"0.9"}], "timestamp":"1780179013211", "event_type":"price_change"}
{"market":"0x4f3421fb2daf5cca7430ed8d8132463963081572d75434393a1808fdb8829fe8", "price_changes":[{"asset_id":"45415751658241142530386585138386640503488308219341470020075667342738719018629", "price":"0.103", "size":"18263.31", "side":"SELL", "hash":"43e1dedaa930e7df2c5471d04d0911b5950988cb", "best_bid":"0.1", "best_ask":"0.101"}, {"asset_id":"31940783580344558651011323787577288681658737625185216525249046282994042503801", "price":"0.897", "size":"18263.31", "side":"BUY", "hash":"aaddfc7388089c8b1df625b710a6bb4849fa07a5", "best_bid":"0.899", "best_ask":"0.9"}], "timestamp":"1780179013301", "event_type":"price_change"}
{"market":"0x4f3421fb2daf5cca7430ed8d8132463963081572d75434393a1808fdb8829fe8", "asset_id":"31940783580344558651011323787577288681658737625185216525249046282994042503801", "best_bid":"0.899", "best_ask":"0.9", "spread":"0.001", "timestamp":"1780179013366", "event_type":"best_bid_ask"}
{"market":"0x4f3421fb2daf5cca7430ed8d8132463963081572d75434393a1808fdb8829fe8", "price_changes":[{"asset_id":"45415751658241142530386585138386640503488308219341470020075667342738719018629", "price":"0.101", "size":"66330.28", "side":"SELL", "hash":"165f934c5c4e60afdc209bc0bbc2698b8c9051ca", "best_bid":"0.1", "best_ask":"0.101"}, {"asset_id":"31940783580344558651011323787577288681658737625185216525249046282994042503801", "price":"0.899", "size":"66330.28", "side":"BUY", "hash":"4bb74c9144677d3ff040a62771982b35d5a19c88", "best_bid":"0.899", "best_ask":"0.9"}], "timestamp":"1780179013366", "event_type":"price_change"}
{"market":"0x4f3421fb2daf5cca7430ed8d8132463963081572d75434393a1808fdb8829fe8", "asset_id":"31940783580344558651011323787577288681658737625185216525249046282994042503801", "bids":[{"price":"0.001", "size":"21074238.91"}, {"price":"0.002", "size":"37.76"}, {"price":"0.01", "size":"25929.6"}, {"price":"0.011", "size":"6.21"}, {"price":"0.014", "size":"1111111"}, {"price":"0.015", "size":"1000000"}, {"price":"0.021", "size":"800"}, {"price":"0.022", "size":"11.19"}, {"price":"0.05", "size":"40"}, {"price":"0.077", "size":"2000"}, {"price":"0.078", "size":"5.64"}, {"price":"0.1", "size":"2229.88"}, {"price":"0.11", "size":"1016"}, {"price":"0.12", "size":"1021"}, {"price":"0.13", "size":"1000"}, {"price":"0.14", "size":"999.99"}, {"price":"0.15", "size":"1153.71"}, {"price":"0.2", "size":"409.2"}, {"price":"0.224", "size":"433.92"}, {"price":"0.225", "size":"5.14"}, {"price":"0.25", "size":"453.7"}, {"price":"0.253", "size":"200"}, {"price":"0.254", "size":"200"}, {"price":"0.27", "size":"200"}, {"price":"0.28", "size":"200"}, {"price":"0.31", "size":"200"}, {"price":"0.33", "size":"215.15"}, {"price":"0.34", "size":"199.99"}, {"price":"0.35", "size":"102.46"}, {"price":"0.36", "size":"228"}, {"price":"0.361", "size":"100"}, {"price":"0.4", "size":"34637.29"}, {"price":"0.401", "size":"5000"}, {"price":"0.41", "size":"200"}, {"price":"0.42", "size":"200"}, {"price":"0.43", "size":"200"}, {"price":"0.44", "size":"200"}, {"price":"0.45", "size":"354.02"}, {"price":"0.46", "size":"200"}, {"price":"0.461", "size":"1077.83"}, {"price":"0.5", "size":"25496.62"}, {"price":"0.501", "size":"5100"}, {"price":"0.51", "size":"205.76"}, {"price":"0.511", "size":"100"}, {"price":"0.52", "size":"100"}, {"price":"0.53", "size":"100"}, {"price":"0.54", "size":"100"}, {"price":"0.55", "size":"100"}, {"price":"0.56", "size":"100"}, {"price":"0.57", "size":"100"}, {"price":"0.58", "size":"100"}, {"price":"0.6", "size":"21059.73"}, {"price":"0.61", "size":"100"}, {"price":"0.62", "size":"111.9"}, {"price":"0.632", "size":"5322.31"}, {"price":"0.64", "size":"28.8"}, {"price":"0.643", "size":"100"}, {"price":"0.65", "size":"16970.62"}, {"price":"0.66", "size":"100"}, {"price":"0.67", "size":"100"}, {"price":"0.673", "size":"100"}, {"price":"0.674", "size":"100"}, {"price":"0.678", "size":"100"}, {"price":"0.68", "size":"410.68"}, {"price":"0.69", "size":"100"}, {"price":"0.7", "size":"422.3"}, {"price":"0.703", "size":"100"}, {"price":"0.704", "size":"100"}, {"price":"0.708", "size":"100"}, {"price":"0.71", "size":"61.7"}, {"price":"0.729", "size":"1000"}, {"price":"0.733", "size":"100"}, {"price":"0.75", "size":"3192.15"}, {"price":"0.759", "size":"1000"}, {"price":"0.76", "size":"341.8"}, {"price":"0.763", "size":"100"}, {"price":"0.764", "size":"100"}, {"price":"0.769", "size":"100"}, {"price":"0.777", "size":"100"}, {"price":"0.778", "size":"400"}, {"price":"0.78", "size":"258.06"}, {"price":"0.781", "size":"100"}, {"price":"0.789", "size":"1000"}, {"price":"0.79", "size":"47.6"}, {"price":"0.798", "size":"1781.45"}, {"price":"0.8", "size":"246868.85"}, {"price":"0.801", "size":"100"}, {"price":"0.809", "size":"1000"}, {"price":"0.819", "size":"1000"}, {"price":"0.82", "size":"30"}, {"price":"0.826", "size":"100"}, {"price":"0.829", "size":"1100"}, {"price":"0.83", "size":"39.23"}, {"price":"0.839", "size":"1000"}, {"price":"0.84", "size":"356.45"}, {"price":"0.847", "size":"100"}, {"price":"0.849", "size":"3541.52"}, {"price":"0.85", "size":"15927.35"}, {"price":"0.851", "size":"800"}, {"price":"0.853", "size":"68.33"}, {"price":"0.855", "size":"13.33"}, {"price":"0.858", "size":"35.21"}, {"price":"0.859", "size":"671"}, {"price":"0.86", "size":"34.6"}, {"price":"0.862", "size":"75"}, {"price":"0.867", "size":"17.97"}, {"price":"0.869", "size":"666"}, {"price":"0.87", "size":"4000"}, {"price":"0.871", "size":"39.42"}, {"price":"0.875", "size":"170"}, {"price":"0.876", "size":"30"}, {"price":"0.88", "size":"197"}, {"price":"0.882", "size":"1000"}, {"price":"0.885", "size":"925.73"}, {"price":"0.886", "size":"100"}, {"price":"0.887", "size":"100"}, {"price":"0.888", "size":"100"}, {"price":"0.889", "size":"100"}, {"price":"0.89", "size":"649.23"}, {"price":"0.891", "size":"1343.33"}, {"price":"0.892", "size":"7071.71"}, {"price":"0.893", "size":"15257.35"}, {"price":"0.894", "size":"121650.88"}, {"price":"0.895", "size":"1515.46"}, {"price":"0.896", "size":"30940.81"}, {"price":"0.897", "size":"18263.31"}, {"price":"0.898", "size":"90693.2"}, {"price":"0.899", "size":"66330.28"}], "asks":[{"price":"0.999", "size":"4715397.01"}, {"price":"0.998", "size":"14"}, {"price":"0.997", "size":"1112792"}, {"price":"0.996", "size":"55564"}, {"price":"0.995", "size":"10009"}, {"price":"0.994", "size":"11109"}, {"price":"0.993", "size":"10009"}, {"price":"0.992", "size":"10009"}, {"price":"0.991", "size":"5009"}, {"price":"0.99", "size":"6209"}, {"price":"0.989", "size":"5009"}, {"price":"0.988", "size":"5009"}, {"price":"0.987", "size":"4309"}, {"price":"0.986", "size":"3009"}, {"price":"0.985", "size":"5009"}, {"price":"0.984", "size":"3009"}, {"price":"0.983", "size":"3009"}, {"price":"0.982", "size":"9"}, {"price":"0.981", "size":"5009"}, {"price":"0.98", "size":"6234"}, {"price":"0.979", "size":"4008.99"}, {"price":"0.978", "size":"4009"}, {"price":"0.977", "size":"4009"}, {"price":"0.976", "size":"3009"}, {"price":"0.975", "size":"3009"}, {"price":"0.974", "size":"4009"}, {"price":"0.973", "size":"3009"}, {"price":"0.972", "size":"4009"}, {"price":"0.971", "size":"2009"}, {"price":"0.97", "size":"409"}, {"price":"0.969", "size":"2509"}, {"price":"0.968", "size":"2652.85"}, {"price":"0.967", "size":"2509"}, {"price":"0.966", "size":"2509"}, {"price":"0.965", "size":"9"}, {"price":"0.964", "size":"9"}, {"price":"0.963", "size":"9"}, {"price":"0.962", "size":"609"}, {"price":"0.961", "size":"9"}, {"price":"0.96", "size":"134"}, {"price":"0.959", "size":"9"}, {"price":"0.958", "size":"9"}, {"price":"0.957", "size":"9"}, {"price":"0.956", "size":"9"}, {"price":"0.955", "size":"9"}, {"price":"0.954", "size":"9"}, {"price":"0.953", "size":"9"}, {"price":"0.952", "size":"9"}, {"price":"0.951", "size":"9"}, {"price":"0.95", "size":"79"}, {"price":"0.949", "size":"10009"}, {"price":"0.948", "size":"9"}, {"price":"0.947", "size":"9"}, {"price":"0.946", "size":"9"}, {"price":"0.945", "size":"309"}, {"price":"0.944", "size":"9"}, {"price":"0.943", "size":"9"}, {"price":"0.942", "size":"9"}, {"price":"0.941", "size":"9"}, {"price":"0.94", "size":"36"}, {"price":"0.939", "size":"202"}, {"price":"0.938", "size":"10009"}, {"price":"0.937", "size":"5009"}, {"price":"0.936", "size":"7509"}, {"price":"0.935", "size":"5151"}, {"price":"0.934", "size":"6209"}, {"price":"0.933", "size":"4603.78"}, {"price":"0.932", "size":"2856.05"}, {"price":"0.931", "size":"2772.73"}, {"price":"0.93", "size":"9438.97"}, {"price":"0.929", "size":"1564"}, {"price":"0.928", "size":"5464.3"}, {"price":"0.927", "size":"1109"}, {"price":"0.926", "size":"357402.07"}, {"price":"0.925", "size":"20562.67"}, {"price":"0.924", "size":"6553.29"}, {"price":"0.923", "size":"434.15"}, {"price":"0.922", "size":"512.12"}, {"price":"0.921", "size":"25029"}, {"price":"0.92", "size":"15376.09"}, {"price":"0.919", "size":"1633.99"}, {"price":"0.918", "size":"14672.52"}, {"price":"0.917", "size":"2431.41"}, {"price":"0.916", "size":"9"}, {"price":"0.915", "size":"821.33"}, {"price":"0.914", "size":"22609"}, {"price":"0.913", "size":"4605.61"}, {"price":"0.912", "size":"1782.17"}, {"price":"0.911", "size":"570.79"}, {"price":"0.91", "size":"6647.21"}, {"price":"0.909", "size":"958.45"}, {"price":"0.908", "size":"909"}, {"price":"0.907", "size":"3608.93"}, {"price":"0.906", "size":"1240.91"}, {"price":"0.905", "size":"3028.99"}, {"price":"0.904", "size":"1169.1"}, {"price":"0.903", "size":"6197.22"}, {"price":"0.902", "size":"6110.44"}, {"price":"0.901", "size":"7768"}, {"price":"0.9", "size":"9239.67"}], "hash":"4bb74c9144677d3ff040a62771982b35d5a19c88", "timestamp":"1780179013366", "event_type":"book"}
{"market":"0x9b6fef249040fd17e9c107955b37ac2c3e923509b6b0ff01cc463a331ddeb894", "price_changes":[{"asset_id":"108233603819467706476318984012158651931658302669301887462181073562758483842092", "price":"0.166", "size":"24952", "side":"SELL", "hash":"a9a3ea0f6ef37eaf12864cbd933235ee33b3242b", "best_bid":"0.163", "best_ask":"0.164"}, {"asset_id":"32270411694523539495262303868629477861017829722282576458031815333486368239544", "price":"0.834", "size":"24952", "side":"BUY", "hash":"4a771b8d0e7f99b6cfcc5530616e48519205445e", "best_bid":"0.836", "best_ask":"0.837"}], "timestamp":"1780179013571", "event_type":"price_change"}
{"market":"0x4f3421fb2daf5cca7430ed8d8132463963081572d75434393a1808fdb8829fe8", "price_changes":[{"asset_id":"45415751658241142530386585138386640503488308219341470020075667342738719018629", "price":"0.099", "size":"7758", "side":"BUY", "hash":"503decd4c38e872f289f7e5efb2cc5e67f45af04", "best_bid":"0.1", "best_ask":"0.101"}, {"asset_id":"31940783580344558651011323787577288681658737625185216525249046282994042503801", "price":"0.901", "size":"7758", "side":"SELL", "hash":"a4d8d529fc8a3db88cd487634f7e94c6ece37ac7", "best_bid":"0.899", "best_ask":"0.9"}], "timestamp":"1780179013573", "event_type":"price_change"}
{"market":"0x9b6fef249040fd17e9c107955b37ac2c3e923509b6b0ff01cc463a331ddeb894", "price_changes":[{"asset_id":"108233603819467706476318984012158651931658302669301887462181073562758483842092", "price":"0.166", "size":"25006.68", "side":"SELL", "hash":"f99c944970b21f93fd6edee6700354030d88c1c4", "best_bid":"0.163", "best_ask":"0.164"}, {"asset_id":"32270411694523539495262303868629477861017829722282576458031815333486368239544", "price":"0.834", "size":"25006.68", "side":"BUY", "hash":"661180a89462064a9bb00d0b871b857aa827ff0c", "best_bid":"0.836", "best_ask":"0.837"}], "timestamp":"1780179013659", "event_type":"price_change"}
{"market":"0x4f3421fb2daf5cca7430ed8d8132463963081572d75434393a1808fdb8829fe8", "price_changes":[{"asset_id":"45415751658241142530386585138386640503488308219341470020075667342738719018629", "price":"0.09", "size":"6657.21", "side":"BUY", "hash":"e2b02963040004c64e4254e509d9a2736cd72bf0", "best_bid":"0.1", "best_ask":"0.101"}, {"asset_id":"31940783580344558651011323787577288681658737625185216525249046282994042503801", "price":"0.91", "size":"6657.21", "side":"SELL", "hash":"7f560b0a0ab330276fadc8410413385a9aa1928f", "best_bid":"0.899", "best_ask":"0.9"}], "timestamp":"1780179013775", "event_type":"price_change"}
{"market":"0x4f3421fb2daf5cca7430ed8d8132463963081572d75434393a1808fdb8829fe8", "price_changes":[{"asset_id":"31940783580344558651011323787577288681658737625185216525249046282994042503801", "price":"0.924", "size":"6753.29", "side":"SELL", "hash":"3583b9a8c7f84d71176a05281a95286d4c820498", "best_bid":"0.899", "best_ask":"0.9"}, {"asset_id":"45415751658241142530386585138386640503488308219341470020075667342738719018629", "price":"0.076", "size":"6753.29", "side":"BUY", "hash":"30c9cd4de346312f95226dbe0b15ae598b22640e", "best_bid":"0.1", "best_ask":"0.101"}], "timestamp":"1780179013873", "event_type":"price_change"}
{"market":"0x375409bc5eeeff961e82b479caeccc20f33d15738e5bce1186d628aa3d9dfb1f", "asset_id":"77121637225348873006259930776623502125079210522997384841464684944292365296940", "best_bid":"0.887", "best_ask":"0.888", "spread":"0.001", "timestamp":"1780179013913", "event_type":"best_bid_ask"}
{"market":"0x375409bc5eeeff961e82b479caeccc20f33d15738e5bce1186d628aa3d9dfb1f", "price_changes":[{"asset_id":"115556263888245616435851357148058235707004733438163639091106356867234218207169", "price":"0.112", "size":"107388.16", "side":"BUY", "hash":"bce8d437f0542ad3188959fcc16508e65bf18ac6", "best_bid":"0.112", "best_ask":"0.113"}, {"asset_id":"77121637225348873006259930776623502125079210522997384841464684944292365296940", "price":"0.888", "size":"107388.16", "side":"SELL", "hash":"6dbe12f866598f40612ec1d5ddb9932eb79beee0", "best_bid":"0.887", "best_ask":"0.888"}], "timestamp":"1780179013912", "event_type":"price_change"}
{"market":"0x375409bc5eeeff961e82b479caeccc20f33d15738e5bce1186d628aa3d9dfb1f", "asset_id":"77121637225348873006259930776623502125079210522997384841464684944292365296940", "bids":[{"price":"0.001", "size":"21319088.56"}, {"price":"0.002", "size":"5005.12"}, {"price":"0.003", "size":"14.23"}, {"price":"0.005", "size":"2222222"}, {"price":"0.006", "size":"2000000"}, {"price":"0.007", "size":"800"}, {"price":"0.008", "size":"5.22"}, {"price":"0.013", "size":"1728"}, {"price":"0.014", "size":"52"}, {"price":"0.1", "size":"491.34"}, {"price":"0.151", "size":"5000"}, {"price":"0.155", "size":"200"}, {"price":"0.16", "size":"300"}, {"price":"0.161", "size":"300"}, {"price":"0.163", "size":"300"}, {"price":"0.18", "size":"300"}, {"price":"0.22", "size":"345.04"}, {"price":"0.221", "size":"335.74"}, {"price":"0.222", "size":"5.25"}, {"price":"0.23", "size":"230.97"}, {"price":"0.25", "size":"300"}, {"price":"0.26", "size":"300"}, {"price":"0.27", "size":"300"}, {"price":"0.3", "size":"2374.99"}, {"price":"0.301", "size":"200"}, {"price":"0.35", "size":"293.98"}, {"price":"0.38", "size":"133.26"}, {"price":"0.39", "size":"105"}, {"price":"0.4", "size":"35775"}, {"price":"0.408", "size":"4900"}, {"price":"0.409", "size":"6100"}, {"price":"0.44", "size":"105"}, {"price":"0.45", "size":"100"}, {"price":"0.451", "size":"1009.54"}, {"price":"0.493", "size":"494.73"}, {"price":"0.5", "size":"27051.85"}, {"price":"0.501", "size":"4100"}, {"price":"0.502", "size":"144.67"}, {"price":"0.51", "size":"275.39"}, {"price":"0.55", "size":"302.74"}, {"price":"0.56", "size":"100"}, {"price":"0.6", "size":"22248.33"}, {"price":"0.613", "size":"100"}, {"price":"0.62", "size":"100"}, {"price":"0.623", "size":"105"}, {"price":"0.643", "size":"100"}, {"price":"0.65", "size":"16362.62"}, {"price":"0.661", "size":"5100"}, {"price":"0.662", "size":"2095.26"}, {"price":"0.67", "size":"11.2"}, {"price":"0.671", "size":"100"}, {"price":"0.673", "size":"100"}, {"price":"0.68", "size":"99.99"}, {"price":"0.69", "size":"242.85"}, {"price":"0.7", "size":"1709.85"}, {"price":"0.703", "size":"100"}, {"price":"0.717", "size":"1000"}, {"price":"0.72", "size":"252.85"}, {"price":"0.721", "size":"100"}, {"price":"0.733", "size":"100"}, {"price":"0.74", "size":"180.76"}, {"price":"0.747", "size":"1000"}, {"price":"0.75", "size":"4458.91"}, {"price":"0.761", "size":"99.99"}, {"price":"0.763", "size":"100"}, {"price":"0.767", "size":"9008.24"}, {"price":"0.77", "size":"200"}, {"price":"0.771", "size":"200"}, {"price":"0.774", "size":"16354.68"}, {"price":"0.776", "size":"9000"}, {"price":"0.777", "size":"1000"}, {"price":"0.79", "size":"3113.4"}, {"price":"0.792", "size":"100"}, {"price":"0.797", "size":"1000"}, {"price":"0.8", "size":"18696.67"}, {"price":"0.804", "size":"1486.78"}, {"price":"0.807", "size":"1006.18"}, {"price":"0.81", "size":"888.99"}, {"price":"0.813", "size":"130"}, {"price":"0.817", "size":"1100"}, {"price":"0.82", "size":"20"}, {"price":"0.827", "size":"1000"}, {"price":"0.83", "size":"110"}, {"price":"0.834", "size":"436.03"}, {"price":"0.837", "size":"1100"}, {"price":"0.84", "size":"377.83"}, {"price":"0.847", "size":"1313.15"}, {"price":"0.849", "size":"75"}, {"price":"0.85", "size":"279.81"}, {"price":"0.852", "size":"1118.59"}, {"price":"0.854", "size":"847.46"}, {"price":"0.855", "size":"144.97"}, {"price":"0.856", "size":"118.44"}, {"price":"0.857", "size":"1045"}, {"price":"0.858", "size":"167.16"}, {"price":"0.86", "size":"190.28"}, {"price":"0.862", "size":"2611.44"}, {"price":"0.863", "size":"173.7"}, {"price":"0.864", "size":"121.7"}, {"price":"0.865", "size":"94.28"}, {"price":"0.866", "size":"141.44"}, {"price":"0.867", "size":"15010"}, {"price":"0.868", "size":"25111.44"}, {"price":"0.869", "size":"21"}, {"price":"0.87", "size":"60785.22"}, {"price":"0.871", "size":"4854.15"}, {"price":"0.872", "size":"55645.74"}, {"price":"0.873", "size":"1122.06"}, {"price":"0.874", "size":"312.33"}, {"price":"0.875", "size":"1629.28"}, {"price":"0.876", "size":"811.41"}, {"price":"0.877", "size":"20"}, {"price":"0.878", "size":"256.72"}, {"price":"0.879", "size":"99"}, {"price":"0.88", "size":"20849.13"}, {"price":"0.881", "size":"115464.59"}, {"price":"0.882", "size":"5243.19"}, {"price":"0.883", "size":"517048.24"}, {"price":"0.884", "size":"22720.12"}, {"price":"0.885", "size":"12079.15"}, {"price":"0.886", "size":"4186.41"}, {"price":"0.887", "size":"231388.42"}], "asks":[{"price":"0.999", "size":"4816069"}, {"price":"0.998", "size":"1001693"}, {"price":"0.996", "size":"556755"}, {"price":"0.995", "size":"55655"}, {"price":"0.994", "size":"20000"}, {"price":"0.993", "size":"10800"}, {"price":"0.992", "size":"10000"}, {"price":"0.991", "size":"10000"}, {"price":"0.99", "size":"10000"}, {"price":"0.989", "size":"5000"}, {"price":"0.988", "size":"5000"}, {"price":"0.987", "size":"5000"}, {"price":"0.986", "size":"5000"}, {"price":"0.985", "size":"6000"}, {"price":"0.984", "size":"5000"}, {"price":"0.983", "size":"5000"}, {"price":"0.982", "size":"5060"}, {"price":"0.981", "size":"5000"}, {"price":"0.98", "size":"5375"}, {"price":"0.979", "size":"5020"}, {"price":"0.978", "size":"5000"}, {"price":"0.977", "size":"5000"}, {"price":"0.976", "size":"5000"}, {"price":"0.975", "size":"715.5"}, {"price":"0.96", "size":"100"}, {"price":"0.959", "size":"100"}, {"price":"0.951", "size":"100"}, {"price":"0.95", "size":"75"}, {"price":"0.949", "size":"175"}, {"price":"0.94", "size":"50150"}, {"price":"0.936", "size":"50.54"}, {"price":"0.935", "size":"5000"}, {"price":"0.93", "size":"100"}, {"price":"0.924", "size":"79.6"}, {"price":"0.92", "size":"600"}, {"price":"0.918", "size":"105"}, {"price":"0.912", "size":"100.11"}, {"price":"0.91", "size":"800"}, {"price":"0.907", "size":"300"}, {"price":"0.906", "size":"319"}, {"price":"0.904", "size":"11000"}, {"price":"0.903", "size":"500"}, {"price":"0.9", "size":"11849.9"}, {"price":"0.899", "size":"10000"}, {"price":"0.898", "size":"1010"}, {"price":"0.897", "size":"20"}, {"price":"0.896", "size":"2540"}, {"price":"0.895", "size":"600"}, {"price":"0.894", "size":"860"}, {"price":"0.892", "size":"12287.02"}, {"price":"0.891", "size":"9926.74"}, {"price":"0.89", "size":"40417.97"}, {"price":"0.889", "size":"192031.85"}, {"price":"0.888", "size":"107388.16"}], "hash":"6dbe12f866598f40612ec1d5ddb9932eb79beee0", "timestamp":"1780179013912", "event_type":"book"}
{"market":"0x375409bc5eeeff961e82b479caeccc20f33d15738e5bce1186d628aa3d9dfb1f", "price_changes":[{"asset_id":"115556263888245616435851357148058235707004733438163639091106356867234218207169", "price":"0.113", "size":"231378.42", "side":"SELL", "hash":"47eca8b240bdfdc895e48268b437a8d82b4fa80f", "best_bid":"0.112", "best_ask":"0.113"}, {"asset_id":"77121637225348873006259930776623502125079210522997384841464684944292365296940", "price":"0.887", "size":"231378.42", "side":"BUY", "hash":"19972d58679de615b642325811245162bc1c46d7", "best_bid":"0.887", "best_ask":"0.888"}], "timestamp":"1780179014526", "event_type":"price_change"}
{"market":"0x7976b8dbacf9077eb1453a62bcefd6ab2df199acd28aad276ff0d920d6992892", "price_changes":[{"asset_id":"4394372887385518214471608448209527405727552777602031099972143344338178308080", "price":"0.17", "size":"27598.28", "side":"SELL", "hash":"364898a9205958cf6efc278aefe88d2ae43ba7f2", "best_bid":"0.167", "best_ask":"0.168"}, {"asset_id":"112680630004798425069810935278212000865453267506345451433803052322987302357330", "price":"0.83", "size":"27598.28", "side":"BUY", "hash":"e843167983f29cb2b3c80b6147ca7fd75f06d599", "best_bid":"0.832", "best_ask":"0.833"}], "timestamp":"1780179015000", "event_type":"price_change"}
{"market":"0x30d55d8124ee1e12dabe89201badc45669b81dff69e4ce44d961f32878ec178a", "price_changes":[{"asset_id":"27576533317283401577758999384642760405921738493660383550832555714312627457443", "price":"0.092", "size":"78371.18", "side":"SELL", "hash":"d36b7b0fa22048f41e4a36a01092bc8dbe203b39", "best_bid":"0.089", "best_ask":"0.09"}, {"asset_id":"52986718774908357330412653486471347449818893503063830313445318937088822580057", "price":"0.908", "size":"78371.18", "side":"BUY", "hash":"686c91f22c08b8641f521a51efabf03a5427b014", "best_bid":"0.91", "best_ask":"0.911"}], "timestamp":"1780179015037", "event_type":"price_change"}
{"market":"0x375409bc5eeeff961e82b479caeccc20f33d15738e5bce1186d628aa3d9dfb1f", "price_changes":[{"asset_id":"115556263888245616435851357148058235707004733438163639091106356867234218207169", "price":"0.12", "size":"20859.13", "side":"SELL", "hash":"89669d13473d8c01b70fb0745698702138b302cc", "best_bid":"0.112", "best_ask":"0.113"}, {"asset_id":"77121637225348873006259930776623502125079210522997384841464684944292365296940", "price":"0.88", "size":"20859.13", "side":"BUY", "hash":"6c28ca7f9b87dadaed4cccbbd979999c0e1c1bba", "best_bid":"0.887", "best_ask":"0.888"}], "timestamp":"1780179015070", "event_type":"price_change"}
{"market":"0x7976b8dbacf9077eb1453a62bcefd6ab2df199acd28aad276ff0d920d6992892", "price_changes":[{"asset_id":"4394372887385518214471608448209527405727552777602031099972143344338178308080", "price":"0.17", "size":"27652.43", "side":"SELL", "hash":"e963a178dbcf9760a42a1ebea1b7a1fb174e7ced", "best_bid":"0.167", "best_ask":"0.168"}, {"asset_id":"112680630004798425069810935278212000865453267506345451433803052322987302357330", "price":"0.83", "size":"27652.43", "side":"BUY", "hash":"483e2201f80c7da839374bdb0698734dedde917e", "best_bid":"0.832", "best_ask":"0.833"}], "timestamp":"1780179015172", "event_type":"price_change"}
{"market":"0x30d55d8124ee1e12dabe89201badc45669b81dff69e4ce44d961f32878ec178a", "price_changes":[{"asset_id":"27576533317283401577758999384642760405921738493660383550832555714312627457443", "price":"0.092", "size":"78431.18", "side":"SELL", "hash":"8295c1c5fb4d95c944099ede818fe73824303726", "best_bid":"0.089", "best_ask":"0.09"}, {"asset_id":"52986718774908357330412653486471347449818893503063830313445318937088822580057", "price":"0.908", "size":"78431.18", "side":"BUY", "hash":"84de3d1b6c42c9680bfff6307b43150c5cbdd5c8", "best_bid":"0.91", "best_ask":"0.911"}], "timestamp":"1780179015182", "event_type":"price_change"}
{"market":"0x1595b4818eeb1ea1e0bec5de6f057218e557feee9b405a0e930d290384fa1d16", "price_changes":[{"asset_id":"81739002353269632749850710185641576213562066971072676369728657545679630163887", "price":"0.053", "size":"3311.26", "side":"SELL", "hash":"10cd0368eb09a06c7eb7059767e84abd37708664", "best_bid":"0.051", "best_ask":"0.052"}, {"asset_id":"45484070731786948288366703334552551439356529561722304542938873238430842810537", "price":"0.947", "size":"3311.26", "side":"BUY", "hash":"f4c25662cf2cac2bb52d5ccdca45c6f045660408", "best_bid":"0.948", "best_ask":"0.949"}], "timestamp":"1780179016417", "event_type":"price_change"}
{"market":"0x0c4cd2055d6ea89354ffddc55d6dbcef9355748112ea952fc925f3db6a5c457f", "price_changes":[{"asset_id":"18812649149814341758733697580460697418474693998558159483117100240528657629879", "price":"0.088", "size":"15069.46", "side":"SELL", "hash":"265b96c6fbe96242ea4cd00da26021cc1cff5e00", "best_bid":"0.085", "best_ask":"0.086"}, {"asset_id":"115428153746996892211798999366308897078723117634059783423375188043903703749062", "price":"0.912", "size":"15069.46", "side":"BUY", "hash":"272300f1027f9437315a13f94e1d204a28bee639", "best_bid":"0.914", "best_ask":"0.915"}], "timestamp":"1780179016418", "event_type":"price_change"}
{"market":"0x375409bc5eeeff961e82b479caeccc20f33d15738e5bce1186d628aa3d9dfb1f", "price_changes":[{"asset_id":"115556263888245616435851357148058235707004733438163639091106356867234218207169", "price":"0.115", "size":"12019.15", "side":"SELL", "hash":"5096093556951f12df881575721b774d1e1bbb42", "best_bid":"0.112", "best_ask":"0.113"}, {"asset_id":"77121637225348873006259930776623502125079210522997384841464684944292365296940", "price":"0.885", "size":"12019.15", "side":"BUY", "hash":"63be304c2aff447271944d1ee704e476b750fbbd", "best_bid":"0.887", "best_ask":"0.888"}], "timestamp":"1780179016421", "event_type":"price_change"}
{"market":"0x0c4cd2055d6ea89354ffddc55d6dbcef9355748112ea952fc925f3db6a5c457f", "price_changes":[{"asset_id":"18812649149814341758733697580460697418474693998558159483117100240528657629879", "price":"0.088", "size":"15129.46", "side":"SELL", "hash":"7631f1f1f24ce58a1113f0d7e1b4c04172ee5bde", "best_bid":"0.085", "best_ask":"0.086"}, {"asset_id":"115428153746996892211798999366308897078723117634059783423375188043903703749062", "price":"0.912", "size":"15129.46", "side":"BUY", "hash":"8c800436d98a1219b44ec71c2ccff316c868c8aa", "best_bid":"0.914", "best_ask":"0.915"}], "timestamp":"1780179016513", "event_type":"price_change"}
{"market":"0x375409bc5eeeff961e82b479caeccc20f33d15738e5bce1186d628aa3d9dfb1f", "price_changes":[{"asset_id":"115556263888245616435851357148058235707004733438163639091106356867234218207169", "price":"0.115", "size":"12079.15", "side":"SELL", "hash":"39f17182f12b002d145c5722fae5678748e8155b", "best_bid":"0.112", "best_ask":"0.113"}, {"asset_id":"77121637225348873006259930776623502125079210522997384841464684944292365296940", "price":"0.885", "size":"12079.15", "side":"BUY", "hash":"0d3f5c961ff1ffeae4e168904f409e5a855a7fd6", "best_bid":"0.887", "best_ask":"0.888"}], "timestamp":"1780179016517", "event_type":"price_change"}
{"market":"0x1595b4818eeb1ea1e0bec5de6f057218e557feee9b405a0e930d290384fa1d16", "price_changes":[{"asset_id":"81739002353269632749850710185641576213562066971072676369728657545679630163887", "price":"0.053", "size":"3371.26", "side":"SELL", "hash":"42abf9589b42bd65b87bdaa1c715397cf3aa229b", "best_bid":"0.051", "best_ask":"0.052"}, {"asset_id":"45484070731786948288366703334552551439356529561722304542938873238430842810537", "price":"0.947", "size":"3371.26", "side":"BUY", "hash":"7c5622f377e3544c836257a1e7bab117284a258c", "best_bid":"0.948", "best_ask":"0.949"}], "timestamp":"1780179016519", "event_type":"price_change"}
{"market":"0x7976b8dbacf9077eb1453a62bcefd6ab2df199acd28aad276ff0d920d6992892", "asset_id":"112680630004798425069810935278212000865453267506345451433803052322987302357330", "best_bid":"0.832", "best_ask":"0.833", "spread":"0.001", "timestamp":"1780179016729", "event_type":"best_bid_ask"}
{"market":"0x7976b8dbacf9077eb1453a62bcefd6ab2df199acd28aad276ff0d920d6992892", "price_changes":[{"asset_id":"4394372887385518214471608448209527405727552777602031099972143344338178308080", "price":"0.168", "size":"126528.94", "side":"SELL", "hash":"751ac904e4d671a5770b21a53a83cdaec93cd94d", "best_bid":"0.167", "best_ask":"0.168"}, {"asset_id":"112680630004798425069810935278212000865453267506345451433803052322987302357330", "price":"0.832", "size":"126528.94", "side":"BUY", "hash":"dcd292bfb4591094d5b5690a1221c830cf46ba6a", "best_bid":"0.832", "best_ask":"0.833"}], "timestamp":"1780179016728", "event_type":"price_change"}
{"market":"0x7976b8dbacf9077eb1453a62bcefd6ab2df199acd28aad276ff0d920d6992892", "asset_id":"112680630004798425069810935278212000865453267506345451433803052322987302357330", "bids":[{"price":"0.001", "size":"13320371.6"}, {"price":"0.002", "size":"9.57"}, {"price":"0.003", "size":"156.25"}, {"price":"0.004", "size":"13.49"}, {"price":"0.009", "size":"8400"}, {"price":"0.01", "size":"7.03"}, {"price":"0.012", "size":"666666"}, {"price":"0.013", "size":"600000"}, {"price":"0.014", "size":"2534.99"}, {"price":"0.016", "size":"125.09"}, {"price":"0.02", "size":"5012"}, {"price":"0.021", "size":"3999.99"}, {"price":"0.022", "size":"5.22"}, {"price":"0.05", "size":"3109.99"}, {"price":"0.051", "size":"10.45"}, {"price":"0.08", "size":"3005"}, {"price":"0.11", "size":"1000"}, {"price":"0.12", "size":"1000"}, {"price":"0.13", "size":"1000"}, {"price":"0.14", "size":"999.99"}, {"price":"0.15", "size":"1000"}, {"price":"0.16", "size":"1000"}, {"price":"0.167", "size":"17.61"}, {"price":"0.196", "size":"301"}, {"price":"0.2", "size":"749.67"}, {"price":"0.207", "size":"400"}, {"price":"0.208", "size":"544.23"}, {"price":"0.209", "size":"300"}, {"price":"0.21", "size":"5.72"}, {"price":"0.23", "size":"408.6"}, {"price":"0.25", "size":"544.97"}, {"price":"0.31", "size":"305.55"}, {"price":"0.32", "size":"205"}, {"price":"0.36", "size":"231.25"}, {"price":"0.384", "size":"7223.76"}, {"price":"0.39", "size":"5"}, {"price":"0.4", "size":"34671.65"}, {"price":"0.403", "size":"1311"}, {"price":"0.42", "size":"211.4"}, {"price":"0.421", "size":"566.22"}, {"price":"0.45", "size":"510.51"}, {"price":"0.451", "size":"510.51"}, {"price":"0.49", "size":"220"}, {"price":"0.5", "size":"29664.87"}, {"price":"0.501", "size":"4216.7"}, {"price":"0.502", "size":"130"}, {"price":"0.504", "size":"457.83"}, {"price":"0.505", "size":"263.77"}, {"price":"0.51", "size":"264.58"}, {"price":"0.52", "size":"100"}, {"price":"0.53", "size":"100"}, {"price":"0.54", "size":"100"}, {"price":"0.55", "size":"726.73"}, {"price":"0.56", "size":"147"}, {"price":"0.57", "size":"100"}, {"price":"0.58", "size":"188.58"}, {"price":"0.59", "size":"110"}, {"price":"0.598", "size":"13.07"}, {"price":"0.6", "size":"26789.54"}, {"price":"0.601", "size":"274.25"}, {"price":"0.602", "size":"406.1"}, {"price":"0.604", "size":"1000"}, {"price":"0.623", "size":"5"}, {"price":"0.63", "size":"3300"}, {"price":"0.634", "size":"1000"}, {"price":"0.65", "size":"15514.62"}, {"price":"0.654", "size":"124.73"}, {"price":"0.656", "size":"122.73"}, {"price":"0.658", "size":"5141.34"}, {"price":"0.66", "size":"1046.85"}, {"price":"0.664", "size":"11100"}, {"price":"0.666", "size":"474.07"}, {"price":"0.671", "size":"100"}, {"price":"0.68", "size":"3006"}, {"price":"0.681", "size":"2095.26"}, {"price":"0.691", "size":"2359.94"}, {"price":"0.694", "size":"1000"}, {"price":"0.7", "size":"311.97"}, {"price":"0.701", "size":"400"}, {"price":"0.718", "size":"100"}, {"price":"0.72", "size":"11.42"}, {"price":"0.724", "size":"1000"}, {"price":"0.726", "size":"16.03"}, {"price":"0.739", "size":"100"}, {"price":"0.744", "size":"1000"}, {"price":"0.75", "size":"371.36"}, {"price":"0.754", "size":"1000"}, {"price":"0.76", "size":"295"}, {"price":"0.761", "size":"30"}, {"price":"0.764", "size":"1107"}, {"price":"0.765", "size":"150"}, {"price":"0.767", "size":"5"}, {"price":"0.77", "size":"17.85"}, {"price":"0.774", "size":"1362.18"}, {"price":"0.78", "size":"125"}, {"price":"0.781", "size":"100"}, {"price":"0.783", "size":"116.02"}, {"price":"0.784", "size":"1000"}, {"price":"0.79", "size":"50"}, {"price":"0.794", "size":"1050"}, {"price":"0.795", "size":"10"}, {"price":"0.796", "size":"100"}, {"price":"0.798", "size":"5"}, {"price":"0.799", "size":"382.17"}, {"price":"0.8", "size":"8271.84"}, {"price":"0.802", "size":"1000"}, {"price":"0.804", "size":"322"}, {"price":"0.806", "size":"145"}, {"price":"0.808", "size":"30"}, {"price":"0.809", "size":"7.3"}, {"price":"0.812", "size":"15279.71"}, {"price":"0.813", "size":"30"}, {"price":"0.814", "size":"10"}, {"price":"0.815", "size":"105.96"}, {"price":"0.816", "size":"49.77"}, {"price":"0.817", "size":"50"}, {"price":"0.818", "size":"9.7"}, {"price":"0.819", "size":"1000"}, {"price":"0.82", "size":"12535.92"}, {"price":"0.821", "size":"8121.56"}, {"price":"0.822", "size":"940.5"}, {"price":"0.823", "size":"1627.85"}, {"price":"0.824", "size":"15407.48"}, {"price":"0.825", "size":"96558.27"}, {"price":"0.826", "size":"58022.86"}, {"price":"0.827", "size":"26925.87"}, {"price":"0.828", "size":"25913.26"}, {"price":"0.829", "size":"2722.4"}, {"price":"0.83", "size":"27652.43"}, {"price":"0.831", "size":"2030"}, {"price":"0.832", "size":"126528.94"}], "asks":[{"price":"0.999", "size":"4816394"}, {"price":"0.998", "size":"2359"}, {"price":"0.997", "size":"100"}, {"price":"0.996", "size":"1111111"}, {"price":"0.995", "size":"255655"}, {"price":"0.994", "size":"100000"}, {"price":"0.993", "size":"10800"}, {"price":"0.992", "size":"10000"}, {"price":"0.991", "size":"10000"}, {"price":"0.99", "size":"10535"}, {"price":"0.989", "size":"10000"}, {"price":"0.988", "size":"10000"}, {"price":"0.987", "size":"5000"}, {"price":"0.986", "size":"5000"}, {"price":"0.985", "size":"5000"}, {"price":"0.984", "size":"5000"}, {"price":"0.982", "size":"5008.33"}, {"price":"0.981", "size":"5000"}, {"price":"0.98", "size":"7380"}, {"price":"0.979", "size":"3000"}, {"price":"0.978", "size":"3000"}, {"price":"0.977", "size":"3000"}, {"price":"0.976", "size":"3000"}, {"price":"0.975", "size":"3000"}, {"price":"0.974", "size":"3000"}, {"price":"0.973", "size":"3000"}, {"price":"0.972", "size":"3000"}, {"price":"0.959", "size":"731.7"}, {"price":"0.951", "size":"100"}, {"price":"0.95", "size":"56135"}, {"price":"0.931", "size":"20"}, {"price":"0.93", "size":"30"}, {"price":"0.927", "size":"30"}, {"price":"0.926", "size":"30"}, {"price":"0.9", "size":"6230"}, {"price":"0.89", "size":"50"}, {"price":"0.889", "size":"1076.32"}, {"price":"0.88", "size":"11038.99"}, {"price":"0.879", "size":"5"}, {"price":"0.878", "size":"5"}, {"price":"0.877", "size":"5"}, {"price":"0.876", "size":"5"}, {"price":"0.875", "size":"5"}, {"price":"0.874", "size":"5"}, {"price":"0.873", "size":"5"}, {"price":"0.872", "size":"5"}, {"price":"0.871", "size":"5"}, {"price":"0.87", "size":"165"}, {"price":"0.869", "size":"5"}, {"price":"0.868", "size":"105"}, {"price":"0.867", "size":"5"}, {"price":"0.866", "size":"5"}, {"price":"0.865", "size":"5"}, {"price":"0.864", "size":"5"}, {"price":"0.863", "size":"5"}, {"price":"0.862", "size":"5"}, {"price":"0.861", "size":"5"}, {"price":"0.86", "size":"2179.99"}, {"price":"0.859", "size":"6015"}, {"price":"0.858", "size":"5005"}, {"price":"0.857", "size":"2505"}, {"price":"0.856", "size":"15"}, {"price":"0.855", "size":"5"}, {"price":"0.854", "size":"6005"}, {"price":"0.853", "size":"3015"}, {"price":"0.852", "size":"775"}, {"price":"0.851", "size":"3105"}, {"price":"0.85", "size":"10190.34"}, {"price":"0.849", "size":"26420"}, {"price":"0.848", "size":"4713.32"}, {"price":"0.847", "size":"18374.44"}, {"price":"0.846", "size":"7112.99"}, {"price":"0.845", "size":"2890"}, {"price":"0.844", "size":"3989.08"}, {"price":"0.843", "size":"30663.44"}, {"price":"0.842", "size":"6895"}, {"price":"0.841", "size":"538.42"}, {"price":"0.84", "size":"3947.71"}, {"price":"0.839", "size":"759"}, {"price":"0.838", "size":"2688.81"}, {"price":"0.837", "size":"8782.11"}, {"price":"0.836", "size":"29232.29"}, {"price":"0.835", "size":"26149.08"}, {"price":"0.834", "size":"4656.87"}, {"price":"0.833", "size":"83184.81"}], "hash":"dcd292bfb4591094d5b5690a1221c830cf46ba6a", "timestamp":"1780179016728", "event_type":"book"}
{"market":"0x7976b8dbacf9077eb1453a62bcefd6ab2df199acd28aad276ff0d920d6992892", "price_changes":[{"asset_id":"4394372887385518214471608448209527405727552777602031099972143344338178308080", "price":"0.178", "size":"930.5", "side":"SELL", "hash":"7faf30035094b28f779d1d0a8a275c62cce861d8", "best_bid":"0.167", "best_ask":"0.168"}, {"asset_id":"112680630004798425069810935278212000865453267506345451433803052322987302357330", "price":"0.822", "size":"930.5", "side":"BUY", "hash":"5add8c1ca755f3bd014f66b454621fcbd9e4534a", "best_bid":"0.832", "best_ask":"0.833"}], "timestamp":"1780179017737", "event_type":"price_change"}
{"market":"0x7976b8dbacf9077eb1453a62bcefd6ab2df199acd28aad276ff0d920d6992892", "price_changes":[{"asset_id":"4394372887385518214471608448209527405727552777602031099972143344338178308080", "price":"0.17", "size":"27662.43", "side":"SELL", "hash":"48e0b1728aae6bf4f7f7e39b1ce42b0540fe9084", "best_bid":"0.167", "best_ask":"0.168"}, {"asset_id":"112680630004798425069810935278212000865453267506345451433803052322987302357330", "price":"0.83", "size":"27662.43", "side":"BUY", "hash":"51ade8cf5d48bcf01502e29471a45759c127a458", "best_bid":"0.832", "best_ask":"0.833"}], "timestamp":"1780179017935", "event_type":"price_change"}
{"market":"0x9b6fef249040fd17e9c107955b37ac2c3e923509b6b0ff01cc463a331ddeb894", "asset_id":"32270411694523539495262303868629477861017829722282576458031815333486368239544", "best_bid":"0.836", "best_ask":"0.837", "spread":"0.001", "timestamp":"1780179018521", "event_type":"best_bid_ask"}
{"market":"0x9b6fef249040fd17e9c107955b37ac2c3e923509b6b0ff01cc463a331ddeb894", "price_changes":[{"asset_id":"108233603819467706476318984012158651931658302669301887462181073562758483842092", "price":"0.163", "size":"15084.23", "side":"BUY", "hash":"259403227f5b0f93c60442ec55b7495cb1beb218", "best_bid":"0.163", "best_ask":"0.164"}, {"asset_id":"32270411694523539495262303868629477861017829722282576458031815333486368239544", "price":"0.837", "size":"15084.23", "side":"SELL", "hash":"37bd41ca3b846061f62ecc13c29314cdc074aa98", "best_bid":"0.836", "best_ask":"0.837"}], "timestamp":"1780179018520", "event_type":"price_change"}
{"market":"0x9b6fef249040fd17e9c107955b37ac2c3e923509b6b0ff01cc463a331ddeb894", "asset_id":"32270411694523539495262303868629477861017829722282576458031815333486368239544", "bids":[{"price":"0.001", "size":"12219098.99"}, {"price":"0.002", "size":"178.57"}, {"price":"0.003", "size":"21.08"}, {"price":"0.009", "size":"18000"}, {"price":"0.01", "size":"100"}, {"price":"0.011", "size":"5.62"}, {"price":"0.012", "size":"1111111"}, {"price":"0.013", "size":"900000"}, {"price":"0.014", "size":"1300"}, {"price":"0.015", "size":"500"}, {"price":"0.02", "size":"99"}, {"price":"0.021", "size":"6.95"}, {"price":"0.05", "size":"246.52"}, {"price":"0.051", "size":"10.84"}, {"price":"0.09", "size":"5.98"}, {"price":"0.1", "size":"15"}, {"price":"0.12", "size":"5005"}, {"price":"0.121", "size":"12000"}, {"price":"0.15", "size":"67.49"}, {"price":"0.163", "size":"36"}, {"price":"0.178", "size":"289.7"}, {"price":"0.2", "size":"796.33"}, {"price":"0.209", "size":"143.54"}, {"price":"0.22", "size":"100.48"}, {"price":"0.221", "size":"5.22"}, {"price":"0.245", "size":"304.87"}, {"price":"0.25", "size":"3597"}, {"price":"0.251", "size":"6000"}, {"price":"0.29", "size":"9.75"}, {"price":"0.3", "size":"55.88"}, {"price":"0.315", "size":"1459.85"}, {"price":"0.33", "size":"1363.34"}, {"price":"0.331", "size":"3000"}, {"price":"0.34", "size":"5"}, {"price":"0.35", "size":"2159.92"}, {"price":"0.4", "size":"34587.44"}, {"price":"0.401", "size":"3000"}, {"price":"0.47", "size":"5688.73"}, {"price":"0.5", "size":"36470.75"}, {"price":"0.502", "size":"1529.99"}, {"price":"0.503", "size":"14000"}, {"price":"0.51", "size":"90.9"}, {"price":"0.511", "size":"1202.04"}, {"price":"0.55", "size":"513.44"}, {"price":"0.56", "size":"111.11"}, {"price":"0.562", "size":"655.13"}, {"price":"0.563", "size":"65.06"}, {"price":"0.57", "size":"3964.15"}, {"price":"0.6", "size":"22272.15"}, {"price":"0.624", "size":"27.04"}, {"price":"0.636", "size":"105.03"}, {"price":"0.637", "size":"1000"}, {"price":"0.638", "size":"23.57"}, {"price":"0.64", "size":"4479.3"}, {"price":"0.648", "size":"7.39"}, {"price":"0.65", "size":"15415.61"}, {"price":"0.651", "size":"2155.26"}, {"price":"0.667", "size":"1000"}, {"price":"0.67", "size":"18.11"}, {"price":"0.672", "size":"482.66"}, {"price":"0.68", "size":"38"}, {"price":"0.697", "size":"1000"}, {"price":"0.7", "size":"487.37"}, {"price":"0.701", "size":"400"}, {"price":"0.72", "size":"167.14"}, {"price":"0.722", "size":"100"}, {"price":"0.727", "size":"1000"}, {"price":"0.743", "size":"100"}, {"price":"0.747", "size":"1000"}, {"price":"0.75", "size":"1422.54"}, {"price":"0.751", "size":"201"}, {"price":"0.752", "size":"1367"}, {"price":"0.754", "size":"334.02"}, {"price":"0.757", "size":"1000"}, {"price":"0.76", "size":"302"}, {"price":"0.764", "size":"130"}, {"price":"0.767", "size":"1100"}, {"price":"0.777", "size":"1011.23"}, {"price":"0.779", "size":"334.02"}, {"price":"0.78", "size":"237"}, {"price":"0.785", "size":"100"}, {"price":"0.786", "size":"15"}, {"price":"0.787", "size":"1100"}, {"price":"0.788", "size":"10"}, {"price":"0.789", "size":"5555.55"}, {"price":"0.79", "size":"122"}, {"price":"0.793", "size":"10"}, {"price":"0.794", "size":"1000"}, {"price":"0.795", "size":"10"}, {"price":"0.797", "size":"1050"}, {"price":"0.8", "size":"17681.66"}, {"price":"0.801", "size":"100"}, {"price":"0.803", "size":"110"}, {"price":"0.806", "size":"44"}, {"price":"0.807", "size":"1180"}, {"price":"0.808", "size":"675.7"}, {"price":"0.809", "size":"2027"}, {"price":"0.81", "size":"6609.61"}, {"price":"0.811", "size":"4653.91"}, {"price":"0.812", "size":"1708.3"}, {"price":"0.813", "size":"782.67"}, {"price":"0.814", "size":"1703.37"}, {"price":"0.815", "size":"5571.35"}, {"price":"0.816", "size":"10939.83"}, {"price":"0.817", "size":"7549.45"}, {"price":"0.818", "size":"6032.61"}, {"price":"0.819", "size":"340"}, {"price":"0.82", "size":"1037.95"}, {"price":"0.821", "size":"1694.21"}, {"price":"0.822", "size":"22719.93"}, {"price":"0.823", "size":"44358.4"}, {"price":"0.824", "size":"47073"}, {"price":"0.825", "size":"47040.85"}, {"price":"0.827", "size":"654.36"}, {"price":"0.829", "size":"19937.62"}, {"price":"0.83", "size":"26050"}, {"price":"0.831", "size":"3000"}, {"price":"0.832", "size":"2000"}, {"price":"0.833", "size":"4950.42"}, {"price":"0.834", "size":"25006.68"}, {"price":"0.835", "size":"182736.01"}, {"price":"0.836", "size":"38057.32"}], "asks":[{"price":"0.999", "size":"2260279"}, {"price":"0.998", "size":"1557248"}, {"price":"0.997", "size":"1001200"}, {"price":"0.996", "size":"55555"}, {"price":"0.995", "size":"90100"}, {"price":"0.99", "size":"720"}, {"price":"0.985", "size":"5.01"}, {"price":"0.984", "size":"555555"}, {"price":"0.983", "size":"60000"}, {"price":"0.982", "size":"105435.9"}, {"price":"0.981", "size":"800"}, {"price":"0.98", "size":"5430"}, {"price":"0.978", "size":"3000"}, {"price":"0.976", "size":"3000"}, {"price":"0.974", "size":"3000"}, {"price":"0.972", "size":"3000"}, {"price":"0.97", "size":"3000"}, {"price":"0.968", "size":"3000"}, {"price":"0.966", "size":"3000"}, {"price":"0.96", "size":"750"}, {"price":"0.951", "size":"100"}, {"price":"0.95", "size":"150"}, {"price":"0.94", "size":"10"}, {"price":"0.937", "size":"16.27"}, {"price":"0.936", "size":"30"}, {"price":"0.935", "size":"10"}, {"price":"0.934", "size":"20"}, {"price":"0.931", "size":"10"}, {"price":"0.93", "size":"50"}, {"price":"0.926", "size":"20"}, {"price":"0.925", "size":"5"}, {"price":"0.924", "size":"30"}, {"price":"0.923", "size":"20"}, {"price":"0.922", "size":"20"}, {"price":"0.921", "size":"20"}, {"price":"0.92", "size":"140"}, {"price":"0.91", "size":"10100"}, {"price":"0.905", "size":"105.2"}, {"price":"0.9", "size":"6296.92"}, {"price":"0.899", "size":"1076.68"}, {"price":"0.893", "size":"37.72"}, {"price":"0.892", "size":"40"}, {"price":"0.89", "size":"400"}, {"price":"0.889", "size":"5000"}, {"price":"0.885", "size":"9"}, {"price":"0.884", "size":"90"}, {"price":"0.88", "size":"120"}, {"price":"0.879", "size":"7500"}, {"price":"0.878", "size":"5000"}, {"price":"0.877", "size":"100"}, {"price":"0.875", "size":"956.59"}, {"price":"0.874", "size":"2500"}, {"price":"0.87", "size":"328"}, {"price":"0.869", "size":"2567"}, {"price":"0.868", "size":"47"}, {"price":"0.867", "size":"1933.93"}, {"price":"0.866", "size":"57"}, {"price":"0.865", "size":"37"}, {"price":"0.864", "size":"5017"}, {"price":"0.863", "size":"3727"}, {"price":"0.862", "size":"7"}, {"price":"0.861", "size":"7"}, {"price":"0.86", "size":"717"}, {"price":"0.859", "size":"7"}, {"price":"0.858", "size":"507"}, {"price":"0.857", "size":"97"}, {"price":"0.856", "size":"7"}, {"price":"0.855", "size":"37"}, {"price":"0.854", "size":"37"}, {"price":"0.853", "size":"722"}, {"price":"0.852", "size":"7"}, {"price":"0.851", "size":"707"}, {"price":"0.85", "size":"6520"}, {"price":"0.849", "size":"877"}, {"price":"0.848", "size":"7"}, {"price":"0.847", "size":"27"}, {"price":"0.846", "size":"287"}, {"price":"0.845", "size":"3760.64"}, {"price":"0.844", "size":"20417"}, {"price":"0.843", "size":"28647.14"}, {"price":"0.842", "size":"10076.94"}, {"price":"0.841", "size":"56.6"}, {"price":"0.84", "size":"67783.1"}, {"price":"0.839", "size":"12119.44"}, {"price":"0.838", "size":"4311.83"}, {"price":"0.837", "size":"15084.23"}], "hash":"37bd41ca3b846061f62ecc13c29314cdc074aa98", "timestamp":"1780179018520", "event_type":"book"}
{"id":"2397870", "question":"Spread: Minnesota Twins (-2.5)", "market":"0x80a3213884ff06d54b7bafc78b54c1adcc4f33109b725b3d6f95ea1be3350c40", "slug":"mlb-min-pit-2026-05-31-spread-away-2pt5", "description":"In the upcoming MLB game between the Minnesota Twins and Pittsburgh Pirates, scheduled for May 31 at 1:35 PM ET:\n\nThis market will resolve to \"Minnesota Twins\" if the Minnesota Twins win the game by 3 or more runs.\n\nOtherwise, this market will resolve to \"Pittsburgh Pirates\". If the game ends in a tie, this market will resolve to \"Pittsburgh Pirates\".\n\nIf the game is postponed, this market will remain open until the game has been completed. If the game is canceled entirely, with no make-up game, this market will resolve 50-50.\n\nTo know when a postponed game will be played, please check the home team's schedule on MLB.com for the listed team and look for the game described as a makeup game.\n\nThe primary resolution source for this market is the official final statistics of the event as recognized by the governing body or event organizers. However, if the governing body or event organizers have not published final match statistics within 24 hours after the event's conclusion, a consensus of credible reporting may be used instead.", "assets_ids":["26233128354185683483761957563516548586250900144516190011159879868152480780412", "71503558040364959965426798471451640977163780786210550478243452014144682968595"], "outcomes":["Minnesota Twins", "Pittsburgh Pirates"], "event_message":{"id":"523527", "ticker":"mlb-min-pit-2026-05-31", "slug":"mlb-min-pit-2026-05-31", "title":"Minnesota Twins vs. Pittsburgh Pirates", "description":"In the upcoming MLB game between the Minnesota Twins and Pittsburgh Pirates, scheduled for May 31 at 1:35PM ET:\n\nThis market will resolve to \"Minnesota Twins\" if the Minnesota Twins win the game.\n\nThis market will resolve to \"Pittsburgh Pirates\" if the Pittsburgh Pirates win the game.\n\nIf the game is postponed, this market will remain open until the game has been completed. If the game is canceled entirely, with no make-up game, or ends in a tie, this market will resolve 50-50.\n\nThe primary resolution source for this market is the official final statistics of the event as recognized by the governing body or event organizers. However, if the governing body or event organizers have not published final match statistics within 24 hours after the event's conclusion, a consensus of credible reporting may be used instead."}, "timestamp":"1780179018794", "event_type":"new_market", "tags":[], "condition_id":"0x80a3213884ff06d54b7bafc78b54c1adcc4f33109b725b3d6f95ea1be3350c40", "active":false, "clob_token_ids":["26233128354185683483761957563516548586250900144516190011159879868152480780412", "71503558040364959965426798471451640977163780786210550478243452014144682968595"], "sports_market_type":"spreads", "line":"-2.5", "game_start_time":"2026-05-31 17:35:00+00", "order_price_min_tick_size":"0.01", "group_item_title":"Spread -2.5", "taker_base_fee":"1000", "fees_enabled":true, "fee_schedule":{"exponent":"1", "rate":"0.03", "taker_only":true, "rebate_rate":"0.25"}}
{"id":"2397645", "question":"Fight to Go the Distance?", "market":"0x0f5faec922e48adc567824532829edbe11bc1b588ac50bbe974b6dfc529fecd0", "slug":"ufc-ion-nav-2026-06-20-go-the-distance", "description":"This market will resolve to \"Yes\" if the fight between Ion Cutelaba and Navajo Stirling at UFC Fight Night: Kape vs. Horiguchi, scheduled for June 20, 2026, goes the full scheduled number of rounds and the result is determined by the judges' scorecards. Otherwise, it will resolve to \"No.\"\n\nDraws decided by the judges' scorecards after all scheduled rounds are completed will resolve \"Yes.\" Technical decisions or technical draws declared before all rounds are completed will resolve \"No.\"\n\nIf the bout is ruled a No Contest, not scored, canceled, or postponed beyond July 4, 2026, this market will resolve \"50-50.\"\n\nThe resolution source for this market will be official information from the UFC.", "assets_ids":["79986683147027436980959927941884367653566370519030609018716148150339634695409", "108495324464077196265784493888876026424430518338275641149155125794855928014057"], "outcomes":["Yes", "No"], "event_message":{"id":"542616", "ticker":"ufc-ion-nav-2026-06-20", "slug":"ufc-ion-nav-2026-06-20", "title":"UFC Fight Night: Ion Cutelaba vs. Navajo Stirling (Light Heavyweight, Main Card)", "description":"This market will resolve to \"Ion Cutelaba\" if Ion Cutelaba is officially declared the winner of the fight against Navajo Stirling at UFC Fight Night: Kape vs. Horiguchi, scheduled for June 20, 2026.\n\nIt will resolve to \"Navajo Stirling\" if Navajo Stirling is officially declared the winner.\n\nIf the fight is declared a draw or technical draw, ruled a No Contest, not scored, canceled, or postponed beyond July 4, 2026, this market will resolve \"50-50.\"\n\nThe resolution source for this market will be official information from the UFC."}, "timestamp":"1780179019822", "event_type":"new_market", "tags":[], "condition_id":"0x0f5faec922e48adc567824532829edbe11bc1b588ac50bbe974b6dfc529fecd0", "active":false, "clob_token_ids":["79986683147027436980959927941884367653566370519030609018716148150339634695409", "108495324464077196265784493888876026424430518338275641149155125794855928014057"], "sports_market_type":"ufc_go_the_distance", "line":"", "game_start_time":"2026-06-20 17:00:00+00", "order_price_min_tick_size":"0.01", "group_item_title":"Fight to Go the Distance?", "taker_base_fee":"1000", "fees_enabled":true, "fee_schedule":{"exponent":"1", "rate":"0.03", "taker_only":true, "rebate_rate":"0.25"}}
PONG
{"market":"0x375409bc5eeeff961e82b479caeccc20f33d15738e5bce1186d628aa3d9dfb1f", "price_changes":[{"asset_id":"77121637225348873006259930776623502125079210522997384841464684944292365296940", "price":"0.2", "size":"1000", "side":"BUY", "hash":"797e8ccf07f8a6cc6027b1a71e6fe1d38ce98ceb", "best_bid":"0.887", "best_ask":"0.888"}, {"asset_id":"115556263888245616435851357148058235707004733438163639091106356867234218207169", "price":"0.8", "size":"1000", "side":"SELL", "hash":"c0cbeb48522d3d00df99eca24af8cd1d25d1e6e5", "best_bid":"0.112", "best_ask":"0.113"}], "timestamp":"1780179021583", "event_type":"price_change"}
{"market":"0x375409bc5eeeff961e82b479caeccc20f33d15738e5bce1186d628aa3d9dfb1f", "price_changes":[{"asset_id":"77121637225348873006259930776623502125079210522997384841464684944292365296940", "price":"0.3", "size":"2974.99", "side":"BUY", "hash":"6feb39ddcc0555db3b409c7163b991cf83a22793", "best_bid":"0.887", "best_ask":"0.888"}, {"asset_id":"115556263888245616435851357148058235707004733438163639091106356867234218207169", "price":"0.7", "size":"2974.99", "side":"SELL", "hash":"185e20cca13ddaad411b29f5b5c9069e0025d6b0", "best_bid":"0.112", "best_ask":"0.113"}], "timestamp":"1780179021588", "event_type":"price_change"}
{"market":"0x375409bc5eeeff961e82b479caeccc20f33d15738e5bce1186d628aa3d9dfb1f", "price_changes":[{"asset_id":"77121637225348873006259930776623502125079210522997384841464684944292365296940", "price":"0.1", "size":"2991.34", "side":"BUY", "hash":"6a537656cbbd8437ca08be53b54a8c0dcc90f496", "best_bid":"0.887", "best_ask":"0.888"}, {"asset_id":"115556263888245616435851357148058235707004733438163639091106356867234218207169", "price":"0.9", "size":"2991.34", "side":"SELL", "hash":"11ce32b0d823f06bed4a5994aefe40f81994b8b0", "best_bid":"0.112", "best_ask":"0.113"}], "timestamp":"1780179021593", "event_type":"price_change"}
{"market":"0x375409bc5eeeff961e82b479caeccc20f33d15738e5bce1186d628aa3d9dfb1f", "price_changes":[{"asset_id":"77121637225348873006259930776623502125079210522997384841464684944292365296940", "price":"0.4", "size":"36025", "side":"BUY", "hash":"e7b5e690c0330a4f7f6c443e3448522a7027c757", "best_bid":"0.887", "best_ask":"0.888"}, {"asset_id":"115556263888245616435851357148058235707004733438163639091106356867234218207169", "price":"0.6", "size":"36025", "side":"SELL", "hash":"2af1132e1b6733f2fa76ff91561c52a7cd7348ee", "best_bid":"0.112", "best_ask":"0.113"}], "timestamp":"1780179021598", "event_type":"price_change"}
{"market":"0x30d55d8124ee1e12dabe89201badc45669b81dff69e4ce44d961f32878ec178a", "price_changes":[{"asset_id":"52986718774908357330412653486471347449818893503063830313445318937088822580057", "price":"0.2", "size":"1000", "side":"BUY", "hash":"09bc9c0442c38b143abdb5d73814bf86f922faf7", "best_bid":"0.91", "best_ask":"0.911"}, {"asset_id":"27576533317283401577758999384642760405921738493660383550832555714312627457443", "price":"0.8", "size":"1000", "side":"SELL", "hash":"296dc1ad638f0215d9c5625767021434f410de57", "best_bid":"0.089", "best_ask":"0.09"}], "timestamp":"1780179021616", "event_type":"price_change"}
{"market":"0x30d55d8124ee1e12dabe89201badc45669b81dff69e4ce44d961f32878ec178a", "price_changes":[{"asset_id":"52986718774908357330412653486471347449818893503063830313445318937088822580057", "price":"0.4", "size":"34625", "side":"BUY", "hash":"8a3b46fcac30a094c01b11577dc1e113fa0d31b9", "best_bid":"0.91", "best_ask":"0.911"}, {"asset_id":"27576533317283401577758999384642760405921738493660383550832555714312627457443", "price":"0.6", "size":"34625", "side":"SELL", "hash":"08c79fc02d5fe36b81076c8e7907e76b3ef85290", "best_bid":"0.089", "best_ask":"0.09"}], "timestamp":"1780179021619", "event_type":"price_change"}
{"market":"0x30d55d8124ee1e12dabe89201badc45669b81dff69e4ce44d961f32878ec178a", "price_changes":[{"asset_id":"52986718774908357330412653486471347449818893503063830313445318937088822580057", "price":"0.1", "size":"2500", "side":"BUY", "hash":"88d39f69992af2e6a8f86497282c40f01f3cec00", "best_bid":"0.91", "best_ask":"0.911"}, {"asset_id":"27576533317283401577758999384642760405921738493660383550832555714312627457443", "price":"0.9", "size":"2500", "side":"SELL", "hash":"198f68e8f1de644e5adf9494a04a397fe27114ee", "best_bid":"0.089", "best_ask":"0.09"}], "timestamp":"1780179021622", "event_type":"price_change"}
{"market":"0x30d55d8124ee1e12dabe89201badc45669b81dff69e4ce44d961f32878ec178a", "price_changes":[{"asset_id":"52986718774908357330412653486471347449818893503063830313445318937088822580057", "price":"0.3", "size":"605", "side":"BUY", "hash":"e012acbe973a2fc31bee108f54a1b2a15b56a90b", "best_bid":"0.91", "best_ask":"0.911"}, {"asset_id":"27576533317283401577758999384642760405921738493660383550832555714312627457443", "price":"0.7", "size":"605", "side":"SELL", "hash":"d8def32142db0b1effddf728fa6e57d7b0092951", "best_bid":"0.089", "best_ask":"0.09"}], "timestamp":"1780179021626", "event_type":"price_change"}
{"market":"0x0c4cd2055d6ea89354ffddc55d6dbcef9355748112ea952fc925f3db6a5c457f", "price_changes":[{"asset_id":"115428153746996892211798999366308897078723117634059783423375188043903703749062", "price":"0.05", "size":"4060", "side":"BUY", "hash":"9212b8e5eaa6cc11a242ddafde3433979bcf7f86", "best_bid":"0.914", "best_ask":"0.915"}, {"asset_id":"18812649149814341758733697580460697418474693998558159483117100240528657629879", "price":"0.95", "size":"4060", "side":"SELL", "hash":"d747f818f20e8dc178b099d5619a73d8efbecc6d", "best_bid":"0.085", "best_ask":"0.086"}], "timestamp":"1780179021642", "event_type":"price_change"}
{"market":"0x0c4cd2055d6ea89354ffddc55d6dbcef9355748112ea952fc925f3db6a5c457f", "price_changes":[{"asset_id":"115428153746996892211798999366308897078723117634059783423375188043903703749062", "price":"0.05", "size":"7660", "side":"BUY", "hash":"e9d5edad4fcfc97d07b7b035a12cf1b8a1c1791a", "best_bid":"0.914", "best_ask":"0.915"}, {"asset_id":"18812649149814341758733697580460697418474693998558159483117100240528657629879", "price":"0.95", "size":"7660", "side":"SELL", "hash":"0e09d4a067d52b5eb5eff1fe0d7eb96f2dba0cca", "best_bid":"0.085", "best_ask":"0.086"}], "timestamp":"1780179021645", "event_type":"price_change"}
{"market":"0x0c4cd2055d6ea89354ffddc55d6dbcef9355748112ea952fc925f3db6a5c457f", "price_changes":[{"asset_id":"115428153746996892211798999366308897078723117634059783423375188043903703749062", "price":"0.05", "size":"12660", "side":"BUY", "hash":"f64f011cd03b53ec3cd51f5b8955477a785dd852", "best_bid":"0.914", "best_ask":"0.915"}, {"asset_id":"18812649149814341758733697580460697418474693998558159483117100240528657629879", "price":"0.95", "size":"12660", "side":"SELL", "hash":"90c1ab5e16aa83fa3f47fed14e28e19f3879d69a", "best_bid":"0.085", "best_ask":"0.086"}], "timestamp":"1780179021647", "event_type":"price_change"}
{"market":"0x0c4cd2055d6ea89354ffddc55d6dbcef9355748112ea952fc925f3db6a5c457f", "price_changes":[{"asset_id":"115428153746996892211798999366308897078723117634059783423375188043903703749062", "price":"0.05", "size":"14660", "side":"BUY", "hash":"5c9d39934c829c8fbbd98a5504c75f77ee7a0ccc", "best_bid":"0.914", "best_ask":"0.915"}, {"asset_id":"18812649149814341758733697580460697418474693998558159483117100240528657629879", "price":"0.95", "size":"14660", "side":"SELL", "hash":"e96bd79e0a65d34200ff911067e73ad2b24a8bfa", "best_bid":"0.085", "best_ask":"0.086"}], "timestamp":"1780179021652", "event_type":"price_change"}
{"market":"0x1595b4818eeb1ea1e0bec5de6f057218e557feee9b405a0e930d290384fa1d16", "price_changes":[{"asset_id":"45484070731786948288366703334552551439356529561722304542938873238430842810537", "price":"0.1", "size":"2500", "side":"BUY", "hash":"d0d75e64719d773e5c8eb0f53b4c961e7063d2b1", "best_bid":"0.948", "best_ask":"0.949"}, {"asset_id":"81739002353269632749850710185641576213562066971072676369728657545679630163887", "price":"0.9", "size":"2500", "side":"SELL", "hash":"3dc892393ba75e1daa8a635f984a714cce1ada4b", "best_bid":"0.051", "best_ask":"0.052"}], "timestamp":"1780179021671", "event_type":"price_change"}
{"market":"0x1595b4818eeb1ea1e0bec5de6f057218e557feee9b405a0e930d290384fa1d16", "price_changes":[{"asset_id":"45484070731786948288366703334552551439356529561722304542938873238430842810537", "price":"0.3", "size":"600", "side":"BUY", "hash":"336117e444184129b2aff5dc3f416af593b6d848", "best_bid":"0.948", "best_ask":"0.949"}, {"asset_id":"81739002353269632749850710185641576213562066971072676369728657545679630163887", "price":"0.7", "size":"600", "side":"SELL", "hash":"72b780f88c76febde7a176a760ae37ee2a021e23", "best_bid":"0.051", "best_ask":"0.052"}], "timestamp":"1780179021673", "event_type":"price_change"}
{"market":"0x1595b4818eeb1ea1e0bec5de6f057218e557feee9b405a0e930d290384fa1d16", "price_changes":[{"asset_id":"45484070731786948288366703334552551439356529561722304542938873238430842810537", "price":"0.4", "size":"34625", "side":"BUY", "hash":"983d0d9cb81955a7337eaf38d4f2a55a4fdc562d", "best_bid":"0.948", "best_ask":"0.949"}, {"asset_id":"81739002353269632749850710185641576213562066971072676369728657545679630163887", "price":"0.6", "size":"34625", "side":"SELL", "hash":"30e3e45395f7ed5c56984147cb0275b498bb5fdb", "best_bid":"0.051", "best_ask":"0.052"}], "timestamp":"1780179021676", "event_type":"price_change"}
{"market":"0x1595b4818eeb1ea1e0bec5de6f057218e557feee9b405a0e930d290384fa1d16", "price_changes":[{"asset_id":"45484070731786948288366703334552551439356529561722304542938873238430842810537", "price":"0.2", "size":"1000", "side":"BUY", "hash":"01a9c615edc7623e68898ade18e09b410e188259", "best_bid":"0.948", "best_ask":"0.949"}, {"asset_id":"81739002353269632749850710185641576213562066971072676369728657545679630163887", "price":"0.8", "size":"1000", "side":"SELL", "hash":"a186f4c950f46edf75b8ffa6517bafb83af078d4", "best_bid":"0.051", "best_ask":"0.052"}], "timestamp":"1780179021679", "event_type":"price_change"}
{"market":"0x4f3421fb2daf5cca7430ed8d8132463963081572d75434393a1808fdb8829fe8", "price_changes":[{"asset_id":"31940783580344558651011323787577288681658737625185216525249046282994042503801", "price":"0.02", "size":"5000", "side":"BUY", "hash":"a857b0f0fe0eabd79ad9680fb4c07e3d669c45f3", "best_bid":"0.899", "best_ask":"0.9"}, {"asset_id":"45415751658241142530386585138386640503488308219341470020075667342738719018629", "price":"0.98", "size":"5000", "side":"SELL", "hash":"0b795362cd8ace6441ea1ff017164947e0c1d861", "best_bid":"0.1", "best_ask":"0.101"}], "timestamp":"1780179021697", "event_type":"price_change"}
{"market":"0x4f3421fb2daf5cca7430ed8d8132463963081572d75434393a1808fdb8829fe8", "price_changes":[{"asset_id":"31940783580344558651011323787577288681658737625185216525249046282994042503801", "price":"0.02", "size":"14000", "side":"BUY", "hash":"b4f6e88b7e861af2c6c58146fae2460fcf889277", "best_bid":"0.899", "best_ask":"0.9"}, {"asset_id":"45415751658241142530386585138386640503488308219341470020075667342738719018629", "price":"0.98", "size":"14000", "side":"SELL", "hash":"861aa6355ab250309c7721a367a993ec84034e1a", "best_bid":"0.1", "best_ask":"0.101"}], "timestamp":"1780179021706", "event_type":"price_change"}
{"market":"0x4f3421fb2daf5cca7430ed8d8132463963081572d75434393a1808fdb8829fe8", "price_changes":[{"asset_id":"31940783580344558651011323787577288681658737625185216525249046282994042503801", "price":"0.02", "size":"24000", "side":"BUY", "hash":"d3a799cfa0d54bdaa4ab53c796fb6bef128cb9a0", "best_bid":"0.899", "best_ask":"0.9"}, {"asset_id":"45415751658241142530386585138386640503488308219341470020075667342738719018629", "price":"0.98", "size":"24000", "side":"SELL", "hash":"cf0cd2eac596d9cbadb2cb3d7ce0f81e978356cd", "best_bid":"0.1", "best_ask":"0.101"}], "timestamp":"1780179021710", "event_type":"price_change"}
{"market":"0x4f3421fb2daf5cca7430ed8d8132463963081572d75434393a1808fdb8829fe8", "price_changes":[{"asset_id":"31940783580344558651011323787577288681658737625185216525249046282994042503801", "price":"0.02", "size":"36500", "side":"BUY", "hash":"0f4b447ba1b6d737df54d26c22dede581ff64373", "best_bid":"0.899", "best_ask":"0.9"}, {"asset_id":"45415751658241142530386585138386640503488308219341470020075667342738719018629", "price":"0.98", "size":"36500", "side":"SELL", "hash":"487de9bef4f8b7b0caafb0564122ae6c40d27cf1", "best_bid":"0.1", "best_ask":"0.101"}], "timestamp":"1780179021714", "event_type":"price_change"}
{"market":"0x7876851632c295043c66536150a304cb785abdf712ba8489d298c6e6926be106", "price_changes":[{"asset_id":"19291692040378529618917910599727571242305935029274321291612270922648172794670", "price":"0.1", "size":"2500", "side":"BUY", "hash":"4355b0e18ef2d57677e39b40a48ab33a11172a92", "best_bid":"0.989", "best_ask":"0.99"}, {"asset_id":"97239126062673310243763617236644392945530356142765650402171508075574679292913", "price":"0.9", "size":"2500", "side":"SELL", "hash":"ebbd8367f20f9844a22c77cb82c3861c3672fd1f", "best_bid":"0.01", "best_ask":"0.011"}], "timestamp":"1780179021808", "event_type":"price_change"}
{"market":"0x7876851632c295043c66536150a304cb785abdf712ba8489d298c6e6926be106", "price_changes":[{"asset_id":"19291692040378529618917910599727571242305935029274321291612270922648172794670", "price":"0.4", "size":"34625", "side":"BUY", "hash":"33a8bca9a6f0d00f118efc21b28a2c61d9f17be7", "best_bid":"0.989", "best_ask":"0.99"}, {"asset_id":"97239126062673310243763617236644392945530356142765650402171508075574679292913", "price":"0.6", "size":"34625", "side":"SELL", "hash":"7f771c1398aa04e6c8d0245851e71fe9b207c7ce", "best_bid":"0.01", "best_ask":"0.011"}], "timestamp":"1780179021811", "event_type":"price_change"}
{"market":"0x7876851632c295043c66536150a304cb785abdf712ba8489d298c6e6926be106", "price_changes":[{"asset_id":"19291692040378529618917910599727571242305935029274321291612270922648172794670", "price":"0.2", "size":"1000", "side":"BUY", "hash":"4ab3a2d795f148332b79c0363dbf41128eaf924d", "best_bid":"0.989", "best_ask":"0.99"}, {"asset_id":"97239126062673310243763617236644392945530356142765650402171508075574679292913", "price":"0.8", "size":"1000", "side":"SELL", "hash":"5d4bf949530552dace8abf7b5edd38c75d495a7d", "best_bid":"0.01", "best_ask":"0.011"}], "timestamp":"1780179021815", "event_type":"price_change"}
{"market":"0x7876851632c295043c66536150a304cb785abdf712ba8489d298c6e6926be106", "price_changes":[{"asset_id":"19291692040378529618917910599727571242305935029274321291612270922648172794670", "price":"0.3", "size":"600", "side":"BUY", "hash":"70fe798ddf359c727e2e9d11e574283c16e5759c", "best_bid":"0.989", "best_ask":"0.99"}, {"asset_id":"97239126062673310243763617236644392945530356142765650402171508075574679292913", "price":"0.7", "size":"600", "side":"SELL", "hash":"a48c57e3390efcc95943ff1c539461ef19a022d2", "best_bid":"0.01", "best_ask":"0.011"}], "timestamp":"1780179021818", "event_type":"price_change"}
{"market":"0x30d55d8124ee1e12dabe89201badc45669b81dff69e4ce44d961f32878ec178a", "asset_id":"52986718774908357330412653486471347449818893503063830313445318937088822580057", "best_bid":"0.91", "best_ask":"0.911", "spread":"0.001", "timestamp":"1780179023197", "event_type":"best_bid_ask"}
{"market":"0x30d55d8124ee1e12dabe89201badc45669b81dff69e4ce44d961f32878ec178a", "price_changes":[{"asset_id":"27576533317283401577758999384642760405921738493660383550832555714312627457443", "price":"0.089", "size":"175421.43", "side":"BUY", "hash":"d723e9d2ffb217a4408ccde82a21836a26ce7433", "best_bid":"0.089", "best_ask":"0.09"}, {"asset_id":"52986718774908357330412653486471347449818893503063830313445318937088822580057", "price":"0.911", "size":"175421.43", "side":"SELL", "hash":"5944cae8d850f6d80391936eda134c9438f306e4", "best_bid":"0.91", "best_ask":"0.911"}], "timestamp":"1780179023197", "event_type":"price_change"}
{"market":"0x30d55d8124ee1e12dabe89201badc45669b81dff69e4ce44d961f32878ec178a", "asset_id":"52986718774908357330412653486471347449818893503063830313445318937088822580057", "bids":[{"price":"0.001", "size":"21109405.6"}, {"price":"0.002", "size":"23.15"}, {"price":"0.004", "size":"2222222"}, {"price":"0.005", "size":"2000000"}, {"price":"0.006", "size":"800"}, {"price":"0.007", "size":"9.04"}, {"price":"0.01", "size":"102.2"}, {"price":"0.013", "size":"1716.8"}, {"price":"0.015", "size":"750"}, {"price":"0.016", "size":"11.01"}, {"price":"0.05", "size":"40"}, {"price":"0.051", "size":"10.88"}, {"price":"0.09", "size":"5"}, {"price":"0.1", "size":"2500"}, {"price":"0.13", "size":"22.93"}, {"price":"0.2", "size":"1000"}, {"price":"0.227", "size":"132.15"}, {"price":"0.228", "size":"5.03"}, {"price":"0.27", "size":"750"}, {"price":"0.3", "size":"605"}, {"price":"0.39", "size":"5"}, {"price":"0.4", "size":"34625"}, {"price":"0.401", "size":"10000"}, {"price":"0.402", "size":"1492"}, {"price":"0.442", "size":"6.78"}, {"price":"0.45", "size":"21"}, {"price":"0.451", "size":"21"}, {"price":"0.5", "size":"25662.35"}, {"price":"0.502", "size":"2000"}, {"price":"0.503", "size":"3100"}, {"price":"0.51", "size":"100"}, {"price":"0.52", "size":"100"}, {"price":"0.53", "size":"100"}, {"price":"0.54", "size":"100"}, {"price":"0.55", "size":"200"}, {"price":"0.56", "size":"100"}, {"price":"0.6", "size":"20920.53"}, {"price":"0.601", "size":"3100"}, {"price":"0.623", "size":"105"}, {"price":"0.637", "size":"100"}, {"price":"0.64", "size":"1263"}, {"price":"0.65", "size":"15539.21"}, {"price":"0.667", "size":"100"}, {"price":"0.67", "size":"50"}, {"price":"0.7", "size":"503.29"}, {"price":"0.74", "size":"1000"}, {"price":"0.75", "size":"1265.57"}, {"price":"0.751", "size":"280"}, {"price":"0.752", "size":"2095.26"}, {"price":"0.76", "size":"117.48"}, {"price":"0.767", "size":"5"}, {"price":"0.77", "size":"1000"}, {"price":"0.78", "size":"355"}, {"price":"0.79", "size":"431.9"}, {"price":"0.794", "size":"100"}, {"price":"0.8", "size":"2556.31"}, {"price":"0.81", "size":"330.25"}, {"price":"0.815", "size":"100"}, {"price":"0.818", "size":"862.62"}, {"price":"0.82", "size":"1217.47"}, {"price":"0.825", "size":"600"}, {"price":"0.83", "size":"1471.36"}, {"price":"0.831", "size":"30"}, {"price":"0.836", "size":"100"}, {"price":"0.84", "size":"1168"}, {"price":"0.85", "size":"1697.11"}, {"price":"0.855", "size":"163.04"}, {"price":"0.856", "size":"18.23"}, {"price":"0.857", "size":"100"}, {"price":"0.86", "size":"3599.34"}, {"price":"0.868", "size":"2500"}, {"price":"0.87", "size":"1213.55"}, {"price":"0.871", "size":"437.5"}, {"price":"0.872", "size":"2575"}, {"price":"0.875", "size":"600"}, {"price":"0.876", "size":"6300"}, {"price":"0.877", "size":"5000"}, {"price":"0.88", "size":"514.12"}, {"price":"0.882", "size":"15000"}, {"price":"0.883", "size":"200"}, {"price":"0.887", "size":"437.5"}, {"price":"0.888", "size":"106.38"}, {"price":"0.889", "size":"30"}, {"price":"0.89", "size":"30299.11"}, {"price":"0.891", "size":"7245"}, {"price":"0.893", "size":"4000"}, {"price":"0.894", "size":"4180.61"}, {"price":"0.895", "size":"9773.48"}, {"price":"0.897", "size":"62499.24"}, {"price":"0.898", "size":"56"}, {"price":"0.9", "size":"8898.5"}, {"price":"0.901", "size":"11460.63"}, {"price":"0.902", "size":"62999.23"}, {"price":"0.903", "size":"25213.57"}, {"price":"0.904", "size":"764967.01"}, {"price":"0.905", "size":"36998.61"}, {"price":"0.906", "size":"31655.15"}, {"price":"0.907", "size":"2188.69"}, {"price":"0.908", "size":"78431.18"}, {"price":"0.909", "size":"25691.16"}, {"price":"0.91", "size":"135816.7"}], "asks":[{"price":"0.999", "size":"4833617.88"}, {"price":"0.998", "size":"1000671"}, {"price":"0.997", "size":"672"}, {"price":"0.996", "size":"501000"}, {"price":"0.995", "size":"30100"}, {"price":"0.994", "size":"1182511"}, {"price":"0.993", "size":"66355"}, {"price":"0.992", "size":"10000"}, {"price":"0.991", "size":"10000"}, {"price":"0.99", "size":"11815"}, {"price":"0.989", "size":"5000"}, {"price":"0.988", "size":"5000"}, {"price":"0.987", "size":"5000"}, {"price":"0.986", "size":"5000"}, {"price":"0.985", "size":"5000"}, {"price":"0.984", "size":"5000"}, {"price":"0.983", "size":"5000"}, {"price":"0.982", "size":"5000"}, {"price":"0.981", "size":"5000"}, {"price":"0.98", "size":"5375"}, {"price":"0.979", "size":"3999.99"}, {"price":"0.978", "size":"3000"}, {"price":"0.977", "size":"3000"}, {"price":"0.976", "size":"3000"}, {"price":"0.975", "size":"3000"}, {"price":"0.974", "size":"3000"}, {"price":"0.973", "size":"3000"}, {"price":"0.972", "size":"3000"}, {"price":"0.971", "size":"288.25"}, {"price":"0.96", "size":"300"}, {"price":"0.959", "size":"300"}, {"price":"0.958", "size":"600"}, {"price":"0.957", "size":"50"}, {"price":"0.956", "size":"134.85"}, {"price":"0.955", "size":"763.02"}, {"price":"0.951", "size":"10"}, {"price":"0.95", "size":"241"}, {"price":"0.949", "size":"6"}, {"price":"0.948", "size":"6"}, {"price":"0.947", "size":"6"}, {"price":"0.946", "size":"6"}, {"price":"0.945", "size":"6"}, {"price":"0.944", "size":"6"}, {"price":"0.943", "size":"6"}, {"price":"0.942", "size":"6"}, {"price":"0.941", "size":"6"}, {"price":"0.94", "size":"206"}, {"price":"0.939", "size":"6"}, {"price":"0.938", "size":"6"}, {"price":"0.937", "size":"6"}, {"price":"0.936", "size":"6"}, {"price":"0.935", "size":"6"}, {"price":"0.934", "size":"6"}, {"price":"0.933", "size":"6"}, {"price":"0.932", "size":"6"}, {"price":"0.931", "size":"6"}, {"price":"0.93", "size":"816"}, {"price":"0.929", "size":"20006"}, {"price":"0.928", "size":"16"}, {"price":"0.927", "size":"6"}, {"price":"0.926", "size":"6"}, {"price":"0.925", "size":"16"}, {"price":"0.924", "size":"38"}, {"price":"0.923", "size":"6"}, {"price":"0.922", "size":"6"}, {"price":"0.921", "size":"1386"}, {"price":"0.92", "size":"33317.5"}, {"price":"0.919", "size":"32011"}, {"price":"0.918", "size":"10006"}, {"price":"0.917", "size":"11106"}, {"price":"0.916", "size":"59047.99"}, {"price":"0.915", "size":"9118.35"}, {"price":"0.914", "size":"4477.13"}, {"price":"0.913", "size":"8518.68"}, {"price":"0.912", "size":"21904"}, {"price":"0.911", "size":"175421.43"}], "hash":"5944cae8d850f6d80391936eda134c9438f306e4", "timestamp":"1780179023197", "event_type":"book"}
{"market":"0x7876851632c295043c66536150a304cb785abdf712ba8489d298c6e6926be106", "price_changes":[{"asset_id":"19291692040378529618917910599727571242305935029274321291612270922648172794670", "price":"0.966", "size":"232.7", "side":"BUY", "hash":"b2e6966c8e7877d5a6e4bc6eab6595824fa4017a", "best_bid":"0.989", "best_ask":"0.99"}, {"asset_id":"97239126062673310243763617236644392945530356142765650402171508075574679292913", "price":"0.034", "size":"232.7", "side":"SELL", "hash":"54125624df01b2d9e29ecb6785de64a156872d98", "best_bid":"0.01", "best_ask":"0.011"}], "timestamp":"1780179023983", "event_type":"price_change"}
{"market":"0x0c4cd2055d6ea89354ffddc55d6dbcef9355748112ea952fc925f3db6a5c457f", "price_changes":[{"asset_id":"115428153746996892211798999366308897078723117634059783423375188043903703749062", "price":"0.893", "size":"232.7", "side":"BUY", "hash":"02f907e63d7984294a9424e0c86c0a85d463f6c2", "best_bid":"0.914", "best_ask":"0.915"}, {"asset_id":"18812649149814341758733697580460697418474693998558159483117100240528657629879", "price":"0.107", "size":"232.7", "side":"SELL", "hash":"c0df7f036b475e655603cfcbe052a68d7bf58a0d", "best_bid":"0.085", "best_ask":"0.086"}], "timestamp":"1780179024001", "event_type":"price_change"}
{"market":"0x1595b4818eeb1ea1e0bec5de6f057218e557feee9b405a0e930d290384fa1d16", "price_changes":[{"asset_id":"45484070731786948288366703334552551439356529561722304542938873238430842810537", "price":"0.926", "size":"4177.46", "side":"BUY", "hash":"ccb271cded1d72a6202d790ffd67cc14cec0be81", "best_bid":"0.948", "best_ask":"0.949"}, {"asset_id":"81739002353269632749850710185641576213562066971072676369728657545679630163887", "price":"0.074", "size":"4177.46", "side":"SELL", "hash":"457638094405f52fa80fa0caa6a3f6e2d7f68bf0", "best_bid":"0.051", "best_ask":"0.052"}], "timestamp":"1780179024033", "event_type":"price_change"}
{"market":"0x30d55d8124ee1e12dabe89201badc45669b81dff69e4ce44d961f32878ec178a", "price_changes":[{"asset_id":"52986718774908357330412653486471347449818893503063830313445318937088822580057", "price":"0.889", "size":"232.7", "side":"BUY", "hash":"7823803802c6ccfadc23358e1a042ed461fb17cc", "best_bid":"0.91", "best_ask":"0.911"}, {"asset_id":"27576533317283401577758999384642760405921738493660383550832555714312627457443", "price":"0.111", "size":"232.7", "side":"SELL", "hash":"0e3635ed050eef3a5c8299f7bedc8fa44f08b900", "best_bid":"0.089", "best_ask":"0.09"}], "timestamp":"1780179024068", "event_type":"price_change"}
{"market":"0x375409bc5eeeff961e82b479caeccc20f33d15738e5bce1186d628aa3d9dfb1f", "price_changes":[{"asset_id":"77121637225348873006259930776623502125079210522997384841464684944292365296940", "price":"0.866", "size":"344.14", "side":"BUY", "hash":"2c1205476b9a9799f8d659cb450c4c828503a6bf", "best_bid":"0.887", "best_ask":"0.888"}, {"asset_id":"115556263888245616435851357148058235707004733438163639091106356867234218207169", "price":"0.134", "size":"344.14", "side":"SELL", "hash":"5a614b5efb08b7d078aa93f5d88f821dbf90fd30", "best_bid":"0.112", "best_ask":"0.113"}], "timestamp":"1780179024076", "event_type":"price_change"}
{"market":"0x9b6fef249040fd17e9c107955b37ac2c3e923509b6b0ff01cc463a331ddeb894", "price_changes":[{"asset_id":"32270411694523539495262303868629477861017829722282576458031815333486368239544", "price":"0.816", "size":"11142.53", "side":"BUY", "hash":"e90d939055aa88084a627843fefe8f2a470cfbda", "best_bid":"0.836", "best_ask":"0.837"}, {"asset_id":"108233603819467706476318984012158651931658302669301887462181073562758483842092", "price":"0.184", "size":"11142.53", "side":"SELL", "hash":"1d30b9da7a72ac0ac09886f8ad4b13d6db3c0168", "best_bid":"0.163", "best_ask":"0.164"}], "timestamp":"1780179024097", "event_type":"price_change"}
{"market":"0x7976b8dbacf9077eb1453a62bcefd6ab2df199acd28aad276ff0d920d6992892", "price_changes":[{"asset_id":"112680630004798425069810935278212000865453267506345451433803052322987302357330", "price":"0.813", "size":"232.7", "side":"BUY", "hash":"788c3952990ca62f542188da00e72fedd0b6d023", "best_bid":"0.832", "best_ask":"0.833"}, {"asset_id":"4394372887385518214471608448209527405727552777602031099972143344338178308080", "price":"0.187", "size":"232.7", "side":"SELL", "hash":"cfed8f0c4743be82cc817063a1f2a865113cd211", "best_bid":"0.167", "best_ask":"0.168"}], "timestamp":"1780179024139", "event_type":"price_change"}
{"market":"0x4f3421fb2daf5cca7430ed8d8132463963081572d75434393a1808fdb8829fe8", "price_changes":[{"asset_id":"31940783580344558651011323787577288681658737625185216525249046282994042503801", "price":"0.878", "size":"202.7", "side":"BUY", "hash":"9724fb2cd89bb0d9ba322ffc2482064b165a6496", "best_bid":"0.899", "best_ask":"0.9"}, {"asset_id":"45415751658241142530386585138386640503488308219341470020075667342738719018629", "price":"0.122", "size":"202.7", "side":"SELL", "hash":"1d95ab40538647e9f8369c594acb6808ea1d0060", "best_bid":"0.1", "best_ask":"0.101"}], "timestamp":"1780179024169", "event_type":"price_change"}
{"market":"0x0c4cd2055d6ea89354ffddc55d6dbcef9355748112ea952fc925f3db6a5c457f", "asset_id":"115428153746996892211798999366308897078723117634059783423375188043903703749062", "best_bid":"0.914", "best_ask":"0.915", "spread":"0.001", "timestamp":"1780179024586", "event_type":"best_bid_ask"}
{"market":"0x0c4cd2055d6ea89354ffddc55d6dbcef9355748112ea952fc925f3db6a5c457f", "price_changes":[{"asset_id":"18812649149814341758733697580460697418474693998558159483117100240528657629879", "price":"0.086", "size":"294614.03", "side":"SELL", "hash":"53f152a495811401a0d513873d2c9c6b6bb29b38", "best_bid":"0.085", "best_ask":"0.086"}, {"asset_id":"115428153746996892211798999366308897078723117634059783423375188043903703749062", "price":"0.914", "size":"294614.03", "side":"BUY", "hash":"bfc044ca775d8c6c7bcaa505e882e3a1de79356c", "best_bid":"0.914", "best_ask":"0.915"}], "timestamp":"1780179024586", "event_type":"price_change"}
