{"id":"2397712", "question":"Will the fight be won by KO or TKO?", "market":"0x5a0e8d3b6c03aff141d53e4a78a9919e0dad674cdd0ef96a27f229c13c068cc6", "slug":"ufc-mel2-mur2-2026-06-20-win-by-ko-tko", "description":"This market will resolve to \"Yes\" if the fight between Melsik Baghdasaryan and Murtazali Magomedov at UFC Fight Night: Kape vs. Horiguchi, scheduled for June 20, 2026, ends by KO or TKO, including referee stoppage, doctor stoppage, or corner stoppage. Otherwise, it will resolve to \"No.\"\n\nIf the fight ends in a draw or by disqualification (either fighter), it will resolve \"No.\"\n\nIf the bout is ruled a No Contest, not scored, canceled, or postponed beyond July 4, 2026, this market will resolve \"50-50.\"\n\nThe resolution source for this market will be official information from the UFC.", "assets_ids":["111398677566225391097134813445821717635191845324771793581319640274173387373825", "47245061838622745790799588986425832757330029788530408848474518227333713570666"], "outcomes":["Yes", "No"], "event_message":{"id":"542639", "ticker":"ufc-mel2-mur2-2026-06-20", "slug":"ufc-mel2-mur2-2026-06-20", "title":"UFC Fight Night: Melsik Baghdasaryan vs. Murtazali Magomedov (Featherweight, Main Card)", "description":"This market will resolve to \"Melsik Baghdasaryan\" if Melsik Baghdasaryan is officially declared the winner of the fight against Murtazali Magomedov at UFC Fight Night: Kape vs. Horiguchi, scheduled for June 20, 2026.\n\nIt will resolve to \"Murtazali Magomedov\" if Murtazali Magomedov is officially declared the winner.\n\nIf the fight is declared a draw or technical draw, ruled a No Contest, not scored, canceled, or postponed beyond July 4, 2026, this market will resolve \"50-50.\"\n\nThe resolution source for this market will be official information from the UFC."}, "timestamp":"1780179124614", "event_type":"new_market", "tags":[], "condition_id":"0x5a0e8d3b6c03aff141d53e4a78a9919e0dad674cdd0ef96a27f229c13c068cc6", "active":false, "clob_token_ids":["111398677566225391097134813445821717635191845324771793581319640274173387373825", "47245061838622745790799588986425832757330029788530408848474518227333713570666"], "sports_market_type":"ufc_method_of_victory", "line":"", "game_start_time":"2026-06-20 17:00:00+00", "order_price_min_tick_size":"0.01", "group_item_title":"Fight won by KO/TKO?", "taker_base_fee":"1000", "fees_enabled":true, "fee_schedule":{"exponent":"1", "rate":"0.03", "taker_only":true, "rebate_rate":"0.25"}}
{"id":"2397869", "question":"Toronto Blue Jays vs. Baltimore Orioles: O/U 7.5", "market":"0x740fa410d647f60e87cdd23e685052bc559467b50cc685e123bc789c6577f15d", "slug":"mlb-tor-bal-2026-05-31-total-7pt5", "description":"In the upcoming MLB game between the Toronto Blue Jays and Baltimore Orioles, scheduled for May 31 at 12:15 PM ET:\n\nThis market will resolve to \"Over\" if the Toronto Blue Jays and Baltimore Orioles combine to score 8 or more runs in this game.\n\nIf the combined total is less than 8, this market will resolve to \"Under\".\n\nIf the game is postponed, this market will remain open until the game has been completed. If the game is canceled entirely, with no make-up game, this market will resolve 50-50.\n\nTo know when a postponed game will be played, please check the home team's schedule on MLB.com for the listed team and look for the game described as a makeup game.\n\nThe primary resolution source for this market is the official final statistics of the event as recognized by the governing body or event organizers. However, if the governing body or event organizers have not published final match statistics within 24 hours after the event's conclusion, a consensus of credible reporting may be used instead.", "assets_ids":["6328347129093436456801397745768850794611568743805187110551858148808472476380", "4655995691613880971168147526144307314900389912318061944237587474176232442488"], "outcomes":["Over", "Under"], "event_message":{"id":"523526", "ticker":"mlb-tor-bal-2026-05-31", "slug":"mlb-tor-bal-2026-05-31", "title":"Toronto Blue Jays vs. Baltimore Orioles", "description":"In the upcoming MLB game between the Toronto Blue Jays and Baltimore Orioles, scheduled for May 31 at 12:15PM ET:\n\nThis market will resolve to \"Toronto Blue Jays\" if the Toronto Blue Jays win the game.\n\nThis market will resolve to \"Baltimore Orioles\" if the Baltimore Orioles win the game.\n\nIf the game is postponed, this market will remain open until the game has been completed. If the game is canceled entirely, with no make-up game, or ends in a tie, this market will resolve 50-50.\n\nThe primary resolution source for this market is the official final statistics of the event as recognized by the governing body or event organizers. However, if the governing body or event organizers have not published final match statistics within 24 hours after the event's conclusion, a consensus of credible reporting may be used instead."}, "timestamp":"1780179128617", "event_type":"new_market", "tags":[], "condition_id":"0x740fa410d647f60e87cdd23e685052bc559467b50cc685e123bc789c6577f15d", "active":false, "clob_token_ids":["6328347129093436456801397745768850794611568743805187110551858148808472476380", "4655995691613880971168147526144307314900389912318061944237587474176232442488"], "sports_market_type":"totals", "line":"7.5", "game_start_time":"2026-05-31 16:15:00+00", "order_price_min_tick_size":"0.01", "group_item_title":"O/U 7.5", "taker_base_fee":"1000", "fees_enabled":true, "fee_schedule":{"exponent":"1", "rate":"0.03", "taker_only":true, "rebate_rate":"0.25"}}
{"market":"0x375409bc5eeeff961e82b479caeccc20f33d15738e5bce1186d628aa3d9dfb1f", "price_changes":[{"asset_id":"77121637225348873006259930776623502125079210522997384841464684944292365296940", "price":"0.866", "size":"111.44", "side":"BUY", "hash":"7ec903ccbd18ee808196eb34cf523c8f373dd85d", "best_bid":"0.887", "best_ask":"0.888"}, {"asset_id":"115556263888245616435851357148058235707004733438163639091106356867234218207169", "price":"0.134", "size":"111.44", "side":"SELL", "hash":"e4a760bdceccddf63ef03154f00ecfcf161bf99a", "best_bid":"0.112", "best_ask":"0.113"}], "timestamp":"1780179131596", "event_type":"price_change"}
{"market":"0x375409bc5eeeff961e82b479caeccc20f33d15738e5bce1186d628aa3d9dfb1f", "price_changes":[{"asset_id":"77121637225348873006259930776623502125079210522997384841464684944292365296940", "price":"0.857", "size":"1000", "side":"BUY", "hash":"7ec903ccbd18ee808196eb34cf523c8f373dd85d", "best_bid":"0.887", "best_ask":"0.888"}, {"asset_id":"115556263888245616435851357148058235707004733438163639091106356867234218207169", "price":"0.143", "size":"1000", "side":"SELL", "hash":"e4a760bdceccddf63ef03154f00ecfcf161bf99a", "best_bid":"0.112", "best_ask":"0.113"}], "timestamp":"1780179131596", "event_type":"price_change"}
{"market":"0x7876851632c295043c66536150a304cb785abdf712ba8489d298c6e6926be106", "price_changes":[{"asset_id":"19291692040378529618917910599727571242305935029274321291612270922648172794670", "price":"0.966", "size":"0", "side":"BUY", "hash":"e35b31e17245e57b2e02503ff2aba1fd8af40059", "best_bid":"0.989", "best_ask":"0.99"}, {"asset_id":"97239126062673310243763617236644392945530356142765650402171508075574679292913", "price":"0.034", "size":"0", "side":"SELL", "hash":"e7367fcf22fcc753427ef07af107bc4d49245ac0", "best_bid":"0.01", "best_ask":"0.011"}], "timestamp":"1780179131600", "event_type":"price_change"}
{"market":"0x7876851632c295043c66536150a304cb785abdf712ba8489d298c6e6926be106", "price_changes":[{"asset_id":"19291692040378529618917910599727571242305935029274321291612270922648172794670", "price":"0.957", "size":"3000", "side":"BUY", "hash":"e35b31e17245e57b2e02503ff2aba1fd8af40059", "best_bid":"0.989", "best_ask":"0.99"}, {"asset_id":"97239126062673310243763617236644392945530356142765650402171508075574679292913", "price":"0.043", "size":"3000", "side":"SELL", "hash":"e7367fcf22fcc753427ef07af107bc4d49245ac0", "best_bid":"0.01", "best_ask":"0.011"}], "timestamp":"1780179131600", "event_type":"price_change"}
{"market":"0x375409bc5eeeff961e82b479caeccc20f33d15738e5bce1186d628aa3d9dfb1f", "price_changes":[{"asset_id":"77121637225348873006259930776623502125079210522997384841464684944292365296940", "price":"0.847", "size":"1263.15", "side":"BUY", "hash":"7ec903ccbd18ee808196eb34cf523c8f373dd85d", "best_bid":"0.887", "best_ask":"0.888"}, {"asset_id":"115556263888245616435851357148058235707004733438163639091106356867234218207169", "price":"0.153", "size":"1263.15", "side":"SELL", "hash":"e4a760bdceccddf63ef03154f00ecfcf161bf99a", "best_bid":"0.112", "best_ask":"0.113"}], "timestamp":"1780179131596", "event_type":"price_change"}
{"market":"0x7876851632c295043c66536150a304cb785abdf712ba8489d298c6e6926be106", "price_changes":[{"asset_id":"19291692040378529618917910599727571242305935029274321291612270922648172794670", "price":"0.947", "size":"1000", "side":"BUY", "hash":"e35b31e17245e57b2e02503ff2aba1fd8af40059", "best_bid":"0.989", "best_ask":"0.99"}, {"asset_id":"97239126062673310243763617236644392945530356142765650402171508075574679292913", "price":"0.053", "size":"1000", "side":"SELL", "hash":"e7367fcf22fcc753427ef07af107bc4d49245ac0", "best_bid":"0.01", "best_ask":"0.011"}], "timestamp":"1780179131600", "event_type":"price_change"}
{"market":"0x7876851632c295043c66536150a304cb785abdf712ba8489d298c6e6926be106", "price_changes":[{"asset_id":"19291692040378529618917910599727571242305935029274321291612270922648172794670", "price":"0.917", "size":"1000", "side":"BUY", "hash":"e35b31e17245e57b2e02503ff2aba1fd8af40059", "best_bid":"0.989", "best_ask":"0.99"}, {"asset_id":"97239126062673310243763617236644392945530356142765650402171508075574679292913", "price":"0.083", "size":"1000", "side":"SELL", "hash":"e7367fcf22fcc753427ef07af107bc4d49245ac0", "best_bid":"0.01", "best_ask":"0.011"}], "timestamp":"1780179131600", "event_type":"price_change"}
{"market":"0x375409bc5eeeff961e82b479caeccc20f33d15738e5bce1186d628aa3d9dfb1f", "price_changes":[{"asset_id":"77121637225348873006259930776623502125079210522997384841464684944292365296940", "price":"0.817", "size":"1000", "side":"BUY", "hash":"7ec903ccbd18ee808196eb34cf523c8f373dd85d", "best_bid":"0.887", "best_ask":"0.888"}, {"asset_id":"115556263888245616435851357148058235707004733438163639091106356867234218207169", "price":"0.183", "size":"1000", "side":"SELL", "hash":"e4a760bdceccddf63ef03154f00ecfcf161bf99a", "best_bid":"0.112", "best_ask":"0.113"}], "timestamp":"1780179131596", "event_type":"price_change"}
{"market":"0x375409bc5eeeff961e82b479caeccc20f33d15738e5bce1186d628aa3d9dfb1f", "price_changes":[{"asset_id":"77121637225348873006259930776623502125079210522997384841464684944292365296940", "price":"0.767", "size":"8608.24", "side":"BUY", "hash":"7ec903ccbd18ee808196eb34cf523c8f373dd85d", "best_bid":"0.887", "best_ask":"0.888"}, {"asset_id":"115556263888245616435851357148058235707004733438163639091106356867234218207169", "price":"0.233", "size":"8608.24", "side":"SELL", "hash":"e4a760bdceccddf63ef03154f00ecfcf161bf99a", "best_bid":"0.112", "best_ask":"0.113"}], "timestamp":"1780179131596", "event_type":"price_change"}
{"market":"0x0c4cd2055d6ea89354ffddc55d6dbcef9355748112ea952fc925f3db6a5c457f", "price_changes":[{"asset_id":"115428153746996892211798999366308897078723117634059783423375188043903703749062", "price":"0.893", "size":"0", "side":"BUY", "hash":"02c1e08fc3abec41ac1d2cdcb82d28c29633031e", "best_bid":"0.914", "best_ask":"0.915"}, {"asset_id":"18812649149814341758733697580460697418474693998558159483117100240528657629879", "price":"0.107", "size":"0", "side":"SELL", "hash":"657203412e10795544d214d46a4d2e59d57ae995", "best_bid":"0.085", "best_ask":"0.086"}], "timestamp":"1780179131669", "event_type":"price_change"}
{"market":"0x0c4cd2055d6ea89354ffddc55d6dbcef9355748112ea952fc925f3db6a5c457f", "price_changes":[{"asset_id":"115428153746996892211798999366308897078723117634059783423375188043903703749062", "price":"0.884", "size":"10789.73", "side":"BUY", "hash":"02c1e08fc3abec41ac1d2cdcb82d28c29633031e", "best_bid":"0.914", "best_ask":"0.915"}, {"asset_id":"18812649149814341758733697580460697418474693998558159483117100240528657629879", "price":"0.116", "size":"10789.73", "side":"SELL", "hash":"657203412e10795544d214d46a4d2e59d57ae995", "best_bid":"0.085", "best_ask":"0.086"}], "timestamp":"1780179131669", "event_type":"price_change"}
{"market":"0x0c4cd2055d6ea89354ffddc55d6dbcef9355748112ea952fc925f3db6a5c457f", "price_changes":[{"asset_id":"115428153746996892211798999366308897078723117634059783423375188043903703749062", "price":"0.874", "size":"1000", "side":"BUY", "hash":"02c1e08fc3abec41ac1d2cdcb82d28c29633031e", "best_bid":"0.914", "best_ask":"0.915"}, {"asset_id":"18812649149814341758733697580460697418474693998558159483117100240528657629879", "price":"0.126", "size":"1000", "side":"SELL", "hash":"657203412e10795544d214d46a4d2e59d57ae995", "best_bid":"0.085", "best_ask":"0.086"}], "timestamp":"1780179131669", "event_type":"price_change"}
{"market":"0x0c4cd2055d6ea89354ffddc55d6dbcef9355748112ea952fc925f3db6a5c457f", "price_changes":[{"asset_id":"115428153746996892211798999366308897078723117634059783423375188043903703749062", "price":"0.844", "size":"1000", "side":"BUY", "hash":"02c1e08fc3abec41ac1d2cdcb82d28c29633031e", "best_bid":"0.914", "best_ask":"0.915"}, {"asset_id":"18812649149814341758733697580460697418474693998558159483117100240528657629879", "price":"0.156", "size":"1000", "side":"SELL", "hash":"657203412e10795544d214d46a4d2e59d57ae995", "best_bid":"0.085", "best_ask":"0.086"}], "timestamp":"1780179131669", "event_type":"price_change"}
{"market":"0x1595b4818eeb1ea1e0bec5de6f057218e557feee9b405a0e930d290384fa1d16", "price_changes":[{"asset_id":"45484070731786948288366703334552551439356529561722304542938873238430842810537", "price":"0.926", "size":"3944.76", "side":"BUY", "hash":"d313e7051b63b16792868b81f1309ea276b8263a", "best_bid":"0.948", "best_ask":"0.949"}, {"asset_id":"81739002353269632749850710185641576213562066971072676369728657545679630163887", "price":"0.074", "size":"3944.76", "side":"SELL", "hash":"4de42ffc9378ab6ae0cb1eb832e1fb4fd7365c20", "best_bid":"0.051", "best_ask":"0.052"}], "timestamp":"1780179131596", "event_type":"price_change"}
{"market":"0x1595b4818eeb1ea1e0bec5de6f057218e557feee9b405a0e930d290384fa1d16", "price_changes":[{"asset_id":"45484070731786948288366703334552551439356529561722304542938873238430842810537", "price":"0.917", "size":"0", "side":"BUY", "hash":"d313e7051b63b16792868b81f1309ea276b8263a", "best_bid":"0.948", "best_ask":"0.949"}, {"asset_id":"81739002353269632749850710185641576213562066971072676369728657545679630163887", "price":"0.083", "size":"0", "side":"SELL", "hash":"4de42ffc9378ab6ae0cb1eb832e1fb4fd7365c20", "best_bid":"0.051", "best_ask":"0.052"}], "timestamp":"1780179131596", "event_type":"price_change"}
{"market":"0x1595b4818eeb1ea1e0bec5de6f057218e557feee9b405a0e930d290384fa1d16", "price_changes":[{"asset_id":"45484070731786948288366703334552551439356529561722304542938873238430842810537", "price":"0.907", "size":"1075", "side":"BUY", "hash":"d313e7051b63b16792868b81f1309ea276b8263a", "best_bid":"0.948", "best_ask":"0.949"}, {"asset_id":"81739002353269632749850710185641576213562066971072676369728657545679630163887", "price":"0.093", "size":"1075", "side":"SELL", "hash":"4de42ffc9378ab6ae0cb1eb832e1fb4fd7365c20", "best_bid":"0.051", "best_ask":"0.052"}], "timestamp":"1780179131596", "event_type":"price_change"}
{"market":"0x1595b4818eeb1ea1e0bec5de6f057218e557feee9b405a0e930d290384fa1d16", "price_changes":[{"asset_id":"45484070731786948288366703334552551439356529561722304542938873238430842810537", "price":"0.877", "size":"1000", "side":"BUY", "hash":"d313e7051b63b16792868b81f1309ea276b8263a", "best_bid":"0.948", "best_ask":"0.949"}, {"asset_id":"81739002353269632749850710185641576213562066971072676369728657545679630163887", "price":"0.123", "size":"1000", "side":"SELL", "hash":"4de42ffc9378ab6ae0cb1eb832e1fb4fd7365c20", "best_bid":"0.051", "best_ask":"0.052"}], "timestamp":"1780179131596", "event_type":"price_change"}
{"market":"0x9b6fef249040fd17e9c107955b37ac2c3e923509b6b0ff01cc463a331ddeb894", "price_changes":[{"asset_id":"32270411694523539495262303868629477861017829722282576458031815333486368239544", "price":"0.816", "size":"10909.83", "side":"BUY", "hash":"d23f40950f66962d7f375e3b01a4a59bcc2b4cbf", "best_bid":"0.836", "best_ask":"0.837"}, {"asset_id":"108233603819467706476318984012158651931658302669301887462181073562758483842092", "price":"0.184", "size":"10909.83", "side":"SELL", "hash":"9485c9588d54210cf59eede1237697d070d0fc3a", "best_bid":"0.163", "best_ask":"0.164"}], "timestamp":"1780179131714", "event_type":"price_change"}
{"market":"0x9b6fef249040fd17e9c107955b37ac2c3e923509b6b0ff01cc463a331ddeb894", "price_changes":[{"asset_id":"32270411694523539495262303868629477861017829722282576458031815333486368239544", "price":"0.807", "size":"1135", "side":"BUY", "hash":"d23f40950f66962d7f375e3b01a4a59bcc2b4cbf", "best_bid":"0.836", "best_ask":"0.837"}, {"asset_id":"108233603819467706476318984012158651931658302669301887462181073562758483842092", "price":"0.193", "size":"1135", "side":"SELL", "hash":"9485c9588d54210cf59eede1237697d070d0fc3a", "best_bid":"0.163", "best_ask":"0.164"}], "timestamp":"1780179131714", "event_type":"price_change"}
{"market":"0x9b6fef249040fd17e9c107955b37ac2c3e923509b6b0ff01cc463a331ddeb894", "price_changes":[{"asset_id":"32270411694523539495262303868629477861017829722282576458031815333486368239544", "price":"0.797", "size":"1000", "side":"BUY", "hash":"d23f40950f66962d7f375e3b01a4a59bcc2b4cbf", "best_bid":"0.836", "best_ask":"0.837"}, {"asset_id":"108233603819467706476318984012158651931658302669301887462181073562758483842092", "price":"0.203", "size":"1000", "side":"SELL", "hash":"9485c9588d54210cf59eede1237697d070d0fc3a", "best_bid":"0.163", "best_ask":"0.164"}], "timestamp":"1780179131714", "event_type":"price_change"}
{"market":"0x9b6fef249040fd17e9c107955b37ac2c3e923509b6b0ff01cc463a331ddeb894", "price_changes":[{"asset_id":"32270411694523539495262303868629477861017829722282576458031815333486368239544", "price":"0.767", "size":"1000", "side":"BUY", "hash":"d23f40950f66962d7f375e3b01a4a59bcc2b4cbf", "best_bid":"0.836", "best_ask":"0.837"}, {"asset_id":"108233603819467706476318984012158651931658302669301887462181073562758483842092", "price":"0.233", "size":"1000", "side":"SELL", "hash":"9485c9588d54210cf59eede1237697d070d0fc3a", "best_bid":"0.163", "best_ask":"0.164"}], "timestamp":"1780179131714", "event_type":"price_change"}
{"market":"0x30d55d8124ee1e12dabe89201badc45669b81dff69e4ce44d961f32878ec178a", "price_changes":[{"asset_id":"52986718774908357330412653486471347449818893503063830313445318937088822580057", "price":"0.889", "size":"0", "side":"BUY", "hash":"2f23add8168b25b26fb8e07cdc9bbe0dc693435a", "best_bid":"0.91", "best_ask":"0.911"}, {"asset_id":"27576533317283401577758999384642760405921738493660383550832555714312627457443", "price":"0.111", "size":"0", "side":"SELL", "hash":"0e57d3c03ef1bf60cde8ad307598ee11eb820851", "best_bid":"0.089", "best_ask":"0.09"}], "timestamp":"1780179131731", "event_type":"price_change"}
{"market":"0x30d55d8124ee1e12dabe89201badc45669b81dff69e4ce44d961f32878ec178a", "price_changes":[{"asset_id":"52986718774908357330412653486471347449818893503063830313445318937088822580057", "price":"0.88", "size":"88.12", "side":"BUY", "hash":"2f23add8168b25b26fb8e07cdc9bbe0dc693435a", "best_bid":"0.91", "best_ask":"0.911"}, {"asset_id":"27576533317283401577758999384642760405921738493660383550832555714312627457443", "price":"0.12", "size":"88.12", "side":"SELL", "hash":"0e57d3c03ef1bf60cde8ad307598ee11eb820851", "best_bid":"0.089", "best_ask":"0.09"}], "timestamp":"1780179131731", "event_type":"price_change"}
{"market":"0x30d55d8124ee1e12dabe89201badc45669b81dff69e4ce44d961f32878ec178a", "price_changes":[{"asset_id":"52986718774908357330412653486471347449818893503063830313445318937088822580057", "price":"0.87", "size":"1163.55", "side":"BUY", "hash":"2f23add8168b25b26fb8e07cdc9bbe0dc693435a", "best_bid":"0.91", "best_ask":"0.911"}, {"asset_id":"27576533317283401577758999384642760405921738493660383550832555714312627457443", "price":"0.13", "size":"1163.55", "side":"SELL", "hash":"0e57d3c03ef1bf60cde8ad307598ee11eb820851", "best_bid":"0.089", "best_ask":"0.09"}], "timestamp":"1780179131731", "event_type":"price_change"}
{"market":"0x30d55d8124ee1e12dabe89201badc45669b81dff69e4ce44d961f32878ec178a", "price_changes":[{"asset_id":"52986718774908357330412653486471347449818893503063830313445318937088822580057", "price":"0.84", "size":"1068", "side":"BUY", "hash":"2f23add8168b25b26fb8e07cdc9bbe0dc693435a", "best_bid":"0.91", "best_ask":"0.911"}, {"asset_id":"27576533317283401577758999384642760405921738493660383550832555714312627457443", "price":"0.16", "size":"1068", "side":"SELL", "hash":"0e57d3c03ef1bf60cde8ad307598ee11eb820851", "best_bid":"0.089", "best_ask":"0.09"}], "timestamp":"1780179131731", "event_type":"price_change"}
{"market":"0x30d55d8124ee1e12dabe89201badc45669b81dff69e4ce44d961f32878ec178a", "price_changes":[{"asset_id":"52986718774908357330412653486471347449818893503063830313445318937088822580057", "price":"0.79", "size":"31.9", "side":"BUY", "hash":"2f23add8168b25b26fb8e07cdc9bbe0dc693435a", "best_bid":"0.91", "best_ask":"0.911"}, {"asset_id":"27576533317283401577758999384642760405921738493660383550832555714312627457443", "price":"0.21", "size":"31.9", "side":"SELL", "hash":"0e57d3c03ef1bf60cde8ad307598ee11eb820851", "best_bid":"0.089", "best_ask":"0.09"}], "timestamp":"1780179131731", "event_type":"price_change"}
{"market":"0x4f3421fb2daf5cca7430ed8d8132463963081572d75434393a1808fdb8829fe8", "price_changes":[{"asset_id":"31940783580344558651011323787577288681658737625185216525249046282994042503801", "price":"0.869", "size":"0", "side":"BUY", "hash":"7e34f3e431de2b5ca859748c9527f3753163e412", "best_bid":"0.899", "best_ask":"0.9"}, {"asset_id":"45415751658241142530386585138386640503488308219341470020075667342738719018629", "price":"0.131", "size":"0", "side":"SELL", "hash":"e5c562a86a2a75793420eaf02703abbfcff0cf8e", "best_bid":"0.1", "best_ask":"0.101"}], "timestamp":"1780179131863", "event_type":"price_change"}
{"market":"0x4f3421fb2daf5cca7430ed8d8132463963081572d75434393a1808fdb8829fe8", "price_changes":[{"asset_id":"31940783580344558651011323787577288681658737625185216525249046282994042503801", "price":"0.859", "size":"0", "side":"BUY", "hash":"7e34f3e431de2b5ca859748c9527f3753163e412", "best_bid":"0.899", "best_ask":"0.9"}, {"asset_id":"45415751658241142530386585138386640503488308219341470020075667342738719018629", "price":"0.141", "size":"0", "side":"SELL", "hash":"e5c562a86a2a75793420eaf02703abbfcff0cf8e", "best_bid":"0.1", "best_ask":"0.101"}], "timestamp":"1780179131863", "event_type":"price_change"}
{"market":"0x4f3421fb2daf5cca7430ed8d8132463963081572d75434393a1808fdb8829fe8", "price_changes":[{"asset_id":"31940783580344558651011323787577288681658737625185216525249046282994042503801", "price":"0.829", "size":"1000", "side":"BUY", "hash":"7e34f3e431de2b5ca859748c9527f3753163e412", "best_bid":"0.899", "best_ask":"0.9"}, {"asset_id":"45415751658241142530386585138386640503488308219341470020075667342738719018629", "price":"0.171", "size":"1000", "side":"SELL", "hash":"e5c562a86a2a75793420eaf02703abbfcff0cf8e", "best_bid":"0.1", "best_ask":"0.101"}], "timestamp":"1780179131863", "event_type":"price_change"}
{"market":"0x4f3421fb2daf5cca7430ed8d8132463963081572d75434393a1808fdb8829fe8", "price_changes":[{"asset_id":"31940783580344558651011323787577288681658737625185216525249046282994042503801", "price":"0.778", "size":"0", "side":"BUY", "hash":"7e34f3e431de2b5ca859748c9527f3753163e412", "best_bid":"0.899", "best_ask":"0.9"}, {"asset_id":"45415751658241142530386585138386640503488308219341470020075667342738719018629", "price":"0.222", "size":"0", "side":"SELL", "hash":"e5c562a86a2a75793420eaf02703abbfcff0cf8e", "best_bid":"0.1", "best_ask":"0.101"}], "timestamp":"1780179131863", "event_type":"price_change"}
{"market":"0x7976b8dbacf9077eb1453a62bcefd6ab2df199acd28aad276ff0d920d6992892", "price_changes":[{"asset_id":"112680630004798425069810935278212000865453267506345451433803052322987302357330", "price":"0.803", "size":"0", "side":"BUY", "hash":"d36773e1a46252acb770712d926c0a2d12ba6e31", "best_bid":"0.832", "best_ask":"0.833"}, {"asset_id":"4394372887385518214471608448209527405727552777602031099972143344338178308080", "price":"0.197", "size":"0", "side":"SELL", "hash":"07237c39b07e98edd9c29ad62a04b290563f1388", "best_bid":"0.167", "best_ask":"0.168"}], "timestamp":"1780179132082", "event_type":"price_change"}
{"market":"0x4f3421fb2daf5cca7430ed8d8132463963081572d75434393a1808fdb8829fe8", "price_changes":[{"asset_id":"31940783580344558651011323787577288681658737625185216525249046282994042503801", "price":"0.876", "size":"0", "side":"BUY", "hash":"96df8853d5cf98c1301ce91d0bcb49d5bac4e4e1", "best_bid":"0.899", "best_ask":"0.9"}, {"asset_id":"45415751658241142530386585138386640503488308219341470020075667342738719018629", "price":"0.124", "size":"0", "side":"SELL", "hash":"0536b65a36944436ea11ff5591bac87ee96939f8", "best_bid":"0.1", "best_ask":"0.101"}], "timestamp":"1780179132410", "event_type":"price_change"}
PONG
{"market":"0x7976b8dbacf9077eb1453a62bcefd6ab2df199acd28aad276ff0d920d6992892", "price_changes":[{"asset_id":"4394372887385518214471608448209527405727552777602031099972143344338178308080", "price":"0.18", "size":"12525.92", "side":"SELL", "hash":"5a783e1347dca2923b13ffe0c7b34d4355619060", "best_bid":"0.167", "best_ask":"0.168"}, {"asset_id":"112680630004798425069810935278212000865453267506345451433803052322987302357330", "price":"0.82", "size":"12525.92", "side":"BUY", "hash":"d37671c62330c91ffa6e103d74ae2e2ff90bf900", "best_bid":"0.832", "best_ask":"0.833"}], "timestamp":"1780179132738", "event_type":"price_change"}
{"market":"0x0c4cd2055d6ea89354ffddc55d6dbcef9355748112ea952fc925f3db6a5c457f", "price_changes":[{"asset_id":"115428153746996892211798999366308897078723117634059783423375188043903703749062", "price":"0.93", "size":"13415.27", "side":"SELL", "hash":"d715018b8ae31cc9ac1cac6fadf1a49e04e98bc5", "best_bid":"0.914", "best_ask":"0.915"}, {"asset_id":"18812649149814341758733697580460697418474693998558159483117100240528657629879", "price":"0.07", "size":"13415.27", "side":"BUY", "hash":"4b9cb23fa786180becca33ccd32e1571e63bd2ca", "best_bid":"0.085", "best_ask":"0.086"}], "timestamp":"1780179132737", "event_type":"price_change"}
{"market":"0x0c4cd2055d6ea89354ffddc55d6dbcef9355748112ea952fc925f3db6a5c457f", "price_changes":[{"asset_id":"115428153746996892211798999366308897078723117634059783423375188043903703749062", "price":"0.76", "size":"0", "side":"BUY", "hash":"d715018b8ae31cc9ac1cac6fadf1a49e04e98bc5", "best_bid":"0.914", "best_ask":"0.915"}, {"asset_id":"18812649149814341758733697580460697418474693998558159483117100240528657629879", "price":"0.24", "size":"0", "side":"SELL", "hash":"4b9cb23fa786180becca33ccd32e1571e63bd2ca", "best_bid":"0.085", "best_ask":"0.086"}], "timestamp":"1780179132737", "event_type":"price_change"}
{"market":"0x375409bc5eeeff961e82b479caeccc20f33d15738e5bce1186d628aa3d9dfb1f", "price_changes":[{"asset_id":"77121637225348873006259930776623502125079210522997384841464684944292365296940", "price":"0.867", "size":"15000", "side":"BUY", "hash":"c92797fdf385ee96c94e79a8a72a972e48478c2b", "best_bid":"0.887", "best_ask":"0.888"}, {"asset_id":"115556263888245616435851357148058235707004733438163639091106356867234218207169", "price":"0.133", "size":"15000", "side":"SELL", "hash":"3246a49c71bc6475551cc6531bf92ceacd88e0b3", "best_bid":"0.112", "best_ask":"0.113"}], "timestamp":"1780179132754", "event_type":"price_change"}
{"market":"0x9b6fef249040fd17e9c107955b37ac2c3e923509b6b0ff01cc463a331ddeb894", "price_changes":[{"asset_id":"108233603819467706476318984012158651931658302669301887462181073562758483842092", "price":"0.19", "size":"6599.61", "side":"SELL", "hash":"5d2c30b4cc0254b43dee7d825d5d4321becc3d8d", "best_bid":"0.163", "best_ask":"0.164"}, {"asset_id":"32270411694523539495262303868629477861017829722282576458031815333486368239544", "price":"0.81", "size":"6599.61", "side":"BUY", "hash":"d342f2e80f48aac3d8870642d67cf3dd97f0ffeb", "best_bid":"0.836", "best_ask":"0.837"}], "timestamp":"1780179132762", "event_type":"price_change"}
{"id":"2397702", "question":"O/U 1.5 Rounds", "market":"0x896c1d716e288aca468ddfba1e7da81625d6a2a222ad7f18c9f7c95e7b31846e", "slug":"ufc-kev15-and26-2026-06-20-totals-1pt5", "description":"Each market will resolve to \"Over\" if the fight between Kevin Borjas and Andre Lima at UFC Fight Night: Kape vs. Horiguchi, scheduled for June 20, 2026, lasts beyond the listed round threshold.\n\nEach market will resolve to \"Under\" if the fight does not last beyond the listed round threshold.\n\nFor example:\n\n\"Over 1.5 Rounds\" will resolve \"Yes\" if the fight continues past the 2:30 mark of Round 2.\n\n\"Under 1.5 Rounds\" will resolve \"Yes\" if the fight ends before the 2:30 mark of Round 2.\n\nIf the fight ends exactly at the threshold, it will resolve \"50-50.\"\n\nIf the bout is not scored, postponed beyond July 4, 2026, or canceled, all options will resolve \"50-50.\"\n\nThe resolution source for this market will be official information from the UFC.", "assets_ids":["71954539112072212566391840178481315631127535581210887772477336737748690989873", "40624097232016249880968088440186862218814199851589041898776865248791914705555"], "outcomes":["Over", "Under"], "event_message":{"id":"542631", "ticker":"ufc-kev15-and26-2026-06-20", "slug":"ufc-kev15-and26-2026-06-20", "title":"UFC Fight Night: Kevin Borjas vs. Andre Lima (Flyweight, Main Card)", "description":"This market will resolve to \"Kevin Borjas\" if Kevin Borjas is officially declared the winner of the fight against Andre Lima at UFC Fight Night: Kape vs. Horiguchi, scheduled for June 20, 2026.\n\nIt will resolve to \"Andre Lima\" if Andre Lima is officially declared the winner.\n\nIf the fight is declared a draw or technical draw, ruled a No Contest, not scored, canceled, or postponed beyond July 4, 2026, this market will resolve \"50-50.\"\n\nThe resolution source for this market will be official information from the UFC."}, "timestamp":"1780179132765", "event_type":"new_market", "tags":[], "condition_id":"0x896c1d716e288aca468ddfba1e7da81625d6a2a222ad7f18c9f7c95e7b31846e", "active":false, "clob_token_ids":["71954539112072212566391840178481315631127535581210887772477336737748690989873", "40624097232016249880968088440186862218814199851589041898776865248791914705555"], "sports_market_type":"totals", "line":"1.5", "game_start_time":"2026-06-20 17:00:00+00", "order_price_min_tick_size":"0.01", "group_item_title":"O/U 1.5 Rounds", "taker_base_fee":"1000", "fees_enabled":true, "fee_schedule":{"exponent":"1", "rate":"0.03", "taker_only":true, "rebate_rate":"0.25"}}
{"market":"0x0c4cd2055d6ea89354ffddc55d6dbcef9355748112ea952fc925f3db6a5c457f", "price_changes":[{"asset_id":"115428153746996892211798999366308897078723117634059783423375188043903703749062", "price":"0.846", "size":"100", "side":"BUY", "hash":"b6c24e4645f25399137830cc2485c43f70c82f66", "best_bid":"0.914", "best_ask":"0.915"}, {"asset_id":"18812649149814341758733697580460697418474693998558159483117100240528657629879", "price":"0.154", "size":"100", "side":"SELL", "hash":"43b33045d63bb543209fabced4c933dd2e9858f5", "best_bid":"0.085", "best_ask":"0.086"}], "timestamp":"1780179132870", "event_type":"price_change"}
{"market":"0x4f3421fb2daf5cca7430ed8d8132463963081572d75434393a1808fdb8829fe8", "price_changes":[{"asset_id":"31940783580344558651011323787577288681658737625185216525249046282994042503801", "price":"0.781", "size":"500", "side":"BUY", "hash":"6ceb3e5579fdbe484cd74997a45bcd81a1c8590b", "best_bid":"0.899", "best_ask":"0.9"}, {"asset_id":"45415751658241142530386585138386640503488308219341470020075667342738719018629", "price":"0.219", "size":"500", "side":"SELL", "hash":"3229dc6bf7a4fc72ff6a7810ed1209055c70b5af", "best_bid":"0.1", "best_ask":"0.101"}], "timestamp":"1780179132888", "event_type":"price_change"}
{"market":"0x1595b4818eeb1ea1e0bec5de6f057218e557feee9b405a0e930d290384fa1d16", "price_changes":[{"asset_id":"45484070731786948288366703334552551439356529561722304542938873238430842810537", "price":"0.928", "size":"7245.61", "side":"BUY", "hash":"2406c910cfd63f25412777393a8c7f72dc0136bb", "best_bid":"0.948", "best_ask":"0.949"}, {"asset_id":"81739002353269632749850710185641576213562066971072676369728657545679630163887", "price":"0.072", "size":"7245.61", "side":"SELL", "hash":"c91c54628682d219e503f94a31e6bcba5c8f1f8b", "best_bid":"0.051", "best_ask":"0.052"}], "timestamp":"1780179132896", "event_type":"price_change"}
{"market":"0x1595b4818eeb1ea1e0bec5de6f057218e557feee9b405a0e930d290384fa1d16", "price_changes":[{"asset_id":"45484070731786948288366703334552551439356529561722304542938873238430842810537", "price":"0.919", "size":"577.55", "side":"BUY", "hash":"24de5ad327660247ae715cc00db2f19077ba054a", "best_bid":"0.948", "best_ask":"0.949"}, {"asset_id":"81739002353269632749850710185641576213562066971072676369728657545679630163887", "price":"0.081", "size":"577.55", "side":"SELL", "hash":"6b0b32448d4c47c56564e957d5cd22429afed3f6", "best_bid":"0.051", "best_ask":"0.052"}], "timestamp":"1780179132901", "event_type":"price_change"}
{"market":"0x1595b4818eeb1ea1e0bec5de6f057218e557feee9b405a0e930d290384fa1d16", "price_changes":[{"asset_id":"45484070731786948288366703334552551439356529561722304542938873238430842810537", "price":"0.908", "size":"50", "side":"BUY", "hash":"064a275bd6212e5e06dde440a80c27e20fc8da08", "best_bid":"0.948", "best_ask":"0.949"}, {"asset_id":"81739002353269632749850710185641576213562066971072676369728657545679630163887", "price":"0.092", "size":"50", "side":"SELL", "hash":"b998590b66f6872adc7370f72a6db1e94737acf2", "best_bid":"0.051", "best_ask":"0.052"}], "timestamp":"1780179132907", "event_type":"price_change"}
{"market":"0x1595b4818eeb1ea1e0bec5de6f057218e557feee9b405a0e930d290384fa1d16", "price_changes":[{"asset_id":"45484070731786948288366703334552551439356529561722304542938873238430842810537", "price":"0.879", "size":"100", "side":"BUY", "hash":"baceebd1c3b9e6e150f8a7450d1ff03286216950", "best_bid":"0.948", "best_ask":"0.949"}, {"asset_id":"81739002353269632749850710185641576213562066971072676369728657545679630163887", "price":"0.121", "size":"100", "side":"SELL", "hash":"fa54f857d332f5f436d32cde400bbc98a2ba73e7", "best_bid":"0.051", "best_ask":"0.052"}], "timestamp":"1780179132913", "event_type":"price_change"}
{"market":"0x7876851632c295043c66536150a304cb785abdf712ba8489d298c6e6926be106", "price_changes":[{"asset_id":"19291692040378529618917910599727571242305935029274321291612270922648172794670", "price":"0.968", "size":"4519.78", "side":"BUY", "hash":"859e646403e029e361b40b54b7f3d24d6100d6de", "best_bid":"0.989", "best_ask":"0.99"}, {"asset_id":"97239126062673310243763617236644392945530356142765650402171508075574679292913", "price":"0.032", "size":"4519.78", "side":"SELL", "hash":"7a5da16dacae9b316e5bf1e7aa1389c6f11046ab", "best_bid":"0.01", "best_ask":"0.011"}], "timestamp":"1780179132962", "event_type":"price_change"}
{"market":"0x7876851632c295043c66536150a304cb785abdf712ba8489d298c6e6926be106", "price_changes":[{"asset_id":"19291692040378529618917910599727571242305935029274321291612270922648172794670", "price":"0.959", "size":"45", "side":"BUY", "hash":"b3ec53c1b898d373958b1e517e79bc3ec627f014", "best_bid":"0.989", "best_ask":"0.99"}, {"asset_id":"97239126062673310243763617236644392945530356142765650402171508075574679292913", "price":"0.041", "size":"45", "side":"SELL", "hash":"79a2392441a297fa6d9bb7218d60005590444bc0", "best_bid":"0.01", "best_ask":"0.011"}], "timestamp":"1780179133040", "event_type":"price_change"}
{"market":"0x7876851632c295043c66536150a304cb785abdf712ba8489d298c6e6926be106", "price_changes":[{"asset_id":"19291692040378529618917910599727571242305935029274321291612270922648172794670", "price":"0.949", "size":"50", "side":"BUY", "hash":"f6250e19537dc97c7aff2231936a9bc9276e6e56", "best_bid":"0.989", "best_ask":"0.99"}, {"asset_id":"97239126062673310243763617236644392945530356142765650402171508075574679292913", "price":"0.051", "size":"50", "side":"SELL", "hash":"ceffa08c55fb75971b8dc6a1653a61016b51133d", "best_bid":"0.01", "best_ask":"0.011"}], "timestamp":"1780179133059", "event_type":"price_change"}
{"market":"0x7876851632c295043c66536150a304cb785abdf712ba8489d298c6e6926be106", "price_changes":[{"asset_id":"19291692040378529618917910599727571242305935029274321291612270922648172794670", "price":"0.918", "size":"100", "side":"BUY", "hash":"e146ed0dc4b020babf7333b3a0014ffae5fb0906", "best_bid":"0.989", "best_ask":"0.99"}, {"asset_id":"97239126062673310243763617236644392945530356142765650402171508075574679292913", "price":"0.082", "size":"100", "side":"SELL", "hash":"f4797141957b2c8d11e4ce8e4e663150fb581e0c", "best_bid":"0.01", "best_ask":"0.011"}], "timestamp":"1780179133065", "event_type":"price_change"}
{"market":"0x4f3421fb2daf5cca7430ed8d8132463963081572d75434393a1808fdb8829fe8", "price_changes":[{"asset_id":"31940783580344558651011323787577288681658737625185216525249046282994042503801", "price":"0.871", "size":"84.42", "side":"BUY", "hash":"f67a33ece0e7cdc5a9f4685e75a7ab50f25c72a4", "best_bid":"0.899", "best_ask":"0.9"}, {"asset_id":"45415751658241142530386585138386640503488308219341470020075667342738719018629", "price":"0.129", "size":"84.42", "side":"SELL", "hash":"8d7ec859797f185fe5763bfe86c347aef8545bb4", "best_bid":"0.1", "best_ask":"0.101"}], "timestamp":"1780179133151", "event_type":"price_change"}
{"market":"0x4f3421fb2daf5cca7430ed8d8132463963081572d75434393a1808fdb8829fe8", "price_changes":[{"asset_id":"31940783580344558651011323787577288681658737625185216525249046282994042503801", "price":"0.861", "size":"50", "side":"BUY", "hash":"9cf23274c2aacbee4da84fafb6ba3cfa8d6cc52e", "best_bid":"0.899", "best_ask":"0.9"}, {"asset_id":"45415751658241142530386585138386640503488308219341470020075667342738719018629", "price":"0.139", "size":"50", "side":"SELL", "hash":"2cbf66abdc3934461ea89eb1536f7989344f6944", "best_bid":"0.1", "best_ask":"0.101"}], "timestamp":"1780179133162", "event_type":"price_change"}
{"market":"0x4f3421fb2daf5cca7430ed8d8132463963081572d75434393a1808fdb8829fe8", "price_changes":[{"asset_id":"31940783580344558651011323787577288681658737625185216525249046282994042503801", "price":"0.831", "size":"100", "side":"BUY", "hash":"94f598baff762f90ac00c7add7ed01d00450be95", "best_bid":"0.899", "best_ask":"0.9"}, {"asset_id":"45415751658241142530386585138386640503488308219341470020075667342738719018629", "price":"0.169", "size":"100", "side":"SELL", "hash":"1fd24fae2524e13d081ccce461e55408b35ab98d", "best_bid":"0.1", "best_ask":"0.101"}], "timestamp":"1780179133172", "event_type":"price_change"}
{"market":"0x0c4cd2055d6ea89354ffddc55d6dbcef9355748112ea952fc925f3db6a5c457f", "price_changes":[{"asset_id":"115428153746996892211798999366308897078723117634059783423375188043903703749062", "price":"0.93", "size":"13425.27", "side":"SELL", "hash":"9ed537d62bce654552d3ea949ff4e76ae88acf1a", "best_bid":"0.914", "best_ask":"0.915"}, {"asset_id":"18812649149814341758733697580460697418474693998558159483117100240528657629879", "price":"0.07", "size":"13425.27", "side":"BUY", "hash":"abeea07f1fd7202398830f4b79b38d10b7608f90", "best_bid":"0.085", "best_ask":"0.086"}], "timestamp":"1780179133228", "event_type":"price_change"}
{"market":"0x0c4cd2055d6ea89354ffddc55d6dbcef9355748112ea952fc925f3db6a5c457f", "price_changes":[{"asset_id":"115428153746996892211798999366308897078723117634059783423375188043903703749062", "price":"0.75", "size":"3393.18", "side":"BUY", "hash":"c748f3b61b1823ed469d02c2e862f0d9575fb88e", "best_bid":"0.914", "best_ask":"0.915"}, {"asset_id":"18812649149814341758733697580460697418474693998558159483117100240528657629879", "price":"0.25", "size":"3393.18", "side":"SELL", "hash":"24cd9ac36d56f5bdf0560480a29da7b6aac48ce6", "best_bid":"0.085", "best_ask":"0.086"}], "timestamp":"1780179133230", "event_type":"price_change"}
{"market":"0x4f3421fb2daf5cca7430ed8d8132463963081572d75434393a1808fdb8829fe8", "price_changes":[{"asset_id":"31940783580344558651011323787577288681658737625185216525249046282994042503801", "price":"0.88", "size":"429.7", "side":"BUY", "hash":"5d2387db5c3a1c4e9c53ecce002b65628d54be30", "best_bid":"0.899", "best_ask":"0.9"}, {"asset_id":"45415751658241142530386585138386640503488308219341470020075667342738719018629", "price":"0.12", "size":"429.7", "side":"SELL", "hash":"72e2a0931bcb4d6fdcdc519485da637572d43928", "best_bid":"0.1", "best_ask":"0.101"}], "timestamp":"1780179133235", "event_type":"price_change"}
{"market":"0x0c4cd2055d6ea89354ffddc55d6dbcef9355748112ea952fc925f3db6a5c457f", "price_changes":[{"asset_id":"115428153746996892211798999366308897078723117634059783423375188043903703749062", "price":"0.75", "size":"3383.18", "side":"BUY", "hash":"7c98b5dea30da6e56d114c332f5b65b171d3277f", "best_bid":"0.914", "best_ask":"0.915"}, {"asset_id":"18812649149814341758733697580460697418474693998558159483117100240528657629879", "price":"0.25", "size":"3383.18", "side":"SELL", "hash":"4ebd5cd19ced348384ac5ac091fddedc8bcc1b41", "best_bid":"0.085", "best_ask":"0.086"}], "timestamp":"1780179133298", "event_type":"price_change"}
{"market":"0x0c4cd2055d6ea89354ffddc55d6dbcef9355748112ea952fc925f3db6a5c457f", "price_changes":[{"asset_id":"115428153746996892211798999366308897078723117634059783423375188043903703749062", "price":"0.93", "size":"13415.27", "side":"SELL", "hash":"7c98b5dea30da6e56d114c332f5b65b171d3277f", "best_bid":"0.914", "best_ask":"0.915"}, {"asset_id":"18812649149814341758733697580460697418474693998558159483117100240528657629879", "price":"0.07", "size":"13415.27", "side":"BUY", "hash":"4ebd5cd19ced348384ac5ac091fddedc8bcc1b41", "best_bid":"0.085", "best_ask":"0.086"}], "timestamp":"1780179133298", "event_type":"price_change"}
{"market":"0x30d55d8124ee1e12dabe89201badc45669b81dff69e4ce44d961f32878ec178a", "price_changes":[{"asset_id":"52986718774908357330412653486471347449818893503063830313445318937088822580057", "price":"0.791", "size":"400", "side":"BUY", "hash":"18c1c89b36ae01f89c73561c1b06aae21713a564", "best_bid":"0.91", "best_ask":"0.911"}, {"asset_id":"27576533317283401577758999384642760405921738493660383550832555714312627457443", "price":"0.209", "size":"400", "side":"SELL", "hash":"223bc314f6cbd8aa02c776948b1ed880f71e2457", "best_bid":"0.089", "best_ask":"0.09"}], "timestamp":"1780179133379", "event_type":"price_change"}
{"market":"0x0c4cd2055d6ea89354ffddc55d6dbcef9355748112ea952fc925f3db6a5c457f", "price_changes":[{"asset_id":"115428153746996892211798999366308897078723117634059783423375188043903703749062", "price":"0.895", "size":"5552.44", "side":"BUY", "hash":"d99e118f7ccf03cc77bdd4dc60f930fac58cc640", "best_bid":"0.914", "best_ask":"0.915"}, {"asset_id":"18812649149814341758733697580460697418474693998558159483117100240528657629879", "price":"0.105", "size":"5552.44", "side":"SELL", "hash":"add6df62e99026d6d472aed4da0c1da068f3c8d0", "best_bid":"0.085", "best_ask":"0.086"}], "timestamp":"1780179133411", "event_type":"price_change"}
{"market":"0x0c4cd2055d6ea89354ffddc55d6dbcef9355748112ea952fc925f3db6a5c457f", "price_changes":[{"asset_id":"115428153746996892211798999366308897078723117634059783423375188043903703749062", "price":"0.886", "size":"275.12", "side":"BUY", "hash":"44df6b218c8a08ac566d4720da75e862c5196111", "best_bid":"0.914", "best_ask":"0.915"}, {"asset_id":"18812649149814341758733697580460697418474693998558159483117100240528657629879", "price":"0.114", "size":"275.12", "side":"SELL", "hash":"c35ba25bdb5dd9e2ffe966ad11bb9b275c09704a", "best_bid":"0.085", "best_ask":"0.086"}], "timestamp":"1780179133418", "event_type":"price_change"}
{"market":"0x0c4cd2055d6ea89354ffddc55d6dbcef9355748112ea952fc925f3db6a5c457f", "price_changes":[{"asset_id":"115428153746996892211798999366308897078723117634059783423375188043903703749062", "price":"0.876", "size":"125", "side":"BUY", "hash":"1c501d5ea68af0650cdac5f765a9616a31168507", "best_bid":"0.914", "best_ask":"0.915"}, {"asset_id":"18812649149814341758733697580460697418474693998558159483117100240528657629879", "price":"0.124", "size":"125", "side":"SELL", "hash":"016cf9c6cf606bfd95af55c968e5f4125e00a8b0", "best_bid":"0.085", "best_ask":"0.086"}], "timestamp":"1780179133422", "event_type":"price_change"}
{"market":"0x30d55d8124ee1e12dabe89201badc45669b81dff69e4ce44d961f32878ec178a", "price_changes":[{"asset_id":"52986718774908357330412653486471347449818893503063830313445318937088822580057", "price":"0.841", "size":"100", "side":"BUY", "hash":"efcf4ed4fe47597c776168e4b7cce0ad24a83d0c", "best_bid":"0.91", "best_ask":"0.911"}, {"asset_id":"27576533317283401577758999384642760405921738493660383550832555714312627457443", "price":"0.159", "size":"100", "side":"SELL", "hash":"e83903466064dd42fe9135c8d67a77dce9184dcd", "best_bid":"0.089", "best_ask":"0.09"}], "timestamp":"1780179133448", "event_type":"price_change"}
{"market":"0x30d55d8124ee1e12dabe89201badc45669b81dff69e4ce44d961f32878ec178a", "price_changes":[{"asset_id":"52986718774908357330412653486471347449818893503063830313445318937088822580057", "price":"0.891", "size":"7477.7", "side":"BUY", "hash":"d1163d37e8704cd1fe1adeb256a140bcd96eccaf", "best_bid":"0.91", "best_ask":"0.911"}, {"asset_id":"27576533317283401577758999384642760405921738493660383550832555714312627457443", "price":"0.109", "size":"7477.7", "side":"SELL", "hash":"6198ddeb05c35eab22f3fb291fc6e5f976c66dd7", "best_bid":"0.089", "best_ask":"0.09"}], "timestamp":"1780179133481", "event_type":"price_change"}
{"market":"0x7976b8dbacf9077eb1453a62bcefd6ab2df199acd28aad276ff0d920d6992892", "price_changes":[{"asset_id":"112680630004798425069810935278212000865453267506345451433803052322987302357330", "price":"0.805", "size":"45", "side":"BUY", "hash":"c73f408f7c9b1ecfc7e11cc0989a3ba7b4f8cba8", "best_bid":"0.832", "best_ask":"0.833"}, {"asset_id":"4394372887385518214471608448209527405727552777602031099972143344338178308080", "price":"0.195", "size":"45", "side":"SELL", "hash":"6dc5525157bbdaa4469bea8a43f4509b11ed4898", "best_bid":"0.167", "best_ask":"0.168"}], "timestamp":"1780179133487", "event_type":"price_change"}
{"market":"0x30d55d8124ee1e12dabe89201badc45669b81dff69e4ce44d961f32878ec178a", "price_changes":[{"asset_id":"52986718774908357330412653486471347449818893503063830313445318937088822580057", "price":"0.882", "size":"15045", "side":"BUY", "hash":"2c4bd4aa7dcd625bf7b4adb2e10d220753839786", "best_bid":"0.91", "best_ask":"0.911"}, {"asset_id":"27576533317283401577758999384642760405921738493660383550832555714312627457443", "price":"0.118", "size":"15045", "side":"SELL", "hash":"65a9c39279bac5c104c1e44e71149f4fcb35fe5a", "best_bid":"0.089", "best_ask":"0.09"}], "timestamp":"1780179133492", "event_type":"price_change"}
{"market":"0x30d55d8124ee1e12dabe89201badc45669b81dff69e4ce44d961f32878ec178a", "price_changes":[{"asset_id":"52986718774908357330412653486471347449818893503063830313445318937088822580057", "price":"0.872", "size":"2625", "side":"BUY", "hash":"eca6bf8befd452c707ebb09ddaad5e0a7376147f", "best_bid":"0.91", "best_ask":"0.911"}, {"asset_id":"27576533317283401577758999384642760405921738493660383550832555714312627457443", "price":"0.128", "size":"2625", "side":"SELL", "hash":"4c1af968e91c3f70d190e3a877e23024dbc5c5c0", "best_bid":"0.089", "best_ask":"0.09"}], "timestamp":"1780179133498", "event_type":"price_change"}
{"market":"0x9b6fef249040fd17e9c107955b37ac2c3e923509b6b0ff01cc463a331ddeb894", "price_changes":[{"asset_id":"32270411694523539495262303868629477861017829722282576458031815333486368239544", "price":"0.768", "size":"100", "side":"BUY", "hash":"b64af45406937d664e32b3e7504a7b5ed1a06ba0", "best_bid":"0.836", "best_ask":"0.837"}, {"asset_id":"108233603819467706476318984012158651931658302669301887462181073562758483842092", "price":"0.232", "size":"100", "side":"SELL", "hash":"286867d1473297375cec32674810ff4a93368bac", "best_bid":"0.163", "best_ask":"0.164"}], "timestamp":"1780179133514", "event_type":"price_change"}
{"market":"0x375409bc5eeeff961e82b479caeccc20f33d15738e5bce1186d628aa3d9dfb1f", "price_changes":[{"asset_id":"77121637225348873006259930776623502125079210522997384841464684944292365296940", "price":"0.868", "size":"25344.14", "side":"BUY", "hash":"c5cda978862d386b02e2b979e8acc0c95797248a", "best_bid":"0.887", "best_ask":"0.888"}, {"asset_id":"115556263888245616435851357148058235707004733438163639091106356867234218207169", "price":"0.132", "size":"25344.14", "side":"SELL", "hash":"6a118b8365a15c0397c7d7f936d94339bdf32d3d", "best_bid":"0.112", "best_ask":"0.113"}], "timestamp":"1780179133676", "event_type":"price_change"}
{"market":"0x375409bc5eeeff961e82b479caeccc20f33d15738e5bce1186d628aa3d9dfb1f", "price_changes":[{"asset_id":"77121637225348873006259930776623502125079210522997384841464684944292365296940", "price":"0.859", "size":"45", "side":"BUY", "hash":"b544e0bcde553ec8eefcbc815812ce5db51bfb5f", "best_bid":"0.887", "best_ask":"0.888"}, {"asset_id":"115556263888245616435851357148058235707004733438163639091106356867234218207169", "price":"0.141", "size":"45", "side":"SELL", "hash":"b8c6098facdc2b41218d43257c124c7bd19a69db", "best_bid":"0.112", "best_ask":"0.113"}], "timestamp":"1780179133681", "event_type":"price_change"}
{"market":"0x375409bc5eeeff961e82b479caeccc20f33d15738e5bce1186d628aa3d9dfb1f", "price_changes":[{"asset_id":"77121637225348873006259930776623502125079210522997384841464684944292365296940", "price":"0.849", "size":"125", "side":"BUY", "hash":"8a262fb3b461244cd6c86d02fefedc8e298717e0", "best_bid":"0.887", "best_ask":"0.888"}, {"asset_id":"115556263888245616435851357148058235707004733438163639091106356867234218207169", "price":"0.151", "size":"125", "side":"SELL", "hash":"4ea67df5fc885a9a8c2d2a97286fa2470b71428c", "best_bid":"0.112", "best_ask":"0.113"}], "timestamp":"1780179133685", "event_type":"price_change"}
{"market":"0x375409bc5eeeff961e82b479caeccc20f33d15738e5bce1186d628aa3d9dfb1f", "price_changes":[{"asset_id":"77121637225348873006259930776623502125079210522997384841464684944292365296940", "price":"0.818", "size":"100", "side":"BUY", "hash":"f9d9c485f55cbc56e05461d5bc941ab22a1521aa", "best_bid":"0.887", "best_ask":"0.888"}, {"asset_id":"115556263888245616435851357148058235707004733438163639091106356867234218207169", "price":"0.182", "size":"100", "side":"SELL", "hash":"e7337c86beaa519f73cf73f4eb08b8bc88d0da52", "best_bid":"0.112", "best_ask":"0.113"}], "timestamp":"1780179133690", "event_type":"price_change"}
{"market":"0x375409bc5eeeff961e82b479caeccc20f33d15738e5bce1186d628aa3d9dfb1f", "price_changes":[{"asset_id":"77121637225348873006259930776623502125079210522997384841464684944292365296940", "price":"0.768", "size":"400", "side":"BUY", "hash":"cacd5e1b52f70bc2cf9ae7ff664a1ac36657851c", "best_bid":"0.887", "best_ask":"0.888"}, {"asset_id":"115556263888245616435851357148058235707004733438163639091106356867234218207169", "price":"0.232", "size":"400", "side":"SELL", "hash":"c0660faf5e1353770aacc19c2e48795ce62316f2", "best_bid":"0.112", "best_ask":"0.113"}], "timestamp":"1780179133695", "event_type":"price_change"}
{"market":"0x9b6fef249040fd17e9c107955b37ac2c3e923509b6b0ff01cc463a331ddeb894", "price_changes":[{"asset_id":"32270411694523539495262303868629477861017829722282576458031815333486368239544", "price":"0.818", "size":"6265.31", "side":"BUY", "hash":"3b16ee9fc93f8e6c707d1cdbb65bc93a85f41843", "best_bid":"0.836", "best_ask":"0.837"}, {"asset_id":"108233603819467706476318984012158651931658302669301887462181073562758483842092", "price":"0.182", "size":"6265.31", "side":"SELL", "hash":"827083bcc53256245a3d57b6c1cd5f9aa0c974d8", "best_bid":"0.163", "best_ask":"0.164"}], "timestamp":"1780179133702", "event_type":"price_change"}
{"market":"0x9b6fef249040fd17e9c107955b37ac2c3e923509b6b0ff01cc463a331ddeb894", "price_changes":[{"asset_id":"32270411694523539495262303868629477861017829722282576458031815333486368239544", "price":"0.809", "size":"2072", "side":"BUY", "hash":"b6b08c2ea5c2a7438819f2a791224c9178330517", "best_bid":"0.836", "best_ask":"0.837"}, {"asset_id":"108233603819467706476318984012158651931658302669301887462181073562758483842092", "price":"0.191", "size":"2072", "side":"SELL", "hash":"a2436ff8ed4377072036d08b44b3698922fdd22a", "best_bid":"0.163", "best_ask":"0.164"}], "timestamp":"1780179133708", "event_type":"price_change"}
{"market":"0x9b6fef249040fd17e9c107955b37ac2c3e923509b6b0ff01cc463a331ddeb894", "price_changes":[{"asset_id":"32270411694523539495262303868629477861017829722282576458031815333486368239544", "price":"0.798", "size":"50", "side":"BUY", "hash":"be5545faf69e9de38384c2795fdeb6d52ede7d3b", "best_bid":"0.836", "best_ask":"0.837"}, {"asset_id":"108233603819467706476318984012158651931658302669301887462181073562758483842092", "price":"0.202", "size":"50", "side":"SELL", "hash":"193716cb0c25aa98da9335e1140d548682b761b0", "best_bid":"0.163", "best_ask":"0.164"}], "timestamp":"1780179133714", "event_type":"price_change"}
{"id":"2397887", "question":"Solana Up or Down - May 31, 6:00PM-6:15PM ET", "market":"0xdb24f968ac2b5cf20f6e1721cac7128e0ea33103ad5834bfd0a020f3ce8167a5", "slug":"sol-updown-15m-1780264800", "description":"This market will resolve to \"Up\" if the Solana price at the end of the time range specified in the title is greater than or equal to the price at the beginning of that range. Otherwise, it will resolve to \"Down\".\nThe resolution source for this market is information from Chainlink, specifically the SOL/USD data stream available at https://data.chain.link/streams/sol-usd.\nPlease note that this market is about the price according to Chainlink data stream SOL/USD, not according to other sources or spot markets.", "assets_ids":["59718190993593049444976037109470167860240708517900840209585317655327446014626", "60097700659270919221618033906669238492756990435755754662161622149338912973247"], "outcomes":["Up", "Down"], "event_message":{"id":"542710", "ticker":"sol-updown-15m-1780264800", "slug":"sol-updown-15m-1780264800", "title":"Solana Up or Down - May 31, 6:00PM-6:15PM ET", "description":"This market will resolve to \"Up\" if the Solana price at the end of the time range specified in the title is greater than or equal to the price at the beginning of that range. Otherwise, it will resolve to \"Down\".\nThe resolution source for this market is information from Chainlink, specifically the SOL/USD data stream available at https://data.chain.link/streams/sol-usd.\nPlease note that this market is about the price according to Chainlink data stream SOL/USD, not according to other sources or spot markets."}, "timestamp":"1780179133805", "event_type":"new_market", "tags":[], "condition_id":"0xdb24f968ac2b5cf20f6e1721cac7128e0ea33103ad5834bfd0a020f3ce8167a5", "active":false, "clob_token_ids":["59718190993593049444976037109470167860240708517900840209585317655327446014626", "60097700659270919221618033906669238492756990435755754662161622149338912973247"], "sports_market_type":"", "line":"", "game_start_time":"", "order_price_min_tick_size":"0.01", "group_item_title":"", "taker_base_fee":"1000", "fees_enabled":true, "fee_schedule":{"exponent":"1", "rate":"0.07", "taker_only":true, "rebate_rate":"0.2"}}
{"market":"0x375409bc5eeeff961e82b479caeccc20f33d15738e5bce1186d628aa3d9dfb1f", "price_changes":[{"asset_id":"77121637225348873006259930776623502125079210522997384841464684944292365296940", "price":"0.867", "size":"15010", "side":"BUY", "hash":"7240cd4acc3d72ba7c2d042ce859d90024314177", "best_bid":"0.887", "best_ask":"0.888"}, {"asset_id":"115556263888245616435851357148058235707004733438163639091106356867234218207169", "price":"0.133", "size":"15010", "side":"SELL", "hash":"11ceaacad7a9fc9961a11286ae307785f17ee731", "best_bid":"0.112", "best_ask":"0.113"}], "timestamp":"1780179134016", "event_type":"price_change"}
{"market":"0x375409bc5eeeff961e82b479caeccc20f33d15738e5bce1186d628aa3d9dfb1f", "price_changes":[{"asset_id":"77121637225348873006259930776623502125079210522997384841464684944292365296940", "price":"0.867", "size":"15000", "side":"BUY", "hash":"328c6aa78c8c7b26d157974f169d08dd68f701e5", "best_bid":"0.887", "best_ask":"0.888"}, {"asset_id":"115556263888245616435851357148058235707004733438163639091106356867234218207169", "price":"0.133", "size":"15000", "side":"SELL", "hash":"1112e133c6bf4d77f0b3af8e71d96f4f284c946f", "best_bid":"0.112", "best_ask":"0.113"}], "timestamp":"1780179134210", "event_type":"price_change"}
{"market":"0x7976b8dbacf9077eb1453a62bcefd6ab2df199acd28aad276ff0d920d6992892", "price_changes":[{"asset_id":"4394372887385518214471608448209527405727552777602031099972143344338178308080", "price":"0.18", "size":"12535.92", "side":"SELL", "hash":"ee78f2633ac259971dbd10717bb7ec5ffe75038e", "best_bid":"0.167", "best_ask":"0.168"}, {"asset_id":"112680630004798425069810935278212000865453267506345451433803052322987302357330", "price":"0.82", "size":"12535.92", "side":"BUY", "hash":"7a2d1db7b624b2578541997e947df7917b808de9", "best_bid":"0.832", "best_ask":"0.833"}], "timestamp":"1780179134483", "event_type":"price_change"}
{"market":"0x4f3421fb2daf5cca7430ed8d8132463963081572d75434393a1808fdb8829fe8", "price_changes":[{"asset_id":"45415751658241142530386585138386640503488308219341470020075667342738719018629", "price":"0.103", "size":"18203.31", "side":"SELL", "hash":"b3dd7b6e5c22bb5e141bef216e53fffbbfe093d4", "best_bid":"0.1", "best_ask":"0.101"}, {"asset_id":"31940783580344558651011323787577288681658737625185216525249046282994042503801", "price":"0.897", "size":"18203.31", "side":"BUY", "hash":"2acc98a933dfbc00f1cfa8d8d72581d7e969317f", "best_bid":"0.899", "best_ask":"0.9"}], "timestamp":"1780179134547", "event_type":"price_change"}
{"market":"0x9b6fef249040fd17e9c107955b37ac2c3e923509b6b0ff01cc463a331ddeb894", "price_changes":[{"asset_id":"108233603819467706476318984012158651931658302669301887462181073562758483842092", "price":"0.166", "size":"24952", "side":"SELL", "hash":"c96d905d021090e999a8c34e02ed01318f3f4fa5", "best_bid":"0.163", "best_ask":"0.164"}, {"asset_id":"32270411694523539495262303868629477861017829722282576458031815333486368239544", "price":"0.834", "size":"24952", "side":"BUY", "hash":"737562f5da27793720898637b51eac4ee06626a6", "best_bid":"0.836", "best_ask":"0.837"}], "timestamp":"1780179134552", "event_type":"price_change"}
{"market":"0x4f3421fb2daf5cca7430ed8d8132463963081572d75434393a1808fdb8829fe8", "price_changes":[{"asset_id":"45415751658241142530386585138386640503488308219341470020075667342738719018629", "price":"0.103", "size":"18263.31", "side":"SELL", "hash":"65f1ca08c1406077a3f439708f79bc6b8e402eff", "best_bid":"0.1", "best_ask":"0.101"}, {"asset_id":"31940783580344558651011323787577288681658737625185216525249046282994042503801", "price":"0.897", "size":"18263.31", "side":"BUY", "hash":"d04a4a9d1c2f8ca6dda993931ae220e8a50b667a", "best_bid":"0.899", "best_ask":"0.9"}], "timestamp":"1780179134643", "event_type":"price_change"}
{"market":"0x9b6fef249040fd17e9c107955b37ac2c3e923509b6b0ff01cc463a331ddeb894", "price_changes":[{"asset_id":"108233603819467706476318984012158651931658302669301887462181073562758483842092", "price":"0.166", "size":"25006.72", "side":"SELL", "hash":"1023483556370e29ccb8458dfb9dae7b2706f470", "best_bid":"0.163", "best_ask":"0.164"}, {"asset_id":"32270411694523539495262303868629477861017829722282576458031815333486368239544", "price":"0.834", "size":"25006.72", "side":"BUY", "hash":"b1edd87e69bad755379de4a53931ff4413e2ad3e", "best_bid":"0.836", "best_ask":"0.837"}], "timestamp":"1780179134645", "event_type":"price_change"}
{"market":"0x7976b8dbacf9077eb1453a62bcefd6ab2df199acd28aad276ff0d920d6992892", "price_changes":[{"asset_id":"4394372887385518214471608448209527405727552777602031099972143344338178308080", "price":"0.18", "size":"12525.92", "side":"SELL", "hash":"1bdf7572c479a5a21514f5249fb7d6421ce2318b", "best_bid":"0.167", "best_ask":"0.168"}, {"asset_id":"112680630004798425069810935278212000865453267506345451433803052322987302357330", "price":"0.82", "size":"12525.92", "side":"BUY", "hash":"7db0a2cfc40e88f2b10d78c0721838603e33d157", "best_bid":"0.832", "best_ask":"0.833"}], "timestamp":"1780179134762", "event_type":"price_change"}
{"market":"0x9b6fef249040fd17e9c107955b37ac2c3e923509b6b0ff01cc463a331ddeb894", "price_changes":[{"asset_id":"108233603819467706476318984012158651931658302669301887462181073562758483842092", "price":"0.19", "size":"6609.61", "side":"SELL", "hash":"20a706d4b8e0f958fa2e86dbb79e10b7cce76220", "best_bid":"0.163", "best_ask":"0.164"}, {"asset_id":"32270411694523539495262303868629477861017829722282576458031815333486368239544", "price":"0.81", "size":"6609.61", "side":"BUY", "hash":"d877c76fca89321f7aff3efa7da4f3c13ca66be0", "best_bid":"0.836", "best_ask":"0.837"}], "timestamp":"1780179135083", "event_type":"price_change"}
{"market":"0x9b6fef249040fd17e9c107955b37ac2c3e923509b6b0ff01cc463a331ddeb894", "price_changes":[{"asset_id":"108233603819467706476318984012158651931658302669301887462181073562758483842092", "price":"0.19", "size":"6599.61", "side":"SELL", "hash":"78a744adef910bdb4f31bb72746dbadef97c4549", "best_bid":"0.163", "best_ask":"0.164"}, {"asset_id":"32270411694523539495262303868629477861017829722282576458031815333486368239544", "price":"0.81", "size":"6599.61", "side":"BUY", "hash":"3724079d5064dcb79e73273965d4fb9011b1c4a1", "best_bid":"0.836", "best_ask":"0.837"}], "timestamp":"1780179135514", "event_type":"price_change"}
{"market":"0x30d55d8124ee1e12dabe89201badc45669b81dff69e4ce44d961f32878ec178a", "price_changes":[{"asset_id":"27576533317283401577758999384642760405921738493660383550832555714312627457443", "price":"0.092", "size":"78371.18", "side":"SELL", "hash":"587d459cc6242fb3c0a53c413758654ef5883486", "best_bid":"0.089", "best_ask":"0.09"}, {"asset_id":"52986718774908357330412653486471347449818893503063830313445318937088822580057", "price":"0.908", "size":"78371.18", "side":"BUY", "hash":"157f5e73909ae63d4a9fe8b62c0c49df8a966b44", "best_bid":"0.91", "best_ask":"0.911"}], "timestamp":"1780179135978", "event_type":"price_change"}
{"market":"0x7976b8dbacf9077eb1453a62bcefd6ab2df199acd28aad276ff0d920d6992892", "price_changes":[{"asset_id":"4394372887385518214471608448209527405727552777602031099972143344338178308080", "price":"0.17", "size":"27608.28", "side":"SELL", "hash":"785b9e576a3ff5018a21ed324b74fd0f2b5db594", "best_bid":"0.167", "best_ask":"0.168"}, {"asset_id":"112680630004798425069810935278212000865453267506345451433803052322987302357330", "price":"0.83", "size":"27608.28", "side":"BUY", "hash":"38cf31a55924dfb4d8e706908b201f1ab67e5f5f", "best_bid":"0.832", "best_ask":"0.833"}], "timestamp":"1780179136003", "event_type":"price_change"}
{"market":"0x30d55d8124ee1e12dabe89201badc45669b81dff69e4ce44d961f32878ec178a", "price_changes":[{"asset_id":"27576533317283401577758999384642760405921738493660383550832555714312627457443", "price":"0.092", "size":"78431.18", "side":"SELL", "hash":"56d491ba595c82db6e3ca2f9ce04719e4c53aa61", "best_bid":"0.089", "best_ask":"0.09"}, {"asset_id":"52986718774908357330412653486471347449818893503063830313445318937088822580057", "price":"0.908", "size":"78431.18", "side":"BUY", "hash":"6a64f9c4d0f9923312d7d83fbd168de7668ecbda", "best_bid":"0.91", "best_ask":"0.911"}], "timestamp":"1780179136079", "event_type":"price_change"}
{"market":"0x7976b8dbacf9077eb1453a62bcefd6ab2df199acd28aad276ff0d920d6992892", "price_changes":[{"asset_id":"4394372887385518214471608448209527405727552777602031099972143344338178308080", "price":"0.17", "size":"27662.47", "side":"SELL", "hash":"63f87458c4942357790151a7e60d03b15338401b", "best_bid":"0.167", "best_ask":"0.168"}, {"asset_id":"112680630004798425069810935278212000865453267506345451433803052322987302357330", "price":"0.83", "size":"27662.47", "side":"BUY", "hash":"ec7fa5f2139111089a4f5972399c4aecc6cfe3c9", "best_bid":"0.832", "best_ask":"0.833"}], "timestamp":"1780179136140", "event_type":"price_change"}
{"id":"2397881", "question":"Ethereum Up or Down - May 31, 6:00PM-6:05PM ET", "market":"0xee236e77d5c3716a77aaa09711bf075e8c3c1b455d589a682c188b092ed4d217", "slug":"eth-updown-5m-1780264800", "description":"This market will resolve to \"Up\" if the Ethereum price at the end of the time range specified in the title is greater than or equal to the price at the beginning of that range. Otherwise, it will resolve to \"Down\".\nThe resolution source for this market is information from Chainlink, specifically the ETH/USD data stream available at https://data.chain.link/streams/eth-usd.\nPlease note that this market is about the price according to Chainlink data stream ETH/USD, not according to other sources or spot markets.", "assets_ids":["110551390136651576659732192184085333392886795174749820610854271300625680877933", "61876967156341797569042515593785622345795245819600737730101723092085250996540"], "outcomes":["Up", "Down"], "event_message":{"id":"542705", "ticker":"eth-updown-5m-1780264800", "slug":"eth-updown-5m-1780264800", "title":"Ethereum Up or Down - May 31, 6:00PM-6:05PM ET", "description":"This market will resolve to \"Up\" if the Ethereum price at the end of the time range specified in the title is greater than or equal to the price at the beginning of that range. Otherwise, it will resolve to \"Down\".\nThe resolution source for this market is information from Chainlink, specifically the ETH/USD data stream available at https://data.chain.link/streams/eth-usd.\nPlease note that this market is about the price according to Chainlink data stream ETH/USD, not according to other sources or spot markets."}, "timestamp":"1780179136860", "event_type":"new_market", "tags":[], "condition_id":"0xee236e77d5c3716a77aaa09711bf075e8c3c1b455d589a682c188b092ed4d217", "active":false, "clob_token_ids":["110551390136651576659732192184085333392886795174749820610854271300625680877933", "61876967156341797569042515593785622345795245819600737730101723092085250996540"], "sports_market_type":"", "line":"", "game_start_time":"", "order_price_min_tick_size":"0.01", "group_item_title":"", "taker_base_fee":"1000", "fees_enabled":true, "fee_schedule":{"exponent":"1", "rate":"0.07", "taker_only":true, "rebate_rate":"0.2"}}
{"market":"0x1595b4818eeb1ea1e0bec5de6f057218e557feee9b405a0e930d290384fa1d16", "price_changes":[{"asset_id":"81739002353269632749850710185641576213562066971072676369728657545679630163887", "price":"0.053", "size":"3311.26", "side":"SELL", "hash":"759ddbd638c15b56c246e29c61599418820b44fe", "best_bid":"0.051", "best_ask":"0.052"}, {"asset_id":"45484070731786948288366703334552551439356529561722304542938873238430842810537", "price":"0.947", "size":"3311.26", "side":"BUY", "hash":"4d6f98fc864591562843784bca0110b228502307", "best_bid":"0.948", "best_ask":"0.949"}], "timestamp":"1780179137275", "event_type":"price_change"}
{"market":"0x0c4cd2055d6ea89354ffddc55d6dbcef9355748112ea952fc925f3db6a5c457f", "price_changes":[{"asset_id":"18812649149814341758733697580460697418474693998558159483117100240528657629879", "price":"0.088", "size":"15069.46", "side":"SELL", "hash":"466446bab607717b49caf69887935111f031eda6", "best_bid":"0.085", "best_ask":"0.086"}, {"asset_id":"115428153746996892211798999366308897078723117634059783423375188043903703749062", "price":"0.912", "size":"15069.46", "side":"BUY", "hash":"60fbb4f38fdce6a561375615a4f52147422f6947", "best_bid":"0.914", "best_ask":"0.915"}], "timestamp":"1780179137277", "event_type":"price_change"}
{"market":"0x375409bc5eeeff961e82b479caeccc20f33d15738e5bce1186d628aa3d9dfb1f", "price_changes":[{"asset_id":"77121637225348873006259930776623502125079210522997384841464684944292365296940", "price":"0.867", "size":"15010", "side":"BUY", "hash":"92c451565b5545517376d8ac9b019909b6c90f43", "best_bid":"0.887", "best_ask":"0.888"}, {"asset_id":"115556263888245616435851357148058235707004733438163639091106356867234218207169", "price":"0.133", "size":"15010", "side":"SELL", "hash":"32a7cf6dad9cf096d1f9e7c41acc7262e400f027", "best_bid":"0.112", "best_ask":"0.113"}], "timestamp":"1780179137391", "event_type":"price_change"}
{"market":"0x1595b4818eeb1ea1e0bec5de6f057218e557feee9b405a0e930d290384fa1d16", "price_changes":[{"asset_id":"81739002353269632749850710185641576213562066971072676369728657545679630163887", "price":"0.053", "size":"3371.26", "side":"SELL", "hash":"dd1bd0db695b9fa423942755187c5bda4c1be87f", "best_bid":"0.051", "best_ask":"0.052"}, {"asset_id":"45484070731786948288366703334552551439356529561722304542938873238430842810537", "price":"0.947", "size":"3371.26", "side":"BUY", "hash":"dbf4a3aeb4a9c72c2567f46f303ad36ccc9bdb9e", "best_bid":"0.948", "best_ask":"0.949"}], "timestamp":"1780179137401", "event_type":"price_change"}
{"market":"0x0c4cd2055d6ea89354ffddc55d6dbcef9355748112ea952fc925f3db6a5c457f", "price_changes":[{"asset_id":"18812649149814341758733697580460697418474693998558159483117100240528657629879", "price":"0.088", "size":"15129.46", "side":"SELL", "hash":"5af8f00ebaaa0f70e6a40d8f964c5a8f99886f17", "best_bid":"0.085", "best_ask":"0.086"}, {"asset_id":"115428153746996892211798999366308897078723117634059783423375188043903703749062", "price":"0.912", "size":"15129.46", "side":"BUY", "hash":"02e1c9f745d27ba4904a4896cd65ede5206c32ba", "best_bid":"0.914", "best_ask":"0.915"}], "timestamp":"1780179137404", "event_type":"price_change"}
{"market":"0x375409bc5eeeff961e82b479caeccc20f33d15738e5bce1186d628aa3d9dfb1f", "price_changes":[{"asset_id":"77121637225348873006259930776623502125079210522997384841464684944292365296940", "price":"0.867", "size":"15000", "side":"BUY", "hash":"5fe5b532eaa2f13bb4f61bcf23d743873db33a43", "best_bid":"0.887", "best_ask":"0.888"}, {"asset_id":"115556263888245616435851357148058235707004733438163639091106356867234218207169", "price":"0.133", "size":"15000", "side":"SELL", "hash":"be81819fcaed3c0fd63c5976bc2c471920ad21e0", "best_bid":"0.112", "best_ask":"0.113"}], "timestamp":"1780179137443", "event_type":"price_change"}
{"market":"0x7876851632c295043c66536150a304cb785abdf712ba8489d298c6e6926be106", "asset_id":"19291692040378529618917910599727571242305935029274321291612270922648172794670", "best_bid":"0.989", "best_ask":"0.99", "spread":"0.001", "timestamp":"1780179137506", "event_type":"best_bid_ask"}
{"market":"0x7876851632c295043c66536150a304cb785abdf712ba8489d298c6e6926be106", "price_changes":[{"asset_id":"97239126062673310243763617236644392945530356142765650402171508075574679292913", "price":"0.01", "size":"1265229.72", "side":"BUY", "hash":"3d90011936cbf2ccfd18d8d799a996b6ed5d680e", "best_bid":"0.01", "best_ask":"0.011"}, {"asset_id":"19291692040378529618917910599727571242305935029274321291612270922648172794670", "price":"0.99", "size":"1265229.72", "side":"SELL", "hash":"e8ae5e846924631920e1f362cfc0793ea06c5260", "best_bid":"0.989", "best_ask":"0.99"}], "timestamp":"1780179137505", "event_type":"price_change"}
{"market":"0x7876851632c295043c66536150a304cb785abdf712ba8489d298c6e6926be106", "asset_id":"19291692040378529618917910599727571242305935029274321291612270922648172794670", "bids":[{"price":"0.001", "size":"21002524.32"}, {"price":"0.002", "size":"90011.18"}, {"price":"0.003", "size":"1600"}, {"price":"0.004", "size":"70.4"}, {"price":"0.031", "size":"500"}, {"price":"0.05", "size":"40"}, {"price":"0.051", "size":"9.59"}, {"price":"0.1", "size":"2500"}, {"price":"0.2", "size":"1000"}, {"price":"0.201", "size":"5.94"}, {"price":"0.247", "size":"121.45"}, {"price":"0.3", "size":"600"}, {"price":"0.4", "size":"34625"}, {"price":"0.401", "size":"18000"}, {"price":"0.45", "size":"100"}, {"price":"0.451", "size":"1330"}, {"price":"0.5", "size":"25000"}, {"price":"0.501", "size":"12000"}, {"price":"0.51", "size":"7.97"}, {"price":"0.6", "size":"20833.33"}, {"price":"0.65", "size":"15384.62"}, {"price":"0.652", "size":"2095.26"}, {"price":"0.653", "size":"1103"}, {"price":"0.75", "size":"100"}, {"price":"0.778", "size":"227.27"}, {"price":"0.808", "size":"8"}, {"price":"0.847", "size":"1000"}, {"price":"0.85", "size":"445.83"}, {"price":"0.851", "size":"400"}, {"price":"0.877", "size":"1000"}, {"price":"0.888", "size":"30"}, {"price":"0.897", "size":"1000"}, {"price":"0.9", "size":"90.9"}, {"price":"0.904", "size":"8"}, {"price":"0.907", "size":"1000"}, {"price":"0.917", "size":"1000"}, {"price":"0.918", "size":"100"}, {"price":"0.92", "size":"1000"}, {"price":"0.927", "size":"1000"}, {"price":"0.935", "size":"3500"}, {"price":"0.937", "size":"1000"}, {"price":"0.938", "size":"3500"}, {"price":"0.94", "size":"2000"}, {"price":"0.943", "size":"3000"}, {"price":"0.944", "size":"2000"}, {"price":"0.947", "size":"1000"}, {"price":"0.948", "size":"75"}, {"price":"0.949", "size":"50"}, {"price":"0.95", "size":"3309.92"}, {"price":"0.951", "size":"2000"}, {"price":"0.952", "size":"3833.33"}, {"price":"0.955", "size":"3067"}, {"price":"0.957", "size":"3000"}, {"price":"0.958", "size":"3793"}, {"price":"0.959", "size":"45"}, {"price":"0.96", "size":"2000"}, {"price":"0.961", "size":"3007.2"}, {"price":"0.964", "size":"5000"}, {"price":"0.965", "size":"15430.62"}, {"price":"0.967", "size":"10424"}, {"price":"0.968", "size":"4519.78"}, {"price":"0.97", "size":"18916.9"}, {"price":"0.971", "size":"3000"}, {"price":"0.972", "size":"14648"}, {"price":"0.974", "size":"5000"}, {"price":"0.975", "size":"10372.72"}, {"price":"0.976", "size":"5500"}, {"price":"0.978", "size":"17239.4"}, {"price":"0.979", "size":"6000"}, {"price":"0.98", "size":"14721.53"}, {"price":"0.981", "size":"2790.7"}, {"price":"0.982", "size":"62681.81"}, {"price":"0.983", "size":"110028.15"}, {"price":"0.984", "size":"118582.98"}, {"price":"0.985", "size":"107389"}, {"price":"0.986", "size":"10"}, {"price":"0.987", "size":"8333.33"}, {"price":"0.988", "size":"4839191.94"}, {"price":"0.989", "size":"1818565.69"}], "asks":[{"price":"0.999", "size":"3862270"}, {"price":"0.998", "size":"1322096"}, {"price":"0.997", "size":"451830"}, {"price":"0.996", "size":"72622"}, {"price":"0.995", "size":"30650"}, {"price":"0.994", "size":"11473.99"}, {"price":"0.993", "size":"31428.57"}, {"price":"0.992", "size":"328294"}, {"price":"0.991", "size":"152880.61"}, {"price":"0.99", "size":"1265229.72"}], "hash":"e8ae5e846924631920e1f362cfc0793ea06c5260", "timestamp":"1780179137505", "event_type":"book"}
{"market":"0x375409bc5eeeff961e82b479caeccc20f33d15738e5bce1186d628aa3d9dfb1f", "price_changes":[{"asset_id":"115556263888245616435851357148058235707004733438163639091106356867234218207169", "price":"0.115", "size":"12019.15", "side":"SELL", "hash":"021af05dc38677eaed34e197ed52d46e4a0bdcdd", "best_bid":"0.112", "best_ask":"0.113"}, {"asset_id":"77121637225348873006259930776623502125079210522997384841464684944292365296940", "price":"0.885", "size":"12019.15", "side":"BUY", "hash":"19278130e07506e654f4c048704a32a9cab8148e", "best_bid":"0.887", "best_ask":"0.888"}], "timestamp":"1780179137516", "event_type":"price_change"}
{"market":"0x7876851632c295043c66536150a304cb785abdf712ba8489d298c6e6926be106", "asset_id":"19291692040378529618917910599727571242305935029274321291612270922648172794670", "price":"0.99", "size":"20.28", "fee_rate_bps":"0", "side":"BUY", "timestamp":"1780179137528", "event_type":"last_trade_price", "transaction_hash":"0x5ff7b70b9487c31bcb71ec35a50f9803f00a95481979e2ed43e154238ed524cb"}
{"market":"0x375409bc5eeeff961e82b479caeccc20f33d15738e5bce1186d628aa3d9dfb1f", "price_changes":[{"asset_id":"115556263888245616435851357148058235707004733438163639091106356867234218207169", "price":"0.115", "size":"12079.15", "side":"SELL", "hash":"1b7b8be9a5bcfc9bb885055205855626dfd15394", "best_bid":"0.112", "best_ask":"0.113"}, {"asset_id":"77121637225348873006259930776623502125079210522997384841464684944292365296940", "price":"0.885", "size":"12079.15", "side":"BUY", "hash":"ab06375f1a78f8e7d0f7248c7d2e77fd49b71494", "best_bid":"0.887", "best_ask":"0.888"}], "timestamp":"1780179137641", "event_type":"price_change"}
{"market":"0x0c4cd2055d6ea89354ffddc55d6dbcef9355748112ea952fc925f3db6a5c457f", "price_changes":[{"asset_id":"115428153746996892211798999366308897078723117634059783423375188043903703749062", "price":"0.76", "size":"10", "side":"BUY", "hash":"760a64ad8fd0fa181188a6421dd26232901e968c", "best_bid":"0.914", "best_ask":"0.915"}, {"asset_id":"18812649149814341758733697580460697418474693998558159483117100240528657629879", "price":"0.24", "size":"10", "side":"SELL", "hash":"90f164c3b136ab62c68bb0661ea7b6339edbf94a", "best_bid":"0.085", "best_ask":"0.086"}], "timestamp":"1780179139008", "event_type":"price_change"}
{"market":"0x0c4cd2055d6ea89354ffddc55d6dbcef9355748112ea952fc925f3db6a5c457f", "price_changes":[{"asset_id":"115428153746996892211798999366308897078723117634059783423375188043903703749062", "price":"0.93", "size":"13425.27", "side":"SELL", "hash":"767c2ec80ce78aac2af5f7f6befd90b6c8bd10ca", "best_bid":"0.914", "best_ask":"0.915"}, {"asset_id":"18812649149814341758733697580460697418474693998558159483117100240528657629879", "price":"0.07", "size":"13425.27", "side":"BUY", "hash":"6ff06790f402d7cf28436ee1c21ddae39533de69", "best_bid":"0.085", "best_ask":"0.086"}], "timestamp":"1780179139009", "event_type":"price_change"}
{"market":"0x0c4cd2055d6ea89354ffddc55d6dbcef9355748112ea952fc925f3db6a5c457f", "price_changes":[{"asset_id":"115428153746996892211798999366308897078723117634059783423375188043903703749062", "price":"0.76", "size":"0", "side":"BUY", "hash":"a6a6700afa608d40ba694aa482818f5989df5b64", "best_bid":"0.914", "best_ask":"0.915"}, {"asset_id":"18812649149814341758733697580460697418474693998558159483117100240528657629879", "price":"0.24", "size":"0", "side":"SELL", "hash":"9ee1efe53c562157f4720b61b0abaa87e527a4c0", "best_bid":"0.085", "best_ask":"0.086"}], "timestamp":"1780179139152", "event_type":"price_change"}
{"market":"0x0c4cd2055d6ea89354ffddc55d6dbcef9355748112ea952fc925f3db6a5c457f", "price_changes":[{"asset_id":"115428153746996892211798999366308897078723117634059783423375188043903703749062", "price":"0.93", "size":"13415.27", "side":"SELL", "hash":"a6a6700afa608d40ba694aa482818f5989df5b64", "best_bid":"0.914", "best_ask":"0.915"}, {"asset_id":"18812649149814341758733697580460697418474693998558159483117100240528657629879", "price":"0.07", "size":"13415.27", "side":"BUY", "hash":"9ee1efe53c562157f4720b61b0abaa87e527a4c0", "best_bid":"0.085", "best_ask":"0.086"}], "timestamp":"1780179139152", "event_type":"price_change"}
{"market":"0x7976b8dbacf9077eb1453a62bcefd6ab2df199acd28aad276ff0d920d6992892", "price_changes":[{"asset_id":"4394372887385518214471608448209527405727552777602031099972143344338178308080", "price":"0.18", "size":"12535.92", "side":"SELL", "hash":"174d7c018823beed53fe9c414ad99785151ff686", "best_bid":"0.167", "best_ask":"0.168"}, {"asset_id":"112680630004798425069810935278212000865453267506345451433803052322987302357330", "price":"0.82", "size":"12535.92", "side":"BUY", "hash":"dcf7e711abb629a78964c5a1073fa8558bda7519", "best_bid":"0.832", "best_ask":"0.833"}], "timestamp":"1780179141036", "event_type":"price_change"}
{"market":"0x7976b8dbacf9077eb1453a62bcefd6ab2df199acd28aad276ff0d920d6992892", "price_changes":[{"asset_id":"4394372887385518214471608448209527405727552777602031099972143344338178308080", "price":"0.18", "size":"12525.92", "side":"SELL", "hash":"7ff1b2a051e9b03e39ae00a6c21d34e3b740bf89", "best_bid":"0.167", "best_ask":"0.168"}, {"asset_id":"112680630004798425069810935278212000865453267506345451433803052322987302357330", "price":"0.82", "size":"12525.92", "side":"BUY", "hash":"776b5e0eef7917d7c2e4d82dbb968ba5951feff7", "best_bid":"0.832", "best_ask":"0.833"}], "timestamp":"1780179141152", "event_type":"price_change"}
{"market":"0x9b6fef249040fd17e9c107955b37ac2c3e923509b6b0ff01cc463a331ddeb894", "price_changes":[{"asset_id":"108233603819467706476318984012158651931658302669301887462181073562758483842092", "price":"0.19", "size":"6609.61", "side":"SELL", "hash":"0f209530fb09e45116354ba0f346d0c3ab04f9e9", "best_bid":"0.163", "best_ask":"0.164"}, {"asset_id":"32270411694523539495262303868629477861017829722282576458031815333486368239544", "price":"0.81", "size":"6609.61", "side":"BUY", "hash":"ad744b0621b5ff6dbeba291bdf27faf8b95feb20", "best_bid":"0.836", "best_ask":"0.837"}], "timestamp":"1780179141527", "event_type":"price_change"}
{"market":"0x9b6fef249040fd17e9c107955b37ac2c3e923509b6b0ff01cc463a331ddeb894", "price_changes":[{"asset_id":"108233603819467706476318984012158651931658302669301887462181073562758483842092", "price":"0.19", "size":"6599.61", "side":"SELL", "hash":"8a5a475e6c7e3ffffcae7f7df8599ea1b681f371", "best_bid":"0.163", "best_ask":"0.164"}, {"asset_id":"32270411694523539495262303868629477861017829722282576458031815333486368239544", "price":"0.81", "size":"6599.61", "side":"BUY", "hash":"b55c349f9c04ecc841804aa7f7abdd7f0622da70", "best_bid":"0.836", "best_ask":"0.837"}], "timestamp":"1780179141596", "event_type":"price_change"}
