[{"market":"0x7876851632c295043c66536150a304cb785abdf712ba8489d298c6e6926be106","asset_id":"19291692040378529618917910599727571242305935029274321291612270922648172794670","timestamp":"1780178255852","hash":"5a2a8690141348d41fa04ba484016ee1a0c2cca8","bids":[{"price":"0.001","size":"21002524.32"},{"price":"0.002","size":"90011.18"},{"price":"0.003","size":"1600"},{"price":"0.004","size":"70.4"},{"price":"0.031","size":"500"},{"price":"0.05","size":"40"},{"price":"0.051","size":"9.59"},{"price":"0.1","size":"2500"},{"price":"0.2","size":"1000"},{"price":"0.201","size":"5.94"},{"price":"0.247","size":"121.45"},{"price":"0.3","size":"600"},{"price":"0.4","size":"34625"},{"price":"0.401","size":"18000"},{"price":"0.45","size":"100"},{"price":"0.451","size":"1330"},{"price":"0.5","size":"25000"},{"price":"0.501","size":"12000"},{"price":"0.51","size":"7.97"},{"price":"0.6","size":"20833.33"},{"price":"0.65","size":"15384.62"},{"price":"0.652","size":"2095.26"},{"price":"0.653","size":"1103"},{"price":"0.75","size":"100"},{"price":"0.778","size":"227.27"},{"price":"0.807","size":"1000"},{"price":"0.808","size":"8"},{"price":"0.837","size":"1000"},{"price":"0.85","size":"445.83"},{"price":"0.851","size":"400"},{"price":"0.867","size":"1000"},{"price":"0.887","size":"1000"},{"price":"0.888","size":"30"},{"price":"0.897","size":"1000"},{"price":"0.9","size":"90.9"},{"price":"0.904","size":"8"},{"price":"0.907","size":"1000"},{"price":"0.917","size":"1100"},{"price":"0.92","size":"1000"},{"price":"0.927","size":"1000"},{"price":"0.935","size":"3500"},{"price":"0.937","size":"1000"},{"price":"0.938","size":"3500"},{"price":"0.94","size":"2000"},{"price":"0.943","size":"3000"},{"price":"0.944","size":"2000"},{"price":"0.945","size":"50"},{"price":"0.948","size":"75"},{"price":"0.95","size":"3309.92"},{"price":"0.951","size":"2000"},{"price":"0.952","size":"3833.33"},{"price":"0.955","size":"3067"},{"price":"0.956","size":"1000"},{"price":"0.957","size":"3045"},{"price":"0.958","size":"3000"},{"price":"0.96","size":"2000"},{"price":"0.961","size":"3007.2"},{"price":"0.964","size":"5000"},{"price":"0.965","size":"15430.62"},{"price":"0.966","size":"232.7"},{"price":"0.967","size":"10424"},{"price":"0.968","size":"4287.08"},{"price":"0.97","size":"18916.9"},{"price":"0.971","size":"3000"},{"price":"0.972","size":"14648"},{"price":"0.974","size":"5000"},{"price":"0.975","size":"10372.72"},{"price":"0.976","size":"5500"},{"price":"0.978","size":"17239.4"},{"price":"0.979","size":"6000"},{"price":"0.98","size":"14721.53"},{"price":"0.981","size":"2790.7"},{"price":"0.982","size":"62681.81"},{"price":"0.983","size":"110028.15"},{"price":"0.984","size":"118582.98"},{"price":"0.985","size":"107389"},{"price":"0.986","size":"10"},{"price":"0.987","size":"8333.33"},{"price":"0.988","size":"4839191.94"},{"price":"0.989","size":"1818725.69"}],"asks":[{"price":"0.999","size":"3862270"},{"price":"0.998","size":"1322096"},{"price":"0.997","size":"451830"},{"price":"0.996","size":"72622"},{"price":"0.995","size":"30650"},{"price":"0.994","size":"11473.99"},{"price":"0.993","size":"31428.57"},{"price":"0.992","size":"328294"},{"price":"0.991","size":"152880.61"},{"price":"0.99","size":"1269380"}],"tick_size":"0.001","event_type":"book","last_trade_price":"0.011"},{"market":"0x4f3421fb2daf5cca7430ed8d8132463963081572d75434393a1808fdb8829fe8","asset_id":"31940783580344558651011323787577288681658737625185216525249046282994042503801","timestamp":"1780178257426","hash":"62e480bbc8251dcda8fb0bd32fc23b77884ea92c","bids":[{"price":"0.001","size":"21074238.91"},{"price":"0.002","size":"37.76"},{"price":"0.01","size":"25929.6"},{"price":"0.011","size":"6.21"},{"price":"0.014","size":"1111111"},{"price":"0.015","size":"1000000"},{"price":"0.02","size":"36500"},{"price":"0.021","size":"800"},{"price":"0.022","size":"11.19"},{"price":"0.05","size":"40"},{"price":"0.077","size":"2000"},{"price":"0.078","size":"5.64"},{"price":"0.1","size":"2254.88"},{"price":"0.11","size":"1016"},{"price":"0.12","size":"1021"},{"price":"0.13","size":"1000"},{"price":"0.14","size":"999.99"},{"price":"0.15","size":"1153.71"},{"price":"0.2","size":"409.2"},{"price":"0.224","size":"433.92"},{"price":"0.225","size":"5.14"},{"price":"0.25","size":"453.7"},{"price":"0.253","size":"200"},{"price":"0.254","size":"200"},{"price":"0.27","size":"200"},{"price":"0.28","size":"200"},{"price":"0.31","size":"200"},{"price":"0.33","size":"215.15"},{"price":"0.34","size":"199.99"},{"price":"0.35","size":"102.46"},{"price":"0.36","size":"228"},{"price":"0.361","size":"100"},{"price":"0.4","size":"34637.29"},{"price":"0.401","size":"5000"},{"price":"0.41","size":"200"},{"price":"0.42","size":"200"},{"price":"0.43","size":"200"},{"price":"0.44","size":"200"},{"price":"0.45","size":"354.02"},{"price":"0.46","size":"200"},{"price":"0.461","size":"1077.83"},{"price":"0.5","size":"25496.62"},{"price":"0.501","size":"5100"},{"price":"0.51","size":"205.76"},{"price":"0.511","size":"100"},{"price":"0.52","size":"100"},{"price":"0.53","size":"100"},{"price":"0.54","size":"100"},{"price":"0.55","size":"100"},{"price":"0.56","size":"100"},{"price":"0.57","size":"100"},{"price":"0.58","size":"100"},{"price":"0.6","size":"21059.73"},{"price":"0.61","size":"100"},{"price":"0.62","size":"111.9"},{"price":"0.632","size":"5322.31"},{"price":"0.64","size":"28.8"},{"price":"0.643","size":"100"},{"price":"0.65","size":"16970.62"},{"price":"0.66","size":"100"},{"price":"0.662","size":"1000"},{"price":"0.67","size":"100"},{"price":"0.673","size":"100"},{"price":"0.674","size":"100"},{"price":"0.678","size":"100"},{"price":"0.68","size":"410.68"},{"price":"0.69","size":"100"},{"price":"0.693","size":"1000"},{"price":"0.7","size":"422.3"},{"price":"0.703","size":"100"},{"price":"0.704","size":"100"},{"price":"0.708","size":"100"},{"price":"0.71","size":"61.7"},{"price":"0.723","size":"1000"},{"price":"0.733","size":"100"},{"price":"0.75","size":"3192.15"},{"price":"0.753","size":"1000"},{"price":"0.76","size":"341.8"},{"price":"0.763","size":"100"},{"price":"0.764","size":"100"},{"price":"0.769","size":"100"},{"price":"0.777","size":"100"},{"price":"0.778","size":"400"},{"price":"0.78","size":"258.06"},{"price":"0.781","size":"100"},{"price":"0.783","size":"1000"},{"price":"0.79","size":"47.6"},{"price":"0.798","size":"1781.45"},{"price":"0.8","size":"246868.85"},{"price":"0.801","size":"100"},{"price":"0.803","size":"1000"},{"price":"0.804","size":"30"},{"price":"0.813","size":"1000"},{"price":"0.823","size":"1000"},{"price":"0.826","size":"100"},{"price":"0.827","size":"100"},{"price":"0.83","size":"39.23"},{"price":"0.833","size":"1000"},{"price":"0.84","size":"356.45"},{"price":"0.843","size":"1000"},{"price":"0.847","size":"100"},{"price":"0.849","size":"2541.52"},{"price":"0.85","size":"15927.35"},{"price":"0.851","size":"800"},{"price":"0.853","size":"68.33"},{"price":"0.855","size":"13.33"},{"price":"0.858","size":"1035.21"},{"price":"0.859","size":"50"},{"price":"0.86","size":"34.6"},{"price":"0.862","size":"75"},{"price":"0.867","size":"17.97"},{"price":"0.868","size":"1000"},{"price":"0.869","size":"45"},{"price":"0.87","size":"4000"},{"price":"0.871","size":"39.42"},{"price":"0.875","size":"170"},{"price":"0.878","size":"232.7"},{"price":"0.88","size":"197"},{"price":"0.882","size":"1000"},{"price":"0.885","size":"925.73"},{"price":"0.886","size":"100"},{"price":"0.887","size":"100"},{"price":"0.888","size":"100"},{"price":"0.889","size":"100"},{"price":"0.89","size":"649.23"},{"price":"0.891","size":"1343.33"},{"price":"0.892","size":"7071.71"},{"price":"0.893","size":"15257.35"},{"price":"0.894","size":"121650.88"},{"price":"0.895","size":"1515.46"},{"price":"0.896","size":"30940.81"},{"price":"0.897","size":"18263.31"},{"price":"0.898","size":"90693.2"},{"price":"0.899","size":"67602.24"}],"asks":[{"price":"0.999","size":"4715397.01"},{"price":"0.998","size":"14"},{"price":"0.997","size":"1112792"},{"price":"0.996","size":"55564"},{"price":"0.995","size":"10009"},{"price":"0.994","size":"11109"},{"price":"0.993","size":"10009"},{"price":"0.992","size":"10009"},{"price":"0.991","size":"5009"},{"price":"0.99","size":"6209"},{"price":"0.989","size":"5009"},{"price":"0.988","size":"5009"},{"price":"0.987","size":"4309"},{"price":"0.986","size":"3009"},{"price":"0.985","size":"5009"},{"price":"0.984","size":"3009"},{"price":"0.983","size":"3009"},{"price":"0.982","size":"9"},{"price":"0.981","size":"5009"},{"price":"0.98","size":"6234"},{"price":"0.979","size":"4008.99"},{"price":"0.978","size":"4009"},{"price":"0.977","size":"4009"},{"price":"0.976","size":"3009"},{"price":"0.975","size":"3009"},{"price":"0.974","size":"4009"},{"price":"0.973","size":"3009"},{"price":"0.972","size":"4009"},{"price":"0.971","size":"2009"},{"price":"0.97","size":"409"},{"price":"0.969","size":"2509"},{"price":"0.968","size":"2652.85"},{"price":"0.967","size":"2509"},{"price":"0.966","size":"2509"},{"price":"0.965","size":"9"},{"price":"0.964","size":"9"},{"price":"0.963","size":"9"},{"price":"0.962","size":"609"},{"price":"0.961","size":"9"},{"price":"0.96","size":"134"},{"price":"0.959","size":"9"},{"price":"0.958","size":"9"},{"price":"0.957","size":"9"},{"price":"0.956","size":"9"},{"price":"0.955","size":"9"},{"price":"0.954","size":"9"},{"price":"0.953","size":"9"},{"price":"0.952","size":"9"},{"price":"0.951","size":"9"},{"price":"0.95","size":"79"},{"price":"0.949","size":"10009"},{"price":"0.948","size":"9"},{"price":"0.947","size":"9"},{"price":"0.946","size":"9"},{"price":"0.945","size":"309"},{"price":"0.944","size":"9"},{"price":"0.943","size":"9"},{"price":"0.942","size":"9"},{"price":"0.941","size":"9"},{"price":"0.94","size":"36"},{"price":"0.939","size":"202"},{"price":"0.938","size":"10009"},{"price":"0.937","size":"5009"},{"price":"0.936","size":"7509"},{"price":"0.935","size":"5151"},{"price":"0.934","size":"6209"},{"price":"0.933","size":"4603.78"},{"price":"0.932","size":"2856.05"},{"price":"0.931","size":"2772.73"},{"price":"0.93","size":"9438.97"},{"price":"0.929","size":"1564"},{"price":"0.928","size":"5464.3"},{"price":"0.927","size":"1109"},{"price":"0.926","size":"357402.07"},{"price":"0.925","size":"20562.67"},{"price":"0.924","size":"6753.29"},{"price":"0.923","size":"434.15"},{"price":"0.922","size":"512.12"},{"price":"0.921","size":"25029"},{"price":"0.92","size":"15376.09"},{"price":"0.919","size":"1633.99"},{"price":"0.918","size":"14672.52"},{"price":"0.917","size":"2431.41"},{"price":"0.916","size":"9"},{"price":"0.915","size":"821.33"},{"price":"0.914","size":"22609"},{"price":"0.913","size":"4605.61"},{"price":"0.912","size":"1782.17"},{"price":"0.911","size":"570.79"},{"price":"0.91","size":"6647.21"},{"price":"0.909","size":"958.45"},{"price":"0.908","size":"909"},{"price":"0.907","size":"3608.93"},{"price":"0.906","size":"1240.91"},{"price":"0.905","size":"3028.99"},{"price":"0.904","size":"1169.1"},{"price":"0.903","size":"6197.22"},{"price":"0.902","size":"6248.36"},{"price":"0.901","size":"7903.47"},{"price":"0.9","size":"9221.83"}],"tick_size":"0.001","event_type":"book","last_trade_price":"0.101"},{"market":"0x9b6fef249040fd17e9c107955b37ac2c3e923509b6b0ff01cc463a331ddeb894","asset_id":"32270411694523539495262303868629477861017829722282576458031815333486368239544","timestamp":"1780178257994","hash":"7ded7d14a3ce99d0ce0d99b8aeb7860414143de6","bids":[{"price":"0.001","size":"12219098.99"},{"price":"0.002","size":"178.57"},{"price":"0.003","size":"21.08"},{"price":"0.009","size":"18000"},{"price":"0.01","size":"100"},{"price":"0.011","size":"5.62"},{"price":"0.012","size":"1111111"},{"price":"0.013","size":"900000"},{"price":"0.014","size":"1300"},{"price":"0.015","size":"500"},{"price":"0.02","size":"99"},{"price":"0.021","size":"6.95"},{"price":"0.05","size":"246.52"},{"price":"0.051","size":"10.84"},{"price":"0.09","size":"5.98"},{"price":"0.1","size":"15"},{"price":"0.12","size":"5005"},{"price":"0.121","size":"12000"},{"price":"0.15","size":"67.49"},{"price":"0.163","size":"36"},{"price":"0.178","size":"289.7"},{"price":"0.2","size":"796.33"},{"price":"0.209","size":"143.54"},{"price":"0.22","size":"100.48"},{"price":"0.221","size":"5.22"},{"price":"0.245","size":"304.87"},{"price":"0.25","size":"3597"},{"price":"0.251","size":"6000"},{"price":"0.29","size":"9.75"},{"price":"0.3","size":"55.88"},{"price":"0.315","size":"1459.85"},{"price":"0.33","size":"1363.34"},{"price":"0.331","size":"3000"},{"price":"0.34","size":"5"},{"price":"0.35","size":"2159.92"},{"price":"0.4","size":"34587.44"},{"price":"0.401","size":"3000"},{"price":"0.47","size":"5688.73"},{"price":"0.5","size":"36470.75"},{"price":"0.502","size":"1529.99"},{"price":"0.503","size":"14000"},{"price":"0.51","size":"90.9"},{"price":"0.511","size":"1202.04"},{"price":"0.55","size":"513.44"},{"price":"0.56","size":"111.11"},{"price":"0.562","size":"655.13"},{"price":"0.563","size":"65.06"},{"price":"0.57","size":"3964.15"},{"price":"0.6","size":"22272.15"},{"price":"0.601","size":"1000"},{"price":"0.624","size":"27.04"},{"price":"0.631","size":"1000"},{"price":"0.636","size":"105.03"},{"price":"0.638","size":"23.57"},{"price":"0.64","size":"4479.3"},{"price":"0.648","size":"7.39"},{"price":"0.65","size":"15415.61"},{"price":"0.651","size":"2155.26"},{"price":"0.661","size":"1000"},{"price":"0.67","size":"18.11"},{"price":"0.672","size":"482.66"},{"price":"0.68","size":"38"},{"price":"0.691","size":"1000"},{"price":"0.7","size":"487.37"},{"price":"0.701","size":"400"},{"price":"0.72","size":"167.14"},{"price":"0.721","size":"1000"},{"price":"0.722","size":"100"},{"price":"0.741","size":"1000"},{"price":"0.743","size":"100"},{"price":"0.744","size":"30"},{"price":"0.75","size":"1422.54"},{"price":"0.751","size":"1201"},{"price":"0.752","size":"1367"},{"price":"0.754","size":"334.02"},{"price":"0.76","size":"302"},{"price":"0.761","size":"1000"},{"price":"0.764","size":"100"},{"price":"0.765","size":"100"},{"price":"0.771","size":"1000"},{"price":"0.777","size":"11.23"},{"price":"0.779","size":"334.02"},{"price":"0.78","size":"237"},{"price":"0.782","size":"1000"},{"price":"0.785","size":"100"},{"price":"0.786","size":"15"},{"price":"0.787","size":"100"},{"price":"0.788","size":"10"},{"price":"0.789","size":"5555.55"},{"price":"0.79","size":"122"},{"price":"0.792","size":"1000"},{"price":"0.793","size":"10"},{"price":"0.794","size":"1000"},{"price":"0.795","size":"10"},{"price":"0.796","size":"50"},{"price":"0.8","size":"17681.66"},{"price":"0.801","size":"100"},{"price":"0.803","size":"110"},{"price":"0.805","size":"1000"},{"price":"0.806","size":"44"},{"price":"0.807","size":"180"},{"price":"0.808","size":"675.7"},{"price":"0.809","size":"2027"},{"price":"0.81","size":"6609.61"},{"price":"0.811","size":"4653.91"},{"price":"0.812","size":"1708.3"},{"price":"0.813","size":"782.67"},{"price":"0.814","size":"1703.37"},{"price":"0.815","size":"5571.35"},{"price":"0.816","size":"11142.53"},{"price":"0.817","size":"7549.45"},{"price":"0.818","size":"6032.61"},{"price":"0.819","size":"340"},{"price":"0.82","size":"1037.95"},{"price":"0.821","size":"1694.21"},{"price":"0.822","size":"22719.93"},{"price":"0.823","size":"44358.4"},{"price":"0.824","size":"47073"},{"price":"0.825","size":"47040.85"},{"price":"0.827","size":"654.36"},{"price":"0.829","size":"19937.62"},{"price":"0.83","size":"26050"},{"price":"0.831","size":"3000"},{"price":"0.832","size":"2000"},{"price":"0.833","size":"4950.42"},{"price":"0.834","size":"25006.68"},{"price":"0.835","size":"182736.01"},{"price":"0.836","size":"42556.12"}],"asks":[{"price":"0.999","size":"2260279"},{"price":"0.998","size":"1557248"},{"price":"0.997","size":"1001200"},{"price":"0.996","size":"55555"},{"price":"0.995","size":"90100"},{"price":"0.99","size":"720"},{"price":"0.985","size":"5.01"},{"price":"0.984","size":"555555"},{"price":"0.983","size":"60000"},{"price":"0.982","size":"105435.9"},{"price":"0.981","size":"800"},{"price":"0.98","size":"5430"},{"price":"0.978","size":"3000"},{"price":"0.976","size":"3000"},{"price":"0.974","size":"3000"},{"price":"0.972","size":"3000"},{"price":"0.97","size":"3000"},{"price":"0.968","size":"3000"},{"price":"0.966","size":"3000"},{"price":"0.96","size":"750"},{"price":"0.951","size":"100"},{"price":"0.95","size":"150"},{"price":"0.94","size":"10"},{"price":"0.937","size":"16.27"},{"price":"0.936","size":"30"},{"price":"0.935","size":"10"},{"price":"0.934","size":"20"},{"price":"0.931","size":"10"},{"price":"0.93","size":"50"},{"price":"0.926","size":"20"},{"price":"0.925","size":"5"},{"price":"0.924","size":"30"},{"price":"0.923","size":"20"},{"price":"0.922","size":"20"},{"price":"0.921","size":"20"},{"price":"0.92","size":"140"},{"price":"0.91","size":"10100"},{"price":"0.905","size":"105.2"},{"price":"0.9","size":"6296.92"},{"price":"0.899","size":"1076.68"},{"price":"0.893","size":"37.72"},{"price":"0.892","size":"40"},{"price":"0.89","size":"400"},{"price":"0.889","size":"5000"},{"price":"0.885","size":"9"},{"price":"0.884","size":"90"},{"price":"0.88","size":"120"},{"price":"0.879","size":"7500"},{"price":"0.878","size":"5000"},{"price":"0.877","size":"100"},{"price":"0.875","size":"956.59"},{"price":"0.874","size":"2500"},{"price":"0.87","size":"328"},{"price":"0.869","size":"2567"},{"price":"0.868","size":"47"},{"price":"0.867","size":"1933.93"},{"price":"0.866","size":"57"},{"price":"0.865","size":"37"},{"price":"0.864","size":"5017"},{"price":"0.863","size":"3727"},{"price":"0.862","size":"7"},{"price":"0.861","size":"7"},{"price":"0.86","size":"717"},{"price":"0.859","size":"7"},{"price":"0.858","size":"507"},{"price":"0.857","size":"97"},{"price":"0.856","size":"7"},{"price":"0.855","size":"37"},{"price":"0.854","size":"37"},{"price":"0.853","size":"722"},{"price":"0.852","size":"7"},{"price":"0.851","size":"707"},{"price":"0.85","size":"6520"},{"price":"0.849","size":"877"},{"price":"0.848","size":"7"},{"price":"0.847","size":"27"},{"price":"0.846","size":"287"},{"price":"0.845","size":"3760.64"},{"price":"0.844","size":"20417"},{"price":"0.843","size":"28647.14"},{"price":"0.842","size":"10076.94"},{"price":"0.841","size":"56.6"},{"price":"0.84","size":"67783.1"},{"price":"0.839","size":"12119.44"},{"price":"0.838","size":"4466.23"},{"price":"0.837","size":"15230.42"}],"tick_size":"0.001","event_type":"book","last_trade_price":"0.164"},{"market":"0x1595b4818eeb1ea1e0bec5de6f057218e557feee9b405a0e930d290384fa1d16","asset_id":"45484070731786948288366703334552551439356529561722304542938873238430842810537","timestamp":"1780178270119","hash":"a2e1481644e125d09549ad4920fc9a98b12b017f","bids":[{"price":"0.001","size":"21202713.62"},{"price":"0.002","size":"105"},{"price":"0.003","size":"29.49"},{"price":"0.01","size":"181.81"},{"price":"0.013","size":"1698.4"},{"price":"0.014","size":"17.32"},{"price":"0.05","size":"2236"},{"price":"0.054","size":"155555"},{"price":"0.055","size":"150000"},{"price":"0.056","size":"800"},{"price":"0.057","size":"5.16"},{"price":"0.1","size":"2500"},{"price":"0.14","size":"27"},{"price":"0.2","size":"1000"},{"price":"0.201","size":"6.72"},{"price":"0.237","size":"126.58"},{"price":"0.3","size":"600"},{"price":"0.348","size":"211.53"},{"price":"0.39","size":"5"},{"price":"0.4","size":"34625"},{"price":"0.401","size":"10000"},{"price":"0.402","size":"1492"},{"price":"0.5","size":"25100"},{"price":"0.501","size":"5000"},{"price":"0.51","size":"87.55"},{"price":"0.511","size":"1076.32"},{"price":"0.58","size":"17.54"},{"price":"0.584","size":"300"},{"price":"0.6","size":"20859.33"},{"price":"0.61","size":"76.92"},{"price":"0.623","size":"5"},{"price":"0.65","size":"15443.05"},{"price":"0.651","size":"2095.26"},{"price":"0.7","size":"780"},{"price":"0.701","size":"437"},{"price":"0.712","size":"50"},{"price":"0.72","size":"18"},{"price":"0.737","size":"1000"},{"price":"0.74","size":"476.92"},{"price":"0.75","size":"2198.07"},{"price":"0.751","size":"400"},{"price":"0.767","size":"1005"},{"price":"0.77","size":"43.3"},{"price":"0.78","size":"192.53"},{"price":"0.792","size":"1100"},{"price":"0.797","size":"1000"},{"price":"0.8","size":"1307.15"},{"price":"0.801","size":"500"},{"price":"0.82","size":"12201.05"},{"price":"0.821","size":"400"},{"price":"0.827","size":"1000"},{"price":"0.83","size":"1079.99"},{"price":"0.832","size":"50"},{"price":"0.838","size":"1913.7"},{"price":"0.84","size":"288"},{"price":"0.847","size":"1000"},{"price":"0.848","size":"33"},{"price":"0.85","size":"13781.98"},{"price":"0.851","size":"30"},{"price":"0.855","size":"327.86"},{"price":"0.856","size":"7"},{"price":"0.857","size":"1000"},{"price":"0.86","size":"334.14"},{"price":"0.867","size":"1000"},{"price":"0.869","size":"20"},{"price":"0.87","size":"1713.81"},{"price":"0.877","size":"1100"},{"price":"0.878","size":"163.93"},{"price":"0.88","size":"613.23"},{"price":"0.885","size":"240"},{"price":"0.887","size":"1370.37"},{"price":"0.89","size":"1231.81"},{"price":"0.896","size":"1592.3"},{"price":"0.897","size":"1000"},{"price":"0.899","size":"100"},{"price":"0.9","size":"6833.45"},{"price":"0.901","size":"50"},{"price":"0.902","size":"7772.33"},{"price":"0.904","size":"500"},{"price":"0.905","size":"5852.55"},{"price":"0.907","size":"125"},{"price":"0.91","size":"11147.07"},{"price":"0.911","size":"911.3"},{"price":"0.913","size":"500"},{"price":"0.915","size":"173.07"},{"price":"0.916","size":"1000"},{"price":"0.917","size":"45"},{"price":"0.918","size":"500"},{"price":"0.919","size":"532.55"},{"price":"0.92","size":"1746.51"},{"price":"0.924","size":"5917.15"},{"price":"0.925","size":"6585.96"},{"price":"0.926","size":"4177.46"},{"price":"0.927","size":"5259.68"},{"price":"0.928","size":"7012.91"},{"price":"0.929","size":"42450.48"},{"price":"0.93","size":"32653.14"},{"price":"0.931","size":"10000"},{"price":"0.932","size":"5905.04"},{"price":"0.933","size":"382.3"},{"price":"0.934","size":"6055.04"},{"price":"0.935","size":"22294.08"},{"price":"0.939","size":"950"},{"price":"0.94","size":"2357.57"},{"price":"0.941","size":"250009.76"},{"price":"0.942","size":"11512.52"},{"price":"0.943","size":"1999.94"},{"price":"0.944","size":"18846.47"},{"price":"0.945","size":"5833.22"},{"price":"0.946","size":"9225.11"},{"price":"0.947","size":"3371.26"},{"price":"0.948","size":"346631.69"}],"asks":[{"price":"0.999","size":"2259057"},{"price":"0.998","size":"1000005"},{"price":"0.997","size":"2224894"},{"price":"0.996","size":"56355"},{"price":"0.994","size":"300"},{"price":"0.993","size":"100"},{"price":"0.99","size":"2517.95"},{"price":"0.988","size":"100000"},{"price":"0.981","size":"200"},{"price":"0.98","size":"905"},{"price":"0.972","size":"100000"},{"price":"0.97","size":"1030"},{"price":"0.967","size":"30"},{"price":"0.966","size":"5000"},{"price":"0.965","size":"999.99"},{"price":"0.964","size":"2500"},{"price":"0.961","size":"1500"},{"price":"0.96","size":"5914.44"},{"price":"0.959","size":"1510"},{"price":"0.958","size":"4305"},{"price":"0.957","size":"4718"},{"price":"0.956","size":"1500"},{"price":"0.955","size":"2500"},{"price":"0.954","size":"2720"},{"price":"0.953","size":"1220"},{"price":"0.952","size":"31030"},{"price":"0.951","size":"39747.51"},{"price":"0.95","size":"84174.74"},{"price":"0.949","size":"557052.13"}],"tick_size":"0.001","event_type":"book","last_trade_price":"0.052"},{"market":"0x30d55d8124ee1e12dabe89201badc45669b81dff69e4ce44d961f32878ec178a","asset_id":"52986718774908357330412653486471347449818893503063830313445318937088822580057","timestamp":"1780178270117","hash":"a000cb52972dd34adaf3d30641461644e9f8d054","bids":[{"price":"0.001","size":"21109405.6"},{"price":"0.002","size":"23.15"},{"price":"0.004","size":"2222222"},{"price":"0.005","size":"2000000"},{"price":"0.006","size":"800"},{"price":"0.007","size":"9.04"},{"price":"0.01","size":"102.2"},{"price":"0.013","size":"1716.8"},{"price":"0.015","size":"750"},{"price":"0.016","size":"11.01"},{"price":"0.05","size":"40"},{"price":"0.051","size":"10.88"},{"price":"0.09","size":"5"},{"price":"0.1","size":"2500"},{"price":"0.13","size":"22.93"},{"price":"0.2","size":"1000"},{"price":"0.227","size":"132.15"},{"price":"0.228","size":"5.03"},{"price":"0.27","size":"750"},{"price":"0.3","size":"605"},{"price":"0.39","size":"5"},{"price":"0.4","size":"34625"},{"price":"0.401","size":"10000"},{"price":"0.402","size":"1492"},{"price":"0.442","size":"6.78"},{"price":"0.45","size":"21"},{"price":"0.451","size":"21"},{"price":"0.5","size":"25662.35"},{"price":"0.502","size":"2000"},{"price":"0.503","size":"3100"},{"price":"0.51","size":"100"},{"price":"0.52","size":"100"},{"price":"0.53","size":"100"},{"price":"0.54","size":"100"},{"price":"0.55","size":"200"},{"price":"0.56","size":"100"},{"price":"0.6","size":"20920.53"},{"price":"0.601","size":"3100"},{"price":"0.623","size":"105"},{"price":"0.637","size":"100"},{"price":"0.64","size":"1263"},{"price":"0.65","size":"15539.21"},{"price":"0.667","size":"100"},{"price":"0.67","size":"50"},{"price":"0.7","size":"1503.29"},{"price":"0.731","size":"1000"},{"price":"0.75","size":"1265.57"},{"price":"0.751","size":"280"},{"price":"0.752","size":"2095.26"},{"price":"0.76","size":"117.48"},{"price":"0.761","size":"1000"},{"price":"0.767","size":"5"},{"price":"0.78","size":"355"},{"price":"0.781","size":"400"},{"price":"0.79","size":"31.9"},{"price":"0.791","size":"1000"},{"price":"0.794","size":"100"},{"price":"0.8","size":"1556.31"},{"price":"0.81","size":"330.25"},{"price":"0.811","size":"1000"},{"price":"0.815","size":"130"},{"price":"0.818","size":"862.62"},{"price":"0.82","size":"217.47"},{"price":"0.821","size":"1000"},{"price":"0.825","size":"600"},{"price":"0.83","size":"471.36"},{"price":"0.831","size":"1000"},{"price":"0.836","size":"100"},{"price":"0.84","size":"168"},{"price":"0.841","size":"1000"},{"price":"0.85","size":"697.11"},{"price":"0.851","size":"1000"},{"price":"0.855","size":"163.04"},{"price":"0.856","size":"18.23"},{"price":"0.857","size":"100"},{"price":"0.86","size":"2599.34"},{"price":"0.861","size":"1000"},{"price":"0.868","size":"2500"},{"price":"0.87","size":"213.55"},{"price":"0.871","size":"437.5"},{"price":"0.872","size":"2575"},{"price":"0.875","size":"600"},{"price":"0.876","size":"6300"},{"price":"0.877","size":"5000"},{"price":"0.879","size":"1000"},{"price":"0.88","size":"133.12"},{"price":"0.882","size":"15000"},{"price":"0.883","size":"200"},{"price":"0.887","size":"437.5"},{"price":"0.888","size":"106.38"},{"price":"0.889","size":"232.7"},{"price":"0.89","size":"30299.11"},{"price":"0.891","size":"7245"},{"price":"0.893","size":"4000"},{"price":"0.894","size":"4180.61"},{"price":"0.895","size":"9773.48"},{"price":"0.897","size":"62499.24"},{"price":"0.898","size":"56"},{"price":"0.9","size":"8898.5"},{"price":"0.901","size":"11460.63"},{"price":"0.902","size":"62999.23"},{"price":"0.903","size":"25213.57"},{"price":"0.904","size":"764967.01"},{"price":"0.905","size":"36998.61"},{"price":"0.906","size":"31655.15"},{"price":"0.907","size":"2188.69"},{"price":"0.908","size":"78431.18"},{"price":"0.909","size":"25691.16"},{"price":"0.91","size":"135833.18"}],"asks":[{"price":"0.999","size":"4833617.88"},{"price":"0.998","size":"1000671"},{"price":"0.997","size":"672"},{"price":"0.996","size":"501000"},{"price":"0.995","size":"30100"},{"price":"0.994","size":"1182511"},{"price":"0.993","size":"66355"},{"price":"0.992","size":"10000"},{"price":"0.991","size":"10000"},{"price":"0.99","size":"11815"},{"price":"0.989","size":"5000"},{"price":"0.988","size":"5000"},{"price":"0.987","size":"5000"},{"price":"0.986","size":"5000"},{"price":"0.985","size":"5000"},{"price":"0.984","size":"5000"},{"price":"0.983","size":"5000"},{"price":"0.982","size":"5000"},{"price":"0.981","size":"5000"},{"price":"0.98","size":"5375"},{"price":"0.979","size":"3999.99"},{"price":"0.978","size":"3000"},{"price":"0.977","size":"3000"},{"price":"0.976","size":"3000"},{"price":"0.975","size":"3000"},{"price":"0.974","size":"3000"},{"price":"0.973","size":"3000"},{"price":"0.972","size":"3000"},{"price":"0.971","size":"288.25"},{"price":"0.96","size":"300"},{"price":"0.959","size":"300"},{"price":"0.958","size":"600"},{"price":"0.957","size":"50"},{"price":"0.956","size":"134.85"},{"price":"0.955","size":"763.02"},{"price":"0.951","size":"10"},{"price":"0.95","size":"241"},{"price":"0.949","size":"6"},{"price":"0.948","size":"6"},{"price":"0.947","size":"6"},{"price":"0.946","size":"6"},{"price":"0.945","size":"6"},{"price":"0.944","size":"6"},{"price":"0.943","size":"6"},{"price":"0.942","size":"6"},{"price":"0.941","size":"6"},{"price":"0.94","size":"206"},{"price":"0.939","size":"6"},{"price":"0.938","size":"6"},{"price":"0.937","size":"6"},{"price":"0.936","size":"6"},{"price":"0.935","size":"6"},{"price":"0.934","size":"6"},{"price":"0.933","size":"6"},{"price":"0.932","size":"6"},{"price":"0.931","size":"6"},{"price":"0.93","size":"816"},{"price":"0.929","size":"20006"},{"price":"0.928","size":"16"},{"price":"0.927","size":"6"},{"price":"0.926","size":"6"},{"price":"0.925","size":"16"},{"price":"0.924","size":"38"},{"price":"0.923","size":"6"},{"price":"0.922","size":"6"},{"price":"0.921","size":"1386"},{"price":"0.92","size":"33317.5"},{"price":"0.919","size":"32011"},{"price":"0.918","size":"10006"},{"price":"0.917","size":"11106"},{"price":"0.916","size":"59047.99"},{"price":"0.915","size":"9118.35"},{"price":"0.914","size":"4477.13"},{"price":"0.913","size":"8518.68"},{"price":"0.912","size":"21904"},{"price":"0.911","size":"175476.98"}],"tick_size":"0.001","event_type":"book","last_trade_price":"0.090"},{"market":"0x375409bc5eeeff961e82b479caeccc20f33d15738e5bce1186d628aa3d9dfb1f","asset_id":"77121637225348873006259930776623502125079210522997384841464684944292365296940","timestamp":"1780178259390","hash":"e7cad0459d7a2d79646fc391b994ac13d2245182","bids":[{"price":"0.001","size":"21319088.56"},{"price":"0.002","size":"5005.12"},{"price":"0.003","size":"14.23"},{"price":"0.005","size":"2222222"},{"price":"0.006","size":"2000000"},{"price":"0.007","size":"800"},{"price":"0.008","size":"5.22"},{"price":"0.013","size":"1728"},{"price":"0.014","size":"52"},{"price":"0.1","size":"2991.34"},{"price":"0.151","size":"5000"},{"price":"0.155","size":"200"},{"price":"0.16","size":"300"},{"price":"0.161","size":"300"},{"price":"0.163","size":"300"},{"price":"0.18","size":"300"},{"price":"0.2","size":"1000"},{"price":"0.22","size":"345.04"},{"price":"0.221","size":"335.74"},{"price":"0.222","size":"5.25"},{"price":"0.23","size":"230.97"},{"price":"0.25","size":"300"},{"price":"0.26","size":"300"},{"price":"0.27","size":"300"},{"price":"0.3","size":"2974.99"},{"price":"0.301","size":"200"},{"price":"0.35","size":"293.98"},{"price":"0.38","size":"133.26"},{"price":"0.39","size":"105"},{"price":"0.4","size":"36025"},{"price":"0.408","size":"4900"},{"price":"0.409","size":"6100"},{"price":"0.44","size":"105"},{"price":"0.45","size":"100"},{"price":"0.451","size":"1009.54"},{"price":"0.493","size":"494.73"},{"price":"0.5","size":"27051.85"},{"price":"0.501","size":"4100"},{"price":"0.502","size":"144.67"},{"price":"0.51","size":"275.39"},{"price":"0.55","size":"302.74"},{"price":"0.56","size":"100"},{"price":"0.6","size":"22248.33"},{"price":"0.613","size":"100"},{"price":"0.618","size":"1000"},{"price":"0.62","size":"100"},{"price":"0.623","size":"105"},{"price":"0.643","size":"100"},{"price":"0.648","size":"1000"},{"price":"0.65","size":"16362.62"},{"price":"0.661","size":"5100"},{"price":"0.662","size":"2095.26"},{"price":"0.67","size":"11.2"},{"price":"0.671","size":"100"},{"price":"0.673","size":"100"},{"price":"0.678","size":"1000"},{"price":"0.68","size":"99.99"},{"price":"0.69","size":"242.85"},{"price":"0.7","size":"1709.85"},{"price":"0.703","size":"100"},{"price":"0.708","size":"1000"},{"price":"0.72","size":"252.85"},{"price":"0.721","size":"100"},{"price":"0.733","size":"100"},{"price":"0.738","size":"1000"},{"price":"0.74","size":"180.76"},{"price":"0.75","size":"4458.91"},{"price":"0.761","size":"99.99"},{"price":"0.763","size":"100"},{"price":"0.767","size":"9008.24"},{"price":"0.768","size":"1000"},{"price":"0.77","size":"200"},{"price":"0.771","size":"200"},{"price":"0.774","size":"16354.68"},{"price":"0.776","size":"9000"},{"price":"0.788","size":"1000"},{"price":"0.79","size":"3113.4"},{"price":"0.792","size":"106.3"},{"price":"0.793","size":"30"},{"price":"0.798","size":"1000"},{"price":"0.8","size":"18696.67"},{"price":"0.804","size":"1486.78"},{"price":"0.81","size":"1888.99"},{"price":"0.813","size":"100"},{"price":"0.814","size":"100"},{"price":"0.82","size":"1020"},{"price":"0.83","size":"1110"},{"price":"0.834","size":"436.03"},{"price":"0.837","size":"100"},{"price":"0.84","size":"1377.83"},{"price":"0.847","size":"313.15"},{"price":"0.849","size":"75"},{"price":"0.85","size":"279.81"},{"price":"0.852","size":"1118.59"},{"price":"0.854","size":"847.46"},{"price":"0.855","size":"144.97"},{"price":"0.856","size":"1118.44"},{"price":"0.857","size":"45"},{"price":"0.858","size":"167.16"},{"price":"0.86","size":"190.28"},{"price":"0.862","size":"2611.44"},{"price":"0.863","size":"173.7"},{"price":"0.864","size":"121.7"},{"price":"0.865","size":"94.28"},{"price":"0.866","size":"344.14"},{"price":"0.867","size":"15010"},{"price":"0.868","size":"25111.44"},{"price":"0.869","size":"21"},{"price":"0.87","size":"60785.22"},{"price":"0.871","size":"4854.15"},{"price":"0.872","size":"55645.74"},{"price":"0.873","size":"1122.06"},{"price":"0.874","size":"312.33"},{"price":"0.875","size":"1629.28"},{"price":"0.876","size":"811.41"},{"price":"0.877","size":"20"},{"price":"0.878","size":"256.72"},{"price":"0.879","size":"99"},{"price":"0.88","size":"20849.13"},{"price":"0.881","size":"115464.59"},{"price":"0.882","size":"5243.19"},{"price":"0.883","size":"517048.24"},{"price":"0.884","size":"22720.12"},{"price":"0.885","size":"12079.15"},{"price":"0.886","size":"4186.41"},{"price":"0.887","size":"232273.38"}],"asks":[{"price":"0.999","size":"4816069"},{"price":"0.998","size":"1001693"},{"price":"0.996","size":"556755"},{"price":"0.995","size":"55655"},{"price":"0.994","size":"20000"},{"price":"0.993","size":"10800"},{"price":"0.992","size":"10000"},{"price":"0.991","size":"10000"},{"price":"0.99","size":"10000"},{"price":"0.989","size":"5000"},{"price":"0.988","size":"5000"},{"price":"0.987","size":"5000"},{"price":"0.986","size":"5000"},{"price":"0.985","size":"6000"},{"price":"0.984","size":"5000"},{"price":"0.983","size":"5000"},{"price":"0.982","size":"5060"},{"price":"0.981","size":"5000"},{"price":"0.98","size":"5375"},{"price":"0.979","size":"5020"},{"price":"0.978","size":"5000"},{"price":"0.977","size":"5000"},{"price":"0.976","size":"5000"},{"price":"0.975","size":"715.5"},{"price":"0.96","size":"100"},{"price":"0.959","size":"100"},{"price":"0.951","size":"100"},{"price":"0.95","size":"75"},{"price":"0.949","size":"175"},{"price":"0.94","size":"50150"},{"price":"0.936","size":"50.54"},{"price":"0.935","size":"5000"},{"price":"0.93","size":"100"},{"price":"0.924","size":"79.6"},{"price":"0.92","size":"600"},{"price":"0.918","size":"105"},{"price":"0.912","size":"100.11"},{"price":"0.91","size":"800"},{"price":"0.907","size":"300"},{"price":"0.906","size":"319"},{"price":"0.904","size":"11000"},{"price":"0.903","size":"500"},{"price":"0.9","size":"11849.9"},{"price":"0.899","size":"10000"},{"price":"0.898","size":"1010"},{"price":"0.897","size":"20"},{"price":"0.896","size":"2540"},{"price":"0.895","size":"600"},{"price":"0.894","size":"860"},{"price":"0.892","size":"12287.02"},{"price":"0.891","size":"9926.74"},{"price":"0.89","size":"40417.97"},{"price":"0.889","size":"192431.85"},{"price":"0.888","size":"107445.32"}],"tick_size":"0.001","event_type":"book","last_trade_price":"0.113"},{"market":"0x7976b8dbacf9077eb1453a62bcefd6ab2df199acd28aad276ff0d920d6992892","asset_id":"112680630004798425069810935278212000865453267506345451433803052322987302357330","timestamp":"1780178270115","hash":"659ada1061e68a30f12bc7a03d5913e7492d77bc","bids":[{"price":"0.001","size":"13320371.6"},{"price":"0.002","size":"9.57"},{"price":"0.003","size":"156.25"},{"price":"0.004","size":"13.49"},{"price":"0.009","size":"8400"},{"price":"0.01","size":"7.03"},{"price":"0.012","size":"666666"},{"price":"0.013","size":"600000"},{"price":"0.014","size":"2534.99"},{"price":"0.016","size":"125.09"},{"price":"0.02","size":"5012"},{"price":"0.021","size":"3999.99"},{"price":"0.022","size":"5.22"},{"price":"0.05","size":"3109.99"},{"price":"0.051","size":"10.45"},{"price":"0.08","size":"3005"},{"price":"0.11","size":"1000"},{"price":"0.12","size":"1000"},{"price":"0.13","size":"1000"},{"price":"0.14","size":"999.99"},{"price":"0.15","size":"1000"},{"price":"0.16","size":"1000"},{"price":"0.196","size":"301"},{"price":"0.2","size":"749.67"},{"price":"0.207","size":"400"},{"price":"0.208","size":"544.23"},{"price":"0.209","size":"300"},{"price":"0.21","size":"5.72"},{"price":"0.23","size":"408.6"},{"price":"0.25","size":"544.97"},{"price":"0.31","size":"305.55"},{"price":"0.32","size":"205"},{"price":"0.36","size":"231.25"},{"price":"0.384","size":"7223.76"},{"price":"0.39","size":"5"},{"price":"0.4","size":"34671.65"},{"price":"0.403","size":"1311"},{"price":"0.42","size":"211.4"},{"price":"0.45","size":"510.51"},{"price":"0.451","size":"510.51"},{"price":"0.49","size":"220"},{"price":"0.5","size":"29664.87"},{"price":"0.501","size":"4216.7"},{"price":"0.502","size":"130"},{"price":"0.504","size":"457.83"},{"price":"0.505","size":"263.77"},{"price":"0.51","size":"264.58"},{"price":"0.52","size":"100"},{"price":"0.53","size":"100"},{"price":"0.54","size":"100"},{"price":"0.55","size":"726.73"},{"price":"0.56","size":"147"},{"price":"0.564","size":"301"},{"price":"0.57","size":"100"},{"price":"0.58","size":"188.58"},{"price":"0.59","size":"110"},{"price":"0.598","size":"13.07"},{"price":"0.6","size":"26789.54"},{"price":"0.601","size":"1274.25"},{"price":"0.602","size":"406.1"},{"price":"0.623","size":"5"},{"price":"0.63","size":"3300"},{"price":"0.631","size":"1000"},{"price":"0.65","size":"15514.62"},{"price":"0.654","size":"124.73"},{"price":"0.656","size":"122.73"},{"price":"0.658","size":"5141.34"},{"price":"0.66","size":"1046.85"},{"price":"0.661","size":"1000"},{"price":"0.664","size":"10100"},{"price":"0.666","size":"474.07"},{"price":"0.671","size":"100"},{"price":"0.68","size":"3006"},{"price":"0.681","size":"2095.26"},{"price":"0.691","size":"3359.94"},{"price":"0.7","size":"311.97"},{"price":"0.701","size":"400"},{"price":"0.718","size":"100"},{"price":"0.72","size":"11.42"},{"price":"0.721","size":"1000"},{"price":"0.726","size":"16.03"},{"price":"0.739","size":"100"},{"price":"0.741","size":"1030"},{"price":"0.75","size":"371.36"},{"price":"0.751","size":"1000"},{"price":"0.76","size":"295"},{"price":"0.761","size":"1000"},{"price":"0.764","size":"107"},{"price":"0.765","size":"150"},{"price":"0.767","size":"5"},{"price":"0.77","size":"17.85"},{"price":"0.771","size":"1000"},{"price":"0.774","size":"362.18"},{"price":"0.78","size":"125"},{"price":"0.781","size":"1100"},{"price":"0.783","size":"116.02"},{"price":"0.79","size":"50"},{"price":"0.791","size":"1000"},{"price":"0.792","size":"50"},{"price":"0.795","size":"10"},{"price":"0.796","size":"100"},{"price":"0.798","size":"5"},{"price":"0.799","size":"382.17"},{"price":"0.8","size":"8271.84"},{"price":"0.802","size":"1000"},{"price":"0.803","size":"1000"},{"price":"0.804","size":"45"},{"price":"0.806","size":"145"},{"price":"0.808","size":"30"},{"price":"0.809","size":"7.3"},{"price":"0.812","size":"15279.71"},{"price":"0.813","size":"232.7"},{"price":"0.814","size":"10"},{"price":"0.815","size":"105.96"},{"price":"0.816","size":"49.77"},{"price":"0.817","size":"50"},{"price":"0.818","size":"9.7"},{"price":"0.819","size":"1000"},{"price":"0.82","size":"12535.92"},{"price":"0.821","size":"8121.56"},{"price":"0.822","size":"930.5"},{"price":"0.823","size":"1627.85"},{"price":"0.824","size":"15407.48"},{"price":"0.825","size":"96558.27"},{"price":"0.826","size":"58022.86"},{"price":"0.827","size":"26925.87"},{"price":"0.828","size":"25913.26"},{"price":"0.829","size":"2722.4"},{"price":"0.83","size":"27652.43"},{"price":"0.831","size":"2030"},{"price":"0.832","size":"126676.17"}],"asks":[{"price":"0.999","size":"4816394"},{"price":"0.998","size":"2359"},{"price":"0.997","size":"100"},{"price":"0.996","size":"1111111"},{"price":"0.995","size":"255655"},{"price":"0.994","size":"100000"},{"price":"0.993","size":"10800"},{"price":"0.992","size":"10000"},{"price":"0.991","size":"10000"},{"price":"0.99","size":"10535"},{"price":"0.989","size":"10000"},{"price":"0.988","size":"10000"},{"price":"0.987","size":"5000"},{"price":"0.986","size":"5000"},{"price":"0.985","size":"5000"},{"price":"0.984","size":"5000"},{"price":"0.982","size":"5008.33"},{"price":"0.981","size":"5000"},{"price":"0.98","size":"7380"},{"price":"0.979","size":"3000"},{"price":"0.978","size":"3000"},{"price":"0.977","size":"3000"},{"price":"0.976","size":"3000"},{"price":"0.975","size":"3000"},{"price":"0.974","size":"3000"},{"price":"0.973","size":"3000"},{"price":"0.972","size":"3000"},{"price":"0.959","size":"731.7"},{"price":"0.951","size":"100"},{"price":"0.95","size":"56135"},{"price":"0.931","size":"20"},{"price":"0.93","size":"30"},{"price":"0.927","size":"30"},{"price":"0.926","size":"30"},{"price":"0.9","size":"6230"},{"price":"0.89","size":"50"},{"price":"0.889","size":"1076.32"},{"price":"0.88","size":"11038.99"},{"price":"0.879","size":"5"},{"price":"0.878","size":"5"},{"price":"0.877","size":"5"},{"price":"0.876","size":"5"},{"price":"0.875","size":"5"},{"price":"0.874","size":"5"},{"price":"0.873","size":"5"},{"price":"0.872","size":"5"},{"price":"0.871","size":"5"},{"price":"0.87","size":"165"},{"price":"0.869","size":"5"},{"price":"0.868","size":"105"},{"price":"0.867","size":"5"},{"price":"0.866","size":"5"},{"price":"0.865","size":"5"},{"price":"0.864","size":"5"},{"price":"0.863","size":"5"},{"price":"0.862","size":"5"},{"price":"0.861","size":"5"},{"price":"0.86","size":"2179.99"},{"price":"0.859","size":"6015"},{"price":"0.858","size":"5005"},{"price":"0.857","size":"2505"},{"price":"0.856","size":"15"},{"price":"0.855","size":"5"},{"price":"0.854","size":"6005"},{"price":"0.853","size":"3015"},{"price":"0.852","size":"775"},{"price":"0.851","size":"3105"},{"price":"0.85","size":"10190.34"},{"price":"0.849","size":"26420"},{"price":"0.848","size":"4713.32"},{"price":"0.847","size":"18374.44"},{"price":"0.846","size":"7112.99"},{"price":"0.845","size":"2890"},{"price":"0.844","size":"3989.08"},{"price":"0.843","size":"30663.44"},{"price":"0.842","size":"6895"},{"price":"0.841","size":"538.42"},{"price":"0.84","size":"3947.71"},{"price":"0.839","size":"759"},{"price":"0.838","size":"2688.81"},{"price":"0.837","size":"8782.11"},{"price":"0.836","size":"29232.29"},{"price":"0.835","size":"26149.08"},{"price":"0.834","size":"4856.87"},{"price":"0.833","size":"83503.85"}],"tick_size":"0.001","event_type":"book","last_trade_price":"0.168"},{"market":"0x0c4cd2055d6ea89354ffddc55d6dbcef9355748112ea952fc925f3db6a5c457f","asset_id":"115428153746996892211798999366308897078723117634059783423375188043903703749062","timestamp":"1780178270114","hash":"df3bede5855d93be3216b1ba71ac749f85d1e47b","bids":[{"price":"0.001","size":"19311591.2"},{"price":"0.002","size":"55.07"},{"price":"0.013","size":"1716.7"},{"price":"0.015","size":"1904.95"},{"price":"0.016","size":"11.03"},{"price":"0.036","size":"36000"},{"price":"0.04","size":"333350"},{"price":"0.041","size":"300000"},{"price":"0.042","size":"800"},{"price":"0.05","size":"14660"},{"price":"0.051","size":"10.53"},{"price":"0.09","size":"19"},{"price":"0.15","size":"127.23"},{"price":"0.22","size":"128.36"},{"price":"0.221","size":"5.26"},{"price":"0.228","size":"131.57"},{"price":"0.27","size":"1904.95"},{"price":"0.39","size":"5"},{"price":"0.4","size":"34375"},{"price":"0.401","size":"10000"},{"price":"0.402","size":"1492"},{"price":"0.45","size":"22.5"},{"price":"0.5","size":"26767.96"},{"price":"0.501","size":"3000"},{"price":"0.502","size":"1077.83"},{"price":"0.6","size":"21522.45"},{"price":"0.601","size":"2000"},{"price":"0.603","size":"1164"},{"price":"0.623","size":"5"},{"price":"0.64","size":"1211"},{"price":"0.65","size":"27012.52"},{"price":"0.66","size":"46.4"},{"price":"0.696","size":"5000"},{"price":"0.7","size":"557.74"},{"price":"0.704","size":"1000"},{"price":"0.73","size":"6500"},{"price":"0.734","size":"1000"},{"price":"0.735","size":"30"},{"price":"0.74","size":"100"},{"price":"0.75","size":"3383.18"},{"price":"0.752","size":"2906.99"},{"price":"0.76","size":"10"},{"price":"0.764","size":"1000"},{"price":"0.767","size":"5"},{"price":"0.768","size":"400"},{"price":"0.794","size":"1000"},{"price":"0.799","size":"100"},{"price":"0.8","size":"12081.05"},{"price":"0.801","size":"2095.26"},{"price":"0.81","size":"100"},{"price":"0.814","size":"1000"},{"price":"0.82","size":"183.62"},{"price":"0.824","size":"1000"},{"price":"0.83","size":"2573"},{"price":"0.834","size":"1000"},{"price":"0.838","size":"168.53"},{"price":"0.84","size":"12150"},{"price":"0.841","size":"100"},{"price":"0.843","size":"100"},{"price":"0.844","size":"1100"},{"price":"0.845","size":"144"},{"price":"0.85","size":"245.57"},{"price":"0.854","size":"1000"},{"price":"0.855","size":"11634.31"},{"price":"0.856","size":"7"},{"price":"0.86","size":"716"},{"price":"0.861","size":"144283.19"},{"price":"0.862","size":"100"},{"price":"0.864","size":"1100"},{"price":"0.867","size":"438"},{"price":"0.87","size":"996"},{"price":"0.871","size":"209826.98"},{"price":"0.872","size":"50"},{"price":"0.875","size":"1020.47"},{"price":"0.876","size":"75"},{"price":"0.88","size":"5096.64"},{"price":"0.882","size":"648.12"},{"price":"0.883","size":"1000"},{"price":"0.884","size":"10834.73"},{"price":"0.886","size":"230.12"},{"price":"0.887","size":"1162.79"},{"price":"0.888","size":"236.32"},{"price":"0.889","size":"1186.28"},{"price":"0.89","size":"6421.54"},{"price":"0.891","size":"5069.15"},{"price":"0.892","size":"52728.52"},{"price":"0.893","size":"232.7"},{"price":"0.894","size":"355.22"},{"price":"0.895","size":"5319.74"},{"price":"0.896","size":"52728.51"},{"price":"0.897","size":"114.3"},{"price":"0.898","size":"329.06"},{"price":"0.899","size":"27080.06"},{"price":"0.9","size":"35120.43"},{"price":"0.901","size":"4710.7"},{"price":"0.902","size":"84437.86"},{"price":"0.903","size":"1730.09"},{"price":"0.904","size":"629.06"},{"price":"0.905","size":"3010"},{"price":"0.906","size":"229.06"},{"price":"0.907","size":"33247.87"},{"price":"0.908","size":"15415.06"},{"price":"0.909","size":"6564.56"},{"price":"0.91","size":"36372.79"},{"price":"0.911","size":"24024.11"},{"price":"0.912","size":"16129.46"},{"price":"0.913","size":"60753.29"},{"price":"0.914","size":"351797.88"}],"asks":[{"price":"0.999","size":"4912713.42"},{"price":"0.998","size":"1003359"},{"price":"0.997","size":"1111111"},{"price":"0.996","size":"55555"},{"price":"0.995","size":"500"},{"price":"0.994","size":"6000"},{"price":"0.99","size":"1200"},{"price":"0.985","size":"5.65"},{"price":"0.984","size":"5000000"},{"price":"0.983","size":"800"},{"price":"0.98","size":"5050"},{"price":"0.979","size":"2300"},{"price":"0.97","size":"530"},{"price":"0.969","size":"367.48"},{"price":"0.959","size":"720"},{"price":"0.958","size":"725.45"},{"price":"0.952","size":"70"},{"price":"0.951","size":"71"},{"price":"0.95","size":"5879.09"},{"price":"0.93","size":"13425.27"},{"price":"0.929","size":"6800"},{"price":"0.928","size":"437"},{"price":"0.927","size":"333"},{"price":"0.925","size":"1245"},{"price":"0.924","size":"5000"},{"price":"0.922","size":"11231.85"},{"price":"0.921","size":"127"},{"price":"0.92","size":"44813"},{"price":"0.919","size":"32326.98"},{"price":"0.918","size":"61985.56"},{"price":"0.917","size":"185052.96"},{"price":"0.916","size":"34133.67"},{"price":"0.915","size":"39184.99"}],"tick_size":"0.001","event_type":"book","last_trade_price":"0.086"}]

PONG
{"market":"0x9b6fef249040fd17e9c107955b37ac2c3e923509b6b0ff01cc463a331ddeb894", "price_changes":[{"asset_id":"108233603819467706476318984012158651931658302669301887462181073562758483842092", "price":"0.166", "size":"24926.68", "side":"SELL", "hash":"eb9764285a47a1d5d085e4a5263cfdd128c777bf", "best_bid":"0.163", "best_ask":"0.164"}, {"asset_id":"32270411694523539495262303868629477861017829722282576458031815333486368239544", "price":"0.834", "size":"24926.68", "side":"BUY", "hash":"4726df062ed8e7065cf097e9667f2264b1ca0d2f", "best_bid":"0.836", "best_ask":"0.837"}], "timestamp":"1780178271381", "event_type":"price_change"}
{"market":"0x375409bc5eeeff961e82b479caeccc20f33d15738e5bce1186d628aa3d9dfb1f", "price_changes":[{"asset_id":"115556263888245616435851357148058235707004733438163639091106356867234218207169", "price":"0.115", "size":"11999.15", "side":"SELL", "hash":"3a0ed8defdb116080b9835300286d52b07cabd2c", "best_bid":"0.112", "best_ask":"0.113"}, {"asset_id":"77121637225348873006259930776623502125079210522997384841464684944292365296940", "price":"0.885", "size":"11999.15", "side":"BUY", "hash":"10e27d7ac1223030e191c8a0c15ee709a410b1b2", "best_bid":"0.887", "best_ask":"0.888"}], "timestamp":"1780178271381", "event_type":"price_change"}
{"market":"0x4f3421fb2daf5cca7430ed8d8132463963081572d75434393a1808fdb8829fe8", "price_changes":[{"asset_id":"45415751658241142530386585138386640503488308219341470020075667342738719018629", "price":"0.103", "size":"18202.51", "side":"SELL", "hash":"f1437716ac8133d39cff705622c994154d88a697", "best_bid":"0.1", "best_ask":"0.101"}, {"asset_id":"31940783580344558651011323787577288681658737625185216525249046282994042503801", "price":"0.897", "size":"18202.51", "side":"BUY", "hash":"15a13cfcc8ee32639980e81d15d14c64097c5d45", "best_bid":"0.899", "best_ask":"0.9"}], "timestamp":"1780178271409", "event_type":"price_change"}
{"market":"0x375409bc5eeeff961e82b479caeccc20f33d15738e5bce1186d628aa3d9dfb1f", "price_changes":[{"asset_id":"115556263888245616435851357148058235707004733438163639091106356867234218207169", "price":"0.115", "size":"12079.15", "side":"SELL", "hash":"1889d2dd157c46dd63b9e0dc6dccfc224e704ae4", "best_bid":"0.112", "best_ask":"0.113"}, {"asset_id":"77121637225348873006259930776623502125079210522997384841464684944292365296940", "price":"0.885", "size":"12079.15", "side":"BUY", "hash":"5779efa1add027d4ab33f57befc801af1868cacb", "best_bid":"0.887", "best_ask":"0.888"}], "timestamp":"1780178271471", "event_type":"price_change"}
{"market":"0x9b6fef249040fd17e9c107955b37ac2c3e923509b6b0ff01cc463a331ddeb894", "price_changes":[{"asset_id":"108233603819467706476318984012158651931658302669301887462181073562758483842092", "price":"0.166", "size":"25006.68", "side":"SELL", "hash":"b433c9827fa483c81dcbf8ca1b75aed617c354f5", "best_bid":"0.163", "best_ask":"0.164"}, {"asset_id":"32270411694523539495262303868629477861017829722282576458031815333486368239544", "price":"0.834", "size":"25006.68", "side":"BUY", "hash":"6541790247293a7a07d0942a21870dc01262f265", "best_bid":"0.836", "best_ask":"0.837"}], "timestamp":"1780178271470", "event_type":"price_change"}
{"market":"0x4f3421fb2daf5cca7430ed8d8132463963081572d75434393a1808fdb8829fe8", "price_changes":[{"asset_id":"45415751658241142530386585138386640503488308219341470020075667342738719018629", "price":"0.103", "size":"18263.31", "side":"SELL", "hash":"15730664d5e89ea31565d52647082a0ef868b546", "best_bid":"0.1", "best_ask":"0.101"}, {"asset_id":"31940783580344558651011323787577288681658737625185216525249046282994042503801", "price":"0.897", "size":"18263.31", "side":"BUY", "hash":"ae99b3d73f46a7d9e37799feb7159490473f8d2c", "best_bid":"0.899", "best_ask":"0.9"}], "timestamp":"1780178271586", "event_type":"price_change"}
{"market":"0x4f3421fb2daf5cca7430ed8d8132463963081572d75434393a1808fdb8829fe8", "asset_id":"31940783580344558651011323787577288681658737625185216525249046282994042503801", "best_bid":"0.899", "best_ask":"0.9", "spread":"0.001", "timestamp":"1780178272866", "event_type":"best_bid_ask"}
{"market":"0x4f3421fb2daf5cca7430ed8d8132463963081572d75434393a1808fdb8829fe8", "price_changes":[{"asset_id":"45415751658241142530386585138386640503488308219341470020075667342738719018629", "price":"0.101", "size":"67551.84", "side":"SELL", "hash":"41cb2912d139b1d5bf817e2bb2cc5d5e03e34acf", "best_bid":"0.1", "best_ask":"0.101"}, {"asset_id":"31940783580344558651011323787577288681658737625185216525249046282994042503801", "price":"0.899", "size":"67551.84", "side":"BUY", "hash":"423d7fecd40c6249ddf1ea3722a16042e291f5fb", "best_bid":"0.899", "best_ask":"0.9"}], "timestamp":"1780178272865", "event_type":"price_change"}
{"market":"0x4f3421fb2daf5cca7430ed8d8132463963081572d75434393a1808fdb8829fe8", "asset_id":"31940783580344558651011323787577288681658737625185216525249046282994042503801", "bids":[{"price":"0.001", "size":"21074238.91"}, {"price":"0.002", "size":"37.76"}, {"price":"0.01", "size":"25929.6"}, {"price":"0.011", "size":"6.21"}, {"price":"0.014", "size":"1111111"}, {"price":"0.015", "size":"1000000"}, {"price":"0.02", "size":"36500"}, {"price":"0.021", "size":"800"}, {"price":"0.022", "size":"11.19"}, {"price":"0.05", "size":"40"}, {"price":"0.077", "size":"2000"}, {"price":"0.078", "size":"5.64"}, {"price":"0.1", "size":"2254.88"}, {"price":"0.11", "size":"1016"}, {"price":"0.12", "size":"1021"}, {"price":"0.13", "size":"1000"}, {"price":"0.14", "size":"999.99"}, {"price":"0.15", "size":"1153.71"}, {"price":"0.2", "size":"409.2"}, {"price":"0.224", "size":"433.92"}, {"price":"0.225", "size":"5.14"}, {"price":"0.25", "size":"453.7"}, {"price":"0.253", "size":"200"}, {"price":"0.254", "size":"200"}, {"price":"0.27", "size":"200"}, {"price":"0.28", "size":"200"}, {"price":"0.31", "size":"200"}, {"price":"0.33", "size":"215.15"}, {"price":"0.34", "size":"199.99"}, {"price":"0.35", "size":"102.46"}, {"price":"0.36", "size":"228"}, {"price":"0.361", "size":"100"}, {"price":"0.4", "size":"34637.29"}, {"price":"0.401", "size":"5000"}, {"price":"0.41", "size":"200"}, {"price":"0.42", "size":"200"}, {"price":"0.43", "size":"200"}, {"price":"0.44", "size":"200"}, {"price":"0.45", "size":"354.02"}, {"price":"0.46", "size":"200"}, {"price":"0.461", "size":"1077.83"}, {"price":"0.5", "size":"25496.62"}, {"price":"0.501", "size":"5100"}, {"price":"0.51", "size":"205.76"}, {"price":"0.511", "size":"100"}, {"price":"0.52", "size":"100"}, {"price":"0.53", "size":"100"}, {"price":"0.54", "size":"100"}, {"price":"0.55", "size":"100"}, {"price":"0.56", "size":"100"}, {"price":"0.57", "size":"100"}, {"price":"0.58", "size":"100"}, {"price":"0.6", "size":"21059.73"}, {"price":"0.61", "size":"100"}, {"price":"0.62", "size":"111.9"}, {"price":"0.632", "size":"5322.31"}, {"price":"0.64", "size":"28.8"}, {"price":"0.643", "size":"100"}, {"price":"0.65", "size":"16970.62"}, {"price":"0.66", "size":"100"}, {"price":"0.662", "size":"1000"}, {"price":"0.67", "size":"100"}, {"price":"0.673", "size":"100"}, {"price":"0.674", "size":"100"}, {"price":"0.678", "size":"100"}, {"price":"0.68", "size":"410.68"}, {"price":"0.69", "size":"100"}, {"price":"0.693", "size":"1000"}, {"price":"0.7", "size":"422.3"}, {"price":"0.703", "size":"100"}, {"price":"0.704", "size":"100"}, {"price":"0.708", "size":"100"}, {"price":"0.71", "size":"61.7"}, {"price":"0.723", "size":"1000"}, {"price":"0.733", "size":"100"}, {"price":"0.75", "size":"3192.15"}, {"price":"0.753", "size":"1000"}, {"price":"0.76", "size":"341.8"}, {"price":"0.763", "size":"100"}, {"price":"0.764", "size":"100"}, {"price":"0.769", "size":"100"}, {"price":"0.777", "size":"100"}, {"price":"0.778", "size":"400"}, {"price":"0.78", "size":"258.06"}, {"price":"0.781", "size":"100"}, {"price":"0.783", "size":"1000"}, {"price":"0.79", "size":"47.6"}, {"price":"0.798", "size":"1781.45"}, {"price":"0.8", "size":"246868.85"}, {"price":"0.801", "size":"100"}, {"price":"0.803", "size":"1000"}, {"price":"0.804", "size":"30"}, {"price":"0.813", "size":"1000"}, {"price":"0.823", "size":"1000"}, {"price":"0.826", "size":"100"}, {"price":"0.827", "size":"100"}, {"price":"0.83", "size":"39.23"}, {"price":"0.833", "size":"1000"}, {"price":"0.84", "size":"356.45"}, {"price":"0.843", "size":"1000"}, {"price":"0.847", "size":"100"}, {"price":"0.849", "size":"2541.52"}, {"price":"0.85", "size":"15927.35"}, {"price":"0.851", "size":"800"}, {"price":"0.853", "size":"68.33"}, {"price":"0.855", "size":"13.33"}, {"price":"0.858", "size":"1035.21"}, {"price":"0.859", "size":"50"}, {"price":"0.86", "size":"34.6"}, {"price":"0.862", "size":"75"}, {"price":"0.867", "size":"17.97"}, {"price":"0.868", "size":"1000"}, {"price":"0.869", "size":"45"}, {"price":"0.87", "size":"4000"}, {"price":"0.871", "size":"39.42"}, {"price":"0.875", "size":"170"}, {"price":"0.878", "size":"232.7"}, {"price":"0.88", "size":"197"}, {"price":"0.882", "size":"1000"}, {"price":"0.885", "size":"925.73"}, {"price":"0.886", "size":"100"}, {"price":"0.887", "size":"100"}, {"price":"0.888", "size":"100"}, {"price":"0.889", "size":"100"}, {"price":"0.89", "size":"649.23"}, {"price":"0.891", "size":"1343.33"}, {"price":"0.892", "size":"7071.71"}, {"price":"0.893", "size":"15257.35"}, {"price":"0.894", "size":"121650.88"}, {"price":"0.895", "size":"1515.46"}, {"price":"0.896", "size":"30940.81"}, {"price":"0.897", "size":"18263.31"}, {"price":"0.898", "size":"90693.2"}, {"price":"0.899", "size":"67551.84"}], "asks":[{"price":"0.999", "size":"4715397.01"}, {"price":"0.998", "size":"14"}, {"price":"0.997", "size":"1112792"}, {"price":"0.996", "size":"55564"}, {"price":"0.995", "size":"10009"}, {"price":"0.994", "size":"11109"}, {"price":"0.993", "size":"10009"}, {"price":"0.992", "size":"10009"}, {"price":"0.991", "size":"5009"}, {"price":"0.99", "size":"6209"}, {"price":"0.989", "size":"5009"}, {"price":"0.988", "size":"5009"}, {"price":"0.987", "size":"4309"}, {"price":"0.986", "size":"3009"}, {"price":"0.985", "size":"5009"}, {"price":"0.984", "size":"3009"}, {"price":"0.983", "size":"3009"}, {"price":"0.982", "size":"9"}, {"price":"0.981", "size":"5009"}, {"price":"0.98", "size":"6234"}, {"price":"0.979", "size":"4008.99"}, {"price":"0.978", "size":"4009"}, {"price":"0.977", "size":"4009"}, {"price":"0.976", "size":"3009"}, {"price":"0.975", "size":"3009"}, {"price":"0.974", "size":"4009"}, {"price":"0.973", "size":"3009"}, {"price":"0.972", "size":"4009"}, {"price":"0.971", "size":"2009"}, {"price":"0.97", "size":"409"}, {"price":"0.969", "size":"2509"}, {"price":"0.968", "size":"2652.85"}, {"price":"0.967", "size":"2509"}, {"price":"0.966", "size":"2509"}, {"price":"0.965", "size":"9"}, {"price":"0.964", "size":"9"}, {"price":"0.963", "size":"9"}, {"price":"0.962", "size":"609"}, {"price":"0.961", "size":"9"}, {"price":"0.96", "size":"134"}, {"price":"0.959", "size":"9"}, {"price":"0.958", "size":"9"}, {"price":"0.957", "size":"9"}, {"price":"0.956", "size":"9"}, {"price":"0.955", "size":"9"}, {"price":"0.954", "size":"9"}, {"price":"0.953", "size":"9"}, {"price":"0.952", "size":"9"}, {"price":"0.951", "size":"9"}, {"price":"0.95", "size":"79"}, {"price":"0.949", "size":"10009"}, {"price":"0.948", "size":"9"}, {"price":"0.947", "size":"9"}, {"price":"0.946", "size":"9"}, {"price":"0.945", "size":"309"}, {"price":"0.944", "size":"9"}, {"price":"0.943", "size":"9"}, {"price":"0.942", "size":"9"}, {"price":"0.941", "size":"9"}, {"price":"0.94", "size":"36"}, {"price":"0.939", "size":"202"}, {"price":"0.938", "size":"10009"}, {"price":"0.937", "size":"5009"}, {"price":"0.936", "size":"7509"}, {"price":"0.935", "size":"5151"}, {"price":"0.934", "size":"6209"}, {"price":"0.933", "size":"4603.78"}, {"price":"0.932", "size":"2856.05"}, {"price":"0.931", "size":"2772.73"}, {"price":"0.93", "size":"9438.97"}, {"price":"0.929", "size":"1564"}, {"price":"0.928", "size":"5464.3"}, {"price":"0.927", "size":"1109"}, {"price":"0.926", "size":"357402.07"}, {"price":"0.925", "size":"20562.67"}, {"price":"0.924", "size":"6753.29"}, {"price":"0.923", "size":"434.15"}, {"price":"0.922", "size":"512.12"}, {"price":"0.921", "size":"25029"}, {"price":"0.92", "size":"15376.09"}, {"price":"0.919", "size":"1633.99"}, {"price":"0.918", "size":"14672.52"}, {"price":"0.917", "size":"2431.41"}, {"price":"0.916", "size":"9"}, {"price":"0.915", "size":"821.33"}, {"price":"0.914", "size":"22609"}, {"price":"0.913", "size":"4605.61"}, {"price":"0.912", "size":"1782.17"}, {"price":"0.911", "size":"570.79"}, {"price":"0.91", "size":"6647.21"}, {"price":"0.909", "size":"958.45"}, {"price":"0.908", "size":"909"}, {"price":"0.907", "size":"3608.93"}, {"price":"0.906", "size":"1240.91"}, {"price":"0.905", "size":"3028.99"}, {"price":"0.904", "size":"1169.1"}, {"price":"0.903", "size":"6197.22"}, {"price":"0.902", "size":"6248.36"}, {"price":"0.901", "size":"7903.47"}, {"price":"0.9", "size":"9221.83"}], "hash":"423d7fecd40c6249ddf1ea3722a16042e291f5fb", "timestamp":"1780178272865", "event_type":"book"}
{"market":"0x4f3421fb2daf5cca7430ed8d8132463963081572d75434393a1808fdb8829fe8", "price_changes":[{"asset_id":"45415751658241142530386585138386640503488308219341470020075667342738719018629", "price":"0.099", "size":"7893.47", "side":"BUY", "hash":"7daa3f8c70d2d8e5b98708ec3aac04aba968afc4", "best_bid":"0.1", "best_ask":"0.101"}, {"asset_id":"31940783580344558651011323787577288681658737625185216525249046282994042503801", "price":"0.901", "size":"7893.47", "side":"SELL", "hash":"f1f6b365232ee63acc5e3d186d7689a47e37b842", "best_bid":"0.899", "best_ask":"0.9"}], "timestamp":"1780178273064", "event_type":"price_change"}
{"market":"0x4f3421fb2daf5cca7430ed8d8132463963081572d75434393a1808fdb8829fe8", "price_changes":[{"asset_id":"45415751658241142530386585138386640503488308219341470020075667342738719018629", "price":"0.09", "size":"6657.21", "side":"BUY", "hash":"257ba94133dac7d793687ee551537b19d8f6acb9", "best_bid":"0.1", "best_ask":"0.101"}, {"asset_id":"31940783580344558651011323787577288681658737625185216525249046282994042503801", "price":"0.91", "size":"6657.21", "side":"SELL", "hash":"50c976407963b1cc8ddca10e6eb23c36ef8a6f0a", "best_bid":"0.899", "best_ask":"0.9"}], "timestamp":"1780178273262", "event_type":"price_change"}
PONG
{"market":"0x4f3421fb2daf5cca7430ed8d8132463963081572d75434393a1808fdb8829fe8", "price_changes":[{"asset_id":"45415751658241142530386585138386640503488308219341470020075667342738719018629", "price":"0.099", "size":"7943.71", "side":"BUY", "hash":"b5f97c26bbfaf14feebd1c2ac5a94275b3a590bc", "best_bid":"0.1", "best_ask":"0.101"}, {"asset_id":"31940783580344558651011323787577288681658737625185216525249046282994042503801", "price":"0.901", "size":"7943.71", "side":"SELL", "hash":"7c323f71010e51292cddbdb47b4e52c99be4f209", "best_bid":"0.899", "best_ask":"0.9"}], "timestamp":"1780178282998", "event_type":"price_change"}
{"market":"0x9b6fef249040fd17e9c107955b37ac2c3e923509b6b0ff01cc463a331ddeb894", "price_changes":[{"asset_id":"108233603819467706476318984012158651931658302669301887462181073562758483842092", "price":"0.162", "size":"4497.11", "side":"BUY", "hash":"40fd75171e3af66e5dbc0edaf0551d3636166655", "best_bid":"0.163", "best_ask":"0.164"}, {"asset_id":"32270411694523539495262303868629477861017829722282576458031815333486368239544", "price":"0.838", "size":"4497.11", "side":"SELL", "hash":"ea858bc99d5d1ece69f6b3949af94842241e7f1e", "best_bid":"0.836", "best_ask":"0.837"}], "timestamp":"1780178283069", "event_type":"price_change"}
{"market":"0x1595b4818eeb1ea1e0bec5de6f057218e557feee9b405a0e930d290384fa1d16", "asset_id":"45484070731786948288366703334552551439356529561722304542938873238430842810537", "best_bid":"0.948", "best_ask":"0.949", "spread":"0.001", "timestamp":"1780178284578", "event_type":"best_bid_ask"}
{"market":"0x1595b4818eeb1ea1e0bec5de6f057218e557feee9b405a0e930d290384fa1d16", "price_changes":[{"asset_id":"81739002353269632749850710185641576213562066971072676369728657545679630163887", "price":"0.051", "size":"557033.11", "side":"BUY", "hash":"4f386ca7a3da07f15ee47d0b853a0e6ffca219e2", "best_bid":"0.051", "best_ask":"0.052"}, {"asset_id":"45484070731786948288366703334552551439356529561722304542938873238430842810537", "price":"0.949", "size":"557033.11", "side":"SELL", "hash":"ad0804c1e3b84d8ad73c6cdaabab825bc4aceeff", "best_bid":"0.948", "best_ask":"0.949"}], "timestamp":"1780178284578", "event_type":"price_change"}
{"market":"0x1595b4818eeb1ea1e0bec5de6f057218e557feee9b405a0e930d290384fa1d16", "asset_id":"45484070731786948288366703334552551439356529561722304542938873238430842810537", "bids":[{"price":"0.001", "size":"21202713.62"}, {"price":"0.002", "size":"105"}, {"price":"0.003", "size":"29.49"}, {"price":"0.01", "size":"181.81"}, {"price":"0.013", "size":"1698.4"}, {"price":"0.014", "size":"17.32"}, {"price":"0.05", "size":"2236"}, {"price":"0.054", "size":"155555"}, {"price":"0.055", "size":"150000"}, {"price":"0.056", "size":"800"}, {"price":"0.057", "size":"5.16"}, {"price":"0.1", "size":"2500"}, {"price":"0.14", "size":"27"}, {"price":"0.2", "size":"1000"}, {"price":"0.201", "size":"6.72"}, {"price":"0.237", "size":"126.58"}, {"price":"0.3", "size":"600"}, {"price":"0.348", "size":"211.53"}, {"price":"0.39", "size":"5"}, {"price":"0.4", "size":"34625"}, {"price":"0.401", "size":"10000"}, {"price":"0.402", "size":"1492"}, {"price":"0.5", "size":"25100"}, {"price":"0.501", "size":"5000"}, {"price":"0.51", "size":"87.55"}, {"price":"0.511", "size":"1076.32"}, {"price":"0.58", "size":"17.54"}, {"price":"0.584", "size":"300"}, {"price":"0.6", "size":"20859.33"}, {"price":"0.61", "size":"76.92"}, {"price":"0.623", "size":"5"}, {"price":"0.65", "size":"15443.05"}, {"price":"0.651", "size":"2095.26"}, {"price":"0.7", "size":"780"}, {"price":"0.701", "size":"437"}, {"price":"0.712", "size":"50"}, {"price":"0.72", "size":"18"}, {"price":"0.737", "size":"1000"}, {"price":"0.74", "size":"476.92"}, {"price":"0.75", "size":"2198.07"}, {"price":"0.751", "size":"400"}, {"price":"0.767", "size":"1005"}, {"price":"0.77", "size":"43.3"}, {"price":"0.78", "size":"192.53"}, {"price":"0.792", "size":"1100"}, {"price":"0.797", "size":"1000"}, {"price":"0.8", "size":"1307.15"}, {"price":"0.801", "size":"500"}, {"price":"0.82", "size":"12201.05"}, {"price":"0.821", "size":"400"}, {"price":"0.827", "size":"1000"}, {"price":"0.83", "size":"1079.99"}, {"price":"0.832", "size":"50"}, {"price":"0.838", "size":"1913.7"}, {"price":"0.84", "size":"288"}, {"price":"0.847", "size":"1000"}, {"price":"0.848", "size":"33"}, {"price":"0.85", "size":"13781.98"}, {"price":"0.851", "size":"30"}, {"price":"0.855", "size":"327.86"}, {"price":"0.856", "size":"7"}, {"price":"0.857", "size":"1000"}, {"price":"0.86", "size":"334.14"}, {"price":"0.867", "size":"1000"}, {"price":"0.869", "size":"20"}, {"price":"0.87", "size":"1713.81"}, {"price":"0.877", "size":"1100"}, {"price":"0.878", "size":"163.93"}, {"price":"0.88", "size":"613.23"}, {"price":"0.885", "size":"240"}, {"price":"0.887", "size":"1370.37"}, {"price":"0.89", "size":"1231.81"}, {"price":"0.896", "size":"1592.3"}, {"price":"0.897", "size":"1000"}, {"price":"0.899", "size":"100"}, {"price":"0.9", "size":"6833.45"}, {"price":"0.901", "size":"50"}, {"price":"0.902", "size":"7772.33"}, {"price":"0.904", "size":"500"}, {"price":"0.905", "size":"5852.55"}, {"price":"0.907", "size":"125"}, {"price":"0.91", "size":"11147.07"}, {"price":"0.911", "size":"911.3"}, {"price":"0.913", "size":"500"}, {"price":"0.915", "size":"173.07"}, {"price":"0.916", "size":"1000"}, {"price":"0.917", "size":"45"}, {"price":"0.918", "size":"500"}, {"price":"0.919", "size":"532.55"}, {"price":"0.92", "size":"1746.51"}, {"price":"0.924", "size":"5917.15"}, {"price":"0.925", "size":"6585.96"}, {"price":"0.926", "size":"4177.46"}, {"price":"0.927", "size":"5259.68"}, {"price":"0.928", "size":"7012.91"}, {"price":"0.929", "size":"42450.48"}, {"price":"0.93", "size":"32653.14"}, {"price":"0.931", "size":"10000"}, {"price":"0.932", "size":"5905.04"}, {"price":"0.933", "size":"382.3"}, {"price":"0.934", "size":"6055.04"}, {"price":"0.935", "size":"22294.08"}, {"price":"0.939", "size":"950"}, {"price":"0.94", "size":"2357.57"}, {"price":"0.941", "size":"250009.76"}, {"price":"0.942", "size":"11512.52"}, {"price":"0.943", "size":"1999.94"}, {"price":"0.944", "size":"18846.47"}, {"price":"0.945", "size":"5833.22"}, {"price":"0.946", "size":"9225.11"}, {"price":"0.947", "size":"3371.26"}, {"price":"0.948", "size":"346631.69"}], "asks":[{"price":"0.999", "size":"2259057"}, {"price":"0.998", "size":"1000005"}, {"price":"0.997", "size":"2224894"}, {"price":"0.996", "size":"56355"}, {"price":"0.994", "size":"300"}, {"price":"0.993", "size":"100"}, {"price":"0.99", "size":"2517.95"}, {"price":"0.988", "size":"100000"}, {"price":"0.981", "size":"200"}, {"price":"0.98", "size":"905"}, {"price":"0.972", "size":"100000"}, {"price":"0.97", "size":"1030"}, {"price":"0.967", "size":"30"}, {"price":"0.966", "size":"5000"}, {"price":"0.965", "size":"999.99"}, {"price":"0.964", "size":"2500"}, {"price":"0.961", "size":"1500"}, {"price":"0.96", "size":"5914.44"}, {"price":"0.959", "size":"1510"}, {"price":"0.958", "size":"4305"}, {"price":"0.957", "size":"4718"}, {"price":"0.956", "size":"1500"}, {"price":"0.955", "size":"2500"}, {"price":"0.954", "size":"2720"}, {"price":"0.953", "size":"1220"}, {"price":"0.952", "size":"31030"}, {"price":"0.951", "size":"39747.51"}, {"price":"0.95", "size":"84174.74"}, {"price":"0.949", "size":"557033.11"}], "hash":"ad0804c1e3b84d8ad73c6cdaabab825bc4aceeff", "timestamp":"1780178284578", "event_type":"book"}
{"market":"0x1595b4818eeb1ea1e0bec5de6f057218e557feee9b405a0e930d290384fa1d16", "asset_id":"45484070731786948288366703334552551439356529561722304542938873238430842810537", "price":"0.949", "size":"19.02", "fee_rate_bps":"0", "side":"BUY", "timestamp":"1780178284601", "event_type":"last_trade_price", "transaction_hash":"0x2737d8716e7e05b4e0b73943b19d13ff437870d1dee5bc9f6e923b5aaba0110b"}
{"market":"0x1595b4818eeb1ea1e0bec5de6f057218e557feee9b405a0e930d290384fa1d16", "price_changes":[{"asset_id":"81739002353269632749850710185641576213562066971072676369728657545679630163887", "price":"0.041", "size":"1500", "side":"BUY", "hash":"7be23b7bfc02d8b5bf7d22f4af88766564169ef3", "best_bid":"0.051", "best_ask":"0.052"}, {"asset_id":"45484070731786948288366703334552551439356529561722304542938873238430842810537", "price":"0.959", "size":"1500", "side":"SELL", "hash":"5cd619e000f6650c8167c3e03637831d9e6d2482", "best_bid":"0.948", "best_ask":"0.949"}], "timestamp":"1780178284786", "event_type":"price_change"}
{"market":"0x1595b4818eeb1ea1e0bec5de6f057218e557feee9b405a0e930d290384fa1d16", "price_changes":[{"asset_id":"81739002353269632749850710185641576213562066971072676369728657545679630163887", "price":"0.041", "size":"1510", "side":"BUY", "hash":"65b5a0a3b57593f874d7a11f3d156e2d89ae8b40", "best_bid":"0.051", "best_ask":"0.052"}, {"asset_id":"45484070731786948288366703334552551439356529561722304542938873238430842810537", "price":"0.959", "size":"1510", "side":"SELL", "hash":"39fa70a8fc528751ccf106e02ffbd7b092d021bd", "best_bid":"0.948", "best_ask":"0.949"}], "timestamp":"1780178284994", "event_type":"price_change"}
{"market":"0x7876851632c295043c66536150a304cb785abdf712ba8489d298c6e6926be106", "price_changes":[{"asset_id":"97239126062673310243763617236644392945530356142765650402171508075574679292913", "price":"0.011", "size":"1818685.69", "side":"SELL", "hash":"7e1e735eb16070362d7b8bcdf48e2b2257ae9d52", "best_bid":"0.01", "best_ask":"0.011"}, {"asset_id":"19291692040378529618917910599727571242305935029274321291612270922648172794670", "price":"0.989", "size":"1818685.69", "side":"BUY", "hash":"a28f12b50316d192c7e3a4def6f36ef28d965175", "best_bid":"0.989", "best_ask":"0.99"}], "timestamp":"1780178286011", "event_type":"price_change"}
{"market":"0x375409bc5eeeff961e82b479caeccc20f33d15738e5bce1186d628aa3d9dfb1f", "price_changes":[{"asset_id":"115556263888245616435851357148058235707004733438163639091106356867234218207169", "price":"0.12", "size":"20554.13", "side":"SELL", "hash":"674ada3fcecf6655141a3172401036e3f420396f", "best_bid":"0.112", "best_ask":"0.113"}, {"asset_id":"77121637225348873006259930776623502125079210522997384841464684944292365296940", "price":"0.88", "size":"20554.13", "side":"BUY", "hash":"5e8b74a998d44db112edd281eb66b7be9bfd9103", "best_bid":"0.887", "best_ask":"0.888"}], "timestamp":"1780178287518", "event_type":"price_change"}
{"market":"0x4f3421fb2daf5cca7430ed8d8132463963081572d75434393a1808fdb8829fe8", "price_changes":[{"asset_id":"45415751658241142530386585138386640503488308219341470020075667342738719018629", "price":"0.103", "size":"18203.31", "side":"SELL", "hash":"00d133a1ccce1d30a3e3f78fac867065dbf3b54a", "best_bid":"0.1", "best_ask":"0.101"}, {"asset_id":"31940783580344558651011323787577288681658737625185216525249046282994042503801", "price":"0.897", "size":"18203.31", "side":"BUY", "hash":"caa32038ca96cacf12fa745069d2a777b9aecd32", "best_bid":"0.899", "best_ask":"0.9"}], "timestamp":"1780178287551", "event_type":"price_change"}
{"market":"0x4f3421fb2daf5cca7430ed8d8132463963081572d75434393a1808fdb8829fe8", "price_changes":[{"asset_id":"45415751658241142530386585138386640503488308219341470020075667342738719018629", "price":"0.103", "size":"18263.31", "side":"SELL", "hash":"5fe468e0f56c07472b006e3dda5cd1068b5913ed", "best_bid":"0.1", "best_ask":"0.101"}, {"asset_id":"31940783580344558651011323787577288681658737625185216525249046282994042503801", "price":"0.897", "size":"18263.31", "side":"BUY", "hash":"c4332db9ce9f75ee082cffafb7374306d9f5179c", "best_bid":"0.899", "best_ask":"0.9"}], "timestamp":"1780178287652", "event_type":"price_change"}
{"market":"0x375409bc5eeeff961e82b479caeccc20f33d15738e5bce1186d628aa3d9dfb1f", "price_changes":[{"asset_id":"115556263888245616435851357148058235707004733438163639091106356867234218207169", "price":"0.12", "size":"20804.13", "side":"SELL", "hash":"eaab67323cd36fcd4e990a20640088b55632f570", "best_bid":"0.112", "best_ask":"0.113"}, {"asset_id":"77121637225348873006259930776623502125079210522997384841464684944292365296940", "price":"0.88", "size":"20804.13", "side":"BUY", "hash":"bac2146d9906b3f403772413f7106378976e3924", "best_bid":"0.887", "best_ask":"0.888"}], "timestamp":"1780178287725", "event_type":"price_change"}
{"market":"0x9b6fef249040fd17e9c107955b37ac2c3e923509b6b0ff01cc463a331ddeb894", "price_changes":[{"asset_id":"108233603819467706476318984012158651931658302669301887462181073562758483842092", "price":"0.166", "size":"24952", "side":"SELL", "hash":"28a9257212eaa3cc3670b26bf4f88853f38b1b32", "best_bid":"0.163", "best_ask":"0.164"}, {"asset_id":"32270411694523539495262303868629477861017829722282576458031815333486368239544", "price":"0.834", "size":"24952", "side":"BUY", "hash":"03ca818e1d8f68d16e26a56bb54c28d8e5eace80", "best_bid":"0.836", "best_ask":"0.837"}], "timestamp":"1780178288006", "event_type":"price_change"}
{"market":"0x9b6fef249040fd17e9c107955b37ac2c3e923509b6b0ff01cc463a331ddeb894", "price_changes":[{"asset_id":"108233603819467706476318984012158651931658302669301887462181073562758483842092", "price":"0.166", "size":"25006.68", "side":"SELL", "hash":"d0cc8f7b8e1cc2c53462de7eaa7b64f4e2ab51cd", "best_bid":"0.163", "best_ask":"0.164"}, {"asset_id":"32270411694523539495262303868629477861017829722282576458031815333486368239544", "price":"0.834", "size":"25006.68", "side":"BUY", "hash":"314802dd2633fa0bdb08ba57d9ae5d3f8c646a69", "best_bid":"0.836", "best_ask":"0.837"}], "timestamp":"1780178288187", "event_type":"price_change"}
{"market":"0x7976b8dbacf9077eb1453a62bcefd6ab2df199acd28aad276ff0d920d6992892", "price_changes":[{"asset_id":"4394372887385518214471608448209527405727552777602031099972143344338178308080", "price":"0.17", "size":"27598.28", "side":"SELL", "hash":"d86483ccf48b7ee533c7420c1465741e35bed4f5", "best_bid":"0.167", "best_ask":"0.168"}, {"asset_id":"112680630004798425069810935278212000865453267506345451433803052322987302357330", "price":"0.83", "size":"27598.28", "side":"BUY", "hash":"07375d1c8701ddd06ad3fa1594170cfc0442b18e", "best_bid":"0.832", "best_ask":"0.833"}], "timestamp":"1780178289563", "event_type":"price_change"}
{"market":"0x1595b4818eeb1ea1e0bec5de6f057218e557feee9b405a0e930d290384fa1d16", "price_changes":[{"asset_id":"81739002353269632749850710185641576213562066971072676369728657545679630163887", "price":"0.053", "size":"3311.26", "side":"SELL", "hash":"f9c6dbbb04fc67e254145e5bc0c8d9332f8d219f", "best_bid":"0.051", "best_ask":"0.052"}, {"asset_id":"45484070731786948288366703334552551439356529561722304542938873238430842810537", "price":"0.947", "size":"3311.26", "side":"BUY", "hash":"098f4d5bfd580ffed3d28658fe4e4cd4fd1846d2", "best_bid":"0.948", "best_ask":"0.949"}], "timestamp":"1780178289580", "event_type":"price_change"}
{"market":"0x30d55d8124ee1e12dabe89201badc45669b81dff69e4ce44d961f32878ec178a", "price_changes":[{"asset_id":"27576533317283401577758999384642760405921738493660383550832555714312627457443", "price":"0.092", "size":"78371.18", "side":"SELL", "hash":"eadcf28ee40189f65429ed502fcb8a5774275cb2", "best_bid":"0.089", "best_ask":"0.09"}, {"asset_id":"52986718774908357330412653486471347449818893503063830313445318937088822580057", "price":"0.908", "size":"78371.18", "side":"BUY", "hash":"5799779bf61dd689020111ee762ac72ca2f37b07", "best_bid":"0.91", "best_ask":"0.911"}], "timestamp":"1780178289579", "event_type":"price_change"}
{"market":"0x0c4cd2055d6ea89354ffddc55d6dbcef9355748112ea952fc925f3db6a5c457f", "price_changes":[{"asset_id":"18812649149814341758733697580460697418474693998558159483117100240528657629879", "price":"0.088", "size":"16069.46", "side":"SELL", "hash":"748d44d3af4056930ebe67256e70904b6a2cb466", "best_bid":"0.085", "best_ask":"0.086"}, {"asset_id":"115428153746996892211798999366308897078723117634059783423375188043903703749062", "price":"0.912", "size":"16069.46", "side":"BUY", "hash":"6145ac68efbd1b7c07dc4ef8b874b90f0ee74a87", "best_bid":"0.914", "best_ask":"0.915"}], "timestamp":"1780178289588", "event_type":"price_change"}
{"market":"0x375409bc5eeeff961e82b479caeccc20f33d15738e5bce1186d628aa3d9dfb1f", "price_changes":[{"asset_id":"115556263888245616435851357148058235707004733438163639091106356867234218207169", "price":"0.12", "size":"20809.13", "side":"SELL", "hash":"23d41e388fef88234696a9e924308520dacb4281", "best_bid":"0.112", "best_ask":"0.113"}, {"asset_id":"77121637225348873006259930776623502125079210522997384841464684944292365296940", "price":"0.88", "size":"20809.13", "side":"BUY", "hash":"ca2fd65a43176601b1ffb90d0f2569c20f9c8c31", "best_bid":"0.887", "best_ask":"0.888"}], "timestamp":"1780178289598", "event_type":"price_change"}
{"market":"0x375409bc5eeeff961e82b479caeccc20f33d15738e5bce1186d628aa3d9dfb1f", "price_changes":[{"asset_id":"115556263888245616435851357148058235707004733438163639091106356867234218207169", "price":"0.115", "size":"12019.15", "side":"SELL", "hash":"f6d4ae7a2c9ad1e2cda8c096952be2fc773a5407", "best_bid":"0.112", "best_ask":"0.113"}, {"asset_id":"77121637225348873006259930776623502125079210522997384841464684944292365296940", "price":"0.885", "size":"12019.15", "side":"BUY", "hash":"9836a2449acd130287a45f8e1aa2902fe70b7829", "best_bid":"0.887", "best_ask":"0.888"}], "timestamp":"1780178289623", "event_type":"price_change"}
{"market":"0x30d55d8124ee1e12dabe89201badc45669b81dff69e4ce44d961f32878ec178a", "price_changes":[{"asset_id":"27576533317283401577758999384642760405921738493660383550832555714312627457443", "price":"0.092", "size":"78431.18", "side":"SELL", "hash":"cf06e62542e3887f0ee0b835e2a95c54f5762cfb", "best_bid":"0.089", "best_ask":"0.09"}, {"asset_id":"52986718774908357330412653486471347449818893503063830313445318937088822580057", "price":"0.908", "size":"78431.18", "side":"BUY", "hash":"30c30b56f2c3d120f918352ecf56647cfef1dc27", "best_bid":"0.91", "best_ask":"0.911"}], "timestamp":"1780178289690", "event_type":"price_change"}
{"market":"0x7976b8dbacf9077eb1453a62bcefd6ab2df199acd28aad276ff0d920d6992892", "price_changes":[{"asset_id":"4394372887385518214471608448209527405727552777602031099972143344338178308080", "price":"0.17", "size":"27652.43", "side":"SELL", "hash":"593e5be71233d867a886ffb7c575202fcc7b743a", "best_bid":"0.167", "best_ask":"0.168"}, {"asset_id":"112680630004798425069810935278212000865453267506345451433803052322987302357330", "price":"0.83", "size":"27652.43", "side":"BUY", "hash":"384af22253f5163842398fcbd85ccf71bfb53436", "best_bid":"0.832", "best_ask":"0.833"}], "timestamp":"1780178289690", "event_type":"price_change"}
{"market":"0x0c4cd2055d6ea89354ffddc55d6dbcef9355748112ea952fc925f3db6a5c457f", "price_changes":[{"asset_id":"18812649149814341758733697580460697418474693998558159483117100240528657629879", "price":"0.088", "size":"16129.46", "side":"SELL", "hash":"98983fa4c6cd276f9221c3a31016b7dd4a293a82", "best_bid":"0.085", "best_ask":"0.086"}, {"asset_id":"115428153746996892211798999366308897078723117634059783423375188043903703749062", "price":"0.912", "size":"16129.46", "side":"BUY", "hash":"400b5961cb77c4ed03dc209f7033827d22641339", "best_bid":"0.914", "best_ask":"0.915"}], "timestamp":"1780178289691", "event_type":"price_change"}
{"market":"0x1595b4818eeb1ea1e0bec5de6f057218e557feee9b405a0e930d290384fa1d16", "price_changes":[{"asset_id":"81739002353269632749850710185641576213562066971072676369728657545679630163887", "price":"0.053", "size":"3371.26", "side":"SELL", "hash":"4d5f15836e2f06ff39a8223d4dbbeb6b4d78203e", "best_bid":"0.051", "best_ask":"0.052"}, {"asset_id":"45484070731786948288366703334552551439356529561722304542938873238430842810537", "price":"0.947", "size":"3371.26", "side":"BUY", "hash":"b85b4e8344f638b6f07c3108581615b1817d494a", "best_bid":"0.948", "best_ask":"0.949"}], "timestamp":"1780178289693", "event_type":"price_change"}
{"market":"0x375409bc5eeeff961e82b479caeccc20f33d15738e5bce1186d628aa3d9dfb1f", "price_changes":[{"asset_id":"115556263888245616435851357148058235707004733438163639091106356867234218207169", "price":"0.115", "size":"12079.15", "side":"SELL", "hash":"2aaf53fa3db30a0c1566518eb845820d3f386400", "best_bid":"0.112", "best_ask":"0.113"}, {"asset_id":"77121637225348873006259930776623502125079210522997384841464684944292365296940", "price":"0.885", "size":"12079.15", "side":"BUY", "hash":"8700f0bd7f97b50a7c47f396f5146a7674fb1946", "best_bid":"0.887", "best_ask":"0.888"}], "timestamp":"1780178289717", "event_type":"price_change"}
{"market":"0x375409bc5eeeff961e82b479caeccc20f33d15738e5bce1186d628aa3d9dfb1f", "price_changes":[{"asset_id":"115556263888245616435851357148058235707004733438163639091106356867234218207169", "price":"0.12", "size":"20814.13", "side":"SELL", "hash":"e7fa6c5c4bf887ea1fac8abade857fb2ed62bdd0", "best_bid":"0.112", "best_ask":"0.113"}, {"asset_id":"77121637225348873006259930776623502125079210522997384841464684944292365296940", "price":"0.88", "size":"20814.13", "side":"BUY", "hash":"655a21775319696ea814d8e36d16c840eb9beb53", "best_bid":"0.887", "best_ask":"0.888"}], "timestamp":"1780178290319", "event_type":"price_change"}
PONG
{"market":"0x7876851632c295043c66536150a304cb785abdf712ba8489d298c6e6926be106", "price_changes":[{"asset_id":"97239126062673310243763617236644392945530356142765650402171508075574679292913", "price":"0.011", "size":"1818725.69", "side":"SELL", "hash":"a9aacc8510562df7843c57dcbd6ca7f6e644ae4a", "best_bid":"0.01", "best_ask":"0.011"}, {"asset_id":"19291692040378529618917910599727571242305935029274321291612270922648172794670", "price":"0.989", "size":"1818725.69", "side":"BUY", "hash":"1fb53e1e51eb64e4a6d266453567d8c408886a0e", "best_bid":"0.989", "best_ask":"0.99"}], "timestamp":"1780178290747", "event_type":"price_change"}
{"market":"0x375409bc5eeeff961e82b479caeccc20f33d15738e5bce1186d628aa3d9dfb1f", "price_changes":[{"asset_id":"115556263888245616435851357148058235707004733438163639091106356867234218207169", "price":"0.12", "size":"20819.13", "side":"SELL", "hash":"6f91a5e76f27b7241ced3df44bd4475e5ac64b26", "best_bid":"0.112", "best_ask":"0.113"}, {"asset_id":"77121637225348873006259930776623502125079210522997384841464684944292365296940", "price":"0.88", "size":"20819.13", "side":"BUY", "hash":"0caf0e0542e4b37bbd4688b5d610b58792cb46ee", "best_bid":"0.887", "best_ask":"0.888"}], "timestamp":"1780178291068", "event_type":"price_change"}
{"market":"0x375409bc5eeeff961e82b479caeccc20f33d15738e5bce1186d628aa3d9dfb1f", "price_changes":[{"asset_id":"115556263888245616435851357148058235707004733438163639091106356867234218207169", "price":"0.12", "size":"20824.13", "side":"SELL", "hash":"de6ec56f056f106652074eb5c7ee4267ca060ac5", "best_bid":"0.112", "best_ask":"0.113"}, {"asset_id":"77121637225348873006259930776623502125079210522997384841464684944292365296940", "price":"0.88", "size":"20824.13", "side":"BUY", "hash":"75de930898d5a7f0f59cb0292d8887a2f7cf27aa", "best_bid":"0.887", "best_ask":"0.888"}], "timestamp":"1780178291788", "event_type":"price_change"}
{"market":"0x375409bc5eeeff961e82b479caeccc20f33d15738e5bce1186d628aa3d9dfb1f", "price_changes":[{"asset_id":"115556263888245616435851357148058235707004733438163639091106356867234218207169", "price":"0.12", "size":"20829.13", "side":"SELL", "hash":"0257d135b14e1aa1fc3a1318633062f26ff15d79", "best_bid":"0.112", "best_ask":"0.113"}, {"asset_id":"77121637225348873006259930776623502125079210522997384841464684944292365296940", "price":"0.88", "size":"20829.13", "side":"BUY", "hash":"95c016736e3e949891b700e48b9ff3acc3e04c17", "best_bid":"0.887", "best_ask":"0.888"}], "timestamp":"1780178292532", "event_type":"price_change"}
{"market":"0x375409bc5eeeff961e82b479caeccc20f33d15738e5bce1186d628aa3d9dfb1f", "price_changes":[{"asset_id":"115556263888245616435851357148058235707004733438163639091106356867234218207169", "price":"0.12", "size":"20834.13", "side":"SELL", "hash":"cbee06d01b5eba9fe3d63786bec2b30323df20a5", "best_bid":"0.112", "best_ask":"0.113"}, {"asset_id":"77121637225348873006259930776623502125079210522997384841464684944292365296940", "price":"0.88", "size":"20834.13", "side":"BUY", "hash":"98cc5706db55568ba78d062919f138de63c29ff7", "best_bid":"0.887", "best_ask":"0.888"}], "timestamp":"1780178293248", "event_type":"price_change"}
{"market":"0x7976b8dbacf9077eb1453a62bcefd6ab2df199acd28aad276ff0d920d6992892", "price_changes":[{"asset_id":"4394372887385518214471608448209527405727552777602031099972143344338178308080", "price":"0.184", "size":"0", "side":"SELL", "hash":"8c0d9209f999386a5bcabbbf3d2f9094b7043455", "best_bid":"0.167", "best_ask":"0.168"}, {"asset_id":"112680630004798425069810935278212000865453267506345451433803052322987302357330", "price":"0.816", "size":"0", "side":"BUY", "hash":"593736f9046d317b6b42e709484ee4a56fd9c249", "best_bid":"0.832", "best_ask":"0.833"}], "timestamp":"1780178293508", "event_type":"price_change"}
{"market":"0x7976b8dbacf9077eb1453a62bcefd6ab2df199acd28aad276ff0d920d6992892", "price_changes":[{"asset_id":"4394372887385518214471608448209527405727552777602031099972143344338178308080", "price":"0.184", "size":"49.77", "side":"SELL", "hash":"913f8ce6b7c8330d694068fb768304bd54334ed2", "best_bid":"0.167", "best_ask":"0.168"}, {"asset_id":"112680630004798425069810935278212000865453267506345451433803052322987302357330", "price":"0.816", "size":"49.77", "side":"BUY", "hash":"51bcd285dc4c00f773eb7f08059f3cdc4c7a0c25", "best_bid":"0.832", "best_ask":"0.833"}], "timestamp":"1780178293706", "event_type":"price_change"}
{"market":"0x375409bc5eeeff961e82b479caeccc20f33d15738e5bce1186d628aa3d9dfb1f", "price_changes":[{"asset_id":"115556263888245616435851357148058235707004733438163639091106356867234218207169", "price":"0.12", "size":"20839.13", "side":"SELL", "hash":"76f3066926cd3304a469efdbb1f83e43347dbe2a", "best_bid":"0.112", "best_ask":"0.113"}, {"asset_id":"77121637225348873006259930776623502125079210522997384841464684944292365296940", "price":"0.88", "size":"20839.13", "side":"BUY", "hash":"1fe8bb3fa9a916959eee2ec4d253cb6d7e8366eb", "best_bid":"0.887", "best_ask":"0.888"}], "timestamp":"1780178293951", "event_type":"price_change"}
{"market":"0x375409bc5eeeff961e82b479caeccc20f33d15738e5bce1186d628aa3d9dfb1f", "price_changes":[{"asset_id":"115556263888245616435851357148058235707004733438163639091106356867234218207169", "price":"0.12", "size":"20844.13", "side":"SELL", "hash":"a17cf81fbfc98c756b6448d777fe45a3ac7870df", "best_bid":"0.112", "best_ask":"0.113"}, {"asset_id":"77121637225348873006259930776623502125079210522997384841464684944292365296940", "price":"0.88", "size":"20844.13", "side":"BUY", "hash":"efa5c1ee08bbcd6308537a2f235d5b11982cc369", "best_bid":"0.887", "best_ask":"0.888"}], "timestamp":"1780178294670", "event_type":"price_change"}
{"market":"0x375409bc5eeeff961e82b479caeccc20f33d15738e5bce1186d628aa3d9dfb1f", "price_changes":[{"asset_id":"115556263888245616435851357148058235707004733438163639091106356867234218207169", "price":"0.12", "size":"20849.13", "side":"SELL", "hash":"9d692d9c8acb9cb16b8acc014ae218a179dbe5e9", "best_bid":"0.112", "best_ask":"0.113"}, {"asset_id":"77121637225348873006259930776623502125079210522997384841464684944292365296940", "price":"0.88", "size":"20849.13", "side":"BUY", "hash":"39e08a19563e29d9cbed5c6a22c8de00d5e22e48", "best_bid":"0.887", "best_ask":"0.888"}], "timestamp":"1780178295399", "event_type":"price_change"}
{"market":"0x0c4cd2055d6ea89354ffddc55d6dbcef9355748112ea952fc925f3db6a5c457f", "price_changes":[{"asset_id":"18812649149814341758733697580460697418474693998558159483117100240528657629879", "price":"0.088", "size":"16049.46", "side":"SELL", "hash":"ba69603fec92577cd3924cd0971aae03e7fd0501", "best_bid":"0.085", "best_ask":"0.086"}, {"asset_id":"115428153746996892211798999366308897078723117634059783423375188043903703749062", "price":"0.912", "size":"16049.46", "side":"BUY", "hash":"4ca8d83f7ce0c3021527cdab3e5df57bb3376fdd", "best_bid":"0.914", "best_ask":"0.915"}], "timestamp":"1780178300224", "event_type":"price_change"}
{"market":"0x1595b4818eeb1ea1e0bec5de6f057218e557feee9b405a0e930d290384fa1d16", "price_changes":[{"asset_id":"81739002353269632749850710185641576213562066971072676369728657545679630163887", "price":"0.053", "size":"3291.26", "side":"SELL", "hash":"a93ea9c85f50afc01f15fa42d92d3ca0c74a7a94", "best_bid":"0.051", "best_ask":"0.052"}, {"asset_id":"45484070731786948288366703334552551439356529561722304542938873238430842810537", "price":"0.947", "size":"3291.26", "side":"BUY", "hash":"7cce97f24d85b4930cdf57892b33c4c1826963d9", "best_bid":"0.948", "best_ask":"0.949"}], "timestamp":"1780178300225", "event_type":"price_change"}
{"market":"0x7976b8dbacf9077eb1453a62bcefd6ab2df199acd28aad276ff0d920d6992892", "price_changes":[{"asset_id":"4394372887385518214471608448209527405727552777602031099972143344338178308080", "price":"0.17", "size":"27626.88", "side":"SELL", "hash":"4d8f722ee23112938212cc7f3eee8c7ab5da7014", "best_bid":"0.167", "best_ask":"0.168"}, {"asset_id":"112680630004798425069810935278212000865453267506345451433803052322987302357330", "price":"0.83", "size":"27626.88", "side":"BUY", "hash":"de5439d66033b9e0a9f83d7d8ed0c29e7781dfbc", "best_bid":"0.832", "best_ask":"0.833"}], "timestamp":"1780178300230", "event_type":"price_change"}
{"market":"0x30d55d8124ee1e12dabe89201badc45669b81dff69e4ce44d961f32878ec178a", "price_changes":[{"asset_id":"27576533317283401577758999384642760405921738493660383550832555714312627457443", "price":"0.092", "size":"78375.52", "side":"SELL", "hash":"3af8fddd3210c5cddd335542ae892aa6b8f62440", "best_bid":"0.089", "best_ask":"0.09"}, {"asset_id":"52986718774908357330412653486471347449818893503063830313445318937088822580057", "price":"0.908", "size":"78375.52", "side":"BUY", "hash":"e1bfd0ec3a0fd8a4d90036d0897c85ded7e608c7", "best_bid":"0.91", "best_ask":"0.911"}], "timestamp":"1780178300233", "event_type":"price_change"}
{"market":"0x1595b4818eeb1ea1e0bec5de6f057218e557feee9b405a0e930d290384fa1d16", "price_changes":[{"asset_id":"81739002353269632749850710185641576213562066971072676369728657545679630163887", "price":"0.053", "size":"3371.26", "side":"SELL", "hash":"66e98b5efa16dc84e0a779361248e5b876048226", "best_bid":"0.051", "best_ask":"0.052"}, {"asset_id":"45484070731786948288366703334552551439356529561722304542938873238430842810537", "price":"0.947", "size":"3371.26", "side":"BUY", "hash":"2cd5c567c16298f4f39773d75a6beb2013fdf05a", "best_bid":"0.948", "best_ask":"0.949"}], "timestamp":"1780178300325", "event_type":"price_change"}
{"market":"0x0c4cd2055d6ea89354ffddc55d6dbcef9355748112ea952fc925f3db6a5c457f", "price_changes":[{"asset_id":"18812649149814341758733697580460697418474693998558159483117100240528657629879", "price":"0.088", "size":"16129.46", "side":"SELL", "hash":"baee9cdd0572d754a22f949ef71804e42db38398", "best_bid":"0.085", "best_ask":"0.086"}, {"asset_id":"115428153746996892211798999366308897078723117634059783423375188043903703749062", "price":"0.912", "size":"16129.46", "side":"BUY", "hash":"7c09983f444a1f039d860202e6d0974e5b0b0d53", "best_bid":"0.914", "best_ask":"0.915"}], "timestamp":"1780178300328", "event_type":"price_change"}
{"market":"0x30d55d8124ee1e12dabe89201badc45669b81dff69e4ce44d961f32878ec178a", "price_changes":[{"asset_id":"27576533317283401577758999384642760405921738493660383550832555714312627457443", "price":"0.092", "size":"78431.18", "side":"SELL", "hash":"3b903ab0e39166f5d8c99c8ddd65dd3c595f22e7", "best_bid":"0.089", "best_ask":"0.09"}, {"asset_id":"52986718774908357330412653486471347449818893503063830313445318937088822580057", "price":"0.908", "size":"78431.18", "side":"BUY", "hash":"793620f0b73e04bf57133a5a197cb0907453f3e2", "best_bid":"0.91", "best_ask":"0.911"}], "timestamp":"1780178300358", "event_type":"price_change"}
{"market":"0x7976b8dbacf9077eb1453a62bcefd6ab2df199acd28aad276ff0d920d6992892", "price_changes":[{"asset_id":"4394372887385518214471608448209527405727552777602031099972143344338178308080", "price":"0.17", "size":"27652.43", "side":"SELL", "hash":"65ff3a25a1bae9e780e6def6ee6476092094cf69", "best_bid":"0.167", "best_ask":"0.168"}, {"asset_id":"112680630004798425069810935278212000865453267506345451433803052322987302357330", "price":"0.83", "size":"27652.43", "side":"BUY", "hash":"92301e4af054d258edae144a46efa9b406fb9f3a", "best_bid":"0.832", "best_ask":"0.833"}], "timestamp":"1780178300366", "event_type":"price_change"}
